Workbook

Sheet DASHBOARD
E21: =(Data!A2-1)+INT((Processing!A19-1)/12)+1 -> 2028
E23: {=INDEX(Processing!U3:U14,Processing!A17)} -> DECEMBER

Sheet DASHBOARD Contrast
E21: =(Data!A2-1)+INT((Processing!A19-1)/12)+1 -> 2028
E23: {=INDEX(Processing!U3:U14,Processing!A17)} -> DECEMBER

Sheet Processing
A1: Time Line | C1: 20 | D1: 0.7 | F1: LN | G1: Plan | H1: Value 1 | I1: Value 2 | J1: Label | K1: Month | L1: Sectors | M1: Name Month | R1: Sectors | X1: Expenditure Budget
A2: {=INDEX(Data!C2:C49,A19)} -> 1 | B2: =240%-A2 -> 1.4 | C2: =$D$1 -> 0.7 | F2: =LN(G13/G2)/11 -> 0.15160971 | G2: =N9 -> 47793.265 | H2: 100 | I2: =IF($A$17=K2,$H$2,0) -> 0 | J2: =IF($A$17=K2,G2,"") | K2: 1 | L2: 30 | M2: JAN | N2: =(A17-1)*30 -> 330 | O2: 30 | P2: =360-SUM(N2:O2) -> 0 | R2: 10 | X2: Month | Y2: Current
C3: 20 | G3: =$G$2 * EXP($F$2 * K2) -> 55617.307 | H3: 100 | I3: =IF($A$17=K3,$H$2,0) -> 0 | J3: =IF($A$17=K3,G3,"") | K3: 2 | L3: 30 | M3: FEB | R3: 10 | T3: 1 | U3: JANUARY | V3: {=INDEX(Data!$H$2:$H$49,MATCH(DASHBOARD!$E$21&Processing!U3,Data!$A$2:$A$49&Data!$B$2:$B$49,0))+V2} -> 307157.06 | W3: 1 | X3: 0 | Y3: {=IF(INDEX($V$3:$V$14,$A$17)=X3,X3,NA())} -> #N/A | AA3: =V3/100 -> 3071.5706
C4: =$D$1 -> 0.7 | G4: =$G$2 * EXP($F$2 * K3) -> 64722.192 | H4: 100 | I4: =IF($A$17=K4,$H$2,0) -> 0 | J4: =IF($A$17=K4,G4,"") | K4: 3 | L4: 30 | M4: MAR | N4: =V16/K15 -> 0.97510179 | O4: Budget Used | R4: 10 | T4: 2 | U4: FEBRUARY | V4: {=INDEX(Data!$H$2:$H$49,MATCH(DASHBOARD!$E$21&Processing!U4,Data!$A$2:$A$49&Data!$B$2:$B$49,0))+V3} -> 330283.32 | W4: 2 | X4: 0 | Y4: {=IF(INDEX($V$3:$V$14,$A$17)=X4,X4,NA())} -> #N/A | AA4: =V4/100 -> 3302.8332
C5: 20 | G5: =$G$2 * EXP($F$2 * K4) -> 75317.601 | H5: 100 | I5: =IF($A$17=K5,$H$2,0) -> 0 | J5: =IF($A$17=K5,G5,"") | K5: 4 | L5: 30 | M5: APR | N5: =N4-O5 -> 0.87510179 | O5: 0.1 | P5: =100%-N5-O5 -> 0.024898214 | Q5: 1 | R5: 10 | T5: 3 | U5: MARCH | V5: {=INDEX(Data!$H$2:$H$49,MATCH(DASHBOARD!$E$21&Processing!U5,Data!$A$2:$A$49&Data!$B$2:$B$49,0))+V4} -> 355150.78 | W5: 3 | X5: 0 | Y5: {=IF(INDEX($V$3:$V$14,$A$17)=X5,X5,NA())} -> #N/A | AA5: =V5/100 -> 3551.5078
C6: =$D$1 -> 0.7 | G6: =$G$2 * EXP($F$2 * K5) -> 87647.542 | H6: 100 | I6: =IF($A$17=K6,$H$2,0) -> 0 | J6: =IF($A$17=K6,G6,"") | K6: 5 | L6: 30 | M6: MAY | R6: 10 | T6: 4 | U6: APRIL | V6: {=INDEX(Data!$H$2:$H$49,MATCH(DASHBOARD!$E$21&Processing!U6,Data!$A$2:$A$49&Data!$B$2:$B$49,0))+V5} -> 381890.55 | W6: 4 | X6: =$V$3 -> 307157.06 | Y6: {=IF(INDEX($V$3:$V$14,$A$17)=X6,X6,NA())} -> #N/A | AA6: =V6/100 -> 3818.9055
C7: 20 | G7: =$G$2 * EXP($F$2 * K6) -> 101995.97 | H7: 100 | I7: =IF($A$17=K7,$H$2,0) -> 0 | J7: =IF($A$17=K7,G7,"") | K7: 6 | L7: 30 | M7: JUN | N7: Tasks | O7: Descript | R7: 10 | T7: 5 | U7: MAY | V7: {=INDEX(Data!$H$2:$H$49,MATCH(DASHBOARD!$E$21&Processing!U7,Data!$A$2:$A$49&Data!$B$2:$B$49,0))+V6} -> 410643.59 | W7: 5 | X7: =$V$3 -> 307157.06 | Y7: {=IF(INDEX($V$3:$V$14,$A$17)=X7,X7,NA())} -> #N/A | AA7: =V7/100 -> 4106.4359
C8: =$D$1 -> 0.7 | G8: =$G$2 * EXP($F$2 * K7) -> 118693.32 | H8: 100 | I8: =IF($A$17=K8,$H$2,0) -> 0 | J8: =IF($A$17=K8,G8,"") | K8: 7 | L8: 30 | M8: JUL | N8: {=INDEX(Data!J2:J49,$A$19)} -> Adjustments | O8: {=INDEX(Data!K2:K49,$A$19)} -> Performance analysis and strategy adjustments – evaluating KPIs, improving processes, and planning future growth. | R8: 10 | T8: 6 | U8: JUNE | V8: {=INDEX(Data!$H$2:$H$49,MATCH(DASHBOARD!$E$21&Processing!U8,Data!$A$2:$A$49&Data!$B$2:$B$49,0))+V7} -> 441561.48 | W8: 6 | X8: =$V$3 -> 307157.06 | Y8: {=IF(INDEX($V$3:$V$14,$A$17)=X8,X8,NA())} -> #N/A | AA8: =V8/100 -> 4415.6148
C9: 20 | G9: =$G$2 * EXP($F$2 * K8) -> 138124.12 | H9: 100 | I9: =IF($A$17=K9,$H$2,0) -> 0 | J9: =IF($A$17=K9,G9,"") | K9: 8 | L9: 30 | M9: AUG | N9: {=INDEX(Data!H2:H49,$A$19)} -> 47793.265 | R9: 10 | T9: 7 | U9: JULY | V9: {=INDEX(Data!$H$2:$H$49,MATCH(DASHBOARD!$E$21&Processing!U9,Data!$A$2:$A$49&Data!$B$2:$B$49,0))+V8} -> 474807.22 | W9: 7 | X9: =$V$3 -> 307157.06 | Y9: {=IF(INDEX($V$3:$V$14,$A$17)=X9,X9,NA())} -> #N/A | AA9: =V9/100 -> 4748.0722
C10: =200-SUM(C1:C9) -> 97.2 | G10: =$G$2 * EXP($F$2 * K9) -> 160735.86 | H10: 100 | I10: =IF($A$17=K10,$H$2,0) -> 0 | J10: =IF($A$17=K10,G10,"") | K10: 9 | L10: 30 | M10: SEP | R10: 10 | T10: 8 | U10: AUGUST | V10: {=INDEX(Data!$H$2:$H$49,MATCH(DASHBOARD!$E$21&Processing!U10,Data!$A$2:$A$49&Data!$B$2:$B$49,0))+V9} -> 510556.08 | W10: 8 | X10: =$V$3 -> 307157.06 | Y10: {=IF(INDEX($V$3:$V$14,$A$17)=X10,X10,NA())} -> #N/A | AA10: =V10/100 -> 5105.5608
G11: =$G$2 * EXP($F$2 * K10) -> 187049.28 | H11: 100 | I11: =IF($A$17=K11,$H$2,0) -> 0 | J11: =IF($A$17=K11,G11,"") | K11: 10 | L11: 30 | M11: OCT | R11: 10 | T11: 9 | U11: SEPTEMBER | V11: {=INDEX(Data!$H$2:$H$49,MATCH(DASHBOARD!$E$21&Processing!U11,Data!$A$2:$A$49&Data!$B$2:$B$49,0))+V10} -> 548996.51 | W11: 9 | X11: =$V$3 -> 307157.06 | Y11: {=IF(INDEX($V$3:$V$14,$A$17)=X11,X11,NA())} -> #N/A | AA11: =V11/100 -> 5489.9651
G12: =$G$2 * EXP($F$2 * K11) -> 217670.36 | H12: 100 | I12: =IF($A$17=K12,$H$2,0) -> 0 | J12: =IF($A$17=K12,G12,"") | K12: 11 | L12: 30 | M12: NOV | R12: 10 | T12: 10 | U12: OCTOBER | V12: {=INDEX(Data!$H$2:$H$49,MATCH(DASHBOARD!$E$21&Processing!U12,Data!$A$2:$A$49&Data!$B$2:$B$49,0))+V11} -> 590331.18 | W12: 10 | X12: =$V$3 -> 307157.06 | Y12: {=IF(INDEX($V$3:$V$14,$A$17)=X12,X12,NA())} -> #N/A | AA12: =V12/100 -> 5903.3118
A13: Planned Profit | F13: =G13 -> 253304.3 | G13: =G2*B14 -> 253304.3 | H13: 100 | I13: =IF($A$17=K13,$H$2,0) -> 100 | J13: =IF($A$17=K13,G13,"") -> 253304.3 | K13: 12 | L13: 30 | M13: DEC | R13: 10 | T13: 11 | U13: NOVEMBER | V13: {=INDEX(Data!$H$2:$H$49,MATCH(DASHBOARD!$E$21&Processing!U13,Data!$A$2:$A$49&Data!$B$2:$B$49,0))+V12} -> 634777.99 | W13: 11 | X13: =$V$3 -> 307157.06 | Y13: {=IF(INDEX($V$3:$V$14,$A$17)=X13,X13,NA())} -> #N/A | AA13: =V13/100 -> 6347.7799
A14: =100%-A15 -> 0.18867925 | B14: =B15/10 -> 5.3 | R14: 10 | T14: 12 | U14: DECEMBER | V14: {=INDEX(Data!$H$2:$H$49,MATCH(DASHBOARD!$E$21&Processing!U14,Data!$A$2:$A$49&Data!$B$2:$B$49,0))+V13} -> 682571.25 | W14: 12 | X14: =$V$3 -> 307157.06 | Y14: {=IF(INDEX($V$3:$V$14,$A$17)=X14,X14,NA())} -> #N/A | AA14: =V14/100 -> 6825.7125
A15: =100%-G2/G13 -> 0.81132075 | B15: 53 | J15: Current Budget | K15: {=INDEX(I18:I21,INT((Processing!A19-1)/12)+1)} -> 700000 | R15: 10 | U15: Month | V15: Expenses | W15: 13 | X15: =$V$3 -> 307157.06 | Y15: {=IF(INDEX($V$3:$V$14,$A$17)=X15,X15,NA())} -> #N/A
A16: Month Num | J16: Total Budget | K16: =SUM(L18:L21) -> 1455000 | R16: 10 | U16: {=INDEX(U3:U14,$A$17)} -> DECEMBER | V16: {=INDEX(V3:V14,$A$17)} -> 682571.25 | W16: 14 | X16: =$V$3 -> 307157.06 | Y16: {=IF(INDEX($V$3:$V$14,$A$17)=X16,X16,NA())} -> #N/A
A17: =MOD($A$19-1,12)+1 -> 12 | I17: Budget | J17: =MAX(J18:J21) -> 0.5 | K17: 0.4 | L17: =MAX(I21:I21) -> 700000 | R17: 10 | W17: 15 | X17: =$V$3 -> 307157.06 | Y17: {=IF(INDEX($V$3:$V$14,$A$17)=X17,X17,NA())} -> #N/A
A18: counter | H18: 2025 | I18: 135000 | J18: 0.5 | K18: 0.4 | L18: =IF(DASHBOARD!$E$21>=Processing!H21,Processing!I21,0) -> 700000 | R18: 10 | W18: 16 | X18: =$V$3 -> 307157.06 | Y18: {=IF(INDEX($V$3:$V$14,$A$17)=X18,X18,NA())} -> #N/A
A19: 48 | H19: 2026 | I19: 220000 | J19: 0.5 | K19: 0.37 | L19: =IF(DASHBOARD!$E$21>=Processing!H20,Processing!I20,0) -> 400000 | R19: 10 | W19: 17 | X19: =$V$3 -> 307157.06 | Y19: {=IF(INDEX($V$3:$V$14,$A$17)=X19,X19,NA())} -> #N/A
H20: 2027 | I20: 400000 | J20: 0.5 | K20: 0.35 | L20: =IF(DASHBOARD!$E$21>=Processing!H19,Processing!I19,0) -> 220000 | R20: 10 | W20: 18 | X20: =$V$3 -> 307157.06 | Y20: {=IF(INDEX($V$3:$V$14,$A$17)=X20,X20,NA())} -> #N/A
H21: 2028 | I21: 700000 | J21: 0.5 | K21: 0.34 | L21: =IF(DASHBOARD!$E$21>=Processing!H18,Processing!I18,0) -> 135000 | R21: 10 | W21: 19 | X21: =$V$3 -> 307157.06 | Y21: {=IF(INDEX($V$3:$V$14,$A$17)=X21,X21,NA())} -> #N/A
A22: Fruit & Veg | B22: {=INDEX(Data!$D$2:$G$49,Processing!$A$19,MATCH(Processing!A22,Data!$D$1:$G$1,0))} -> 1 | C22: =IF($B22,$C$26,0) -> 0.05 | D22: =B22 -> 1 | E22: =IF($B22,$C$26,0) -> 0.05 | F22: =100%-D22 -> 0 | G22: =IF($B22<100%,$C$26,0) -> 0 | W22: 20 | X22: =$V$3 -> 307157.06 | Y22: {=IF(INDEX($V$3:$V$14,$A$17)=X22,X22,NA())} -> #N/A
A23: Electronics | B23: {=INDEX(Data!$D$2:$G$49,Processing!$A$19,MATCH(Processing!A23,Data!$D$1:$G$1,0))} -> 1 | C23: =IF($B23,$C$26,0) -> 0.05 | D23: =B23 -> 1 | E23: =IF($B23,$C$26,0) -> 0.05 | F23: =100%-D23 -> 0 | G23: =IF($B23<100%,$C$26,0) -> 0 | L23: Margin | W23: 21 | X23: =$V$3 -> 307157.06 | Y23: {=IF(INDEX($V$3:$V$14,$A$17)=X23,X23,NA())} -> #N/A
A24: Clothing & Style | B24: {=INDEX(Data!$D$2:$G$49,Processing!$A$19,MATCH(Processing!A24,Data!$D$1:$G$1,0))} -> 0.37 | C24: =IF($B24,$C$26,0) -> 0.05 | D24: =B24 -> 0.37 | E24: =IF($B24,$C$26,0) -> 0.05 | F24: =100%-D24 -> 0.63 | G24: =IF($B24<100%,$C$26,0) -> 0.05 | K24: 2025 | L24: 0.12 | M24: =25%-(N24/2) -> 0.19 | N24: {=IF(DASHBOARD!$E$21=Processing!K24,INDEX(Data!$I$2:$I$49,Processing!$A$19),IF(DASHBOARD!$E$21>Processing!K24,INDEX(Data!$I$2:$I$49,12),0))} -> 0.12 | O24: =100%-N24-M24 -> 0.69 | W24: 22 | X24: =$V$3 -> 307157.06 | Y24: {=IF(INDEX($V$3:$V$14,$A$17)=X24,X24,NA())} -> #N/A
A25: Home & Living | B25: {=INDEX(Data!$D$2:$G$49,Processing!$A$19,MATCH(Processing!A25,Data!$D$1:$G$1,0))} -> 0.45 | C25: =IF($B25,$C$26,0) -> 0.05 | D25: =B25 -> 0.45 | E25: =IF($B25,$C$26,0) -> 0.05 | F25: =100%-D25 -> 0.55 | G25: =IF($B25<100%,$C$26,0) -> 0.05 | K25: 2026 | L25: 0.3 | M25: =25%-(N25/2) -> 0.1 | N25: {=IF(DASHBOARD!$E$21=Processing!K25,INDEX(Data!$I$2:$I$49,Processing!$A$19),IF(DASHBOARD!$E$21>Processing!K25,INDEX(Data!$I$2:$I$49,24),0))} -> 0.3 | O25: =100%-N25-M25 -> 0.6 | W25: 23 | X25: =$V$3 -> 307157.06 | Y25: {=IF(INDEX($V$3:$V$14,$A$17)=X25,X25,NA())} -> #N/A
B26: Indent | C26: 0.05 | K26: 2027 | L26: 0.18 | M26: =25%-(N26/2) -> 0.16 | N26: {=IF(DASHBOARD!$E$21=Processing!K26,INDEX(Data!$I$2:$I$49,Processing!$A$19),IF(DASHBOARD!$E$21>Processing!K26,INDEX(Data!$I$2:$I$49,36),0))} -> 0.18 | O26: =100%-N26-M26 -> 0.66 | W26: 24 | X26: =$V$3 -> 307157.06 | Y26: {=IF(INDEX($V$3:$V$14,$A$17)=X26,X26,NA())} -> #N/A
K27: 2028 | L27: 0.25 | M27: =25%-(N27/2) -> 0.125 | N27: {=IF(DASHBOARD!$E$21=Processing!K27,INDEX(Data!$I$2:$I$49,Processing!$A$19),IF(DASHBOARD!$E$21>Processing!K27,INDEX(Data!$I$2:$I$49,48),0))} -> 0.25 | O27: =100%-N27-M27 -> 0.625 | W27: 25 | X27: =$V$3 -> 307157.06 | Y27: {=IF(INDEX($V$3:$V$14,$A$17)=X27,X27,NA())} -> #N/A
W28: 26 | X28: =$V$3 -> 307157.06 | Y28: {=IF(INDEX($V$3:$V$14,$A$17)=X28,X28,NA())} -> #N/A
W29: 27 | X29: =$V$3 -> 307157.06 | Y29: {=IF(INDEX($V$3:$V$14,$A$17)=X29,X29,NA())} -> #N/A
W30: 28 | X30: =$V$3 -> 307157.06 | Y30: {=IF(INDEX($V$3:$V$14,$A$17)=X30,X30,NA())} -> #N/A
W31: 29 | X31: =$V$3 -> 307157.06 | Y31: {=IF(INDEX($V$3:$V$14,$A$17)=X31,X31,NA())} -> #N/A
W32: 30 | X32: =$V$3 -> 307157.06 | Y32: {=IF(INDEX($V$3:$V$14,$A$17)=X32,X32,NA())} -> #N/A
W33: 31 | X33: 0 | Y33: {=IF(INDEX($V$3:$V$14,$A$17)=X33,X33,NA())} -> #N/A
W34: 32 | X34: 0 | Y34: {=IF(INDEX($V$3:$V$14,$A$17)=X34,X34,NA())} -> #N/A
W35: 33 | X35: 0 | Y35: {=IF(INDEX($V$3:$V$14,$A$17)=X35,X35,NA())} -> #N/A
W36: 34 | X36: =$V$4 -> 330283.32 | Y36: {=IF(INDEX($V$3:$V$14,$A$17)=X36,X36,NA())} -> #N/A
W37: 35 | X37: =$V$4 -> 330283.32 | Y37: {=IF(INDEX($V$3:$V$14,$A$17)=X37,X37,NA())} -> #N/A
W38: 36 | X38: =$V$4 -> 330283.32 | Y38: {=IF(INDEX($V$3:$V$14,$A$17)=X38,X38,NA())} -> #N/A
W39: 37 | X39: =$V$4 -> 330283.32 | Y39: {=IF(INDEX($V$3:$V$14,$A$17)=X39,X39,NA())} -> #N/A
W40: 38 | X40: =$V$4 -> 330283.32 | Y40: {=IF(INDEX($V$3:$V$14,$A$17)=X40,X40,NA())} -> #N/A
...

Sheet Data
C1: Progress Bar | D1: Fruit & Veg | E1: Electronics | F1: Clothing & Style | G1: Home & Living | H1: Expenses | I1: Margin
A2: 2025 | B2: JANUARY | C2: =ROW(B1)/COUNTA(B:B) -> 0.020833333 | D2: 0 | E2: 0 | F2: 0 | G2: 0 | H2: 9491 | I2: 0 | J2: Market Analysis | K2: Market analysis and location selection – studying competitors, target audience, foot traffic, and rental options.
A3: 2025 | B3: FEBRUARY | C3: =ROW(B2)/COUNTA(B:B) -> 0.041666667 | D3: 0 | E3: 0 | F3: 0 | G3: 0 | H3: 9960 | I3: 0.02 | J3: Lease | K3: Signing the lease agreement – negotiating terms, signing the contract, and handling necessary paperwork.
A4: 2025 | B4: MARCH | C4: =ROW(B3)/COUNTA(B:B) -> 0.0625 | D4: 0 | E4: 0 | F4: 0 | G4: 0 | H4: 7863 | I4: 0.03 | J4: Design Project | K4: Design project development – planning the layout, branding, and visual design.
A5: 2025 | B5: APRIL | C5: =ROW(B4)/COUNTA(B:B) -> 0.083333333 | D5: 0 | E5: 0 | F5: 0 | G5: 0 | H5: 8395 | I5: 0.04 | J5: Renovation | K5: Renovation and site preparation – construction work, finishing, and setting up utilities.
A6: 2025 | B6: MAY | C6: =ROW(B5)/COUNTA(B:B) -> 0.10416667 | D6: 0 | E6: 0 | F6: 0 | G6: 0 | H6: 10565 | I6: 0.05 | J6: Equipment | K6: Purchasing and installing equipment – shelves, cash registers, lighting, and furniture.
A7: 2025 | B7: JUNE | C7: =ROW(B6)/COUNTA(B:B) -> 0.125 | D7: 0 | E7: 0 | F7: 0 | G7: 0 | H7: 14588 | I7: 0.06 | J7: Assortment | K7: Forming the product assortment – signing contracts with suppliers and purchasing initial inventory.
A8: 2025 | B8: JULY | C8: =ROW(B7)/COUNTA(B:B) -> 0.14583333 | D8: 0 | E8: 0 | F8: 0 | G8: 0 | H8: 18211 | I8: 0.07 | J8: Staff | K8: Hiring and training staff – recruiting employees, conducting training, and processing paperwork.
A9: 2025 | B9: AUGUST | C9: =ROW(B8)/COUNTA(B:B) -> 0.16666667 | D9: 0 | E9: 0 | F9: 0 | G9: 0 | H9: 12421 | I9: 0.08 | J9: Strategy | K9: Developing a marketing strategy – advertising campaigns, social media setup, and promotions.
A10: 2025 | B10: SEPTEMBER | C10: =ROW(B9)/COUNTA(B:B) -> 0.1875 | D10: 0 | E10: 0 | F10: 0 | G10: 0 | H10: 7150 | I10: 0.09 | J10: Test Processes | K10: Testing internal processes – trial sales, POS system setup, and logistics testing.
A11: 2025 | B11: OCTOBER | C11: =ROW(B10)/COUNTA(B:B) -> 0.20833333 | D11: 0 | E11: 0 | F11: 0 | G11: 0 | H11: 8294 | I11: 0.1 | J11: Advertising | K11: Launching an advertising campaign – announcements, promotions, and attracting first customers.
A12: 2025 | B12: NOVEMBER | C12: =ROW(B11)/COUNTA(B:B) -> 0.22916667 | D12: 0 | E12: 0 | F12: 0 | G12: 0 | H12: 9432 | I12: 0.11 | J12: Store Opening | K12: Store grand opening – hosting an opening event and starting sales.
A13: 2025 | B13: DECEMBER | C13: =ROW(B12)/COUNTA(B:B) -> 0.25 | D13: 0.35 | E13: 0 | F13: 0 | G13: 0 | H13: 16003 | I13: 0.12 | J13: Adjustments | K13: Performance analysis and strategy adjustments – evaluating KPIs, improving processes, and planning future growth.
... A49: 2028 | B49: DECEMBER | C49: =ROW(B48)/COUNTA(B:B) -> 1 | D49: 1 | E49: 1 | F49: 0.37 | G49: 0.45 | H49: 47793.265 | I49: 0.25 | J49: Adjustments | K49: Performance analysis and strategy adjustments – evaluating KPIs, improving processes, and planning future growth.

Sheet R
B1: C3EFE5 | D1: analysis
B2: 0EBAC7 | D2: warehouse
D3: design
D4: renovation
D5: store
D6: product
D7: person
D8: strategy
D9: processes
D10: marketing
D11: store
D12: analysis
