Workbook
Name dborders: 'ALL ORDERS'!$A$3:$X$806
Name Slicer_Month: #N/A
Name Slicer_Year: #N/A

Sheet DASHBOARD

Sheet ALL ORDERS
F2: ALL ORDERS
A3: Registration Date | B3: Day | C3: Month | D3: Year | E3: Manager | F3: Service | G3: Cash | H3: Card | I3: Discount | J3: Total | K3: Date of visit | L3: Day of visit | M3: Month of visit | N3: Year of visit | O3: Visit time | P3: Client | Q3: City | R3: Address | S3: Master | T3: Contact | U3: Channel | V3: Status | W3: Cost | X3: Client rating
A4: 44927 | B4: =DAY(A4) -> 1 | C4: {=INDEX(Processing!$C$11:$C$22,MONTH('ALL ORDERS'!A4))} -> JAN | D4: =YEAR(A4) -> 2023 | E4: Jacob | F4: Dismantling the balcony block | G4: 4500 | H4: 0 | J4: =G4+H4 -> 4500 | K4: 44927 | L4: =DAY(K4) -> 1 | M4: {=INDEX(Processing!$W$6:$W$17,MONTH('ALL ORDERS'!K4))} -> January | N4: =YEAR(K4) -> 2023 | O4: 0.4375 | P4: Client 1 | Q4: Chikago | R4: 123 Elm Street, Apt. 4B | S4: Jack | T4: (917) 555-5616 | U4: Instagram | V4: Completed | W4: 5618 | X4: 5 | Y4: 1467 | Z4: =W4+Y4 -> 7085
A5: 44928 | B5: =DAY(A5) -> 2 | C5: {=INDEX(Processing!$C$11:$C$22,MONTH('ALL ORDERS'!A5))} -> JAN | D5: =YEAR(A5) -> 2023 | E5: Joseph | F5: Laying parquet boards with glue | G5: 10000 | H5: 0 | J5: =G5+H5 -> 10000 | K5: 44928 | L5: =DAY(K5) -> 2 | M5: {=INDEX(Processing!$W$6:$W$17,MONTH('ALL ORDERS'!K5))} -> January | N5: =YEAR(K5) -> 2023 | O5: 0.41666667 | P5: Client 2 | Q5: Chikago | R5: 456 Willow Avenue, Unit 7 | S5: William | T5: (718) 555-8703 | U5: WhatsApp | V5: Completed | W5: 10619 | X5: 4 | Y5: 2073 | Z5: =W5+Y5 -> 12692
A6: 44929 | B6: =DAY(A6) -> 3 | C6: {=INDEX(Processing!$C$11:$C$22,MONTH('ALL ORDERS'!A6))} -> JAN | D6: =YEAR(A6) -> 2023 | E6: Liam | F6: Laying quartz vinyl tiles on a substrate | G6: 5450 | H6: 0 | J6: =G6+H6 -> 5450 | K6: 44929 | L6: =DAY(K6) -> 3 | M6: {=INDEX(Processing!$W$6:$W$17,MONTH('ALL ORDERS'!K6))} -> January | N6: =YEAR(K6) -> 2023 | O6: 0.5 | P6: Client 3 | Q6: New York | R6: 789 Oak Lane, Suite 12 | S6: James | T6: (646) 555-2283 | U6: Facebook | V6: Completed | W6: 8931 | X6: 4 | Y6: 1235 | Z6: =W6+Y6 -> 10166
A7: 44930 | B7: =DAY(A7) -> 4 | C7: {=INDEX(Processing!$C$11:$C$22,MONTH('ALL ORDERS'!A7))} -> JAN | D7: =YEAR(A7) -> 2023 | E7: Isabella | F7: Laying parquet boards on a substrate | G7: 6200 | H7: 0 | J7: =G7+H7 -> 6200 | K7: 44930 | L7: =DAY(K7) -> 4 | M7: {=INDEX(Processing!$W$6:$W$17,MONTH('ALL ORDERS'!K7))} -> January | N7: =YEAR(K7) -> 2023 | O7: 0.66666667 | P7: Client 4 | Q7: Chikago | R7: 234 Pine Road, Apt. 3C | S7: Oliver | T7: (212) 555-7828 | U7: Reddit | V7: Completed | W7: 11848 | X7: 4 | Y7: 1883 | Z7: =W7+Y7 -> 13731
A8: 44957 | B8: =DAY(A8) -> 31 | C8: {=INDEX(Processing!$C$11:$C$22,MONTH('ALL ORDERS'!A8))} -> JAN | D8: =YEAR(A8) -> 2023 | E8: Joseph | F8: Laying parquet boards on a substrate | G8: 5000 | H8: 6250 | J8: =G8+H8 -> 11250 | K8: 44957 | L8: =DAY(K8) -> 31 | M8: {=INDEX(Processing!$W$6:$W$17,MONTH('ALL ORDERS'!K8))} -> January | N8: =YEAR(K8) -> 2023 | O8: 0.70833333 | P8: Client 5 | Q8: Chikago | R8: 235 Pine Road, Apt. 3C | S8: Lucas | T8: (212) 555-7829 | U8: Instagram | V8: Completed | W8: 2176 | X8: 5 | Y8: 921 | Z8: =W8+Y8 -> 3097
A9: 44931 | B9: =DAY(A9) -> 5 | C9: {=INDEX(Processing!$C$11:$C$22,MONTH('ALL ORDERS'!A9))} -> JAN | D9: =YEAR(A9) -> 2023 | E9: Charlotte | F9: Laying solid boards | G9: 4000 | H9: 0 | J9: =G9+H9 -> 4000 | K9: 44931 | L9: =DAY(K9) -> 5 | M9: {=INDEX(Processing!$W$6:$W$17,MONTH('ALL ORDERS'!K9))} -> January | N9: =YEAR(K9) -> 2023 | O9: 0.4375 | P9: Client 5 | Q9: Chikago | R9: 567 Birch Street, Unit 8D | S9: Sofia | T9: (917) 555-4259 | U9: Instagram | V9: Completed | W9: 10588 | X9: 4 | Y9: 1331 | Z9: =W9+Y9 -> 11919
A10: 44958 | B10: =DAY(A10) -> 1 | C10: {=INDEX(Processing!$C$11:$C$22,MONTH('ALL ORDERS'!A10))} -> FEB | D10: =YEAR(A10) -> 2023 | E10: Joseph | F10: Installation of ceiling plinth | G10: 8600 | H10: 0 | I10: 0.05 | J10: =G10+H10 -> 8600 | K10: 44958 | L10: =DAY(K10) -> 1 | M10: {=INDEX(Processing!$W$6:$W$17,MONTH('ALL ORDERS'!K10))} -> February | N10: =YEAR(K10) -> 2023 | O10: 0.4375 | P10: Client 6 | Q10: Chikago | R10: 890 Maple Drive, Apt. 2A | S10: Jack | T10: (718) 555-3394 | U10: WhatsApp | V10: Completed | W10: 10812 | X10: 4 | Y10: 2111 | Z10: =W10+Y10 -> 12923
A11: 44959 | B11: =DAY(A11) -> 2 | C11: {=INDEX(Processing!$C$11:$C$22,MONTH('ALL ORDERS'!A11))} -> FEB | D11: =YEAR(A11) -> 2023 | E11: Jacob | F11: Laying solid boards | G11: 10000 | H11: 0 | J11: =G11+H11 -> 10000 | K11: 44959 | L11: =DAY(K11) -> 2 | M11: {=INDEX(Processing!$W$6:$W$17,MONTH('ALL ORDERS'!K11))} -> February | N11: =YEAR(K11) -> 2023 | O11: 0.41666667 | P11: Client 7 | Q11: Chikago | R11: 345 Cedar Court, Suite 6E | S11: William | T11: (646) 555-6727 | U11: Facebook | V11: Completed | W11: 4615 | X11: 4 | Y11: 785 | Z11: =W11+Y11 -> 5400
A12: 44985 | B12: =DAY(A12) -> 28 | C12: {=INDEX(Processing!$C$11:$C$22,MONTH('ALL ORDERS'!A12))} -> FEB | D12: =YEAR(A12) -> 2023 | E12: Charlotte | F12: Laying solid boards | G12: 0 | H12: 14900 | J12: =G12+H12 -> 14900 | K12: 44985 | L12: =DAY(K12) -> 28 | M12: {=INDEX(Processing!$W$6:$W$17,MONTH('ALL ORDERS'!K12))} -> February | N12: =YEAR(K12) -> 2023 | O12: 0.45833333 | P12: Client 8 | Q12: Chikago | R12: 346 Cedar Court, Suite 6E | S12: James | T12: (646) 555-6728 | U12: Facebook | V12: Completed | W12: 5454 | X12: 5 | Y12: 957 | Z12: =W12+Y12 -> 6411
A13: 44960 | B13: =DAY(A13) -> 3 | C13: {=INDEX(Processing!$C$11:$C$22,MONTH('ALL ORDERS'!A13))} -> FEB | D13: =YEAR(A13) -> 2023 | E13: Liam | F13: Installation of ceiling plinth | G13: 10300 | H13: 0 | J13: =G13+H13 -> 10300 | K13: 44960 | L13: =DAY(K13) -> 3 | M13: {=INDEX(Processing!$W$6:$W$17,MONTH('ALL ORDERS'!K13))} -> February | N13: =YEAR(K13) -> 2023 | O13: 0.5 | P13: Client 8 | Q13: New York | R13: 678 Spruce Lane, Apt. 1F | S13: Oliver | T13: (212) 555-9814 | U13: Reddit | V13: Completed | W13: 11688 | X13: 4 | Y13: 1216 | Z13: =W13+Y13 -> 12904
A14: 44961 | B14: =DAY(A14) -> 4 | C14: {=INDEX(Processing!$C$11:$C$22,MONTH('ALL ORDERS'!A14))} -> FEB | D14: =YEAR(A14) -> 2023 | E14: Isabella | F14: Installation of ceiling plinth | G14: 10300 | H14: 0 | J14: =G14+H14 -> 10300 | K14: 44961 | L14: =DAY(K14) -> 4 | M14: {=INDEX(Processing!$W$6:$W$17,MONTH('ALL ORDERS'!K14))} -> February | N14: =YEAR(K14) -> 2023 | O14: 0.54166667 | P14: Client 9 | Q14: New York | R14: 679 Spruce Lane, Apt. 1F | S14: Lucas | T14: (212) 555-9815 | U14: Instagram | V14: Completed | W14: 6749 | X14: 5 | Y14: 1165 | Z14: =W14+Y14 -> 7914
A15: 44986 | B15: =DAY(A15) -> 1 | C15: {=INDEX(Processing!$C$11:$C$22,MONTH('ALL ORDERS'!A15))} -> MAR | D15: =YEAR(A15) -> 2023 | E15: Isabella | F15: Cutting and installation of additional corners | G15: 13000 | H15: 0 | J15: =G15+H15 -> 13000 | K15: 44986 | L15: =DAY(K15) -> 1 | M15: {=INDEX(Processing!$W$6:$W$17,MONTH('ALL ORDERS'!K15))} -> March | N15: =YEAR(K15) -> 2023 | O15: 0.66666667 | P15: Client 9 | Q15: Chikago | R15: 1234 Redwood Road, Unit 5G | S15: Sofia | T15: (917) 555-7828 | U15: Instagram | V15: Completed | W15: 9627 | X15: 4 | Y15: 2721 | Z15: =W15+Y15 -> 12348
A16: 44987 | B16: =DAY(A16) -> 2 | C16: {=INDEX(Processing!$C$11:$C$22,MONTH('ALL ORDERS'!A16))} -> MAR | D16: =YEAR(A16) -> 2023 | E16: Charlotte | F16: Laying parquet boards on a substrate | G16: 10000 | H16: 0 | J16: =G16+H16 -> 10000 | K16: 44987 | L16: =DAY(K16) -> 2 | M16: {=INDEX(Processing!$W$6:$W$17,MONTH('ALL ORDERS'!K16))} -> March | N16: =YEAR(K16) -> 2023 | O16: 0.4375 | P16: Client 10 | Q16: Chikago | R16: 5678 Juniper Street, Apt. 9H | S16: Oliver | T16: (718) 555-2283 | U16: Reddit | V16: Completed | W16: 5190 | X16: 4 | Y16: 783 | Z16: =W16+Y16 -> 5973
A17: 44988 | B17: =DAY(A17) -> 3 | C17: {=INDEX(Processing!$C$11:$C$22,MONTH('ALL ORDERS'!A17))} -> MAR | D17: =YEAR(A17) -> 2023 | E17: Joseph | F17: Dismantling the balcony block | G17: 2500 | H17: 10000 | I17: 0.1 | J17: =G17+H17 -> 12500 | K17: 44988 | L17: =DAY(K17) -> 3 | M17: {=INDEX(Processing!$W$6:$W$17,MONTH('ALL ORDERS'!K17))} -> March | N17: =YEAR(K17) -> 2023 | O17: 0.4375 | P17: Client 11 | Q17: Chikago | R17: 987 Aspen Avenue, Suite 10I | S17: Lucas | T17: 60900888990 | U17: Facebook | V17: Completed | W17: 9051 | X17: 4 | Y17: 1326 | Z17: =W17+Y17 -> 10377
A18: 44989 | B18: =DAY(A18) -> 4 | C18: {=INDEX(Processing!$C$11:$C$22,MONTH('ALL ORDERS'!A18))} -> MAR | D18: =YEAR(A18) -> 2023 | E18: Jacob | F18: Removing the front door | G18: 0 | H18: 6500 | J18: =G18+H18 -> 6500 | K18: 44989 | L18: =DAY(K18) -> 4 | M18: {=INDEX(Processing!$W$6:$W$17,MONTH('ALL ORDERS'!K18))} -> March | N18: =YEAR(K18) -> 2023 | O18: 0.41666667 | P18: Client 12 | Q18: New York | R18: 654 Pinecone Lane, Unit 11J | S18: Sofia | T18: (212) 555-1173 | U18: Reddit | V18: Completed | W18: 12438 | X18: 4 | Y18: 931 | Z18: =W18+Y18 -> 13369
A19: 44990 | B19: =DAY(A19) -> 5 | C19: {=INDEX(Processing!$C$11:$C$22,MONTH('ALL ORDERS'!A19))} -> MAR | D19: =YEAR(A19) -> 2023 | E19: Isabella | F19: Laying solid boards | G19: 2000 | H19: 0 | J19: =G19+H19 -> 2000 | K19: 44990 | L19: =DAY(K19) -> 5 | M19: {=INDEX(Processing!$W$6:$W$17,MONTH('ALL ORDERS'!K19))} -> March | N19: =YEAR(K19) -> 2023 | O19: 0.45833333 | P19: Client 12 | Q19: Chikago | R19: 320 Acorn Drive, Apt. 12K | S19: Jack | T19: (917) 555-5616 | U19: Reddit | V19: Completed | W19: 8956 | X19: 4 | Y19: 1414 | Z19: =W19+Y19 -> 10370
A20: 45016 | B20: =DAY(A20) -> 31 | C20: {=INDEX(Processing!$C$11:$C$22,MONTH('ALL ORDERS'!A20))} -> MAR | D20: =YEAR(A20) -> 2023 | E20: Liam | F20: Laying solid boards | G20: 12200 | H20: 0 | J20: =G20+H20 -> 12200 | K20: 45016 | L20: =DAY(K20) -> 31 | M20: {=INDEX(Processing!$W$6:$W$17,MONTH('ALL ORDERS'!K20))} -> March | N20: =YEAR(K20) -> 2023 | O20: 0.5 | P20: Client 13 | Q20: Chikago | R20: 321 Acorn Drive, Apt. 12K | S20: William | T20: (917) 555-5617 | U20: Instagram | V20: Completed | W20: 3530 | X20: 5 | Y20: 1323 | Z20: =W20+Y20 -> 4853
A21: 45017 | B21: =DAY(A21) -> 1 | C21: {=INDEX(Processing!$C$11:$C$22,MONTH('ALL ORDERS'!A21))} -> APR | D21: =YEAR(A21) -> 2023 | E21: Charlotte | F21: Installation of ceiling plinth | G21: 0 | H21: 6540 | J21: =G21+H21 -> 6540 | K21: 45017 | L21: =DAY(K21) -> 1 | M21: {=INDEX(Processing!$W$6:$W$17,MONTH('ALL ORDERS'!K21))} -> April | N21: =YEAR(K21) -> 2023 | O21: 0.66666667 | P21: Client 14 | Q21: Miami | R21: 876 Sequoia Road, Suite 13L | S21: James | T21: (718) 555-8704 | U21: Instagram | V21: Completed | W21: 8029 | X21: 5 | Y21: 1329 | Z21: =W21+Y21 -> 9358
A22: 45018 | B22: =DAY(A22) -> 2 | C22: {=INDEX(Processing!$C$11:$C$22,MONTH('ALL ORDERS'!A22))} -> APR | D22: =YEAR(A22) -> 2023 | E22: Joseph | F22: Removing the shower tray | G22: 0 | H22: 4550 | I22: 0.15 | J22: =G22+H22 -> 4550 | K22: 45018 | L22: =DAY(K22) -> 2 | M22: {=INDEX(Processing!$W$6:$W$17,MONTH('ALL ORDERS'!K22))} -> April | N22: =YEAR(K22) -> 2023 | O22: 0.4375 | P22: Client 15 | Q22: Chikago | R22: 543 Willowbrook Lane, Apt. 14M | S22: Oliver | T22: (646) 555-2284 | U22: Instagram | V22: Completed | W22: 6134 | X22: 5 | Y22: 1438 | Z22: =W22+Y22 -> 7572
A23: 45038 | B23: =DAY(A23) -> 22 | C23: {=INDEX(Processing!$C$11:$C$22,MONTH('ALL ORDERS'!A23))} -> APR | D23: =YEAR(A23) -> 2023 | E23: Jacob | F23: Removing the shower tray | G23: 0 | H23: 17710 | J23: =G23+H23 -> 17710 | K23: 45038 | L23: =DAY(K23) -> 22 | M23: {=INDEX(Processing!$W$6:$W$17,MONTH('ALL ORDERS'!K23))} -> April | N23: =YEAR(K23) -> 2023 | O23: 0.47916667 | P23: Client 16 | Q23: Chikago | R23: 544 Willowbrook Lane, Apt. 14M | S23: Lucas | T23: (646) 555-2285 | U23: Facebook | V23: Completed | W23: 4243 | X23: 5 | Y23: 597 | Z23: =W23+Y23 -> 4840
A24: 45039 | B24: =DAY(A24) -> 23 | C24: {=INDEX(Processing!$C$11:$C$22,MONTH('ALL ORDERS'!A24))} -> APR | D24: =YEAR(A24) -> 2023 | E24: Isabella | F24: Removing the shower tray | G24: 10000 | H24: 0 | J24: =G24+H24 -> 10000 | K24: 45039 | L24: =DAY(K24) -> 23 | M24: {=INDEX(Processing!$W$6:$W$17,MONTH('ALL ORDERS'!K24))} -> April | N24: =YEAR(K24) -> 2023 | O24: 0.52083333 | P24: Client 17 | Q24: Chikago | R24: 545 Willowbrook Lane, Apt. 14M | S24: Sofia | T24: (646) 555-2286 | U24: Reddit | V24: Completed | W24: 10772 | X24: 6 | Y24: 1394 | Z24: =W24+Y24 -> 12166
A25: 45040 | B25: =DAY(A25) -> 24 | C25: {=INDEX(Processing!$C$11:$C$22,MONTH('ALL ORDERS'!A25))} -> APR | D25: =YEAR(A25) -> 2023 | E25: Liam | F25: Removing the shower tray | G25: 0 | H25: 10000 | J25: =G25+H25 -> 10000 | K25: 45040 | L25: =DAY(K25) -> 24 | M25: {=INDEX(Processing!$W$6:$W$17,MONTH('ALL ORDERS'!K25))} -> April | N25: =YEAR(K25) -> 2023 | O25: 0.5625 | P25: Client 18 | Q25: Chikago | R25: 546 Willowbrook Lane, Apt. 14M | S25: Jack | T25: (646) 555-2287 | U25: WhatsApp | V25: Completed | W25: 10784 | X25: 7 | Y25: 1259 | Z25: =W25+Y25 -> 12043
A26: 45047 | B26: =DAY(A26) -> 1 | C26: {=INDEX(Processing!$C$11:$C$22,MONTH('ALL ORDERS'!A26))} -> MAY | D26: =YEAR(A26) -> 2023 | E26: Charlotte | F26: Dismantling the balcony block | G26: 0 | H26: 8060 | I26: 0.05 | J26: =G26+H26 -> 8060 | K26: 45047 | L26: =DAY(K26) -> 1 | M26: {=INDEX(Processing!$W$6:$W$17,MONTH('ALL ORDERS'!K26))} -> May | N26: =YEAR(K26) -> 2023 | O26: 0.41666667 | P26: Client 16 | Q26: Chikago | R26: 210 Magnolia Street, Unit 15N | S26: William | T26: (212) 555-7829 | U26: Facebook | V26: Completed | W26: 9985 | X26: 5 | Y26: 2222 | Z26: =W26+Y26 -> 12207
A27: 45048 | B27: =DAY(A27) -> 2 | C27: {=INDEX(Processing!$C$11:$C$22,MONTH('ALL ORDERS'!A27))} -> MAY | D27: =YEAR(A27) -> 2023 | E27: Joseph | F27: Laying parquet boards with glue | G27: 0 | H27: 2450 | J27: =G27+H27 -> 2450 | K27: 45048 | L27: =DAY(K27) -> 2 | M27: {=INDEX(Processing!$W$6:$W$17,MONTH('ALL ORDERS'!K27))} -> May | N27: =YEAR(K27) -> 2023 | O27: 0.5 | P27: Client 17 | Q27: Chikago | R27: 8765 Sycamore Court, Suite 16O | S27: James | T27: (917) 555-4260 | U27: Reddit | V27: Completed | W27: 7141 | X27: 5 | Y27: 1724 | Z27: =W27+Y27 -> 8865
A28: 45049 | B28: =DAY(A28) -> 3 | C28: {=INDEX(Processing!$C$11:$C$22,MONTH('ALL ORDERS'!A28))} -> MAY | D28: =YEAR(A28) -> 2023 | E28: Jacob | F28: Laying quartz vinyl tiles on a substrate | G28: 5000 | H28: 890 | J28: =G28+H28 -> 5890 | K28: 45049 | L28: =DAY(K28) -> 3 | M28: {=INDEX(Processing!$W$6:$W$17,MONTH('ALL ORDERS'!K28))} -> May | N28: =YEAR(K28) -> 2023 | O28: 0.66666667 | P28: Client 18 | Q28: Chikago | R28: 4321 Cedarwood Drive, Apt. 17P | S28: Oliver | T28: (718) 555-3395 | U28: WhatsApp | V28: Completed | W28: 9079 | X28: 3 | Y28: 1824 | Z28: =W28+Y28 -> 10903
A29: 45050 | B29: =DAY(A29) -> 4 | C29: {=INDEX(Processing!$C$11:$C$22,MONTH('ALL ORDERS'!A29))} -> MAY | D29: =YEAR(A29) -> 2023 | E29: Isabella | F29: Laying quartz vinyl tiles on a substrate | G29: 5000 | H29: 0 | J29: =G29+H29 -> 5000 | K29: 45050 | L29: =DAY(K29) -> 4 | M29: {=INDEX(Processing!$W$6:$W$17,MONTH('ALL ORDERS'!K29))} -> May | N29: =YEAR(K29) -> 2023 | O29: 0.70833333 | P29: Client 19 | Q29: Chikago | R29: 4322 Cedarwood Drive, Apt. 17P | S29: Lucas | T29: (718) 555-3396 | U29: WhatsApp | V29: Completed | W29: 7195 | X29: 4 | Y29: 1639 | Z29: =W29+Y29 -> 8834
A30: 45051 | B30: =DAY(A30) -> 5 | C30: {=INDEX(Processing!$C$11:$C$22,MONTH('ALL ORDERS'!A30))} -> MAY | D30: =YEAR(A30) -> 2023 | E30: Liam | F30: Laying quartz vinyl tiles on a substrate | G30: 10000 | H30: 0 | J30: =G30+H30 -> 10000 | K30: 45051 | L30: =DAY(K30) -> 5 | M30: {=INDEX(Processing!$W$6:$W$17,MONTH('ALL ORDERS'!K30))} -> May | N30: =YEAR(K30) -> 2023 | O30: 0.75 | P30: Client 20 | Q30: Chikago | R30: 4323 Cedarwood Drive, Apt. 17P | S30: Sofia | T30: (718) 555-3397 | U30: WhatsApp | V30: Completed | W30: 1645 | X30: 5 | Y30: 1250 | Z30: =W30+Y30 -> 2895
A31: 45078 | B31: =DAY(A31) -> 1 | C31: {=INDEX(Processing!$C$11:$C$22,MONTH('ALL ORDERS'!A31))} -> JUN | D31: =YEAR(A31) -> 2023 | E31: Charlotte | F31: Laying parquet boards on a substrate | G31: 3200 | H31: 0 | J31: =G31+H31 -> 3200 | K31: 45078 | L31: =DAY(K31) -> 1 | M31: {=INDEX(Processing!$W$6:$W$17,MONTH('ALL ORDERS'!K31))} -> June | N31: =YEAR(K31) -> 2023 | O31: 0.4375 | P31: Client 19 | Q31: Chikago | R31: 123 Elm Street, Unit 18Q | S31: Jack | T31: (646) 555-6728 | U31: Facebook | V31: Completed | W31: 5595 | X31: 3 | Y31: 1703 | Z31: =W31+Y31 -> 7298
A32: 45079 | B32: =DAY(A32) -> 2 | C32: {=INDEX(Processing!$C$11:$C$22,MONTH('ALL ORDERS'!A32))} -> JUN | D32: =YEAR(A32) -> 2023 | E32: Joseph | F32: Cutting and installation of additional corners | G32: 5000 | H32: 0 | J32: =G32+H32 -> 5000 | K32: 45079 | L32: =DAY(K32) -> 2 | M32: {=INDEX(Processing!$W$6:$W$17,MONTH('ALL ORDERS'!K32))} -> June | N32: =YEAR(K32) -> 2023 | O32: 0.47916667 | P32: Client 20 | Q32: Chikago | R32: 124 Elm Street, Unit 18Q | S32: William | T32: (646) 555-6729 | U32: WhatsApp | V32: Completed | W32: 9709 | X32: 4 | Y32: 1570 | Z32: =W32+Y32 -> 11279
A33: 45080 | B33: =DAY(A33) -> 3 | C33: {=INDEX(Processing!$C$11:$C$22,MONTH('ALL ORDERS'!A33))} -> JUN | D33: =YEAR(A33) -> 2023 | E33: Jacob | F33: Laying parquet boards on a substrate | G33: 0 | H33: 5000 | J33: =G33+H33 -> 5000 | K33: 45080 | L33: =DAY(K33) -> 3 | M33: {=INDEX(Processing!$W$6:$W$17,MONTH('ALL ORDERS'!K33))} -> June | N33: =YEAR(K33) -> 2023 | O33: 0.52083333 | P33: Client 21 | Q33: Chikago | R33: 125 Elm Street, Unit 18Q | S33: James | T33: (646) 555-6730 | U33: Facebook | V33: Completed | W33: 10307 | X33: 5 | Y33: 1438 | Z33: =W33+Y33 -> 11745
A34: 45081 | B34: =DAY(A34) -> 4 | C34: {=INDEX(Processing!$C$11:$C$22,MONTH('ALL ORDERS'!A34))} -> JUN | D34: =YEAR(A34) -> 2023 | E34: Isabella | F34: Removing the shower tray | G34: 0 | H34: 5000 | J34: =G34+H34 -> 5000 | K34: 45081 | L34: =DAY(K34) -> 4 | M34: {=INDEX(Processing!$W$6:$W$17,MONTH('ALL ORDERS'!K34))} -> June | N34: =YEAR(K34) -> 2023 | O34: 0.5625 | P34: Client 22 | Q34: Chikago | R34: 126 Elm Street, Unit 18Q | S34: Oliver | T34: (646) 555-6731 | U34: Reddit | V34: Completed | W34: 6557 | X34: 6 | Y34: 1891 | Z34: =W34+Y34 -> 8448
A35: 45082 | B35: =DAY(A35) -> 5 | C35: {=INDEX(Processing!$C$11:$C$22,MONTH('ALL ORDERS'!A35))} -> JUN | D35: =YEAR(A35) -> 2023 | E35: Liam | F35: Laying parquet boards on a substrate | G35: 5000 | H35: 0 | J35: =G35+H35 -> 5000 | K35: 45082 | L35: =DAY(K35) -> 5 | M35: {=INDEX(Processing!$W$6:$W$17,MONTH('ALL ORDERS'!K35))} -> June | N35: =YEAR(K35) -> 2023 | O35: 0.60416667 | P35: Client 23 | Q35: Chikago | R35: 127 Elm Street, Unit 18Q | S35: Lucas | T35: (646) 555-6732 | U35: Facebook | V35: Completed | W35: 12381 | X35: 7 | Y35: 1501 | Z35: =W35+Y35 -> 13882
A36: 45108 | B36: =DAY(A36) -> 1 | C36: {=INDEX(Processing!$C$11:$C$22,MONTH('ALL ORDERS'!A36))} -> JUL | D36: =YEAR(A36) -> 2023 | E36: Charlotte | F36: Laying solid boards | G36: 8800 | H36: 0 | J36: =G36+H36 -> 8800 | K36: 45108 | L36: =DAY(K36) -> 1 | M36: {=INDEX(Processing!$W$6:$W$17,MONTH('ALL ORDERS'!K36))} -> July | N36: =YEAR(K36) -> 2023 | O36: 0.4375 | P36: Client 20 | Q36: Chikago | R36: 456 Birch Avenue, Suite 19R | S36: Sofia | T36: (212) 555-9815 | U36: Reddit | V36: Completed | W36: 9211 | X36: 3 | Y36: 1316 | Z36: =W36+Y36 -> 10527
A37: 45109 | B37: =DAY(A37) -> 2 | C37: {=INDEX(Processing!$C$11:$C$22,MONTH('ALL ORDERS'!A37))} -> JUL | D37: =YEAR(A37) -> 2023 | E37: Joseph | F37: Installation of ceiling plinth | G37: 4500 | H37: 0 | J37: =G37+H37 -> 4500 | K37: 45109 | L37: =DAY(K37) -> 2 | M37: {=INDEX(Processing!$W$6:$W$17,MONTH('ALL ORDERS'!K37))} -> July | N37: =YEAR(K37) -> 2023 | O37: 0.41666667 | P37: Client 21 | Q37: New York | R37: 789 Oak Lane, Apt. 20S | S37: Jack | T37: (917) 555-7829 | U37: Reddit | V37: Completed | W37: 8933 | X37: 3 | Y37: 1416 | Z37: =W37+Y37 -> 10349
A38: 45110 | B38: =DAY(A38) -> 3 | C38: {=INDEX(Processing!$C$11:$C$22,MONTH('ALL ORDERS'!A38))} -> JUL | D38: =YEAR(A38) -> 2023 | E38: Jacob | F38: Laying solid boards | G38: 6100 | H38: 0 | I38: 0.05 | J38: =G38+H38 -> 6100 | K38: 45110 | L38: =DAY(K38) -> 3 | M38: {=INDEX(Processing!$W$6:$W$17,MONTH('ALL ORDERS'!K38))} -> July | N38: =YEAR(K38) -> 2023 | O38: 0.5 | P38: Client 22 | Q38: Chikago | R38: 234 Maple Road, Unit 21T | S38: William | T38: (718) 555-2284 | U38: Facebook | V38: Completed | W38: 5412 | X38: 3 | Y38: 919 | Z38: =W38+Y38 -> 6331
A39: 45111 | B39: =DAY(A39) -> 4 | C39: {=INDEX(Processing!$C$11:$C$22,MONTH('ALL ORDERS'!A39))} -> JUL | D39: =YEAR(A39) -> 2023 | E39: Isabella | F39: Installation of ceiling plinth | G39: 600 | H39: 10000 | J39: =G39+H39 -> 10600 | K39: 45111 | L39: =DAY(K39) -> 4 | M39: {=INDEX(Processing!$W$6:$W$17,MONTH('ALL ORDERS'!K39))} -> July | N39: =YEAR(K39) -> 2023 | O39: 0.66666667 | P39: Client 23 | Q39: Chikago | R39: 567 Pine Street, Suite 22U | S39: James | T39: 59900888990 | U39: Reddit | V39: Completed | W39: 8575 | X39: 2 | Y39: 1881 | Z39: =W39+Y39 -> 10456
A40: 45138 | B40: =DAY(A40) -> 31 | C40: {=INDEX(Processing!$C$11:$C$22,MONTH('ALL ORDERS'!A40))} -> JUL | D40: =YEAR(A40) -> 2023 | E40: Liam | F40: Installation of ceiling plinth | G40: 800 | H40: 4000 | I40: 0.05 | J40: =G40+H40 -> 4800 | K40: 45138 | L40: =DAY(K40) -> 31 | M40: {=INDEX(Processing!$W$6:$W$17,MONTH('ALL ORDERS'!K40))} -> July | N40: =YEAR(K40) -> 2023 | O40: 0.70833333 | P40: Client 24 | Q40: Chikago | R40: 568 Pine Street, Suite 22U | S40: Oliver | T40: 59900888991 | U40: WhatsApp | V40: Completed | W40: 2526 | X40: 3 | Y40: 1747 | Z40: =W40+Y40 -> 4273
A41: 45139 | B41: =DAY(A41) -> 1 | C41: {=INDEX(Processing!$C$11:$C$22,MONTH('ALL ORDERS'!A41))} -> AUG | D41: =YEAR(A41) -> 2023 | E41: Charlotte | F41: Cutting and installation of additional corners | G41: 5000 | H41: 0 | J41: =G41+H41 -> 5000 | K41: 45139 | L41: =DAY(K41) -> 1 | M41: {=INDEX(Processing!$W$6:$W$17,MONTH('ALL ORDERS'!K41))} -> August | N41: =YEAR(K41) -> 2023 | O41: 0.4375 | P41: Client 24 | Q41: Chikago | R41: 890 Willow Drive, Apt. 23V | S41: Lucas | T41: (212) 555-1174 | U41: WhatsApp | V41: Completed | W41: 7602 | X41: 3 | Y41: 2543 | Z41: =W41+Y41 -> 10145
...

Sheet ORDER
F1: Jacob | G1: MANAGER
B3: CUSTOMER | D3: DETAILS | F3: PAYMENT
B5: Client Name | D5: Service | F5: Quantity (pcs, sq.m, etc.)
B8: Contact | D8: Date of Visit | F8: Price
B9: =IFERROR(INDEX('Customer Database'!F4:F103,MATCH(ORDER!B6,'Customer Database'!B4:B103,0)),"") | F9: =Processing!Q19 -> 0
B11: City | D11: Visit Time | F11: Payment Method
B14: Address | D14: Master | F14: Discount
B15: =IFERROR(INDEX('Customer Database'!D4:D103,MATCH(ORDER!B6,'Customer Database'!B4:B103,0)),"")
B17: Channels Attracting | D17: Total Payable
D18: =ROUND(F6*Processing!Q19*(1-F15),2) -> 0

Sheet Control
A3: Row Labels | B3: Sum of Cash | C3: Sum of Card | D3: Sum of Total | E3: Sum of Cost
A4: JAN | B4: 33820 | C4: 43780 | D4: 77600 | E4: 75137
A5: FEB | B5: 28020 | C5: 67080 | D5: 95100 | E5: 102667
A6: MAR | B6: 28020 | C6: 81580 | D6: 109600 | E6: 111307
A7: APR | B7: 18020 | C7: 99080 | D7: 117100 | E7: 110749
A8: MAY | B8: 38290 | C8: 71110 | D8: 109400 | E8: 99947
A9: JUN | B9: 14300 | C9: 81300 | D9: 95600 | E9: 98003
A10: JUL | B10: 5600 | C10: 84100 | D10: 89700 | E10: 98707
A11: AUG | B11: 37130 | C11: 65470 | D11: 102600 | E11: 111153
A12: SEP | B12: 46650 | C12: 77850 | D12: 124500 | E12: 89309
A13: OCT | B13: 55900 | C13: 81300 | D13: 137200 | E13: 93153
A14: NOV | B14: 81000 | C14: 64000 | D14: 145000 | E14: 83973
A15: DEC | B15: 103410 | C15: 30290 | D15: 133700 | E15: 51384
A16: Grand Total | B16: 490160 | C16: 846940 | D16: 1337100 | E16: 1125489
A19: Row Labels | B19: Sum of Cash | C19: Sum of Card | D19: Sum of Total | E19: Sum of Cost | G19: Row Labels | H19: Sum of Total | J19: Row Labels | K19: Count of Client rating | M19: Row Labels | N19: Count of Channel | P19: Row Labels | Q19: Count of Status | S19: Sum of Card | T19: Sum of Cash
A20: JAN | B20: 33820 | C20: 43780 | D20: 77600 | E20: 75137 | G20: Charlotte | H20: 349080 | J20: Jack | K20: 86 | M20: Facebook | N20: 47 | P20: Canceled | Q20: 18 | S20: 846940 | T20: 490160
A21: FEB | B21: 28020 | C21: 67080 | D21: 95100 | E21: 102667 | G21: Isabella | H21: 240940 | J21: James | K21: 73 | M21: Instagram | N21: 98 | P21: Completed | Q21: 326
A22: MAR | B22: 28020 | C22: 81580 | D22: 109600 | E22: 111307 | G22: Jacob | H22: 192980 | J22: Lucas | K22: 37 | M22: Reddit | N22: 79 | P22: Running | Q22: 7
A23: APR | B23: 18020 | C23: 99080 | D23: 117100 | E23: 110749 | G23: Joseph | H23: 254780 | J23: Oliver | K23: 33 | M23: WhatsApp | N23: 42 | P23: Grand Total | Q23: 351
A24: MAY | B24: 38290 | C24: 71110 | D24: 109400 | E24: 99947 | G24: Liam | H24: 299320 | J24: William | K24: 60 | M24: YouTube | N24: 85
A25: JUN | B25: 14300 | C25: 81300 | D25: 95600 | E25: 98003 | G25: Grand Total | H25: 1337100 | J25: Sofia | K25: 37 | M25: Grand Total | N25: 351
A26: JUL | B26: 5600 | C26: 84100 | D26: 89700 | E26: 98707 | J26: Grand Total | K26: 326
A27: AUG | B27: 37130 | C27: 65470 | D27: 102600 | E27: 111153
A28: SEP | B28: 46650 | C28: 77850 | D28: 124500 | E28: 89309
A29: OCT | B29: 55900 | C29: 81300 | D29: 137200 | E29: 93153
A30: NOV | B30: 81000 | C30: 64000 | D30: 145000 | E30: 83973
A31: DEC | B31: 103410 | C31: 30290 | D31: 133700 | E31: 51384
A32: Grand Total | B32: 490160 | C32: 846940 | D32: 1337100 | E32: 1125489
A35: Row Labels
A36: 2025
A41: Row Labels | G41: Row Labels | H41: Count of Service
A42: JAN | G42: Application of decorative plaster | H42: 2
A43: FEB | G43: Cutting and installation of additional corners | H43: 27
A44: MAR | G44: Dismantling the balcony block | H44: 1
A45: APR | G45: Dismantling the window block | H45: 22
A46: MAY | G46: Installation of ceiling plinth | H46: 3
A47: JUN | G47: Installation of PVC skirting boards | H47: 24
A48: JUL | G48: Installation of slatted ceilings | H48: 49
A49: AUG | G49: Laying linoleum with glue | H49: 26
A50: SEP | G50: Laying parquet boards on a substrate | H50: 1
...

Sheet Personnel
I5: =UPPER(Processing!L9) -> MASTERS | K5: SALARY | M5: SALES PLAN | O5: DONE | Q5: KPI % | R5: PRIZE
I7: Jack | K7: =INDEX(Processing!$W$38:$W$48,MATCH(Personnel!I7,Processing!$S$38:$S$48,0),1) -> 24200 | M7: =AVERAGE(KPI!$D$4:$D$39) -> 4 | O7: =INDEX(Processing!$O$18:$P$23,MATCH(Personnel!I7,Processing!$N$18:$N$23,0),1) -> 86 | Q7: =INDEX(Processing!$O$18:$P$23,MATCH(Personnel!I7,Processing!$N$18:$N$23,0),2) -> 1.7916667 | R7: =IF(Q7>=100%,CHOOSE(SUM(Q7>=100%,Q7>130%),3%,5%),0%) -> 0.05
I9: William | K9: =INDEX(Processing!$W$38:$W$48,MATCH(Personnel!I9,Processing!$S$38:$S$48,0),1) -> 24200 | M9: =AVERAGE(KPI!$D$4:$D$39) -> 4 | O9: =INDEX(Processing!$O$18:$P$23,MATCH(Personnel!I9,Processing!$N$18:$N$23,0),1) -> 60 | Q9: =INDEX(Processing!$O$18:$P$23,MATCH(Personnel!I9,Processing!$N$18:$N$23,0),2) -> 1.25 | R9: =IF(Q9>=100%,CHOOSE(SUM(Q9>=100%,Q9>130%),3%,5%),0%) -> 0.03
I11: James | K11: =INDEX(Processing!$W$38:$W$48,MATCH(Personnel!I11,Processing!$S$38:$S$48,0),1) -> 24200 | M11: =AVERAGE(KPI!$D$4:$D$39) -> 4 | O11: =INDEX(Processing!$O$18:$P$23,MATCH(Personnel!I11,Processing!$N$18:$N$23,0),1) -> 73 | Q11: =INDEX(Processing!$O$18:$P$23,MATCH(Personnel!I11,Processing!$N$18:$N$23,0),2) -> 1.5208333 | R11: =IF(Q11>=100%,CHOOSE(SUM(Q11>=100%,Q11>130%),3%,5%),0%) -> 0.05
I13: Oliver | K13: =INDEX(Processing!$W$38:$W$48,MATCH(Personnel!I13,Processing!$S$38:$S$48,0),1) -> 24200 | M13: =AVERAGE(KPI!$D$4:$D$39) -> 4 | O13: =INDEX(Processing!$O$18:$P$23,MATCH(Personnel!I13,Processing!$N$18:$N$23,0),1) -> 33 | Q13: =INDEX(Processing!$O$18:$P$23,MATCH(Personnel!I13,Processing!$N$18:$N$23,0),2) -> 0.6875 | R13: =IF(Q13>=100%,CHOOSE(SUM(Q13>=100%,Q13>130%),3%,5%),0%) -> 0
I15: Lucas | K15: =INDEX(Processing!$W$38:$W$48,MATCH(Personnel!I15,Processing!$S$38:$S$48,0),1) -> 24200 | M15: =AVERAGE(KPI!$D$4:$D$39) -> 4 | O15: =INDEX(Processing!$O$18:$P$23,MATCH(Personnel!I15,Processing!$N$18:$N$23,0),1) -> 37 | Q15: =INDEX(Processing!$O$18:$P$23,MATCH(Personnel!I15,Processing!$N$18:$N$23,0),2) -> 0.77083333 | R15: =IF(Q15>=100%,CHOOSE(SUM(Q15>=100%,Q15>130%),3%,5%),0%) -> 0
I17: Sofia | K17: =INDEX(Processing!$W$38:$W$48,MATCH(Personnel!I17,Processing!$S$38:$S$48,0),1) -> 24200 | M17: =AVERAGE(KPI!$D$4:$D$39) -> 4 | O17: =INDEX(Processing!$O$18:$P$23,MATCH(Personnel!I17,Processing!$N$18:$N$23,0),1) -> 37 | Q17: =INDEX(Processing!$O$18:$P$23,MATCH(Personnel!I17,Processing!$N$18:$N$23,0),2) -> 0.77083333 | R17: =IF(Q17>=100%,CHOOSE(SUM(Q17>=100%,Q17>130%),3%,5%),0%) -> 0
I21: =UPPER(Processing!M9) -> MANAGERS | K21: SALARY | M21: SALES PLAN | O21: DONE | Q21: KPI % | R21: PRIZE
I23: Isabella | K23: =INDEX(Processing!$W$38:$W$48,MATCH(Personnel!I23,Processing!$S$38:$S$48,0),1) -> 31900 | M23: =AVERAGE(KPI!$C$4:$C$39) -> 15000 | O23: =INDEX(Processing!$L$18:$M$22,MATCH(Personnel!I23,Processing!$K$18:$K$22,0),1) -> 240940 | Q23: =INDEX(Processing!$L$18:$M$22,MATCH(Personnel!I23,Processing!$K$18:$K$22,0),2) -> 1.3385556 | R23: =IF(Q23>=100%,CHOOSE(SUM(Q23>=100%,Q23>130%),3%,5%),0%) -> 0.05
I25: Joseph | K25: =INDEX(Processing!$W$38:$W$48,MATCH(Personnel!I25,Processing!$S$38:$S$48,0),1) -> 31900 | M25: =AVERAGE(KPI!$C$4:$C$39) -> 15000 | O25: =INDEX(Processing!$L$18:$M$22,MATCH(Personnel!I25,Processing!$K$18:$K$22,0),1) -> 254780 | Q25: =INDEX(Processing!$L$18:$M$22,MATCH(Personnel!I25,Processing!$K$18:$K$22,0),2) -> 1.4154444 | R25: =IF(Q25>=100%,CHOOSE(SUM(Q25>=100%,Q25>130%),3%,5%),0%) -> 0.05
I27: Liam | K27: =INDEX(Processing!$W$38:$W$48,MATCH(Personnel!I27,Processing!$S$38:$S$48,0),1) -> 31900 | M27: =AVERAGE(KPI!$C$4:$C$39) -> 15000 | O27: =INDEX(Processing!$L$18:$M$22,MATCH(Personnel!I27,Processing!$K$18:$K$22,0),1) -> 299320 | Q27: =INDEX(Processing!$L$18:$M$22,MATCH(Personnel!I27,Processing!$K$18:$K$22,0),2) -> 1.6628889 | R27: =IF(Q27>=100%,CHOOSE(SUM(Q27>=100%,Q27>130%),3%,5%),0%) -> 0.05
I29: Charlotte | K29: =INDEX(Processing!$W$38:$W$48,MATCH(Personnel!I29,Processing!$S$38:$S$48,0),1) -> 31900 | M29: =AVERAGE(KPI!$C$4:$C$39) -> 15000 | O29: =INDEX(Processing!$L$18:$M$22,MATCH(Personnel!I29,Processing!$K$18:$K$22,0),1) -> 349080 | Q29: =INDEX(Processing!$L$18:$M$22,MATCH(Personnel!I29,Processing!$K$18:$K$22,0),2) -> 1.9393333 | R29: =IF(Q29>=100%,CHOOSE(SUM(Q29>=100%,Q29>130%),3%,5%),0%) -> 0.05
I31: Jacob | K31: =INDEX(Processing!$W$38:$W$48,MATCH(Personnel!I31,Processing!$S$38:$S$48,0),1) -> 31900 | M31: =AVERAGE(KPI!$C$4:$C$39) -> 15000 | O31: =INDEX(Processing!$L$18:$M$22,MATCH(Personnel!I31,Processing!$K$18:$K$22,0),1) -> 192980 | Q31: =INDEX(Processing!$L$18:$M$22,MATCH(Personnel!I31,Processing!$K$18:$K$22,0),2) -> 1.0721111 | R31: =IF(Q31>=100%,CHOOSE(SUM(Q31>=100%,Q31>130%),3%,5%),0%) -> 0.03

Sheet Processing
D1: Amount | I1: Services | K1: Indent | L1: =MAX(J2:J6)*0.05 -> 3.6 | O1: Channel | S1: Lable | W1: ToDay | Z1: Current Month | AA1: Time | AC1: 1 | AD1: =K18 -> Isabella | AE1: =M18 -> 1.3385556 | AF1: {=INDEX($AD$1:$AD$5,SMALL(IF($AE$1:$AE$5=AG1,ROW($AE$1:$AE$5)),COUNTIF($AG$1:AG1,AG1)))} -> Charlotte | AG1: =LARGE($AE$1:$AE$5,AC1) -> 1.9393333 | AI1: 1 | AJ1: =N18 -> Jack | AK1: =P18 -> 1.7916667 | AL1: {=INDEX($AJ$1:$AJ$6,SMALL(IF($AK$1:$AK$6=AM1,ROW($AK$1:$AK$6)),COUNTIF($AM$1:AM1,AM1)))} -> Jack | AM1: =LARGE($AK$1:$AK$6,AI1) -> 1.7916667 | AO1: 1 | AP1: =B38 -> Dismantling the balcony block | AQ1: =C38 -> 1 | AR1: {=INDEX($AP$1:$AP$26,SMALL(IF($AQ$1:$AQ$26=AS1,ROW($AQ$1:$AQ$26)),COUNTIF($AS$1:AS1,AS1)))} -> Wallpapering ceilings | AS1: =LARGE($AQ$1:$AQ$26,AO1) -> 72 | AT1: =$AU$1 -> 2.16 | AU1: =MAX(AS1:AS26)*0.03 -> 2.16
A2: Cash | B2: =D2/D4 -> 0.3665844 | C2: =1-B2 -> 0.6334156 | D2: =GETPIVOTDATA("Sum of Cash",Control!$S$19) -> 490160 | I2: =AR1 -> Wallpapering ceilings | J2: =AS1 -> 72 | K2: =$L$1 -> 3.6 | L2: =LEFT(I2,18)&"…" -> Wallpapering ceili… | O2: =Data!M8 -> Facebook | P2: =Q2/$Q$7 -> 0.13390313 | Q2: =IFERROR(GETPIVOTDATA(""&$O$1,Control!$M$19,""&$O$1,""&O2),0) -> 47 | S2: =O2&T1&O3&T1&O4&CHAR(10)&CHAR(10)&O5&T1&O6 -> Facebook Reddit Instagram YouTube WhatsApp | W2: =TODAY() -> 46283 | Y2: 1 | Z2: =DATE(YEAR($W$2),MONTH($W$2),Y2) -> 46266 | AA2: 0.041666667 | AC2: 2 | AD2: =K19 -> Joseph | AE2: =M19 -> 1.4154444 | AF2: {=INDEX($AD$1:$AD$5,SMALL(IF($AE$1:$AE$5=AG2,ROW($AE$1:$AE$5)),COUNTIF($AG$1:AG2,AG2)))} -> Liam | AG2: =LARGE($AE$1:$AE$5,AC2) -> 1.6628889 | AI2: 2 | AJ2: =N19 -> William | AK2: =P19 -> 1.25 | AL2: {=INDEX($AJ$1:$AJ$6,SMALL(IF($AK$1:$AK$6=AM2,ROW($AK$1:$AK$6)),COUNTIF($AM$1:AM2,AM2)))} -> James | AM2: =LARGE($AK$1:$AK$6,AI2) -> 1.5208333 | AO2: 2 | AP2: =B39 -> Laying parquet boards with glue | AQ2: =C39 -> 49 | AR2: {=INDEX($AP$1:$AP$26,SMALL(IF($AQ$1:$AQ$26=AS2,ROW($AQ$1:$AQ$26)),COUNTIF($AS$1:AS2,AS2)))} -> Laying parquet boards with glue | AS2: =LARGE($AQ$1:$AQ$26,AO2) -> 49 | AT2: =$AU$1 -> 2.16
A3: Card | B3: =D3/D4 -> 0.6334156 | C3: =1-B3 -> 0.3665844 | D3: =GETPIVOTDATA("Sum of Card",Control!$S$19) -> 846940 | I3: =AR2 -> Laying parquet boards with glue | J3: =AS2 -> 49 | K3: =$L$1 -> 3.6 | L3: =LEFT(I3,18)&"…" -> Laying parquet boa… | O3: =Data!M9 -> Reddit | P3: =Q3/$Q$7 -> 0.22507123 | Q3: =IFERROR(GETPIVOTDATA(""&$O$1,Control!$M$19,""&$O$1,""&O3),0) -> 79 | W3: {=INDEX(W6:W17,MONTH(W2))&X1&DAY(W2)&X1&YEAR(W2)} -> September 18 2026 | Y3: 2 | Z3: =DATE(YEAR($W$2),MONTH($W$2),Y3) -> 46267 | AA3: 0.083333333 | AC3: 3 | AD3: =K20 -> Liam | AE3: =M20 -> 1.6628889 | AF3: {=INDEX($AD$1:$AD$5,SMALL(IF($AE$1:$AE$5=AG3,ROW($AE$1:$AE$5)),COUNTIF($AG$1:AG3,AG3)))} -> Joseph | AG3: =LARGE($AE$1:$AE$5,AC3) -> 1.4154444 | AI3: 3 | AJ3: =N20 -> James | AK3: =P20 -> 1.5208333 | AL3: {=INDEX($AJ$1:$AJ$6,SMALL(IF($AK$1:$AK$6=AM3,ROW($AK$1:$AK$6)),COUNTIF($AM$1:AM3,AM3)))} -> William | AM3: =LARGE($AK$1:$AK$6,AI3) -> 1.25 | AO3: 3 | AP3: =B40 -> Laying quartz vinyl tiles on a substrate | AQ3: =C40 -> 1 | AR3: {=INDEX($AP$1:$AP$26,SMALL(IF($AQ$1:$AQ$26=AS3,ROW($AQ$1:$AQ$26)),COUNTIF($AS$1:AS3,AS3)))} -> Installation of slatted ceilings | AS3: =LARGE($AQ$1:$AQ$26,AO3) -> 49 | AT3: =$AU$1 -> 2.16
B4: Status | D4: =SUM(D2:D3) -> 1337100 | I4: =AR3 -> Installation of slatted ceilings | J4: =AS3 -> 49 | K4: =$L$1 -> 3.6 | L4: =LEFT(I4,18)&"…" -> Installation of sl… | O4: =Data!M10 -> Instagram | P4: =Q4/$Q$7 -> 0.27920228 | Q4: =IFERROR(GETPIVOTDATA(""&$O$1,Control!$M$19,""&$O$1,""&O4),0) -> 98 | W4: {=INDEX(X6:X12,WEEKDAY(W2))} -> Friday | Y4: 3 | Z4: =DATE(YEAR($W$2),MONTH($W$2),Y4) -> 46268 | AA4: 0.125 | AC4: 4 | AD4: =K21 -> Charlotte | AE4: =M21 -> 1.9393333 | AF4: {=INDEX($AD$1:$AD$5,SMALL(IF($AE$1:$AE$5=AG4,ROW($AE$1:$AE$5)),COUNTIF($AG$1:AG4,AG4)))} -> Isabella | AG4: =LARGE($AE$1:$AE$5,AC4) -> 1.3385556 | AI4: 4 | AJ4: =N21 -> Oliver | AK4: =P21 -> 0.6875 | AL4: {=INDEX($AJ$1:$AJ$6,SMALL(IF($AK$1:$AK$6=AM4,ROW($AK$1:$AK$6)),COUNTIF($AM$1:AM4,AM4)))} -> Lucas | AM4: =LARGE($AK$1:$AK$6,AI4) -> 0.77083333 | AO4: 4 | AP4: =B41 -> Laying parquet boards on a substrate | AQ4: =C41 -> 1 | AR4: {=INDEX($AP$1:$AP$26,SMALL(IF($AQ$1:$AQ$26=AS4,ROW($AQ$1:$AQ$26)),COUNTIF($AS$1:AS4,AS4)))} -> Cutting and installation of additional corners | AS4: =LARGE($AQ$1:$AQ$26,AO4) -> 27 | AT4: =$AU$1 -> 2.16
B5: Completed | C5: =IFERROR(GETPIVOTDATA("Status",Control!$P$19,""&$B$4,""&B5),0) -> 326 | I5: =AR4 -> Cutting and installation of additional corners | J5: =AS4 -> 27 | K5: =$L$1 -> 3.6 | L5: =LEFT(I5,18)&"…" -> Cutting and instal… | O5: =Data!M11 -> YouTube | P5: =Q5/$Q$7 -> 0.24216524 | Q5: =IFERROR(GETPIVOTDATA(""&$O$1,Control!$M$19,""&$O$1,""&O5),0) -> 85 | Y5: 4 | Z5: =DATE(YEAR($W$2),MONTH($W$2),Y5) -> 46269 | AA5: 0.16666667 | AC5: 5 | AD5: =K22 -> Jacob | AE5: =M22 -> 1.0721111 | AF5: {=INDEX($AD$1:$AD$5,SMALL(IF($AE$1:$AE$5=AG5,ROW($AE$1:$AE$5)),COUNTIF($AG$1:AG5,AG5)))} -> Jacob | AG5: =LARGE($AE$1:$AE$5,AC5) -> 1.0721111 | AI5: 5 | AJ5: =N22 -> Lucas | AK5: =P22 -> 0.77083333 | AL5: {=INDEX($AJ$1:$AJ$6,SMALL(IF($AK$1:$AK$6=AM5,ROW($AK$1:$AK$6)),COUNTIF($AM$1:AM5,AM5)))} -> Sofia | AM5: =LARGE($AK$1:$AK$6,AI5) -> 0.77083333 | AO5: 5 | AP5: =B42 -> Laying solid boards | AQ5: =C42 -> 25 | AR5: {=INDEX($AP$1:$AP$26,SMALL(IF($AQ$1:$AQ$26=AS5,ROW($AQ$1:$AQ$26)),COUNTIF($AS$1:AS5,AS5)))} -> Laying linoleum with glue | AS5: =LARGE($AQ$1:$AQ$26,AO5) -> 26 | AT5: =$AU$1 -> 2.16
B6: Canceled | C6: =IFERROR(GETPIVOTDATA("Status",Control!$P$19,""&$B$4,""&B6),0) -> 18 | I6: =AR5 -> Laying linoleum with glue | J6: =AS5 -> 26 | K6: =$L$1 -> 3.6 | L6: =LEFT(I6,18)&"…" -> Laying linoleum wi… | O6: =Data!M12 -> WhatsApp | P6: =Q6/$Q$7 -> 0.11965812 | Q6: =IFERROR(GETPIVOTDATA(""&$O$1,Control!$M$19,""&$O$1,""&O6),0) -> 42 | W6: January | X6: Sunday | Y6: 5 | Z6: =DATE(YEAR($W$2),MONTH($W$2),Y6) -> 46270 | AA6: 0.20833333 | AB6: Managers Top | AI6: 6 | AJ6: =N23 -> Sofia | AK6: =P23 -> 0.77083333 | AL6: {=INDEX($AJ$1:$AJ$6,SMALL(IF($AK$1:$AK$6=AM6,ROW($AK$1:$AK$6)),COUNTIF($AM$1:AM6,AM6)))} -> Oliver | AM6: =LARGE($AK$1:$AK$6,AI6) -> 0.6875 | AO6: 6 | AP6: =B43 -> Installation of ceiling plinth | AQ6: =C43 -> 3 | AR6: {=INDEX($AP$1:$AP$26,SMALL(IF($AQ$1:$AQ$26=AS6,ROW($AQ$1:$AQ$26)),COUNTIF($AS$1:AS6,AS6)))} -> Laying solid boards | AS6: =LARGE($AQ$1:$AQ$26,AO6) -> 25 | AT6: =$AU$1 -> 2.16
B7: Running | C7: =IFERROR(GETPIVOTDATA("Status",Control!$P$19,""&$B$4,""&B7),0) -> 7 | I7: Total | J7: =SUM(J2:J6) -> 223 | Q7: =SUM(Q2:Q6) -> 351 | W7: February | X7: Monday | Y7: 6 | Z7: =DATE(YEAR($W$2),MONTH($W$2),Y7) -> 46271 | AA7: 0.25 | AH7: Masters Top | AO7: 7 | AP7: =B44 -> Cutting and installation of additional corners | AQ7: =C44 -> 27 | AR7: {=INDEX($AP$1:$AP$26,SMALL(IF($AQ$1:$AQ$26=AS7,ROW($AQ$1:$AQ$26)),COUNTIF($AS$1:AS7,AS7)))} -> Installation of PVC skirting boards | AS7: =LARGE($AQ$1:$AQ$26,AO7) -> 24 | AT7: =$AU$1 -> 2.16
L8: KPI | N8: 0.1 | O8: 0.03 | R8: Personnel | W8: March | X8: Tuesday | Y8: 7 | Z8: =DATE(YEAR($W$2),MONTH($W$2),Y8) -> 46272 | AA8: 0.29166667 | AO8: 8 | AP8: =B45 -> Dismantling the balcony block | AQ8: =C45 -> 1 | AR8: {=INDEX($AP$1:$AP$26,SMALL(IF($AQ$1:$AQ$26=AS8,ROW($AQ$1:$AQ$26)),COUNTIF($AS$1:AS8,AS8)))} -> Dismantling the window block | AS8: =LARGE($AQ$1:$AQ$26,AO8) -> 22 | AT8: =$AU$1 -> 2.16
E9: =MAX(D11:D22)*0.05 -> 7250 | H9: =MAX(D11:D22)*0.5 -> 72500 | K9: Indent Left | L9: =T10&"s" -> Masters | M9: =T11&"s" -> Managers | N9: Indent Center | O9: Indents | P9: Indent Right | R9: =L9 -> Masters | S9: =M9 -> Managers | T9: Job Titles | U9: State | W9: April | X9: Wednesday | Y9: 8 | Z9: =DATE(YEAR($W$2),MONTH($W$2),Y9) -> 46273 | AA9: 0.33333333 | AO9: 9 | AP9: =B46 -> Removing the front door | AQ9: =C46 -> 1 | AR9: {=INDEX($AP$1:$AP$26,SMALL(IF($AQ$1:$AQ$26=AS9,ROW($AQ$1:$AQ$26)),COUNTIF($AS$1:AS9,AS9)))} -> Laying quartz vinyl tiles with glue | AS9: =LARGE($AQ$1:$AQ$26,AO9) -> 22 | AT9: =$AU$1 -> 2.16
B10: Number | C10: Month | D10: Total | E10: Indent | F10: Selected M | G10: Selected I | H10: Indent2 | I10: Cost | J10: =SUM(K10:O10) -> 0.87010542 | K10: =0.5-L10 -> 0.24010542 | L10: =AG1/$L$15/2 -> 0.25989458 | M10: =AM1/$L$15/2 -> 0.24010542 | N10: =$N$8 -> 0.1 | O10: =$O$8 -> 0.03 | P10: {=MAX($J$10:$J$14-J10)} -> 0 | R10: =Data!E4 -> Jack | S10: =Data!H4 -> Isabella | T10: =Data!K4 -> Master | U10: fired | W10: May | X10: Thursday | Y10: 9 | Z10: =DATE(YEAR($W$2),MONTH($W$2),Y10) -> 46274 | AA10: 0.375 | AO10: 10 | AP10: =B47 -> Removing the shower tray | AQ10: =C47 -> 1 | AR10: {=INDEX($AP$1:$AP$26,SMALL(IF($AQ$1:$AQ$26=AS10,ROW($AQ$1:$AQ$26)),COUNTIF($AS$1:AS10,AS10)))} -> Threshold installation | AS10: =LARGE($AQ$1:$AQ$26,AO10) -> 21 | AT10: =$AU$1 -> 2.16
B11: 1 | C11: JAN | D11: =GETPIVOTDATA(""&$D$10,Control!$A$3,""&$C$10,""&C11) -> 77600 | E11: =$E$9 -> 7250 | F11: =IFERROR(GETPIVOTDATA(""&$D$10,Control!$A$19,""&$C$10,""&C11),0) -> 77600 | G11: =IF(F11>0,E11,0) -> 7250 | H11: =D11+$H$9 -> 150100 | I11: =GETPIVOTDATA(""&$I$10,Control!$A$3,""&$C$10,""&C11) -> 75137 | J11: =SUM(K11:O11) -> 0.83381042 | K11: =0.5-L11 -> 0.27715239 | L11: =AG2/$L$15/2 -> 0.22284761 | M11: =AM2/$L$15/2 -> 0.20381042 | N11: =$N$8 -> 0.1 | O11: =$O$8 -> 0.03 | P11: {=MAX($J$10:$J$14-J11)} -> 0.036295006 | R11: =Data!E5 -> William | S11: =Data!H5 -> Joseph | T11: =Data!K5 -> Manager | W11: June | X11: Friday | Y11: 10 | Z11: =DATE(YEAR($W$2),MONTH($W$2),Y11) -> 46275 | AA11: 0.41666667 | AO11: 11 | AP11: =B48 -> Removing the sink | AQ11: =C48 -> 0 | AR11: {=INDEX($AP$1:$AP$26,SMALL(IF($AQ$1:$AQ$26=AS11,ROW($AQ$1:$AQ$26)),COUNTIF($AS$1:AS11,AS11)))} -> Installation of ceiling plinth | AS11: =LARGE($AQ$1:$AQ$26,AO11) -> 3 | AT11: =$AU$1 -> 2.16
B12: 2 | C12: FEB | D12: =GETPIVOTDATA(""&$D$10,Control!$A$3,""&$C$10,""&C12) -> 95100 | E12: =$E$9 -> 7250 | F12: =IFERROR(GETPIVOTDATA(""&$D$10,Control!$A$19,""&$C$10,""&C12),0) -> 95100 | G12: =IF(F12>0,E12,0) -> 7250 | H12: =D12+$H$9 -> 167600 | I12: =GETPIVOTDATA(""&$I$10,Control!$A$3,""&$C$10,""&C12) -> 102667 | J12: =SUM(K12:O12) -> 0.79751541 | K12: =0.5-L12 -> 0.31031299 | L12: =AG3/$L$15/2 -> 0.18968701 | M12: =AM3/$L$15/2 -> 0.16751541 | N12: =$N$8 -> 0.1 | O12: =$O$8 -> 0.03 | P12: {=MAX($J$10:$J$14-J12)} -> 0.072590012 | R12: =Data!E6 -> James | S12: =Data!H6 -> Liam | W12: July | X12: Saturday | Y12: 11 | Z12: =DATE(YEAR($W$2),MONTH($W$2),Y12) -> 46276 | AA12: 0.45833333 | AO12: 12 | AP12: =B49 -> Dismantling the window block | AQ12: =C49 -> 22 | AR12: {=INDEX($AP$1:$AP$26,SMALL(IF($AQ$1:$AQ$26=AS12,ROW($AQ$1:$AQ$26)),COUNTIF($AS$1:AS12,AS12)))} -> Application of decorative plaster | AS12: =LARGE($AQ$1:$AQ$26,AO12) -> 2 | AT12: =$AU$1 -> 2.16
B13: 3 | C13: MAR | D13: =GETPIVOTDATA(""&$D$10,Control!$A$3,""&$C$10,""&C13) -> 109600 | E13: =$E$9 -> 7250 | F13: =IFERROR(GETPIVOTDATA(""&$D$10,Control!$A$19,""&$C$10,""&C13),0) -> 109600 | G13: =IF(F13>0,E13,0) -> 7250 | H13: =D13+$H$9 -> 182100 | I13: =GETPIVOTDATA(""&$I$10,Control!$A$3,""&$C$10,""&C13) -> 111307 | J13: =SUM(K13:O13) -> 0.73330117 | K13: =0.5-L13 -> 0.32061705 | L13: =AG4/$L$15/2 -> 0.17938295 | M13: =AM4/$L$15/2 -> 0.10330117 | N13: =$N$8 -> 0.1 | O13: =$O$8 -> 0.03 | P13: {=MAX($J$10:$J$14-J13)} -> 0.13680425 | R13: =Data!E7 -> Oliver | S13: =Data!H7 -> Charlotte | W13: August | Y13: 12 | Z13: =DATE(YEAR($W$2),MONTH($W$2),Y13) -> 46277 | AA13: 0.5 | AO13: 13 | AP13: =B50 -> Laying ceramic tiles, porcelain tiles on the floor with grout | AQ13: =C50 -> 0 | AR13: {=INDEX($AP$1:$AP$26,SMALL(IF($AQ$1:$AQ$26=AS13,ROW($AQ$1:$AQ$26)),COUNTIF($AS$1:AS13,AS13)))} -> Dismantling the balcony block | AS13: =LARGE($AQ$1:$AQ$26,AO13) -> 1 | AT13: =$AU$1 -> 2.16
B14: 4 | C14: APR | D14: =GETPIVOTDATA(""&$D$10,Control!$A$3,""&$C$10,""&C14) -> 117100 | E14: =$E$9 -> 7250 | F14: =IFERROR(GETPIVOTDATA(""&$D$10,Control!$A$19,""&$C$10,""&C14),0) -> 117100 | G14: =IF(F14>0,E14,0) -> 7250 | H14: =D14+$H$9 -> 189600 | I14: =GETPIVOTDATA(""&$I$10,Control!$A$3,""&$C$10,""&C14) -> 110749 | J14: =SUM(K14:O14) -> 0.73330117 | K14: =0.5-L14 -> 0.35632389 | L14: =AG5/$L$15/2 -> 0.14367611 | M14: =AM5/$L$15/2 -> 0.10330117 | N14: =$N$8 -> 0.1 | O14: =$O$8 -> 0.03 | P14: {=MAX($J$10:$J$14-J14)} -> 0.13680425 | R14: =Data!E8 -> Lucas | S14: =Data!H8 -> Jacob | W14: September | Y14: 13 | Z14: =DATE(YEAR($W$2),MONTH($W$2),Y14) -> 46278 | AA14: 0.54166667 | AO14: 14 | AP14: =B51 -> Application of decorative plaster | AQ14: =C51 -> 2 | AR14: {=INDEX($AP$1:$AP$26,SMALL(IF($AQ$1:$AQ$26=AS14,ROW($AQ$1:$AQ$26)),COUNTIF($AS$1:AS14,AS14)))} -> Laying quartz vinyl tiles on a substrate | AS14: =LARGE($AQ$1:$AQ$26,AO14) -> 1 | AT14: =$AU$1 -> 2.16
B15: 5 | C15: MAY | D15: =GETPIVOTDATA(""&$D$10,Control!$A$3,""&$C$10,""&C15) -> 109400 | E15: =$E$9 -> 7250 | F15: =IFERROR(GETPIVOTDATA(""&$D$10,Control!$A$19,""&$C$10,""&C15),0) -> 109400 | G15: =IF(F15>0,E15,0) -> 7250 | H15: =D15+$H$9 -> 181900 | I15: =GETPIVOTDATA(""&$I$10,Control!$A$3,""&$C$10,""&C15) -> 99947 | L15: =MAX(AG1:AG5)+MAX(AM1:AM6) -> 3.731 | R15: =Data!E9 -> Sofia | W15: October | Y15: 14 | Z15: =DATE(YEAR($W$2),MONTH($W$2),Y15) -> 46279 | AA15: 0.58333333 | AO15: 15 | AP15: =B52 -> Wallpapering | AQ15: =C52 -> 1 | AR15: {=INDEX($AP$1:$AP$26,SMALL(IF($AQ$1:$AQ$26=AS15,ROW($AQ$1:$AQ$26)),COUNTIF($AS$1:AS15,AS15)))} -> Laying parquet boards on a substrate | AS15: =LARGE($AQ$1:$AQ$26,AO15) -> 1 | AT15: =$AU$1 -> 2.16
B16: 6 | C16: JUN | D16: =GETPIVOTDATA(""&$D$10,Control!$A$3,""&$C$10,""&C16) -> 95600 | E16: =$E$9 -> 7250 | F16: =IFERROR(GETPIVOTDATA(""&$D$10,Control!$A$19,""&$C$10,""&C16),0) -> 95600 | G16: =IF(F16>0,E16,0) -> 7250 | H16: =D16+$H$9 -> 168100 | I16: =GETPIVOTDATA(""&$I$10,Control!$A$3,""&$C$10,""&C16) -> 98003 | W16: November | Y16: 15 | Z16: =DATE(YEAR($W$2),MONTH($W$2),Y16) -> 46280 | AA16: 0.625 | AO16: 16 | AP16: =B53 -> Laying plywood in 1 layer | AQ16: =C53 -> 1 | AR16: {=INDEX($AP$1:$AP$26,SMALL(IF($AQ$1:$AQ$26=AS16,ROW($AQ$1:$AQ$26)),COUNTIF($AS$1:AS16,AS16)))} -> Dismantling the balcony block | AS16: =LARGE($AQ$1:$AQ$26,AO16) -> 1 | AT16: =$AU$1 -> 2.16
B17: 7 | C17: JUL | D17: =GETPIVOTDATA(""&$D$10,Control!$A$3,""&$C$10,""&C17) -> 89700 | E17: =$E$9 -> 7250 | F17: =IFERROR(GETPIVOTDATA(""&$D$10,Control!$A$19,""&$C$10,""&C17),0) -> 89700 | G17: =IF(F17>0,E17,0) -> 7250 | H17: =D17+$H$9 -> 162200 | I17: =GETPIVOTDATA(""&$I$10,Control!$A$3,""&$C$10,""&C17) -> 98707 | K17: =T11 -> Manager | L17: Total | M17: KPI | N17: =T10 -> Master | O17: Client rating | P17: KPI | Q17: Order | R17: Payment Method | W17: December | Y17: 16 | Z17: =DATE(YEAR($W$2),MONTH($W$2),Y17) -> 46281 | AA17: 0.66666667 | AO17: 17 | AP17: =B54 -> Laying linoleum with glue | AQ17: =C54 -> 26 | AR17: {=INDEX($AP$1:$AP$26,SMALL(IF($AQ$1:$AQ$26=AS17,ROW($AQ$1:$AQ$26)),COUNTIF($AS$1:AS17,AS17)))} -> Removing the front door | AS17: =LARGE($AQ$1:$AQ$26,AO17) -> 1 | AT17: =$AU$1 -> 2.16
B18: 8 | C18: AUG | D18: =GETPIVOTDATA(""&$D$10,Control!$A$3,""&$C$10,""&C18) -> 102600 | E18: =$E$9 -> 7250 | F18: =IFERROR(GETPIVOTDATA(""&$D$10,Control!$A$19,""&$C$10,""&C18),0) -> 102600 | G18: =IF(F18>0,E18,0) -> 7250 | H18: =D18+$H$9 -> 175100 | I18: =GETPIVOTDATA(""&$I$10,Control!$A$3,""&$C$10,""&C18) -> 111153 | K18: =S10 -> Isabella | L18: =IFERROR(GETPIVOTDATA(""&$L$17,Control!$G$19,""&$K$17,""&K18),0) -> 240940 | M18: =L18/$L$31 -> 1.3385556 | N18: =R10 -> Jack | O18: =IFERROR(GETPIVOTDATA(""&$O$17,Control!$J$19,""&$N$17,""&N18),0) -> 86 | P18: =O18/$N$31 -> 1.7916667 | Q18: Get Price | R18: =Data!M4 -> Cash Money | Y18: 17 | Z18: =DATE(YEAR($W$2),MONTH($W$2),Y18) -> 46282 | AA18: 0.70833333 | AO18: 18 | AP18: =B55 -> Removing the shower cabin | AQ18: =C55 -> 1 | AR18: {=INDEX($AP$1:$AP$26,SMALL(IF($AQ$1:$AQ$26=AS18,ROW($AQ$1:$AQ$26)),COUNTIF($AS$1:AS18,AS18)))} -> Removing the shower tray | AS18: =LARGE($AQ$1:$AQ$26,AO18) -> 1 | AT18: =$AU$1 -> 2.16
B19: 9 | C19: SEP | D19: =GETPIVOTDATA(""&$D$10,Control!$A$3,""&$C$10,""&C19) -> 124500 | E19: =$E$9 -> 7250 | F19: =IFERROR(GETPIVOTDATA(""&$D$10,Control!$A$19,""&$C$10,""&C19),0) -> 124500 | G19: =IF(F19>0,E19,0) -> 7250 | H19: =D19+$H$9 -> 197000 | I19: =GETPIVOTDATA(""&$I$10,Control!$A$3,""&$C$10,""&C19) -> 89309 | K19: =S11 -> Joseph | L19: =IFERROR(GETPIVOTDATA(""&$L$17,Control!$G$19,""&$K$17,""&K19),0) -> 254780 | M19: =L19/$L$31 -> 1.4154444 | N19: =R11 -> William | O19: =IFERROR(GETPIVOTDATA(""&$O$17,Control!$J$19,""&$N$17,""&N19),0) -> 60 | P19: =O19/$N$31 -> 1.25 | Q19: =INDEX(Data!$C$4:$C$30,MATCH(ORDER!$D$6,Data!$B$4:$B$30,0)) -> 0 | R19: =Data!M5 -> Credit Cards | Y19: 18 | Z19: =DATE(YEAR($W$2),MONTH($W$2),Y19) -> 46283 | AA19: 0.75 | AO19: 19 | AP19: =B56 -> Installation of thermal vapor barrier of the ceiling | AQ19: =C56 -> 0 | AR19: {=INDEX($AP$1:$AP$26,SMALL(IF($AQ$1:$AQ$26=AS19,ROW($AQ$1:$AQ$26)),COUNTIF($AS$1:AS19,AS19)))} -> Wallpapering | AS19: =LARGE($AQ$1:$AQ$26,AO19) -> 1 | AT19: =$AU$1 -> 2.16
B20: 10 | C20: OCT | D20: =GETPIVOTDATA(""&$D$10,Control!$A$3,""&$C$10,""&C20) -> 137200 | E20: =$E$9 -> 7250 | F20: =IFERROR(GETPIVOTDATA(""&$D$10,Control!$A$19,""&$C$10,""&C20),0) -> 137200 | G20: =IF(F20>0,E20,0) -> 7250 | H20: =D20+$H$9 -> 209700 | I20: =GETPIVOTDATA(""&$I$10,Control!$A$3,""&$C$10,""&C20) -> 93153 | K20: =S12 -> Liam | L20: =IFERROR(GETPIVOTDATA(""&$L$17,Control!$G$19,""&$K$17,""&K20),0) -> 299320 | M20: =L20/$L$31 -> 1.6628889 | N20: =R12 -> James | O20: =IFERROR(GETPIVOTDATA(""&$O$17,Control!$J$19,""&$N$17,""&N20),0) -> 73 | P20: =O20/$N$31 -> 1.5208333 | Q20: =IF(ORDER!F6>0,ORDER!F6*Processing!Q19,"Error: Enetr Count") -> Error: Enetr Count | Y20: 19 | Z20: =DATE(YEAR($W$2),MONTH($W$2),Y20) -> 46284 | AA20: 0.79166667 | AO20: 20 | AP20: =B57 -> Laying quartz vinyl tiles with glue | AQ20: =C57 -> 22 | AR20: {=INDEX($AP$1:$AP$26,SMALL(IF($AQ$1:$AQ$26=AS20,ROW($AQ$1:$AQ$26)),COUNTIF($AS$1:AS20,AS20)))} -> Laying plywood in 1 layer | AS20: =LARGE($AQ$1:$AQ$26,AO20) -> 1 | AT20: =$AU$1 -> 2.16
B21: 11 | C21: NOV | D21: =GETPIVOTDATA(""&$D$10,Control!$A$3,""&$C$10,""&C21) -> 145000 | E21: =$E$9 -> 7250 | F21: =IFERROR(GETPIVOTDATA(""&$D$10,Control!$A$19,""&$C$10,""&C21),0) -> 145000 | G21: =IF(F21>0,E21,0) -> 7250 | H21: =D21+$H$9 -> 217500 | I21: =GETPIVOTDATA(""&$I$10,Control!$A$3,""&$C$10,""&C21) -> 83973 | K21: =S13 -> Charlotte | L21: =IFERROR(GETPIVOTDATA(""&$L$17,Control!$G$19,""&$K$17,""&K21),0) -> 349080 | M21: =L21/$L$31 -> 1.9393333 | N21: =R13 -> Oliver | O21: =IFERROR(GETPIVOTDATA(""&$O$17,Control!$J$19,""&$N$17,""&N21),0) -> 33 | P21: =O21/$N$31 -> 0.6875 | Y21: 20 | Z21: =DATE(YEAR($W$2),MONTH($W$2),Y21) -> 46285 | AA21: 0.83333333 | AO21: 21 | AP21: =B58 -> Threshold installation | AQ21: =C58 -> 21 | AR21: {=INDEX($AP$1:$AP$26,SMALL(IF($AQ$1:$AQ$26=AS21,ROW($AQ$1:$AQ$26)),COUNTIF($AS$1:AS21,AS21)))} -> Removing the shower cabin | AS21: =LARGE($AQ$1:$AQ$26,AO21) -> 1 | AT21: =$AU$1 -> 2.16
B22: 12 | C22: DEC | D22: =GETPIVOTDATA(""&$D$10,Control!$A$3,""&$C$10,""&C22) -> 133700 | E22: =$E$9 -> 7250 | F22: =IFERROR(GETPIVOTDATA(""&$D$10,Control!$A$19,""&$C$10,""&C22),0) -> 133700 | G22: =IF(F22>0,E22,0) -> 7250 | H22: =D22+$H$9 -> 206200 | I22: =GETPIVOTDATA(""&$I$10,Control!$A$3,""&$C$10,""&C22) -> 51384 | K22: =S14 -> Jacob | L22: =IFERROR(GETPIVOTDATA(""&$L$17,Control!$G$19,""&$K$17,""&K22),0) -> 192980 | M22: =L22/$L$31 -> 1.0721111 | N22: =R14 -> Lucas | O22: =IFERROR(GETPIVOTDATA(""&$O$17,Control!$J$19,""&$N$17,""&N22),0) -> 37 | P22: =O22/$N$31 -> 0.77083333 | Y22: 21 | Z22: =DATE(YEAR($W$2),MONTH($W$2),Y22) -> 46286 | AA22: 0.875 | AO22: 22 | AP22: =B59 -> Production and installation of suspended ceilings (matte, glossy) | AQ22: =C59 -> 0 | AR22: {=INDEX($AP$1:$AP$26,SMALL(IF($AQ$1:$AQ$26=AS22,ROW($AQ$1:$AQ$26)),COUNTIF($AS$1:AS22,AS22)))} -> Removing an interior door | AS22: =LARGE($AQ$1:$AQ$26,AO22) -> 1 | AT22: =$AU$1 -> 2.16
N23: =R15 -> Sofia | O23: =IFERROR(GETPIVOTDATA(""&$O$17,Control!$J$19,""&$N$17,""&N23),0) -> 37 | P23: =O23/$N$31 -> 0.77083333 | Y23: 22 | Z23: =DATE(YEAR($W$2),MONTH($W$2),Y23) -> 46287 | AA23: 0.91666667 | AO23: 23 | AP23: =B60 -> Wallpapering ceilings | AQ23: =C60 -> 72 | AR23: {=INDEX($AP$1:$AP$26,SMALL(IF($AQ$1:$AQ$26=AS23,ROW($AQ$1:$AQ$26)),COUNTIF($AS$1:AS23,AS23)))} -> Removing the sink | AS23: =LARGE($AQ$1:$AQ$26,AO23) -> 0 | AT23: =$AU$1 -> 2.16
Y24: 23 | Z24: =DATE(YEAR($W$2),MONTH($W$2),Y24) -> 46288 | AA24: 0.95833333 | AO24: 24 | AP24: =B61 -> Installation of PVC skirting boards | AQ24: =C61 -> 24 | AR24: {=INDEX($AP$1:$AP$26,SMALL(IF($AQ$1:$AQ$26=AS24,ROW($AQ$1:$AQ$26)),COUNTIF($AS$1:AS24,AS24)))} -> Laying ceramic tiles, porcelain tiles on the floor with grout | AS24: =LARGE($AQ$1:$AQ$26,AO24) -> 0 | AT24: =$AU$1 -> 2.16
F25: Map | Y25: 24 | Z25: =DATE(YEAR($W$2),MONTH($W$2),Y25) -> 46289 | AA25: 1 | AO25: 25 | AP25: =B62 -> Installation of slatted ceilings | AQ25: =C62 -> 49 | AR25: {=INDEX($AP$1:$AP$26,SMALL(IF($AQ$1:$AQ$26=AS25,ROW($AQ$1:$AQ$26)),COUNTIF($AS$1:AS25,AS25)))} -> Installation of thermal vapor barrier of the ceiling | AS25: =LARGE($AQ$1:$AQ$26,AO25) -> 0 | AT25: =$AU$1 -> 2.16
F26: City | G26: Done % | H26: Running % | R26: $ | S26: % | Y26: 25 | Z26: =DATE(YEAR($W$2),MONTH($W$2),Y26) -> 46290 | AO26: 26 | AP26: =B63 -> Removing an interior door | AQ26: =C63 -> 1 | AR26: {=INDEX($AP$1:$AP$26,SMALL(IF($AQ$1:$AQ$26=AS26,ROW($AQ$1:$AQ$26)),COUNTIF($AS$1:AS26,AS26)))} -> Production and installation of suspended ceilings (matte, glossy) | AS26: =LARGE($AQ$1:$AQ$26,AO26) -> 0 | AT26: =$AU$1 -> 2.16
F27: =Data!Q4 -> New York | G27: =100-H27 -> 72 | H27: 28 | Q27: Margin | R27: =T28-T29 -> 211611 | S27: =R27/T28 -> 0.15826116 | T27: =1-S27 -> 0.84173884 | U27: Visual | Y27: 26 | Z27: =DATE(YEAR($W$2),MONTH($W$2),Y27) -> 46291
F28: =Data!Q5 -> Miami | G28: =100-H28 -> 100 | H28: 0 | Q28: $ | R28: =GETPIVOTDATA("Sum of Cash",Control!$S$19) -> 490160 | S28: =GETPIVOTDATA("Sum of Card",Control!$S$19) -> 846940 | T28: =GETPIVOTDATA("Sum of Total",Control!$A$19) -> 1337100 | U28: Total cach flow | Y28: 27 | Z28: =DATE(YEAR($W$2),MONTH($W$2),Y28) -> 46292
F29: =Data!Q6 -> Chikago | G29: =100-H29 -> 28 | H29: 72 | T29: =GETPIVOTDATA("Sum of Cost",Control!$A$19) -> 1125489 | U29: Total Cost | Y29: 28 | Z29: =DATE(YEAR($W$2),MONTH($W$2),Y29) -> 46293
F30: =Data!Q7 -> Dallas | G30: =100-H30 -> 10 | H30: 90 | L30: KPI PLAN | N30: KPI PLAN | Y30: 29 | Z30: =DATE(YEAR($W$2),MONTH($W$2),Y30) -> 46294
F31: =Data!Q8 -> New Orleans | G31: =100-H31 -> 75 | H31: 25 | L31: =DSUM(KPI!A3:G39,L32,J32:K68) -> 180000 | N31: =DSUM(KPI!A3:G39,N32,J32:K68) -> 48 | Y31: 30 | Z31: =DATE(YEAR($W$2),MONTH($W$2),Y31) -> 46295
J32: Year | K32: Month | L32: Managers Sales | N32: Masters Order Quantity | P32: Year | Y32: 31 | Z32: =DATE(YEAR($W$2),MONTH($W$2),Y32) -> 46296
J33: =Control!$A$36 -> 2025 | K33: =Control!A42 -> JAN | P33: =Control!A36 -> 2025
J34: =Control!$A$36 -> 2025 | K34: =Control!A43 -> FEB | P34: =Control!A37 -> 0 | Q34: SALARY
J35: =Control!$A$36 -> 2025 | K35: =Control!A44 -> MAR | P35: =Control!A38 -> 0 | T35: 1 | U35: 2 | V35: 3
J36: =Control!$A$36 -> 2025 | K36: =Control!A45 -> APR | T36: =IF(IFERROR(MATCH(T37,$P$33:$P$35,0),0),T35,NA()) -> #N/A | U36: =IF(IFERROR(MATCH(U37,$P$33:$P$35,0),0),U35,NA()) -> #N/A | V36: =IF(IFERROR(MATCH(V37,$P$33:$P$35,0),0),V35,NA()) -> 3
B37: Service | J37: =Control!$A$36 -> 2025 | K37: =Control!A46 -> MAY | Q37: Count Years | R37: Count Month | S37: Employee | T37: 2023 | U37: 2024 | V37: 2025 | W37: Total | X37: =SUM(W38:W48) -> 304700 | Y37: Prize | Z37: Rank | AA37: 1 | AB37: 2 | AC37: 3 | AD37: 4 | AE37: 5 | AF37: 6 | AG37: 7 | AH37: 8 | AI37: 9 | AJ37: 10
B38: =Data!B4 -> Dismantling the balcony block | C38: =IFERROR(GETPIVOTDATA(""&$B$37,Control!$G$41,""&$B$37,""&B38),0) -> 1 | J38: =Control!$A$36 -> 2025 | K38: =Control!A47 -> JUN | Q38: {=SUM(1/COUNTIF(J33:J68,J33:J68))-1} -> 1 | R38: {=SUM(1/COUNTIF(K33:K68,K33:K68))-1} -> 11 | S38: ='Employee Database'!B4 -> Jack | T38: {=IFERROR(INDEX('Employee Database'!$F$4:$H$14,MATCH(Processing!$S38,'Employee Database'!$B$4:$B$14,0),T$36)*$R$38,0)} -> 0 | U38: {=IFERROR(INDEX('Employee Database'!$F$4:$H$14,MATCH(Processing!$S38,'Employee Database'!$B$4:$B$14,0),U$36)*$R$38,0)} -> 0 | V38: {=IFERROR(INDEX('Employee Database'!$F$4:$H$14,MATCH(Processing!$S38,'Employee Database'!$B$4:$B$14,0),V$36)*$R$38,0)} -> 24200 | W38: =SUM(T38:V38) -> 24200 | X38: =INDEX(_xlfn.VSTACK($P$18:$P$23,$M$18:$M$22),MATCH(S38,$S$38:$S$48,0),1) -> #NAME? | Y38: =IF(X38>100%,CHOOSE(SUM(X38>=100%,X38>130%),3%,5%)*W38+W38,W38) -> #NAME? | Z38: =ROUND(COUNTIF($X$38:$X$48,">=100%")/COUNT($X$38:$X$48),1)*10 -> #DIV/0! | AA38: =IF($Z$38<AA37,0,0.5) -> #DIV/0! | AB38: =IF($Z$38<AB37,0,0.5) -> #DIV/0! | AC38: =IF($Z$38<AC37,0,0.5) -> #DIV/0! | AD38: =IF($Z$38<AD37,0,0.5) -> #DIV/0! | AE38: =IF($Z$38<AE37,0,0.5) -> #DIV/0! | AF38: =IF($Z$38<AF37,0,0.5) -> #DIV/0! | AG38: =IF($Z$38<AG37,0,0.5) -> #DIV/0! | AH38: =IF($Z$38<AH37,0,0.5) -> #DIV/0! | ... AJ38: =IF($Z$38<AJ37,0,0.5) -> #DIV/0!
B39: =Data!B5 -> Laying parquet boards with glue | C39: =IFERROR(GETPIVOTDATA(""&$B$37,Control!$G$41,""&$B$37,""&B39),0) -> 49 | J39: =Control!$A$36 -> 2025 | K39: =Control!A48 -> JUL | S39: ='Employee Database'!B5 -> William | T39: {=IFERROR(INDEX('Employee Database'!$F$4:$H$14,MATCH(Processing!$S39,'Employee Database'!$B$4:$B$14,0),T$36)*$R$38,0)} -> 0 | U39: {=IFERROR(INDEX('Employee Database'!$F$4:$H$14,MATCH(Processing!$S39,'Employee Database'!$B$4:$B$14,0),U$36)*$R$38,0)} -> 0 | V39: {=IFERROR(INDEX('Employee Database'!$F$4:$H$14,MATCH(Processing!$S39,'Employee Database'!$B$4:$B$14,0),V$36)*$R$38,0)} -> 24200 | W39: =SUM(T39:V39) -> 24200 | X39: =INDEX(_xlfn.VSTACK($P$18:$P$23,$M$18:$M$22),MATCH(S39,$S$38:$S$48,0),1) -> #NAME? | Y39: =IF(X39>100%,CHOOSE(SUM(X39>=100%,X39>130%),3%,5%)*W39+W39,W39) -> #NAME?
B40: =Data!B6 -> Laying quartz vinyl tiles on a substrate | C40: =IFERROR(GETPIVOTDATA(""&$B$37,Control!$G$41,""&$B$37,""&B40),0) -> 1 | J40: =Control!$A$36 -> 2025 | K40: =Control!A49 -> AUG | S40: ='Employee Database'!B6 -> James | T40: {=IFERROR(INDEX('Employee Database'!$F$4:$H$14,MATCH(Processing!$S40,'Employee Database'!$B$4:$B$14,0),T$36)*$R$38,0)} -> 0 | U40: {=IFERROR(INDEX('Employee Database'!$F$4:$H$14,MATCH(Processing!$S40,'Employee Database'!$B$4:$B$14,0),U$36)*$R$38,0)} -> 0 | V40: {=IFERROR(INDEX('Employee Database'!$F$4:$H$14,MATCH(Processing!$S40,'Employee Database'!$B$4:$B$14,0),V$36)*$R$38,0)} -> 24200 | W40: =SUM(T40:V40) -> 24200 | X40: =INDEX(_xlfn.VSTACK($P$18:$P$23,$M$18:$M$22),MATCH(S40,$S$38:$S$48,0),1) -> #NAME? | Y40: =IF(X40>100%,CHOOSE(SUM(X40>=100%,X40>130%),3%,5%)*W40+W40,W40) -> #NAME?
...

Sheet Today
C2: =NOW()-TODAY() -> 0.66658449
E14: CLIENT | G14: CONTACT | I14: TIME | J14: SERVICE | N14: MASTER | O14: PRIСE
D17: =E17>0 -> TRUE | E17: ='ALL ORDERS'!P806 -> Client 56 | G17: ='ALL ORDERS'!T806 -> (917) 555-5678 | I17: ='ALL ORDERS'!O806 -> 0.66666667 | J17: ='ALL ORDERS'!R806 -> 456 Willow Lane, Unit 55BBB | N17: ='ALL ORDERS'!S806 -> William | O17: ='ALL ORDERS'!J806 -> 500
E19: ='ALL ORDERS'!P807 -> Client 96 | G19: ='ALL ORDERS'!T807 -> (718) 555-8765 | I19: ='ALL ORDERS'!O807 -> 0.70833333 | J19: ='ALL ORDERS'!R807 -> 210 Oak Lane, Apt. 95PPPP | N19: ='ALL ORDERS'!S807 -> Oliver | O19: ='ALL ORDERS'!J807 -> 2300
D22: =E22>0 -> TRUE | E22: ='ALL ORDERS'!P808 -> Client 70 | G22: ='ALL ORDERS'!T806 -> (917) 555-5678 | I22: ='ALL ORDERS'!O808 -> 0.75 | J22: ='ALL ORDERS'!R808 -> 678 Spruce Street, Suite 69PPP | N22: ='ALL ORDERS'!S808 -> Jack | O22: ='ALL ORDERS'!J808 -> 300
E24: ='ALL ORDERS'!P809 -> Client 30 | G24: ='ALL ORDERS'!T809 -> (212) 555-7890 | I24: ='ALL ORDERS'!O809 -> 0.79166667 | J24: ='ALL ORDERS'!R809 -> 654 Magnolia Lane, Apt. 29BB | N24: ='ALL ORDERS'!S809 -> James | O24: ='ALL ORDERS'!J809 -> 700
D27: =E27>0 -> TRUE | E27: ='ALL ORDERS'!P810 -> Client 31 | G27: ='ALL ORDERS'!T810 -> (212) 555-7891 | I27: ='ALL ORDERS'!O810 -> 0.83333333 | J27: ='ALL ORDERS'!R810 -> 655 Magnolia Lane, Apt. 29BB | N27: ='ALL ORDERS'!S810 -> Lucas | O27: ='ALL ORDERS'!J810 -> 300
D32: =E32>0 -> FALSE

Sheet Data
E2: PERSONNEL | M2: ORDER
B3: LIST OF SERVICES PROVIDED | C3: PRICE | E3: MASTERS | F3: CONTACT | H3: MANAGERS | I3: CONTACT | K3: JOB TITLES | M3: PAYMENT METHOD | O3: STATE | Q3: CITYs
B4: Dismantling the balcony block | C4: 2500 | E4: Jack | F4: (917) 555-4321 | H4: Isabella | I4: (212) 555-1234 | K4: Master | M4: Cash Money | O4: Running | Q4: New York
B5: Laying parquet boards with glue | C5: 3400 | E5: William | F5: (718) 555-3456 | H5: Joseph | I5: (917) 555-5678 | K5: Manager | M5: Credit Cards | O5: Completed | Q5: Miami
B6: Laying quartz vinyl tiles on a substrate | C6: 1200 | E6: James | F6: (646) 555-6789 | H6: Liam | I6: (718) 555-8765 | O6: Canceled | Q6: Chikago
B7: Laying parquet boards on a substrate | C7: 500 | E7: Oliver | F7: (212) 555-9876 | H7: Charlotte | I7: (646) 555-2345 | K7: STATE | M7: CHANELS | Q7: Dallas
B8: Laying solid boards | C8: 560 | E8: Lucas | F8: (917) 555-7890 | H8: Jacob | I8: (212) 555-7890 | K8: fired | M8: Facebook | O8: DISCOUNT | Q8: New Orleans
B9: Installation of ceiling plinth | C9: 670 | E9: Sofia | F9: (718) 555-2345 | M9: Reddit | O9: 0.05
B10: Cutting and installation of additional corners | C10: 740 | M10: Instagram | O10: 0.1
B11: Dismantling the balcony block | C11: 1450 | M11: YouTube | O11: 0.15
