Workbook
Name Slicer_Employee_Categories: #N/A
Name Slicer_Month: #N/A
Name Slicer_Year: #N/A

Sheet DASHBOARD

Sheet Processing
A1: Employee Categories | J1: Budget Fulfillment | K1: =GETPIVOTDATA("Average of Budget Fulfillment",Control!$A$3) -> 0.6 | L1: =IF(K1<100%,K1,0) -> 0.6 | M1: =IF(K1<100%,0.2%,K1-100%) -> 0.002 | N1: =IF(K1<100%,100%-L1,0) -> 0.4 | O1: =IF(K1<100%,0,100%-M1) -> 0 | P1: Task Deadline Compliance | Q1: =GETPIVOTDATA("Average of Task Deadline Compliance",Control!$A$3) -> 0.65
Q2: =Q1 -> 0.65 | R2: =100%-Q2 -> 0.35
A3: Executives | B3: =GETPIVOTDATA("Sum of TotalCost",Control!$A$36,"Employee Categories",""&A3) -> 146350 | C3: =$B3 -> 146350 | D3: =$B3 -> 146350 | E3: =$B3 -> 146350 | F3: =$B3 -> 146350 | G3: =$B3 -> 146350 | H3: =GETPIVOTDATA("Sum of TotalCost",Control!$A$48,"Employee Categories",""&A3) -> 146350 | J3: Employee Performance | K3: =GETPIVOTDATA("Average of Employee Productivity",Control!$A$3) -> 0.56041667 | L3: =IF(K3<100%,K3,100%) -> 0.56041667 | M3: =IF(K3<100%,100%-K3,0) -> 0.43958333 | N3: Productivity | Q3: =Q2 -> 0.65 | R3: =R2 -> 0.35
A4: Admin | B4: =GETPIVOTDATA("Sum of TotalCost",Control!$A$36,"Employee Categories",""&A4) -> 189850 | C4: =$B4 -> 189850 | D4: =$B4 -> 189850 | E4: =$B4 -> 189850 | F4: =$B4 -> 189850 | G4: =$B4 -> 189850 | H4: =GETPIVOTDATA("Sum of TotalCost",Control!$A$48,"Employee Categories",""&A4) -> 189850 | K4: =GETPIVOTDATA("Average of Employee Satisfaction",Control!$A$3) -> 0.60416667 | L4: =IF(K4<100%,K4,100%) -> 0.60416667 | M4: =IF(K4<100%,100%-K4,0) -> 0.39583333 | N4: Satisfaction | Q4: =Q3 -> 0.65 | R4: =R3 -> 0.35
A5: Sales Reps | B5: =GETPIVOTDATA("Sum of TotalCost",Control!$A$36,"Employee Categories",""&A5) -> 267390 | C5: =$B5 -> 267390 | D5: =$B5 -> 267390 | E5: =$B5 -> 267390 | F5: =$B5 -> 267390 | G5: =$B5 -> 267390 | H5: =GETPIVOTDATA("Sum of TotalCost",Control!$A$48,"Employee Categories",""&A5) -> 267390 | J5: Label 2 | K5: =IF(K4<100%,K4,"") -> 0.60416667 | L5: =IF(K4<100%,0,K4-100%) -> 0 | M5: =IF(K4<100%,0,100%-L5) -> 0 | Q5: 1 | R5: 1
A6: Operations | B6: =GETPIVOTDATA("Sum of TotalCost",Control!$A$36,"Employee Categories",""&A6) -> 156530 | C6: =$B6 -> 156530 | D6: =$B6 -> 156530 | E6: =$B6 -> 156530 | F6: =$B6 -> 156530 | G6: =$B6 -> 156530 | H6: =GETPIVOTDATA("Sum of TotalCost",Control!$A$48,"Employee Categories",""&A6) -> 156530 | J6: Label 1 | K6: =IF(K3<100%,K3,"") -> 0.56041667 | L6: =IF(K3<100%,0,K3-100%) -> 0 | M6: =IF(K3<100%,0,100%-L6) -> 0 | Q6: 2 | R6: 1
A7: Remote | B7: =GETPIVOTDATA("Sum of TotalCost",Control!$A$36,"Employee Categories",""&A7) -> 284950 | C7: =$B7 -> 284950 | D7: =$B7 -> 284950 | E7: =$B7 -> 284950 | F7: =$B7 -> 284950 | G7: =$B7 -> 284950 | H7: =GETPIVOTDATA("Sum of TotalCost",Control!$A$48,"Employee Categories",""&A7) -> 284950 | J7: Label 2 | K7: =IF(K4>100%,K4,"") | Q7: 3 | R7: 1
A8: Contractors | B8: =GETPIVOTDATA("Sum of TotalCost",Control!$A$36,"Employee Categories",""&A8) -> 216060 | C8: =$B8 -> 216060 | D8: =$B8 -> 216060 | E8: =$B8 -> 216060 | F8: =$B8 -> 216060 | G8: =$B8 -> 216060 | H8: =GETPIVOTDATA("Sum of TotalCost",Control!$A$48,"Employee Categories",""&A8) -> 216060 | J8: Label 1 | K8: =IF(K3>100%,K3,"") | Q8: 4 | R8: 1
A9: Outsourcing | B9: =GETPIVOTDATA("Sum of TotalCost",Control!$A$36,"Employee Categories",""&A9) -> 293660 | C9: =$B9 -> 293660 | D9: =$B9 -> 293660 | E9: =$B9 -> 293660 | F9: =$B9 -> 293660 | G9: =$B9 -> 293660 | H9: =GETPIVOTDATA("Sum of TotalCost",Control!$A$48,"Employee Categories",""&A9) -> 293660 | Q9: 5 | R9: 1
A10: Service Staff | B10: =GETPIVOTDATA("Sum of TotalCost",Control!$A$36,"Employee Categories",""&A10) -> 222130 | C10: =$B10 -> 222130 | D10: =$B10 -> 222130 | E10: =$B10 -> 222130 | F10: =$B10 -> 222130 | G10: =$B10 -> 222130 | H10: =GETPIVOTDATA("Sum of TotalCost",Control!$A$48,"Employee Categories",""&A10) -> 222130 | Q10: 6 | R10: 1
B11: {=IF(AND(ISNUMBER(B3:B10)),0,SUM(H3:H10)-SUM(IFERROR(B3:B10,0)))} -> 0 | C11: =$B11 -> 0 | D11: =$B11 -> 0 | E11: =$B11 -> 0 | F11: =$B11 -> 0 | G11: =$B11 -> 0 | H11: =GETPIVOTDATA("Sum of TotalCost",Control!$A$48,"Employee Categories",""&A11) -> #REF! | Q11: 7 | R11: 1
A12: Total | B12: =GETPIVOTDATA("Sum of Fixed Costs",Control!$A$36)+GETPIVOTDATA("Sum of Supplementary Pay",Control!$A$36) -> 1776920 | Q12: 8 | R12: 1
B13: =GETPIVOTDATA("Sum of TotalCost",Control!$A$48) -> 1776920 | Q13: 9 | R13: 1
Q14: 10 | R14: 1
A15: Cost Structure and Productivity | B15: Fixed Costs | C15: Supplementary Pay | D15: Productivity | H15: Payroll vs. Extra Pay | I15: Base Salary | J15: Bonuses | K15: Current Month | Q15: 11 | R15: 1
A16: JAN | B16: =GETPIVOTDATA("Sum of Fixed Costs",Control!$A$20,"Month",""&A16)/$B$30 -> 0.25713741 | C16: =GETPIVOTDATA("Sum of Supplementary Pay",Control!$A$20,"Month",""&A16)/$B$30 -> 0.18042926 | D16: =GETPIVOTDATA("Average of Productivity",Control!$A$20,"Month",""&A16) -> 0.5675 | E16: =IF(ISNA(F16),F16,B16+C16) -> #N/A | F16: =IFERROR(GETPIVOTDATA("Productivity",Control!$A$3,"Month",""&A16),NA()) -> #N/A | H16: JAN | I16: =GETPIVOTDATA("Sum of Base Salary",Control!$A$20,"Month",""&A16) -> 107260 | J16: =GETPIVOTDATA("Sum of Bonuses",Control!$A$20,"Month",""&A16) -> 51560 | K16: =IF(ISNA(F16),F16,J16) -> #N/A | Q16: 12 | R16: 1
A17: FEB | B17: =GETPIVOTDATA("Sum of Fixed Costs",Control!$A$20,"Month",""&A17)/$B$30 -> 0.38387097 | C17: =GETPIVOTDATA("Sum of Supplementary Pay",Control!$A$20,"Month",""&A17)/$B$30 -> 0.30339091 | D17: =GETPIVOTDATA("Average of Productivity",Control!$A$20,"Month",""&A17) -> 0.56625 | E17: =IF(ISNA(F17),F17,B17+C17) -> #N/A | F17: =IFERROR(GETPIVOTDATA("Productivity",Control!$A$3,"Month",""&A17),NA()) -> #N/A | H17: FEB | I17: =GETPIVOTDATA("Sum of Base Salary",Control!$A$20,"Month",""&A17) -> 105695 | J17: =GETPIVOTDATA("Sum of Bonuses",Control!$A$20,"Month",""&A17) -> 42060 | K17: =IF(ISNA(F17),F17,J17) -> #N/A | Q17: 13 | R17: 1
A18: MAR | B18: =GETPIVOTDATA("Sum of Fixed Costs",Control!$A$20,"Month",""&A18)/$B$30 -> 0.58835408 | C18: =GETPIVOTDATA("Sum of Supplementary Pay",Control!$A$20,"Month",""&A18)/$B$30 -> 0.41164592 | D18: =GETPIVOTDATA("Average of Productivity",Control!$A$20,"Month",""&A18) -> 0.65 | E18: =IF(ISNA(F18),F18,B18+C18) -> #N/A | F18: =IFERROR(GETPIVOTDATA("Productivity",Control!$A$3,"Month",""&A18),NA()) -> #N/A | H18: MAR | I18: =GETPIVOTDATA("Sum of Base Salary",Control!$A$20,"Month",""&A18) -> 104405 | J18: =GETPIVOTDATA("Sum of Bonuses",Control!$A$20,"Month",""&A18) -> 46460 | K18: =IF(ISNA(F18),F18,J18) -> #N/A | Q18: 14 | R18: 1
A19: APR | B19: =GETPIVOTDATA("Sum of Fixed Costs",Control!$A$20,"Month",""&A19)/$B$30 -> 0.48524257 | C19: =GETPIVOTDATA("Sum of Supplementary Pay",Control!$A$20,"Month",""&A19)/$B$30 -> 0.39546609 | D19: =GETPIVOTDATA("Average of Productivity",Control!$A$20,"Month",""&A19) -> 0.72875 | E19: =IF(ISNA(F19),F19,B19+C19) -> 0.88070866 | F19: =IFERROR(GETPIVOTDATA("Productivity",Control!$A$3,"Month",""&A19),NA()) -> 0.72875 | H19: APR | I19: =GETPIVOTDATA("Sum of Base Salary",Control!$A$20,"Month",""&A19) -> 102253 | J19: =GETPIVOTDATA("Sum of Bonuses",Control!$A$20,"Month",""&A19) -> 57960 | K19: =IF(ISNA(F19),F19,J19) -> 57960 | Q19: 15 | R19: 1
A20: MAY | B20: =GETPIVOTDATA("Sum of Fixed Costs",Control!$A$20,"Month",""&A20)/$B$30 -> 0.43272797 | C20: =GETPIVOTDATA("Sum of Supplementary Pay",Control!$A$20,"Month",""&A20)/$B$30 -> 0.31752604 | D20: =GETPIVOTDATA("Average of Productivity",Control!$A$20,"Month",""&A20) -> 0.59375 | E20: =IF(ISNA(F20),F20,B20+C20) -> 0.750254 | F20: =IFERROR(GETPIVOTDATA("Productivity",Control!$A$3,"Month",""&A20),NA()) -> 0.59375 | H20: MAY | I20: =GETPIVOTDATA("Sum of Base Salary",Control!$A$20,"Month",""&A20) -> 118346 | J20: =GETPIVOTDATA("Sum of Bonuses",Control!$A$20,"Month",""&A20) -> 61940 | K20: =IF(ISNA(F20),F20,J20) -> 61940 | Q20: 16 | R20: 1
A21: JUN | B21: =GETPIVOTDATA("Sum of Fixed Costs",Control!$A$20,"Month",""&A21)/$B$30 -> 0.38989078 | C21: =GETPIVOTDATA("Sum of Supplementary Pay",Control!$A$20,"Month",""&A21)/$B$30 -> 0.23583947 | D21: =GETPIVOTDATA("Average of Productivity",Control!$A$20,"Month",""&A21) -> 0.61625 | E21: =IF(ISNA(F21),F21,B21+C21) -> 0.62573025 | F21: =IFERROR(GETPIVOTDATA("Productivity",Control!$A$3,"Month",""&A21),NA()) -> 0.61625 | H21: JUN | I21: =GETPIVOTDATA("Sum of Base Salary",Control!$A$20,"Month",""&A21) -> 117876 | J21: =GETPIVOTDATA("Sum of Bonuses",Control!$A$20,"Month",""&A21) -> 59900 | K21: =IF(ISNA(F21),F21,J21) -> 59900 | Q21: 17 | R21: 1
A22: JUL | B22: =GETPIVOTDATA("Sum of Fixed Costs",Control!$A$20,"Month",""&A22)/$B$30 -> 0.37745745 | C22: =GETPIVOTDATA("Sum of Supplementary Pay",Control!$A$20,"Month",""&A22)/$B$30 -> 0.2482728 | D22: =GETPIVOTDATA("Average of Productivity",Control!$A$20,"Month",""&A22) -> 0.655 | E22: =IF(ISNA(F22),F22,B22+C22) -> #N/A | F22: =IFERROR(GETPIVOTDATA("Productivity",Control!$A$3,"Month",""&A22),NA()) -> #N/A | H22: JUL | I22: =GETPIVOTDATA("Sum of Base Salary",Control!$A$20,"Month",""&A22) -> 116949 | J22: =GETPIVOTDATA("Sum of Bonuses",Control!$A$20,"Month",""&A22) -> 57300 | K22: =IF(ISNA(F22),F22,J22) -> #N/A | Q22: 18 | R22: 1
A23: AUG | B23: =GETPIVOTDATA("Sum of Fixed Costs",Control!$A$20,"Month",""&A23)/$B$30 -> 0.41466853 | C23: =GETPIVOTDATA("Sum of Supplementary Pay",Control!$A$20,"Month",""&A23)/$B$30 -> 0.33564897 | D23: =GETPIVOTDATA("Average of Productivity",Control!$A$20,"Month",""&A23) -> 0.6375 | E23: =IF(ISNA(F23),F23,B23+C23) -> #N/A | F23: =IFERROR(GETPIVOTDATA("Productivity",Control!$A$3,"Month",""&A23),NA()) -> #N/A | H23: AUG | I23: =GETPIVOTDATA("Sum of Base Salary",Control!$A$20,"Month",""&A23) -> 118526 | J23: =GETPIVOTDATA("Sum of Bonuses",Control!$A$20,"Month",""&A23) -> 60120 | K23: =IF(ISNA(F23),F23,J23) -> #N/A | Q23: 19 | R23: 1
A24: SEP | B24: =GETPIVOTDATA("Sum of Fixed Costs",Control!$A$20,"Month",""&A24)/$B$30 -> 0.54359919 | C24: =GETPIVOTDATA("Sum of Supplementary Pay",Control!$A$20,"Month",""&A24)/$B$30 -> 0.33708407 | D24: =GETPIVOTDATA("Average of Productivity",Control!$A$20,"Month",""&A24) -> 0.6525 | E24: =IF(ISNA(F24),F24,B24+C24) -> #N/A | F24: =IFERROR(GETPIVOTDATA("Productivity",Control!$A$3,"Month",""&A24),NA()) -> #N/A | H24: SEP | I24: =GETPIVOTDATA("Sum of Base Salary",Control!$A$20,"Month",""&A24) -> 121179 | J24: =GETPIVOTDATA("Sum of Bonuses",Control!$A$20,"Month",""&A24) -> 52000 | K24: =IF(ISNA(F24),F24,J24) -> #N/A | Q24: 20 | R24: 1
A25: OCT | B25: =GETPIVOTDATA("Sum of Fixed Costs",Control!$A$20,"Month",""&A25)/$B$30 -> 0.57345695 | C25: =GETPIVOTDATA("Sum of Supplementary Pay",Control!$A$20,"Month",""&A25)/$B$30 -> 0.42654305 | D25: =GETPIVOTDATA("Average of Productivity",Control!$A$20,"Month",""&A25) -> 0.655 | E25: =IF(ISNA(F25),F25,B25+C25) -> #N/A | F25: =IFERROR(GETPIVOTDATA("Productivity",Control!$A$3,"Month",""&A25),NA()) -> #N/A | H25: OCT | I25: =GETPIVOTDATA("Sum of Base Salary",Control!$A$20,"Month",""&A25) -> 122137 | J25: =GETPIVOTDATA("Sum of Bonuses",Control!$A$20,"Month",""&A25) -> 42520 | K25: =IF(ISNA(F25),F25,J25) -> #N/A | Q25: 21 | R25: 1
A26: NOV | B26: =GETPIVOTDATA("Sum of Fixed Costs",Control!$A$20,"Month",""&A26)/$B$30 -> 0.4010922 | C26: =GETPIVOTDATA("Sum of Supplementary Pay",Control!$A$20,"Month",""&A26)/$B$30 -> 0.28619507 | D26: =GETPIVOTDATA("Average of Productivity",Control!$A$20,"Month",""&A26) -> 0.52125 | E26: =IF(ISNA(F26),F26,B26+C26) -> #N/A | F26: =IFERROR(GETPIVOTDATA("Productivity",Control!$A$3,"Month",""&A26),NA()) -> #N/A | H26: NOV | I26: =GETPIVOTDATA("Sum of Base Salary",Control!$A$20,"Month",""&A26) -> 123521 | J26: =GETPIVOTDATA("Sum of Bonuses",Control!$A$20,"Month",""&A26) -> 46940 | K26: =IF(ISNA(F26),F26,J26) -> #N/A | Q26: 22 | R26: 1
A27: DEC | B27: =GETPIVOTDATA("Sum of Fixed Costs",Control!$A$20,"Month",""&A27)/$B$30 -> 0.27040894 | C27: =GETPIVOTDATA("Sum of Supplementary Pay",Control!$A$20,"Month",""&A27)/$B$30 -> 0.16719583 | D27: =GETPIVOTDATA("Average of Productivity",Control!$A$20,"Month",""&A27) -> 0.58125 | E27: =IF(ISNA(F27),F27,B27+C27) -> #N/A | F27: =IFERROR(GETPIVOTDATA("Productivity",Control!$A$3,"Month",""&A27),NA()) -> #N/A | H27: DEC | I27: =GETPIVOTDATA("Sum of Base Salary",Control!$A$20,"Month",""&A27) -> 124621 | J27: =GETPIVOTDATA("Sum of Bonuses",Control!$A$20,"Month",""&A27) -> 58260 | K27: =IF(ISNA(F27),F27,J27) -> #N/A | Q27: 23 | R27: 1
I28: =GETPIVOTDATA(""&I15,Control!$A$3) -> 338475 | J28: =GETPIVOTDATA(""&J15,Control!$A$3) -> 179800 | Q28: 24 | R28: 1
Q29: 25 | R29: 1
A30: MAX | B30: =MAX(Control!G21:G32) -> 787400 | Q30: 26 | R30: 1
Q31: 27 | R31: 1
A32: Label1 | B32: =GETPIVOTDATA(""&D15,Control!$A$3) -> 0.64625 | Q32: 28 | R32: 1
A33: Label2 | B33: =GETPIVOTDATA(""&B15,Control!$A$3) -> 1029810 | Q33: 29 | R33: 1
A34: Label3 | B34: =GETPIVOTDATA(""&C15,Control!$A$3) -> 747110 | Q34: 30 | R34: 1
A35: Label4 | B35: =GETPIVOTDATA("Sum of for max",Control!$A$20) -> 6900100 | Q35: 31 | R35: 1
Q36: 32 | R36: 1
Q37: 33 | R37: 1
Q38: 34 | R38: 1
Q39: 35 | R39: 1
Q40: 36 | R40: 1
...

Sheet Control
A3: Row Labels | B3: Average of Productivity | C3: Average of Budget Fulfillment | D3: Average of Employee Productivity | E3: Average of Employee Satisfaction | F3: Average of Task Deadline Compliance | G3: Sum of Fixed Costs | H3: Sum of Supplementary Pay | I3: Sum of Base Salary | J3: Sum of Bonuses
A4: APR | B4: 0.72875 | C4: 0.5 | D4: 1.20125 | E4: 1.2225 | F4: 0.55 | G4: 382080 | H4: 311390 | I4: 102253 | J4: 57960
A5: MAY | B5: 0.59375 | C5: 0.6 | D5: 0.16 | E5: 0.215 | F5: 0.65 | G5: 340730 | H5: 250020 | I5: 118346 | J5: 61940
A6: JUN | B6: 0.61625 | C6: 0.7 | D6: 0.32 | E6: 0.375 | F6: 0.75 | G6: 307000 | H6: 185700 | I6: 117876 | J6: 59900
A7: Grand Total | B7: 0.64625 | C7: 0.6 | D7: 0.56041667 | E7: 0.60416667 | F7: 0.65 | G7: 1029810 | H7: 747110 | I7: 338475 | J7: 179800
A20: Row Labels | B20: Sum of Fixed Costs | C20: Sum of Supplementary Pay | D20: Average of Productivity | E20: Sum of Base Salary | F20: Sum of Bonuses | G20: Sum of for max
A21: JAN | B21: 202470 | C21: 142070 | D21: 0.5675 | E21: 107260 | F21: 51560 | G21: 344540
A22: FEB | B22: 302260 | C22: 238890 | D22: 0.56625 | E22: 105695 | F22: 42060 | G22: 541150
A23: MAR | B23: 463270 | C23: 324130 | D23: 0.65 | E23: 104405 | F23: 46460 | G23: 787400
A24: APR | B24: 382080 | C24: 311390 | D24: 0.72875 | E24: 102253 | F24: 57960 | G24: 693470
A25: MAY | B25: 340730 | C25: 250020 | D25: 0.59375 | E25: 118346 | F25: 61940 | G25: 590750
A26: JUN | B26: 307000 | C26: 185700 | D26: 0.61625 | E26: 117876 | F26: 59900 | G26: 492700
A27: JUL | B27: 297210 | C27: 195490 | D27: 0.655 | E27: 116949 | F27: 57300 | G27: 492700
A28: AUG | B28: 326510 | C28: 264290 | D28: 0.6375 | E28: 118526 | F28: 60120 | G28: 590800
A29: SEP | B29: 428030 | C29: 265420 | D29: 0.6525 | E29: 121179 | F29: 52000 | G29: 693450
A30: OCT | B30: 451540 | C30: 335860 | D30: 0.655 | E30: 122137 | F30: 42520 | G30: 787400
A31: NOV | B31: 315820 | C31: 225350 | D31: 0.52125 | E31: 123521 | F31: 46940 | G31: 541170
A32: DEC | B32: 212920 | C32: 131650 | D32: 0.58125 | E32: 124621 | F32: 58260 | G32: 344570
A33: Grand Total | B33: 4029840 | C33: 2870260 | D33: 0.61875 | E33: 1382768 | F33: 637020 | G33: 6900100
A36: Row Labels | B36: Sum of Fixed Costs | C36: Sum of Supplementary Pay | D36: Sum of TotalCost
A37: Admin | B37: 109270 | C37: 80580 | D37: 189850
A38: Contractors | B38: 124900 | C38: 91160 | D38: 216060
A39: Executives | B39: 94240 | C39: 52110 | D39: 146350
A40: Operations | B40: 75490 | C40: 81040 | D40: 156530
A41: Outsourcing | B41: 153590 | C41: 140070 | D41: 293660
A42: Remote | B42: 197290 | C42: 87660 | D42: 284950
A43: Sales Reps | B43: 141270 | C43: 126120 | D43: 267390
A44: Service Staff | B44: 133760 | C44: 88370 | D44: 222130
A45: Grand Total | B45: 1029810 | C45: 747110 | D45: 1776920
A48: Row Labels | B48: Sum of Fixed Costs | C48: Sum of Supplementary Pay | D48: Sum of TotalCost
A49: Admin | B49: 109270 | C49: 80580 | D49: 189850
A50: Contractors | B50: 124900 | C50: 91160 | D50: 216060
A51: Executives | B51: 94240 | C51: 52110 | D51: 146350
A52: Operations | B52: 75490 | C52: 81040 | D52: 156530
A53: Outsourcing | B53: 153590 | C53: 140070 | D53: 293660
A54: Remote | B54: 197290 | C54: 87660 | D54: 284950
A55: Sales Reps | B55: 141270 | C55: 126120 | D55: 267390
A56: Service Staff | B56: 133760 | C56: 88370 | D56: 222130
A57: Grand Total | B57: 1029810 | C57: 747110 | D57: 1776920

Sheet Data
A1: Year | B1: Month | C1: Fixed Costs | D1: Supplementary Pay | E1: Productivity | F1: Base Salary | G1: Bonuses | H1: Budget Fulfillment | I1: Employee Productivity | J1: Employee Satisfaction | K1: Task Deadline Compliance | L1: Employee Categories
A2: 2025 | B2: JAN | C2: 23870 | D2: 9280 | E2: 0.4 | F2: 1760 | G2: 4140 | H2: 0.15 | I2: 0.14 | J2: 0.196 | K2: 0.19 | L2: Executives
A3: 2025 | B3: FEB | C3: 27830 | D3: 19340 | E3: 0.32 | F3: 3510 | G3: 5410 | H3: 0.23 | I3: 0.278 | J3: 0.331 | K3: 0.28 | L3: Executives
A4: 2025 | B4: MAR | C4: 26830 | D4: 15090 | E4: 0.55 | F4: 4960 | G4: 5620 | H4: 0.32 | I4: 0.389 | J4: 0.44 | K4: 0.36 | L4: Executives
A5: 2025 | B5: APR | C5: 15720 | D5: 21710 | E5: 0.68 | F5: 5500 | G5: 4880 | H5: 0.4 | I5: 0.524 | J5: 0.5832 | K5: 0.44 | L5: Executives
A6: 2025 | B6: MAY | C6: 41400 | D6: 20390 | E6: 0.52 | F6: 4940 | G6: 3140 | H6: 0.49 | I6: 0.663 | J6: 0.6966 | K6: 0.53 | L6: Executives
A7: 2025 | B7: JUN | C7: 25400 | D7: 27520 | E7: 0.62 | F7: 3560 | G7: 2320 | H7: 0.57 | I7: 0.775 | J7: 0.8046 | K7: 0.62 | L7: Executives
A8: 2025 | B8: JUL | C8: 23780 | D8: 24740 | E8: 0.57 | F8: 2970 | G8: 3480 | H8: 0.66 | I8: 0.887 | J8: 0.9126 | K8: 0.7 | L8: Executives
A9: 2025 | B9: AUG | C9: 9250 | D9: 6980 | E9: 0.72 | F9: 4260 | G9: 6750 | H9: 0.74 | I9: 1.335 | J9: 1.2096 | K9: 0.78 | L9: Executives
A10: 2025 | B10: SEP | C10: 11450 | D10: 13440 | E10: 0.77 | F10: 6450 | G10: 8200 | H10: 0.81 | I10: 0.14 | J10: 0.196 | K10: 0.85 | L10: Executives
A11: 2025 | B11: OCT | C11: 23440 | D11: 32360 | E11: 0.67 | F11: 7720 | G11: 7040 | H11: 0.89 | I11: 0.305 | J11: 0.358 | K11: 0.92 | L11: Executives
A12: 2025 | B12: NOV | C12: 9090 | D12: 9850 | E12: 0.58 | F12: 8000 | G12: 5470 | H12: 1.15 | I12: 0.443 | J12: 0.4968 | K12: 0.96 | L12: Executives
A13: 2025 | B13: DEC | C13: 15670 | D13: 21640 | E13: 0.65 | F13: 7370 | G13: 6050 | H13: 1.24 | I13: 0.607 | J13: 0.6408 | K13: 1 | L13: Executives
... A385: 2028 | B385: DEC | C385: 29720 | D385: 13350 | E385: 0.6 | F385: 24012 | G385: 6040 | H385: 1.35 | I385: 1.167 | J385: 1.1016 | K385: 1 | L385: Service Staff

Sheet R
B1: 8B6DFF | D1: https://exceltable.com/
B2: 673FFF
B3: 09CA4F
B4: 72F46A
B5: 06C9D0
B6: 03E3C7
B7: 03AEFF
B8: 1794FF
B9: #FF1492
B11: #FF6CFF
B12: 7A0D82
B13: #00405A
B14: 62A3D6
B15: 246691
B17: 21428
