Workbook
Name mydata: Data!$A$1:$AC$366
Name Slicer_Day: #N/A
Name Slicer_Month: #N/A
Name Slicer_Week: #N/A

Sheet DASHBOARD

Sheet Processing
A1: =IF(ROW()<=ROUND($D$2*100,0),"",$C$2) | B1: =IF(ROW()<=ROUND($D$2*100,0),$C$2,"") -> █ | C1: Alt + 219 | D1: PRESENCE | E1: ABSENTEEISM RATE | I1: Day | K1: Employee Turnover | L1: Rang 3 | M1: Rang 2 | N1: Rang 1 | O1: Cur1 | P1: Cur2 | Q1: Cur3 | R1: X | S1: Cursors
A2: =IF(ROW()<=ROUND($D$2*100,0),"",$C$2) | B2: =IF(ROW()<=ROUND($D$2*100,0),$C$2,"") -> █ | C2: █ | D2: =GETPIVOTDATA("Average of PRESENCE",Control!$A$3) -> 0.64509589 | E2: =100%-D2 -> 0.35490411 | I2: 3 | J2: 1 | K2: start | L2: =L3/1.5 -> 941.33333 | M2: =M3/1.5 -> 2235.3333 | N2: =N3/1.5 -> 3056.6667 | O2: #N/A | P2: #N/A | Q2: #N/A | R2: #N/A | S2: =IF(COUNTIF(O3:O9,">0"),_xlfn.MAXIFS(O3:O9,O3:O9,">0"),NA()) -> 1544 | T2: {=MATCH($S$2&$S$3&$S$4,$L$3:$L$9&$M$3:$M$9&$N$3:$N$9,0)+1} -> 5
A3: =IF(ROW()<=ROUND($D$2*100,0),"",$C$2) | B3: =IF(ROW()<=ROUND($D$2*100,0),$C$2,"") -> █ | J3: 2 | K3: Sunday | L3: =IFERROR(GETPIVOTDATA(""&L$1,Control!$A$17,"Day",""&$K3),0) -> 1412 | M3: =IFERROR(GETPIVOTDATA(""&M$1,Control!$A$17,"Day",""&$K3),0) -> 3353 | N3: =IFERROR(GETPIVOTDATA(""&N$1,Control!$A$17,"Day",""&$K3),0) -> 4585 | O3: =IF(ISNUMBER(GETPIVOTDATA("Average of PRESENCE",Control!$A$3,"Day",$K3)),L3,NA()) -> 1412 | P3: =IF(ISNUMBER(GETPIVOTDATA("Average of PRESENCE",Control!$A$3,"Day",$K3)),M3,NA()) -> 3353 | Q3: =IF(ISNUMBER(GETPIVOTDATA("Average of PRESENCE",Control!$A$3,"Day",$K3)),N3,NA()) -> 4585 | R3: =IF(ISNA(Q3),Q3,ROW(R1)) -> 1 | S3: =IF(COUNTIF(P3:P9,">0"),_xlfn.MAXIFS(P3:P9,P3:P9,">0"),NA()) -> 3474 | T3: {=MATCH($S$2&$S$3&$S$4,$L$3:$L$9&$M$3:$M$9&$N$3:$N$9,0)+1} -> 5
A4: =IF(ROW()<=ROUND($D$2*100,0),"",$C$2) | B4: =IF(ROW()<=ROUND($D$2*100,0),$C$2,"") -> █ | C4: Dia | D4: General Productivity | J4: 3 | K4: Monday | L4: =IFERROR(GETPIVOTDATA(""&L$1,Control!$A$17,"Day",""&$K4),0) -> 1489 | M4: =IFERROR(GETPIVOTDATA(""&M$1,Control!$A$17,"Day",""&$K4),0) -> 3440 | N4: =IFERROR(GETPIVOTDATA(""&N$1,Control!$A$17,"Day",""&$K4),0) -> 4651 | O4: =IF(ISNUMBER(GETPIVOTDATA("Average of PRESENCE",Control!$A$3,"Day",$K4)),L4,NA()) -> 1489 | P4: =IF(ISNUMBER(GETPIVOTDATA("Average of PRESENCE",Control!$A$3,"Day",$K4)),M4,NA()) -> 3440 | Q4: =IF(ISNUMBER(GETPIVOTDATA("Average of PRESENCE",Control!$A$3,"Day",$K4)),N4,NA()) -> 4651 | R4: =IF(ISNA(Q4),Q4,ROW(R2)) -> 2 | S4: =IF(COUNTIF(Q3:Q9,">0"),_xlfn.MAXIFS(Q3:Q9,Q3:Q9,">0"),NA()) -> 4743 | T4: {=MATCH($S$2&$S$3&$S$4,$L$3:$L$9&$M$3:$M$9&$N$3:$N$9,0)+1} -> 5
A5: =IF(ROW()<=ROUND($D$2*100,0),"",$C$2) | B5: =IF(ROW()<=ROUND($D$2*100,0),$C$2,"") -> █ | C5: 1 | D5: =GETPIVOTDATA("Average of General Productivity",Control!$A$3) -> 0.57129277 | E5: =100%-D5 -> 0.42870723 | F5: 0.5 | J5: 4 | K5: Tuesday | L5: =IFERROR(GETPIVOTDATA(""&L$1,Control!$A$17,"Day",""&$K5),0) -> 1397 | M5: =IFERROR(GETPIVOTDATA(""&M$1,Control!$A$17,"Day",""&$K5),0) -> 3422 | N5: =IFERROR(GETPIVOTDATA(""&N$1,Control!$A$17,"Day",""&$K5),0) -> 4645 | O5: =IF(ISNUMBER(GETPIVOTDATA("Average of PRESENCE",Control!$A$3,"Day",$K5)),L5,NA()) -> 1397 | P5: =IF(ISNUMBER(GETPIVOTDATA("Average of PRESENCE",Control!$A$3,"Day",$K5)),M5,NA()) -> 3422 | Q5: =IF(ISNUMBER(GETPIVOTDATA("Average of PRESENCE",Control!$A$3,"Day",$K5)),N5,NA()) -> 4645 | R5: =IF(ISNA(Q5),Q5,ROW(R3)) -> 3
A6: =IF(ROW()<=ROUND($D$2*100,0),"",$C$2) | B6: =IF(ROW()<=ROUND($D$2*100,0),$C$2,"") -> █ | C6: 1 | J6: 5 | K6: Wednesday | L6: =IFERROR(GETPIVOTDATA(""&L$1,Control!$A$17,"Day",""&$K6),0) -> 1544 | M6: =IFERROR(GETPIVOTDATA(""&M$1,Control!$A$17,"Day",""&$K6),0) -> 3474 | N6: =IFERROR(GETPIVOTDATA(""&N$1,Control!$A$17,"Day",""&$K6),0) -> 4743 | O6: =IF(ISNUMBER(GETPIVOTDATA("Average of PRESENCE",Control!$A$3,"Day",$K6)),L6,NA()) -> 1544 | P6: =IF(ISNUMBER(GETPIVOTDATA("Average of PRESENCE",Control!$A$3,"Day",$K6)),M6,NA()) -> 3474 | Q6: =IF(ISNUMBER(GETPIVOTDATA("Average of PRESENCE",Control!$A$3,"Day",$K6)),N6,NA()) -> 4743 | R6: =IF(ISNA(Q6),Q6,ROW(R4)) -> 4
A7: =IF(ROW()<=ROUND($D$2*100,0),"",$C$2) | B7: =IF(ROW()<=ROUND($D$2*100,0),$C$2,"") -> █ | C7: 1 | D7: Employee Engagement Rate | J7: 6 | K7: Thursday | L7: =IFERROR(GETPIVOTDATA(""&L$1,Control!$A$17,"Day",""&$K7),0) -> 1528 | M7: =IFERROR(GETPIVOTDATA(""&M$1,Control!$A$17,"Day",""&$K7),0) -> 3267 | N7: =IFERROR(GETPIVOTDATA(""&N$1,Control!$A$17,"Day",""&$K7),0) -> 4571 | O7: =IF(ISNUMBER(GETPIVOTDATA("Average of PRESENCE",Control!$A$3,"Day",$K7)),L7,NA()) -> 1528 | P7: =IF(ISNUMBER(GETPIVOTDATA("Average of PRESENCE",Control!$A$3,"Day",$K7)),M7,NA()) -> 3267 | Q7: =IF(ISNUMBER(GETPIVOTDATA("Average of PRESENCE",Control!$A$3,"Day",$K7)),N7,NA()) -> 4571 | R7: =IF(ISNA(Q7),Q7,ROW(R5)) -> 5
A8: =IF(ROW()<=ROUND($D$2*100,0),"",$C$2) | B8: =IF(ROW()<=ROUND($D$2*100,0),$C$2,"") -> █ | C8: 1 | D8: EER | F8: X | G8: Y | J8: 7 | K8: Friday | L8: =IFERROR(GETPIVOTDATA(""&L$1,Control!$A$17,"Day",""&$K8),0) -> 1486 | M8: =IFERROR(GETPIVOTDATA(""&M$1,Control!$A$17,"Day",""&$K8),0) -> 3382 | N8: =IFERROR(GETPIVOTDATA(""&N$1,Control!$A$17,"Day",""&$K8),0) -> 4614 | O8: =IF(ISNUMBER(GETPIVOTDATA("Average of PRESENCE",Control!$A$3,"Day",$K8)),L8,NA()) -> 1486 | P8: =IF(ISNUMBER(GETPIVOTDATA("Average of PRESENCE",Control!$A$3,"Day",$K8)),M8,NA()) -> 3382 | Q8: =IF(ISNUMBER(GETPIVOTDATA("Average of PRESENCE",Control!$A$3,"Day",$K8)),N8,NA()) -> 4614 | R8: =IF(ISNA(Q8),Q8,ROW(R6)) -> 6
A9: =IF(ROW()<=ROUND($D$2*100,0),"",$C$2) | B9: =IF(ROW()<=ROUND($D$2*100,0),$C$2,"") -> █ | C9: 1 | D9: =100%-E9 -> 0.36786301 | E9: =GETPIVOTDATA("Average of EER",Control!$A$3) -> 0.63213699 | F9: =SIN(D10*2*PI()) -> 0.30185936 | G9: =COS(E10*2*PI()) -> -0.95335247 | J9: 8 | K9: Saturday | L9: =IFERROR(GETPIVOTDATA(""&L$1,Control!$A$17,"Day",""&$K9),0) -> 1405 | M9: =IFERROR(GETPIVOTDATA(""&M$1,Control!$A$17,"Day",""&$K9),0) -> 3397 | N9: =IFERROR(GETPIVOTDATA(""&N$1,Control!$A$17,"Day",""&$K9),0) -> 4686 | O9: =IF(ISNUMBER(GETPIVOTDATA("Average of PRESENCE",Control!$A$3,"Day",$K9)),L9,NA()) -> 1405 | P9: =IF(ISNUMBER(GETPIVOTDATA("Average of PRESENCE",Control!$A$3,"Day",$K9)),M9,NA()) -> 3397 | Q9: =IF(ISNUMBER(GETPIVOTDATA("Average of PRESENCE",Control!$A$3,"Day",$K9)),N9,NA()) -> 4686 | R9: =IF(ISNA(Q9),Q9,ROW(R7)) -> 7
A10: =IF(ROW()<=ROUND($D$2*100,0),"",$C$2) | B10: =IF(ROW()<=ROUND($D$2*100,0),$C$2,"") -> █ | C10: 1 | D10: =D9+100%/12 -> 0.45119635 | E10: =100%-D10 -> 0.54880365 | F10: 0.5 | G10: 0.866 | J10: 9 | K10: end | L10: =L9/1.5 -> 936.66667 | M10: =M9/1.5 -> 2264.6667 | N10: =N9/1.5 -> 3124 | O10: #N/A | P10: #N/A | Q10: #N/A | R10: #N/A
A11: =IF(ROW()<=ROUND($D$2*100,0),"",$C$2) | B11: =IF(ROW()<=ROUND($D$2*100,0),$C$2,"") -> █ | C11: 1 | D11: Employee Satisfaction Rate
A12: =IF(ROW()<=ROUND($D$2*100,0),"",$C$2) | B12: =IF(ROW()<=ROUND($D$2*100,0),$C$2,"") -> █ | C12: 1 | D12: ESR | F12: X | G12: Y
A13: =IF(ROW()<=ROUND($D$2*100,0),"",$C$2) | B13: =IF(ROW()<=ROUND($D$2*100,0),$C$2,"") -> █ | C13: 1 | D13: =100%-E13 -> 0.37035616 | E13: =GETPIVOTDATA("Average of ESR",Control!$A$3) -> 0.62964384 | F13: =SIN(D14*2*PI()) -> 0.28688874 | G13: =COS(E14*2*PI()) -> -0.95796391
A14: =IF(ROW()<=ROUND($D$2*100,0),"",$C$2) | B14: =IF(ROW()<=ROUND($D$2*100,0),$C$2,"") -> █ | C14: 1 | D14: =D13+100%/12 -> 0.4536895 | E14: =100%-D14 -> 0.5463105 | F14: 0.5 | G14: 0.866
A15: =IF(ROW()<=ROUND($D$2*100,0),"",$C$2) | B15: =IF(ROW()<=ROUND($D$2*100,0),$C$2,"") -> █ | C15: 1
A16: =IF(ROW()<=ROUND($D$2*100,0),"",$C$2) | B16: =IF(ROW()<=ROUND($D$2*100,0),$C$2,"") -> █ | C16: 1 | E16: Applicant to Job Ratio | I16: 0.2 | M16: 0.05 | N16: 85 | O16: =M16 -> 0.05
A17: =IF(ROW()<=ROUND($D$2*100,0),"",$C$2) | B17: =IF(ROW()<=ROUND($D$2*100,0),$C$2,"") -> █ | C17: 1 | D17: APJO | E17: Vacancies | F17: Resumes | H17: Vacancies vs Resumes | I17: indent | M17: Indent | N17: Progress | O17: Indent | P17: End | Q17: Labels Done
A18: =IF(ROW()<=ROUND($D$2*100,0),"",$C$2) | B18: =IF(ROW()<=ROUND($D$2*100,0),$C$2,"") -> █ | C18: 1 | D18: APJO | E18: =E19/1.5 -> 836 | F18: =F19/1.5 -> 858.66667 | H18: =SUM(E19:E25)/SUM(E19:F25) -> 0.50411043 | I18: =I16 -> 0.2 | J18: =100%-H18 -> 0.49588957 | L18: Filling Vacancies | M18: =M16 -> 0.05 | N18: =GETPIVOTDATA(""&L18,Control!$A$3) -> 0.59561644 | O18: =M18 -> 0.05 | P18: =100%-N18 -> 0.40438356 | Q18: =IF(N18>=44%,TEXT(N18,"0%"),"") -> 60% | R18: =IF(N18>=44%,"",TEXT(N18,"0%"))
A19: =IF(ROW()<=ROUND($D$2*100,0),"",$C$2) | B19: =IF(ROW()<=ROUND($D$2*100,0),$C$2,"") -> █ | C19: 1 | D19: Sunday | E19: =IFERROR(GETPIVOTDATA(""&E$17,Control!$A$17,"Day",$D19),0) -> 1254 | F19: =IFERROR(GETPIVOTDATA(""&F$17,Control!$A$17,"Day",$D19),0) -> 1288 | H19: =SUM(F19:F25)/SUM(E19:F25) -> 0.49588957 | I19: =I16 -> 0.2 | J19: =100%-H19 -> 0.50411043 | L19: Adaptation | M19: =M16 -> 0.05 | N19: =GETPIVOTDATA(""&L19,Control!$A$3) -> 0.58850844 | O19: =O16 -> 0.05 | P19: =100%-N19 -> 0.41149156 | Q19: =IF(N19>=44%,TEXT(N19,"0%"),"") -> 59% | R19: =IF(N19>=44%,"",TEXT(N19,"0%"))
A20: =IF(ROW()<=ROUND($D$2*100,0),"",$C$2) | B20: =IF(ROW()<=ROUND($D$2*100,0),$C$2,"") -> █ | D20: Monday | E20: =IFERROR(GETPIVOTDATA(""&E$17,Control!$A$17,"Day",$D20),0) -> 1219 | F20: =IFERROR(GETPIVOTDATA(""&F$17,Control!$A$17,"Day",$D20),0) -> 1179 | L20: Education | M20: =M16 -> 0.05 | N20: =GETPIVOTDATA(""&L20,Control!$A$3) -> 0.52975342 | O20: =O16 -> 0.05 | P20: =100%-N20 -> 0.47024658 | Q20: =IF(N20>=44%,TEXT(N20,"0%"),"") -> 53% | R20: =IF(N20>=44%,"",TEXT(N20,"0%"))
A21: =IF(ROW()<=ROUND($D$2*100,0),"",$C$2) | B21: =IF(ROW()<=ROUND($D$2*100,0),$C$2,"") -> █ | D21: Tuesday | E21: =IFERROR(GETPIVOTDATA(""&E$17,Control!$A$17,"Day",$D21),0) -> 1130 | F21: =IFERROR(GETPIVOTDATA(""&F$17,Control!$A$17,"Day",$D21),0) -> 1050
A22: =IF(ROW()<=ROUND($D$2*100,0),"",$C$2) | B22: =IF(ROW()<=ROUND($D$2*100,0),$C$2,"") -> █ | D22: Wednesday | E22: =IFERROR(GETPIVOTDATA(""&E$17,Control!$A$17,"Day",$D22),0) -> 1072 | F22: =IFERROR(GETPIVOTDATA(""&F$17,Control!$A$17,"Day",$D22),0) -> 1096
A23: =IF(ROW()<=ROUND($D$2*100,0),"",$C$2) | B23: =IF(ROW()<=ROUND($D$2*100,0),$C$2,"") -> █ | D23: Thursday | E23: =IFERROR(GETPIVOTDATA(""&E$17,Control!$A$17,"Day",$D23),0) -> 1226 | F23: =IFERROR(GETPIVOTDATA(""&F$17,Control!$A$17,"Day",$D23),0) -> 1095
A24: =IF(ROW()<=ROUND($D$2*100,0),"",$C$2) | B24: =IF(ROW()<=ROUND($D$2*100,0),$C$2,"") -> █ | D24: Friday | E24: =IFERROR(GETPIVOTDATA(""&E$17,Control!$A$17,"Day",$D24),0) -> 1108 | F24: =IFERROR(GETPIVOTDATA(""&F$17,Control!$A$17,"Day",$D24),0) -> 1240
A25: =IF(ROW()<=ROUND($D$2*100,0),"",$C$2) | B25: =IF(ROW()<=ROUND($D$2*100,0),$C$2,"") -> █ | D25: Saturday | E25: =IFERROR(GETPIVOTDATA(""&E$17,Control!$A$17,"Day",$D25),0) -> 1208 | F25: =IFERROR(GETPIVOTDATA(""&F$17,Control!$A$17,"Day",$D25),0) -> 1135
A26: =IF(ROW()<=ROUND($D$2*100,0),"",$C$2) | B26: =IF(ROW()<=ROUND($D$2*100,0),$C$2,"") -> █ | D26: end | E26: =E25/1.5 -> 805.33333 | F26: =F25/1.5 -> 756.66667
A27: =IF(ROW()<=ROUND($D$2*100,0),"",$C$2) | B27: =IF(ROW()<=ROUND($D$2*100,0),$C$2,"") -> █
A28: =IF(ROW()<=ROUND($D$2*100,0),"",$C$2) | B28: =IF(ROW()<=ROUND($D$2*100,0),$C$2,"") -> █ | C28: Interviews | D28: Sunday | E28: Monday | F28: Tuesday | G28: Wednesday | H28: Thursday | I28: Friday | J28: Saturday
A29: =IF(ROW()<=ROUND($D$2*100,0),"",$C$2) | B29: =IF(ROW()<=ROUND($D$2*100,0),$C$2,"") -> █ | C29: Recruiters | D29: SU | E29: MO | F29: TU | G29: WE | H29: TH | I29: FR | J29: SA | L29: Top 3 KPI Achievement | M29: X | N29: Y | O29: Rank
A30: =IF(ROW()<=ROUND($D$2*100,0),"",$C$2) | B30: =IF(ROW()<=ROUND($D$2*100,0),$C$2,"") -> █ | C30: Recruiter 1 | D30: =GETPIVOTDATA(""&$C30,Control!$A$17,"Day",D$28) -> 197 | E30: =GETPIVOTDATA(""&$C30,Control!$A$17,"Day",E$28) -> 306 | F30: =GETPIVOTDATA(""&$C30,Control!$A$17,"Day",F$28) -> 331 | G30: =GETPIVOTDATA(""&$C30,Control!$A$17,"Day",G$28) -> 343 | H30: =GETPIVOTDATA(""&$C30,Control!$A$17,"Day",H$28) -> 345 | I30: =GETPIVOTDATA(""&$C30,Control!$A$17,"Day",I$28) -> 227 | J30: =GETPIVOTDATA(""&$C30,Control!$A$17,"Day",J$28) -> 209 | L30: KPI 1 | M30: 0.35 | N30: 0.5 | O30: =GETPIVOTDATA("Average of KPI 1",Control!$A$3) -> 0.67961644
A31: =IF(ROW()<=ROUND($D$2*100,0),"",$C$2) | B31: =IF(ROW()<=ROUND($D$2*100,0),$C$2,"") -> █ | C31: Recruiter 2 | D31: =GETPIVOTDATA(""&$C31,Control!$A$17,"Day",D$28) -> 219 | E31: =GETPIVOTDATA(""&$C31,Control!$A$17,"Day",E$28) -> 358 | F31: =GETPIVOTDATA(""&$C31,Control!$A$17,"Day",F$28) -> 315 | G31: =GETPIVOTDATA(""&$C31,Control!$A$17,"Day",G$28) -> 360 | H31: =GETPIVOTDATA(""&$C31,Control!$A$17,"Day",H$28) -> 349 | I31: =GETPIVOTDATA(""&$C31,Control!$A$17,"Day",I$28) -> 221 | J31: =GETPIVOTDATA(""&$C31,Control!$A$17,"Day",J$28) -> 235 | L31: KPI 2 | M31: 0.51 | N31: 0.6 | O31: =GETPIVOTDATA("Average of KPI 2",Control!$A$3) -> 0.68178082
A32: =IF(ROW()<=ROUND($D$2*100,0),"",$C$2) | B32: =IF(ROW()<=ROUND($D$2*100,0),$C$2,"") -> █ | C32: Recruiter 3 | D32: =GETPIVOTDATA(""&$C32,Control!$A$17,"Day",D$28) -> 229 | E32: =GETPIVOTDATA(""&$C32,Control!$A$17,"Day",E$28) -> 362 | F32: =GETPIVOTDATA(""&$C32,Control!$A$17,"Day",F$28) -> 373 | G32: =GETPIVOTDATA(""&$C32,Control!$A$17,"Day",G$28) -> 345 | H32: =GETPIVOTDATA(""&$C32,Control!$A$17,"Day",H$28) -> 338 | I32: =GETPIVOTDATA(""&$C32,Control!$A$17,"Day",I$28) -> 212 | J32: =GETPIVOTDATA(""&$C32,Control!$A$17,"Day",J$28) -> 222 | L32: KPI 3 | M32: 0.5 | N32: 0.45 | O32: =GETPIVOTDATA("Average of KPI 3",Control!$A$3) -> 0.65309589
A33: =IF(ROW()<=ROUND($D$2*100,0),"",$C$2) | B33: =IF(ROW()<=ROUND($D$2*100,0),$C$2,"") -> █ | C33: Recruiter 4 | D33: =GETPIVOTDATA(""&$C33,Control!$A$17,"Day",D$28) -> 192 | E33: =GETPIVOTDATA(""&$C33,Control!$A$17,"Day",E$28) -> 320 | F33: =GETPIVOTDATA(""&$C33,Control!$A$17,"Day",F$28) -> 340 | G33: =GETPIVOTDATA(""&$C33,Control!$A$17,"Day",G$28) -> 336 | H33: =GETPIVOTDATA(""&$C33,Control!$A$17,"Day",H$28) -> 300 | I33: =GETPIVOTDATA(""&$C33,Control!$A$17,"Day",I$28) -> 205 | J33: =GETPIVOTDATA(""&$C33,Control!$A$17,"Day",J$28) -> 216
A34: =IF(ROW()<=ROUND($D$2*100,0),"",$C$2) | B34: =IF(ROW()<=ROUND($D$2*100,0),$C$2,"") -> █ | C34: Recruiter 5 | D34: =GETPIVOTDATA(""&$C34,Control!$A$17,"Day",D$28) -> 210 | E34: =GETPIVOTDATA(""&$C34,Control!$A$17,"Day",E$28) -> 309 | F34: =GETPIVOTDATA(""&$C34,Control!$A$17,"Day",F$28) -> 343 | G34: =GETPIVOTDATA(""&$C34,Control!$A$17,"Day",G$28) -> 343 | H34: =GETPIVOTDATA(""&$C34,Control!$A$17,"Day",H$28) -> 319 | I34: =GETPIVOTDATA(""&$C34,Control!$A$17,"Day",I$28) -> 216 | J34: =GETPIVOTDATA(""&$C34,Control!$A$17,"Day",J$28) -> 215
A35: =IF(ROW()<=ROUND($D$2*100,0),"",$C$2) | B35: =IF(ROW()<=ROUND($D$2*100,0),$C$2,"") -> █ | C35: Top | D35: =SUM(D30:D34) -> 1047 | E35: =SUM(E30:E34) -> 1655 | F35: =SUM(F30:F34) -> 1702 | G35: =SUM(G30:G34) -> 1727 | H35: =SUM(H30:H34) -> 1651 | I35: =SUM(I30:I34) -> 1081 | J35: =SUM(J30:J34) -> 1097
A36: =IF(ROW()<=ROUND($D$2*100,0),"",$C$2) | B36: =IF(ROW()<=ROUND($D$2*100,0),$C$2,"") -> █ | C36: Down | D36: 0 | E36: 0 | F36: 0 | G36: 0 | H36: 0 | I36: 0 | J36: 0
A37: =IF(ROW()<=ROUND($D$2*100,0),"",$C$2) | B37: =IF(ROW()<=ROUND($D$2*100,0),$C$2,"") -> █ | C37: Y | D37: =IF(ISNUMBER(GETPIVOTDATA("Average of PRESENCE",Control!$A$3,"Day",D28)),D35,NA()) -> 1047 | E37: =IF(ISNUMBER(GETPIVOTDATA("Average of PRESENCE",Control!$A$3,"Day",E28)),E35,NA()) -> 1655 | F37: =IF(ISNUMBER(GETPIVOTDATA("Average of PRESENCE",Control!$A$3,"Day",F28)),F35,NA()) -> 1702 | G37: =IF(ISNUMBER(GETPIVOTDATA("Average of PRESENCE",Control!$A$3,"Day",G28)),G35,NA()) -> 1727 | H37: =IF(ISNUMBER(GETPIVOTDATA("Average of PRESENCE",Control!$A$3,"Day",H28)),H35,NA()) -> 1651 | I37: =IF(ISNUMBER(GETPIVOTDATA("Average of PRESENCE",Control!$A$3,"Day",I28)),I35,NA()) -> 1081 | J37: =IF(ISNUMBER(GETPIVOTDATA("Average of PRESENCE",Control!$A$3,"Day",J28)),J35,NA()) -> 1097
A38: =IF(ROW()<=ROUND($D$2*100,0),"",$C$2) | B38: =IF(ROW()<=ROUND($D$2*100,0),$C$2,"") -> █ | C38: Cursor | D38: 1 | E38: 2 | F38: 3 | G38: 4 | H38: 5 | I38: 6 | J38: 7
A39: =IF(ROW()<=ROUND($D$2*100,0),"",$C$2) | B39: =IF(ROW()<=ROUND($D$2*100,0),$C$2,"") -> █
A40: =IF(ROW()<=ROUND($D$2*100,0),"",$C$2) | B40: =IF(ROW()<=ROUND($D$2*100,0),$C$2,"") -> █ | D40: Top 3 Employee Productivity | L40: Loss of Working Time
...

Sheet Control
A1: Month | B1: (All)
A3: Row Labels | B3: Average of PRESENCE | C3: Average of EER | D3: Average of ESR | E3: Sum of Top-1 | F3: Sum of Top-2 | G3: Sum of Top-3 | H3: Sum of Sales Plan | I3: Average of KPI 1 | J3: Average of KPI 2 | K3: Average of KPI 3 | L3: Average of Loss of Working Time | M3: Average of General Productivity | N3: Average of Filling Vacancies | O3: Average of Adaptation | P3: Average of Education
A4: Sunday | B4: 0.29557692 | C4: 0.60807692 | D4: 0.63307692 | E4: 99676 | F4: 90789 | G4: 76297.5 | H4: 176808 | I4: 0.62634615 | J4: 0.73173077 | K4: 0.64153846 | L4: 0.054230769 | M4: 0.30597346 | N4: 0.30695192 | O4: 0.32201654 | P4: 0.28895192
A5: Monday | B5: 0.79115385 | C5: 0.64846154 | D5: 0.60769231 | E5: 96904 | F5: 87683 | G5: 74446.5 | H5: 171883 | I5: 0.72038462 | J5: 0.66961538 | K5: 0.71615385 | L5: 0.058269231 | M5: 0.66732308 | N5: 0.72173077 | O5: 0.64908462 | P5: 0.63115385
A6: Tuesday | B6: 0.79346154 | C6: 0.62115385 | D6: 0.62846154 | E6: 88466 | F6: 80601 | G6: 70033.5 | H6: 149131 | I6: 0.66807692 | J6: 0.68557692 | K6: 0.58634615 | L6: 0.0625 | M6: 0.68167692 | N6: 0.70961538 | O6: 0.68868462 | P6: 0.64673077
A7: Wednesday | B7: 0.80113208 | C7: 0.63962264 | D7: 0.65358491 | E7: 94923 | F7: 83472 | G7: 71179.5 | H7: 165475 | I7: 0.70566038 | J7: 0.6845283 | K7: 0.67566038 | L7: 0.059056604 | M7: 0.66174088 | N7: 0.68698113 | O7: 0.69710943 | P7: 0.60113208
A8: Thursday | B8: 0.77961538 | C8: 0.66403846 | D8: 0.62538462 | E8: 96987 | F8: 72178 | G8: 66891 | H8: 159320 | I8: 0.73153846 | J8: 0.61865385 | K8: 0.64942308 | L8: 0.054615385 | M8: 0.68208718 | N8: 0.69288462 | O8: 0.73183846 | P8: 0.62153846
A9: Friday | B9: 0.78711538 | C9: 0.59403846 | D9: 0.62576923 | E9: 91258 | F9: 90802 | G9: 61090.5 | H9: 165573 | I9: 0.635 | J9: 0.67423077 | K9: 0.69865385 | L9: 0.055 | M9: 0.68903077 | N9: 0.72980769 | O9: 0.7194 | P9: 0.61788462
A10: Saturday | B10: 0.26461538 | C10: 0.64942308 | D10: 0.63307692 | E10: 97338 | F10: 83365 | G10: 69882 | H10: 176140 | I10: 0.66980769 | J10: 0.70807692 | K10: 0.60346154 | L10: 0.054038462 | M10: 0.30947769 | N10: 0.31958654 | O10: 0.30933692 | P10: 0.29950962
A11: Grand Total | B11: 0.64509589 | C11: 0.63213699 | D11: 0.62964384 | E11: 665552 | F11: 588890 | G11: 489820.5 | H11: 1164330 | I11: 0.67961644 | J11: 0.68178082 | K11: 0.65309589 | L11: 0.056821918 | M11: 0.57129277 | N11: 0.59561644 | O11: 0.58850844 | P11: 0.52975342
A15: Month | B15: (All)
A17: Row Labels | B17: Sum of Vacancies | C17: Sum of Resumes | D17: Sum of Recruiter 1 | E17: Sum of Recruiter 2 | F17: Sum of Recruiter 3 | G17: Sum of Recruiter 4 | H17: Sum of Recruiter 5 | I17: Sum of Rang 1 | J17: Sum of Rang 2 | K17: Sum of Rang 3
A18: Sunday | B18: 1254 | C18: 1288 | D18: 197 | E18: 219 | F18: 229 | G18: 192 | H18: 210 | I18: 4585 | J18: 3353 | K18: 1412
A19: Monday | B19: 1219 | C19: 1179 | D19: 306 | E19: 358 | F19: 362 | G19: 320 | H19: 309 | I19: 4651 | J19: 3440 | K19: 1489
A20: Tuesday | B20: 1130 | C20: 1050 | D20: 331 | E20: 315 | F20: 373 | G20: 340 | H20: 343 | I20: 4645 | J20: 3422 | K20: 1397
A21: Wednesday | B21: 1072 | C21: 1096 | D21: 343 | E21: 360 | F21: 345 | G21: 336 | H21: 343 | I21: 4743 | J21: 3474 | K21: 1544
A22: Thursday | B22: 1226 | C22: 1095 | D22: 345 | E22: 349 | F22: 338 | G22: 300 | H22: 319 | I22: 4571 | J22: 3267 | K22: 1528
A23: Friday | B23: 1108 | C23: 1240 | D23: 227 | E23: 221 | F23: 212 | G23: 205 | H23: 216 | I23: 4614 | J23: 3382 | K23: 1486
A24: Saturday | B24: 1208 | C24: 1135 | D24: 209 | E24: 235 | F24: 222 | G24: 216 | H24: 215 | I24: 4686 | J24: 3397 | K24: 1405
A25: Grand Total | B25: 8217 | C25: 8083 | D25: 1958 | E25: 2057 | F25: 2081 | G25: 1909 | H25: 1955 | I25: 32495 | J25: 23735 | K25: 10261

Sheet Data
A1: Date | B1: Month | C1: Week | D1: Day | E1: PRESENCE | F1: EER | G1: ESR | H1: Vacancies | I1: Resumes | J1: Recruiter 1 | K1: Recruiter 2 | L1: Recruiter 3 | M1: Recruiter 4 | N1: Recruiter 5 | O1: Top-1 | P1: Top-2 | Q1: Top-3 | R1: Sales Plan | S1: KPI 1 | T1: KPI 2 | U1: KPI 3 | V1: Loss of Working Time | W1: Filling Vacancies | X1: Adaptation | Y1: Education | Z1: Rang 1 | AA1: Rang 2 | AB1: Rang 3 | AC1: General Productivity
A2: 45658 | B2: JAN | C2: =WEEKNUM(A2, 2)-WEEKNUM(DATE(YEAR(A2),MONTH(A2),1),2) +1 -> 1 | D2: Wednesday | E2: 0.84 | F2: 0.66 | G2: 0.86 | H2: 28 | I2: 15 | J2: 1 | K2: 4 | L2: 5 | M2: 9 | N2: 7 | O2: 3305 | P2: 133 | Q2: 2067 | R2: 4891 | S2: 0.53 | T2: 0.3 | U2: 0.67 | V2: 0.03 | W2: 0.91 | X2: 0.7788 | Y2: 0.6 | Z2: 98 | AA2: 66 | AB2: 23 | AC2: =AVERAGE(W2:Y2) -> 0.76293333
A3: 45659 | B3: JAN | C3: =WEEKNUM(A3, 2)-WEEKNUM(DATE(YEAR(A3),MONTH(A3),1),2) +1 -> 1 | D3: Thursday | E3: 0.92 | F3: 0.75 | G3: 0.8 | H3: 9 | I3: 8 | J3: 11 | K3: 6 | L3: 12 | M3: 2 | N3: 7 | O3: 2880 | P3: 423 | Q3: 715.5 | R3: 4224 | S3: 0.63 | T3: 0.44 | U3: 0.59 | V3: 0.01 | W3: 0.83 | X3: 0.9108 | Y3: 0.68 | Z3: 89 | AA3: 64 | AB3: 10 | AC3: =AVERAGE(W3:Y3) -> 0.80693333
A4: 45660 | B4: JAN | C4: =WEEKNUM(A4, 2)-WEEKNUM(DATE(YEAR(A4),MONTH(A4),1),2) +1 -> 1 | D4: Friday | E4: 0.86 | F4: 0.44 | G4: 0.68 | H4: 11 | I4: 12 | J4: 2 | K4: 4 | L4: 2 | M4: 2 | N4: 2 | O4: 1812 | P4: 664 | Q4: 378 | R4: 2512 | S4: 0.54 | T4: 1.04 | U4: 1 | V4: 0.1 | W4: 0.89 | X4: 0.8184 | Y4: 0.54 | Z4: 80 | AA4: 56 | AB4: 29 | AC4: =AVERAGE(W4:Y4) -> 0.74946667
A5: 45661 | B5: JAN | C5: =WEEKNUM(A5, 2)-WEEKNUM(DATE(YEAR(A5),MONTH(A5),1),2) +1 -> 1 | D5: Saturday | E5: 0.27 | F5: 0.56 | G5: 0.47 | H5: 9 | I5: 18 | J5: 2 | K5: 2 | L5: 4 | M5: 4 | N5: 2 | O5: 3385 | P5: 2054 | Q5: 252 | R5: 4468 | S5: 0.37 | T5: 0.53 | U5: 1.02 | V5: 0.09 | W5: 0.423 | X5: 0.43956 | Y5: 0.261 | Z5: 85 | AA5: 57 | AB5: 11 | AC5: =AVERAGE(W5:Y5) -> 0.37452
A6: 45662 | B6: JAN | C6: =WEEKNUM(A6, 2)-WEEKNUM(DATE(YEAR(A6),MONTH(A6),1),2) +1 -> 1 | D6: Sunday | E6: 0.38 | F6: 0.63 | G6: 0.89 | H6: 40 | I6: 40 | J6: 5 | K6: 2 | L6: 2 | M6: 2 | N6: 2 | O6: 1330 | P6: 124 | Q6: 141 | R6: 2394 | S6: 1 | T6: 1.2 | U6: 0.43 | V6: 0.09 | W6: 0.351 | X6: 0.19602 | Y6: 0.3015 | Z6: 85 | AA6: 57 | AB6: 34 | AC6: =AVERAGE(W6:Y6) -> 0.28284
A7: 45663 | B7: JAN | C7: =WEEKNUM(A7, 2)-WEEKNUM(DATE(YEAR(A7),MONTH(A7),1),2) +1 -> 2 | D7: Monday | E7: 0.72 | F7: 0.67 | G7: 0.42 | H7: 6 | I7: 18 | J7: 7 | K7: 5 | L7: 2 | M7: 2 | N7: 5 | O7: 2485 | P7: 2595 | Q7: 1383 | R7: 3844 | S7: 1.06 | T7: 0.62 | U7: 0.26 | V7: 0.04 | W7: 0.93 | X7: 0.4884 | Y7: 0.71 | Z7: 100 | AA7: 72 | AB7: 28 | AC7: =AVERAGE(W7:Y7) -> 0.70946667
A8: 45664 | B8: JAN | C8: =WEEKNUM(A8, 2)-WEEKNUM(DATE(YEAR(A8),MONTH(A8),1),2) +1 -> 2 | D8: Tuesday | E8: 0.91 | F8: 0.54 | G8: 0.38 | H8: 37 | I8: 20 | J8: 2 | K8: 2 | L8: 12 | M8: 6 | N8: 1 | O8: 49 | P8: 2661 | Q8: 2313 | R8: 2927 | S8: 0.83 | T8: 1.13 | U8: 0.35 | V8: 0.1 | W8: 0.94 | X8: 0.4884 | Y8: 0.79 | Z8: 97 | AA8: 65 | AB8: 22 | AC8: =AVERAGE(W8:Y8) -> 0.73946667
A9: 45665 | B9: JAN | C9: =WEEKNUM(A9, 2)-WEEKNUM(DATE(YEAR(A9),MONTH(A9),1),2) +1 -> 2 | D9: Wednesday | E9: 0.98 | F9: 0.69 | G9: 0.83 | H9: 32 | I9: 32 | J9: 5 | K9: 4 | L9: 3 | M9: 11 | N9: 8 | O9: 2251 | P9: 2871 | Q9: 1828.5 | R9: 3158 | S9: 0.61 | T9: 0.67 | U9: 0.84 | V9: 0.03 | W9: 0.67 | X9: 0.4356 | Y9: 0.86 | Z9: 82 | AA9: 62 | AB9: 36 | AC9: =AVERAGE(W9:Y9) -> 0.6552
A10: 45666 | B10: JAN | C10: =WEEKNUM(A10, 2)-WEEKNUM(DATE(YEAR(A10),MONTH(A10),1),2) +1 -> 2 | D10: Thursday | E10: 0.76 | F10: 0.83 | G10: 0.82 | H10: 7 | I10: 33 | J10: 2 | K10: 2 | L10: 11 | M10: 9 | N10: 2 | O10: 2354 | P10: 131 | Q10: 1192.5 | R10: 3295 | S10: 0.49 | T10: 0.69 | U10: 0.42 | V10: 0.02 | W10: 0.67 | X10: 0.6864 | Y10: 0.87 | Z10: 78 | AA10: 65 | AB10: 14 | AC10: =AVERAGE(W10:Y10) -> 0.74213333
A11: 45667 | B11: JAN | C11: =WEEKNUM(A11, 2)-WEEKNUM(DATE(YEAR(A11),MONTH(A11),1),2) +1 -> 2 | D11: Friday | E11: 0.77 | F11: 0.69 | G11: 0.8 | H11: 20 | I11: 10 | J11: 2 | K11: 6 | L11: 7 | M11: 3 | N11: 4 | O11: 135 | P11: 168 | Q11: 414 | R11: 455 | S11: 0.91 | T11: 0.63 | U11: 0.71 | V11: 0.08 | W11: 0.49 | X11: 0.6864 | Y11: 0.89 | Z11: 95 | AA11: 80 | AB11: 36 | AC11: =AVERAGE(W11:Y11) -> 0.6888
A12: 45668 | B12: JAN | C12: =WEEKNUM(A12, 2)-WEEKNUM(DATE(YEAR(A12),MONTH(A12),1),2) +1 -> 2 | D12: Saturday | E12: 0.39 | F12: 0.54 | G12: 0.87 | H12: 19 | I12: 22 | J12: 7 | K12: 2 | L12: 8 | M12: 3 | N12: 2 | O12: 2811 | P12: 684 | Q12: 240 | R12: 4986 | S12: 0.15 | T12: 0.18 | U12: 0.8 | V12: 0.01 | W12: 0.387 | X12: 0.32076 | Y12: 0.3105 | Z12: 79 | AA12: 78 | AB12: 23 | AC12: =AVERAGE(W12:Y12) -> 0.33942
A13: 45669 | B13: JAN | C13: =WEEKNUM(A13, 2)-WEEKNUM(DATE(YEAR(A13),MONTH(A13),1),2) +1 -> 2 | D13: Sunday | E13: 0.37 | F13: 0.8 | G13: 0.82 | H13: 35 | I13: 35 | J13: 1 | K13: 1 | L13: 7 | M13: 7 | N13: 6 | O13: 2554 | P13: 1719 | Q13: 2637 | R13: 3406 | S13: 0.43 | T13: 0.85 | U13: 0.87 | V13: 0.08 | W13: 0.3555 | X13: 0.297 | Y13: 0.3285 | Z13: 89 | AA13: 51 | AB13: 33 | AC13: =AVERAGE(W13:Y13) -> 0.327
... A366: 46022 | B366: DEC | C366: =WEEKNUM(A366, 2)-WEEKNUM(DATE(YEAR(A366),MONTH(A366),1),2) +1 -> 5 | D366: Wednesday | E366: 0.86 | F366: 0.55 | G366: 0.82 | H366: 33 | I366: 13 | J366: 12 | K366: 5 | L366: 2 | M366: 2 | N366: 11 | O366: 642 | P366: 304 | Q366: 1887 | R366: 2075 | S366: 1.11 | T366: 0.6 | U366: 0.54 | V366: 0.07 | W366: 0.51 | X366: 0.5676 | Y366: 0.6 | Z366: 90 | AA366: 57 | AB366: 39 | AC366: =AVERAGE(W366:Y366) -> 0.5592

Sheet Resources
