Workbook
Name Slicer_Drivers: #N/A
Name Slicer_Month: #N/A
Name Slicer_Routes: #N/A

Sheet DASHBOARD

Sheet Routes
P21: TOTAL
E22: Month | F22: Route1 | H22: Route2 | J22: Route3 | L22: Route4 | N22: Route5
F23: $ Cagro | G23: Millage | H23: $ Cagro | I23: Millage | J23: $ Cagro | K23: Millage | L23: $ Cagro | M23: Millage | N23: $ Cagro | O23: Millage | P23: Value of Cargo | R23: Millage
E24: =Control!A61 -> JAN | F24: =Control!M61 -> 14718.373 | G24: =Control!N61 -> 5318 | H24: =Control!O61 -> 27778.107 | I24: =Control!P61 -> 7355 | J24: =Control!Q61 -> 24332.058 | K24: =Control!R61 -> 4600 | L24: =Control!S61 -> 18480.148 | M24: =Control!T61 -> 1845 | ... O24: =Control!V61 -> 3921 | P24: =F24+H24+J24+L24+N24 -> 117212.47 | R24: =G24+I24+K24+M24+O24 -> 23039
E25: =Control!A62 -> FEB | F25: =Control!M62 -> 15749.374 | G25: =Control!N62 -> 4174 | H25: =Control!O62 -> 11399.888 | I25: =Control!P62 -> 4939 | J25: =Control!Q62 -> 17542.596 | K25: =Control!R62 -> 4400 | L25: =Control!S62 -> 14087.113 | M25: =Control!T62 -> 3861 | ... O25: =Control!V62 -> 4719 | P25: =F25+H25+J25+L25+N25 -> 76186.763 | R25: =G25+I25+K25+M25+O25 -> 22093
E26: =Control!A63 -> MAR | F26: =Control!M63 -> 23156.139 | G26: =Control!N63 -> 8196 | H26: =Control!O63 -> 26640.43 | I26: =Control!P63 -> 7958 | J26: =Control!Q63 -> 19944.036 | K26: =Control!R63 -> 8705 | L26: =Control!S63 -> 30876.118 | M26: =Control!T63 -> 9242 | ... O26: =Control!V63 -> 9004 | P26: =F26+H26+J26+L26+N26 -> 131729.34 | R26: =G26+I26+K26+M26+O26 -> 43105
E27: =Control!A64 -> APR | F27: =Control!M64 -> 9745.555 | G27: =Control!N64 -> 3148 | H27: =Control!O64 -> 13800.269 | I27: =Control!P64 -> 1386 | J27: =Control!Q64 -> 10946.775 | K27: =Control!R64 -> 3400 | L27: =Control!S64 -> 8468.0136 | M27: =Control!T64 -> 5414 | ... O27: =Control!V64 -> 3744 | P27: =F27+H27+J27+L27+N27 -> 49381.071 | R27: =G27+I27+K27+M27+O27 -> 17092
E28: =Control!A65 -> MAY | F28: =Control!M65 -> 12202.46 | G28: =Control!N65 -> 1374 | H28: =Control!O65 -> 7910.7382 | I28: =Control!P65 -> 3206 | J28: =Control!Q65 -> 14048.925 | K28: =Control!R65 -> 2400 | L28: =Control!S65 -> 19582.389 | M28: =Control!T65 -> 1594 | ... O28: =Control!V65 -> 3615 | P28: =F28+H28+J28+L28+N28 -> 71678.926 | R28: =G28+I28+K28+M28+O28 -> 12189
E29: =Control!A66 -> JUN | F29: =Control!M66 -> 26951.441 | G29: =Control!N66 -> 7177 | H29: =Control!O66 -> 30705.946 | I29: =Control!P66 -> 3359 | J29: =Control!Q66 -> 32349.906 | K29: =Control!R66 -> 10011 | L29: =Control!S66 -> 36281.922 | M29: =Control!T66 -> 16722 | ... O29: =Control!V66 -> 12823 | P29: =F29+H29+J29+L29+N29 -> 163223.66 | R29: =G29+I29+K29+M29+O29 -> 50092
E30: =Control!A67 -> JUL | F30: =Control!M67 -> 15124.671 | G30: =Control!N67 -> 4062 | H30: =Control!O67 -> 10570.07 | I30: =Control!P67 -> 4982 | J30: =Control!Q67 -> 16047.018 | K30: =Control!R67 -> 3805 | L30: =Control!S67 -> 13598.701 | M30: =Control!T67 -> 2618 | ... O30: =Control!V67 -> 3558 | P30: =F30+H30+J30+L30+N30 -> 66402.267 | R30: =G30+I30+K30+M30+O30 -> 19025
E31: =Control!A68 -> AUG | F31: =Control!M68 -> 20616.152 | G31: =Control!N68 -> 3816 | H31: =Control!O68 -> 13439.244 | I31: =Control!P68 -> 5464 | J31: =Control!Q68 -> 19472.594 | K31: =Control!R68 -> 6600 | L31: =Control!S68 -> 18706.249 | M31: =Control!T68 -> 7736 | ... O31: =Control!V68 -> 9594 | P31: =F31+H31+J31+L31+N31 -> 80157.401 | R31: =G31+I31+K31+M31+O31 -> 33210
E32: =Control!A69 -> SEP | F32: =Control!M69 -> 11007.383 | G32: =Control!N69 -> 821 | H32: =Control!O69 -> 17293.678 | I32: =Control!P69 -> 3406 | J32: =Control!Q69 -> 5193.7405 | K32: =Control!R69 -> 2001 | L32: =Control!S69 -> 10423.883 | M32: =Control!T69 -> 594 | ... O32: =Control!V69 -> 3303 | P32: =F32+H32+J32+L32+N32 -> 54380.463 | R32: =G32+I32+K32+M32+O32 -> 10125
E33: =Control!A70 -> OCT | F33: =Control!M70 -> 22461.855 | G33: =Control!N70 -> 12065 | H33: =Control!O70 -> 26172.862 | I33: =Control!P70 -> 9156 | J33: =Control!Q70 -> 33630.81 | K33: =Control!R70 -> 9140 | L33: =Control!S70 -> 26933.662 | M33: =Control!T70 -> 8844 | ... O33: =Control!V70 -> 5935 | P33: =F33+H33+J33+L33+N33 -> 139617.14 | R33: =G33+I33+K33+M33+O33 -> 45140
E34: =Control!A71 -> NOV | F34: =Control!M71 -> 5798.1311 | G34: =Control!N71 -> 3447 | H34: =Control!O71 -> 19222.517 | I34: =Control!P71 -> 1383 | J34: =Control!Q71 -> 13369.852 | K34: =Control!R71 -> 2601 | L34: =Control!S71 -> 3129.1807 | M34: =Control!T71 -> 2928 | ... O34: =Control!V71 -> 2753 | P34: =F34+H34+J34+L34+N34 -> 64125.341 | R34: =G34+I34+K34+M34+O34 -> 13112
E35: =Control!A72 -> DEC | F35: =Control!M72 -> 13303.554 | G35: =Control!N72 -> 1975 | H35: =Control!O72 -> 16623.857 | I35: =Control!P72 -> 2698 | J35: =Control!Q72 -> 13168.751 | K35: =Control!R72 -> 3472 | L35: =Control!S72 -> 19311.082 | M35: =Control!T72 -> 4102 | ... O35: =Control!V72 -> 4865 | P35: =F35+H35+J35+L35+N35 -> 77293.34 | R35: =G35+I35+K35+M35+O35 -> 17112

Sheet Processing
A1: =B1 -> 2 | B1: 2 | C1: 1 | F1: Cars | G1: =IF($N$26=1,10,0) -> 0 | H1: =IF($N$26=2,10,0) -> 0 | I1: =IF($N$26=3,10,0) -> 10
C2: Value of Сargo by Month ($ thous.) | F2: Colors | G2: =IF(G22,10,0) -> 0 | H2: =IF(G23,10,0) -> 0 | I2: =IF(G24,10,0) -> 0 | J2: =IF(G25,10,0) -> 0 | K2: =IF(G26,10,0) -> 0 | L2: =IF(G27,10,0) -> 0
A3: 1 | B3: JAN | C3: =Control!F2 -> 117 | D3: =IF(ISNA(MATCH($B3,Control!$A$31:$A$42,0)),NA(),C3) -> 117 | F3: Labels | G3: VisibleD | H3: VisibleR | I3: CodeR1 | J3: CodeR2 | K3: CodeR3 | L3: CodeR4 | M3: CodeR5 | N3: Result | O3: CheckR1 | P3: CheckR2 | Q3: CheckR3 | R3: CheckR4 | S3: CheckR5
A4: 2 | B4: FEB | C4: =Control!F3 -> 76 | D4: =IF(ISNA(MATCH($B4,Control!$A$31:$A$42,0)),NA(),C4) -> 76 | F4: =IF(G17,F17&CHAR(10),"")&IF(G18,F18&CHAR(10),"")&IF(G19,F19&CHAR(10),"")&IF(G20,F20&CHAR(10),"")&IF(G21,F21,"") -> Route 1 Route 2 Route 3 Route 4 Route 5 | G4: =IF(N4,"",$F$10) -> | | H4: =IF(N4,$F$10,"") | I4: 1 | J4: 1 | K4: 0 | L4: 0 | M4: 1 | N4: =O4*P4*Q4*R4*S4 -> 0 | O4: =IF($G$17,I4,1) -> 1 | P4: =IF($G$18,J4,1) -> 1 | Q4: =IF($G$19,K4,1) -> 0 | R4: =IF($G$20,L4,1) -> 0 | S4: =IF($G$21,M4,1) -> 1
A5: 3 | B5: MAR | C5: =Control!F4 -> 132 | D5: =IF(ISNA(MATCH($B5,Control!$A$31:$A$42,0)),NA(),C5) -> 132 | F5: =IF(K23,J23&CHAR(10),"")&IF(K24,J24&CHAR(10),"")&IF(K25,J25&CHAR(10),"") -> Driver 1 Driver 2 Driver 3 | G5: =IF(N5,"",$F$10) -> | | H5: =IF(N5,$F$10,"") | I5: 1 | J5: 1 | K5: 1 | L5: 0 | M5: 1 | N5: =O5*P5*Q5*R5*S5 -> 0 | O5: =IF($G$17,I5,1) -> 1 | P5: =IF($G$18,J5,1) -> 1 | Q5: =IF($G$19,K5,1) -> 1 | R5: =IF($G$20,L5,1) -> 0 | S5: =IF($G$21,M5,1) -> 1
A6: 4 | B6: APR | C6: =Control!F5 -> 49 | D6: =IF(ISNA(MATCH($B6,Control!$A$31:$A$42,0)),NA(),C6) -> 49 | G6: =IF(N6,"",$F$10) -> | | H6: =IF(N6,$F$10,"") | I6: 1 | J6: 1 | K6: 0 | L6: 1 | M6: 1 | N6: =O6*P6*Q6*R6*S6 -> 0 | O6: =IF($G$17,I6,1) -> 1 | P6: =IF($G$18,J6,1) -> 1 | Q6: =IF($G$19,K6,1) -> 0 | R6: =IF($G$20,L6,1) -> 1 | S6: =IF($G$21,M6,1) -> 1
A7: 5 | B7: MAY | C7: =Control!F6 -> 72 | D7: =IF(ISNA(MATCH($B7,Control!$A$31:$A$42,0)),NA(),C7) -> 72 | G7: =IF(N7,"",$F$10) -> | | H7: =IF(N7,$F$10,"") | I7: 1 | J7: 0 | K7: 1 | L7: 0 | M7: 1 | N7: =O7*P7*Q7*R7*S7 -> 0 | O7: =IF($G$17,I7,1) -> 1 | P7: =IF($G$18,J7,1) -> 0 | Q7: =IF($G$19,K7,1) -> 1 | R7: =IF($G$20,L7,1) -> 0 | S7: =IF($G$21,M7,1) -> 1
A8: 6 | B8: JUN | C8: =Control!F7 -> 163 | D8: =IF(ISNA(MATCH($B8,Control!$A$31:$A$42,0)),NA(),C8) -> 163 | G8: =IF(N8,"",$F$10) -> | | H8: =IF(N8,$F$10,"") | I8: 0 | J8: 1 | K8: 0 | L8: 1 | M8: 0 | N8: =O8*P8*Q8*R8*S8 -> 0 | O8: =IF($G$17,I8,1) -> 0 | P8: =IF($G$18,J8,1) -> 1 | Q8: =IF($G$19,K8,1) -> 0 | R8: =IF($G$20,L8,1) -> 1 | S8: =IF($G$21,M8,1) -> 0
A9: 7 | B9: JUL | C9: =Control!F8 -> 66 | D9: =IF(ISNA(MATCH($B9,Control!$A$31:$A$42,0)),NA(),C9) -> 66 | F9: Symbols | G9: =IF(N9,"",$F$10) -> | | H9: =IF(N9,$F$10,"") | I9: 1 | J9: 1 | K9: 0 | L9: 1 | M9: 0 | N9: =O9*P9*Q9*R9*S9 -> 0 | O9: =IF($G$17,I9,1) -> 1 | P9: =IF($G$18,J9,1) -> 1 | Q9: =IF($G$19,K9,1) -> 0 | R9: =IF($G$20,L9,1) -> 1 | S9: =IF($G$21,M9,1) -> 0
A10: 8 | B10: AUG | C10: =Control!F9 -> 80 | D10: =IF(ISNA(MATCH($B10,Control!$A$31:$A$42,0)),NA(),C10) -> 80 | F10: | | G10: =IF(N10,"",$F$10) -> | | H10: =IF(N10,$F$10,"") | I10: 0 | J10: 0 | K10: 1 | L10: 1 | M10: 0 | N10: =O10*P10*Q10*R10*S10 -> 0 | O10: =IF($G$17,I10,1) -> 0 | P10: =IF($G$18,J10,1) -> 0 | Q10: =IF($G$19,K10,1) -> 1 | R10: =IF($G$20,L10,1) -> 1 | S10: =IF($G$21,M10,1) -> 0
A11: 9 | B11: SEP | C11: =Control!F10 -> 54 | D11: =IF(ISNA(MATCH($B11,Control!$A$31:$A$42,0)),NA(),C11) -> 54 | F11: ○ | G11: =IF(N11,"",$F$10) -> | | H11: =IF(N11,$F$10,"") | I11: 1 | J11: 0 | K11: 0 | L11: 1 | M11: 0 | N11: =O11*P11*Q11*R11*S11 -> 0 | O11: =IF($G$17,I11,1) -> 1 | P11: =IF($G$18,J11,1) -> 0 | Q11: =IF($G$19,K11,1) -> 0 | R11: =IF($G$20,L11,1) -> 1 | S11: =IF($G$21,M11,1) -> 0
A12: 10 | B12: OCT | C12: =Control!F11 -> 140 | D12: =IF(ISNA(MATCH($B12,Control!$A$31:$A$42,0)),NA(),C12) -> 140 | F12: • | G12: =IF(N12,"",$F$10) -> | | H12: =IF(N12,$F$10,"") | I12: 0 | J12: 1 | K12: 1 | L12: 1 | M12: 1 | N12: =O12*P12*Q12*R12*S12 -> 0 | O12: =IF($G$17,I12,1) -> 0 | P12: =IF($G$18,J12,1) -> 1 | Q12: =IF($G$19,K12,1) -> 1 | R12: =IF($G$20,L12,1) -> 1 | S12: =IF($G$21,M12,1) -> 1
A13: 11 | B13: NOV | C13: =Control!F12 -> 64 | D13: =IF(ISNA(MATCH($B13,Control!$A$31:$A$42,0)),NA(),C13) -> 64 | F13: ⬛ | G13: =IF(N13,"",$F$10) -> | | H13: =IF(N13,$F$10,"") | I13: 0 | J13: 0 | K13: 0 | L13: 1 | M13: 0 | N13: =O13*P13*Q13*R13*S13 -> 0 | O13: =IF($G$17,I13,1) -> 0 | P13: =IF($G$18,J13,1) -> 0 | Q13: =IF($G$19,K13,1) -> 0 | R13: =IF($G$20,L13,1) -> 1 | S13: =IF($G$21,M13,1) -> 0
A14: 12 | B14: DEC | C14: =Control!F13 -> 77 | D14: =IF(ISNA(MATCH($B14,Control!$A$31:$A$42,0)),NA(),C14) -> 77 | H14: =IF(N14,"",$F$12) -> • | I14: 0 | J14: 0 | K14: 0 | L14: 0 | M14: 0 | N14: =O14*P14*Q14*R14*S14 -> 0 | O14: =IF($G$17,I14,1) -> 0 | P14: =IF($G$18,J14,1) -> 0 | Q14: =IF($G$19,K14,1) -> 0 | R14: =IF($G$20,L14,1) -> 0 | S14: =IF($G$21,M14,1) -> 0
H15: =IF(N15,"",$F$12) -> • | I15: 1 | J15: 1 | K15: 0 | L15: 0 | M15: 1 | N15: =O15*P15*Q15*R15*S15 -> 0 | O15: =IF($G$17,I15,1) -> 1 | P15: =IF($G$18,J15,1) -> 1 | Q15: =IF($G$19,K15,1) -> 0 | R15: =IF($G$20,L15,1) -> 0 | S15: =IF($G$21,M15,1) -> 1
C16: Mileage by Month (miles thous.) | F16: Select Options | H16: =IF(N16,"",$F$12) -> • | I16: 0 | J16: 0 | K16: 0 | L16: 1 | M16: 0 | N16: =O16*P16*Q16*R16*S16 -> 0 | O16: =IF($G$17,I16,1) -> 0 | P16: =IF($G$18,J16,1) -> 0 | Q16: =IF($G$19,K16,1) -> 0 | R16: =IF($G$20,L16,1) -> 1 | S16: =IF($G$21,M16,1) -> 0
A17: 1 | B17: JAN | C17: =Control!G2 -> 23 | D17: =IF(ISNA(MATCH($B17,Control!$A$31:$A$42,0)),NA(),C17) -> 23 | F17: Route 1 | G17: =IF(ISNA(MATCH(F17,Control!$A$47:$A$51,0)),FALSE,TRUE) -> TRUE | H17: =IF(N17,"",$F$12) -> • | I17: 0 | J17: 0 | K17: 0 | L17: 1 | M17: 0 | N17: =O17*P17*Q17*R17*S17 -> 0 | O17: =IF($G$17,I17,1) -> 0 | P17: =IF($G$18,J17,1) -> 0 | Q17: =IF($G$19,K17,1) -> 0 | R17: =IF($G$20,L17,1) -> 1 | S17: =IF($G$21,M17,1) -> 0
A18: 2 | B18: FEB | C18: =Control!G3 -> 22 | D18: =IF(ISNA(MATCH($B18,Control!$A$31:$A$42,0)),NA(),C18) -> 22 | F18: Route 2 | G18: =IF(ISNA(MATCH(F18,Control!$A$47:$A$51,0)),FALSE,TRUE) -> TRUE | H18: =IF(N18,"",$F$12) -> • | I18: 1 | J18: 0 | K18: 0 | L18: 0 | M18: 0 | N18: =O18*P18*Q18*R18*S18 -> 0 | O18: =IF($G$17,I18,1) -> 1 | P18: =IF($G$18,J18,1) -> 0 | Q18: =IF($G$19,K18,1) -> 0 | R18: =IF($G$20,L18,1) -> 0 | S18: =IF($G$21,M18,1) -> 0
A19: 3 | B19: MAR | C19: =Control!G4 -> 43 | D19: =IF(ISNA(MATCH($B19,Control!$A$31:$A$42,0)),NA(),C19) -> 43 | F19: Route 3 | G19: =IF(ISNA(MATCH(F19,Control!$A$47:$A$51,0)),FALSE,TRUE) -> TRUE | H19: =IF(N19,"",$F$12) -> • | I19: 0 | J19: 1 | K19: 0 | L19: 1 | M19: 0 | N19: =O19*P19*Q19*R19*S19 -> 0 | O19: =IF($G$17,I19,1) -> 0 | P19: =IF($G$18,J19,1) -> 1 | Q19: =IF($G$19,K19,1) -> 0 | R19: =IF($G$20,L19,1) -> 1 | S19: =IF($G$21,M19,1) -> 0
A20: 4 | B20: APR | C20: =Control!G5 -> 17 | D20: =IF(ISNA(MATCH($B20,Control!$A$31:$A$42,0)),NA(),C20) -> 17 | F20: Route 4 | G20: =IF(ISNA(MATCH(F20,Control!$A$47:$A$51,0)),FALSE,TRUE) -> TRUE | H20: =IF(N20,"",$F$12) -> • | I20: 0 | J20: 1 | K20: 0 | L20: 1 | M20: 0 | N20: =O20*P20*Q20*R20*S20 -> 0 | O20: =IF($G$17,I20,1) -> 0 | P20: =IF($G$18,J20,1) -> 1 | Q20: =IF($G$19,K20,1) -> 0 | R20: =IF($G$20,L20,1) -> 1 | S20: =IF($G$21,M20,1) -> 0
A21: 5 | B21: MAY | C21: =Control!G6 -> 12 | D21: =IF(ISNA(MATCH($B21,Control!$A$31:$A$42,0)),NA(),C21) -> 12 | F21: Route 5 | G21: =IF(ISNA(MATCH(F21,Control!$A$47:$A$51,0)),FALSE,TRUE) -> TRUE | H21: =IF(N21,"",$F$12) -> • | I21: 1 | J21: 0 | K21: 1 | L21: 0 | M21: 1 | N21: =O21*P21*Q21*R21*S21 -> 0 | O21: =IF($G$17,I21,1) -> 1 | P21: =IF($G$18,J21,1) -> 0 | Q21: =IF($G$19,K21,1) -> 1 | R21: =IF($G$20,L21,1) -> 0 | S21: =IF($G$21,M21,1) -> 1
A22: 6 | B22: JUN | C22: =Control!G7 -> 50 | D22: =IF(ISNA(MATCH($B22,Control!$A$31:$A$42,0)),NA(),C22) -> 50 | F22: Color1 | G22: FALSE | H22: =IF(G22,"",$F$12) -> • | J22: Select Drivers | L22: Cars | M22: Salary | P22: ='Input Value'!A1 -> Fuel Сonsumption Gallon per 100 mil | Q22: ='Input Value'!C1 -> Depreciation USD per 100 mil | S22: KPI
A23: 7 | B23: JUL | C23: =Control!G8 -> 19 | D23: =IF(ISNA(MATCH($B23,Control!$A$31:$A$42,0)),NA(),C23) -> 19 | F23: Color2 | G23: FALSE | H23: =IF(G23,"",$F$12) -> • | I23: 1 | J23: Driver 1 | K23: =IF(ISNA(MATCH($J23,Control!$A$21:$A$23,0)),FALSE,TRUE) -> TRUE | L23: ='Input Value'!A2 -> Mack Anthem | M23: =IF(K23,'Input Value'!F2/12*$D$69) -> 75000 | N23: =IF(K23,I23,0) -> 1 | O23: =IF(K23,"",$F$13) | P23: ='Input Value'!B2&"gal/100ml" -> 9,3gal/100ml | Q23: ='Input Value'!C2&"$/100ml" -> 25,05$/100ml | S23: =IFERROR(REPT("I",INT(IF(U23*10-10<0,U23*10,10))),"") -> IIIIIIIII | T23: =IFERROR(REPT("I",INT(U23*10-10)),"") | U23: =IFERROR(GETPIVOTDATA("KPI",Control!$A$53,"Drivers","Driver 1"),"") -> 0.95461272
A24: 8 | B24: AUG | C24: =Control!G9 -> 33 | D24: =IF(ISNA(MATCH($B24,Control!$A$31:$A$42,0)),NA(),C24) -> 33 | F24: Color3 | G24: FALSE | H24: =IF(G24,"",$F$12) -> • | I24: 2 | J24: Driver 2 | K24: =IF(ISNA(MATCH($J24,Control!$A$21:$A$23,0)),FALSE,TRUE) -> TRUE | L24: ='Input Value'!A3 -> DAF XF | M24: =IF(K24,'Input Value'!F3/12*$D$69) -> 65000 | N24: =IF(K24,I24,0) -> 2 | O24: =IF(K24,"",$F$13) | P24: ='Input Value'!B3&"gal/100ml" -> 7,1gal/100ml | Q24: ='Input Value'!C3&"$/100ml" -> 17,2$/100ml | S24: =IFERROR(REPT("I",INT(IF(U24*10-10<0,U24*10,10))),"") -> IIIIIIIIII | T24: =IFERROR(REPT("I",INT(U24*10-10)),"") -> IIII | U24: =IFERROR(GETPIVOTDATA("KPI",Control!$A$53,"Drivers","Driver 2"),"") -> 1.4100177
A25: 9 | B25: SEP | C25: =Control!G10 -> 10 | D25: =IF(ISNA(MATCH($B25,Control!$A$31:$A$42,0)),NA(),C25) -> 10 | F25: Color4 | G25: FALSE | H25: =IF(G25,"",$F$12) -> • | I25: 3 | J25: Driver 3 | K25: =IF(ISNA(MATCH($J25,Control!$A$21:$A$23,0)),FALSE,TRUE) -> TRUE | L25: ='Input Value'!A4 -> Volvo FM | M25: =IF(K25,'Input Value'!F4/12*$D$69) -> 60000 | N25: =IF(K25,I25,0) -> 3 | O25: =IF(K25,"",$F$13) | P25: ='Input Value'!B4&"gal/100ml" -> 5,7gal/100ml | Q25: ='Input Value'!C4&"$/100ml" -> 20,75$/100ml | S25: =IFERROR(REPT("I",INT(IF(U25*10-10<0,U25*10,10))),"") -> IIIIIIIIII | T25: =IFERROR(REPT("I",INT(U25*10-10)),"") -> III | U25: =IFERROR(GETPIVOTDATA("KPI",Control!$A$53,"Drivers","Driver 3"),"") -> 1.3281665
A26: 10 | B26: OCT | C26: =Control!G11 -> 45 | D26: =IF(ISNA(MATCH($B26,Control!$A$31:$A$42,0)),NA(),C26) -> 45 | F26: Color5 | G26: FALSE | H26: =IF(G26,"",$F$12) -> • | L26: {=INDEX(L23:L25,N26)} -> Volvo FM | M26: =SUM(M23:M25) -> 200000 | N26: =MAX(N23:N25) -> 3 | T26: =REPT("I",S26)
A27: 11 | B27: NOV | C27: =Control!G12 -> 13 | D27: =IF(ISNA(MATCH($B27,Control!$A$31:$A$42,0)),NA(),C27) -> 13 | F27: Color6 | G27: FALSE | H27: =IF(G27,"",$F$12) -> •
A28: 12 | B28: DEC | C28: =Control!G13 -> 17 | D28: =IF(ISNA(MATCH($B28,Control!$A$31:$A$42,0)),NA(),C28) -> 17
C29: =Control!A27 -> 305334 | D29: =ROUND(Control!A27/1000,0) -> 305 | I29: Products Types (ton)
B30: Total Amount of Cargo | E30: Route Types | I30: Firewood | J30: Pellets | L30: Cargo Types (ton)
B31: =GETPIVOTDATA("Sum of Value of Сargo",Control!$A$30) -> 1091388.2 | E31: Far | F31: =Control!B28 -> 0.60814714 | H31: Driver 1 | I31: =INDEX(Control!$E$21:$G$23,MATCH($H31,Control!$A$21:$A$23,0),2) -> 232 | J31: =INDEX(Control!$E$21:$G$23,MATCH($H31,Control!$A$21:$A$23,0),3) -> 111 | L31: Pellets | M31: =Control!G24 -> 306
B32: =GETPIVOTDATA("Sum of Total Weight",Control!$A$30)/2000 -> 1968 | C32: =TEXT(ROUND(B32,0),"0 0")&"ton" -> 196 8ton | E32: Regular | F32: =Control!C28 -> 0.23865996 | H32: Driver 2 | I32: =INDEX(Control!$E$21:$G$23,MATCH($H32,Control!$A$21:$A$23,0),2) -> 252 | J32: =INDEX(Control!$E$21:$G$23,MATCH($H32,Control!$A$21:$A$23,0),3) -> 125 | L32: Firewood | M32: =Control!F24 -> 610
E33: Close | F33: =Control!D28 -> 0.14882391 | H33: Driver 3 | I33: =INDEX(Control!$E$21:$G$23,MATCH($H33,Control!$A$21:$A$23,0),2) -> 126 | J33: =INDEX(Control!$E$21:$G$23,MATCH($H33,Control!$A$21:$A$23,0),3) -> 70 | L33: Raw materials | M33: =Control!E24 -> 1051
B36: Logistics Costs
A37: =C37/B31 -> 0.43941005 | B37: =100%-A37 -> 0.56058995 | C37: =C39+E43+E57+C55+C69 -> 479566.94
B38: Fuel Budget
A39: =IF(C39/Control!H18<1,C39/Control!H18,1) -> 0.71056636 | B39: =100%-A39 -> 0.28943364 | C39: =Control!G18*'Input Value'!E7 -> 71056.636
A40: =IF(C39/Control!H18>1,C39/Control!H18-1,0) -> 0 | B40: =100%-A40 -> 1 | C40: =IF(C39/Control!H18<1,A39,A40+1) -> 0.71056636
C41: Variable Costs | E41: Fixed Costs
C42: bonuses | E42: salary
...

Sheet Data
A1: Month | B1: Raw materials | C1: Firewood | D1: Pellets | E1: Total Weight | F1: Value of Сargo | G1: Routes | H1: Mileage | I1: Far | J1: Regular | K1: Close | L1: U-Turn | M1: One Way | N1: Cars | O1: Fuel Сonsumption | P1: Fuel Budget | Q1: Depreciation | R1: Drivers | S1: Salary | T1: Business Trips | U1: KPI | V1: Bonuses
A2: JAN | B2: 11383 | C2: 18114 | D2: 15155 | E2: =SUM(B2:D2) -> 44652 | F2: =(B2*('Input Value'!$B$9/'Input Value'!$C$9))+(C2*('Input Value'!$B$7/'Input Value'!$C$7)+(D2*('Input Value'!$B$8/'Input Value'!$C$8))) -> 14718.373 | G2: Route 1 | H2: 5318 | I2: 3565 | J2: 1052 | K2: 701 | L2: =IF((H2-INDEX('Input Value'!$C$12:$C$16,MATCH(G2,'Input Value'!$B$12:$B$16,0)))>0,0,1) -> 0 | M2: =IF((H2-INDEX('Input Value'!$C$12:$C$16,MATCH(G2,'Input Value'!$B$12:$B$16,0)))>0,1,0) -> 1 | N2: Mack Anthem | O2: =H2/100*INDEX('Input Value'!$B$2:$B$4,MATCH(N2,'Input Value'!$A$2:$A$4,0)) -> 494.574 | P2: ='Input Value'!$E$9/12/5 -> 1666.6667 | Q2: =H2/100*INDEX('Input Value'!$C$2:$C$4,MATCH(N2,'Input Value'!$A$2:$A$4,0)) -> 1332.159 | R2: Driver 1 | S2: =ROUND(INDEX('Input Value'!$F$2:$F$4,MATCH(R2,'Input Value'!$E$2:$E$4,0))/12,2) -> 6250 | T2: =H2/100*INDEX('Input Value'!$G$2:$G$4,MATCH(N2,'Input Value'!$A$2:$A$4,0)) -> 957.24 | U2: =F2/INDEX('Input Value'!$H$2:$H$4,MATCH(N2,'Input Value'!$A$2:$A$4,0)) -> 0.8176874 | V2: =IF((F2-INDEX('Input Value'!$H$2:$H$4,MATCH(N2,'Input Value'!$A$2:$A$4,0)))>0,(F2-INDEX('Input Value'!$H$2:$H$4,MATCH(N2,'Input Value'!$A$2:$A$4,0)))*INDEX('Input Value'!$I$2:$I$4,MATCH(N2,'Input Value'!$A$2:$A$4,0)),0) -> 0
A3: JAN | B3: 64716 | C3: 19596 | D3: 21429 | E3: =SUM(B3:D3) -> 105741 | F3: =(B3*('Input Value'!$B$9/'Input Value'!$C$9))+(C3*('Input Value'!$B$7/'Input Value'!$C$7)+(D3*('Input Value'!$B$8/'Input Value'!$C$8))) -> 27778.107 | G3: Route 2 | H3: 7355 | I3: 3715 | J3: 2265 | K3: 1375 | L3: =IF((H3-INDEX('Input Value'!$C$12:$C$16,MATCH(G3,'Input Value'!$B$12:$B$16,0)))>0,0,1) -> 0 | M3: =IF((H3-INDEX('Input Value'!$C$12:$C$16,MATCH(G3,'Input Value'!$B$12:$B$16,0)))>0,1,0) -> 1 | N3: Mack Anthem | O3: =H3/100*INDEX('Input Value'!$B$2:$B$4,MATCH(N3,'Input Value'!$A$2:$A$4,0)) -> 684.015 | P3: ='Input Value'!$E$9/12/5 -> 1666.6667 | Q3: =H3/100*INDEX('Input Value'!$C$2:$C$4,MATCH(N3,'Input Value'!$A$2:$A$4,0)) -> 1842.4275 | R3: Driver 1 | S3: =ROUND(INDEX('Input Value'!$F$2:$F$4,MATCH(R3,'Input Value'!$E$2:$E$4,0))/12,2) -> 6250 | T3: =H3/100*INDEX('Input Value'!$G$2:$G$4,MATCH(N3,'Input Value'!$A$2:$A$4,0)) -> 1323.9 | U3: =F3/INDEX('Input Value'!$H$2:$H$4,MATCH(N3,'Input Value'!$A$2:$A$4,0)) -> 1.5432282 | V3: =IF((F3-INDEX('Input Value'!$H$2:$H$4,MATCH(N3,'Input Value'!$A$2:$A$4,0)))>0,(F3-INDEX('Input Value'!$H$2:$H$4,MATCH(N3,'Input Value'!$A$2:$A$4,0)))*INDEX('Input Value'!$I$2:$I$4,MATCH(N3,'Input Value'!$A$2:$A$4,0)),0) -> 977.81073
A4: JAN | B4: 40715 | C4: 24817 | D4: 19158 | E4: =SUM(B4:D4) -> 84690 | F4: =(B4*('Input Value'!$B$9/'Input Value'!$C$9))+(C4*('Input Value'!$B$7/'Input Value'!$C$7)+(D4*('Input Value'!$B$8/'Input Value'!$C$8))) -> 24332.058 | G4: Route 3 | H4: 4600 | I4: 2779 | J4: 1012 | K4: 809 | L4: =IF((H4-INDEX('Input Value'!$C$12:$C$16,MATCH(G4,'Input Value'!$B$12:$B$16,0)))>0,0,1) -> 0 | M4: =IF((H4-INDEX('Input Value'!$C$12:$C$16,MATCH(G4,'Input Value'!$B$12:$B$16,0)))>0,1,0) -> 1 | N4: Volvo FM | O4: =H4/100*INDEX('Input Value'!$B$2:$B$4,MATCH(N4,'Input Value'!$A$2:$A$4,0)) -> 262.2 | P4: ='Input Value'!$E$9/12/5 -> 1666.6667 | Q4: =H4/100*INDEX('Input Value'!$C$2:$C$4,MATCH(N4,'Input Value'!$A$2:$A$4,0)) -> 954.5 | R4: Driver 2 | S4: =ROUND(INDEX('Input Value'!$F$2:$F$4,MATCH(R4,'Input Value'!$E$2:$E$4,0))/12,2) -> 5416.67 | T4: =H4/100*INDEX('Input Value'!$G$2:$G$4,MATCH(N4,'Input Value'!$A$2:$A$4,0)) -> 460 | U4: =F4/INDEX('Input Value'!$H$2:$H$4,MATCH(N4,'Input Value'!$A$2:$A$4,0)) -> 1.8716968 | V4: =IF((F4-INDEX('Input Value'!$H$2:$H$4,MATCH(N4,'Input Value'!$A$2:$A$4,0)))>0,(F4-INDEX('Input Value'!$H$2:$H$4,MATCH(N4,'Input Value'!$A$2:$A$4,0)))*INDEX('Input Value'!$I$2:$I$4,MATCH(N4,'Input Value'!$A$2:$A$4,0)),0) -> 793.24409
A5: JAN | B5: 30242 | C5: 11980 | D5: 21766 | E5: =SUM(B5:D5) -> 63988 | F5: =(B5*('Input Value'!$B$9/'Input Value'!$C$9))+(C5*('Input Value'!$B$7/'Input Value'!$C$7)+(D5*('Input Value'!$B$8/'Input Value'!$C$8))) -> 18480.148 | G5: Route 4 | H5: 1845 | I5: 1095 | J5: 527 | K5: 223 | L5: =IF((H5-INDEX('Input Value'!$C$12:$C$16,MATCH(G5,'Input Value'!$B$12:$B$16,0)))>0,0,1) -> 1 | M5: =IF((H5-INDEX('Input Value'!$C$12:$C$16,MATCH(G5,'Input Value'!$B$12:$B$16,0)))>0,1,0) -> 0 | N5: Volvo FM | O5: =H5/100*INDEX('Input Value'!$B$2:$B$4,MATCH(N5,'Input Value'!$A$2:$A$4,0)) -> 105.165 | P5: ='Input Value'!$E$9/12/5 -> 1666.6667 | Q5: =H5/100*INDEX('Input Value'!$C$2:$C$4,MATCH(N5,'Input Value'!$A$2:$A$4,0)) -> 382.8375 | R5: Driver 2 | S5: =ROUND(INDEX('Input Value'!$F$2:$F$4,MATCH(R5,'Input Value'!$E$2:$E$4,0))/12,2) -> 5416.67 | T5: =H5/100*INDEX('Input Value'!$G$2:$G$4,MATCH(N5,'Input Value'!$A$2:$A$4,0)) -> 184.5 | U5: =F5/INDEX('Input Value'!$H$2:$H$4,MATCH(N5,'Input Value'!$A$2:$A$4,0)) -> 1.4215499 | V5: =IF((F5-INDEX('Input Value'!$H$2:$H$4,MATCH(N5,'Input Value'!$A$2:$A$4,0)))>0,(F5-INDEX('Input Value'!$H$2:$H$4,MATCH(N5,'Input Value'!$A$2:$A$4,0)))*INDEX('Input Value'!$I$2:$I$4,MATCH(N5,'Input Value'!$A$2:$A$4,0)),0) -> 383.61037
A6: JAN | B6: 54009 | C6: 37385 | D6: 19957 | E6: =SUM(B6:D6) -> 111351 | F6: =(B6*('Input Value'!$B$9/'Input Value'!$C$9))+(C6*('Input Value'!$B$7/'Input Value'!$C$7)+(D6*('Input Value'!$B$8/'Input Value'!$C$8))) -> 31903.779 | G6: Route 5 | H6: 3921 | I6: 2047 | J6: 1195 | K6: 640 | L6: =IF((H6-INDEX('Input Value'!$C$12:$C$16,MATCH(G6,'Input Value'!$B$12:$B$16,0)))>0,0,1) -> 0 | M6: =IF((H6-INDEX('Input Value'!$C$12:$C$16,MATCH(G6,'Input Value'!$B$12:$B$16,0)))>0,1,0) -> 1 | N6: DAF XF | O6: =H6/100*INDEX('Input Value'!$B$2:$B$4,MATCH(N6,'Input Value'!$A$2:$A$4,0)) -> 278.391 | P6: ='Input Value'!$E$9/12/5 -> 1666.6667 | Q6: =H6/100*INDEX('Input Value'!$C$2:$C$4,MATCH(N6,'Input Value'!$A$2:$A$4,0)) -> 674.412 | R6: Driver 3 | S6: =ROUND(INDEX('Input Value'!$F$2:$F$4,MATCH(R6,'Input Value'!$E$2:$E$4,0))/12,2) -> 5000 | T6: =H6/100*INDEX('Input Value'!$G$2:$G$4,MATCH(N6,'Input Value'!$A$2:$A$4,0)) -> 588.15 | U6: =F6/INDEX('Input Value'!$H$2:$H$4,MATCH(N6,'Input Value'!$A$2:$A$4,0)) -> 2.1269186 | V6: =IF((F6-INDEX('Input Value'!$H$2:$H$4,MATCH(N6,'Input Value'!$A$2:$A$4,0)))>0,(F6-INDEX('Input Value'!$H$2:$H$4,MATCH(N6,'Input Value'!$A$2:$A$4,0)))*INDEX('Input Value'!$I$2:$I$4,MATCH(N6,'Input Value'!$A$2:$A$4,0)),0) -> 1183.2646
A7: FEB | B7: 34033 | C7: 16298 | D7: 8298 | E7: =SUM(B7:D7) -> 58629 | F7: =(B7*('Input Value'!$B$9/'Input Value'!$C$9))+(C7*('Input Value'!$B$7/'Input Value'!$C$7)+(D7*('Input Value'!$B$8/'Input Value'!$C$8))) -> 15749.374 | G7: Route 1 | H7: 4174 | I7: 2376 | J7: 1212 | K7: 493 | L7: =IF((H7-INDEX('Input Value'!$C$12:$C$16,MATCH(G7,'Input Value'!$B$12:$B$16,0)))>0,0,1) -> 0 | M7: =IF((H7-INDEX('Input Value'!$C$12:$C$16,MATCH(G7,'Input Value'!$B$12:$B$16,0)))>0,1,0) -> 1 | N7: Mack Anthem | O7: =H7/100*INDEX('Input Value'!$B$2:$B$4,MATCH(N7,'Input Value'!$A$2:$A$4,0)) -> 388.182 | P7: ='Input Value'!$E$9/12/5 -> 1666.6667 | Q7: =H7/100*INDEX('Input Value'!$C$2:$C$4,MATCH(N7,'Input Value'!$A$2:$A$4,0)) -> 1045.587 | R7: Driver 1 | S7: =ROUND(INDEX('Input Value'!$F$2:$F$4,MATCH(R7,'Input Value'!$E$2:$E$4,0))/12,2) -> 6250 | T7: =H7/100*INDEX('Input Value'!$G$2:$G$4,MATCH(N7,'Input Value'!$A$2:$A$4,0)) -> 751.32 | U7: =F7/INDEX('Input Value'!$H$2:$H$4,MATCH(N7,'Input Value'!$A$2:$A$4,0)) -> 0.87496523 | V7: =IF((F7-INDEX('Input Value'!$H$2:$H$4,MATCH(N7,'Input Value'!$A$2:$A$4,0)))>0,(F7-INDEX('Input Value'!$H$2:$H$4,MATCH(N7,'Input Value'!$A$2:$A$4,0)))*INDEX('Input Value'!$I$2:$I$4,MATCH(N7,'Input Value'!$A$2:$A$4,0)),0) -> 0
A8: FEB | B8: 23057 | C8: 9515 | D8: 9084 | E8: =SUM(B8:D8) -> 41656 | F8: =(B8*('Input Value'!$B$9/'Input Value'!$C$9))+(C8*('Input Value'!$B$7/'Input Value'!$C$7)+(D8*('Input Value'!$B$8/'Input Value'!$C$8))) -> 11399.888 | G8: Route 2 | H8: 4939 | I8: 2604 | J8: 1412 | K8: 923 | L8: =IF((H8-INDEX('Input Value'!$C$12:$C$16,MATCH(G8,'Input Value'!$B$12:$B$16,0)))>0,0,1) -> 0 | M8: =IF((H8-INDEX('Input Value'!$C$12:$C$16,MATCH(G8,'Input Value'!$B$12:$B$16,0)))>0,1,0) -> 1 | N8: Mack Anthem | O8: =H8/100*INDEX('Input Value'!$B$2:$B$4,MATCH(N8,'Input Value'!$A$2:$A$4,0)) -> 459.327 | P8: ='Input Value'!$E$9/12/5 -> 1666.6667 | Q8: =H8/100*INDEX('Input Value'!$C$2:$C$4,MATCH(N8,'Input Value'!$A$2:$A$4,0)) -> 1237.2195 | R8: Driver 1 | S8: =ROUND(INDEX('Input Value'!$F$2:$F$4,MATCH(R8,'Input Value'!$E$2:$E$4,0))/12,2) -> 6250 | T8: =H8/100*INDEX('Input Value'!$G$2:$G$4,MATCH(N8,'Input Value'!$A$2:$A$4,0)) -> 889.02 | U8: =F8/INDEX('Input Value'!$H$2:$H$4,MATCH(N8,'Input Value'!$A$2:$A$4,0)) -> 0.63332711 | V8: =IF((F8-INDEX('Input Value'!$H$2:$H$4,MATCH(N8,'Input Value'!$A$2:$A$4,0)))>0,(F8-INDEX('Input Value'!$H$2:$H$4,MATCH(N8,'Input Value'!$A$2:$A$4,0)))*INDEX('Input Value'!$I$2:$I$4,MATCH(N8,'Input Value'!$A$2:$A$4,0)),0) -> 0
A9: FEB | B9: 27736 | C9: 18585 | D9: 13934 | E9: =SUM(B9:D9) -> 60255 | F9: =(B9*('Input Value'!$B$9/'Input Value'!$C$9))+(C9*('Input Value'!$B$7/'Input Value'!$C$7)+(D9*('Input Value'!$B$8/'Input Value'!$C$8))) -> 17542.596 | G9: Route 3 | H9: 4400 | I9: 2658 | J9: 968 | K9: 774 | L9: =IF((H9-INDEX('Input Value'!$C$12:$C$16,MATCH(G9,'Input Value'!$B$12:$B$16,0)))>0,0,1) -> 0 | M9: =IF((H9-INDEX('Input Value'!$C$12:$C$16,MATCH(G9,'Input Value'!$B$12:$B$16,0)))>0,1,0) -> 1 | N9: Volvo FM | O9: =H9/100*INDEX('Input Value'!$B$2:$B$4,MATCH(N9,'Input Value'!$A$2:$A$4,0)) -> 250.8 | P9: ='Input Value'!$E$9/12/5 -> 1666.6667 | Q9: =H9/100*INDEX('Input Value'!$C$2:$C$4,MATCH(N9,'Input Value'!$A$2:$A$4,0)) -> 913 | R9: Driver 2 | S9: =ROUND(INDEX('Input Value'!$F$2:$F$4,MATCH(R9,'Input Value'!$E$2:$E$4,0))/12,2) -> 5416.67 | T9: =H9/100*INDEX('Input Value'!$G$2:$G$4,MATCH(N9,'Input Value'!$A$2:$A$4,0)) -> 440 | U9: =F9/INDEX('Input Value'!$H$2:$H$4,MATCH(N9,'Input Value'!$A$2:$A$4,0)) -> 1.3494304 | V9: =IF((F9-INDEX('Input Value'!$H$2:$H$4,MATCH(N9,'Input Value'!$A$2:$A$4,0)))>0,(F9-INDEX('Input Value'!$H$2:$H$4,MATCH(N9,'Input Value'!$A$2:$A$4,0)))*INDEX('Input Value'!$I$2:$I$4,MATCH(N9,'Input Value'!$A$2:$A$4,0)),0) -> 317.9817
A10: FEB | B10: 11844 | C10: 20792 | D10: 10570 | E10: =SUM(B10:D10) -> 43206 | F10: =(B10*('Input Value'!$B$9/'Input Value'!$C$9))+(C10*('Input Value'!$B$7/'Input Value'!$C$7)+(D10*('Input Value'!$B$8/'Input Value'!$C$8))) -> 14087.113 | G10: Route 4 | H10: 3861 | I10: 2163 | J10: 1019 | K10: 679 | L10: =IF((H10-INDEX('Input Value'!$C$12:$C$16,MATCH(G10,'Input Value'!$B$12:$B$16,0)))>0,0,1) -> 0 | M10: =IF((H10-INDEX('Input Value'!$C$12:$C$16,MATCH(G10,'Input Value'!$B$12:$B$16,0)))>0,1,0) -> 1 | N10: Volvo FM | O10: =H10/100*INDEX('Input Value'!$B$2:$B$4,MATCH(N10,'Input Value'!$A$2:$A$4,0)) -> 220.077 | P10: ='Input Value'!$E$9/12/5 -> 1666.6667 | Q10: =H10/100*INDEX('Input Value'!$C$2:$C$4,MATCH(N10,'Input Value'!$A$2:$A$4,0)) -> 801.1575 | R10: Driver 2 | S10: =ROUND(INDEX('Input Value'!$F$2:$F$4,MATCH(R10,'Input Value'!$E$2:$E$4,0))/12,2) -> 5416.67 | T10: =H10/100*INDEX('Input Value'!$G$2:$G$4,MATCH(N10,'Input Value'!$A$2:$A$4,0)) -> 386.1 | U10: =F10/INDEX('Input Value'!$H$2:$H$4,MATCH(N10,'Input Value'!$A$2:$A$4,0)) -> 1.0836241 | V10: =IF((F10-INDEX('Input Value'!$H$2:$H$4,MATCH(N10,'Input Value'!$A$2:$A$4,0)))>0,(F10-INDEX('Input Value'!$H$2:$H$4,MATCH(N10,'Input Value'!$A$2:$A$4,0)))*INDEX('Input Value'!$I$2:$I$4,MATCH(N10,'Input Value'!$A$2:$A$4,0)),0) -> 76.097891
A11: FEB | B11: 42663 | C11: 14001 | D11: 10646 | E11: =SUM(B11:D11) -> 67310 | F11: =(B11*('Input Value'!$B$9/'Input Value'!$C$9))+(C11*('Input Value'!$B$7/'Input Value'!$C$7)+(D11*('Input Value'!$B$8/'Input Value'!$C$8))) -> 17407.793 | G11: Route 5 | H11: 4719 | I11: 2384 | J11: 1453 | K11: 882 | L11: =IF((H11-INDEX('Input Value'!$C$12:$C$16,MATCH(G11,'Input Value'!$B$12:$B$16,0)))>0,0,1) -> 0 | M11: =IF((H11-INDEX('Input Value'!$C$12:$C$16,MATCH(G11,'Input Value'!$B$12:$B$16,0)))>0,1,0) -> 1 | N11: DAF XF | O11: =H11/100*INDEX('Input Value'!$B$2:$B$4,MATCH(N11,'Input Value'!$A$2:$A$4,0)) -> 335.049 | P11: ='Input Value'!$E$9/12/5 -> 1666.6667 | Q11: =H11/100*INDEX('Input Value'!$C$2:$C$4,MATCH(N11,'Input Value'!$A$2:$A$4,0)) -> 811.668 | R11: Driver 3 | S11: =ROUND(INDEX('Input Value'!$F$2:$F$4,MATCH(R11,'Input Value'!$E$2:$E$4,0))/12,2) -> 5000 | T11: =H11/100*INDEX('Input Value'!$G$2:$G$4,MATCH(N11,'Input Value'!$A$2:$A$4,0)) -> 707.85 | U11: =F11/INDEX('Input Value'!$H$2:$H$4,MATCH(N11,'Input Value'!$A$2:$A$4,0)) -> 1.1605195 | V11: =IF((F11-INDEX('Input Value'!$H$2:$H$4,MATCH(N11,'Input Value'!$A$2:$A$4,0)))>0,(F11-INDEX('Input Value'!$H$2:$H$4,MATCH(N11,'Input Value'!$A$2:$A$4,0)))*INDEX('Input Value'!$I$2:$I$4,MATCH(N11,'Input Value'!$A$2:$A$4,0)),0) -> 168.54551
A12: MAR | B12: 46846 | C12: 22235 | D12: 15537 | E12: =SUM(B12:D12) -> 84618 | F12: =(B12*('Input Value'!$B$9/'Input Value'!$C$9))+(C12*('Input Value'!$B$7/'Input Value'!$C$7)+(D12*('Input Value'!$B$8/'Input Value'!$C$8))) -> 23156.139 | G12: Route 1 | H12: 8196 | I12: 4861 | J12: 1803 | K12: 1532 | L12: =IF((H12-INDEX('Input Value'!$C$12:$C$16,MATCH(G12,'Input Value'!$B$12:$B$16,0)))>0,0,1) -> 0 | M12: =IF((H12-INDEX('Input Value'!$C$12:$C$16,MATCH(G12,'Input Value'!$B$12:$B$16,0)))>0,1,0) -> 1 | N12: Mack Anthem | O12: =H12/100*INDEX('Input Value'!$B$2:$B$4,MATCH(N12,'Input Value'!$A$2:$A$4,0)) -> 762.228 | P12: ='Input Value'!$E$9/12/5 -> 1666.6667 | Q12: =H12/100*INDEX('Input Value'!$C$2:$C$4,MATCH(N12,'Input Value'!$A$2:$A$4,0)) -> 2053.098 | R12: Driver 1 | S12: =ROUND(INDEX('Input Value'!$F$2:$F$4,MATCH(R12,'Input Value'!$E$2:$E$4,0))/12,2) -> 6250 | T12: =H12/100*INDEX('Input Value'!$G$2:$G$4,MATCH(N12,'Input Value'!$A$2:$A$4,0)) -> 1475.28 | U12: =F12/INDEX('Input Value'!$H$2:$H$4,MATCH(N12,'Input Value'!$A$2:$A$4,0)) -> 1.2864522 | V12: =IF((F12-INDEX('Input Value'!$H$2:$H$4,MATCH(N12,'Input Value'!$A$2:$A$4,0)))>0,(F12-INDEX('Input Value'!$H$2:$H$4,MATCH(N12,'Input Value'!$A$2:$A$4,0)))*INDEX('Input Value'!$I$2:$I$4,MATCH(N12,'Input Value'!$A$2:$A$4,0)),0) -> 515.61389
A13: MAR | B13: 30757 | C13: 30739 | D13: 24366 | E13: =SUM(B13:D13) -> 85862 | F13: =(B13*('Input Value'!$B$9/'Input Value'!$C$9))+(C13*('Input Value'!$B$7/'Input Value'!$C$7)+(D13*('Input Value'!$B$8/'Input Value'!$C$8))) -> 26640.43 | G13: Route 2 | H13: 7958 | I13: 4370 | J13: 2275 | K13: 1313 | L13: =IF((H13-INDEX('Input Value'!$C$12:$C$16,MATCH(G13,'Input Value'!$B$12:$B$16,0)))>0,0,1) -> 0 | M13: =IF((H13-INDEX('Input Value'!$C$12:$C$16,MATCH(G13,'Input Value'!$B$12:$B$16,0)))>0,1,0) -> 1 | N13: Mack Anthem | O13: =H13/100*INDEX('Input Value'!$B$2:$B$4,MATCH(N13,'Input Value'!$A$2:$A$4,0)) -> 740.094 | P13: ='Input Value'!$E$9/12/5 -> 1666.6667 | Q13: =H13/100*INDEX('Input Value'!$C$2:$C$4,MATCH(N13,'Input Value'!$A$2:$A$4,0)) -> 1993.479 | R13: Driver 1 | S13: =ROUND(INDEX('Input Value'!$F$2:$F$4,MATCH(R13,'Input Value'!$E$2:$E$4,0))/12,2) -> 6250 | T13: =H13/100*INDEX('Input Value'!$G$2:$G$4,MATCH(N13,'Input Value'!$A$2:$A$4,0)) -> 1432.44 | U13: =F13/INDEX('Input Value'!$H$2:$H$4,MATCH(N13,'Input Value'!$A$2:$A$4,0)) -> 1.4800239 | V13: =IF((F13-INDEX('Input Value'!$H$2:$H$4,MATCH(N13,'Input Value'!$A$2:$A$4,0)))>0,(F13-INDEX('Input Value'!$H$2:$H$4,MATCH(N13,'Input Value'!$A$2:$A$4,0)))*INDEX('Input Value'!$I$2:$I$4,MATCH(N13,'Input Value'!$A$2:$A$4,0)),0) -> 864.04298
... A61: DEC | B61: 30067 | C61: 18169 | D61: 6135 | E61: =SUM(B61:D61) -> 54371 | F61: =(B61*('Input Value'!$B$9/'Input Value'!$C$9))+(C61*('Input Value'!$B$7/'Input Value'!$C$7)+(D61*('Input Value'!$B$8/'Input Value'!$C$8))) -> 14886.096 | G61: Route 5 | H61: 4865 | I61: 3047 | J61: 1016 | K61: 802 | L61: =IF((H61-INDEX('Input Value'!$C$12:$C$16,MATCH(G61,'Input Value'!$B$12:$B$16,0)))>0,0,1) -> 0 | M61: =IF((H61-INDEX('Input Value'!$C$12:$C$16,MATCH(G61,'Input Value'!$B$12:$B$16,0)))>0,1,0) -> 1 | N61: DAF XF | O61: =H61/100*INDEX('Input Value'!$B$2:$B$4,MATCH(N61,'Input Value'!$A$2:$A$4,0)) -> 345.415 | P61: ='Input Value'!$E$9/12/5 -> 1666.6667 | Q61: =H61/100*INDEX('Input Value'!$C$2:$C$4,MATCH(N61,'Input Value'!$A$2:$A$4,0)) -> 836.78 | R61: Driver 3 | S61: =ROUND(INDEX('Input Value'!$F$2:$F$4,MATCH(R61,'Input Value'!$E$2:$E$4,0))/12,2) -> 5000 | T61: =H61/100*INDEX('Input Value'!$G$2:$G$4,MATCH(N61,'Input Value'!$A$2:$A$4,0)) -> 729.75 | U61: =F61/INDEX('Input Value'!$H$2:$H$4,MATCH(N61,'Input Value'!$A$2:$A$4,0)) -> 0.99240638 | V61: =IF((F61-INDEX('Input Value'!$H$2:$H$4,MATCH(N61,'Input Value'!$A$2:$A$4,0)))>0,(F61-INDEX('Input Value'!$H$2:$H$4,MATCH(N61,'Input Value'!$A$2:$A$4,0)))*INDEX('Input Value'!$I$2:$I$4,MATCH(N61,'Input Value'!$A$2:$A$4,0)),0) -> 0

Sheet Control
A1: Row Labels | B1: Sum of Value of Сargo | C1: Sum of Mileage | D1: Sum of Business Trips | E1: Sum of Bonuses | F1: Value of Сargo | G1: Mileage | H1: Business Trips | I1: Bonuses
A2: JAN | B2: 117212.47 | C2: 23039 | D2: 3513.79 | E2: 3337.9297 | F2: =ROUND(B2/1000,0) -> 117 | G2: =ROUND(C2/1000,0) -> 23 | H2: =ROUND(D2,0) -> 3514 | I2: =ROUND(E2,0) -> 3338
A3: FEB | B3: 76186.763 | C3: 22093 | D3: 3174.29 | E3: 562.6251 | F3: =ROUND(B3/1000,0) -> 76 | G3: =ROUND(C3/1000,0) -> 22 | H3: =ROUND(D3,0) -> 3174 | I3: =ROUND(E3,0) -> 563
A4: MAR | B4: 131729.34 | C4: 43105 | D4: 6053.02 | E4: 4244.9507 | F4: =ROUND(B4/1000,0) -> 132 | G4: =ROUND(C4/1000,0) -> 43 | H4: =ROUND(D4,0) -> 6053 | I4: =ROUND(E4,0) -> 4245
A5: APR | B5: 49381.071 | C5: 17092 | D5: 2259.12 | E5: 0 | F5: =ROUND(B5/1000,0) -> 49 | G5: =ROUND(C5/1000,0) -> 17 | H5: =ROUND(D5,0) -> 2259 | I5: =ROUND(E5,0) -> 0
A6: MAY | B6: 71678.926 | C6: 12189 | D6: 1766.05 | E6: 739.60094 | F6: =ROUND(B6/1000,0) -> 72 | G6: =ROUND(C6/1000,0) -> 12 | H6: =ROUND(D6,0) -> 1766 | I6: =ROUND(E6,0) -> 740
A7: JUN | B7: 163223.66 | C7: 50092 | D7: 6493.23 | E7: 6685.378 | F7: =ROUND(B7/1000,0) -> 163 | G7: =ROUND(C7/1000,0) -> 50 | H7: =ROUND(D7,0) -> 6493 | I7: =ROUND(E7,0) -> 6685
A8: JUL | B8: 66402.267 | C8: 19025 | D8: 2803.92 | E8: 255.20034 | F8: =ROUND(B8/1000,0) -> 66 | G8: =ROUND(C8/1000,0) -> 19 | H8: =ROUND(D8,0) -> 2804 | I8: =ROUND(E8,0) -> 255
A9: AUG | B9: 80157.401 | C9: 33210 | D9: 4543.1 | E9: 1114.1342 | F9: =ROUND(B9/1000,0) -> 80 | G9: =ROUND(C9/1000,0) -> 33 | H9: =ROUND(D9,0) -> 4543 | I9: =ROUND(E9,0) -> 1114
A10: SEP | B10: 54380.463 | C10: 10125 | D10: 1515.81 | E10: 0 | F10: =ROUND(B10/1000,0) -> 54 | G10: =ROUND(C10/1000,0) -> 10 | H10: =ROUND(D10,0) -> 1516 | I10: =ROUND(E10,0) -> 0
A11: OCT | B11: 139617.14 | C11: 45140 | D11: 6508.43 | E11: 4762.2415 | F11: =ROUND(B11/1000,0) -> 140 | G11: =ROUND(C11/1000,0) -> 45 | H11: =ROUND(D11,0) -> 6508 | I11: =ROUND(E11,0) -> 4762
A12: NOV | B12: 64125.341 | C12: 13112 | D12: 1835.25 | E12: 680.53753 | F12: =ROUND(B12/1000,0) -> 64 | G12: =ROUND(C12/1000,0) -> 13 | H12: =ROUND(D12,0) -> 1835 | I12: =ROUND(E12,0) -> 681
A13: DEC | B13: 77293.34 | C13: 17112 | D13: 2328.29 | E13: 453.58832 | F13: =ROUND(B13/1000,0) -> 77 | G13: =ROUND(C13/1000,0) -> 17 | H13: =ROUND(D13,0) -> 2328 | I13: =ROUND(E13,0) -> 454
A14: Grand Total | B14: 1091388.2 | C14: 305334 | D14: 42794.3 | E14: 22836.186 | F14: =ROUND(B14,0) -> 1091388 | G14: =ROUND(C14,0) -> 305334 | H14: =ROUND(D14,0) -> 42794 | I14: =ROUND(E14,0) -> 22836
A17: Sum of U-Turn | B17: Sum of One Way | D17: Sum of Depreciation | G17: Sum of Fuel Сonsumption | H17: Sum of Fuel Budget | I17: Sum of Business Trips | J17: Sum of Bonuses
A18: 25 | B18: 35 | D18: 65715.893 | E18: =ROUND(D18,0) -> 65716 | G18: 22344.854 | H18: 100000 | I18: 42794.3 | J18: 22836.186
A20: Row Labels | B20: Sum of Raw materials | C20: Sum of Firewood | D20: Sum of Pellets | E20: Raw materials | F20: Firewood | G20: Pellets
A21: Driver 1 | B21: 806257 | C21: 463784 | D21: 222983 | E21: =ROUND(B21/2000,0) -> 403 | F21: =ROUND(C21/2000,0) -> 232 | G21: =ROUND(D21/2000,0) -> 111
A22: Driver 2 | B22: 818086 | C22: 504166 | D22: 249598 | E22: =ROUND(B22/2000,0) -> 409 | F22: =ROUND(C22/2000,0) -> 252 | G22: =ROUND(D22/2000,0) -> 125
A23: Driver 3 | B23: 478657 | C23: 252050 | D23: 140419 | E23: =ROUND(B23/2000,0) -> 239 | F23: =ROUND(C23/2000,0) -> 126 | G23: =ROUND(D23/2000,0) -> 70
E24: =SUM(E21:E23) -> 1051 | F24: =SUM(F21:F23) -> 610 | G24: =SUM(G21:G23) -> 306
A26: Sum of Mileage | B26: Sum of Far | C26: Sum of Regular | D26: Sum of Close
A27: 305334 | B27: 185688 | C27: 72871 | D27: 45441
B28: =B27/$A$27 -> 0.60814714 | C28: =C27/$A$27 -> 0.23865996 | D28: =D27/$A$27 -> 0.14882391
A30: Row Labels | B30: Sum of Value of Сargo | C30: Sum of Raw materials | D30: Sum of Firewood | E30: Sum of Pellets | F30: Sum of Total Weight
A31: JAN | B31: 117212.47 | C31: 201065 | D31: 111892 | E31: 97465 | F31: 410422
A32: FEB | B32: 76186.763 | C32: 139333 | D32: 79191 | E32: 52532 | F32: 271056
A33: MAR | B33: 131729.34 | C33: 242048 | D33: 133178 | E33: 94005 | F33: 469231
A34: APR | B34: 49381.071 | C34: 131612 | D34: 46279 | E34: 18301 | F34: 196192
A35: MAY | B35: 71678.926 | C35: 231128 | D35: 54667 | E35: 18893 | F35: 304688
A36: JUN | B36: 163223.66 | C36: 308688 | D36: 176451 | E36: 100624 | F36: 585763
A37: JUL | B37: 66402.267 | C37: 104812 | D37: 99882 | E37: 23279 | F37: 227973
A38: AUG | B38: 80157.401 | C38: 94575 | D38: 112984 | E38: 51784 | F38: 259343
A39: SEP | B39: 54380.463 | C39: 112685 | D39: 61735 | E39: 25619 | F39: 200039
A40: OCT | B40: 139617.14 | C40: 199452 | D40: 170358 | E40: 99162 | F40: 468972
A41: NOV | B41: 64125.341 | C41: 156435 | D41: 79439 | E41: 11701 | F41: 247575
A42: DEC | B42: 77293.34 | C42: 181167 | D42: 93944 | E42: 19635 | F42: 294746
A43: Grand Total | B43: 1091388.2 | C43: 2103000 | D43: 1220000 | E43: 613000 | F43: 3936000
A46: Row Labels
A47: Route 1
...

Sheet Input Value
A1: Fuel Сonsumption Gallon per 100 mil | C1: Depreciation USD per 100 mil | E1: Drivers | F1: Salary USD per 1 year | G1: Business trips USD per 100 mil | H1: Plan KPI: Value of Сargo > per 1 Route | I1: Bonuses
A2: Mack Anthem | B2: 9.3 | C2: 25.05 | E2: Driver 1 | F2: 75000 | G2: 18 | H2: 18000 | I2: 0.1 | J2: per Value of Сargo-Plan KPI
A3: DAF XF | B3: 7.1 | C3: 17.2 | E3: Driver 2 | F3: 65000 | G3: 15 | H3: 15000 | I3: 0.07 | J3: per Value of Сargo-Plan KPI
A4: Volvo FM | B4: 5.7 | C4: 20.75 | E4: Driver 3 | F4: 60000 | G4: 10 | H4: 13000 | I4: 0.07 | J4: per Value of Сargo-Plan KPI
A6: Cargo | B6: Price Package | C6: Weight Package | E6: Fuel price USD per 1 Gallon
A7: Firewood | B7: 7.55 | C7: 20 | E7: 3.18
A8: Pellets | B8: 12.45 | C8: 33 | E8: Fuel Budget 1 year
A9: Raw materials | B9: 190 | C9: 1000 | E9: 100000
A11: № | B11: Routes | C11: Mileage
A12: 1 | B12: Route 1 | C12: 3364
A13: 2 | B13: Route 2 | C13: 3644
A14: 3 | B14: Route 3 | C14: 3975
A15: 4 | B15: Route 4 | C15: 3096
A16: 5 | B16: Route 5 | C16: 3739

Sheet Resources
