Workbook
Name mydata: Data!$A$3:$BA$51
Name Slicer_Month: #N/A
Name Slicer_Year: #N/A

Sheet DASHBOARD

Sheet Processing
A1: Employee Categories | B1: Management | C1: Administrative staff | D1: Sales department | E1: Production department | F1: Logistics department | I1: Payroll Cost Breakdown | M1: Payroll Forecast | N1: Planned Payroll | O1: Actual Payroll | Q1: Payroll WHR | T1: (Payroll Work Hour Representation)
A2: Value | B2: =GETPIVOTDATA(""&B1,Control!$A$3) -> 36840 | C2: =GETPIVOTDATA(""&C1,Control!$A$3) -> 23340 | D2: =GETPIVOTDATA(""&D1,Control!$A$3) -> 36425 | E2: =GETPIVOTDATA(""&E1,Control!$A$3) -> 33470 | F2: =GETPIVOTDATA(""&F1,Control!$A$3) -> 30730 | I2: Basic Payroll | J2: =GETPIVOTDATA(""&I2,Control!$A$3) -> 0.36 | K2: =100%-J2 -> 0.64 | M2: SU | N2: =GETPIVOTDATA(""&M2,Control!$A$3) -> 28363 | O2: =GETPIVOTDATA(M2&2,Control!$A$3) -> 19542 | Q2: Standard Hours | R2: =GETPIVOTDATA(""&Q2,Control!$A$3) -> 0.4 | S2: =100%-R2 -> 0.6 | T2: Standard Hours Completed as a Percentage of Total Work Hours
A3: % | B3: =B2/MAX($B$2:$F$2) -> 1 | C3: =C2/MAX($B$2:$F$2) -> 0.63355049 | D3: =D2/MAX($B$2:$F$2) -> 0.98873507 | E3: =E2/MAX($B$2:$F$2) -> 0.90852334 | F3: =F2/MAX($B$2:$F$2) -> 0.83414767 | I3: Bonuses and Prizes | J3: =GETPIVOTDATA(""&I3,Control!$A$3) -> 0.45 | K3: =100%-J3 -> 0.55 | M3: MO | N3: =GETPIVOTDATA(""&M3,Control!$A$3) -> 32559 | O3: =GETPIVOTDATA(M3&2,Control!$A$3) -> 42659 | Q3: Actual Hours | R3: =GETPIVOTDATA(""&Q3,Control!$A$3) -> 0.24 | S3: =100%-R3 -> 0.76 | T3: Payment Based on Actual Work Hours as a Percentage of Total Payroll Fund
A4: Total | B4: =SUM(B2:F2) -> 160805 | C4: =B4 -> 160805 | I4: Payroll Taxes & Insurance | J4: =GETPIVOTDATA(""&I4,Control!$A$3) -> 0.19 | K4: =100%-J4 -> 0.81 | M4: TU | N4: =GETPIVOTDATA(""&M4,Control!$A$3) -> 2859 | O4: =GETPIVOTDATA(M4&2,Control!$A$3) -> 40003
B5: Asset 1 | D5: Asset 2 | F5: Asset 3 | H5: Asset 4 | J5: Asset 5 | K5: Sectors | M5: WE | N5: =GETPIVOTDATA(""&M5,Control!$A$3) -> 44682 | O5: =GETPIVOTDATA(M5&2,Control!$A$3) -> 20115
A6: Done | B6: {=(100%-B8)*INDEX($B$3:$F$3,1,B9)} -> 0.75 | C6: {=(100%-C8)*INDEX($B$3:$F$3,1,C9)} -> 0.75 | D6: {=(100%-D8)*INDEX($B$3:$F$3,1,D9)} -> 0.47516287 | E6: {=(100%-E8)*INDEX($B$3:$F$3,1,E9)} -> 0.47516287 | F6: {=(100%-F8)*INDEX($B$3:$F$3,1,F9)} -> 0.7415513 | G6: {=(100%-G8)*INDEX($B$3:$F$3,1,G9)} -> 0.7415513 | H6: {=(100%-H8)*INDEX($B$3:$F$3,1,H9)} -> 0.68139251 | I6: {=(100%-I8)*INDEX($B$3:$F$3,1,I9)} -> 0.68139251 | J6: {=(100%-J8)*INDEX($B$3:$F$3,1,J9)} -> 0.62561075 | K6: 0.75 | M6: TH | N6: =GETPIVOTDATA(""&M6,Control!$A$3) -> 89111 | O6: =GETPIVOTDATA(M6&2,Control!$A$3) -> 40007
A7: Running | B7: =100%-B8-B6 -> 0 | C7: =100%-C8-C6 -> 0 | D7: =100%-D8-D6 -> 0.27483713 | E7: =100%-E8-E6 -> 0.27483713 | F7: =100%-F8-F6 -> 0.0084486971 | G7: =100%-G8-G6 -> 0.0084486971 | H7: =100%-H8-H6 -> 0.068607492 | I7: =100%-I8-I6 -> 0.068607492 | J7: =100%-J8-J6 -> 0.12438925 | K7: 0 | M7: FR | N7: =GETPIVOTDATA(""&M7,Control!$A$3) -> 8141 | O7: =GETPIVOTDATA(M7&2,Control!$A$3) -> 40200
B8: =$K$8 -> 0.25 | C8: =$K$8 -> 0.25 | D8: =$K$8 -> 0.25 | E8: =$K$8 -> 0.25 | F8: =$K$8 -> 0.25 | G8: =$K$8 -> 0.25 | H8: =$K$8 -> 0.25 | I8: =$K$8 -> 0.25 | J8: =$K$8 -> 0.25 | K8: =100%-K6 -> 0.25 | M8: SA | N8: =GETPIVOTDATA(""&M8,Control!$A$3) -> 34285 | O8: =GETPIVOTDATA(M8&2,Control!$A$3) -> 33754
B9: 1 | C9: 1 | D9: 2 | E9: 2 | F9: 3 | G9: 3 | H9: 4 | I9: 4 | J9: 5
C10: Annual Payroll Plan | F10: PDL | G10: Payroll Distribution by Location | M10: Employee Performance
A11: Payroll Fund | B11: Payroll | C11: =GETPIVOTDATA("Average of Annual Payroll Plan",Control!$A$20) -> 120000 | F11: Head Office | G11: =GETPIVOTDATA(""&F11,Control!$A$3) -> 0.31 | H11: =G11 -> 0.31 | I11: =H11 -> 0.31 | J11: =I11 -> 0.31 | M11: KPI | N11: Compensation
C12: =$C$11 -> 120000 | F12: Regional Offices | G12: =GETPIVOTDATA(""&F12,Control!$A$3) -> 0.3 | H12: =G12 -> 0.3 | I12: =H12 -> 0.3 | J12: =I12 -> 0.3 | L12: A | M12: =GETPIVOTDATA(L12&"",Control!$A$3) -> 1.24 | N12: =GETPIVOTDATA(L12&2,Control!$A$3) -> 0.26 | O12: Management
A13: JAN | B13: =GETPIVOTDATA("Sum of Payroll",Control!$A$20,"Month",""&A13) -> 107635 | C13: =$C$11 -> 120000 | D13: =IFERROR(GETPIVOTDATA(""&$B$11,Control!$A$3,"Month",""&A13),NA()) -> #N/A | F13: Regional Branches | G13: =GETPIVOTDATA(""&F13,Control!$A$3) -> 0.12 | H13: =G13 -> 0.12 | I13: =H13 -> 0.12 | J13: =I13 -> 0.12 | L13: B | M13: =GETPIVOTDATA(L13&"",Control!$A$3) -> 1.06 | N13: =GETPIVOTDATA(L13&2,Control!$A$3) -> 0.31 | O13: Administrative staff
A14: FEB | B14: =GETPIVOTDATA("Sum of Payroll",Control!$A$20,"Month",""&A14) -> 153595 | C14: =$C$11 -> 120000 | D14: =IFERROR(GETPIVOTDATA(""&$B$11,Control!$A$3,"Month",""&A14),NA()) -> #N/A | F14: Remote Employees | G14: =GETPIVOTDATA(""&F14,Control!$A$3) -> 0.07 | H14: =G14 -> 0.07 | I14: =H14 -> 0.07 | J14: =I14 -> 0.07 | L14: C | M14: =GETPIVOTDATA(L14&"",Control!$A$3) -> 1.08 | N14: =GETPIVOTDATA(L14&2,Control!$A$3) -> 0.56 | O14: Sales department
A15: MAR | B15: =GETPIVOTDATA("Sum of Payroll",Control!$A$20,"Month",""&A15) -> 156760 | C15: =$C$11 -> 120000 | D15: =IFERROR(GETPIVOTDATA(""&$B$11,Control!$A$3,"Month",""&A15),NA()) -> #N/A | F15: Outsourcing | G15: =GETPIVOTDATA(""&F15,Control!$A$3) -> 0.2 | H15: =G15 -> 0.2 | I15: =H15 -> 0.2 | J15: =I15 -> 0.2 | L15: D | M15: =GETPIVOTDATA(L15&"",Control!$A$3) -> 0.91 | N15: =GETPIVOTDATA(L15&2,Control!$A$3) -> 0.7 | O15: Production department
A16: APR | B16: =GETPIVOTDATA("Sum of Payroll",Control!$A$20,"Month",""&A16) -> 160805 | C16: =$C$11 -> 120000 | D16: =IFERROR(GETPIVOTDATA(""&$B$11,Control!$A$3,"Month",""&A16),NA()) -> 160805 | L16: E | M16: =GETPIVOTDATA(L16&"",Control!$A$3) -> 1.07 | N16: =GETPIVOTDATA(L16&2,Control!$A$3) -> 0.3 | O16: Logistics department
A17: MAY | B17: =GETPIVOTDATA("Sum of Payroll",Control!$A$20,"Month",""&A17) -> 220180 | C17: =$C$11 -> 120000 | D17: =IFERROR(GETPIVOTDATA(""&$B$11,Control!$A$3,"Month",""&A17),NA()) -> #N/A
A18: JUN | B18: =GETPIVOTDATA("Sum of Payroll",Control!$A$20,"Month",""&A18) -> 254540 | C18: =$C$11 -> 120000 | D18: =IFERROR(GETPIVOTDATA(""&$B$11,Control!$A$3,"Month",""&A18),NA()) -> #N/A | I18: VALUE | K18: SORT | O18: DATA
A19: JUL | B19: =GETPIVOTDATA("Sum of Payroll",Control!$A$20,"Month",""&A19) -> 254180 | C19: =$C$11 -> 120000 | D19: =IFERROR(GETPIVOTDATA(""&$B$11,Control!$A$3,"Month",""&A19),NA()) -> #N/A | G19: Top 5 Employees Payroll | H19: 1 | I19: Salary | J19: Bonus | L19: Total | M19: Bonus | N19: Base Salary | O19: Empls | P19: Total | Q19: Bonus | R19: Base Salary
A20: AUG | B20: =GETPIVOTDATA("Sum of Payroll",Control!$A$20,"Month",""&A20) -> 253290 | C20: =$C$11 -> 120000 | D20: =IFERROR(GETPIVOTDATA(""&$B$11,Control!$A$3,"Month",""&A20),NA()) -> #N/A | G20: =K20 -> Employee1 | H20: =$H$19 -> 1 | I20: =(M20+N20)/$L$20 -> 1 | J20: =M20/L20 -> 0.53174603 | K20: {=_xlfn._xlws.SORT(O20:R24,2,-1)} -> Employee1 | L20: 12600 | M20: 6700 | N20: 5900 | O20: Employee1 | P20: =SUM(Q20:R20) -> 12600 | Q20: =GETPIVOTDATA(""&O20,Control!$A$3) -> 6700 | R20: =GETPIVOTDATA(O20&2,Control!$A$3) -> 5900
A21: SEP | B21: =GETPIVOTDATA("Sum of Payroll",Control!$A$20,"Month",""&A21) -> 242850 | C21: =$C$11 -> 120000 | D21: =IFERROR(GETPIVOTDATA(""&$B$11,Control!$A$3,"Month",""&A21),NA()) -> #N/A | G21: =K21 -> Employee2 | H21: =$H$19 -> 1 | I21: =(M21+N21)/$L$20 -> 0.93650794 | J21: =M21/L21 -> 0.48305085 | K21: Employee2 | L21: 11800 | M21: 5700 | N21: 6100 | O21: Employee2 | P21: =SUM(Q21:R21) -> 11800 | Q21: =GETPIVOTDATA(""&O21,Control!$A$3) -> 5700 | R21: =GETPIVOTDATA(O21&2,Control!$A$3) -> 6100
A22: OCT | B22: =GETPIVOTDATA("Sum of Payroll",Control!$A$20,"Month",""&A22) -> 237680 | C22: =$C$11 -> 120000 | D22: =IFERROR(GETPIVOTDATA(""&$B$11,Control!$A$3,"Month",""&A22),NA()) -> #N/A | G22: =K22 -> Employee3 | H22: =$H$19 -> 1 | I22: =(M22+N22)/$L$20 -> 0.79365079 | J22: =M22/L22 -> 0.45 | K22: Employee3 | L22: 10000 | M22: 4500 | N22: 5500 | O22: Employee3 | P22: =SUM(Q22:R22) -> 10000 | Q22: =GETPIVOTDATA(""&O22,Control!$A$3) -> 4500 | R22: =GETPIVOTDATA(O22&2,Control!$A$3) -> 5500
A23: NOV | B23: =GETPIVOTDATA("Sum of Payroll",Control!$A$20,"Month",""&A23) -> 197370 | C23: =$C$11 -> 120000 | D23: =IFERROR(GETPIVOTDATA(""&$B$11,Control!$A$3,"Month",""&A23),NA()) -> #N/A | G23: =K23 -> Employee5 | H23: =$H$19 -> 1 | I23: =(M23+N23)/$L$20 -> 0.6984127 | J23: =M23/L23 -> 0.30681818 | K23: Employee5 | L23: 8800 | M23: 2700 | N23: 6100 | O23: Employee4 | P23: =SUM(Q23:R23) -> 8500 | Q23: =GETPIVOTDATA(""&O23,Control!$A$3) -> 5000 | R23: =GETPIVOTDATA(O23&2,Control!$A$3) -> 3500
A24: DEC | B24: =GETPIVOTDATA("Sum of Payroll",Control!$A$20,"Month",""&A24) -> 98395 | C24: =$C$11 -> 120000 | D24: =IFERROR(GETPIVOTDATA(""&$B$11,Control!$A$3,"Month",""&A24),NA()) -> #N/A | G24: =K24 -> Employee4 | H24: =$H$19 -> 1 | I24: =(M24+N24)/$L$20 -> 0.67460317 | J24: =M24/L24 -> 0.58823529 | K24: Employee4 | L24: 8500 | M24: 5000 | N24: 3500 | O24: Employee5 | P24: =SUM(Q24:R24) -> 8800 | Q24: =GETPIVOTDATA(""&O24,Control!$A$3) -> 2700 | R24: =GETPIVOTDATA(O24&2,Control!$A$3) -> 6100
C25: =$C$11 -> 120000
N26: Year | O26: Month
B27: Working Time Heat Map | C27: Day | I27: Day | J27: Shift 1 | K27: Shift 2 | L27: Shift 3 | M27: Shift 4 | N27: =MAX(Control!A37:A40) -> 2025 | O27: {=INDEX(Control!A4:A15,COUNTA(Control!A4:A16)-1)} -> APR
A28: Underwork | B28: 1 | C28: =INT((ROW(Q1)-1)/4)+1 -> 1 | D28: {=INDEX(J$28:J$55,$C28)=$B28} -> FALSE | E28: {=INDEX(K$28:K$55,$C28)=$B28} -> FALSE | F28: {=INDEX(L$28:L$55,$C28)=$B28} -> FALSE | G28: {=INDEX(M$28:M$55,$C28)=$B28} -> TRUE | I28: 1 | J28: {=INDEX('HOTMAP-DATA'!$D$2:$G$1345,MATCH($N$27&$O$27&$I28,'HOTMAP-DATA'!$A$2:$A$1345&'HOTMAP-DATA'!$B$2:$B$1345&'HOTMAP-DATA'!$C$2:$C$1345,0),COLUMN(A$1))} -> 4 | K28: {=INDEX('HOTMAP-DATA'!$D$2:$G$1345,MATCH($N$27&$O$27&$I28,'HOTMAP-DATA'!$A$2:$A$1345&'HOTMAP-DATA'!$B$2:$B$1345&'HOTMAP-DATA'!$C$2:$C$1345,0),COLUMN(B$1))} -> 2 | L28: {=INDEX('HOTMAP-DATA'!$D$2:$G$1345,MATCH($N$27&$O$27&$I28,'HOTMAP-DATA'!$A$2:$A$1345&'HOTMAP-DATA'!$B$2:$B$1345&'HOTMAP-DATA'!$C$2:$C$1345,0),COLUMN(C$1))} -> 3 | M28: {=INDEX('HOTMAP-DATA'!$D$2:$G$1345,MATCH($N$27&$O$27&$I28,'HOTMAP-DATA'!$A$2:$A$1345&'HOTMAP-DATA'!$B$2:$B$1345&'HOTMAP-DATA'!$C$2:$C$1345,0),COLUMN(D$1))} -> 1
A29: Standard Hours | B29: 2 | C29: =INT((ROW(Q2)-1)/4)+1 -> 1 | D29: {=INDEX(J$28:J$55,$C29)=$B29} -> FALSE | E29: {=INDEX(K$28:K$55,$C29)=$B29} -> TRUE | F29: {=INDEX(L$28:L$55,$C29)=$B29} -> FALSE | G29: {=INDEX(M$28:M$55,$C29)=$B29} -> FALSE | I29: 2 | J29: {=INDEX('HOTMAP-DATA'!$D$2:$G$1345,MATCH($N$27&$O$27&$I29,'HOTMAP-DATA'!$A$2:$A$1345&'HOTMAP-DATA'!$B$2:$B$1345&'HOTMAP-DATA'!$C$2:$C$1345,0),COLUMN(A$1))} -> 2 | K29: {=INDEX('HOTMAP-DATA'!$D$2:$G$1345,MATCH($N$27&$O$27&$I29,'HOTMAP-DATA'!$A$2:$A$1345&'HOTMAP-DATA'!$B$2:$B$1345&'HOTMAP-DATA'!$C$2:$C$1345,0),COLUMN(B$1))} -> 1 | L29: {=INDEX('HOTMAP-DATA'!$D$2:$G$1345,MATCH($N$27&$O$27&$I29,'HOTMAP-DATA'!$A$2:$A$1345&'HOTMAP-DATA'!$B$2:$B$1345&'HOTMAP-DATA'!$C$2:$C$1345,0),COLUMN(C$1))} -> 1 | M29: {=INDEX('HOTMAP-DATA'!$D$2:$G$1345,MATCH($N$27&$O$27&$I29,'HOTMAP-DATA'!$A$2:$A$1345&'HOTMAP-DATA'!$B$2:$B$1345&'HOTMAP-DATA'!$C$2:$C$1345,0),COLUMN(D$1))} -> 2
A30: Overtime | B30: 3 | C30: =INT((ROW(Q3)-1)/4)+1 -> 1 | D30: {=INDEX(J$28:J$55,$C30)=$B30} -> FALSE | E30: {=INDEX(K$28:K$55,$C30)=$B30} -> FALSE | F30: {=INDEX(L$28:L$55,$C30)=$B30} -> TRUE | G30: {=INDEX(M$28:M$55,$C30)=$B30} -> FALSE | I30: 3 | J30: {=INDEX('HOTMAP-DATA'!$D$2:$G$1345,MATCH($N$27&$O$27&$I30,'HOTMAP-DATA'!$A$2:$A$1345&'HOTMAP-DATA'!$B$2:$B$1345&'HOTMAP-DATA'!$C$2:$C$1345,0),COLUMN(A$1))} -> 1 | K30: {=INDEX('HOTMAP-DATA'!$D$2:$G$1345,MATCH($N$27&$O$27&$I30,'HOTMAP-DATA'!$A$2:$A$1345&'HOTMAP-DATA'!$B$2:$B$1345&'HOTMAP-DATA'!$C$2:$C$1345,0),COLUMN(B$1))} -> 3 | L30: {=INDEX('HOTMAP-DATA'!$D$2:$G$1345,MATCH($N$27&$O$27&$I30,'HOTMAP-DATA'!$A$2:$A$1345&'HOTMAP-DATA'!$B$2:$B$1345&'HOTMAP-DATA'!$C$2:$C$1345,0),COLUMN(C$1))} -> 2 | M30: {=INDEX('HOTMAP-DATA'!$D$2:$G$1345,MATCH($N$27&$O$27&$I30,'HOTMAP-DATA'!$A$2:$A$1345&'HOTMAP-DATA'!$B$2:$B$1345&'HOTMAP-DATA'!$C$2:$C$1345,0),COLUMN(D$1))} -> 1
A31: Excessive Overtime | B31: 4 | C31: =INT((ROW(Q4)-1)/4)+1 -> 1 | D31: {=INDEX(J$28:J$55,$C31)=$B31} -> TRUE | E31: {=INDEX(K$28:K$55,$C31)=$B31} -> FALSE | F31: {=INDEX(L$28:L$55,$C31)=$B31} -> FALSE | G31: {=INDEX(M$28:M$55,$C31)=$B31} -> FALSE | I31: 4 | J31: {=INDEX('HOTMAP-DATA'!$D$2:$G$1345,MATCH($N$27&$O$27&$I31,'HOTMAP-DATA'!$A$2:$A$1345&'HOTMAP-DATA'!$B$2:$B$1345&'HOTMAP-DATA'!$C$2:$C$1345,0),COLUMN(A$1))} -> 2 | K31: {=INDEX('HOTMAP-DATA'!$D$2:$G$1345,MATCH($N$27&$O$27&$I31,'HOTMAP-DATA'!$A$2:$A$1345&'HOTMAP-DATA'!$B$2:$B$1345&'HOTMAP-DATA'!$C$2:$C$1345,0),COLUMN(B$1))} -> 1 | L31: {=INDEX('HOTMAP-DATA'!$D$2:$G$1345,MATCH($N$27&$O$27&$I31,'HOTMAP-DATA'!$A$2:$A$1345&'HOTMAP-DATA'!$B$2:$B$1345&'HOTMAP-DATA'!$C$2:$C$1345,0),COLUMN(C$1))} -> 1 | M31: {=INDEX('HOTMAP-DATA'!$D$2:$G$1345,MATCH($N$27&$O$27&$I31,'HOTMAP-DATA'!$A$2:$A$1345&'HOTMAP-DATA'!$B$2:$B$1345&'HOTMAP-DATA'!$C$2:$C$1345,0),COLUMN(D$1))} -> 3
B32: 1 | C32: =INT((ROW(Q5)-1)/4)+1 -> 2 | D32: {=INDEX(J$28:J$55,$C32)=$B32} -> FALSE | E32: {=INDEX(K$28:K$55,$C32)=$B32} -> TRUE | F32: {=INDEX(L$28:L$55,$C32)=$B32} -> TRUE | G32: {=INDEX(M$28:M$55,$C32)=$B32} -> FALSE | I32: 5 | J32: {=INDEX('HOTMAP-DATA'!$D$2:$G$1345,MATCH($N$27&$O$27&$I32,'HOTMAP-DATA'!$A$2:$A$1345&'HOTMAP-DATA'!$B$2:$B$1345&'HOTMAP-DATA'!$C$2:$C$1345,0),COLUMN(A$1))} -> 2 | K32: {=INDEX('HOTMAP-DATA'!$D$2:$G$1345,MATCH($N$27&$O$27&$I32,'HOTMAP-DATA'!$A$2:$A$1345&'HOTMAP-DATA'!$B$2:$B$1345&'HOTMAP-DATA'!$C$2:$C$1345,0),COLUMN(B$1))} -> 2 | L32: {=INDEX('HOTMAP-DATA'!$D$2:$G$1345,MATCH($N$27&$O$27&$I32,'HOTMAP-DATA'!$A$2:$A$1345&'HOTMAP-DATA'!$B$2:$B$1345&'HOTMAP-DATA'!$C$2:$C$1345,0),COLUMN(C$1))} -> 1 | M32: {=INDEX('HOTMAP-DATA'!$D$2:$G$1345,MATCH($N$27&$O$27&$I32,'HOTMAP-DATA'!$A$2:$A$1345&'HOTMAP-DATA'!$B$2:$B$1345&'HOTMAP-DATA'!$C$2:$C$1345,0),COLUMN(D$1))} -> 3
B33: 2 | C33: =INT((ROW(Q6)-1)/4)+1 -> 2 | D33: {=INDEX(J$28:J$55,$C33)=$B33} -> TRUE | E33: {=INDEX(K$28:K$55,$C33)=$B33} -> FALSE | F33: {=INDEX(L$28:L$55,$C33)=$B33} -> FALSE | G33: {=INDEX(M$28:M$55,$C33)=$B33} -> TRUE | I33: 6 | J33: {=INDEX('HOTMAP-DATA'!$D$2:$G$1345,MATCH($N$27&$O$27&$I33,'HOTMAP-DATA'!$A$2:$A$1345&'HOTMAP-DATA'!$B$2:$B$1345&'HOTMAP-DATA'!$C$2:$C$1345,0),COLUMN(A$1))} -> 2 | K33: {=INDEX('HOTMAP-DATA'!$D$2:$G$1345,MATCH($N$27&$O$27&$I33,'HOTMAP-DATA'!$A$2:$A$1345&'HOTMAP-DATA'!$B$2:$B$1345&'HOTMAP-DATA'!$C$2:$C$1345,0),COLUMN(B$1))} -> 2 | L33: {=INDEX('HOTMAP-DATA'!$D$2:$G$1345,MATCH($N$27&$O$27&$I33,'HOTMAP-DATA'!$A$2:$A$1345&'HOTMAP-DATA'!$B$2:$B$1345&'HOTMAP-DATA'!$C$2:$C$1345,0),COLUMN(C$1))} -> 2 | M33: {=INDEX('HOTMAP-DATA'!$D$2:$G$1345,MATCH($N$27&$O$27&$I33,'HOTMAP-DATA'!$A$2:$A$1345&'HOTMAP-DATA'!$B$2:$B$1345&'HOTMAP-DATA'!$C$2:$C$1345,0),COLUMN(D$1))} -> 2
B34: 3 | C34: =INT((ROW(Q7)-1)/4)+1 -> 2 | D34: {=INDEX(J$28:J$55,$C34)=$B34} -> FALSE | E34: {=INDEX(K$28:K$55,$C34)=$B34} -> FALSE | F34: {=INDEX(L$28:L$55,$C34)=$B34} -> FALSE | G34: {=INDEX(M$28:M$55,$C34)=$B34} -> FALSE | I34: 7 | J34: {=INDEX('HOTMAP-DATA'!$D$2:$G$1345,MATCH($N$27&$O$27&$I34,'HOTMAP-DATA'!$A$2:$A$1345&'HOTMAP-DATA'!$B$2:$B$1345&'HOTMAP-DATA'!$C$2:$C$1345,0),COLUMN(A$1))} -> 2 | K34: {=INDEX('HOTMAP-DATA'!$D$2:$G$1345,MATCH($N$27&$O$27&$I34,'HOTMAP-DATA'!$A$2:$A$1345&'HOTMAP-DATA'!$B$2:$B$1345&'HOTMAP-DATA'!$C$2:$C$1345,0),COLUMN(B$1))} -> 3 | L34: {=INDEX('HOTMAP-DATA'!$D$2:$G$1345,MATCH($N$27&$O$27&$I34,'HOTMAP-DATA'!$A$2:$A$1345&'HOTMAP-DATA'!$B$2:$B$1345&'HOTMAP-DATA'!$C$2:$C$1345,0),COLUMN(C$1))} -> 1 | M34: {=INDEX('HOTMAP-DATA'!$D$2:$G$1345,MATCH($N$27&$O$27&$I34,'HOTMAP-DATA'!$A$2:$A$1345&'HOTMAP-DATA'!$B$2:$B$1345&'HOTMAP-DATA'!$C$2:$C$1345,0),COLUMN(D$1))} -> 3
B35: 4 | C35: =INT((ROW(Q8)-1)/4)+1 -> 2 | D35: {=INDEX(J$28:J$55,$C35)=$B35} -> FALSE | E35: {=INDEX(K$28:K$55,$C35)=$B35} -> FALSE | F35: {=INDEX(L$28:L$55,$C35)=$B35} -> FALSE | G35: {=INDEX(M$28:M$55,$C35)=$B35} -> FALSE | I35: 8 | J35: {=INDEX('HOTMAP-DATA'!$D$2:$G$1345,MATCH($N$27&$O$27&$I35,'HOTMAP-DATA'!$A$2:$A$1345&'HOTMAP-DATA'!$B$2:$B$1345&'HOTMAP-DATA'!$C$2:$C$1345,0),COLUMN(A$1))} -> 1 | K35: {=INDEX('HOTMAP-DATA'!$D$2:$G$1345,MATCH($N$27&$O$27&$I35,'HOTMAP-DATA'!$A$2:$A$1345&'HOTMAP-DATA'!$B$2:$B$1345&'HOTMAP-DATA'!$C$2:$C$1345,0),COLUMN(B$1))} -> 3 | L35: {=INDEX('HOTMAP-DATA'!$D$2:$G$1345,MATCH($N$27&$O$27&$I35,'HOTMAP-DATA'!$A$2:$A$1345&'HOTMAP-DATA'!$B$2:$B$1345&'HOTMAP-DATA'!$C$2:$C$1345,0),COLUMN(C$1))} -> 1 | M35: {=INDEX('HOTMAP-DATA'!$D$2:$G$1345,MATCH($N$27&$O$27&$I35,'HOTMAP-DATA'!$A$2:$A$1345&'HOTMAP-DATA'!$B$2:$B$1345&'HOTMAP-DATA'!$C$2:$C$1345,0),COLUMN(D$1))} -> 3
B36: 1 | C36: =INT((ROW(Q9)-1)/4)+1 -> 3 | D36: {=INDEX(J$28:J$55,$C36)=$B36} -> TRUE | E36: {=INDEX(K$28:K$55,$C36)=$B36} -> FALSE | F36: {=INDEX(L$28:L$55,$C36)=$B36} -> FALSE | G36: {=INDEX(M$28:M$55,$C36)=$B36} -> TRUE | I36: 9 | J36: {=INDEX('HOTMAP-DATA'!$D$2:$G$1345,MATCH($N$27&$O$27&$I36,'HOTMAP-DATA'!$A$2:$A$1345&'HOTMAP-DATA'!$B$2:$B$1345&'HOTMAP-DATA'!$C$2:$C$1345,0),COLUMN(A$1))} -> 3 | K36: {=INDEX('HOTMAP-DATA'!$D$2:$G$1345,MATCH($N$27&$O$27&$I36,'HOTMAP-DATA'!$A$2:$A$1345&'HOTMAP-DATA'!$B$2:$B$1345&'HOTMAP-DATA'!$C$2:$C$1345,0),COLUMN(B$1))} -> 2 | L36: {=INDEX('HOTMAP-DATA'!$D$2:$G$1345,MATCH($N$27&$O$27&$I36,'HOTMAP-DATA'!$A$2:$A$1345&'HOTMAP-DATA'!$B$2:$B$1345&'HOTMAP-DATA'!$C$2:$C$1345,0),COLUMN(C$1))} -> 1 | M36: {=INDEX('HOTMAP-DATA'!$D$2:$G$1345,MATCH($N$27&$O$27&$I36,'HOTMAP-DATA'!$A$2:$A$1345&'HOTMAP-DATA'!$B$2:$B$1345&'HOTMAP-DATA'!$C$2:$C$1345,0),COLUMN(D$1))} -> 2
B37: 2 | C37: =INT((ROW(Q10)-1)/4)+1 -> 3 | D37: {=INDEX(J$28:J$55,$C37)=$B37} -> FALSE | E37: {=INDEX(K$28:K$55,$C37)=$B37} -> FALSE | F37: {=INDEX(L$28:L$55,$C37)=$B37} -> TRUE | G37: {=INDEX(M$28:M$55,$C37)=$B37} -> FALSE | I37: 10 | J37: {=INDEX('HOTMAP-DATA'!$D$2:$G$1345,MATCH($N$27&$O$27&$I37,'HOTMAP-DATA'!$A$2:$A$1345&'HOTMAP-DATA'!$B$2:$B$1345&'HOTMAP-DATA'!$C$2:$C$1345,0),COLUMN(A$1))} -> 1 | K37: {=INDEX('HOTMAP-DATA'!$D$2:$G$1345,MATCH($N$27&$O$27&$I37,'HOTMAP-DATA'!$A$2:$A$1345&'HOTMAP-DATA'!$B$2:$B$1345&'HOTMAP-DATA'!$C$2:$C$1345,0),COLUMN(B$1))} -> 1 | L37: {=INDEX('HOTMAP-DATA'!$D$2:$G$1345,MATCH($N$27&$O$27&$I37,'HOTMAP-DATA'!$A$2:$A$1345&'HOTMAP-DATA'!$B$2:$B$1345&'HOTMAP-DATA'!$C$2:$C$1345,0),COLUMN(C$1))} -> 1 | M37: {=INDEX('HOTMAP-DATA'!$D$2:$G$1345,MATCH($N$27&$O$27&$I37,'HOTMAP-DATA'!$A$2:$A$1345&'HOTMAP-DATA'!$B$2:$B$1345&'HOTMAP-DATA'!$C$2:$C$1345,0),COLUMN(D$1))} -> 1
B38: 3 | C38: =INT((ROW(Q11)-1)/4)+1 -> 3 | D38: {=INDEX(J$28:J$55,$C38)=$B38} -> FALSE | E38: {=INDEX(K$28:K$55,$C38)=$B38} -> TRUE | F38: {=INDEX(L$28:L$55,$C38)=$B38} -> FALSE | G38: {=INDEX(M$28:M$55,$C38)=$B38} -> FALSE | I38: 11 | J38: {=INDEX('HOTMAP-DATA'!$D$2:$G$1345,MATCH($N$27&$O$27&$I38,'HOTMAP-DATA'!$A$2:$A$1345&'HOTMAP-DATA'!$B$2:$B$1345&'HOTMAP-DATA'!$C$2:$C$1345,0),COLUMN(A$1))} -> 2 | K38: {=INDEX('HOTMAP-DATA'!$D$2:$G$1345,MATCH($N$27&$O$27&$I38,'HOTMAP-DATA'!$A$2:$A$1345&'HOTMAP-DATA'!$B$2:$B$1345&'HOTMAP-DATA'!$C$2:$C$1345,0),COLUMN(B$1))} -> 1 | L38: {=INDEX('HOTMAP-DATA'!$D$2:$G$1345,MATCH($N$27&$O$27&$I38,'HOTMAP-DATA'!$A$2:$A$1345&'HOTMAP-DATA'!$B$2:$B$1345&'HOTMAP-DATA'!$C$2:$C$1345,0),COLUMN(C$1))} -> 3 | M38: {=INDEX('HOTMAP-DATA'!$D$2:$G$1345,MATCH($N$27&$O$27&$I38,'HOTMAP-DATA'!$A$2:$A$1345&'HOTMAP-DATA'!$B$2:$B$1345&'HOTMAP-DATA'!$C$2:$C$1345,0),COLUMN(D$1))} -> 3
B39: 4 | C39: =INT((ROW(Q12)-1)/4)+1 -> 3 | D39: {=INDEX(J$28:J$55,$C39)=$B39} -> FALSE | E39: {=INDEX(K$28:K$55,$C39)=$B39} -> FALSE | F39: {=INDEX(L$28:L$55,$C39)=$B39} -> FALSE | G39: {=INDEX(M$28:M$55,$C39)=$B39} -> FALSE | I39: 12 | J39: {=INDEX('HOTMAP-DATA'!$D$2:$G$1345,MATCH($N$27&$O$27&$I39,'HOTMAP-DATA'!$A$2:$A$1345&'HOTMAP-DATA'!$B$2:$B$1345&'HOTMAP-DATA'!$C$2:$C$1345,0),COLUMN(A$1))} -> 3 | K39: {=INDEX('HOTMAP-DATA'!$D$2:$G$1345,MATCH($N$27&$O$27&$I39,'HOTMAP-DATA'!$A$2:$A$1345&'HOTMAP-DATA'!$B$2:$B$1345&'HOTMAP-DATA'!$C$2:$C$1345,0),COLUMN(B$1))} -> 1 | L39: {=INDEX('HOTMAP-DATA'!$D$2:$G$1345,MATCH($N$27&$O$27&$I39,'HOTMAP-DATA'!$A$2:$A$1345&'HOTMAP-DATA'!$B$2:$B$1345&'HOTMAP-DATA'!$C$2:$C$1345,0),COLUMN(C$1))} -> 4 | M39: {=INDEX('HOTMAP-DATA'!$D$2:$G$1345,MATCH($N$27&$O$27&$I39,'HOTMAP-DATA'!$A$2:$A$1345&'HOTMAP-DATA'!$B$2:$B$1345&'HOTMAP-DATA'!$C$2:$C$1345,0),COLUMN(D$1))} -> 4
B40: 1 | C40: =INT((ROW(Q13)-1)/4)+1 -> 4 | D40: {=INDEX(J$28:J$55,$C40)=$B40} -> FALSE | E40: {=INDEX(K$28:K$55,$C40)=$B40} -> TRUE | F40: {=INDEX(L$28:L$55,$C40)=$B40} -> TRUE | G40: {=INDEX(M$28:M$55,$C40)=$B40} -> FALSE | I40: 13 | J40: {=INDEX('HOTMAP-DATA'!$D$2:$G$1345,MATCH($N$27&$O$27&$I40,'HOTMAP-DATA'!$A$2:$A$1345&'HOTMAP-DATA'!$B$2:$B$1345&'HOTMAP-DATA'!$C$2:$C$1345,0),COLUMN(A$1))} -> 1 | K40: {=INDEX('HOTMAP-DATA'!$D$2:$G$1345,MATCH($N$27&$O$27&$I40,'HOTMAP-DATA'!$A$2:$A$1345&'HOTMAP-DATA'!$B$2:$B$1345&'HOTMAP-DATA'!$C$2:$C$1345,0),COLUMN(B$1))} -> 3 | L40: {=INDEX('HOTMAP-DATA'!$D$2:$G$1345,MATCH($N$27&$O$27&$I40,'HOTMAP-DATA'!$A$2:$A$1345&'HOTMAP-DATA'!$B$2:$B$1345&'HOTMAP-DATA'!$C$2:$C$1345,0),COLUMN(C$1))} -> 3 | M40: {=INDEX('HOTMAP-DATA'!$D$2:$G$1345,MATCH($N$27&$O$27&$I40,'HOTMAP-DATA'!$A$2:$A$1345&'HOTMAP-DATA'!$B$2:$B$1345&'HOTMAP-DATA'!$C$2:$C$1345,0),COLUMN(D$1))} -> 2
...

Sheet Control
A3: Row Labels | B3: Sum of Management | C3: Sum of Administrative Staff | D3: Sum of Sales Department | E3: Sum of Production Department | F3: Sum of Logistics Department | G3: Average of Basic Payroll | H3: Average of Bonuses and Prizes | I3: Average of Payroll Taxes & Insurance | J3: Sum of SU | K3: Sum of MO | L3: Sum of TU | M3: Sum of WE | N3: Sum of TH | O3: Sum of FR | P3: Sum of SA | Q3: Sum of SU2 | R3: Sum of MO2 | S3: Sum of TU2 | T3: Sum of WE2 | U3: Sum of TH2 | V3: Sum of FR2 | W3: Sum of SA2 | X3: Average of Head Office | Y3: Average of Regional Offices | Z3: Average of Regional Branches | AA3: Average of Remote Employees | AB3: Average of Outsourcing | AC3: Average of Standard Hours | AD3: Average of Actual Hours | AE3: Sum of Employee1 | AF3: Sum of Employee2 | AG3: Sum of Employee3 | AH3: Sum of Employee4 | AI3: Sum of Employee5 | AJ3: Sum of Employee12 | AK3: Sum of Employee22 | AL3: Sum of Employee32 | AM3: Sum of Employee42 | AN3: Sum of Employee52 | AO3: Average of A | AP3: Average of B | AQ3: Average of C | AR3: Average of D | AS3: Average of E | AT3: Average of A2 | AU3: Average of B2 | AV3: Average of C2 | AW3: Average of D2 | AX3: Average of E2 | AY3: Sum of Payroll
A4: APR | B4: 36840 | C4: 23340 | D4: 36425 | E4: 33470 | F4: 30730 | G4: 0.36 | H4: 0.45 | I4: 0.19 | J4: 28363 | K4: 32559 | L4: 2859 | M4: 44682 | N4: 89111 | O4: 8141 | P4: 34285 | Q4: 19542 | R4: 42659 | S4: 40003 | T4: 20115 | U4: 40007 | V4: 40200 | W4: 33754 | X4: 0.31 | Y4: 0.3 | Z4: 0.12 | AA4: 0.07 | AB4: 0.2 | AC4: 0.4 | AD4: 0.24 | AE4: 6700 | AF4: 5700 | AG4: 4500 | AH4: 5000 | AI4: 2700 | AJ4: 5900 | AK4: 6100 | AL4: 5500 | AM4: 3500 | AN4: 6100 | AO4: 1.24 | AP4: 1.06 | AQ4: 1.08 | AR4: 0.91 | AS4: 1.07 | AT4: 0.26 | AU4: 0.31 | AV4: 0.56 | AW4: 0.7 | AX4: 0.3 | AY4: 160805
A5: Grand Total | B5: 36840 | C5: 23340 | D5: 36425 | E5: 33470 | F5: 30730 | G5: 0.36 | H5: 0.45 | I5: 0.19 | J5: 28363 | K5: 32559 | L5: 2859 | M5: 44682 | N5: 89111 | O5: 8141 | P5: 34285 | Q5: 19542 | R5: 42659 | S5: 40003 | T5: 20115 | U5: 40007 | V5: 40200 | W5: 33754 | X5: 0.31 | Y5: 0.3 | Z5: 0.12 | AA5: 0.07 | AB5: 0.2 | AC5: 0.4 | AD5: 0.24 | AE5: 6700 | AF5: 5700 | AG5: 4500 | AH5: 5000 | AI5: 2700 | AJ5: 5900 | AK5: 6100 | AL5: 5500 | AM5: 3500 | AN5: 6100 | AO5: 1.24 | AP5: 1.06 | AQ5: 1.08 | AR5: 0.91 | AS5: 1.07 | AT5: 0.26 | AU5: 0.31 | AV5: 0.56 | AW5: 0.7 | AX5: 0.3 | AY5: 160805
A20: Row Labels | B20: Sum of Payroll | C20: Average of Annual Payroll Plan
A21: JAN | B21: 107635 | C21: 120000
A22: FEB | B22: 153595 | C22: 120000
A23: MAR | B23: 156760 | C23: 120000
A24: APR | B24: 160805 | C24: 120000
A25: MAY | B25: 220180 | C25: 120000
A26: JUN | B26: 254540 | C26: 120000
A27: JUL | B27: 254180 | C27: 120000
A28: AUG | B28: 253290 | C28: 120000
A29: SEP | B29: 242850 | C29: 120000
A30: OCT | B30: 237680 | C30: 120000
A31: NOV | B31: 197370 | C31: 120000
A32: DEC | B32: 98395 | C32: 120000
A33: Grand Total | B33: 2337280 | C33: 120000
A36: Row Labels
A37: 2025

Sheet Data
T1: Employee Performance | AD1: Payroll Forecast | AR1: Top 5 Employees Payroll
C2: Employee Categories | H2: Payroll Cost Breakdown | K2: Payroll Fund | M2: Payroll WHR | O2: PDL | T2: KPI | Y2: Compensation | AD2: Planned Payroll | AK2: Actual Payroll | AR2: Bonus | AW2: Base Salary
A3: Year | B3: Month | C3: Management | D3: Administrative Staff | E3: Sales Department | F3: Production Department | G3: Logistics Department | H3: Basic Payroll | I3: Bonuses and Prizes | J3: Payroll Taxes & Insurance | K3: Payroll | L3: Annual Payroll Plan | M3: Standard Hours | N3: Actual Hours | O3: Head Office | P3: Regional Offices | Q3: Regional Branches | R3: Remote Employees | S3: Outsourcing | T3: A | U3: B | V3: C | W3: D | X3: E | Y3: A | Z3: B | AA3: C | AB3: D | AC3: E | AD3: SU | AE3: MO | AF3: TU | AG3: WE | AH3: TH | AI3: FR | AJ3: SA | AK3: SU | AL3: MO | AM3: TU | AN3: WE | AO3: TH | AP3: FR | AQ3: SA | AR3: Employee1 | AS3: Employee2 | AT3: Employee3 | AU3: Employee4 | AV3: Employee5 | AW3: Employee1 | AX3: Employee2 | AY3: Employee3 | AZ3: Employee4 | BA3: Employee5
A4: 2025 | B4: JAN | C4: 28340 | D4: 18130 | E4: 20185 | F4: 20270 | G4: 20710 | H4: 0.4 | I4: 0.41 | J4: 0.19 | K4: =SUM(C4:G4) -> 107635 | L4: 120000 | M4: 0.33 | N4: 0.71 | O4: 0.26 | P4: 0.23 | Q4: 0.12 | R4: 0.11 | S4: 0.28 | T4: 1.08 | U4: 0.47 | V4: 1.34 | W4: 0.47 | X4: 0.5 | Y4: 0.46 | Z4: 0.39 | AA4: 0.59 | AB4: 0.48 | AC4: 0.7 | AD4: 59867 | AE4: 29705 | AF4: 695 | AG4: 88522 | AH4: 10928 | AI4: 15996 | AJ4: 34287 | AK4: 33107 | AL4: 10047 | AM4: 37625 | AN4: 42413 | AO4: 37885 | AP4: 27649 | AQ4: 31454 | AR4: 5200 | AS4: 3100 | AT4: 6300 | AU4: 6000 | AV4: 6600 | AW4: 7300 | AX4: 4300 | AY4: 4500 | AZ4: 4100 | BA4: 4100
A5: 2025 | B5: FEB | C5: 33090 | D5: 19480 | E5: 23855 | F5: 43990 | G5: 33180 | H5: 0.37 | I5: 0.43 | J5: 0.2 | K5: =SUM(C5:G5) -> 153595 | L5: 120000 | M5: 0.17 | N5: 0.5 | O5: 0.34 | P5: 0.23 | Q5: 0.12 | R5: 0.12 | S5: 0.19 | T5: 0.91 | U5: 0.54 | V5: 1.32 | W5: 0.52 | X5: 1.13 | Y5: 0.48 | Z5: 0.56 | AA5: 0.57 | AB5: 0.38 | AC5: 0.64 | AD5: 10456 | AE5: 27396 | AF5: 49816 | AG5: 34348 | AH5: 38205 | AI5: 45492 | AJ5: 34287 | AK5: 42731 | AL5: 41459 | AM5: 21075 | AN5: 31812 | AO5: 21932 | AP5: 38151 | AQ5: 32860 | AR5: 9300 | AS5: 2900 | AT5: 3800 | AU5: 4800 | AV5: 6100 | AW5: 3600 | AX5: 5700 | AY5: 5400 | AZ5: 3300 | BA5: 3700
A6: 2025 | B6: MAR | C6: 31685 | D6: 33955 | E6: 27270 | F6: 34630 | G6: 29220 | H6: 0.35 | I6: 0.48 | J6: 0.17 | K6: =SUM(C6:G6) -> 156760 | L6: 120000 | M6: 0.64 | N6: 0.64 | O6: 0.28 | P6: 0.21 | Q6: 0.16 | R6: 0.11 | S6: 0.24 | T6: 0.91 | U6: 0.35 | V6: 1.21 | W6: 0.98 | X6: 0.81 | Y6: 0.57 | Z6: 0.45 | AA6: 0.61 | AB6: 0.38 | AC6: 0.26 | AD6: 24662 | AE6: 37454 | AF6: 37903 | AG6: 47190 | AH6: 44974 | AI6: 13532 | AJ6: 34285 | AK6: 53313 | AL6: 4272 | AM6: 27492 | AN6: 43898 | AO6: 38795 | AP6: 42932 | AQ6: 35118 | AR6: 7000 | AS6: 3000 | AT6: 7000 | AU6: 8300 | AV6: 2800 | AW6: 3100 | AX6: 5500 | AY6: 4400 | AZ6: 3500 | BA6: 5200
A7: 2025 | B7: APR | C7: 36840 | D7: 23340 | E7: 36425 | F7: 33470 | G7: 30730 | H7: 0.36 | I7: 0.45 | J7: 0.19 | K7: =SUM(C7:G7) -> 160805 | L7: 120000 | M7: 0.4 | N7: 0.24 | O7: 0.31 | P7: 0.3 | Q7: 0.12 | R7: 0.07 | S7: 0.2 | T7: 1.24 | U7: 1.06 | V7: 1.08 | W7: 0.91 | X7: 1.07 | Y7: 0.26 | Z7: 0.31 | AA7: 0.56 | AB7: 0.7 | AC7: 0.3 | AD7: 28363 | AE7: 32559 | AF7: 2859 | AG7: 44682 | AH7: 89111 | AI7: 8141 | AJ7: 34285 | AK7: 19542 | AL7: 42659 | AM7: 40003 | AN7: 20115 | AO7: 40007 | AP7: 40200 | AQ7: 33754 | AR7: 6700 | AS7: 5700 | AT7: 4500 | AU7: 5000 | AV7: 2700 | AW7: 5900 | AX7: 6100 | AY7: 5500 | AZ7: 3500 | BA7: 6100
A8: 2025 | B8: MAY | C8: 64590 | D8: 41860 | E8: 49940 | F8: 34330 | G8: 29460 | H8: 0.36 | I8: 0.4 | J8: 0.24 | K8: =SUM(C8:G8) -> 220180 | L8: 120000 | M8: 0.2 | N8: 0.25 | O8: 0.31 | P8: 0.22 | Q8: 0.13 | R8: 0.14 | S8: 0.2 | T8: 0.94 | U8: 0.99 | V8: 0.77 | W8: 1.02 | X8: 0.76 | Y8: 0.3 | Z8: 0.59 | AA8: 0.31 | AB8: 0.73 | AC8: 0.55 | AD8: 6097 | AE8: 46394 | AF8: 56704 | AG8: 18425 | AH8: 17854 | AI8: 60241 | AJ8: 34285 | AK8: 48037 | AL8: 41586 | AM8: 31950 | AN8: 44847 | AO8: 8193 | AP8: 43737 | AQ8: 36390 | AR8: 8900 | AS8: 3400 | AT8: 2900 | AU8: 4000 | AV8: 4500 | AW8: 3500 | AX8: 5400 | AY8: 4200 | AZ8: 2900 | BA8: 6600
A9: 2025 | B9: JUN | C9: 76530 | D9: 54200 | E9: 45950 | F9: 42900 | G9: 34960 | H9: 0.38 | I9: 0.5 | J9: 0.12 | K9: =SUM(C9:G9) -> 254540 | L9: 120000 | M9: 0.44 | N9: 0.69 | O9: 0.35 | P9: 0.21 | Q9: 0.16 | R9: 0.08 | S9: 0.2 | T9: 1.1 | U9: 1.25 | V9: 0.85 | W9: 1.31 | X9: 0.94 | Y9: 0.59 | Z9: 0.56 | AA9: 0.7 | AB9: 0.73 | AC9: 0.39 | AD9: 23965 | AE9: 47071 | AF9: 30345 | AG9: 36671 | AH9: 54945 | AI9: 12717 | AJ9: 34286 | AK9: 31971 | AL9: 45318 | AM9: 39555 | AN9: 45223 | AO9: 16585 | AP9: 43065 | AQ9: 36953 | AR9: 6200 | AS9: 3200 | AT9: 4200 | AU9: 3100 | AV9: 4900 | AW9: 4000 | AX9: 4600 | AY9: 5500 | AZ9: 5200 | BA9: 3800
A10: 2025 | B10: JUL | C10: 84020 | D10: 53040 | E10: 54240 | F10: 32710 | G10: 30170 | H10: 0.37 | I10: 0.48 | J10: 0.15 | K10: =SUM(C10:G10) -> 254180 | L10: 120000 | M10: 0.24 | N10: 0.41 | O10: 0.31 | P10: 0.2 | Q10: 0.16 | R10: 0.11 | S10: 0.22 | T10: 0.37 | U10: 0.46 | V10: 0.68 | W10: 1.24 | X10: 0.88 | Y10: 0.52 | Z10: 0.61 | AA10: 0.34 | AB10: 0.48 | AC10: 0.33 | AD10: 33952 | AE10: 59758 | AF10: 23186 | AG10: 5088 | AH10: 15481 | AI10: 68250 | AJ10: 34285 | AK10: 73225 | AL10: 82752 | AM10: 6957 | AN10: 11539 | AO10: 18644 | AP10: 7222 | AQ10: 33391 | AR10: 4900 | AS10: 4800 | AT10: 2300 | AU10: 2700 | AV10: 4700 | AW10: 4100 | AX10: 3400 | AY10: 4700 | AZ10: 4800 | BA10: 2500
A11: 2025 | B11: AUG | C11: 84170 | D11: 49190 | E11: 50140 | F11: 41480 | G11: 28310 | H11: 0.37 | I11: 0.44 | J11: 0.19 | K11: =SUM(C11:G11) -> 253290 | L11: 120000 | M11: 0.75 | N11: 0.6 | O11: 0.34 | P11: 0.26 | Q11: 0.17 | R11: 0.12 | S11: 0.11 | T11: 0.53 | U11: 1.05 | V11: 0.59 | W11: 0.44 | X11: 0.64 | Y11: 0.51 | Z11: 0.29 | AA11: 0.3 | AB11: 0.41 | AC11: 0.32 | AD11: 44592 | AE11: 48774 | AF11: 27775 | AG11: 25626 | AH11: 32862 | AI11: 26085 | AJ11: 34286 | AK11: 56058 | AL11: 49917 | AM11: 48765 | AN11: 42341 | AO11: 4345 | AP11: 13391 | AQ11: 35803 | AR11: 7900 | AS11: 5400 | AT11: 5800 | AU11: 4800 | AV11: 3300 | AW11: 4300 | AX11: 5100 | AY11: 3000 | AZ11: 2200 | BA11: 7000
A12: 2025 | B12: SEP | C12: 78630 | D12: 41370 | E12: 53770 | F12: 37090 | G12: 31990 | H12: 0.37 | I12: 0.44 | J12: 0.19 | K12: =SUM(C12:G12) -> 242850 | L12: 120000 | M12: 0.73 | N12: 0.5 | O12: 0.33 | P12: 0.21 | Q12: 0.17 | R12: 0.11 | S12: 0.18 | T12: 0.74 | U12: 0.45 | V12: 1.24 | W12: 0.38 | X12: 1.06 | Y12: 0.72 | Z12: 0.42 | AA12: 0.38 | AB12: 0.74 | AC12: 0.49 | AD12: 41608 | AE12: 38687 | AF12: 32685 | AG12: 40758 | AH12: 15259 | AI12: 36718 | AJ12: 34285 | AK12: 17916 | AL12: 14439 | AM12: 6383 | AN12: 47775 | AO12: 68781 | AP12: 62626 | AQ12: 36320 | AR12: 6900 | AS12: 5400 | AT12: 3400 | AU12: 4800 | AV12: 4500 | AW12: 4200 | AX12: 5400 | AY12: 6000 | AZ12: 5200 | BA12: 5600
A13: 2025 | B13: OCT | C13: 60760 | D13: 50950 | E13: 53140 | F13: 38170 | G13: 34660 | H13: 0.39 | I13: 0.54 | J13: 0.07 | K13: =SUM(C13:G13) -> 237680 | L13: 120000 | M13: 0.72 | N13: 0.47 | O13: 0.28 | P13: 0.21 | Q13: 0.13 | R13: 0.05 | S13: 0.33 | T13: 0.62 | U13: 0.87 | V13: 1.18 | W13: 0.38 | X13: 0.36 | Y13: 0.35 | Z13: 0.45 | AA13: 0.63 | AB13: 0.61 | AC13: 0.53 | AD13: 55756 | AE13: 73802 | AF13: 10991 | AG13: 7018 | AH13: 46491 | AI13: 11657 | AJ13: 34285 | AK13: 30546 | AL13: 14673 | AM13: 18630 | AN13: 49112 | AO13: 49019 | AP13: 29146 | AQ13: 31854 | AR13: 9700 | AS13: 2900 | AT13: 4600 | AU13: 5300 | AV13: 6000 | AW13: 3500 | AX13: 6500 | AY13: 2400 | AZ13: 5900 | BA13: 3000
A14: 2025 | B14: NOV | C14: 44165 | D14: 37275 | E14: 37120 | F14: 44480 | G14: 34330 | H14: 0.38 | I14: 0.45 | J14: 0.17 | K14: =SUM(C14:G14) -> 197370 | L14: 120000 | M14: 0.73 | N14: 0.75 | O14: 0.25 | P14: 0.22 | Q14: 0.15 | R14: 0.07 | S14: 0.31 | T14: 0.63 | U14: 0.97 | V14: 0.82 | W14: 1.07 | X14: 0.72 | Y14: 0.61 | Z14: 0.4 | AA14: 0.68 | AB14: 0.39 | AC14: 0.63 | AD14: 41610 | AE14: 2642 | AF14: 48284 | AG14: 17938 | AH14: 48687 | AI14: 46554 | AJ14: 34285 | AK14: 58809 | AL14: 44756 | AM14: 6109 | AN14: 24468 | AO14: 33398 | AP14: 49565 | AQ14: 36185 | AR14: 5400 | AS14: 4700 | AT14: 3500 | AU14: 6000 | AV14: 4900 | AW14: 4800 | AX14: 2600 | AY14: 7500 | AZ14: 4300 | BA14: 6200
A15: 2025 | B15: DEC | C15: 21930 | D15: 14850 | E15: 11285 | F15: 27630 | G15: 22700 | H15: 0.4 | I15: 0.54 | J15: 0.06 | K15: =SUM(C15:G15) -> 98395 | L15: 120000 | M15: 0.36 | N15: 0.28 | O15: 0.3 | P15: 0.24 | Q15: 0.15 | R15: 0.15 | S15: 0.16 | T15: 0.71 | U15: 0.8 | V15: 0.57 | W15: 0.39 | X15: 0.61 | Y15: 0.72 | Z15: 0.58 | AA15: 0.65 | AB15: 0.49 | AC15: 0.57 | AD15: 45691 | AE15: 60215 | AF15: 19839 | AG15: 13621 | AH15: 59767 | AI15: 6581 | AJ15: 34286 | AK15: 42222 | AL15: 4090 | AM15: 39033 | AN15: 58269 | AO15: 68482 | AP15: 58702 | AQ15: 45132 | AR15: 8700 | AS15: 3600 | AT15: 4700 | AU15: 6500 | AV15: 4500 | AW15: 4900 | AX15: 4700 | AY15: 6700 | AZ15: 3600 | BA15: 3200
... A51: 2028 | B51: DEC | C51: 62575 | D51: 70425 | E51: 52725 | F51: 79400 | G51: 66650 | H51: 0.36 | I51: 0.48 | J51: 0.16 | K51: =SUM(C51:G51) -> 331775 | L51: 250000 | M51: 0.22 | N51: 0.45 | O51: 0.33 | P51: 0.25 | Q51: 0.15 | R51: 0.05 | S51: 0.22 | T51: 1.04 | U51: 0.95 | V51: 0.63 | W51: 0.55 | X51: 1.26 | Y51: 0.63 | Z51: 0.69 | AA51: 0.6 | AB51: 0.28 | AC51: 0.29 | AD51: 62859 | AE51: 117796 | AF51: 118263 | AG51: 667 | AH51: 74945 | AI51: 54042 | AJ51: 71428 | AK51: 52446 | AL51: 92341 | AM51: 76327 | AN51: 33912 | AO51: 95373 | AP51: 93173 | AQ51: 73928 | AR51: 3100 | AS51: 3900 | AT51: 7100 | AU51: 4600 | AV51: 4800 | AW51: 7400 | AX51: 4300 | AY51: 4400 | AZ51: 5800 | BA51: 4300

Sheet HOTMAP-DATA
A1: Year | B1: Month | C1: Day | D1: Shift 1 | E1: Shift 2 | F1: Shift 3 | G1: Shift 4 | I1: 1 | J1: Underwork
A2: 2025 | B2: JAN | C2: 1 | D2: 2 | E2: 1 | F2: 2 | G2: 4 | I2: 2 | J2: Standard Hours
A3: 2025 | B3: JAN | C3: 2 | D3: 1 | E3: 2 | F3: 1 | G3: 1 | I3: 3 | J3: Overtime
A4: 2025 | B4: JAN | C4: 3 | D4: 1 | E4: 2 | F4: 4 | G4: 1 | I4: 4 | J4: Excessive Overtime
A5: 2025 | B5: JAN | C5: 4 | D5: 3 | E5: 2 | F5: 1 | G5: 3
A6: 2025 | B6: JAN | C6: 5 | D6: 1 | E6: 2 | F6: 2 | G6: 3
A7: 2025 | B7: JAN | C7: 6 | D7: 1 | E7: 2 | F7: 2 | G7: 1
A8: 2025 | B8: JAN | C8: 7 | D8: 4 | E8: 2 | F8: 3 | G8: 1
A9: 2025 | B9: JAN | C9: 8 | D9: 1 | E9: 2 | F9: 3 | G9: 3
A10: 2025 | B10: JAN | C10: 9 | D10: 1 | E10: 2 | F10: 3 | G10: 3
A11: 2025 | B11: JAN | C11: 10 | D11: 1 | E11: 2 | F11: 3 | G11: 4
A12: 2025 | B12: JAN | C12: 11 | D12: 3 | E12: 2 | F12: 3 | G12: 4
A13: 2025 | B13: JAN | C13: 12 | D13: 1 | E13: 4 | F13: 3 | G13: 3
A14: 2025 | B14: JAN | C14: 13 | D14: 1 | E14: 2 | F14: 4 | G14: 2
A15: 2025 | B15: JAN | C15: 14 | D15: 1 | E15: 2 | F15: 3 | G15: 1
A16: 2025 | B16: JAN | C16: 15 | D16: 1 | E16: 2 | F16: 4 | G16: 1
... A1345: 2028 | B1345: DEC | C1345: 28 | D1345: 2 | E1345: 1 | F1345: 1 | G1345: 3

Sheet R
B1: #8F72FF
B2: #673FFF
B3: #178BFF
B4: #4AA5FF
B5: #1AFFD5
B6: #00E5BB
B7: #73F46A
B8: #00C74D
B9: #F9F871
B10: #E34F10
B12: #F631B5
B14: 322664
