Workbook
Name labels: Processing!$E$2:INDEX(Processing!$E$2:$E$7,CHOOSE(Processing!$I$5,6,4,5))
Name Slicer_Indicator: #N/A
Name Slicer_Month: #N/A
Name Slicer_Year: #N/A
Name values: Processing!$F$2:INDEX(Processing!$F$2:$F$7,CHOOSE(Processing!$I$5,6,4,5))

Sheet DASHBOARD
K47: #0273FC

Sheet DASHBOARD Light

Sheet Income Light

Sheet Expenses Light

Sheet Balance Light

Sheet Goals Light

Sheet Income
K47: #0273FC

Sheet Expenses
K47: #0273FC

Sheet Balance
K47: #0273FC

Sheet Goals
K47: #0273FC

Sheet Processing
B1: Expenses | E1: Structure | F1: Sources | H1: Indicator | I1: Num | K1: Income | M1: Goals | Q1: Goals | R1: Plan | S1: Actual | T1: %
A2: Housing | B2: =C2/$C$8 -> 0.50025694 | C2: =GETPIVOTDATA(""&A2,Control!$A$3)*B26 -> 3894 | E2: =CHOOSE($I$5,A2,Q2,J2) -> Checking | F2: =CHOOSE($I$5,B2,T2,K2) -> 0 | H2: Expenses | I2: 1 | J2: Checking | K2: =L2/$L$7 -> 0 | L2: =GETPIVOTDATA(""&J2,Control!$A$3)*K26 -> 0 | M2: =Q11 -> Home | N2: =IF(T11>1,1-(T11-1),T11) -> 0.7052 | O2: =IF(T11>1,0,1-N2) -> 0.2948 | P2: =IF(T11>1,T11-1,0) -> 0 | Q2: Home | R2: =GETPIVOTDATA(Q2&" "&R$1,Control!$A$3) -> 1500 | S2: {=GETPIVOTDATA(""&Q2,Control!$A$3)*(100%/COUNTA($K$26:$O$26)*SUM($K$26:$O$26*1))} -> 1057.8 | T2: =S2/R2 -> 0.7052
A3: Food | B3: =C3/$C$8 -> 0 | C3: =GETPIVOTDATA(""&A3,Control!$A$3)*C26 -> 0 | E3: =CHOOSE($I$5,A3,Q3,J3) -> Saving | F3: =CHOOSE($I$5,B3,T3,K3) -> 0 | H3: Goals | I3: 2 | J3: Saving | K3: =L3/$L$7 -> 0 | L3: =GETPIVOTDATA(""&J3,Control!$A$3)*L26 -> 0 | M3: =Q12 -> Hobby | N3: =IF(T12>1,1-(T12-1),T12) -> 0.3568 | O3: =IF(T12>1,0,1-N3) -> 0.6432 | P3: =IF(T12>1,T12-1,0) -> 0 | Q3: Travel | R3: =GETPIVOTDATA(Q3&" "&R$1,Control!$A$3) -> 3000 | S3: {=GETPIVOTDATA(""&Q3,Control!$A$3)*(100%/COUNTA($K$26:$O$26)*SUM($K$26:$O$26*1))} -> 882 | T3: =S3/R3 -> 0.294
A4: Transport | B4: =C4/$C$8 -> 0 | C4: =GETPIVOTDATA(""&A4,Control!$A$3)*D26 -> 0 | E4: =CHOOSE($I$5,A4,Q4,J4) -> Investments | F4: =CHOOSE($I$5,B4,T4,K4) -> 0.41682053 | H4: Income | I4: 3 | J4: Investments | K4: =L4/$L$7 -> 0.41682053 | L4: =GETPIVOTDATA(""&J4,Control!$A$3)*M26 -> 4515 | M4: =Q13 -> Drive | N4: =IF(T13>1,1-(T13-1),T13) -> 0.29472 | O4: =IF(T13>1,0,1-N4) -> 0.70528 | P4: =IF(T13>1,T13-1,0) -> 0 | Q4: Drive | R4: =GETPIVOTDATA(Q4&" "&R$1,Control!$A$3) -> 2500 | S4: {=GETPIVOTDATA(""&Q4,Control!$A$3)*(100%/COUNTA($K$26:$O$26)*SUM($K$26:$O$26*1))} -> 736.8 | T4: =S4/R4 -> 0.29472
A5: Shopping | B5: =C5/$C$8 -> 0 | C5: =GETPIVOTDATA(""&A5,Control!$A$3)*E26 -> 0 | E5: =CHOOSE($I$5,A5,Q5,J5) -> Digital Craft | F5: =CHOOSE($I$5,B5,T5,K5) -> 0.26338626 | H5: Select | I5: =GETPIVOTDATA("Num",Control!$A$35) -> 3 | J5: Digital Craft | K5: =L5/$L$7 -> 0.26338626 | L5: =GETPIVOTDATA(""&J5,Control!$A$3)*N26 -> 2853 | M5: =Q14 -> Travel | N5: =IF(T14>1,1-(T14-1),T14) -> 0.294 | O5: =IF(T14>1,0,1-N5) -> 0.706 | P5: =IF(T14>1,T14-1,0) -> 0 | Q5: Hobby | R5: =GETPIVOTDATA(Q5&" "&R$1,Control!$A$3) -> 1875 | S5: {=GETPIVOTDATA(""&Q5,Control!$A$3)*(100%/COUNTA($K$26:$O$26)*SUM($K$26:$O$26*1))} -> 669 | T5: =S5/R5 -> 0.3568
A6: Gym | B6: =C6/$C$8 -> 0.38527749 | C6: =GETPIVOTDATA(""&A6,Control!$A$3)*F26 -> 2999 | E6: =CHOOSE($I$5,A6,Q6,J6) -> Rewards | F6: =CHOOSE($I$5,B6,T6,K6) -> 0.31979321 | J6: Rewards | K6: =L6/$L$7 -> 0.31979321 | L6: =GETPIVOTDATA(""&J6,Control!$A$3)*O26 -> 3464 | R6: =SUM(R2:R5) -> 8875 | S6: =SUM(S2:S5) -> 3345.6 | T6: =AVERAGE(T2:T5) -> 0.41268
A7: Other | B7: =C7/$C$8 -> 0.11446557 | C7: =GETPIVOTDATA(""&A7,Control!$A$3)*G26 -> 891 | E7: =CHOOSE($I$5,A7,Q7,J7) | F7: =CHOOSE($I$5,B7,T7,K7) -> 0 | H7: Total Balance | I7: =IF(($I$23-$C$23)>0,$I$23-$C$23,"") -> 3048 | J7: =IF(($I$23-$C$23)>0,"",$I$23-$C$23) | L7: =SUM(L2:L6) -> 10832
C8: =SUM(C2:C7) -> 7784 | H8: =J10 -> Goals Accumulation | I8: =T6 -> 0.41268 | J8: =(I8<1.01)*3.5% -> 0.035 | K8: =MAX(0,1.035-I8-J8) -> 0.58732
A9: Expenses Dynamics | D9: TRUE | J9: TRUE | M9: Total Cash Flow
A10: Month | B10: Expenses | C10: Cursor | D10: Income | E10: Cursor I | F10: Tumbler | G10: Month | H10: Income Dynamics | I10: Cursor1 | J10: Goals Accumulation | K10: Cursor2 | L10: Tumbler | M10: Month | N10: Value | O10: Cursor | Q10: Sort | R10: Plan | S10: Actual | T10: % | W10: 1 | X10: 2 | Y10: 3 | Z10: 4
A11: JAN | B11: =H28 -> 1430 | C11: =IF(ISNUMBER(GETPIVOTDATA(""&B$10,Control!$A$3,"Month",""&$A11)),H28,NA()) -> #N/A | D11: =IF($D$9,H11,NA()) -> 1048 | E11: =IF(AND(D9,ISNUMBER(GETPIVOTDATA(""&D$10,Control!$A$3,"Month",""&$A11))),P28,NA()) -> #N/A | F11: =D9*10 -> 10 | G11: JAN | H11: =P28 -> 1048 | I11: =IF(ISNUMBER(GETPIVOTDATA(""&D$10,Control!$A$3,"Month",""&$A11)),P28,NA()) -> #N/A | J11: {=IF($J$9,GETPIVOTDATA(""&$J$10,Control!$A$20,"Month",""&G11),NA())*(100%/COUNTA($K$26:$O$26)*SUM($K$26:$O$26*1))} -> 405 | K11: {=IF($J$9,IFERROR(GETPIVOTDATA(""&$J$10,Control!$A$3,"Month",""&G11),NA()),NA())*(100%/COUNTA(K26:O26)*SUM($K$26:$O$26*1))} -> #N/A | L11: =J9*10 -> 10 | M11: JAN | N11: =H11+B11 -> 2478 | O11: =IF(ISNA(C11),C11,N11) -> #N/A | Q11: {=_xlfn._xlws.SORT($Q$2:$T$5,Q15,-1)} -> Home | R11: 1500 | S11: 1057.8 | T11: 0.7052 | V11: =MATCH(Q2,$Q$11:$Q$14,0) -> 1 | W11: =($V11=W$10)*10 -> 10 | X11: =($V11=X$10)*10 -> 0 | Y11: =($V11=Y$10)*10 -> 0 | Z11: =($V11=Z$10)*10 -> 0
A12: FEB | B12: =H29 -> 1315 | C12: =IF(ISNUMBER(GETPIVOTDATA(""&B$10,Control!$A$3,"Month",""&$A12)),H29,NA()) -> #N/A | D12: =IF($D$9,H12,NA()) -> 1191 | E12: =IF(AND(D10,ISNUMBER(GETPIVOTDATA(""&D$10,Control!$A$3,"Month",""&$A12))),P29,NA()) -> #N/A | F12: =10-F11 -> 0 | G12: FEB | H12: =P29 -> 1191 | I12: =IF(ISNUMBER(GETPIVOTDATA(""&D$10,Control!$A$3,"Month",""&$A12)),P29,NA()) -> #N/A | J12: {=IF($J$9,GETPIVOTDATA(""&$J$10,Control!$A$20,"Month",""&G12),NA())*(100%/COUNTA($K$26:$O$26)*SUM($K$26:$O$26*1))} -> 240 | K12: {=IF($J$9,IFERROR(GETPIVOTDATA(""&$J$10,Control!$A$3,"Month",""&G12),NA()),NA())*(100%/COUNTA(K27:O27)*SUM($K$26:$O$26*1))} -> #N/A | L12: =10-L11 -> 0 | M12: FEB | N12: =H12+B12 -> 2506 | O12: =IF(ISNA(C12),C12,N12) -> #N/A | Q12: Hobby | R12: 1875 | S12: 669 | T12: 0.3568 | V12: =MATCH(Q3,$Q$11:$Q$14,0) -> 4 | W12: =($V12=W$10)*10 -> 0 | X12: =($V12=X$10)*10 -> 0 | Y12: =($V12=Y$10)*10 -> 0 | Z12: =($V12=Z$10)*10 -> 10
A13: MAR | B13: =H30 -> 1535 | C13: =IF(ISNUMBER(GETPIVOTDATA(""&B$10,Control!$A$3,"Month",""&$A13)),H30,NA()) -> #N/A | D13: =IF($D$9,H13,NA()) -> 838 | E13: =IF(AND(D11,ISNUMBER(GETPIVOTDATA(""&D$10,Control!$A$3,"Month",""&$A13))),P30,NA()) -> #N/A | G13: MAR | H13: =P30 -> 838 | I13: =IF(ISNUMBER(GETPIVOTDATA(""&D$10,Control!$A$3,"Month",""&$A13)),P30,NA()) -> #N/A | J13: {=IF($J$9,GETPIVOTDATA(""&$J$10,Control!$A$20,"Month",""&G13),NA())*(100%/COUNTA($K$26:$O$26)*SUM($K$26:$O$26*1))} -> 57 | K13: {=IF($J$9,IFERROR(GETPIVOTDATA(""&$J$10,Control!$A$3,"Month",""&G13),NA()),NA())*(100%/COUNTA(K28:O28)*SUM($K$26:$O$26*1))} -> #N/A | M13: MAR | N13: =H13+B13 -> 2373 | O13: =IF(ISNA(C13),C13,N13) -> #N/A | Q13: Drive | R13: 2500 | S13: 736.8 | T13: 0.29472 | V13: =MATCH(Q4,$Q$11:$Q$14,0) -> 3 | W13: =($V13=W$10)*10 -> 0 | X13: =($V13=X$10)*10 -> 0 | Y13: =($V13=Y$10)*10 -> 10 | Z13: =($V13=Z$10)*10 -> 0
A14: APR | B14: =H31 -> 969 | C14: =IF(ISNUMBER(GETPIVOTDATA(""&B$10,Control!$A$3,"Month",""&$A14)),H31,NA()) -> #N/A | D14: =IF($D$9,H14,NA()) -> 979 | E14: =IF(AND(D12,ISNUMBER(GETPIVOTDATA(""&D$10,Control!$A$3,"Month",""&$A14))),P31,NA()) -> #N/A | G14: APR | H14: =P31 -> 979 | I14: =IF(ISNUMBER(GETPIVOTDATA(""&D$10,Control!$A$3,"Month",""&$A14)),P31,NA()) -> #N/A | J14: {=IF($J$9,GETPIVOTDATA(""&$J$10,Control!$A$20,"Month",""&G14),NA())*(100%/COUNTA($K$26:$O$26)*SUM($K$26:$O$26*1))} -> 12 | K14: {=IF($J$9,IFERROR(GETPIVOTDATA(""&$J$10,Control!$A$3,"Month",""&G14),NA()),NA())*(100%/COUNTA(K29:O29)*SUM($K$26:$O$26*1))} -> #N/A | M14: APR | N14: =H14+B14 -> 1948 | O14: =IF(ISNA(C14),C14,N14) -> #N/A | Q14: Travel | R14: 3000 | S14: 882 | T14: 0.294 | V14: =MATCH(Q5,$Q$11:$Q$14,0) -> 2 | W14: =($V14=W$10)*10 -> 0 | X14: =($V14=X$10)*10 -> 10 | Y14: =($V14=Y$10)*10 -> 0 | Z14: =($V14=Z$10)*10 -> 0
A15: MAY | B15: =H32 -> 1003 | C15: =IF(ISNUMBER(GETPIVOTDATA(""&B$10,Control!$A$3,"Month",""&$A15)),H32,NA()) -> #N/A | D15: =IF($D$9,H15,NA()) -> 1480 | E15: =IF(AND(D13,ISNUMBER(GETPIVOTDATA(""&D$10,Control!$A$3,"Month",""&$A15))),P32,NA()) -> #N/A | G15: MAY | H15: =P32 -> 1480 | I15: =IF(ISNUMBER(GETPIVOTDATA(""&D$10,Control!$A$3,"Month",""&$A15)),P32,NA()) -> #N/A | J15: {=IF($J$9,GETPIVOTDATA(""&$J$10,Control!$A$20,"Month",""&G15),NA())*(100%/COUNTA($K$26:$O$26)*SUM($K$26:$O$26*1))} -> 183 | K15: {=IF($J$9,IFERROR(GETPIVOTDATA(""&$J$10,Control!$A$3,"Month",""&G15),NA()),NA())*(100%/COUNTA(K30:O30)*SUM($K$26:$O$26*1))} -> #N/A | M15: MAY | N15: =H15+B15 -> 2483 | O15: =IF(ISNA(C15),C15,N15) -> #N/A | P15: Sort by | Q15: =2+Q16 -> 4
A16: JUN | B16: =H33 -> 897 | C16: =IF(ISNUMBER(GETPIVOTDATA(""&B$10,Control!$A$3,"Month",""&$A16)),H33,NA()) -> #N/A | D16: =IF($D$9,H16,NA()) -> 1903 | E16: =IF(AND(D14,ISNUMBER(GETPIVOTDATA(""&D$10,Control!$A$3,"Month",""&$A16))),P33,NA()) -> #N/A | G16: JUN | H16: =P33 -> 1903 | I16: =IF(ISNUMBER(GETPIVOTDATA(""&D$10,Control!$A$3,"Month",""&$A16)),P33,NA()) -> #N/A | J16: {=IF($J$9,GETPIVOTDATA(""&$J$10,Control!$A$20,"Month",""&G16),NA())*(100%/COUNTA($K$26:$O$26)*SUM($K$26:$O$26*1))} -> 414 | K16: {=IF($J$9,IFERROR(GETPIVOTDATA(""&$J$10,Control!$A$3,"Month",""&G16),NA()),NA())*(100%/COUNTA(K31:O31)*SUM($K$26:$O$26*1))} -> #N/A | M16: JUN | N16: =H16+B16 -> 2800 | O16: =IF(ISNA(C16),C16,N16) -> #N/A | P16: Control | Q16: 2
A17: JUL | B17: =H34 -> 1251 | C17: =IF(ISNUMBER(GETPIVOTDATA(""&B$10,Control!$A$3,"Month",""&$A17)),H34,NA()) -> 1251 | D17: =IF($D$9,H17,NA()) -> 2017 | E17: =IF(AND(D15,ISNUMBER(GETPIVOTDATA(""&D$10,Control!$A$3,"Month",""&$A17))),P34,NA()) -> 2017 | G17: JUL | H17: =P34 -> 2017 | I17: =IF(ISNUMBER(GETPIVOTDATA(""&D$10,Control!$A$3,"Month",""&$A17)),P34,NA()) -> 2017 | J17: {=IF($J$9,GETPIVOTDATA(""&$J$10,Control!$A$20,"Month",""&G17),NA())*(100%/COUNTA($K$26:$O$26)*SUM($K$26:$O$26*1))} -> 549 | K17: {=IF($J$9,IFERROR(GETPIVOTDATA(""&$J$10,Control!$A$3,"Month",""&G17),NA()),NA())*(100%/COUNTA(K32:O32)*SUM($K$26:$O$26*1))} -> 549 | M17: JUL | N17: =H17+B17 -> 3268 | O17: =IF(ISNA(C17),C17,N17) -> 3268
A18: AUG | B18: =H35 -> 1809 | C18: =IF(ISNUMBER(GETPIVOTDATA(""&B$10,Control!$A$3,"Month",""&$A18)),H35,NA()) -> 1809 | D18: =IF($D$9,H18,NA()) -> 1868 | E18: =IF(AND(D16,ISNUMBER(GETPIVOTDATA(""&D$10,Control!$A$3,"Month",""&$A18))),P35,NA()) -> 1868 | G18: AUG | H18: =P35 -> 1868 | I18: =IF(ISNUMBER(GETPIVOTDATA(""&D$10,Control!$A$3,"Month",""&$A18)),P35,NA()) -> 1868 | J18: {=IF($J$9,GETPIVOTDATA(""&$J$10,Control!$A$20,"Month",""&G18),NA())*(100%/COUNTA($K$26:$O$26)*SUM($K$26:$O$26*1))} -> 546 | K18: {=IF($J$9,IFERROR(GETPIVOTDATA(""&$J$10,Control!$A$3,"Month",""&G18),NA()),NA())*(100%/COUNTA(K33:O33)*SUM($K$26:$O$26*1))} -> 546 | M18: AUG | N18: =H18+B18 -> 3677 | O18: =IF(ISNA(C18),C18,N18) -> 3677
A19: SEP | B19: =H36 -> 1785 | C19: =IF(ISNUMBER(GETPIVOTDATA(""&B$10,Control!$A$3,"Month",""&$A19)),H36,NA()) -> 1785 | D19: =IF($D$9,H19,NA()) -> 1888 | E19: =IF(AND(D17,ISNUMBER(GETPIVOTDATA(""&D$10,Control!$A$3,"Month",""&$A19))),P36,NA()) -> 1888 | G19: SEP | H19: =P36 -> 1888 | I19: =IF(ISNUMBER(GETPIVOTDATA(""&D$10,Control!$A$3,"Month",""&$A19)),P36,NA()) -> 1888 | J19: {=IF($J$9,GETPIVOTDATA(""&$J$10,Control!$A$20,"Month",""&G19),NA())*(100%/COUNTA($K$26:$O$26)*SUM($K$26:$O$26*1))} -> 549 | K19: {=IF($J$9,IFERROR(GETPIVOTDATA(""&$J$10,Control!$A$3,"Month",""&G19),NA()),NA())*(100%/COUNTA(K34:O34)*SUM($K$26:$O$26*1))} -> 549 | M19: SEP | N19: =H19+B19 -> 3673 | O19: =IF(ISNA(C19),C19,N19) -> 3673
A20: OCT | B20: =H37 -> 1556 | C20: =IF(ISNUMBER(GETPIVOTDATA(""&B$10,Control!$A$3,"Month",""&$A20)),H37,NA()) -> 1556 | D20: =IF($D$9,H20,NA()) -> 2407 | E20: =IF(AND(D18,ISNUMBER(GETPIVOTDATA(""&D$10,Control!$A$3,"Month",""&$A20))),P37,NA()) -> 2407 | G20: OCT | H20: =P37 -> 2407 | I20: =IF(ISNUMBER(GETPIVOTDATA(""&D$10,Control!$A$3,"Month",""&$A20)),P37,NA()) -> 2407 | J20: {=IF($J$9,GETPIVOTDATA(""&$J$10,Control!$A$20,"Month",""&G20),NA())*(100%/COUNTA($K$26:$O$26)*SUM($K$26:$O$26*1))} -> 744 | K20: {=IF($J$9,IFERROR(GETPIVOTDATA(""&$J$10,Control!$A$3,"Month",""&G20),NA()),NA())*(100%/COUNTA(K35:O35)*SUM($K$26:$O$26*1))} -> 744 | M20: OCT | N20: =H20+B20 -> 3963 | O20: =IF(ISNA(C20),C20,N20) -> 3963 | Q20: Accaunts | R20: =SUM(R21:R24) -> 8313.6 | S20: Accaunts | T20: =SUM(T21:T24) -> 8313.6 | W20: 1 | X20: 2 | Y20: 3 | Z20: 4
A21: NOV | B21: =H38 -> 1383 | C21: =IF(ISNUMBER(GETPIVOTDATA(""&B$10,Control!$A$3,"Month",""&$A21)),H38,NA()) -> 1383 | D21: =IF($D$9,H21,NA()) -> 2652 | E21: =IF(AND(D19,ISNUMBER(GETPIVOTDATA(""&D$10,Control!$A$3,"Month",""&$A21))),P38,NA()) -> 2652 | G21: NOV | H21: =P38 -> 2652 | I21: =IF(ISNUMBER(GETPIVOTDATA(""&D$10,Control!$A$3,"Month",""&$A21)),P38,NA()) -> 2652 | J21: {=IF($J$9,GETPIVOTDATA(""&$J$10,Control!$A$20,"Month",""&G21),NA())*(100%/COUNTA($K$26:$O$26)*SUM($K$26:$O$26*1))} -> 957 | K21: {=IF($J$9,IFERROR(GETPIVOTDATA(""&$J$10,Control!$A$3,"Month",""&G21),NA()),NA())*(100%/COUNTA(K36:O36)*SUM($K$26:$O$26*1))} -> 957 | M21: NOV | N21: =H21+B21 -> 4035 | O21: =IF(ISNA(C21),C21,N21) -> 4035 | Q21: {=_xlfn._xlws.SORT($S$21:$T$24,2,-1)} -> Investments | R21: 2709 | S21: Checking | T21: {=GETPIVOTDATA(""&S21,Control!$A$3)*(100%/COUNTA($K$26:$O$26)*SUM($K$26:$O$26*1))} -> 1977 | V21: =MATCH(S21,$Q$21:$Q$24,0) -> 2 | W21: =($V21=W$20)*10 -> 0 | X21: =($V21=X$20)*10 -> 10 | Y21: =($V21=Y$20)*10 -> 0 | Z21: =($V21=Z$20)*10 -> 0
A22: DEC | B22: =H39 -> 1740 | C22: =IF(ISNUMBER(GETPIVOTDATA(""&B$10,Control!$A$3,"Month",""&$A22)),H39,NA()) -> #N/A | D22: =IF($D$9,H22,NA()) -> 1935 | E22: =IF(AND(D20,ISNUMBER(GETPIVOTDATA(""&D$10,Control!$A$3,"Month",""&$A22))),P39,NA()) -> #N/A | G22: DEC | H22: =P39 -> 1935 | I22: =IF(ISNUMBER(GETPIVOTDATA(""&D$10,Control!$A$3,"Month",""&$A22)),P39,NA()) -> #N/A | J22: {=IF($J$9,GETPIVOTDATA(""&$J$10,Control!$A$20,"Month",""&G22),NA())*(100%/COUNTA($K$26:$O$26)*SUM($K$26:$O$26*1))} -> 1032 | K22: {=IF($J$9,IFERROR(GETPIVOTDATA(""&$J$10,Control!$A$3,"Month",""&G22),NA()),NA())*(100%/COUNTA(K37:O37)*SUM($K$26:$O$26*1))} -> #N/A | M22: DEC | N22: =H22+B22 -> 3675 | O22: =IF(ISNA(C22),C22,N22) -> #N/A | Q22: Checking | R22: 1977 | S22: Saving | T22: {=GETPIVOTDATA(""&S22,Control!$A$3)*(100%/COUNTA($K$26:$O$26)*SUM($K$26:$O$26*1))} -> 1915.8 | V22: =MATCH(S22,$Q$21:$Q$24,0) -> 3 | W22: =($V22=W$20)*10 -> 0 | X22: =($V22=X$20)*10 -> 0 | Y22: =($V22=Y$20)*10 -> 10 | Z22: =($V22=Z$20)*10 -> 0
C23: {=SUM(IFERROR(C11:C22,0))} -> 7784 | E23: =IF(D9,GETPIVOTDATA(""&D10,Control!$A$3),"") -> 17320 | I23: {=SUM(IFERROR(I11:I22,0))} -> 10832 | K23: {=IF(J9,SUM(IFERROR(K11:K22,0)),"")} -> 3345 | O23: {=SUM(IFERROR(O11:O22,0))} -> 18616 | Q23: Saving | R23: 1915.8 | S23: Credit Cards | T23: {=GETPIVOTDATA(""&E5,Control!$A$3)*(100%/COUNTA($K$26:$O$26)*SUM($K$26:$O$26*1))} -> 1711.8 | V23: =MATCH(S23,$Q$21:$Q$24,0) -> 4 | W23: =($V23=W$20)*10 -> 0 | X23: =($V23=X$20)*10 -> 0 | Y23: =($V23=Y$20)*10 -> 0 | Z23: =($V23=Z$20)*10 -> 10
E24: =IF(D9,H10,"") -> Income Dynamics | K24: =IF($J$9,J10,"") -> Goals Accumulation | Q24: Credit Cards | R24: 1711.8 | S24: Investments | T24: {=GETPIVOTDATA(""&S24,Control!$A$3)*(100%/COUNTA($K$26:$O$26)*SUM($K$26:$O$26*1))} -> 2709 | V24: =MATCH(S24,$Q$21:$Q$24,0) -> 1 | W24: =($V24=W$20)*10 -> 10 | X24: =($V24=X$20)*10 -> 0 | Y24: =($V24=Y$20)*10 -> 0 | Z24: =($V24=Z$20)*10 -> 0
B26: TRUE | C26: FALSE | D26: FALSE | E26: FALSE | F26: TRUE | G26: TRUE | K26: FALSE | L26: FALSE | M26: TRUE | N26: TRUE | O26: TRUE
A27: Month | B27: Housing | C27: Food | D27: Transport | E27: Shopping | F27: Gym | G27: Other | H27: Expenses | J27: Month | K27: Checking | L27: Saving | M27: Investments | N27: Digital Craft | O27: Rewards | P27: Income
A28: JAN | B28: =GETPIVOTDATA(""&B$27,Control!$A$20,"Month",""&$A28)*B$26 -> 744 | C28: =GETPIVOTDATA(""&C$27,Control!$A$20,"Month",""&$A28)*C$26 -> 0 | D28: =GETPIVOTDATA(""&D$27,Control!$A$20,"Month",""&$A28)*D$26 -> 0 | E28: =GETPIVOTDATA(""&E$27,Control!$A$20,"Month",""&$A28)*E$26 -> 0 | F28: =GETPIVOTDATA(""&F$27,Control!$A$20,"Month",""&$A28)*F$26 -> 501 | G28: =GETPIVOTDATA(""&G$27,Control!$A$20,"Month",""&$A28)*G$26 -> 185 | H28: =SUM(B28:G28) -> 1430 | J28: JAN | K28: =GETPIVOTDATA(""&K$27,Control!$A$20,"Month",""&$J28)*K$26 -> 0 | L28: =GETPIVOTDATA(""&L$27,Control!$A$20,"Month",""&$J28)*L$26 -> 0 | M28: =GETPIVOTDATA(""&M$27,Control!$A$20,"Month",""&$J28)*M$26 -> 270 | N28: =GETPIVOTDATA(""&N$27,Control!$A$20,"Month",""&$J28)*N$26 -> 378 | O28: =GETPIVOTDATA(""&O$27,Control!$A$20,"Month",""&$J28)*O$26 -> 400 | P28: =SUM(K28:O28) -> 1048
A29: FEB | B29: =GETPIVOTDATA(""&B$27,Control!$A$20,"Month",""&$A29)*B$26 -> 670 | C29: =GETPIVOTDATA(""&C$27,Control!$A$20,"Month",""&$A29)*C$26 -> 0 | D29: =GETPIVOTDATA(""&D$27,Control!$A$20,"Month",""&$A29)*D$26 -> 0 | E29: =GETPIVOTDATA(""&E$27,Control!$A$20,"Month",""&$A29)*E$26 -> 0 | F29: =GETPIVOTDATA(""&F$27,Control!$A$20,"Month",""&$A29)*F$26 -> 551 | G29: =GETPIVOTDATA(""&G$27,Control!$A$20,"Month",""&$A29)*G$26 -> 94 | H29: =SUM(B29:G29) -> 1315 | J29: FEB | K29: =GETPIVOTDATA(""&K$27,Control!$A$20,"Month",""&$J29)*K$26 -> 0 | L29: =GETPIVOTDATA(""&L$27,Control!$A$20,"Month",""&$J29)*L$26 -> 0 | M29: =GETPIVOTDATA(""&M$27,Control!$A$20,"Month",""&$J29)*M$26 -> 364 | N29: =GETPIVOTDATA(""&N$27,Control!$A$20,"Month",""&$J29)*N$26 -> 507 | O29: =GETPIVOTDATA(""&O$27,Control!$A$20,"Month",""&$J29)*O$26 -> 320 | P29: =SUM(K29:O29) -> 1191
A30: MAR | B30: =GETPIVOTDATA(""&B$27,Control!$A$20,"Month",""&$A30)*B$26 -> 795 | C30: =GETPIVOTDATA(""&C$27,Control!$A$20,"Month",""&$A30)*C$26 -> 0 | D30: =GETPIVOTDATA(""&D$27,Control!$A$20,"Month",""&$A30)*D$26 -> 0 | E30: =GETPIVOTDATA(""&E$27,Control!$A$20,"Month",""&$A30)*E$26 -> 0 | F30: =GETPIVOTDATA(""&F$27,Control!$A$20,"Month",""&$A30)*F$26 -> 570 | G30: =GETPIVOTDATA(""&G$27,Control!$A$20,"Month",""&$A30)*G$26 -> 170 | H30: =SUM(B30:G30) -> 1535 | J30: MAR | K30: =GETPIVOTDATA(""&K$27,Control!$A$20,"Month",""&$J30)*K$26 -> 0 | L30: =GETPIVOTDATA(""&L$27,Control!$A$20,"Month",""&$J30)*L$26 -> 0 | M30: =GETPIVOTDATA(""&M$27,Control!$A$20,"Month",""&$J30)*M$26 -> 216 | N30: =GETPIVOTDATA(""&N$27,Control!$A$20,"Month",""&$J30)*N$26 -> 342 | O30: =GETPIVOTDATA(""&O$27,Control!$A$20,"Month",""&$J30)*O$26 -> 280 | P30: =SUM(K30:O30) -> 838
A31: APR | B31: =GETPIVOTDATA(""&B$27,Control!$A$20,"Month",""&$A31)*B$26 -> 595 | C31: =GETPIVOTDATA(""&C$27,Control!$A$20,"Month",""&$A31)*C$26 -> 0 | D31: =GETPIVOTDATA(""&D$27,Control!$A$20,"Month",""&$A31)*D$26 -> 0 | E31: =GETPIVOTDATA(""&E$27,Control!$A$20,"Month",""&$A31)*E$26 -> 0 | F31: =GETPIVOTDATA(""&F$27,Control!$A$20,"Month",""&$A31)*F$26 -> 286 | G31: =GETPIVOTDATA(""&G$27,Control!$A$20,"Month",""&$A31)*G$26 -> 88 | H31: =SUM(B31:G31) -> 969 | J31: APR | K31: =GETPIVOTDATA(""&K$27,Control!$A$20,"Month",""&$J31)*K$26 -> 0 | L31: =GETPIVOTDATA(""&L$27,Control!$A$20,"Month",""&$J31)*L$26 -> 0 | M31: =GETPIVOTDATA(""&M$27,Control!$A$20,"Month",""&$J31)*M$26 -> 309 | N31: =GETPIVOTDATA(""&N$27,Control!$A$20,"Month",""&$J31)*N$26 -> 309 | O31: =GETPIVOTDATA(""&O$27,Control!$A$20,"Month",""&$J31)*O$26 -> 361 | P31: =SUM(K31:O31) -> 979
A32: MAY | B32: =GETPIVOTDATA(""&B$27,Control!$A$20,"Month",""&$A32)*B$26 -> 576 | C32: =GETPIVOTDATA(""&C$27,Control!$A$20,"Month",""&$A32)*C$26 -> 0 | D32: =GETPIVOTDATA(""&D$27,Control!$A$20,"Month",""&$A32)*D$26 -> 0 | E32: =GETPIVOTDATA(""&E$27,Control!$A$20,"Month",""&$A32)*E$26 -> 0 | F32: =GETPIVOTDATA(""&F$27,Control!$A$20,"Month",""&$A32)*F$26 -> 354 | G32: =GETPIVOTDATA(""&G$27,Control!$A$20,"Month",""&$A32)*G$26 -> 73 | H32: =SUM(B32:G32) -> 1003 | J32: MAY | K32: =GETPIVOTDATA(""&K$27,Control!$A$20,"Month",""&$J32)*K$26 -> 0 | L32: =GETPIVOTDATA(""&L$27,Control!$A$20,"Month",""&$J32)*L$26 -> 0 | M32: =GETPIVOTDATA(""&M$27,Control!$A$20,"Month",""&$J32)*M$26 -> 354 | N32: =GETPIVOTDATA(""&N$27,Control!$A$20,"Month",""&$J32)*N$26 -> 566 | O32: =GETPIVOTDATA(""&O$27,Control!$A$20,"Month",""&$J32)*O$26 -> 560 | P32: =SUM(K32:O32) -> 1480
A33: JUN | B33: =GETPIVOTDATA(""&B$27,Control!$A$20,"Month",""&$A33)*B$26 -> 541 | C33: =GETPIVOTDATA(""&C$27,Control!$A$20,"Month",""&$A33)*C$26 -> 0 | D33: =GETPIVOTDATA(""&D$27,Control!$A$20,"Month",""&$A33)*D$26 -> 0 | E33: =GETPIVOTDATA(""&E$27,Control!$A$20,"Month",""&$A33)*E$26 -> 0 | F33: =GETPIVOTDATA(""&F$27,Control!$A$20,"Month",""&$A33)*F$26 -> 249 | G33: =GETPIVOTDATA(""&G$27,Control!$A$20,"Month",""&$A33)*G$26 -> 107 | H33: =SUM(B33:G33) -> 897 | J33: JUN | K33: =GETPIVOTDATA(""&K$27,Control!$A$20,"Month",""&$J33)*K$26 -> 0 | L33: =GETPIVOTDATA(""&L$27,Control!$A$20,"Month",""&$J33)*L$26 -> 0 | M33: =GETPIVOTDATA(""&M$27,Control!$A$20,"Month",""&$J33)*M$26 -> 914 | N33: =GETPIVOTDATA(""&N$27,Control!$A$20,"Month",""&$J33)*N$26 -> 341 | O33: =GETPIVOTDATA(""&O$27,Control!$A$20,"Month",""&$J33)*O$26 -> 648 | P33: =SUM(K33:O33) -> 1903
A34: JUL | B34: =GETPIVOTDATA(""&B$27,Control!$A$20,"Month",""&$A34)*B$26 -> 562 | C34: =GETPIVOTDATA(""&C$27,Control!$A$20,"Month",""&$A34)*C$26 -> 0 | D34: =GETPIVOTDATA(""&D$27,Control!$A$20,"Month",""&$A34)*D$26 -> 0 | E34: =GETPIVOTDATA(""&E$27,Control!$A$20,"Month",""&$A34)*E$26 -> 0 | F34: =GETPIVOTDATA(""&F$27,Control!$A$20,"Month",""&$A34)*F$26 -> 531 | G34: =GETPIVOTDATA(""&G$27,Control!$A$20,"Month",""&$A34)*G$26 -> 158 | H34: =SUM(B34:G34) -> 1251 | J34: JUL | K34: =GETPIVOTDATA(""&K$27,Control!$A$20,"Month",""&$J34)*K$26 -> 0 | L34: =GETPIVOTDATA(""&L$27,Control!$A$20,"Month",""&$J34)*L$26 -> 0 | M34: =GETPIVOTDATA(""&M$27,Control!$A$20,"Month",""&$J34)*M$26 -> 842 | N34: =GETPIVOTDATA(""&N$27,Control!$A$20,"Month",""&$J34)*N$26 -> 535 | O34: =GETPIVOTDATA(""&O$27,Control!$A$20,"Month",""&$J34)*O$26 -> 640 | P34: =SUM(K34:O34) -> 2017
A35: AUG | B35: =GETPIVOTDATA(""&B$27,Control!$A$20,"Month",""&$A35)*B$26 -> 837 | C35: =GETPIVOTDATA(""&C$27,Control!$A$20,"Month",""&$A35)*C$26 -> 0 | D35: =GETPIVOTDATA(""&D$27,Control!$A$20,"Month",""&$A35)*D$26 -> 0 | E35: =GETPIVOTDATA(""&E$27,Control!$A$20,"Month",""&$A35)*E$26 -> 0 | F35: =GETPIVOTDATA(""&F$27,Control!$A$20,"Month",""&$A35)*F$26 -> 717 | G35: =GETPIVOTDATA(""&G$27,Control!$A$20,"Month",""&$A35)*G$26 -> 255 | H35: =SUM(B35:G35) -> 1809 | J35: AUG | K35: =GETPIVOTDATA(""&K$27,Control!$A$20,"Month",""&$J35)*K$26 -> 0 | L35: =GETPIVOTDATA(""&L$27,Control!$A$20,"Month",""&$J35)*L$26 -> 0 | M35: =GETPIVOTDATA(""&M$27,Control!$A$20,"Month",""&$J35)*M$26 -> 836 | N35: =GETPIVOTDATA(""&N$27,Control!$A$20,"Month",""&$J35)*N$26 -> 431 | O35: =GETPIVOTDATA(""&O$27,Control!$A$20,"Month",""&$J35)*O$26 -> 601 | P35: =SUM(K35:O35) -> 1868
A36: SEP | B36: =GETPIVOTDATA(""&B$27,Control!$A$20,"Month",""&$A36)*B$26 -> 895 | C36: =GETPIVOTDATA(""&C$27,Control!$A$20,"Month",""&$A36)*C$26 -> 0 | D36: =GETPIVOTDATA(""&D$27,Control!$A$20,"Month",""&$A36)*D$26 -> 0 | E36: =GETPIVOTDATA(""&E$27,Control!$A$20,"Month",""&$A36)*E$26 -> 0 | F36: =GETPIVOTDATA(""&F$27,Control!$A$20,"Month",""&$A36)*F$26 -> 684 | G36: =GETPIVOTDATA(""&G$27,Control!$A$20,"Month",""&$A36)*G$26 -> 206 | H36: =SUM(B36:G36) -> 1785 | J36: SEP | K36: =GETPIVOTDATA(""&K$27,Control!$A$20,"Month",""&$J36)*K$26 -> 0 | L36: =GETPIVOTDATA(""&L$27,Control!$A$20,"Month",""&$J36)*L$26 -> 0 | M36: =GETPIVOTDATA(""&M$27,Control!$A$20,"Month",""&$J36)*M$26 -> 579 | N36: =GETPIVOTDATA(""&N$27,Control!$A$20,"Month",""&$J36)*N$26 -> 669 | O36: =GETPIVOTDATA(""&O$27,Control!$A$20,"Month",""&$J36)*O$26 -> 640 | P36: =SUM(K36:O36) -> 1888
A37: OCT | B37: =GETPIVOTDATA(""&B$27,Control!$A$20,"Month",""&$A37)*B$26 -> 883 | C37: =GETPIVOTDATA(""&C$27,Control!$A$20,"Month",""&$A37)*C$26 -> 0 | D37: =GETPIVOTDATA(""&D$27,Control!$A$20,"Month",""&$A37)*D$26 -> 0 | E37: =GETPIVOTDATA(""&E$27,Control!$A$20,"Month",""&$A37)*E$26 -> 0 | F37: =GETPIVOTDATA(""&F$27,Control!$A$20,"Month",""&$A37)*F$26 -> 508 | G37: =GETPIVOTDATA(""&G$27,Control!$A$20,"Month",""&$A37)*G$26 -> 165 | H37: =SUM(B37:G37) -> 1556 | J37: OCT | K37: =GETPIVOTDATA(""&K$27,Control!$A$20,"Month",""&$J37)*K$26 -> 0 | L37: =GETPIVOTDATA(""&L$27,Control!$A$20,"Month",""&$J37)*L$26 -> 0 | M37: =GETPIVOTDATA(""&M$27,Control!$A$20,"Month",""&$J37)*M$26 -> 898 | N37: =GETPIVOTDATA(""&N$27,Control!$A$20,"Month",""&$J37)*N$26 -> 710 | O37: =GETPIVOTDATA(""&O$27,Control!$A$20,"Month",""&$J37)*O$26 -> 799 | P37: =SUM(K37:O37) -> 2407
A38: NOV | B38: =GETPIVOTDATA(""&B$27,Control!$A$20,"Month",""&$A38)*B$26 -> 717 | C38: =GETPIVOTDATA(""&C$27,Control!$A$20,"Month",""&$A38)*C$26 -> 0 | D38: =GETPIVOTDATA(""&D$27,Control!$A$20,"Month",""&$A38)*D$26 -> 0 | E38: =GETPIVOTDATA(""&E$27,Control!$A$20,"Month",""&$A38)*E$26 -> 0 | F38: =GETPIVOTDATA(""&F$27,Control!$A$20,"Month",""&$A38)*F$26 -> 559 | G38: =GETPIVOTDATA(""&G$27,Control!$A$20,"Month",""&$A38)*G$26 -> 107 | H38: =SUM(B38:G38) -> 1383 | J38: NOV | K38: =GETPIVOTDATA(""&K$27,Control!$A$20,"Month",""&$J38)*K$26 -> 0 | L38: =GETPIVOTDATA(""&L$27,Control!$A$20,"Month",""&$J38)*L$26 -> 0 | M38: =GETPIVOTDATA(""&M$27,Control!$A$20,"Month",""&$J38)*M$26 -> 1360 | N38: =GETPIVOTDATA(""&N$27,Control!$A$20,"Month",""&$J38)*N$26 -> 508 | O38: =GETPIVOTDATA(""&O$27,Control!$A$20,"Month",""&$J38)*O$26 -> 784 | P38: =SUM(K38:O38) -> 2652
A39: DEC | B39: =GETPIVOTDATA(""&B$27,Control!$A$20,"Month",""&$A39)*B$26 -> 908 | C39: =GETPIVOTDATA(""&C$27,Control!$A$20,"Month",""&$A39)*C$26 -> 0 | D39: =GETPIVOTDATA(""&D$27,Control!$A$20,"Month",""&$A39)*D$26 -> 0 | E39: =GETPIVOTDATA(""&E$27,Control!$A$20,"Month",""&$A39)*E$26 -> 0 | F39: =GETPIVOTDATA(""&F$27,Control!$A$20,"Month",""&$A39)*F$26 -> 639 | G39: =GETPIVOTDATA(""&G$27,Control!$A$20,"Month",""&$A39)*G$26 -> 193 | H39: =SUM(B39:G39) -> 1740 | J39: DEC | K39: =GETPIVOTDATA(""&K$27,Control!$A$20,"Month",""&$J39)*K$26 -> 0 | L39: =GETPIVOTDATA(""&L$27,Control!$A$20,"Month",""&$J39)*L$26 -> 0 | M39: =GETPIVOTDATA(""&M$27,Control!$A$20,"Month",""&$J39)*M$26 -> 625 | N39: =GETPIVOTDATA(""&N$27,Control!$A$20,"Month",""&$J39)*N$26 -> 669 | O39: =GETPIVOTDATA(""&O$27,Control!$A$20,"Month",""&$J39)*O$26 -> 641 | P39: =SUM(K39:O39) -> 1935
A41: Total Balance | C41: Total Cash Flow | E41: Expenses | G41: Income
A42: Previous | B42: Current | C42: Previous | D42: Current | E42: Previous | F42: Current | G42: Previous | H42: Current
...

Sheet Control
A3: Row Labels | B3: Max of Num Month | C3: Sum of Income | D3: Sum of Checking | E3: Sum of Saving | F3: Sum of Investments | G3: Sum of Digital Craft | H3: Sum of Rewards | I3: Sum of Expenses | J3: Sum of Housing | K3: Sum of Food | L3: Sum of Transport | M3: Sum of Shopping | N3: Sum of Gym | O3: Sum of Other | P3: Sum of Goals Accumulation | Q3: Sum of Home | R3: Sum of Travel | S3: Sum of Drive | T3: Sum of Hobby | U3: Sum of Home Plan | V3: Sum of Travel Plan | W3: Sum of Drive Plan | X3: Sum of Hobby Plan | Y3: Sum of Previous Expenses | Z3: Sum of Previous Income
A4: JUL | B4: 7 | C4: 3200 | D4: 375 | E4: 808 | F4: 842 | G4: 535 | H4: 640 | I4: 2300 | J4: 562 | K4: 417 | L4: 291 | M4: 341 | N4: 531 | O4: 158 | P4: 915 | Q4: 146 | R4: 323 | S4: 264 | T4: 183 | U4: 300 | V4: 600 | W4: 500 | X4: 375 | Y4: 1700 | Z4: 3240
A5: AUG | B5: 8 | C5: 3000 | D5: 593 | E5: 539 | F5: 836 | G5: 431 | H5: 601 | I5: 3020 | J5: 837 | K5: 558 | L5: 295 | M5: 358 | N5: 717 | O5: 255 | P5: 910 | Q5: 412 | R5: 141 | S5: 175 | T5: 182 | U5: 300 | V5: 600 | W5: 500 | X5: 375 | Y5: 2300 | Z5: 3200
A6: SEP | B6: 9 | C6: 3200 | D6: 810 | E6: 502 | F6: 579 | G6: 669 | H6: 640 | I6: 3180 | J6: 895 | K6: 440 | L6: 637 | M6: 318 | N6: 684 | O6: 206 | P6: 915 | Q6: 265 | R6: 294 | S6: 173 | T6: 183 | U6: 300 | V6: 600 | W6: 500 | X6: 375 | Y6: 3020 | Z6: 3000
A7: OCT | B7: 10 | C7: 4000 | D7: 1028 | E7: 565 | F7: 898 | G7: 710 | H7: 799 | I7: 2700 | J7: 883 | K7: 357 | L7: 316 | M7: 471 | N7: 508 | O7: 165 | P7: 1240 | Q7: 490 | R7: 307 | S7: 196 | T7: 248 | U7: 300 | V7: 600 | W7: 500 | X7: 375 | Y7: 3180 | Z7: 3200
A8: NOV | B8: 11 | C8: 3920 | D8: 489 | E8: 779 | F8: 1360 | G8: 508 | H8: 784 | I8: 2500 | J8: 717 | K8: 490 | L8: 214 | M8: 413 | N8: 559 | O8: 107 | P8: 1595 | Q8: 450 | R8: 405 | S8: 420 | T8: 319 | U8: 300 | V8: 600 | W8: 500 | X8: 375 | Y8: 2700 | Z8: 4000
A9: Grand Total | B9: 11 | C9: 17320 | D9: 3295 | E9: 3193 | F9: 4515 | G9: 2853 | H9: 3464 | I9: 13700 | J9: 3894 | K9: 2262 | L9: 1753 | M9: 1901 | N9: 2999 | O9: 891 | P9: 5575 | Q9: 1763 | R9: 1470 | S9: 1228 | T9: 1115 | U9: 1500 | V9: 3000 | W9: 2500 | X9: 1875 | Y9: 12900 | Z9: 16640
A20: Row Labels | B20: Sum of Income | C20: Sum of Expenses | D20: Sum of Goals Accumulation | E20: Sum of Checking | F20: Sum of Saving | G20: Sum of Investments | H20: Sum of Digital Craft | I20: Sum of Rewards | J20: Sum of Housing | K20: Sum of Food | L20: Sum of Transport | M20: Sum of Shopping | N20: Sum of Gym | O20: Sum of Other
A21: JAN | B21: 2000 | C21: 2300 | D21: 675 | E21: 368 | F21: 584 | G21: 270 | H21: 378 | I21: 400 | J21: 744 | K21: 339 | L21: 231 | M21: 300 | N21: 501 | O21: 185
A22: FEB | B22: 1600 | C22: 2700 | D22: 400 | E22: 212 | F22: 197 | G22: 364 | H22: 507 | I22: 320 | J22: 670 | K22: 506 | L22: 513 | M22: 367 | N22: 551 | O22: 94
A23: MAR | B23: 1400 | C23: 2620 | D23: 95 | E23: 289 | F23: 273 | G23: 216 | H23: 342 | I23: 280 | J23: 795 | K23: 278 | L23: 299 | M23: 509 | N23: 570 | O23: 170
A24: APR | B24: 1800 | C24: 2100 | D24: 20 | E24: 374 | F24: 447 | G24: 309 | H24: 309 | I24: 361 | J24: 595 | K24: 385 | L24: 368 | M24: 379 | N24: 286 | O24: 88
A25: MAY | B25: 2800 | C25: 1660 | D25: 305 | E25: 448 | F25: 872 | G25: 354 | H25: 566 | I25: 560 | J25: 576 | K25: 305 | L25: 126 | M25: 227 | N25: 354 | O25: 73
A26: JUN | B26: 3240 | C26: 1700 | D26: 690 | E26: 573 | F26: 764 | G26: 914 | H26: 341 | I26: 648 | J26: 541 | K26: 359 | L26: 162 | M26: 283 | N26: 249 | O26: 107
A27: JUL | B27: 3200 | C27: 2300 | D27: 915 | E27: 375 | F27: 808 | G27: 842 | H27: 535 | I27: 640 | J27: 562 | K27: 417 | L27: 291 | M27: 341 | N27: 531 | O27: 158
A28: AUG | B28: 3000 | C28: 3020 | D28: 910 | E28: 593 | F28: 539 | G28: 836 | H28: 431 | I28: 601 | J28: 837 | K28: 558 | L28: 295 | M28: 358 | N28: 717 | O28: 255
A29: SEP | B29: 3200 | C29: 3180 | D29: 915 | E29: 810 | F29: 502 | G29: 579 | H29: 669 | I29: 640 | J29: 895 | K29: 440 | L29: 637 | M29: 318 | N29: 684 | O29: 206
A30: OCT | B30: 4000 | C30: 2700 | D30: 1240 | E30: 1028 | F30: 565 | G30: 898 | H30: 710 | I30: 799 | J30: 883 | K30: 357 | L30: 316 | M30: 471 | N30: 508 | O30: 165
A31: NOV | B31: 3920 | C31: 2500 | D31: 1595 | E31: 489 | F31: 779 | G31: 1360 | H31: 508 | I31: 784 | J31: 717 | K31: 490 | L31: 214 | M31: 413 | N31: 559 | O31: 107
A32: DEC | B32: 3200 | C32: 2700 | D32: 1720 | E32: 727 | F32: 538 | G32: 625 | H32: 669 | I32: 641 | J32: 908 | K32: 295 | L32: 325 | M32: 340 | N32: 639 | O32: 193
A33: Grand Total | B33: 33360 | C33: 29480 | D33: 9480 | E33: 6286 | F33: 6868 | G33: 7567 | H33: 5965 | I33: 6674 | J33: 8723 | K33: 4729 | L33: 3777 | M33: 4306 | N33: 6149 | O33: 1801
A35: Row Labels | B35: Max of Num
A36: Income | B36: 3
A37: Grand Total | B37: 3

Sheet Data
A1: Year | B1: Month | C1: Num Month | D1: Income | E1: Checking | F1: Saving | G1: Investments | H1: Digital Craft | I1: Rewards | J1: Expenses | K1: Housing | L1: Food | M1: Transport | N1: Shopping | O1: Gym | P1: Other | Q1: Goals Accumulation | R1: Home | S1: Travel | T1: Drive | U1: Hobby | V1: Total Goals Plan | W1: Home Plan | X1: Travel Plan | Y1: Drive Plan | Z1: Hobby Plan | AA1: Previous Expenses | AB1: Previous Income
A2: 2028 | B2: JAN | C2: 1 | D2: 2000 | E2: 368 | F2: 584 | G2: 270 | H2: 378 | I2: 400 | J2: 2300 | K2: 744 | L2: 339 | M2: 231 | N2: 300 | O2: 501 | P2: 185 | Q2: 675 | R2: 167 | S2: 263 | T2: 110 | U2: 135 | V2: 1775 | W2: 300 | X2: 600 | Y2: 500 | Z2: 375 | AA2: 890 | AB2: 1523
A3: 2028 | B3: FEB | C3: 2 | D3: 1600 | E3: 212 | F3: 197 | G3: 364 | H3: 507 | I3: 320 | J3: 2700 | K3: 670 | L3: 506 | M3: 513 | N3: 367 | O3: 551 | P3: 94 | Q3: 400 | R3: 114 | S3: 80 | T3: 126 | U3: 80 | V3: 1775 | W3: 300 | X3: 600 | Y3: 500 | Z3: 375 | AA3: 2300 | AB3: 2000
A4: 2028 | B4: MAR | C4: 3 | D4: 1400 | E4: 289 | F4: 273 | G4: 216 | H4: 342 | I4: 280 | J4: 2620 | K4: 795 | L4: 278 | M4: 299 | N4: 509 | O4: 570 | P4: 170 | Q4: 95 | R4: 32 | S4: 22 | T4: 22 | U4: 19 | V4: 1775 | W4: 300 | X4: 600 | Y4: 500 | Z4: 375 | AA4: 2700 | AB4: 1600
A5: 2028 | B5: APR | C5: 4 | D5: 1800 | E5: 374 | F5: 447 | G5: 309 | H5: 309 | I5: 361 | J5: 2100 | K5: 595 | L5: 385 | M5: 368 | N5: 379 | O5: 286 | P5: 88 | Q5: 20 | R5: 5 | S5: 7 | T5: 4 | U5: 4 | V5: 1775 | W5: 300 | X5: 600 | Y5: 500 | Z5: 375 | AA5: 2620 | AB5: 1400
A6: 2028 | B6: MAY | C6: 5 | D6: 2800 | E6: 448 | F6: 872 | G6: 354 | H6: 566 | I6: 560 | J6: 1660 | K6: 576 | L6: 305 | M6: 126 | N6: 227 | O6: 354 | P6: 73 | Q6: 305 | R6: 89 | S6: 82 | T6: 73 | U6: 61 | V6: 1775 | W6: 300 | X6: 600 | Y6: 500 | Z6: 375 | AA6: 2100 | AB6: 1800
A7: 2028 | B7: JUN | C7: 6 | D7: 3240 | E7: 573 | F7: 764 | G7: 914 | H7: 341 | I7: 648 | J7: 1700 | K7: 541 | L7: 359 | M7: 162 | N7: 283 | O7: 249 | P7: 107 | Q7: 690 | R7: 276 | S7: 161 | T7: 116 | U7: 138 | V7: 1775 | W7: 300 | X7: 600 | Y7: 500 | Z7: 375 | AA7: 1660 | AB7: 2800
A8: 2028 | B8: JUL | C8: 7 | D8: 3200 | E8: 375 | F8: 808 | G8: 842 | H8: 535 | I8: 640 | J8: 2300 | K8: 562 | L8: 417 | M8: 291 | N8: 341 | O8: 531 | P8: 158 | Q8: 915 | R8: 146 | S8: 323 | T8: 264 | U8: 183 | V8: 1775 | W8: 300 | X8: 600 | Y8: 500 | Z8: 375 | AA8: 1700 | AB8: 3240
A9: 2028 | B9: AUG | C9: 8 | D9: 3000 | E9: 593 | F9: 539 | G9: 836 | H9: 431 | I9: 601 | J9: 3020 | K9: 837 | L9: 558 | M9: 295 | N9: 358 | O9: 717 | P9: 255 | Q9: 910 | R9: 412 | S9: 141 | T9: 175 | U9: 182 | V9: 1775 | W9: 300 | X9: 600 | Y9: 500 | Z9: 375 | AA9: 2300 | AB9: 3200
A10: 2028 | B10: SEP | C10: 9 | D10: 3200 | E10: 810 | F10: 502 | G10: 579 | H10: 669 | I10: 640 | J10: 3180 | K10: 895 | L10: 440 | M10: 637 | N10: 318 | O10: 684 | P10: 206 | Q10: 915 | R10: 265 | S10: 294 | T10: 173 | U10: 183 | V10: 1775 | W10: 300 | X10: 600 | Y10: 500 | Z10: 375 | AA10: 3020 | AB10: 3000
A11: 2028 | B11: OCT | C11: 10 | D11: 4000 | E11: 1028 | F11: 565 | G11: 898 | H11: 710 | I11: 799 | J11: 2700 | K11: 883 | L11: 357 | M11: 316 | N11: 471 | O11: 508 | P11: 165 | Q11: 1240 | R11: 490 | S11: 307 | T11: 196 | U11: 248 | V11: 1775 | W11: 300 | X11: 600 | Y11: 500 | Z11: 375 | AA11: 3180 | AB11: 3200
A12: 2028 | B12: NOV | C12: 11 | D12: 3920 | E12: 489 | F12: 779 | G12: 1360 | H12: 508 | I12: 784 | J12: 2500 | K12: 717 | L12: 490 | M12: 214 | N12: 413 | O12: 559 | P12: 107 | Q12: 1595 | R12: 450 | S12: 405 | T12: 420 | U12: 319 | V12: 1775 | W12: 300 | X12: 600 | Y12: 500 | Z12: 375 | AA12: 2700 | AB12: 4000
A13: 2028 | B13: DEC | C13: 12 | D13: 3200 | E13: 727 | F13: 538 | G13: 625 | H13: 669 | I13: 641 | J13: 2700 | K13: 908 | L13: 295 | M13: 325 | N13: 340 | O13: 639 | P13: 193 | Q13: 1720 | R13: 280 | S13: 559 | T13: 537 | U13: 344 | V13: 1775 | W13: 300 | X13: 600 | Y13: 500 | Z13: 375 | AA13: 2500 | AB13: 3920
... A37: 2030 | B37: DEC | C37: 12 | D37: 2340 | E37: 672 | F37: 529 | G37: 275 | H37: 396 | I37: 468 | J37: 1752 | K37: 589 | L37: 370 | M37: 264 | N37: 196 | O37: 249 | P37: 85 | Q37: 4377 | R37: 1158 | S37: 1497 | T37: 847 | U37: 876 | V37: 4250 | W37: 1000 | X37: 1500 | Y37: 1000 | Z37: 750 | AA37: 1701 | AB37: 2099

Sheet Resources
B1: Colors | C1: Position | D1: Angle | E1: Transparency | G1: Shadow | O1: $#,##0;-$#,##0;0 | R1: [>=1000]0,"k";[<=-1000]-0,"k";0
