Workbook
Name Slicer_Buttons: #N/A
Name Slicer_Buttons1: #N/A
Name Slicer_Month: #N/A
Name Slicer_Year: #N/A

Sheet DASHBOARD

Sheet DASHBOARD Light

Sheet Financial Goals

Sheet Financial Goals Light

Sheet Income Expenses

Sheet Income Expenses Light

Sheet Essential Costs

Sheet Essential Costs Light

Sheet Processing
C1: Target 1 | D1: Target 2 | E1: Target 3 | F1: Target 4 | G1: Target 5 | I1: Year | O1: Design Customization | S1: Budget | T1: Cost | U1: Budget Plan | V1: Years
A2: Number | B2: Month | H2: Cursor | I2: =MAX(Control!A52:A55) -> 2028 | J2: Targets | L2: Start | M2: Process | N2: End | O2: First | P2: Middle | Q2: Last | S2: {=SUM(W2:W5*U2:U5)} -> 50000 | T2: =SUM(F18:INDEX(F18:F29,I4)) -> 17954 | U2: 40000 | V2: 2027 | W2: =ISNUMBER(MATCH(V2,Control!$A$52:$A$55,0)) -> FALSE
A3: 1 | B3: JAN | C3: =GETPIVOTDATA(""&C$1,Control!$A$20,"Month",""&$B3) -> 400 | D3: =GETPIVOTDATA(""&D$1,Control!$A$20,"Month",""&$B3) -> 0 | E3: =GETPIVOTDATA(""&E$1,Control!$A$20,"Month",""&$B3) -> 0 | F3: =GETPIVOTDATA(""&F$1,Control!$A$20,"Month",""&$B3) -> 0 | G3: =GETPIVOTDATA(""&G$1,Control!$A$20,"Month",""&$B3) -> 0 | H3: =IF(ISNUMBER(GETPIVOTDATA("Num Month",Control!$A$3,"Month",""&B3)),100%,NA()) -> #N/A | I3: Month | J3: Target 1 | K3: =GETPIVOTDATA(""&J3,Control!$A$3) -> 0 | L3: {=COUNTIFS(INDEX($C$1:$G$1,1,A3):INDEX($C$2:$G$14,MATCH(TRUE,INDEX($C$2:$G$14,,A3)>0,0)-1,A3),0)+O3} -> 0.2 | M3: =COUNTIF(INDEX($C$3:$G$14,,A3),">0")-P3 -> 1.8 | N3: =12-SUM(L3:M3) -> 10 | O3: 0.2 | P3: 0.2 | Q3: 0 | S3: =1-T3 -> 0.64092 | T3: =T2/S2 -> 0.35908 | U3: 50000 | V3: 2028 | W3: =ISNUMBER(MATCH(V3,Control!$A$52:$A$55,0)) -> TRUE
A4: 2 | B4: FEB | C4: =GETPIVOTDATA(""&C$1,Control!$A$20,"Month",""&$B4) -> 400 | D4: =GETPIVOTDATA(""&D$1,Control!$A$20,"Month",""&$B4) -> 500 | E4: =GETPIVOTDATA(""&E$1,Control!$A$20,"Month",""&$B4) -> 0 | F4: =GETPIVOTDATA(""&F$1,Control!$A$20,"Month",""&$B4) -> 0 | G4: =GETPIVOTDATA(""&G$1,Control!$A$20,"Month",""&$B4) -> 0 | H4: =IF(ISNUMBER(GETPIVOTDATA("Num Month",Control!$A$3,"Month",""&B4)),100%,NA()) -> #N/A | I4: =GETPIVOTDATA("Max of Num Month",Control!$A$3) -> 6 | J4: Target 2 | K4: =GETPIVOTDATA(""&J4,Control!$A$3) -> 500 | L4: {=COUNTIFS(INDEX($C$1:$G$1,1,A4):INDEX($C$2:$G$14,MATCH(TRUE,INDEX($C$2:$G$14,,A4)>0,0)-1,A4),0)+O4} -> 1 | M4: =COUNTIF(INDEX($C$3:$G$14,,A4),">0")-P4 -> 3 | N4: =12-SUM(L4:M4) -> 8 | O4: 0 | P4: 0 | Q4: 0 | S4: Cursors | U4: 50000 | V4: 2029 | W4: =ISNUMBER(MATCH(V4,Control!$A$52:$A$55,0)) -> FALSE
A5: 3 | B5: MAR | C5: =GETPIVOTDATA(""&C$1,Control!$A$20,"Month",""&$B5) -> 0 | D5: =GETPIVOTDATA(""&D$1,Control!$A$20,"Month",""&$B5) -> 500 | E5: =GETPIVOTDATA(""&E$1,Control!$A$20,"Month",""&$B5) -> 0 | F5: =GETPIVOTDATA(""&F$1,Control!$A$20,"Month",""&$B5) -> 0 | G5: =GETPIVOTDATA(""&G$1,Control!$A$20,"Month",""&$B5) -> 0 | H5: =IF(ISNUMBER(GETPIVOTDATA("Num Month",Control!$A$3,"Month",""&B5)),100%,NA()) -> #N/A | I5: {=INDEX(B3:B14,I4)} -> JUN | J5: Target 3 | K5: =GETPIVOTDATA(""&J5,Control!$A$3) -> 1400 | L5: {=COUNTIFS(INDEX($C$1:$G$1,1,A5):INDEX($C$2:$G$14,MATCH(TRUE,INDEX($C$2:$G$14,,A5)>0,0)-1,A5),0)+O5} -> 3 | M5: =COUNTIF(INDEX($C$3:$G$14,,A5),">0")-P5 -> 2 | N5: =12-SUM(L5:M5) -> 7 | O5: 0 | P5: 0 | Q5: 0 | S5: X | T5: Y | U5: 60000 | V5: 2030 | W5: =ISNUMBER(MATCH(V5,Control!$A$52:$A$55,0)) -> FALSE
A6: 4 | B6: APR | C6: =GETPIVOTDATA(""&C$1,Control!$A$20,"Month",""&$B6) -> 0 | D6: =GETPIVOTDATA(""&D$1,Control!$A$20,"Month",""&$B6) -> 500 | E6: =GETPIVOTDATA(""&E$1,Control!$A$20,"Month",""&$B6) -> 700 | F6: =GETPIVOTDATA(""&F$1,Control!$A$20,"Month",""&$B6) -> 0 | G6: =GETPIVOTDATA(""&G$1,Control!$A$20,"Month",""&$B6) -> 0 | H6: =IF(ISNUMBER(GETPIVOTDATA("Num Month",Control!$A$3,"Month",""&B6)),100%,NA()) -> 1 | I6: Label | J6: Target 4 | K6: =GETPIVOTDATA(""&J6,Control!$A$3) -> 1000 | L6: {=COUNTIFS(INDEX($C$1:$G$1,1,A6):INDEX($C$2:$G$14,MATCH(TRUE,INDEX($C$2:$G$14,,A6)>0,0)-1,A6),0)+O6} -> 4 | M6: =COUNTIF(INDEX($C$3:$G$14,,A6),">0")-P6 -> 4 | N6: =12-SUM(L6:M6) -> 4 | O6: 0 | P6: 0 | Q6: 0 | S6: 0 | T6: 1
A7: 5 | B7: MAY | C7: =GETPIVOTDATA(""&C$1,Control!$A$20,"Month",""&$B7) -> 0 | D7: =GETPIVOTDATA(""&D$1,Control!$A$20,"Month",""&$B7) -> 0 | E7: =GETPIVOTDATA(""&E$1,Control!$A$20,"Month",""&$B7) -> 700 | F7: =GETPIVOTDATA(""&F$1,Control!$A$20,"Month",""&$B7) -> 500 | G7: =GETPIVOTDATA(""&G$1,Control!$A$20,"Month",""&$B7) -> 0 | H7: =IF(ISNUMBER(GETPIVOTDATA("Num Month",Control!$A$3,"Month",""&B7)),100%,NA()) -> 1 | I7: =B3&I8&B4&I8&B5&I8&B6&I8&B7&I8&B8&I8&B9&I8&B10&I8&B11&I8&B12&I8&B13&I8&B14 -> JAN FEB MAR APR MAY JUN JUL AUG SEP OCT NOV DEC | J7: Target 5 | K7: =GETPIVOTDATA(""&J7,Control!$A$3) -> 0 | L7: {=COUNTIFS(INDEX($C$1:$G$1,1,A7):INDEX($C$2:$G$14,MATCH(TRUE,INDEX($C$2:$G$14,,A7)>0,0)-1,A7),0)+O7} -> 7 | M7: =COUNTIF(INDEX($C$3:$G$14,,A7),">0")-P7 -> 4.8 | N7: =12-SUM(L7:M7) -> 0.2 | O7: 0 | P7: 0.2 | Q7: 0.2 | S7: =SIN(S3*2*PI()) -> -0.774185 | T7: =COS(T3*2*PI()) -> -0.63295939
A8: 6 | B8: JUN | C8: =GETPIVOTDATA(""&C$1,Control!$A$20,"Month",""&$B8) -> 0 | D8: =GETPIVOTDATA(""&D$1,Control!$A$20,"Month",""&$B8) -> 0 | E8: =GETPIVOTDATA(""&E$1,Control!$A$20,"Month",""&$B8) -> 0 | F8: =GETPIVOTDATA(""&F$1,Control!$A$20,"Month",""&$B8) -> 500 | G8: =GETPIVOTDATA(""&G$1,Control!$A$20,"Month",""&$B8) -> 0 | H8: =IF(ISNUMBER(GETPIVOTDATA("Num Month",Control!$A$3,"Month",""&B8)),100%,NA()) -> 1
A9: 7 | B9: JUL | C9: =GETPIVOTDATA(""&C$1,Control!$A$20,"Month",""&$B9) -> 0 | D9: =GETPIVOTDATA(""&D$1,Control!$A$20,"Month",""&$B9) -> 0 | E9: =GETPIVOTDATA(""&E$1,Control!$A$20,"Month",""&$B9) -> 0 | F9: =GETPIVOTDATA(""&F$1,Control!$A$20,"Month",""&$B9) -> 500 | G9: =GETPIVOTDATA(""&G$1,Control!$A$20,"Month",""&$B9) -> 0 | H9: =IF(ISNUMBER(GETPIVOTDATA("Num Month",Control!$A$3,"Month",""&B9)),100%,NA()) -> #N/A | J9: heatmap
A10: 8 | B10: AUG | C10: =GETPIVOTDATA(""&C$1,Control!$A$20,"Month",""&$B10) -> 0 | D10: =GETPIVOTDATA(""&D$1,Control!$A$20,"Month",""&$B10) -> 0 | E10: =GETPIVOTDATA(""&E$1,Control!$A$20,"Month",""&$B10) -> 0 | F10: =GETPIVOTDATA(""&F$1,Control!$A$20,"Month",""&$B10) -> 500 | G10: =GETPIVOTDATA(""&G$1,Control!$A$20,"Month",""&$B10) -> 300 | H10: =IF(ISNUMBER(GETPIVOTDATA("Num Month",Control!$A$3,"Month",""&B10)),100%,NA()) -> #N/A | J10: W/D | K10: 1 | L10: 2 | M10: 3 | N10: 4 | O10: 5 | P10: 6 | Q10: 7
A11: 9 | B11: SEP | C11: =GETPIVOTDATA(""&C$1,Control!$A$20,"Month",""&$B11) -> 0 | D11: =GETPIVOTDATA(""&D$1,Control!$A$20,"Month",""&$B11) -> 0 | E11: =GETPIVOTDATA(""&E$1,Control!$A$20,"Month",""&$B11) -> 0 | F11: =GETPIVOTDATA(""&F$1,Control!$A$20,"Month",""&$B11) -> 0 | G11: =GETPIVOTDATA(""&G$1,Control!$A$20,"Month",""&$B11) -> 300 | H11: =IF(ISNUMBER(GETPIVOTDATA("Num Month",Control!$A$3,"Month",""&B11)),100%,NA()) -> #N/A | J11: 1 | K11: {=INDEX('heatmap-DATA'!$D$2:$J$289,MATCH($I$2&$I$4&$J11,'heatmap-DATA'!$A$2:$A$289&'heatmap-DATA'!$B$2:$B$289&'heatmap-DATA'!$C$2:$C$289,0),COLUMN(A$1))} -> 1 | L11: {=INDEX('heatmap-DATA'!$D$2:$J$289,MATCH($I$2&$I$4&$J11,'heatmap-DATA'!$A$2:$A$289&'heatmap-DATA'!$B$2:$B$289&'heatmap-DATA'!$C$2:$C$289,0),COLUMN(B$1))} -> 1 | M11: {=INDEX('heatmap-DATA'!$D$2:$J$289,MATCH($I$2&$I$4&$J11,'heatmap-DATA'!$A$2:$A$289&'heatmap-DATA'!$B$2:$B$289&'heatmap-DATA'!$C$2:$C$289,0),COLUMN(C$1))} -> 1 | N11: {=INDEX('heatmap-DATA'!$D$2:$J$289,MATCH($I$2&$I$4&$J11,'heatmap-DATA'!$A$2:$A$289&'heatmap-DATA'!$B$2:$B$289&'heatmap-DATA'!$C$2:$C$289,0),COLUMN(D$1))} -> 1 | O11: {=INDEX('heatmap-DATA'!$D$2:$J$289,MATCH($I$2&$I$4&$J11,'heatmap-DATA'!$A$2:$A$289&'heatmap-DATA'!$B$2:$B$289&'heatmap-DATA'!$C$2:$C$289,0),COLUMN(E$1))} -> 3 | P11: {=INDEX('heatmap-DATA'!$D$2:$J$289,MATCH($I$2&$I$4&$J11,'heatmap-DATA'!$A$2:$A$289&'heatmap-DATA'!$B$2:$B$289&'heatmap-DATA'!$C$2:$C$289,0),COLUMN(F$1))} -> 2 | Q11: {=INDEX('heatmap-DATA'!$D$2:$J$289,MATCH($I$2&$I$4&$J11,'heatmap-DATA'!$A$2:$A$289&'heatmap-DATA'!$B$2:$B$289&'heatmap-DATA'!$C$2:$C$289,0),COLUMN(G$1))} -> 3
A12: 10 | B12: OCT | C12: =GETPIVOTDATA(""&C$1,Control!$A$20,"Month",""&$B12) -> 0 | D12: =GETPIVOTDATA(""&D$1,Control!$A$20,"Month",""&$B12) -> 0 | E12: =GETPIVOTDATA(""&E$1,Control!$A$20,"Month",""&$B12) -> 0 | F12: =GETPIVOTDATA(""&F$1,Control!$A$20,"Month",""&$B12) -> 0 | G12: =GETPIVOTDATA(""&G$1,Control!$A$20,"Month",""&$B12) -> 300 | H12: =IF(ISNUMBER(GETPIVOTDATA("Num Month",Control!$A$3,"Month",""&B12)),100%,NA()) -> #N/A | J12: 2 | K12: {=INDEX('heatmap-DATA'!$D$2:$J$289,MATCH($I$2&$I$4&$J12,'heatmap-DATA'!$A$2:$A$289&'heatmap-DATA'!$B$2:$B$289&'heatmap-DATA'!$C$2:$C$289,0),COLUMN(A$15))} -> 2 | L12: {=INDEX('heatmap-DATA'!$D$2:$J$289,MATCH($I$2&$I$4&$J12,'heatmap-DATA'!$A$2:$A$289&'heatmap-DATA'!$B$2:$B$289&'heatmap-DATA'!$C$2:$C$289,0),COLUMN(B$1))} -> 2 | M12: {=INDEX('heatmap-DATA'!$D$2:$J$289,MATCH($I$2&$I$4&$J12,'heatmap-DATA'!$A$2:$A$289&'heatmap-DATA'!$B$2:$B$289&'heatmap-DATA'!$C$2:$C$289,0),COLUMN(C$1))} -> 2 | N12: {=INDEX('heatmap-DATA'!$D$2:$J$289,MATCH($I$2&$I$4&$J12,'heatmap-DATA'!$A$2:$A$289&'heatmap-DATA'!$B$2:$B$289&'heatmap-DATA'!$C$2:$C$289,0),COLUMN(D$1))} -> 2 | O12: {=INDEX('heatmap-DATA'!$D$2:$J$289,MATCH($I$2&$I$4&$J12,'heatmap-DATA'!$A$2:$A$289&'heatmap-DATA'!$B$2:$B$289&'heatmap-DATA'!$C$2:$C$289,0),COLUMN(E$1))} -> 2 | P12: {=INDEX('heatmap-DATA'!$D$2:$J$289,MATCH($I$2&$I$4&$J12,'heatmap-DATA'!$A$2:$A$289&'heatmap-DATA'!$B$2:$B$289&'heatmap-DATA'!$C$2:$C$289,0),COLUMN(F$1))} -> 2 | Q12: {=INDEX('heatmap-DATA'!$D$2:$J$289,MATCH($I$2&$I$4&$J12,'heatmap-DATA'!$A$2:$A$289&'heatmap-DATA'!$B$2:$B$289&'heatmap-DATA'!$C$2:$C$289,0),COLUMN(G$1))} -> 3
A13: 11 | B13: NOV | C13: =GETPIVOTDATA(""&C$1,Control!$A$20,"Month",""&$B13) -> 0 | D13: =GETPIVOTDATA(""&D$1,Control!$A$20,"Month",""&$B13) -> 0 | E13: =GETPIVOTDATA(""&E$1,Control!$A$20,"Month",""&$B13) -> 0 | F13: =GETPIVOTDATA(""&F$1,Control!$A$20,"Month",""&$B13) -> 0 | G13: =GETPIVOTDATA(""&G$1,Control!$A$20,"Month",""&$B13) -> 300 | H13: =IF(ISNUMBER(GETPIVOTDATA("Num Month",Control!$A$3,"Month",""&B13)),100%,NA()) -> #N/A | J13: 3 | K13: {=INDEX('heatmap-DATA'!$D$2:$J$289,MATCH($I$2&$I$4&$J13,'heatmap-DATA'!$A$2:$A$289&'heatmap-DATA'!$B$2:$B$289&'heatmap-DATA'!$C$2:$C$289,0),COLUMN(A$15))} -> 3 | L13: {=INDEX('heatmap-DATA'!$D$2:$J$289,MATCH($I$2&$I$4&$J13,'heatmap-DATA'!$A$2:$A$289&'heatmap-DATA'!$B$2:$B$289&'heatmap-DATA'!$C$2:$C$289,0),COLUMN(B$1))} -> 2 | M13: {=INDEX('heatmap-DATA'!$D$2:$J$289,MATCH($I$2&$I$4&$J13,'heatmap-DATA'!$A$2:$A$289&'heatmap-DATA'!$B$2:$B$289&'heatmap-DATA'!$C$2:$C$289,0),COLUMN(C$1))} -> 3 | N13: {=INDEX('heatmap-DATA'!$D$2:$J$289,MATCH($I$2&$I$4&$J13,'heatmap-DATA'!$A$2:$A$289&'heatmap-DATA'!$B$2:$B$289&'heatmap-DATA'!$C$2:$C$289,0),COLUMN(D$1))} -> 3 | O13: {=INDEX('heatmap-DATA'!$D$2:$J$289,MATCH($I$2&$I$4&$J13,'heatmap-DATA'!$A$2:$A$289&'heatmap-DATA'!$B$2:$B$289&'heatmap-DATA'!$C$2:$C$289,0),COLUMN(E$1))} -> 3 | P13: {=INDEX('heatmap-DATA'!$D$2:$J$289,MATCH($I$2&$I$4&$J13,'heatmap-DATA'!$A$2:$A$289&'heatmap-DATA'!$B$2:$B$289&'heatmap-DATA'!$C$2:$C$289,0),COLUMN(F$1))} -> 2 | Q13: {=INDEX('heatmap-DATA'!$D$2:$J$289,MATCH($I$2&$I$4&$J13,'heatmap-DATA'!$A$2:$A$289&'heatmap-DATA'!$B$2:$B$289&'heatmap-DATA'!$C$2:$C$289,0),COLUMN(G$1))} -> 2
A14: 12 | B14: DEC | C14: =GETPIVOTDATA(""&C$1,Control!$A$20,"Month",""&$B14) -> 0 | D14: =GETPIVOTDATA(""&D$1,Control!$A$20,"Month",""&$B14) -> 0 | E14: =GETPIVOTDATA(""&E$1,Control!$A$20,"Month",""&$B14) -> 0 | F14: =GETPIVOTDATA(""&F$1,Control!$A$20,"Month",""&$B14) -> 0 | G14: =GETPIVOTDATA(""&G$1,Control!$A$20,"Month",""&$B14) -> 300 | H14: =IF(ISNUMBER(GETPIVOTDATA("Num Month",Control!$A$3,"Month",""&B14)),100%,NA()) -> #N/A | J14: 4 | K14: {=INDEX('heatmap-DATA'!$D$2:$J$289,MATCH($I$2&$I$4&$J14,'heatmap-DATA'!$A$2:$A$289&'heatmap-DATA'!$B$2:$B$289&'heatmap-DATA'!$C$2:$C$289,0),COLUMN(A$15))} -> 3 | L14: {=INDEX('heatmap-DATA'!$D$2:$J$289,MATCH($I$2&$I$4&$J14,'heatmap-DATA'!$A$2:$A$289&'heatmap-DATA'!$B$2:$B$289&'heatmap-DATA'!$C$2:$C$289,0),COLUMN(B$1))} -> 3 | M14: {=INDEX('heatmap-DATA'!$D$2:$J$289,MATCH($I$2&$I$4&$J14,'heatmap-DATA'!$A$2:$A$289&'heatmap-DATA'!$B$2:$B$289&'heatmap-DATA'!$C$2:$C$289,0),COLUMN(C$1))} -> 3 | N14: {=INDEX('heatmap-DATA'!$D$2:$J$289,MATCH($I$2&$I$4&$J14,'heatmap-DATA'!$A$2:$A$289&'heatmap-DATA'!$B$2:$B$289&'heatmap-DATA'!$C$2:$C$289,0),COLUMN(D$1))} -> 2 | O14: {=INDEX('heatmap-DATA'!$D$2:$J$289,MATCH($I$2&$I$4&$J14,'heatmap-DATA'!$A$2:$A$289&'heatmap-DATA'!$B$2:$B$289&'heatmap-DATA'!$C$2:$C$289,0),COLUMN(E$1))} -> 4 | P14: {=INDEX('heatmap-DATA'!$D$2:$J$289,MATCH($I$2&$I$4&$J14,'heatmap-DATA'!$A$2:$A$289&'heatmap-DATA'!$B$2:$B$289&'heatmap-DATA'!$C$2:$C$289,0),COLUMN(F$1))} -> 3 | Q14: {=INDEX('heatmap-DATA'!$D$2:$J$289,MATCH($I$2&$I$4&$J14,'heatmap-DATA'!$A$2:$A$289&'heatmap-DATA'!$B$2:$B$289&'heatmap-DATA'!$C$2:$C$289,0),COLUMN(G$1))} -> 3
A15: Financial Goals | B15: =SUM(C3:G14) -> 7200 | C15: Total Progress | D15: =SUM(C3:INDEX(G3:G14,I4)) -> 4700 | E15: =D15/B15 -> 0.65277778 | F15: =1-E15 -> 0.34722222 | G15: Current | H15: =GETPIVOTDATA("Sum of Target 1",Control!$A$3)+GETPIVOTDATA("Sum of Target 2",Control!$A$3)+GETPIVOTDATA("Sum of Target 3",Control!$A$3)+GETPIVOTDATA("Sum of Target 4",Control!$A$3)+GETPIVOTDATA("Sum of Target 5",Control!$A$3) -> 2900 | J15: 5 | K15: {=INDEX('heatmap-DATA'!$D$2:$J$289,MATCH($I$2&$I$4&$J15,'heatmap-DATA'!$A$2:$A$289&'heatmap-DATA'!$B$2:$B$289&'heatmap-DATA'!$C$2:$C$289,0),COLUMN(A$15))} -> 2 | L15: {=INDEX('heatmap-DATA'!$D$2:$J$289,MATCH($I$2&$I$4&$J15,'heatmap-DATA'!$A$2:$A$289&'heatmap-DATA'!$B$2:$B$289&'heatmap-DATA'!$C$2:$C$289,0),COLUMN(B$1))} -> 4 | M15: {=INDEX('heatmap-DATA'!$D$2:$J$289,MATCH($I$2&$I$4&$J15,'heatmap-DATA'!$A$2:$A$289&'heatmap-DATA'!$B$2:$B$289&'heatmap-DATA'!$C$2:$C$289,0),COLUMN(C$1))} -> 2 | N15: {=INDEX('heatmap-DATA'!$D$2:$J$289,MATCH($I$2&$I$4&$J15,'heatmap-DATA'!$A$2:$A$289&'heatmap-DATA'!$B$2:$B$289&'heatmap-DATA'!$C$2:$C$289,0),COLUMN(D$1))} -> 2 | O15: {=INDEX('heatmap-DATA'!$D$2:$J$289,MATCH($I$2&$I$4&$J15,'heatmap-DATA'!$A$2:$A$289&'heatmap-DATA'!$B$2:$B$289&'heatmap-DATA'!$C$2:$C$289,0),COLUMN(E$1))} -> 2 | P15: {=INDEX('heatmap-DATA'!$D$2:$J$289,MATCH($I$2&$I$4&$J15,'heatmap-DATA'!$A$2:$A$289&'heatmap-DATA'!$B$2:$B$289&'heatmap-DATA'!$C$2:$C$289,0),COLUMN(F$1))} -> 2 | Q15: {=INDEX('heatmap-DATA'!$D$2:$J$289,MATCH($I$2&$I$4&$J15,'heatmap-DATA'!$A$2:$A$289&'heatmap-DATA'!$B$2:$B$289&'heatmap-DATA'!$C$2:$C$289,0),COLUMN(G$1))} -> 1
A16: Income & Expenses | J16: 6 | K16: {=INDEX('heatmap-DATA'!$D$2:$J$289,MATCH($I$2&$I$4&$J16,'heatmap-DATA'!$A$2:$A$289&'heatmap-DATA'!$B$2:$B$289&'heatmap-DATA'!$C$2:$C$289,0),COLUMN(A$15))} -> 1 | L16: {=INDEX('heatmap-DATA'!$D$2:$J$289,MATCH($I$2&$I$4&$J16,'heatmap-DATA'!$A$2:$A$289&'heatmap-DATA'!$B$2:$B$289&'heatmap-DATA'!$C$2:$C$289,0),COLUMN(B$1))} -> 1 | M16: {=INDEX('heatmap-DATA'!$D$2:$J$289,MATCH($I$2&$I$4&$J16,'heatmap-DATA'!$A$2:$A$289&'heatmap-DATA'!$B$2:$B$289&'heatmap-DATA'!$C$2:$C$289,0),COLUMN(C$1))} -> 1 | N16: {=INDEX('heatmap-DATA'!$D$2:$J$289,MATCH($I$2&$I$4&$J16,'heatmap-DATA'!$A$2:$A$289&'heatmap-DATA'!$B$2:$B$289&'heatmap-DATA'!$C$2:$C$289,0),COLUMN(D$1))} -> 1 | O16: {=INDEX('heatmap-DATA'!$D$2:$J$289,MATCH($I$2&$I$4&$J16,'heatmap-DATA'!$A$2:$A$289&'heatmap-DATA'!$B$2:$B$289&'heatmap-DATA'!$C$2:$C$289,0),COLUMN(E$1))} -> 1 | P16: {=INDEX('heatmap-DATA'!$D$2:$J$289,MATCH($I$2&$I$4&$J16,'heatmap-DATA'!$A$2:$A$289&'heatmap-DATA'!$B$2:$B$289&'heatmap-DATA'!$C$2:$C$289,0),COLUMN(F$1))} -> 1 | Q16: {=INDEX('heatmap-DATA'!$D$2:$J$289,MATCH($I$2&$I$4&$J16,'heatmap-DATA'!$A$2:$A$289&'heatmap-DATA'!$B$2:$B$289&'heatmap-DATA'!$C$2:$C$289,0),COLUMN(G$1))} -> 1
A17: Month | B17: indent | C17: Income | D17: indent Cursor | E17: Cursor | F17: Expenses | G17: Markers | H17: Labels | K17: Calendar | L17: 1 | N17: =IF(L17,"ON","") -> ON | O17: =IF(L17,"","OFF")
A18: JAN | B18: =$B$30 -> 242.05 | C18: =GETPIVOTDATA(""&C$17,Control!$A$20,"Month",""&$A18) -> 2075 | D18: =B18 -> 242.05 | E18: =IFERROR(GETPIVOTDATA(""&C$17,Control!$A$3,"Month",""&$A18),NA()) -> #N/A | F18: =GETPIVOTDATA(""&F$17,Control!$A$20,"Month",""&$A18) -> 2412 | G18: =E18+B18 -> #N/A | H18: =IF(E18>=1000,TEXT(ROUND(E18/1000,0),"0")&"k",E18) -> #N/A | K18: =IF($L$17, IF( AND( (COLUMN() - COLUMN($K$10) + 1) + (ROW() - ROW($K$18)) * 7 - WEEKDAY(DATE($I$2, $I$4, 1), 1) + 1 > 0, (COLUMN() - COLUMN($K$10) + 1) + (ROW() - ROW($K$18)) * 7 - WEEKDAY(DATE($I$2, $I$4, 1), 1) + 1 <= DAY(EOMONTH(DATE($I$2, $I$4, 1), 0)) ), (COLUMN() - COLUMN($K$10) + 1) + (ROW() - ROW($K$18)) * 7 - WEEKDAY(DATE($I$2, $I$4, 1), 1) + 1, "" ), "" ) | L18: =IF($L$17, IF( AND( (COLUMN() - COLUMN($K$10) + 1) + (ROW() - ROW($K$18)) * 7 - WEEKDAY(DATE($I$2, $I$4, 1), 1) + 1 > 0, (COLUMN() - COLUMN($K$10) + 1) + (ROW() - ROW($K$18)) * 7 - WEEKDAY(DATE($I$2, $I$4, 1), 1) + 1 <= DAY(EOMONTH(DATE($I$2, $I$4, 1), 0)) ), (COLUMN() - COLUMN($K$10) + 1) + (ROW() - ROW($K$18)) * 7 - WEEKDAY(DATE($I$2, $I$4, 1), 1) + 1, "" ), "" ) | M18: =IF($L$17, IF( AND( (COLUMN() - COLUMN($K$10) + 1) + (ROW() - ROW($K$18)) * 7 - WEEKDAY(DATE($I$2, $I$4, 1), 1) + 1 > 0, (COLUMN() - COLUMN($K$10) + 1) + (ROW() - ROW($K$18)) * 7 - WEEKDAY(DATE($I$2, $I$4, 1), 1) + 1 <= DAY(EOMONTH(DATE($I$2, $I$4, 1), 0)) ), (COLUMN() - COLUMN($K$10) + 1) + (ROW() - ROW($K$18)) * 7 - WEEKDAY(DATE($I$2, $I$4, 1), 1) + 1, "" ), "" ) | N18: =IF($L$17, IF( AND( (COLUMN() - COLUMN($K$10) + 1) + (ROW() - ROW($K$18)) * 7 - WEEKDAY(DATE($I$2, $I$4, 1), 1) + 1 > 0, (COLUMN() - COLUMN($K$10) + 1) + (ROW() - ROW($K$18)) * 7 - WEEKDAY(DATE($I$2, $I$4, 1), 1) + 1 <= DAY(EOMONTH(DATE($I$2, $I$4, 1), 0)) ), (COLUMN() - COLUMN($K$10) + 1) + (ROW() - ROW($K$18)) * 7 - WEEKDAY(DATE($I$2, $I$4, 1), 1) + 1, "" ), "" ) | O18: =IF($L$17, IF( AND( (COLUMN() - COLUMN($K$10) + 1) + (ROW() - ROW($K$18)) * 7 - WEEKDAY(DATE($I$2, $I$4, 1), 1) + 1 > 0, (COLUMN() - COLUMN($K$10) + 1) + (ROW() - ROW($K$18)) * 7 - WEEKDAY(DATE($I$2, $I$4, 1), 1) + 1 <= DAY(EOMONTH(DATE($I$2, $I$4, 1), 0)) ), (COLUMN() - COLUMN($K$10) + 1) + (ROW() - ROW($K$18)) * 7 - WEEKDAY(DATE($I$2, $I$4, 1), 1) + 1, "" ), "" ) -> 1 | P18: =IF($L$17, IF( AND( (COLUMN() - COLUMN($K$10) + 1) + (ROW() - ROW($K$18)) * 7 - WEEKDAY(DATE($I$2, $I$4, 1), 1) + 1 > 0, (COLUMN() - COLUMN($K$10) + 1) + (ROW() - ROW($K$18)) * 7 - WEEKDAY(DATE($I$2, $I$4, 1), 1) + 1 <= DAY(EOMONTH(DATE($I$2, $I$4, 1), 0)) ), (COLUMN() - COLUMN($K$10) + 1) + (ROW() - ROW($K$18)) * 7 - WEEKDAY(DATE($I$2, $I$4, 1), 1) + 1, "" ), "" ) -> 2 | Q18: =IF($L$17, IF( AND( (COLUMN() - COLUMN($K$10) + 1) + (ROW() - ROW($K$18)) * 7 - WEEKDAY(DATE($I$2, $I$4, 1), 1) + 1 > 0, (COLUMN() - COLUMN($K$10) + 1) + (ROW() - ROW($K$18)) * 7 - WEEKDAY(DATE($I$2, $I$4, 1), 1) + 1 <= DAY(EOMONTH(DATE($I$2, $I$4, 1), 0)) ), (COLUMN() - COLUMN($K$10) + 1) + (ROW() - ROW($K$18)) * 7 - WEEKDAY(DATE($I$2, $I$4, 1), 1) + 1, "" ), "" ) -> 3
A19: FEB | B19: =$B$30 -> 242.05 | C19: =GETPIVOTDATA(""&C$17,Control!$A$20,"Month",""&$A19) -> 3066 | D19: =B19 -> 242.05 | E19: =IFERROR(GETPIVOTDATA(""&C$17,Control!$A$3,"Month",""&$A19),NA()) -> #N/A | F19: =GETPIVOTDATA(""&F$17,Control!$A$20,"Month",""&$A19) -> 1696 | G19: =E19+B19 -> #N/A | H19: =IF(E19>=1000,TEXT(ROUND(E19/1000,0),"0")&"k",E19) -> #N/A | K19: =IF($L$17, IF( AND( (COLUMN() - COLUMN($K$10) + 1) + (ROW() - ROW($K$18)) * 7 - WEEKDAY(DATE($I$2, $I$4, 1), 1) + 1 > 0, (COLUMN() - COLUMN($K$10) + 1) + (ROW() - ROW($K$18)) * 7 - WEEKDAY(DATE($I$2, $I$4, 1), 1) + 1 <= DAY(EOMONTH(DATE($I$2, $I$4, 1), 0)) ), (COLUMN() - COLUMN($K$10) + 1) + (ROW() - ROW($K$18)) * 7 - WEEKDAY(DATE($I$2, $I$4, 1), 1) + 1, "" ), "" ) -> 4 | L19: =IF($L$17, IF( AND( (COLUMN() - COLUMN($K$10) + 1) + (ROW() - ROW($K$18)) * 7 - WEEKDAY(DATE($I$2, $I$4, 1), 1) + 1 > 0, (COLUMN() - COLUMN($K$10) + 1) + (ROW() - ROW($K$18)) * 7 - WEEKDAY(DATE($I$2, $I$4, 1), 1) + 1 <= DAY(EOMONTH(DATE($I$2, $I$4, 1), 0)) ), (COLUMN() - COLUMN($K$10) + 1) + (ROW() - ROW($K$18)) * 7 - WEEKDAY(DATE($I$2, $I$4, 1), 1) + 1, "" ), "" ) -> 5 | M19: =IF($L$17, IF( AND( (COLUMN() - COLUMN($K$10) + 1) + (ROW() - ROW($K$18)) * 7 - WEEKDAY(DATE($I$2, $I$4, 1), 1) + 1 > 0, (COLUMN() - COLUMN($K$10) + 1) + (ROW() - ROW($K$18)) * 7 - WEEKDAY(DATE($I$2, $I$4, 1), 1) + 1 <= DAY(EOMONTH(DATE($I$2, $I$4, 1), 0)) ), (COLUMN() - COLUMN($K$10) + 1) + (ROW() - ROW($K$18)) * 7 - WEEKDAY(DATE($I$2, $I$4, 1), 1) + 1, "" ), "" ) -> 6 | N19: =IF($L$17, IF( AND( (COLUMN() - COLUMN($K$10) + 1) + (ROW() - ROW($K$18)) * 7 - WEEKDAY(DATE($I$2, $I$4, 1), 1) + 1 > 0, (COLUMN() - COLUMN($K$10) + 1) + (ROW() - ROW($K$18)) * 7 - WEEKDAY(DATE($I$2, $I$4, 1), 1) + 1 <= DAY(EOMONTH(DATE($I$2, $I$4, 1), 0)) ), (COLUMN() - COLUMN($K$10) + 1) + (ROW() - ROW($K$18)) * 7 - WEEKDAY(DATE($I$2, $I$4, 1), 1) + 1, "" ), "" ) -> 7 | O19: =IF($L$17, IF( AND( (COLUMN() - COLUMN($K$10) + 1) + (ROW() - ROW($K$18)) * 7 - WEEKDAY(DATE($I$2, $I$4, 1), 1) + 1 > 0, (COLUMN() - COLUMN($K$10) + 1) + (ROW() - ROW($K$18)) * 7 - WEEKDAY(DATE($I$2, $I$4, 1), 1) + 1 <= DAY(EOMONTH(DATE($I$2, $I$4, 1), 0)) ), (COLUMN() - COLUMN($K$10) + 1) + (ROW() - ROW($K$18)) * 7 - WEEKDAY(DATE($I$2, $I$4, 1), 1) + 1, "" ), "" ) -> 8 | P19: =IF($L$17, IF( AND( (COLUMN() - COLUMN($K$10) + 1) + (ROW() - ROW($K$18)) * 7 - WEEKDAY(DATE($I$2, $I$4, 1), 1) + 1 > 0, (COLUMN() - COLUMN($K$10) + 1) + (ROW() - ROW($K$18)) * 7 - WEEKDAY(DATE($I$2, $I$4, 1), 1) + 1 <= DAY(EOMONTH(DATE($I$2, $I$4, 1), 0)) ), (COLUMN() - COLUMN($K$10) + 1) + (ROW() - ROW($K$18)) * 7 - WEEKDAY(DATE($I$2, $I$4, 1), 1) + 1, "" ), "" ) -> 9 | Q19: =IF($L$17, IF( AND( (COLUMN() - COLUMN($K$10) + 1) + (ROW() - ROW($K$18)) * 7 - WEEKDAY(DATE($I$2, $I$4, 1), 1) + 1 > 0, (COLUMN() - COLUMN($K$10) + 1) + (ROW() - ROW($K$18)) * 7 - WEEKDAY(DATE($I$2, $I$4, 1), 1) + 1 <= DAY(EOMONTH(DATE($I$2, $I$4, 1), 0)) ), (COLUMN() - COLUMN($K$10) + 1) + (ROW() - ROW($K$18)) * 7 - WEEKDAY(DATE($I$2, $I$4, 1), 1) + 1, "" ), "" ) -> 10
A20: MAR | B20: =$B$30 -> 242.05 | C20: =GETPIVOTDATA(""&C$17,Control!$A$20,"Month",""&$A20) -> 4626 | D20: =B20 -> 242.05 | E20: =IFERROR(GETPIVOTDATA(""&C$17,Control!$A$3,"Month",""&$A20),NA()) -> #N/A | F20: =GETPIVOTDATA(""&F$17,Control!$A$20,"Month",""&$A20) -> 3544 | G20: =E20+B20 -> #N/A | H20: =IF(E20>=1000,TEXT(ROUND(E20/1000,0),"0")&"k",E20) -> #N/A | K20: =IF($L$17, IF( AND( (COLUMN() - COLUMN($K$10) + 1) + (ROW() - ROW($K$18)) * 7 - WEEKDAY(DATE($I$2, $I$4, 1), 1) + 1 > 0, (COLUMN() - COLUMN($K$10) + 1) + (ROW() - ROW($K$18)) * 7 - WEEKDAY(DATE($I$2, $I$4, 1), 1) + 1 <= DAY(EOMONTH(DATE($I$2, $I$4, 1), 0)) ), (COLUMN() - COLUMN($K$10) + 1) + (ROW() - ROW($K$18)) * 7 - WEEKDAY(DATE($I$2, $I$4, 1), 1) + 1, "" ), "" ) -> 11 | L20: =IF($L$17, IF( AND( (COLUMN() - COLUMN($K$10) + 1) + (ROW() - ROW($K$18)) * 7 - WEEKDAY(DATE($I$2, $I$4, 1), 1) + 1 > 0, (COLUMN() - COLUMN($K$10) + 1) + (ROW() - ROW($K$18)) * 7 - WEEKDAY(DATE($I$2, $I$4, 1), 1) + 1 <= DAY(EOMONTH(DATE($I$2, $I$4, 1), 0)) ), (COLUMN() - COLUMN($K$10) + 1) + (ROW() - ROW($K$18)) * 7 - WEEKDAY(DATE($I$2, $I$4, 1), 1) + 1, "" ), "" ) -> 12 | M20: =IF($L$17, IF( AND( (COLUMN() - COLUMN($K$10) + 1) + (ROW() - ROW($K$18)) * 7 - WEEKDAY(DATE($I$2, $I$4, 1), 1) + 1 > 0, (COLUMN() - COLUMN($K$10) + 1) + (ROW() - ROW($K$18)) * 7 - WEEKDAY(DATE($I$2, $I$4, 1), 1) + 1 <= DAY(EOMONTH(DATE($I$2, $I$4, 1), 0)) ), (COLUMN() - COLUMN($K$10) + 1) + (ROW() - ROW($K$18)) * 7 - WEEKDAY(DATE($I$2, $I$4, 1), 1) + 1, "" ), "" ) -> 13 | N20: =IF($L$17, IF( AND( (COLUMN() - COLUMN($K$10) + 1) + (ROW() - ROW($K$18)) * 7 - WEEKDAY(DATE($I$2, $I$4, 1), 1) + 1 > 0, (COLUMN() - COLUMN($K$10) + 1) + (ROW() - ROW($K$18)) * 7 - WEEKDAY(DATE($I$2, $I$4, 1), 1) + 1 <= DAY(EOMONTH(DATE($I$2, $I$4, 1), 0)) ), (COLUMN() - COLUMN($K$10) + 1) + (ROW() - ROW($K$18)) * 7 - WEEKDAY(DATE($I$2, $I$4, 1), 1) + 1, "" ), "" ) -> 14 | O20: =IF($L$17, IF( AND( (COLUMN() - COLUMN($K$10) + 1) + (ROW() - ROW($K$18)) * 7 - WEEKDAY(DATE($I$2, $I$4, 1), 1) + 1 > 0, (COLUMN() - COLUMN($K$10) + 1) + (ROW() - ROW($K$18)) * 7 - WEEKDAY(DATE($I$2, $I$4, 1), 1) + 1 <= DAY(EOMONTH(DATE($I$2, $I$4, 1), 0)) ), (COLUMN() - COLUMN($K$10) + 1) + (ROW() - ROW($K$18)) * 7 - WEEKDAY(DATE($I$2, $I$4, 1), 1) + 1, "" ), "" ) -> 15 | P20: =IF($L$17, IF( AND( (COLUMN() - COLUMN($K$10) + 1) + (ROW() - ROW($K$18)) * 7 - WEEKDAY(DATE($I$2, $I$4, 1), 1) + 1 > 0, (COLUMN() - COLUMN($K$10) + 1) + (ROW() - ROW($K$18)) * 7 - WEEKDAY(DATE($I$2, $I$4, 1), 1) + 1 <= DAY(EOMONTH(DATE($I$2, $I$4, 1), 0)) ), (COLUMN() - COLUMN($K$10) + 1) + (ROW() - ROW($K$18)) * 7 - WEEKDAY(DATE($I$2, $I$4, 1), 1) + 1, "" ), "" ) -> 16 | Q20: =IF($L$17, IF( AND( (COLUMN() - COLUMN($K$10) + 1) + (ROW() - ROW($K$18)) * 7 - WEEKDAY(DATE($I$2, $I$4, 1), 1) + 1 > 0, (COLUMN() - COLUMN($K$10) + 1) + (ROW() - ROW($K$18)) * 7 - WEEKDAY(DATE($I$2, $I$4, 1), 1) + 1 <= DAY(EOMONTH(DATE($I$2, $I$4, 1), 0)) ), (COLUMN() - COLUMN($K$10) + 1) + (ROW() - ROW($K$18)) * 7 - WEEKDAY(DATE($I$2, $I$4, 1), 1) + 1, "" ), "" ) -> 17
A21: APR | B21: =$B$30 -> 242.05 | C21: =GETPIVOTDATA(""&C$17,Control!$A$20,"Month",""&$A21) -> 4841 | D21: =B21 -> 242.05 | E21: =IFERROR(GETPIVOTDATA(""&C$17,Control!$A$3,"Month",""&$A21),NA()) -> 4841 | F21: =GETPIVOTDATA(""&F$17,Control!$A$20,"Month",""&$A21) -> 2671 | G21: =E21+B21 -> 5083.05 | H21: =IF(E21>=1000,TEXT(ROUND(E21/1000,0),"0")&"k",E21) -> 5k | K21: =IF($L$17, IF( AND( (COLUMN() - COLUMN($K$10) + 1) + (ROW() - ROW($K$18)) * 7 - WEEKDAY(DATE($I$2, $I$4, 1), 1) + 1 > 0, (COLUMN() - COLUMN($K$10) + 1) + (ROW() - ROW($K$18)) * 7 - WEEKDAY(DATE($I$2, $I$4, 1), 1) + 1 <= DAY(EOMONTH(DATE($I$2, $I$4, 1), 0)) ), (COLUMN() - COLUMN($K$10) + 1) + (ROW() - ROW($K$18)) * 7 - WEEKDAY(DATE($I$2, $I$4, 1), 1) + 1, "" ), "" ) -> 18 | L21: =IF($L$17, IF( AND( (COLUMN() - COLUMN($K$10) + 1) + (ROW() - ROW($K$18)) * 7 - WEEKDAY(DATE($I$2, $I$4, 1), 1) + 1 > 0, (COLUMN() - COLUMN($K$10) + 1) + (ROW() - ROW($K$18)) * 7 - WEEKDAY(DATE($I$2, $I$4, 1), 1) + 1 <= DAY(EOMONTH(DATE($I$2, $I$4, 1), 0)) ), (COLUMN() - COLUMN($K$10) + 1) + (ROW() - ROW($K$18)) * 7 - WEEKDAY(DATE($I$2, $I$4, 1), 1) + 1, "" ), "" ) -> 19 | M21: =IF($L$17, IF( AND( (COLUMN() - COLUMN($K$10) + 1) + (ROW() - ROW($K$18)) * 7 - WEEKDAY(DATE($I$2, $I$4, 1), 1) + 1 > 0, (COLUMN() - COLUMN($K$10) + 1) + (ROW() - ROW($K$18)) * 7 - WEEKDAY(DATE($I$2, $I$4, 1), 1) + 1 <= DAY(EOMONTH(DATE($I$2, $I$4, 1), 0)) ), (COLUMN() - COLUMN($K$10) + 1) + (ROW() - ROW($K$18)) * 7 - WEEKDAY(DATE($I$2, $I$4, 1), 1) + 1, "" ), "" ) -> 20 | N21: =IF($L$17, IF( AND( (COLUMN() - COLUMN($K$10) + 1) + (ROW() - ROW($K$18)) * 7 - WEEKDAY(DATE($I$2, $I$4, 1), 1) + 1 > 0, (COLUMN() - COLUMN($K$10) + 1) + (ROW() - ROW($K$18)) * 7 - WEEKDAY(DATE($I$2, $I$4, 1), 1) + 1 <= DAY(EOMONTH(DATE($I$2, $I$4, 1), 0)) ), (COLUMN() - COLUMN($K$10) + 1) + (ROW() - ROW($K$18)) * 7 - WEEKDAY(DATE($I$2, $I$4, 1), 1) + 1, "" ), "" ) -> 21 | O21: =IF($L$17, IF( AND( (COLUMN() - COLUMN($K$10) + 1) + (ROW() - ROW($K$18)) * 7 - WEEKDAY(DATE($I$2, $I$4, 1), 1) + 1 > 0, (COLUMN() - COLUMN($K$10) + 1) + (ROW() - ROW($K$18)) * 7 - WEEKDAY(DATE($I$2, $I$4, 1), 1) + 1 <= DAY(EOMONTH(DATE($I$2, $I$4, 1), 0)) ), (COLUMN() - COLUMN($K$10) + 1) + (ROW() - ROW($K$18)) * 7 - WEEKDAY(DATE($I$2, $I$4, 1), 1) + 1, "" ), "" ) -> 22 | P21: =IF($L$17, IF( AND( (COLUMN() - COLUMN($K$10) + 1) + (ROW() - ROW($K$18)) * 7 - WEEKDAY(DATE($I$2, $I$4, 1), 1) + 1 > 0, (COLUMN() - COLUMN($K$10) + 1) + (ROW() - ROW($K$18)) * 7 - WEEKDAY(DATE($I$2, $I$4, 1), 1) + 1 <= DAY(EOMONTH(DATE($I$2, $I$4, 1), 0)) ), (COLUMN() - COLUMN($K$10) + 1) + (ROW() - ROW($K$18)) * 7 - WEEKDAY(DATE($I$2, $I$4, 1), 1) + 1, "" ), "" ) -> 23 | Q21: =IF($L$17, IF( AND( (COLUMN() - COLUMN($K$10) + 1) + (ROW() - ROW($K$18)) * 7 - WEEKDAY(DATE($I$2, $I$4, 1), 1) + 1 > 0, (COLUMN() - COLUMN($K$10) + 1) + (ROW() - ROW($K$18)) * 7 - WEEKDAY(DATE($I$2, $I$4, 1), 1) + 1 <= DAY(EOMONTH(DATE($I$2, $I$4, 1), 0)) ), (COLUMN() - COLUMN($K$10) + 1) + (ROW() - ROW($K$18)) * 7 - WEEKDAY(DATE($I$2, $I$4, 1), 1) + 1, "" ), "" ) -> 24
A22: MAY | B22: =$B$30 -> 242.05 | C22: =GETPIVOTDATA(""&C$17,Control!$A$20,"Month",""&$A22) -> 4626 | D22: =B22 -> 242.05 | E22: =IFERROR(GETPIVOTDATA(""&C$17,Control!$A$3,"Month",""&$A22),NA()) -> 4626 | F22: =GETPIVOTDATA(""&F$17,Control!$A$20,"Month",""&$A22) -> 3036 | G22: =E22+B22 -> 4868.05 | H22: =IF(E22>=1000,TEXT(ROUND(E22/1000,0),"0")&"k",E22) -> 5k | K22: =IF($L$17, IF( AND( (COLUMN() - COLUMN($K$10) + 1) + (ROW() - ROW($K$18)) * 7 - WEEKDAY(DATE($I$2, $I$4, 1), 1) + 1 > 0, (COLUMN() - COLUMN($K$10) + 1) + (ROW() - ROW($K$18)) * 7 - WEEKDAY(DATE($I$2, $I$4, 1), 1) + 1 <= DAY(EOMONTH(DATE($I$2, $I$4, 1), 0)) ), (COLUMN() - COLUMN($K$10) + 1) + (ROW() - ROW($K$18)) * 7 - WEEKDAY(DATE($I$2, $I$4, 1), 1) + 1, "" ), "" ) -> 25 | L22: =IF($L$17, IF( AND( (COLUMN() - COLUMN($K$10) + 1) + (ROW() - ROW($K$18)) * 7 - WEEKDAY(DATE($I$2, $I$4, 1), 1) + 1 > 0, (COLUMN() - COLUMN($K$10) + 1) + (ROW() - ROW($K$18)) * 7 - WEEKDAY(DATE($I$2, $I$4, 1), 1) + 1 <= DAY(EOMONTH(DATE($I$2, $I$4, 1), 0)) ), (COLUMN() - COLUMN($K$10) + 1) + (ROW() - ROW($K$18)) * 7 - WEEKDAY(DATE($I$2, $I$4, 1), 1) + 1, "" ), "" ) -> 26 | M22: =IF($L$17, IF( AND( (COLUMN() - COLUMN($K$10) + 1) + (ROW() - ROW($K$18)) * 7 - WEEKDAY(DATE($I$2, $I$4, 1), 1) + 1 > 0, (COLUMN() - COLUMN($K$10) + 1) + (ROW() - ROW($K$18)) * 7 - WEEKDAY(DATE($I$2, $I$4, 1), 1) + 1 <= DAY(EOMONTH(DATE($I$2, $I$4, 1), 0)) ), (COLUMN() - COLUMN($K$10) + 1) + (ROW() - ROW($K$18)) * 7 - WEEKDAY(DATE($I$2, $I$4, 1), 1) + 1, "" ), "" ) -> 27 | N22: =IF($L$17, IF( AND( (COLUMN() - COLUMN($K$10) + 1) + (ROW() - ROW($K$18)) * 7 - WEEKDAY(DATE($I$2, $I$4, 1), 1) + 1 > 0, (COLUMN() - COLUMN($K$10) + 1) + (ROW() - ROW($K$18)) * 7 - WEEKDAY(DATE($I$2, $I$4, 1), 1) + 1 <= DAY(EOMONTH(DATE($I$2, $I$4, 1), 0)) ), (COLUMN() - COLUMN($K$10) + 1) + (ROW() - ROW($K$18)) * 7 - WEEKDAY(DATE($I$2, $I$4, 1), 1) + 1, "" ), "" ) -> 28 | O22: =IF($L$17, IF( AND( (COLUMN() - COLUMN($K$10) + 1) + (ROW() - ROW($K$18)) * 7 - WEEKDAY(DATE($I$2, $I$4, 1), 1) + 1 > 0, (COLUMN() - COLUMN($K$10) + 1) + (ROW() - ROW($K$18)) * 7 - WEEKDAY(DATE($I$2, $I$4, 1), 1) + 1 <= DAY(EOMONTH(DATE($I$2, $I$4, 1), 0)) ), (COLUMN() - COLUMN($K$10) + 1) + (ROW() - ROW($K$18)) * 7 - WEEKDAY(DATE($I$2, $I$4, 1), 1) + 1, "" ), "" ) -> 29 | P22: =IF($L$17, IF( AND( (COLUMN() - COLUMN($K$10) + 1) + (ROW() - ROW($K$18)) * 7 - WEEKDAY(DATE($I$2, $I$4, 1), 1) + 1 > 0, (COLUMN() - COLUMN($K$10) + 1) + (ROW() - ROW($K$18)) * 7 - WEEKDAY(DATE($I$2, $I$4, 1), 1) + 1 <= DAY(EOMONTH(DATE($I$2, $I$4, 1), 0)) ), (COLUMN() - COLUMN($K$10) + 1) + (ROW() - ROW($K$18)) * 7 - WEEKDAY(DATE($I$2, $I$4, 1), 1) + 1, "" ), "" ) -> 30 | Q22: =IF($L$17, IF( AND( (COLUMN() - COLUMN($K$10) + 1) + (ROW() - ROW($K$18)) * 7 - WEEKDAY(DATE($I$2, $I$4, 1), 1) + 1 > 0, (COLUMN() - COLUMN($K$10) + 1) + (ROW() - ROW($K$18)) * 7 - WEEKDAY(DATE($I$2, $I$4, 1), 1) + 1 <= DAY(EOMONTH(DATE($I$2, $I$4, 1), 0)) ), (COLUMN() - COLUMN($K$10) + 1) + (ROW() - ROW($K$18)) * 7 - WEEKDAY(DATE($I$2, $I$4, 1), 1) + 1, "" ), "" )
A23: JUN | B23: =$B$30 -> 242.05 | C23: =GETPIVOTDATA(""&C$17,Control!$A$20,"Month",""&$A23) -> 3066 | D23: =B23 -> 242.05 | E23: =IFERROR(GETPIVOTDATA(""&C$17,Control!$A$3,"Month",""&$A23),NA()) -> 3066 | F23: =GETPIVOTDATA(""&F$17,Control!$A$20,"Month",""&$A23) -> 4595 | G23: =E23+B23 -> 3308.05 | H23: =IF(E23>=1000,TEXT(ROUND(E23/1000,0),"0")&"k",E23) -> 3k | K23: =IF($L$17, IF( AND( (COLUMN() - COLUMN($K$10) + 1) + (ROW() - ROW($K$18)) * 7 - WEEKDAY(DATE($I$2, $I$4, 1), 1) + 1 > 0, (COLUMN() - COLUMN($K$10) + 1) + (ROW() - ROW($K$18)) * 7 - WEEKDAY(DATE($I$2, $I$4, 1), 1) + 1 <= DAY(EOMONTH(DATE($I$2, $I$4, 1), 0)) ), (COLUMN() - COLUMN($K$10) + 1) + (ROW() - ROW($K$18)) * 7 - WEEKDAY(DATE($I$2, $I$4, 1), 1) + 1, "" ), "" ) | L23: =IF($L$17, IF( AND( (COLUMN() - COLUMN($K$10) + 1) + (ROW() - ROW($K$18)) * 7 - WEEKDAY(DATE($I$2, $I$4, 1), 1) + 1 > 0, (COLUMN() - COLUMN($K$10) + 1) + (ROW() - ROW($K$18)) * 7 - WEEKDAY(DATE($I$2, $I$4, 1), 1) + 1 <= DAY(EOMONTH(DATE($I$2, $I$4, 1), 0)) ), (COLUMN() - COLUMN($K$10) + 1) + (ROW() - ROW($K$18)) * 7 - WEEKDAY(DATE($I$2, $I$4, 1), 1) + 1, "" ), "" ) | M23: =IF($L$17, IF( AND( (COLUMN() - COLUMN($K$10) + 1) + (ROW() - ROW($K$18)) * 7 - WEEKDAY(DATE($I$2, $I$4, 1), 1) + 1 > 0, (COLUMN() - COLUMN($K$10) + 1) + (ROW() - ROW($K$18)) * 7 - WEEKDAY(DATE($I$2, $I$4, 1), 1) + 1 <= DAY(EOMONTH(DATE($I$2, $I$4, 1), 0)) ), (COLUMN() - COLUMN($K$10) + 1) + (ROW() - ROW($K$18)) * 7 - WEEKDAY(DATE($I$2, $I$4, 1), 1) + 1, "" ), "" ) | N23: =IF($L$17, IF( AND( (COLUMN() - COLUMN($K$10) + 1) + (ROW() - ROW($K$18)) * 7 - WEEKDAY(DATE($I$2, $I$4, 1), 1) + 1 > 0, (COLUMN() - COLUMN($K$10) + 1) + (ROW() - ROW($K$18)) * 7 - WEEKDAY(DATE($I$2, $I$4, 1), 1) + 1 <= DAY(EOMONTH(DATE($I$2, $I$4, 1), 0)) ), (COLUMN() - COLUMN($K$10) + 1) + (ROW() - ROW($K$18)) * 7 - WEEKDAY(DATE($I$2, $I$4, 1), 1) + 1, "" ), "" ) | O23: =IF($L$17, IF( AND( (COLUMN() - COLUMN($K$10) + 1) + (ROW() - ROW($K$18)) * 7 - WEEKDAY(DATE($I$2, $I$4, 1), 1) + 1 > 0, (COLUMN() - COLUMN($K$10) + 1) + (ROW() - ROW($K$18)) * 7 - WEEKDAY(DATE($I$2, $I$4, 1), 1) + 1 <= DAY(EOMONTH(DATE($I$2, $I$4, 1), 0)) ), (COLUMN() - COLUMN($K$10) + 1) + (ROW() - ROW($K$18)) * 7 - WEEKDAY(DATE($I$2, $I$4, 1), 1) + 1, "" ), "" ) | P23: =IF($L$17, IF( AND( (COLUMN() - COLUMN($K$10) + 1) + (ROW() - ROW($K$18)) * 7 - WEEKDAY(DATE($I$2, $I$4, 1), 1) + 1 > 0, (COLUMN() - COLUMN($K$10) + 1) + (ROW() - ROW($K$18)) * 7 - WEEKDAY(DATE($I$2, $I$4, 1), 1) + 1 <= DAY(EOMONTH(DATE($I$2, $I$4, 1), 0)) ), (COLUMN() - COLUMN($K$10) + 1) + (ROW() - ROW($K$18)) * 7 - WEEKDAY(DATE($I$2, $I$4, 1), 1) + 1, "" ), "" ) | Q23: =IF($L$17, IF( AND( (COLUMN() - COLUMN($K$10) + 1) + (ROW() - ROW($K$18)) * 7 - WEEKDAY(DATE($I$2, $I$4, 1), 1) + 1 > 0, (COLUMN() - COLUMN($K$10) + 1) + (ROW() - ROW($K$18)) * 7 - WEEKDAY(DATE($I$2, $I$4, 1), 1) + 1 <= DAY(EOMONTH(DATE($I$2, $I$4, 1), 0)) ), (COLUMN() - COLUMN($K$10) + 1) + (ROW() - ROW($K$18)) * 7 - WEEKDAY(DATE($I$2, $I$4, 1), 1) + 1, "" ), "" ) | T23: =_xlfn.LET(_xlpm.StartDay, WEEKDAY(DATE($I$2, $I$4, 1), 1),_xlpm.DayNum, (COLUMN() - COLUMN($S$18) + 1) + (ROW() - ROW($S$18)) * 7 - _xlpm.StartDay + 1,IF(AND(_xlpm.DayNum > 0, _xlpm.DayNum <= DAY(EOMONTH(DATE($I$2, $I$4, 1), 0))), _xlpm.DayNum, "")) | U23: =_xlfn.LET(_xlpm.StartDay, WEEKDAY(DATE($I$2, $I$4, 1), 1),_xlpm.DayNum, (COLUMN() - COLUMN($S$18) + 1) + (ROW() - ROW($S$18)) * 7 - _xlpm.StartDay + 1,IF(AND(_xlpm.DayNum > 0, _xlpm.DayNum <= DAY(EOMONTH(DATE($I$2, $I$4, 1), 0))), _xlpm.DayNum, "")) | V23: =_xlfn.LET(_xlpm.StartDay, WEEKDAY(DATE($I$2, $I$4, 1), 1),_xlpm.DayNum, (COLUMN() - COLUMN($S$18) + 1) + (ROW() - ROW($S$18)) * 7 - _xlpm.StartDay + 1,IF(AND(_xlpm.DayNum > 0, _xlpm.DayNum <= DAY(EOMONTH(DATE($I$2, $I$4, 1), 0))), _xlpm.DayNum, "")) | W23: =_xlfn.LET(_xlpm.StartDay, WEEKDAY(DATE($I$2, $I$4, 1), 1),_xlpm.DayNum, (COLUMN() - COLUMN($S$18) + 1) + (ROW() - ROW($S$18)) * 7 - _xlpm.StartDay + 1,IF(AND(_xlpm.DayNum > 0, _xlpm.DayNum <= DAY(EOMONTH(DATE($I$2, $I$4, 1), 0))), _xlpm.DayNum, "")) | X23: =_xlfn.LET(_xlpm.StartDay, WEEKDAY(DATE($I$2, $I$4, 1), 1),_xlpm.DayNum, (COLUMN() - COLUMN($S$18) + 1) + (ROW() - ROW($S$18)) * 7 - _xlpm.StartDay + 1,IF(AND(_xlpm.DayNum > 0, _xlpm.DayNum <= DAY(EOMONTH(DATE($I$2, $I$4, 1), 0))), _xlpm.DayNum, "")) | Y23: =_xlfn.LET(_xlpm.StartDay, WEEKDAY(DATE($I$2, $I$4, 1), 1),_xlpm.DayNum, (COLUMN() - COLUMN($S$18) + 1) + (ROW() - ROW($S$18)) * 7 - _xlpm.StartDay + 1,IF(AND(_xlpm.DayNum > 0, _xlpm.DayNum <= DAY(EOMONTH(DATE($I$2, $I$4, 1), 0))), _xlpm.DayNum, ""))
A24: JUL | B24: =$B$30 -> 242.05 | C24: =GETPIVOTDATA(""&C$17,Control!$A$20,"Month",""&$A24) -> 2075 | D24: =B24 -> 242.05 | E24: =IFERROR(GETPIVOTDATA(""&C$17,Control!$A$3,"Month",""&$A24),NA()) -> #N/A | F24: =GETPIVOTDATA(""&F$17,Control!$A$20,"Month",""&$A24) -> 2714 | G24: =E24+B24 -> #N/A | H24: =IF(E24>=1000,TEXT(ROUND(E24/1000,0),"0")&"k",E24) -> #N/A | K24: SU | L24: MO | M24: TU | N24: WE | O24: TH | P24: FR | Q24: SA | R24: Activity | S24: WEEK
A25: AUG | B25: =$B$30 -> 242.05 | C25: =GETPIVOTDATA(""&C$17,Control!$A$20,"Month",""&$A25) -> 3066 | D25: =B25 -> 242.05 | E25: =IFERROR(GETPIVOTDATA(""&C$17,Control!$A$3,"Month",""&$A25),NA()) -> #N/A | F25: =GETPIVOTDATA(""&F$17,Control!$A$20,"Month",""&$A25) -> 3731 | G25: =E25+B25 -> #N/A | H25: =IF(E25>=1000,TEXT(ROUND(E25/1000,0),"0")&"k",E25) -> #N/A | K25: {=INDEX(K$11:K$16,$S25)=$R25} -> TRUE | L25: {=INDEX(L$11:L$16,$S25)=$R25} -> TRUE | M25: {=INDEX(M$11:M$16,$S25)=$R25} -> TRUE | N25: {=INDEX(N$11:N$16,$S25)=$R25} -> TRUE | O25: {=INDEX(O$11:O$16,$S25)=$R25} -> FALSE | P25: {=INDEX(P$11:P$16,$S25)=$R25} -> FALSE | Q25: {=INDEX(Q$11:Q$16,$S25)=$R25} -> FALSE | R25: 1 | S25: =INT((ROW(A1)-1)/4)+1 -> 1
A26: SEP | B26: =$B$30 -> 242.05 | C26: =GETPIVOTDATA(""&C$17,Control!$A$20,"Month",""&$A26) -> 4626 | D26: =B26 -> 242.05 | E26: =IFERROR(GETPIVOTDATA(""&C$17,Control!$A$3,"Month",""&$A26),NA()) -> #N/A | F26: =GETPIVOTDATA(""&F$17,Control!$A$20,"Month",""&$A26) -> 4952 | G26: =E26+B26 -> #N/A | H26: =IF(E26>=1000,TEXT(ROUND(E26/1000,0),"0")&"k",E26) -> #N/A | K26: {=INDEX(K$11:K$16,$S26)=$R26} -> FALSE | L26: {=INDEX(L$11:L$16,$S26)=$R26} -> FALSE | M26: {=INDEX(M$11:M$16,$S26)=$R26} -> FALSE | N26: {=INDEX(N$11:N$16,$S26)=$R26} -> FALSE | O26: {=INDEX(O$11:O$16,$S26)=$R26} -> FALSE | P26: {=INDEX(P$11:P$16,$S26)=$R26} -> TRUE | Q26: {=INDEX(Q$11:Q$16,$S26)=$R26} -> FALSE | R26: 2 | S26: =INT((ROW(A2)-1)/4)+1 -> 1
A27: OCT | B27: =$B$30 -> 242.05 | C27: =GETPIVOTDATA(""&C$17,Control!$A$20,"Month",""&$A27) -> 4841 | D27: =B27 -> 242.05 | E27: =IFERROR(GETPIVOTDATA(""&C$17,Control!$A$3,"Month",""&$A27),NA()) -> #N/A | F27: =GETPIVOTDATA(""&F$17,Control!$A$20,"Month",""&$A27) -> 3544 | G27: =E27+B27 -> #N/A | H27: =IF(E27>=1000,TEXT(ROUND(E27/1000,0),"0")&"k",E27) -> #N/A | K27: {=INDEX(K$11:K$16,$S27)=$R27} -> FALSE | L27: {=INDEX(L$11:L$16,$S27)=$R27} -> FALSE | M27: {=INDEX(M$11:M$16,$S27)=$R27} -> FALSE | N27: {=INDEX(N$11:N$16,$S27)=$R27} -> FALSE | O27: {=INDEX(O$11:O$16,$S27)=$R27} -> TRUE | P27: {=INDEX(P$11:P$16,$S27)=$R27} -> FALSE | Q27: {=INDEX(Q$11:Q$16,$S27)=$R27} -> TRUE | R27: 3 | S27: =INT((ROW(A3)-1)/4)+1 -> 1
A28: NOV | B28: =$B$30 -> 242.05 | C28: =GETPIVOTDATA(""&C$17,Control!$A$20,"Month",""&$A28) -> 4626 | D28: =B28 -> 242.05 | E28: =IFERROR(GETPIVOTDATA(""&C$17,Control!$A$3,"Month",""&$A28),NA()) -> #N/A | F28: =GETPIVOTDATA(""&F$17,Control!$A$20,"Month",""&$A28) -> 4595 | G28: =E28+B28 -> #N/A | H28: =IF(E28>=1000,TEXT(ROUND(E28/1000,0),"0")&"k",E28) -> #N/A | K28: {=INDEX(K$11:K$16,$S28)=$R28} -> FALSE | L28: {=INDEX(L$11:L$16,$S28)=$R28} -> FALSE | M28: {=INDEX(M$11:M$16,$S28)=$R28} -> FALSE | N28: {=INDEX(N$11:N$16,$S28)=$R28} -> FALSE | O28: {=INDEX(O$11:O$16,$S28)=$R28} -> FALSE | P28: {=INDEX(P$11:P$16,$S28)=$R28} -> FALSE | Q28: {=INDEX(Q$11:Q$16,$S28)=$R28} -> FALSE | R28: 4 | S28: =INT((ROW(A4)-1)/4)+1 -> 1
A29: DEC | B29: =$B$30 -> 242.05 | C29: =GETPIVOTDATA(""&C$17,Control!$A$20,"Month",""&$A29) -> 2666 | D29: =B29 -> 242.05 | E29: =IFERROR(GETPIVOTDATA(""&C$17,Control!$A$3,"Month",""&$A29),NA()) -> #N/A | F29: =GETPIVOTDATA(""&F$17,Control!$A$20,"Month",""&$A29) -> 1739 | G29: =E29+B29 -> #N/A | H29: =IF(E29>=1000,TEXT(ROUND(E29/1000,0),"0")&"k",E29) -> #N/A | K29: {=INDEX(K$11:K$16,$S29)=$R29} -> FALSE | L29: {=INDEX(L$11:L$16,$S29)=$R29} -> FALSE | M29: {=INDEX(M$11:M$16,$S29)=$R29} -> FALSE | N29: {=INDEX(N$11:N$16,$S29)=$R29} -> FALSE | O29: {=INDEX(O$11:O$16,$S29)=$R29} -> FALSE | P29: {=INDEX(P$11:P$16,$S29)=$R29} -> FALSE | Q29: {=INDEX(Q$11:Q$16,$S29)=$R29} -> FALSE | R29: 1 | S29: =INT((ROW(A5)-1)/4)+1 -> 2
B30: =MAX(C18:C29)*5% -> 242.05 | E30: {=SUM(IFERROR(E18:E29,0))} -> 12533 | F30: {=SUM(ISNUMBER(E18:E29)*F18:F29)} -> 10302 | K30: {=INDEX(K$11:K$16,$S30)=$R30} -> TRUE | L30: {=INDEX(L$11:L$16,$S30)=$R30} -> TRUE | M30: {=INDEX(M$11:M$16,$S30)=$R30} -> TRUE | N30: {=INDEX(N$11:N$16,$S30)=$R30} -> TRUE | O30: {=INDEX(O$11:O$16,$S30)=$R30} -> TRUE | P30: {=INDEX(P$11:P$16,$S30)=$R30} -> TRUE | Q30: {=INDEX(Q$11:Q$16,$S30)=$R30} -> FALSE | R30: 2 | S30: =INT((ROW(A6)-1)/4)+1 -> 2
E31: Income | F31: Expenses | K31: {=INDEX(K$11:K$16,$S31)=$R31} -> FALSE | L31: {=INDEX(L$11:L$16,$S31)=$R31} -> FALSE | M31: {=INDEX(M$11:M$16,$S31)=$R31} -> FALSE | N31: {=INDEX(N$11:N$16,$S31)=$R31} -> FALSE | O31: {=INDEX(O$11:O$16,$S31)=$R31} -> FALSE | P31: {=INDEX(P$11:P$16,$S31)=$R31} -> FALSE | Q31: {=INDEX(Q$11:Q$16,$S31)=$R31} -> TRUE | R31: 3 | S31: =INT((ROW(A7)-1)/4)+1 -> 2
A32: Source Rating | K32: {=INDEX(K$11:K$16,$S32)=$R32} -> FALSE | L32: {=INDEX(L$11:L$16,$S32)=$R32} -> FALSE | M32: {=INDEX(M$11:M$16,$S32)=$R32} -> FALSE | N32: {=INDEX(N$11:N$16,$S32)=$R32} -> FALSE | O32: {=INDEX(O$11:O$16,$S32)=$R32} -> FALSE | P32: {=INDEX(P$11:P$16,$S32)=$R32} -> FALSE | Q32: {=INDEX(Q$11:Q$16,$S32)=$R32} -> FALSE | R32: 4 | S32: =INT((ROW(A8)-1)/4)+1 -> 2
A33: Sources | B33: indent | C33: Income | D33: Name | E33: indent | F33: Rank | K33: {=INDEX(K$11:K$16,$S33)=$R33} -> FALSE | L33: {=INDEX(L$11:L$16,$S33)=$R33} -> FALSE | M33: {=INDEX(M$11:M$16,$S33)=$R33} -> FALSE | N33: {=INDEX(N$11:N$16,$S33)=$R33} -> FALSE | O33: {=INDEX(O$11:O$16,$S33)=$R33} -> FALSE | P33: {=INDEX(P$11:P$16,$S33)=$R33} -> FALSE | Q33: {=INDEX(Q$11:Q$16,$S33)=$R33} -> FALSE | R33: 1 | S33: =INT((ROW(A9)-1)/4)+1 -> 3
A34: Savings | B34: =$B$38 -> 271.18 | C34: =GETPIVOTDATA(""&A34,Control!$A$3) -> 3874 | D34: {=_xlfn._xlws.SORT(A34:C37,3,-1)} -> Savings | E34: 271.18 | F34: 3874 | K34: {=INDEX(K$11:K$16,$S34)=$R34} -> FALSE | L34: {=INDEX(L$11:L$16,$S34)=$R34} -> TRUE | M34: {=INDEX(M$11:M$16,$S34)=$R34} -> FALSE | N34: {=INDEX(N$11:N$16,$S34)=$R34} -> FALSE | O34: {=INDEX(O$11:O$16,$S34)=$R34} -> FALSE | P34: {=INDEX(P$11:P$16,$S34)=$R34} -> TRUE | Q34: {=INDEX(Q$11:Q$16,$S34)=$R34} -> TRUE | R34: 2 | S34: =INT((ROW(A10)-1)/4)+1 -> 3
A35: Side Job | B35: =$B$38 -> 271.18 | C35: =GETPIVOTDATA(""&A35,Control!$A$3) -> 2607 | D35: Salary | E35: 271.18 | F35: 3546 | K35: {=INDEX(K$11:K$16,$S35)=$R35} -> TRUE | L35: {=INDEX(L$11:L$16,$S35)=$R35} -> FALSE | M35: {=INDEX(M$11:M$16,$S35)=$R35} -> TRUE | N35: {=INDEX(N$11:N$16,$S35)=$R35} -> TRUE | O35: {=INDEX(O$11:O$16,$S35)=$R35} -> TRUE | P35: {=INDEX(P$11:P$16,$S35)=$R35} -> FALSE | Q35: {=INDEX(Q$11:Q$16,$S35)=$R35} -> FALSE | R35: 3 | S35: =INT((ROW(A11)-1)/4)+1 -> 3
A36: Salary | B36: =$B$38 -> 271.18 | C36: =GETPIVOTDATA(""&A36,Control!$A$3) -> 3546 | D36: Side Job | E36: 271.18 | F36: 2607 | K36: {=INDEX(K$11:K$16,$S36)=$R36} -> FALSE | L36: {=INDEX(L$11:L$16,$S36)=$R36} -> FALSE | M36: {=INDEX(M$11:M$16,$S36)=$R36} -> FALSE | N36: {=INDEX(N$11:N$16,$S36)=$R36} -> FALSE | O36: {=INDEX(O$11:O$16,$S36)=$R36} -> FALSE | P36: {=INDEX(P$11:P$16,$S36)=$R36} -> FALSE | Q36: {=INDEX(Q$11:Q$16,$S36)=$R36} -> FALSE | R36: 4 | S36: =INT((ROW(A12)-1)/4)+1 -> 3
A37: Stock | B37: =$B$38 -> 271.18 | C37: =GETPIVOTDATA(""&A37,Control!$A$3) -> 2506 | D37: Stock | E37: 271.18 | F37: 2506 | K37: {=INDEX(K$11:K$16,$S37)=$R37} -> FALSE | L37: {=INDEX(L$11:L$16,$S37)=$R37} -> FALSE | M37: {=INDEX(M$11:M$16,$S37)=$R37} -> FALSE | N37: {=INDEX(N$11:N$16,$S37)=$R37} -> FALSE | O37: {=INDEX(O$11:O$16,$S37)=$R37} -> FALSE | P37: {=INDEX(P$11:P$16,$S37)=$R37} -> FALSE | Q37: {=INDEX(Q$11:Q$16,$S37)=$R37} -> FALSE | R37: 1 | S37: =INT((ROW(A13)-1)/4)+1 -> 4
B38: =MAX(C34:C37)*7% -> 271.18 | K38: {=INDEX(K$11:K$16,$S38)=$R38} -> FALSE | L38: {=INDEX(L$11:L$16,$S38)=$R38} -> FALSE | M38: {=INDEX(M$11:M$16,$S38)=$R38} -> FALSE | N38: {=INDEX(N$11:N$16,$S38)=$R38} -> TRUE | O38: {=INDEX(O$11:O$16,$S38)=$R38} -> FALSE | P38: {=INDEX(P$11:P$16,$S38)=$R38} -> FALSE | Q38: {=INDEX(Q$11:Q$16,$S38)=$R38} -> FALSE | R38: 2 | S38: =INT((ROW(A14)-1)/4)+1 -> 4
A39: Source Rating | K39: {=INDEX(K$11:K$16,$S39)=$R39} -> TRUE | L39: {=INDEX(L$11:L$16,$S39)=$R39} -> TRUE | M39: {=INDEX(M$11:M$16,$S39)=$R39} -> TRUE | N39: {=INDEX(N$11:N$16,$S39)=$R39} -> FALSE | O39: {=INDEX(O$11:O$16,$S39)=$R39} -> FALSE | P39: {=INDEX(P$11:P$16,$S39)=$R39} -> TRUE | Q39: {=INDEX(Q$11:Q$16,$S39)=$R39} -> TRUE | R39: 3 | S39: =INT((ROW(A15)-1)/4)+1 -> 4
A40: Year | B40: Income | C40: Cursor | D40: Labels | K40: {=INDEX(K$11:K$16,$S40)=$R40} -> FALSE | L40: {=INDEX(L$11:L$16,$S40)=$R40} -> FALSE | M40: {=INDEX(M$11:M$16,$S40)=$R40} -> FALSE | N40: {=INDEX(N$11:N$16,$S40)=$R40} -> FALSE | O40: {=INDEX(O$11:O$16,$S40)=$R40} -> TRUE | P40: {=INDEX(P$11:P$16,$S40)=$R40} -> FALSE | Q40: {=INDEX(Q$11:Q$16,$S40)=$R40} -> FALSE | R40: 4 | S40: =INT((ROW(A16)-1)/4)+1 -> 4
...

Sheet Control
A3: Row Labels | B3: Max of Num Month | C3: Sum of Income | D3: Sum of Expenses | E3: Sum of Savings | F3: Sum of Side Job | G3: Sum of Salary | H3: Sum of Stock | I3: Sum of Travel | J3: Sum of FoodCourt | K3: Sum of Supermarket | L3: Sum of Entertainment | M3: Sum of Workplace | N3: Sum of Eating T | O3: Sum of Fuel T | P3: Sum of Leisure T | Q3: Sum of Shopping T | R3: Sum of Hobbies T | S3: Sum of Eating F | T3: Sum of Fuel F | U3: Sum of Leisure F | V3: Sum of Shopping F | W3: Sum of Hobbies F | X3: Sum of Eating S | Y3: Sum of Eating E | Z3: Sum of Fuel E | AA3: Sum of Leisure E | AB3: Sum of Shopping E | AC3: Sum of Hobbies E | AD3: Sum of Eating W | AE3: Sum of Fuel W | AF3: Sum of Leisure W | AG3: Sum of Shopping W | AH3: Sum of Hobbies W | AI3: Sum of Fuel S | AJ3: Sum of Leisure S | AK3: Sum of Hobbies S | AL3: Sum of Shopping S | AM3: Sum of Target 1 | AN3: Sum of Target 2 | AO3: Sum of Target 3 | AP3: Sum of Target 4 | AQ3: Sum of Target 5
A4: APR | B4: 4 | C4: 4841 | D4: 2671 | E4: 1798 | F4: 1134 | G4: 941 | H4: 968 | I4: 547 | J4: 527 | K4: 646 | L4: 417 | M4: 534 | N4: 54 | O4: 143 | P4: 139 | Q4: 101 | R4: 110 | S4: 85 | T4: 154 | U4: 124 | V4: 58 | W4: 106 | X4: 167 | Y4: 106 | Z4: 48 | AA4: 60 | AB4: 120 | AC4: 83 | AD4: 142 | AE4: 84 | AF4: 107 | AG4: 94 | AH4: 107 | AI4: 88 | AJ4: 153 | AK4: 130 | AL4: 108 | AM4: 0 | AN4: 500 | AO4: 700 | AP4: 0 | AQ4: 0
A5: MAY | B5: 5 | C5: 4626 | D5: 3036 | E5: 931 | F5: 982 | G5: 1787 | H5: 926 | I5: 545 | J5: 632 | K5: 582 | L5: 669 | M5: 608 | N5: 56 | O5: 103 | P5: 161 | Q5: 116 | R5: 109 | S5: 131 | T5: 68 | U5: 147 | V5: 160 | W5: 126 | X5: 91 | Y5: 113 | Z5: 145 | AA5: 159 | AB5: 118 | AC5: 134 | AD5: 112 | AE5: 73 | AF5: 142 | AG5: 160 | AH5: 121 | AI5: 136 | AJ5: 136 | AK5: 116 | AL5: 103 | AM5: 0 | AN5: 0 | AO5: 700 | AP5: 500 | AQ5: 0
A6: JUN | B6: 6 | C6: 3066 | D6: 4595 | E6: 1145 | F6: 491 | G6: 818 | H6: 612 | I6: 755 | J6: 436 | K6: 1259 | L6: 1225 | M6: 920 | N6: 128 | O6: 213 | P6: 167 | Q6: 96 | R6: 151 | S6: 126 | T6: 76 | U6: 43 | V6: 104 | W6: 87 | X6: 266 | Y6: 340 | Z6: 236 | AA6: 197 | AB6: 207 | AC6: 245 | AD6: 184 | AE6: 191 | AF6: 187 | AG6: 174 | AH6: 184 | AI6: 326 | AJ6: 117 | AK6: 252 | AL6: 298 | AM6: 0 | AN6: 0 | AO6: 0 | AP6: 500 | AQ6: 0
A7: Grand Total | B7: 6 | C7: 12533 | D7: 10302 | E7: 3874 | F7: 2607 | G7: 3546 | H7: 2506 | I7: 1847 | J7: 1595 | K7: 2487 | L7: 2311 | M7: 2062 | N7: 238 | O7: 459 | P7: 467 | Q7: 313 | R7: 370 | S7: 342 | T7: 298 | U7: 314 | V7: 322 | W7: 319 | X7: 524 | Y7: 559 | Z7: 429 | AA7: 416 | AB7: 445 | AC7: 462 | AD7: 438 | AE7: 348 | AF7: 436 | AG7: 428 | AH7: 412 | AI7: 550 | AJ7: 406 | AK7: 498 | AL7: 509 | AM7: 0 | AN7: 500 | AO7: 1400 | AP7: 1000 | AQ7: 0
A20: Row Labels | B20: Sum of Target 1 | C20: Sum of Target 2 | D20: Sum of Target 3 | E20: Sum of Target 4 | F20: Sum of Target 5 | G20: Sum of Income | H20: Sum of Expenses
A21: JAN | B21: 400 | C21: 0 | D21: 0 | E21: 0 | F21: 0 | G21: 2075 | H21: 2412
A22: FEB | B22: 400 | C22: 500 | D22: 0 | E22: 0 | F22: 0 | G22: 3066 | H22: 1696
A23: MAR | B23: 0 | C23: 500 | D23: 0 | E23: 0 | F23: 0 | G23: 4626 | H23: 3544
A24: APR | B24: 0 | C24: 500 | D24: 700 | E24: 0 | F24: 0 | G24: 4841 | H24: 2671
A25: MAY | B25: 0 | C25: 0 | D25: 700 | E25: 500 | F25: 0 | G25: 4626 | H25: 3036
A26: JUN | B26: 0 | C26: 0 | D26: 0 | E26: 500 | F26: 0 | G26: 3066 | H26: 4595
A27: JUL | B27: 0 | C27: 0 | D27: 0 | E27: 500 | F27: 0 | G27: 2075 | H27: 2714
A28: AUG | B28: 0 | C28: 0 | D28: 0 | E28: 500 | F28: 300 | G28: 3066 | H28: 3731
A29: SEP | B29: 0 | C29: 0 | D29: 0 | E29: 0 | F29: 300 | G29: 4626 | H29: 4952
A30: OCT | B30: 0 | C30: 0 | D30: 0 | E30: 0 | F30: 300 | G30: 4841 | H30: 3544
A31: NOV | B31: 0 | C31: 0 | D31: 0 | E31: 0 | F31: 300 | G31: 4626 | H31: 4595
A32: DEC | B32: 0 | C32: 0 | D32: 0 | E32: 0 | F32: 300 | G32: 2666 | H32: 1739
A33: Grand Total | B33: 800 | C33: 1500 | D33: 1400 | E33: 2000 | F33: 1500 | G33: 44200 | H33: 39229
A35: Row Labels | B35: Sum of Income
A36: 2028 | B36: 44200
A37: Grand Total | B37: 44200
A44: Row Labels | B44: Sum of Income
A45: 2027 | B45: 37965
A46: 2028 | B46: 44200
A47: 2029 | B47: 38780
A48: 2030 | B48: 53560
A49: Grand Total | B49: 174505
A51: Row Labels
A52: 2028
A58: Row Labels
A59: FoodCourt
A60: Supermarket
A61: Travel
A62: Grand Total
A67: Row Labels
A68: Eating
A69: Fuel
A70: Hobbies
A71: Leisure
...

Sheet Data
A1: Year | B1: Month | C1: Num Month | D1: Target 1 | E1: Target 2 | F1: Target 3 | G1: Target 4 | H1: Target 5 | I1: Income | J1: Expenses | K1: Savings | L1: Side Job | M1: Salary | N1: Stock | O1: Travel | P1: Eating T | Q1: Fuel T | R1: Leisure T | S1: Shopping T | T1: Hobbies T | U1: FoodCourt | V1: Eating F | W1: Fuel F | X1: Leisure F | Y1: Shopping F | Z1: Hobbies F | AA1: Supermarket | AB1: Eating S | AC1: Fuel S | AD1: Leisure S | AE1: Shopping S | AF1: Hobbies S | AG1: Entertainment | AH1: Eating E | AI1: Fuel E | AJ1: Leisure E | AK1: Shopping E | AL1: Hobbies E | AM1: Workplace | AN1: Eating W | AO1: Fuel W | AP1: Leisure W | AQ1: Shopping W | AR1: Hobbies W
A2: 2027 | B2: JAN | C2: 1 | D2: 200 | E2: 0 | F2: 0 | G2: 0 | H2: 0 | I2: 1245 | J2: 1623 | K2: 462 | L2: 195 | M2: 339 | N2: 249 | O2: 315 | P2: 83 | Q2: 43 | R2: 89 | S2: 37 | T2: 63 | U2: 315 | V2: 40 | W2: 83 | X2: 72 | Y2: 57 | Z2: 63 | AA2: 197 | AB2: 47 | AC2: 49 | AD2: 24 | AE2: 38 | AF2: 39 | AG2: 472 | AH2: 114 | AI2: 58 | AJ2: 116 | AK2: 89 | AL2: 95 | AM2: 324 | AN2: 63 | AO2: 73 | AP2: 65 | AQ2: 58 | AR2: 65
A3: 2027 | B3: FEB | C3: 2 | D3: 200 | E3: 100 | F3: 0 | G3: 0 | H3: 0 | I3: 2555 | J3: 2535 | K3: 861 | L3: 707 | M3: 476 | N3: 511 | O3: 664 | P3: 118 | Q3: 138 | R3: 155 | S3: 121 | T3: 132 | U3: 440 | V3: 56 | W3: 116 | X3: 64 | Y3: 116 | Z3: 88 | AA3: 341 | AB3: 46 | AC3: 49 | AD3: 120 | AE3: 57 | AF3: 69 | AG3: 583 | AH3: 116 | AI3: 155 | AJ3: 114 | AK3: 81 | AL3: 117 | AM3: 507 | AN3: 75 | AO3: 108 | AP3: 84 | AQ3: 138 | AR3: 102
A4: 2027 | B4: MAR | C4: 3 | D4: 200 | E4: 100 | F4: 0 | G4: 0 | H4: 0 | I4: 2955 | J4: 1959 | K4: 949 | L4: 365 | M4: 1051 | N4: 590 | O4: 293 | P4: 47 | Q4: 50 | R4: 62 | S4: 76 | T4: 58 | U4: 540 | V4: 103 | W4: 64 | X4: 110 | Y4: 156 | Z4: 107 | AA4: 317 | AB4: 87 | AC4: 38 | AD4: 83 | AE4: 45 | AF4: 64 | AG4: 417 | AH4: 100 | AI4: 85 | AJ4: 52 | AK4: 96 | AL4: 84 | AM4: 392 | AN4: 134 | AO4: 77 | AP4: 54 | AQ4: 48 | AR4: 79
A5: 2027 | B5: APR | C5: 4 | D5: 0 | E5: 100 | F5: 0 | G5: 0 | H5: 0 | I5: 3260 | J5: 2877 | K5: 988 | L5: 771 | M5: 850 | N5: 651 | O5: 506 | P5: 93 | Q5: 105 | R5: 120 | S5: 88 | T5: 100 | U5: 401 | V5: 87 | W5: 106 | X5: 44 | Y5: 84 | Z5: 80 | AA5: 697 | AB5: 109 | AC5: 191 | AD5: 122 | AE5: 135 | AF5: 140 | AG5: 697 | AH5: 93 | AI5: 168 | AJ5: 192 | AK5: 104 | AL5: 140 | AM5: 576 | AN5: 143 | AO5: 118 | AP5: 145 | AQ5: 54 | AR5: 116
A6: 2027 | B6: MAY | C6: 5 | D6: 0 | E6: 100 | F6: 0 | G6: 0 | H6: 0 | I6: 2675 | J6: 1968 | K6: 774 | L6: 665 | M6: 701 | N6: 535 | O6: 285 | P6: 75 | Q6: 69 | R6: 56 | S6: 29 | T6: 56 | U6: 598 | V6: 146 | W6: 73 | X6: 122 | Y6: 137 | Z6: 120 | AA6: 313 | AB6: 82 | AC6: 55 | AD6: 54 | AE6: 60 | AF6: 62 | AG6: 377 | AH6: 112 | AI6: 48 | AJ6: 68 | AK6: 73 | AL6: 76 | AM6: 395 | AN6: 99 | AO6: 72 | AP6: 78 | AQ6: 68 | AR6: 78
A7: 2027 | B7: JUN | C7: 6 | D7: 0 | E7: 100 | F7: 300 | G7: 0 | H7: 0 | I7: 3020 | J7: 3180 | K7: 519 | L7: 1278 | M7: 619 | N7: 604 | O7: 843 | P7: 170 | Q7: 189 | R7: 204 | S7: 111 | T7: 169 | U7: 484 | V7: 77 | W7: 89 | X7: 117 | Y7: 103 | Z7: 98 | AA7: 498 | AB7: 48 | AC7: 96 | AD7: 133 | AE7: 122 | AF7: 99 | AG7: 719 | AH7: 146 | AI7: 180 | AJ7: 79 | AK7: 170 | AL7: 144 | AM7: 636 | AN7: 147 | AO7: 181 | AP7: 89 | AQ7: 92 | AR7: 127
A8: 2027 | B8: JUL | C8: 7 | D8: 0 | E8: 100 | F8: 300 | G8: 200 | H8: 0 | I8: 3655 | J8: 1921 | K8: 851 | L8: 1004 | M8: 1069 | N8: 731 | O8: 421 | P8: 75 | Q8: 51 | R8: 116 | S8: 95 | T8: 84 | U8: 439 | V8: 129 | W8: 79 | X8: 81 | Y8: 62 | Z8: 88 | AA8: 360 | AB8: 77 | AC8: 67 | AD8: 95 | AE8: 49 | AF8: 72 | AG8: 317 | AH8: 55 | AI8: 75 | AJ8: 59 | AK8: 65 | AL8: 63 | AM8: 384 | AN8: 84 | AO8: 107 | AP8: 54 | AQ8: 62 | AR8: 77
A9: 2027 | B9: AUG | C9: 8 | D9: 0 | E9: 0 | F9: 300 | G9: 200 | H9: 0 | I9: 3000 | J9: 3068 | K9: 688 | L9: 1070 | M9: 642 | N9: 600 | O9: 453 | P9: 100 | Q9: 81 | R9: 51 | S9: 130 | T9: 91 | U9: 417 | V9: 67 | W9: 64 | X9: 102 | Y9: 101 | Z9: 83 | AA9: 715 | AB9: 98 | AC9: 192 | AD9: 154 | AE9: 128 | AF9: 143 | AG9: 870 | AH9: 275 | AI9: 205 | AJ9: 100 | AK9: 115 | AL9: 175 | AM9: 613 | AN9: 94 | AO9: 104 | AP9: 155 | AQ9: 138 | AR9: 122
A10: 2027 | B10: SEP | C10: 9 | D10: 0 | E10: 0 | F10: 300 | G10: 200 | H10: 0 | I10: 3445 | J10: 2527 | K10: 1160 | L10: 526 | M10: 1070 | N10: 689 | O10: 382 | P10: 110 | Q10: 56 | R10: 48 | S10: 91 | T10: 77 | U10: 501 | V10: 65 | W10: 140 | X10: 118 | Y10: 77 | Z10: 101 | AA10: 565 | AB10: 82 | AC10: 120 | AD10: 111 | AE10: 139 | AF10: 113 | AG10: 574 | AH10: 86 | AI10: 77 | AJ10: 136 | AK10: 160 | AL10: 115 | AM10: 505 | AN10: 160 | AO10: 90 | AP10: 68 | AQ10: 86 | AR10: 101
A11: 2027 | B11: OCT | C11: 10 | D11: 0 | E11: 0 | F11: 0 | G11: 200 | H11: 100 | I11: 4040 | J11: 3467 | K11: 1237 | L11: 739 | M11: 1256 | N11: 808 | O11: 630 | P11: 177 | Q11: 82 | R11: 125 | S11: 120 | T11: 126 | U11: 683 | V11: 206 | W11: 157 | X11: 77 | Y11: 106 | Z11: 137 | AA11: 911 | AB11: 220 | AC11: 196 | AD11: 132 | AE11: 181 | AF11: 182 | AG11: 549 | AH11: 99 | AI11: 142 | AJ11: 76 | AK11: 122 | AL11: 110 | AM11: 694 | AN11: 165 | AO11: 133 | AP11: 159 | AQ11: 98 | AR11: 139
A12: 2027 | B12: NOV | C12: 11 | D12: 0 | E12: 0 | F12: 0 | G12: 200 | H12: 100 | I12: 3695 | J12: 2716 | K12: 1267 | L12: 880 | M12: 809 | N12: 739 | O12: 377 | P12: 66 | Q12: 72 | R12: 103 | S12: 61 | T12: 75 | U12: 890 | V12: 108 | W12: 170 | X12: 298 | Y12: 137 | Z12: 177 | AA12: 498 | AB12: 114 | AC12: 116 | AD12: 72 | AE12: 96 | AF12: 100 | AG12: 407 | AH12: 61 | AI12: 114 | AJ12: 67 | AK12: 84 | AL12: 81 | AM12: 544 | AN12: 133 | AO12: 120 | AP12: 61 | AQ12: 122 | AR12: 108
A13: 2027 | B13: DEC | C13: 12 | D13: 0 | E13: 0 | F13: 0 | G13: 0 | H13: 100 | I13: 4420 | J13: 3608 | K13: 1572 | L13: 859 | M13: 1105 | N13: 884 | O13: 901 | P13: 195 | Q13: 184 | R13: 168 | S13: 173 | T13: 181 | U13: 817 | V13: 117 | W13: 147 | X13: 246 | Y13: 144 | Z13: 163 | AA13: 746 | AB13: 190 | AC13: 113 | AD13: 127 | AE13: 167 | AF13: 149 | AG13: 422 | AH13: 84 | AI13: 128 | AJ13: 46 | AK13: 80 | AL13: 84 | AM13: 722 | AN13: 170 | AO13: 173 | AP13: 170 | AQ13: 64 | AR13: 145
... A49: 2030 | B49: DEC | C49: 12 | D49: 0 | E49: 0 | F49: 0 | G49: 0 | H49: 500 | I49: 4333 | J49: 5536 | K49: 969 | L49: 1616 | M49: 881 | N49: 867 | O49: 970 | P49: 211 | Q49: 154 | R49: 246 | S49: 165 | T49: 194 | U49: 647 | V49: 182 | W49: 105 | X49: 121 | Y49: 109 | Z49: 130 | AA49: 1866 | AB49: 452 | AC49: 433 | AD49: 257 | AE49: 351 | AF49: 373 | AG49: 945 | AH49: 166 | AI49: 252 | AJ49: 97 | AK49: 241 | AL49: 189 | AM49: 1108 | AN49: 185 | AO49: 200 | AP49: 239 | AQ49: 262 | AR49: 222

Sheet heatmap-DATA
A1: Year | B1: Month | C1: Week | D1: 1 | E1: 2 | F1: 3 | G1: 4 | H1: 5 | I1: 6 | J1: 7 | K1: 1 | L1: 2 | M1: 3 | N1: 4 | O1: 5 | P1: 6 | Q1: 7 | S1: 1 | U1: NON
A2: 2027 | B2: 1 | C2: 1 | D2: 1 | E2: 1 | F2: 3 | G2: 1 | H2: 1 | I2: 2 | J2: 2 | K2: =IF(D2<>1,"ERROR!!!","") | L2: =IF(E2<>1,"ERROR!!!","") | M2: =IF(F2<>1,"ERROR!!!","") -> ERROR!!! | N2: =IF(G2<>1,"ERROR!!!","") | O2: =IF(H2<>1,"ERROR!!!","") | P2: =_xlfn.LET(_xlpm.StartDay, WEEKDAY(DATE($A2, $B2, 1), 1),_xlpm.DayNum, (COLUMN() - COLUMN($K$2) + 1) + (ROW() - ROW($K$2)) * 7 - _xlpm.StartDay + 1,IF(AND(_xlpm.DayNum > 0, _xlpm.DayNum <= DAY(EOMONTH(DATE($A2, $B2, 1), 0))), _xlpm.DayNum, "")) -> 1 | Q2: =_xlfn.LET(_xlpm.StartDay, WEEKDAY(DATE($A2, $B2, 1), 1),_xlpm.DayNum, (COLUMN() - COLUMN($K$2) + 1) + (ROW() - ROW($K$2)) * 7 - _xlpm.StartDay + 1,IF(AND(_xlpm.DayNum > 0, _xlpm.DayNum <= DAY(EOMONTH(DATE($A2, $B2, 1), 0))), _xlpm.DayNum, "")) -> 2 | S2: 2 | U2: LOW
A3: 2027 | B3: 1 | C3: 2 | D3: 3 | E3: 2 | F3: 4 | G3: 2 | H3: 3 | I3: 4 | J3: 2 | K3: =_xlfn.LET(_xlpm.StartDay, WEEKDAY(DATE($A3, $B3, 1), 1),_xlpm.DayNum, (COLUMN() - COLUMN($K$2) + 1) + (ROW() - ROW($K$2)) * 7 - _xlpm.StartDay + 1,IF(AND(_xlpm.DayNum > 0, _xlpm.DayNum <= DAY(EOMONTH(DATE($A3, $B3, 1), 0))), _xlpm.DayNum, "")) -> 3 | L3: =_xlfn.LET(_xlpm.StartDay, WEEKDAY(DATE($A3, $B3, 1), 1),_xlpm.DayNum, (COLUMN() - COLUMN($K$2) + 1) + (ROW() - ROW($K$2)) * 7 - _xlpm.StartDay + 1,IF(AND(_xlpm.DayNum > 0, _xlpm.DayNum <= DAY(EOMONTH(DATE($A3, $B3, 1), 0))), _xlpm.DayNum, "")) -> 4 | M3: =_xlfn.LET(_xlpm.StartDay, WEEKDAY(DATE($A3, $B3, 1), 1),_xlpm.DayNum, (COLUMN() - COLUMN($K$2) + 1) + (ROW() - ROW($K$2)) * 7 - _xlpm.StartDay + 1,IF(AND(_xlpm.DayNum > 0, _xlpm.DayNum <= DAY(EOMONTH(DATE($A3, $B3, 1), 0))), _xlpm.DayNum, "")) -> 5 | N3: =_xlfn.LET(_xlpm.StartDay, WEEKDAY(DATE($A3, $B3, 1), 1),_xlpm.DayNum, (COLUMN() - COLUMN($K$2) + 1) + (ROW() - ROW($K$2)) * 7 - _xlpm.StartDay + 1,IF(AND(_xlpm.DayNum > 0, _xlpm.DayNum <= DAY(EOMONTH(DATE($A3, $B3, 1), 0))), _xlpm.DayNum, "")) -> 6 | O3: =_xlfn.LET(_xlpm.StartDay, WEEKDAY(DATE($A3, $B3, 1), 1),_xlpm.DayNum, (COLUMN() - COLUMN($K$2) + 1) + (ROW() - ROW($K$2)) * 7 - _xlpm.StartDay + 1,IF(AND(_xlpm.DayNum > 0, _xlpm.DayNum <= DAY(EOMONTH(DATE($A3, $B3, 1), 0))), _xlpm.DayNum, "")) -> 7 | P3: =_xlfn.LET(_xlpm.StartDay, WEEKDAY(DATE($A3, $B3, 1), 1),_xlpm.DayNum, (COLUMN() - COLUMN($K$2) + 1) + (ROW() - ROW($K$2)) * 7 - _xlpm.StartDay + 1,IF(AND(_xlpm.DayNum > 0, _xlpm.DayNum <= DAY(EOMONTH(DATE($A3, $B3, 1), 0))), _xlpm.DayNum, "")) -> 8 | Q3: =_xlfn.LET(_xlpm.StartDay, WEEKDAY(DATE($A3, $B3, 1), 1),_xlpm.DayNum, (COLUMN() - COLUMN($K$2) + 1) + (ROW() - ROW($K$2)) * 7 - _xlpm.StartDay + 1,IF(AND(_xlpm.DayNum > 0, _xlpm.DayNum <= DAY(EOMONTH(DATE($A3, $B3, 1), 0))), _xlpm.DayNum, "")) -> 9 | S3: 3 | U3: MIDDLE
