Workbook
Name Slicer_Buttons: #N/A
Name Slicer_Buttons1: #N/A
Name Slicer_Month: #N/A
Name Slicer_Week_Day1: #N/A
Name Slicer_Week_Num: #N/A
Name Slicer_Year: #N/A
Name Slicer_Year1: #N/A

Sheet DASHBOARD

Sheet Burndown Chart

Sheet Sprint Cycle

Sheet Cost Structure

Sheet Prototype 1
A48: Weekly Essential Expenses
A49: Week Day | B49: Cost | C49: Cursor | D49: Week Num | F49: Week Num | G49: Budget Plan | H49: Budget | I49: Cost | K49: Sources | L49: indent | M49: Income | N49: Marker | O49: Label
A50: SUN | B50: =GETPIVOTDATA("Cost",$A$105,"Week Day",""&A50) -> 155.4 | C50: =IFERROR(GETPIVOTDATA(""&B$49,$A$95,"Week Day",""&$A50),NA()) -> #N/A | D50: =GETPIVOTDATA("Max of Week Day Num",$A$95) -> 3 | E50: =ISNUMBER(MATCH(F50,$A$117:$A$120,0)) -> FALSE | F50: W01: 1-7 | G50: 800 | H50: {=SUM(G50:G53*E50:E53)} -> 750 | I50: =SUM(B50:INDEX(B50:B56,D50)) -> 376.6 | K50: Savings | L50: =$L$53 -> 15.813 | M50: =GETPIVOTDATA(""&K50,$A$95) -> 75.6 | N50: =L50+M50 -> 91.413 | O50: =ROUND(M50,0) -> 76
A51: MON | B51: =GETPIVOTDATA("Cost",$A$105,"Week Day",""&A51) -> 100.6 | C51: =IFERROR(GETPIVOTDATA(""&B$49,$A$95,"Week Day",""&$A51),NA()) -> #N/A | E51: =ISNUMBER(MATCH(F51,$A$117:$A$120,0)) -> FALSE | F51: W02: 8-14 | G51: 850 | H51: =1-I51 -> 0.49786667 | I51: =I50/H50 -> 0.50213333 | K51: Side Job | L51: =$L$53 -> 15.813 | M51: =GETPIVOTDATA(""&K51,$A$95) -> 151.8 | N51: =L51+M51 -> 167.613 | O51: =ROUND(M51,0) -> 152
A52: TUE | B52: =GETPIVOTDATA("Cost",$A$105,"Week Day",""&A52) -> 120.6 | C52: =IFERROR(GETPIVOTDATA(""&B$49,$A$95,"Week Day",""&$A52),NA()) -> 120.6 | E52: =ISNUMBER(MATCH(F52,$A$117:$A$120,0)) -> FALSE | F52: W03: 15-21 | G52: 900 | K52: Salary | L52: =$L$53 -> 15.813 | M52: =GETPIVOTDATA(""&K52,$A$95) -> 225.9 | N52: =L52+M52 -> 241.713 | O52: =ROUND(M52,0) -> 226
A53: WED | B53: =GETPIVOTDATA("Cost",$A$105,"Week Day",""&A53) -> 100.5 | C53: =IFERROR(GETPIVOTDATA(""&B$49,$A$95,"Week Day",""&$A53),NA()) -> #N/A | E53: =ISNUMBER(MATCH(F53,$A$117:$A$120,0)) -> TRUE | F53: W04: 22-28 | G53: 750 | L53: =MAX(M50:M52)*7% -> 15.813 | M53: =SUM(M50:M52) -> 453.3
A54: THU | B54: =GETPIVOTDATA("Cost",$A$105,"Week Day",""&A54) -> 34.9 | C54: =IFERROR(GETPIVOTDATA(""&B$49,$A$95,"Week Day",""&$A54),NA()) -> #N/A
A55: FRI | B55: =GETPIVOTDATA("Cost",$A$105,"Week Day",""&A55) -> 114.7 | C55: =IFERROR(GETPIVOTDATA(""&B$49,$A$95,"Week Day",""&$A55),NA()) -> #N/A | E55: Essential Costs | F55: Costs | H55: Personal Investments | I55: Costs | J55: indent | K55: Type | L55: Rank
A56: SAT | B56: =GETPIVOTDATA("Cost",$A$105,"Week Day",""&A56) -> 120 | C56: =IFERROR(GETPIVOTDATA(""&B$49,$A$95,"Week Day",""&$A56),NA()) -> #N/A | D56: =LEFT(E56,1) -> E | E56: Eating | F56: =GETPIVOTDATA(""&E56,$A$95) -> 39.8 | H56: Work | I56: =GETPIVOTDATA(""&H56,$A$95) -> 51.2 | J56: =$I$60 -> 4.028 | K56: {=_xlfn._xlws.SORT(H56:I59,2,-1)} -> Home | L56: 100.7
D57: =LEFT(E57,1) -> F | E57: Fuel | F57: =GETPIVOTDATA(""&E57,$A$95) -> 20.4 | H57: Home | I57: =GETPIVOTDATA(""&H57,$A$95) -> 100.7 | J57: =$I$60 -> 4.028 | K57: Work | L57: 51.2
A58: Total Income | B58: =M53 -> 453.3 | D58: =LEFT(E58,1) -> L | E58: Leisure | F58: =GETPIVOTDATA(""&E58,$A$95) -> 24.6 | H58: Body | I58: =GETPIVOTDATA(""&H58,$A$95) -> 9.9 | J58: =$I$60 -> 4.028 | K58: Save | L58: 20.3
A59: Total Expenses | B59: =0-(GETPIVOTDATA("Sum of Cost",$A$95)+L60) -> -302.7 | D59: =LEFT(E59,1) -> S | E59: Shopping | F59: =GETPIVOTDATA(""&E59,$A$95) -> 25.3 | H59: Save | I59: =GETPIVOTDATA(""&H59,$A$95) -> 20.3 | J59: =$I$60 -> 4.028 | K59: Body | L59: 9.9
D60: =LEFT(E60,1) -> H | E60: Hobbies | F60: =GETPIVOTDATA(""&E60,$A$95) -> 10.5 | I60: =MAX(I56:I59)*4% -> 4.028 | L60: =SUM(L56:L59) -> 182.1
F61: =SUM(F56:F60) -> 120.6
A64: Week Day | B64: Cost | C64: Eating | D64: Fuel | E64: Leisure | F64: Shopping | G64: Hobbies | H64: Work | I64: Home | J64: Body | K64: Save | L64: Salary | M64: Side Job | N64: Savings | O64: Week Num | P64: Week Day Num
A65: SUN | B65: =SUM(dataP1[[#This Row],[Eating]:[Hobbies]]) -> 100 | C65: 40 | D65: 15 | E65: 20 | F65: 10 | G65: 15 | H65: 50 | I65: 100 | J65: 10 | K65: 20 | L65: 225 | M65: 150 | N65: 75 | O65: W01: 1-7 | P65: 1
A66: MON | B66: =SUM(dataP1[[#This Row],[Eating]:[Hobbies]]) -> 35 | C66: 15 | D66: 5 | E66: 5 | F66: 5 | G66: 5 | H66: 50 | I66: 50 | J66: 2 | K66: 10 | L66: 45 | M66: 60 | N66: 15 | O66: W01: 1-7 | P66: 2
A67: TUE | B67: =SUM(dataP1[[#This Row],[Eating]:[Hobbies]]) -> 115 | C67: 30 | D67: 10 | E67: 25 | F67: 25 | G67: 25 | H67: 100 | I67: 50 | J67: 5 | K67: 100 | L67: 225 | M67: 150 | N67: 75 | O67: W01: 1-7 | P67: 3
A68: WED | B68: =SUM(dataP1[[#This Row],[Eating]:[Hobbies]]) -> 82 | C68: 25 | D68: 10 | E68: 15 | F68: 15 | G68: 17 | H68: 50 | I68: 320 | J68: 5 | K68: 10 | L68: 225 | M68: 150 | N68: 75 | O68: W01: 1-7 | P68: 4
A69: THU | B69: =SUM(dataP1[[#This Row],[Eating]:[Hobbies]]) -> 155 | C69: 50 | D69: 25 | E69: 30 | F69: 30 | G69: 20 | H69: 100 | I69: 100 | J69: 20 | K69: 20 | L69: 525 | M69: 300 | N69: 150 | O69: W01: 1-7 | P69: 5
A70: FRI | B70: =SUM(dataP1[[#This Row],[Eating]:[Hobbies]]) -> 100 | C70: 30 | D70: 10 | E70: 20 | F70: 20 | G70: 20 | H70: 50 | I70: 100 | J70: 10 | K70: 20 | L70: 225 | M70: 150 | N70: 75 | O70: W01: 1-7 | P70: 6
A71: SAT | B71: =SUM(dataP1[[#This Row],[Eating]:[Hobbies]]) -> 120 | C71: 40 | D71: 20 | E71: 25 | F71: 25 | G71: 10 | H71: 50 | I71: 100 | J71: 10 | K71: 20 | L71: 225 | M71: 150 | N71: 75 | O71: W01: 1-7 | P71: 7
A72: SUN | B72: =SUM(dataP1[[#This Row],[Eating]:[Hobbies]]) -> 35.5 | C72: 15.6 | D72: 5.2 | E72: 4.8 | F72: 4.6 | G72: 5.3 | H72: 48.7 | I72: 51.5 | J72: 1.8 | K72: 9.7 | L72: 44.4 | M72: 62.7 | N72: 15.9 | O72: W02: 8-14 | P72: 1
A73: MON | B73: =SUM(dataP1[[#This Row],[Eating]:[Hobbies]]) -> 116 | C73: 29.8 | D73: 9.4 | E73: 24.1 | F73: 26.2 | G73: 26.5 | H73: 100.9 | I73: 49.3 | J73: 4.7 | K73: 98.7 | L73: 227.7 | M73: 146.4 | N73: 72.3 | O73: W02: 8-14 | P73: 2
A74: TUE | B74: =SUM(dataP1[[#This Row],[Eating]:[Hobbies]]) -> 82.8 | C74: 24.5 | D74: 10.4 | E74: 14.7 | F74: 15.6 | G74: 17.6 | H74: 51.3 | I74: 321.4 | J74: 4.9 | K74: 10.5 | L74: 227.4 | M74: 148.5 | N74: 77.4 | O74: W02: 8-14 | P74: 3
A75: WED | B75: =SUM(dataP1[[#This Row],[Eating]:[Hobbies]]) -> 155.4 | C75: 49.8 | D75: 25.6 | E75: 29.3 | F75: 31.2 | G75: 19.5 | H75: 99.4 | I75: 98.7 | J75: 20.3 | K75: 20.5 | L75: 528.3 | M75: 304.5 | N75: 152.4 | O75: W02: 8-14 | P75: 4
A76: THU | B76: =SUM(dataP1[[#This Row],[Eating]:[Hobbies]]) -> 100.6 | C76: 30.6 | D76: 9.8 | E76: 20.4 | F76: 19.5 | G76: 20.3 | H76: 51.1 | I76: 102.3 | J76: 9.5 | K76: 20.4 | L76: 224.4 | M76: 152.1 | N76: 73.5 | O76: W02: 8-14 | P76: 5
... A92: SAT | B92: =SUM(dataP1[[#This Row],[Eating]:[Hobbies]]) -> 120 | C92: 40 | D92: 20 | E92: 25 | F92: 25 | G92: 10 | H92: 50 | I92: 100 | J92: 10 | K92: 20 | L92: 225 | M92: 150 | N92: 75 | O92: W04: 22-28 | P92: 7
A95: Row Labels | B95: Max of Week Day Num | C95: Sum of Cost | D95: Sum of Eating | E95: Sum of Fuel | F95: Sum of Leisure | G95: Sum of Shopping | H95: Sum of Hobbies | I95: Sum of Work | J95: Sum of Home | K95: Sum of Body | L95: Sum of Save | M95: Sum of Salary | N95: Sum of Side Job | O95: Sum of Savings
A96: TUE | B96: 3 | C96: 120.6 | D96: 39.8 | E96: 20.4 | F96: 24.6 | G96: 25.3 | H96: 10.5 | I96: 51.2 | J96: 100.7 | K96: 9.9 | L96: 20.3 | M96: 225.9 | N96: 151.8 | O96: 75.6
A97: Grand Total | B97: 3 | C97: 120.6 | D97: 39.8 | E97: 20.4 | F97: 24.6 | G97: 25.3 | H97: 10.5 | I97: 51.2 | J97: 100.7 | K97: 9.9 | L97: 20.3 | M97: 225.9 | N97: 151.8 | O97: 75.6
A105: Row Labels | B105: Sum of Cost
A106: SUN | B106: 155.4
A107: MON | B107: 100.6
A108: TUE | B108: 120.6
A109: WED | B109: 100.5
A110: THU | B110: 34.9
A111: FRI | B111: 114.7
A112: SAT | B112: 120
A113: Grand Total | B113: 746.7
...

Sheet Prototype 2
H46: Essential Costs
C47: Travel | D47: FoodCourt | E47: Supermarket | F47: Entertainment | G47: Workplace | H47: Directions | I47: Buttons | J47: Costs | S47: Budget | U47: X | V47: Y
A48: Eating | B48: =LEFT(A48,1) -> E | C48: #N/A | D48: 131 | E48: #N/A | F48: #N/A | G48: 100 | H48: Travel | I48: =LEFT(H48,1) -> T | J48: 315 | M48: 72 | N48: 72 | O48: 72 | P48: 72 | Q48: 72 | S48: 0.75 | T48: =1-S48 -> 0.25 | U48: 0 | V48: 1
A49: Fuel | B49: =LEFT(A49,1) -> F | C49: #N/A | D49: 102 | E49: #N/A | F49: #N/A | G49: 123 | H49: FoodCourt | I49: =LEFT(H49,1) -> F | J49: 524 | M49: 72 | N49: 72 | O49: 72 | P49: 72 | Q49: 72 | U49: =SIN(S48*2*PI()) -> -1 | V49: =COS(T48*2*PI()) -> 6.1257423e-17
A50: Leisure | B50: =LEFT(A50,1) -> L | C50: #N/A | D50: 85 | E50: #N/A | F50: #N/A | G50: 118 | H50: Supermarket | I50: =LEFT(H50,1) -> S | J50: 428 | M50: 72 | N50: 72 | O50: 72 | P50: 72 | Q50: 72
A51: Shopping | B51: =LEFT(A51,1) -> S | C51: #N/A | D51: 112 | E51: #N/A | F51: #N/A | G51: 85 | H51: Entertainment | I51: =LEFT(H51,1) -> E | J51: 754 | M51: 72 | N51: 72 | O51: 72 | P51: 72 | Q51: 72
A52: Hobbies | B52: =LEFT(A52,1) -> H | C52: #N/A | D52: 104 | E52: #N/A | F52: #N/A | G52: 78 | H52: Workplace | I52: =LEFT(H52,1) -> W | J52: 525
B53: Cursor | C53: =SUM(C48:C52) -> #N/A | D53: =SUM(D48:D52) -> 534 | E53: =SUM(E48:E52) -> #N/A | F53: =SUM(F48:F52) -> #N/A | G53: =SUM(G48:G52) -> 504
B54: indent Cursor | C54: =C56 -> 37.7 | D54: =D56 -> 37.7 | E54: =E56 -> 37.7 | F54: =F56 -> 37.7 | G54: =G56 -> 37.7 | S54: Income & Expenses
B55: Total | C55: 315 | D55: 524 | E55: 428 | F55: 754 | G55: 525 | S55: Month | T55: indent | U55: Income | V55: indent Cursor | W55: Cursor | X55: Expenses | Y55: Markers | Z55: Labels
B56: indent | C56: =$H$56 -> 37.7 | D56: =$H$56 -> 37.7 | E56: =$H$56 -> 37.7 | F56: =$H$56 -> 37.7 | G56: =$H$56 -> 37.7 | H56: =MAX(C55:G55)*5% -> 37.7 | S56: JAN | T56: =$T$68 -> 176.8 | U56: 1245 | V56: =T56 -> 176.8 | W56: #N/A | X56: 1623 | Y56: =W56+T56 -> #N/A | Z56: =IF(W56>=1000,TEXT(ROUND(W56/1000,0),"0")&"k",W56) -> #N/A
B57: Markers | C57: =C53+C54 -> #N/A | D57: =D53+D54 -> 571.7 | E57: =E53+E54 -> #N/A | F57: =F53+F54 -> #N/A | G57: =G53+G54 -> 541.7 | S57: FEB | T57: =$T$68 -> 176.8 | U57: 2555 | V57: =T57 -> 176.8 | W57: #N/A | X57: 2535 | Y57: =W57+T57 -> #N/A | Z57: =IF(W57>=1000,TEXT(ROUND(W57/1000,0),"0")&"k",W57) -> #N/A
S58: MAR | T58: =$T$68 -> 176.8 | U58: 2955 | V58: =T58 -> 176.8 | W58: #N/A | X58: 1959 | Y58: =W58+T58 -> #N/A | Z58: =IF(W58>=1000,TEXT(ROUND(W58/1000,0),"0")&"k",W58) -> #N/A
S59: APR | T59: =$T$68 -> 176.8 | U59: 3260 | V59: =T59 -> 176.8 | W59: #N/A | X59: 2877 | Y59: =W59+T59 -> #N/A | Z59: =IF(W59>=1000,TEXT(ROUND(W59/1000,0),"0")&"k",W59) -> #N/A
B60: WEEK | C60: 1 | D60: 2 | E60: 3 | F60: 4 | G60: 5 | H60: 6 | I60: 7 | K60: SU | L60: MO | M60: TU | N60: WE | O60: TH | P60: FR | Q60: SA | S60: MAY | T60: =$T$68 -> 176.8 | U60: 2675 | V60: =T60 -> 176.8 | W60: #N/A | X60: 1968 | Y60: =W60+T60 -> #N/A | Z60: =IF(W60>=1000,TEXT(ROUND(W60/1000,0),"0")&"k",W60) -> #N/A
B61: 1 | C61: 1 | D61: 3 | E61: 3 | F61: 2 | G61: 2 | H61: 4 | I61: 4 | K61: TRUE | L61: FALSE | M61: FALSE | N61: FALSE | O61: FALSE | P61: FALSE | Q61: FALSE | S61: JUN | T61: =$T$68 -> 176.8 | U61: 3020 | V61: =T61 -> 176.8 | W61: #N/A | X61: 3180 | Y61: =W61+T61 -> #N/A | Z61: =IF(W61>=1000,TEXT(ROUND(W61/1000,0),"0")&"k",W61) -> #N/A
B62: 2 | C62: 2 | D62: 3 | E62: 3 | F62: 4 | G62: 3 | H62: 2 | I62: 4 | K62: FALSE | L62: FALSE | M62: FALSE | N62: TRUE | O62: TRUE | P62: FALSE | Q62: FALSE | S62: JUL | T62: =$T$68 -> 176.8 | U62: 3655 | V62: =T62 -> 176.8 | W62: #N/A | X62: 1921 | Y62: =W62+T62 -> #N/A | Z62: =IF(W62>=1000,TEXT(ROUND(W62/1000,0),"0")&"k",W62) -> #N/A
B63: 3 | C63: 3 | D63: 3 | E63: 2 | F63: 2 | G63: 2 | H63: 2 | I63: 3 | K63: FALSE | L63: TRUE | M63: TRUE | N63: FALSE | O63: FALSE | P63: FALSE | Q63: FALSE | S63: AUG | T63: =$T$68 -> 176.8 | U63: 3000 | V63: =T63 -> 176.8 | W63: #N/A | X63: 3068 | Y63: =W63+T63 -> #N/A | Z63: =IF(W63>=1000,TEXT(ROUND(W63/1000,0),"0")&"k",W63) -> #N/A
B64: 4 | C64: 3 | D64: 3 | E64: 3 | F64: 3 | G64: 2 | H64: 2 | I64: 2 | K64: FALSE | L64: FALSE | M64: FALSE | N64: FALSE | O64: FALSE | P64: TRUE | Q64: TRUE | S64: SEP | T64: =$T$68 -> 176.8 | U64: 3445 | V64: =T64 -> 176.8 | W64: =U64 -> 3445 | X64: 2527 | Y64: =W64+T64 -> 3621.8 | Z64: =IF(W64>=1000,TEXT(ROUND(W64/1000,0),"0")&"k",W64) -> 3k
B65: 5 | C65: 3 | D65: 3 | E65: 2 | F65: 1 | G65: 1 | H65: 1 | I65: 1 | K65: FALSE | L65: FALSE | M65: FALSE | N65: FALSE | O65: FALSE | P65: FALSE | Q65: FALSE | S65: OCT | T65: =$T$68 -> 176.8 | U65: 4040 | V65: =T65 -> 176.8 | W65: #N/A | X65: 3467 | Y65: =W65+T65 -> #N/A | Z65: =IF(W65>=1000,TEXT(ROUND(W65/1000,0),"0")&"k",W65) -> #N/A
B66: 6 | C66: 1 | D66: 1 | E66: 1 | F66: 1 | G66: 1 | H66: 1 | I66: 1 | K66: TRUE | L66: FALSE | M66: FALSE | N66: FALSE | O66: FALSE | P66: TRUE | Q66: FALSE | S66: NOV | T66: =$T$68 -> 176.8 | U66: 3695 | V66: =T66 -> 176.8 | W66: #N/A | X66: 2716 | Y66: =W66+T66 -> #N/A | Z66: =IF(W66>=1000,TEXT(ROUND(W66/1000,0),"0")&"k",W66) -> #N/A
B67: Calendar | C67: TRUE | E67: ON | K67: FALSE | L67: TRUE | M67: TRUE | N67: FALSE | O67: TRUE | P67: FALSE | Q67: FALSE | S67: DEC | T67: =$T$68 -> 176.8 | U67: 4420 | V67: =T67 -> 176.8 | W67: #N/A | X67: 3608 | Y67: =W67+T67 -> #N/A | Z67: =IF(W67>=1000,TEXT(ROUND(W67/1000,0),"0")&"k",W67) -> #N/A
B68: Label | D68: 1 | E68: 2 | F68: 3 | G68: 4 | H68: 5 | I68: 6 | K68: FALSE | L68: FALSE | M68: FALSE | N68: TRUE | O68: FALSE | P68: FALSE | Q68: TRUE | T68: =MAX(U56:U67)*4% -> 176.8 | W68: {=SUM(IFERROR(W56:W67,0))} -> 3445 | X68: {=SUM(ISNUMBER(W56:W67)*X56:X67)} -> 2527
B69: =ROMAN(B61)&CHAR(10)&ROMAN(B62)&CHAR(10)&ROMAN(B63)&CHAR(10)&ROMAN(B64)&CHAR(10)&ROMAN(B65)&CHAR(10)&ROMAN(B66) -> I II III IV V VI | C69: 7 | D69: 8 | E69: 9 | F69: 10 | G69: 11 | H69: 12 | I69: 13 | K69: FALSE | L69: FALSE | M69: FALSE | N69: FALSE | O69: FALSE | P69: FALSE | Q69: FALSE | W69: Income | X69: Expenses
C70: 14 | D70: 15 | E70: 16 | F70: 17 | G70: 18 | H70: 19 | I70: 20 | K70: FALSE | L70: FALSE | M70: TRUE | N70: TRUE | O70: TRUE | P70: TRUE | Q70: FALSE
C71: 21 | D71: 22 | E71: 23 | F71: 24 | G71: 25 | H71: 26 | I71: 27 | K71: TRUE | L71: TRUE | M71: FALSE | N71: FALSE | O71: FALSE | P71: FALSE | Q71: TRUE | T71: Year | U71: Income | V71: Cursor | W71: Labels
C72: 28 | D72: 29 | E72: 30 | K72: FALSE | L72: FALSE | M72: FALSE | N72: FALSE | O72: FALSE | P72: FALSE | Q72: FALSE | T72: 2025 | U72: 37965 | V72: #N/A | W72: =IF(V72>=1000,TEXT(ROUND(V72/1000,0),"0")&"k",V72) -> #N/A
B73: FinPlan | K73: FALSE | L73: FALSE | M73: FALSE | N73: FALSE | O73: FALSE | P73: FALSE | Q73: FALSE | T73: 2026 | U73: 41287 | V73: #N/A | W73: =IF(V73>=1000,TEXT(ROUND(V73/1000,0),"0")&"k",V73) -> #N/A
B74: Targets | C74: Start | D74: Process | E74: End | G74: Month | H74: Cursor | K74: FALSE | L74: FALSE | M74: FALSE | N74: FALSE | O74: TRUE | P74: TRUE | Q74: TRUE | T74: 2027 | U74: 28512 | V74: =U74 -> 28512 | W74: =IF(V74>=1000,TEXT(ROUND(V74/1000,0),"0")&"k",V74) -> 29k
B75: Target 1 | C75: 0.2 | D75: 4.8 | E75: 7 | G75: JAN | H75: #N/A | K75: TRUE | L75: TRUE | M75: TRUE | N75: TRUE | O75: FALSE | P75: FALSE | Q75: FALSE | T75: 2028 | U75: 55018 | V75: #N/A | W75: =IF(V75>=1000,TEXT(ROUND(V75/1000,0),"0")&"k",V75) -> #N/A
B76: Target 2 | C76: 2 | D76: 5 | E76: 5 | G76: FEB | H76: #N/A | K76: FALSE | L76: FALSE | M76: FALSE | N76: FALSE | O76: FALSE | P76: FALSE | Q76: FALSE | U76: =SUM(U72:U75) -> 162782
B77: Target 3 | C77: 5 | D77: 3 | E77: 4 | G77: MAR | H77: #N/A | K77: FALSE | L77: FALSE | M77: FALSE | N77: TRUE | O77: TRUE | P77: TRUE | Q77: TRUE | T77: Source Rating
B78: Target 4 | C78: 6 | D78: 3 | E78: 3 | G78: APR | H78: #N/A | K78: FALSE | L78: FALSE | M78: TRUE | N78: FALSE | O78: FALSE | P78: FALSE | Q78: FALSE | T78: indent | U78: Sources | V78: Income | W78: Name | X78: Rank
B79: Target 5 | C79: 8 | D79: 3.8 | E79: 0.2 | G79: MAY | H79: #N/A | K79: TRUE | L79: TRUE | M79: FALSE | N79: FALSE | O79: FALSE | P79: FALSE | Q79: FALSE | T79: =$T$83 -> 714.96 | U79: Savings | V79: 4978 | W79: {=_xlfn._xlws.SORT(U79:V82,2,-1)} -> Salary | X79: 17874
G80: JUN | H80: #N/A | K80: FALSE | L80: FALSE | M80: FALSE | N80: FALSE | O80: FALSE | P80: FALSE | Q80: FALSE | T80: =$T$83 -> 714.96 | U80: Side Job | V80: 12217 | W80: Side Job | X80: 12217
G81: JUL | H81: #N/A | K81: TRUE | L81: TRUE | M81: TRUE | N81: TRUE | O81: TRUE | P81: TRUE | Q81: TRUE | T81: =$T$83 -> 714.96 | U81: Salary | V81: 17874 | W81: Savings | X81: 4978
G82: AUG | H82: #N/A | K82: FALSE | L82: FALSE | M82: FALSE | N82: FALSE | O82: FALSE | P82: FALSE | Q82: FALSE | T82: =$T$83 -> 714.96 | U82: Stock | V82: 2896 | W82: Stock | X82: 2896
G83: SEP | H83: 1 | K83: FALSE | L83: FALSE | M83: FALSE | N83: FALSE | O83: FALSE | P83: FALSE | Q83: FALSE | T83: =MAX(V79:V82)*4% -> 714.96
G84: OCT | H84: #N/A | K84: FALSE | L84: FALSE | M84: FALSE | N84: FALSE | O84: FALSE | P84: FALSE | Q84: FALSE
G85: NOV | H85: #N/A
...

Sheet Prototype 3
A52: Dashboard | B52: PERSONAL FINANCE
A53: Budgeting | B53: 37528 | D53: Ratio Income | I53: Balance: | J53: 6146 | L53: Budget Plan | M53: Budgeting
A54: Income | B54: 35296 | D54: Income | E54: Expenses | F54: X | G54: Y | L54: 0.20678704 | M54: 0.26768127 | N54: 0.082393663 | O54: 0.16114759 | P54: 0.21544034 | Q54: 0.0665501
A55: Expenses | B55: 25057 | D55: =F73/SUM($F$73:$G$73) -> 0.58049767 | E55: =G73/SUM($F$73:$G$73) -> 0.41950233 | F55: 0 | G55: 1 | I55: Used Budget | L55: 0.20678704 | M55: 0.26768127 | N55: 0.082393663 | O55: 0.16114759 | P55: 0.21544034 | Q55: 0.0665501
A56: Investments | B56: 125000 | F56: =SIN(D55*2*PI()) -> -0.4844915 | G56: =COS(E55*2*PI()) -> -0.87479597 | I56: 0.72 | J56: =1-I56 -> 0.28 | L56: 0.20678704 | M56: 0.26768127 | N56: 0.082393663 | O56: 0.16114759 | P56: 0.21544034 | Q56: 0.0665501
A57: Debts | B57: 54534 | I57: 37528
A58: Fin Goals | B58: 109619
A60: Month | B60: indent | C60: Income | D60: Expenses | E60: indent Cursor | F60: Cursors I | G60: Cursors E | H60: Marker | I60: Label | L60: Invest | M60: 125000
A61: JAN | B61: =$B$73 -> 1449.24 | C61: 18166 | D61: 20397 | E61: =B61 -> 1449.24 | F61: #N/A | G61: #N/A | H61: =F61+B61 -> #N/A | I61: =IF(F61>=1000,TEXT(ROUND(F61/1000,0),"0")&"k",F61) -> #N/A | K61: Business | L61: 37500 | M61: 0.3 | N61: 0.3 | O61: 0.3 | P61: 0.3 | Q61: 0.3
A62: FEB | B62: =$B$73 -> 1449.24 | C62: 19801 | D62: 26548 | E62: =B62 -> 1449.24 | F62: #N/A | G62: #N/A | H62: =F62+B62 -> #N/A | I62: =IF(F62>=1000,TEXT(ROUND(F62/1000,0),"0")&"k",F62) -> #N/A | K62: Securities | L62: 18750 | M62: 0.15 | N62: 0.15 | O62: 0.15 | P62: 0.15 | Q62: 0.15
A63: MAR | B63: =$B$73 -> 1449.24 | C63: 22196 | D63: 22099 | E63: =B63 -> 1449.24 | F63: #N/A | G63: #N/A | H63: =F63+B63 -> #N/A | I63: =IF(F63>=1000,TEXT(ROUND(F63/1000,0),"0")&"k",F63) -> #N/A | K63: Gold | L63: 30000 | M63: 0.24 | N63: 0.24 | O63: 0.24 | P63: 0.24 | Q63: 0.24
A64: APR | B64: =$B$73 -> 1449.24 | C64: 25558 | D64: 19614 | E64: =B64 -> 1449.24 | F64: #N/A | G64: #N/A | H64: =F64+B64 -> #N/A | I64: =IF(F64>=1000,TEXT(ROUND(F64/1000,0),"0")&"k",F64) -> #N/A | K64: Rent | L64: 12500 | M64: 0.1 | N64: 0.1 | O64: 0.1 | P64: 0.1 | Q64: 0.1
A65: MAY | B65: =$B$73 -> 1449.24 | C65: 31043 | D65: 24519 | E65: =B65 -> 1449.24 | F65: #N/A | G65: #N/A | H65: =F65+B65 -> #N/A | I65: =IF(F65>=1000,TEXT(ROUND(F65/1000,0),"0")&"k",F65) -> #N/A | K65: Crypto | L65: 26250 | M65: 0.21 | N65: 0.21 | O65: 0.21 | P65: 0.21 | Q65: 0.21
A66: JUN | B66: =$B$73 -> 1449.24 | C66: 31211 | D66: 24837 | E66: =B66 -> 1449.24 | F66: #N/A | G66: #N/A | H66: =F66+B66 -> #N/A | I66: =IF(F66>=1000,TEXT(ROUND(F66/1000,0),"0")&"k",F66) -> #N/A | M66: 1 | N66: 1 | O66: 1 | P66: 1 | Q66: 1
A67: JUL | B67: =$B$73 -> 1449.24 | C67: 30268 | D67: 21183 | E67: =B67 -> 1449.24 | F67: #N/A | G67: #N/A | H67: =F67+B67 -> #N/A | I67: =IF(F67>=1000,TEXT(ROUND(F67/1000,0),"0")&"k",F67) -> #N/A
A68: AUG | B68: =$B$73 -> 1449.24 | C68: 35419 | D68: 22263 | E68: =B68 -> 1449.24 | F68: #N/A | G68: #N/A | H68: =F68+B68 -> #N/A | I68: =IF(F68>=1000,TEXT(ROUND(F68/1000,0),"0")&"k",F68) -> #N/A
A69: SEP | B69: =$B$73 -> 1449.24 | C69: 35296 | D69: 25507 | E69: =B69 -> 1449.24 | F69: 35296 | G69: 25507 | H69: =F69+B69 -> 36745.24 | I69: =IF(F69>=1000,TEXT(ROUND(F69/1000,0),"0")&"k",F69) -> 35k | K69: Debts | L69: Interest Rate | M69: Amount of Debt
A70: OCT | B70: =$B$73 -> 1449.24 | C70: 33397 | D70: 20455 | E70: =B70 -> 1449.24 | F70: #N/A | G70: #N/A | H70: =F70+B70 -> #N/A | I70: =IF(F70>=1000,TEXT(ROUND(F70/1000,0),"0")&"k",F70) -> #N/A | K70: Mortgage | L70: 0.03 | M70: 18500
A71: NOV | B71: =$B$73 -> 1449.24 | C71: 33613 | D71: 26772 | E71: =B71 -> 1449.24 | F71: #N/A | G71: #N/A | H71: =F71+B71 -> #N/A | I71: =IF(F71>=1000,TEXT(ROUND(F71/1000,0),"0")&"k",F71) -> #N/A | K71: Credit Card | L71: 0.095 | M71: 17915
A72: DEC | B72: =$B$73 -> 1449.24 | C72: 36231 | D72: 24419 | E72: =B72 -> 1449.24 | F72: #N/A | G72: #N/A | H72: =F72+B72 -> #N/A | I72: =IF(F72>=1000,TEXT(ROUND(F72/1000,0),"0")&"k",F72) -> #N/A | K72: Car Leasing | L72: 0.05 | M72: 10000
B73: =MAX(C61:D72)*4% -> 1449.24 | F73: {=SUM(IFERROR(F61:F72,0))} -> 35296 | G73: {=SUM(IFERROR(G61:G72,0))} -> 25507 | K73: Consumer Credit | L73: 0.07 | M73: 8119
AC74: Buttons | AD74: Num
A75: 109619 | AC75: JANUARY | AD75: 1
A76: Financial Goals | C76: 0.51 | D76: =H82&CHAR(10)&F82&CHAR(10)&D82&CHAR(10)&B82 -> Goal 1 Goal 2 Goal 3 Goal 4 | AC76: FEBRUARY | AD76: 2
A77: Plan ON | B77: TRUE | AC77: MARCH | AD77: 3
A78: 0.74675325 | B78: 0.30088312 | C78: 0.30088312 | D78: 0.45271429 | E78: 0.45271429 | F78: 0.61906494 | G78: 0.61906494 | H78: 0.79076623 | I78: Done | AC78: APRIL | AD78: 4
A79: 0.01 | B79: 0.088727273 | C79: 0.088727273 | D79: 0.30053247 | E79: 0.30053247 | F79: 0.22509091 | G79: 0.22509091 | H79: 0.20923377 | I79: Running | AC79: MAY | AD79: 5
A80: 0.24324675 | B80: 0.61038961 | C80: 0.61038961 | D80: 0.24675325 | E80: 0.24675325 | F80: 0.15584416 | G80: 0.15584416 | H80: 0 | I80: Reserve | AC80: JUNE | AD80: 6
A81: 0.34 | B81: 0.34 | C81: 0.34 | D81: 0.34 | E81: 0.34 | F81: 0.34 | G81: 0.34 | H81: 0.34 | AC81: JULY | AD81: 7
B82: Goal 4 | D82: Goal 3 | F82: Goal 2 | H82: Goal 1 | AC82: AUGUST | AD82: 8
AC83: SEPTEMBER | AD83: 9
AC84: OCTOBER | AD84: 10
AC85: NOVEMBER | AD85: 11
AC86: DECEMBER | AD86: 12
AC88: Row Labels | AD88: Max of Num
AC89: SEPTEMBER | AD89: 9
AC90: Grand Total | AD90: 9

Sheet Processing
A1: Month | B1: Actual | C1: Progress | D1: Target | E1: Cursor | F1: Month | G1: Risks | H1: Probability | J1: Cost Structure | K1: Cost | M1: Budget & Cost | N1: =(M3-ABS(N3))/M3 -> 0.3707275 | O1: =1-N1 -> 0.6292725 | Q1: Year | R1: Budget
A2: JAN | B2: =GETPIVOTDATA(""&B$1,Control!$A$20,"Month",""&$A2) -> 0.9 | C2: =IF(ROW()>$F$2,B2,NA()) -> #N/A | D2: =GETPIVOTDATA(""&D$1,Control!$A$20,"Month",""&$A2) -> 1 | E2: =IF((ROW()-1)=$F$2,B2,NA()) -> #N/A | F2: =GETPIVOTDATA("Max of Num Month",Control!$A$3) -> 9 | G2: R1 | H2: =GETPIVOTDATA(""&G2,Control!$A$3) -> 0.15 | I2: Planning | J2: P | K2: =GETPIVOTDATA(""&I2,Control!$A$3) -> 2413 | M2: Budget | N2: Cost | P2: =ISNUMBER(MATCH(Q2,Control!$A$36:$A$39,0)) -> TRUE | Q2: 2025 | R2: 400000
A3: FEB | B3: =GETPIVOTDATA(""&B$1,Control!$A$20,"Month",""&A3) -> 0.7 | C3: =IF(ROW()>$F$2,B3,NA()) -> #N/A | D3: =GETPIVOTDATA(""&D$1,Control!$A$20,"Month",""&$A3) -> 0.95 | E3: =IF((ROW()-1)=$F$2,B3,NA()) -> #N/A | G3: R2 | H3: =GETPIVOTDATA(""&G3,Control!$A$3) -> 0.74 | I3: Design | J3: D | K3: =GETPIVOTDATA(""&I3,Control!$A$3) -> 3819 | M3: {=SUM(R2:R4*P2:P4)} -> 400000 | N3: =0-SUM(C17:INDEX(C17:C28,F2)) -> -251709 | P3: =ISNUMBER(MATCH(Q3,Control!$A$36:$A$39,0)) -> FALSE | Q3: 2026 | R3: 450000
A4: MAR | B4: =GETPIVOTDATA(""&B$1,Control!$A$20,"Month",""&A4) -> 0.8 | C4: =IF(ROW()>$F$2,B4,NA()) -> #N/A | D4: =GETPIVOTDATA(""&D$1,Control!$A$20,"Month",""&$A4) -> 0.9 | E4: =IF((ROW()-1)=$F$2,B4,NA()) -> #N/A | G4: R3 | H4: =GETPIVOTDATA(""&G4,Control!$A$3) -> 0.72 | I4: Coding | J4: I | K4: =GETPIVOTDATA(""&I4,Control!$A$3) -> 4950 | P4: =ISNUMBER(MATCH(Q4,Control!$A$36:$A$39,0)) -> FALSE | Q4: 2027 | R4: 380000
A5: APR | B5: =GETPIVOTDATA(""&B$1,Control!$A$20,"Month",""&A5) -> 0.55 | C5: =IF(ROW()>$F$2,B5,NA()) -> #N/A | D5: =GETPIVOTDATA(""&D$1,Control!$A$20,"Month",""&$A5) -> 0.85 | E5: =IF((ROW()-1)=$F$2,B5,NA()) -> #N/A | G5: R4 | H5: =GETPIVOTDATA(""&G5,Control!$A$3) -> 0.41 | I5: Testing | J5: P | K5: =GETPIVOTDATA(""&I5,Control!$A$3) -> 2520 | M5: Days | O5: Time Remaining
A6: MAY | B6: =GETPIVOTDATA(""&B$1,Control!$A$20,"Month",""&A6) -> 0.45 | C6: =IF(ROW()>$F$2,B6,NA()) -> #N/A | D6: =GETPIVOTDATA(""&D$1,Control!$A$20,"Month",""&$A6) -> 0.8 | E6: =IF((ROW()-1)=$F$2,B6,NA()) -> #N/A | G6: R5 | H6: =GETPIVOTDATA(""&G6,Control!$A$3) -> 0.82 | I6: Release | J6: R | K6: =GETPIVOTDATA(""&I6,Control!$A$3) -> 2118 | M6: =GETPIVOTDATA("Sum of Days",Control!$A$20)-SUM(Control!$E$21:INDEX(Control!E21:E32,F2)) -> 92 | N6: =1-O6 -> 0.74794521 | O6: =M6/GETPIVOTDATA("Sum of Days",Control!$A$20) -> 0.25205479
A7: JUN | B7: =GETPIVOTDATA(""&B$1,Control!$A$20,"Month",""&A7) -> 0.5 | C7: =IF(ROW()>$F$2,B7,NA()) -> #N/A | D7: =GETPIVOTDATA(""&D$1,Control!$A$20,"Month",""&$A7) -> 0.7 | E7: =IF((ROW()-1)=$F$2,B7,NA()) -> #N/A | G7: Probability of Risk
A8: JUL | B8: =GETPIVOTDATA(""&B$1,Control!$A$20,"Month",""&A8) -> 0.3 | C8: =IF(ROW()>$F$2,B8,NA()) -> #N/A | D8: =GETPIVOTDATA(""&D$1,Control!$A$20,"Month",""&$A8) -> 0.6 | E8: =IF((ROW()-1)=$F$2,B8,NA()) -> #N/A | G8: back | H8: HR | I8: HR Team Activity | M8: Scope of Work | O8: Label
A9: AUG | B9: =GETPIVOTDATA(""&B$1,Control!$A$20,"Month",""&A9) -> 0.35 | C9: =IF(ROW()>$F$2,B9,NA()) -> #N/A | D9: =GETPIVOTDATA(""&D$1,Control!$A$20,"Month",""&$A9) -> 0.5 | E9: =IF((ROW()-1)=$F$2,B9,NA()) -> #N/A | G9: 1 | H9: =ROUND(GETPIVOTDATA(""&J9,Control!$A$3),0)/10 -> 0.3 | I9: P | J9: Team P | M9: Tasks Completed | N9: tasks | O9: =M10&"/"&N10 -> 80/220
A10: SEP | B10: =GETPIVOTDATA(""&B$1,Control!$A$20,"Month",""&A10) -> 0.2 | C10: =IF(ROW()>$F$2,B10,NA()) -> 0.2 | D10: =GETPIVOTDATA(""&D$1,Control!$A$20,"Month",""&$A10) -> 0.4 | E10: =IF((ROW()-1)=$F$2,B10,NA()) -> 0.2 | G10: 1 | H10: =ROUND(GETPIVOTDATA(""&J10,Control!$A$3),0)/10 -> 0.3 | I10: D | J10: Team D | M10: =N10-SUM(Control!$F$21:INDEX(Control!F21:F32,F2)) -> 80 | N10: =GETPIVOTDATA("Sum of Tasks",Control!$A$20) -> 220
A11: OCT | B11: =GETPIVOTDATA(""&B$1,Control!$A$20,"Month",""&A11) -> 0.25 | C11: =IF(ROW()>$F$2,B11,NA()) -> 0.25 | D11: =GETPIVOTDATA(""&D$1,Control!$A$20,"Month",""&$A11) -> 0.3 | E11: =IF((ROW()-1)=$F$2,B11,NA()) -> #N/A | G11: 1 | H11: =ROUND(GETPIVOTDATA(""&J11,Control!$A$3),0)/10 -> 1 | I11: С | J11: Team С | M11: =1-N11 -> 0.63636364 | N11: =M10/N10 -> 0.36363636
A12: NOV | B12: =GETPIVOTDATA(""&B$1,Control!$A$20,"Month",""&A12) -> 0.15 | C12: =IF(ROW()>$F$2,B12,NA()) -> 0.15 | D12: =GETPIVOTDATA(""&D$1,Control!$A$20,"Month",""&$A12) -> 0.2 | E12: =IF((ROW()-1)=$F$2,B12,NA()) -> #N/A | G12: 1 | H12: =ROUND(GETPIVOTDATA(""&J12,Control!$A$3),0)/10 -> 0.3 | I12: P | J12: Team P
A13: DEC | B13: =GETPIVOTDATA(""&B$1,Control!$A$20,"Month",""&A13) -> 0.2 | C13: =IF(ROW()>$F$2,B13,NA()) -> 0.2 | D13: =GETPIVOTDATA(""&D$1,Control!$A$20,"Month",""&$A13) -> 0.1 | E13: =IF((ROW()-1)=$F$2,B13,NA()) -> #N/A | G13: 1 | H13: =ROUND(GETPIVOTDATA(""&J13,Control!$A$3),0)/10 -> 0.4 | I13: R | J13: Team R
A14: Burndown Chart | E14: 0.3 | H14: =AVERAGE(H9:H13) -> 0.46
J15: Sprint Cycle | Q15: Plan Months
A16: Month | B16: indent | C16: Cost | D16: indent C | E16: Cursor | F16: marker | G16: label | I16: Sprint | J16: Cursor | K16: back | L16: front1 | M16: front2 | N16: front3 | Q16: 3 | R16: =MIN(1,MAX(0,(F$2-SUM(Q$16:Q16)+Q16)/Q16)) -> 1 | S16: Planning
A17: JAN | B17: =$B$29 -> 2312.85 | C17: =GETPIVOTDATA("Sum of Cost",Control!$A$20,"Month",""&A17) -> 17063 | D17: =B17 -> 2312.85 | E17: =IFERROR(GETPIVOTDATA("Sum of Cost",Control!$A$3,"Month",""&A17),NA()) -> #N/A | F17: =B17+E17 -> #N/A | G17: =IF(E17>=1000,TEXT(ROUND(E17/1000,0),"0")&"k",E17) -> #N/A | I17: 10 | J17: =F2 -> 9 | K17: 10 | L17: =CHOOSE($J$17,10,10,0,0,0,0,0,0,0,0,0,0) -> 0 | M17: =CHOOSE($J$17,10,0,0,0,0,0,0,0,0,0,0,0) -> 0 | N17: =CHOOSE($J$17,10,0,0,0,0,0,0,0,0,0,0,0) -> 0 | Q17: 2 | R17: =MIN(1,MAX(0,(F$2-SUM(Q$16:Q17)+Q17)/Q17)) -> 1 | S17: Design | T17: =IF($F$2>3,S17,"") -> Design | V17: =$F$2>Q17 -> TRUE
A18: FEB | B18: =$B$29 -> 2312.85 | C18: =GETPIVOTDATA("Sum of Cost",Control!$A$20,"Month",""&A18) -> 19009 | D18: =B18 -> 2312.85 | E18: =IFERROR(GETPIVOTDATA("Sum of Cost",Control!$A$3,"Month",""&A18),NA()) -> #N/A | F18: =B18+E18 -> #N/A | G18: =IF(E18>=1000,TEXT(ROUND(E18/1000,0),"0")&"k",E18) -> #N/A | I18: 10 | J18: =80-SUM(J19:J20) -> 10 | K18: 10 | L18: =CHOOSE($J$17,0,10,0,0,0,0,0,0,0,0,0,0) -> 0 | M18: =CHOOSE($J$17,10,10,10,10,10,10,10,10,10,0,0,0) -> 10 | N18: =CHOOSE($J$17,0,10,0,0,0,0,0,0,0,0,0,0) -> 0 | Q18: 4 | R18: =MIN(1,MAX(0,(F$2-SUM(Q$16:Q18)+Q18)/Q18)) -> 1 | S18: Coding | T18: =IF($F$2>5,S18,"") -> Coding
A19: MAR | B19: =$B$29 -> 2312.85 | C19: =GETPIVOTDATA("Sum of Cost",Control!$A$20,"Month",""&A19) -> 21172 | D19: =B19 -> 2312.85 | E19: =IFERROR(GETPIVOTDATA("Sum of Cost",Control!$A$3,"Month",""&A19),NA()) -> #N/A | F19: =B19+E19 -> #N/A | G19: =IF(E19>=1000,TEXT(ROUND(E19/1000,0),"0")&"k",E19) -> #N/A | I19: 10 | J19: =CHOOSE(J17,0,0,10,10,10,10,10,10,10,10,0,0) -> 10 | K19: 10 | L19: =CHOOSE($J$17,0,0,0,0,0,0,0,0,0,0,10,0) -> 0 | M19: =CHOOSE($J$17,0,0,0,0,0,0,0,0,0,10,10,10) -> 0 | N19: =CHOOSE($J$17,0,0,0,0,0,0,0,0,0,0,10,0) -> 0 | Q19: 2 | R19: =MIN(1,MAX(0,(F$2-SUM(Q$16:Q19)+Q19)/Q19)) -> 0 | S19: Testing | T19: =IF($F$2>9,S19,"")
A20: APR | B20: =$B$29 -> 2312.85 | C20: =GETPIVOTDATA("Sum of Cost",Control!$A$20,"Month",""&A20) -> 25512 | D20: =B20 -> 2312.85 | E20: =IFERROR(GETPIVOTDATA("Sum of Cost",Control!$A$3,"Month",""&A20),NA()) -> #N/A | F20: =B20+E20 -> #N/A | G20: =IF(E20>=1000,TEXT(ROUND(E20/1000,0),"0")&"k",E20) -> #N/A | I20: 10 | J20: =CHOOSE(J17,0,0,0,10,20,30,40,50,60,70,0,0) -> 60 | K20: 10 | L20: =CHOOSE($J$17,0,0,0,0,0,0,0,0,0,0,0,0) -> 0 | M20: =CHOOSE($J$17,0,0,0,0,0,0,0,0,0,0,0,0) -> 0 | N20: =CHOOSE($J$17,0,0,0,0,0,0,0,0,0,0,0,10) -> 0 | Q20: 1 | R20: =MIN(1,MAX(0,(F$2-SUM(Q$16:Q20)+Q20)/Q20)) -> 0 | S20: Release | T20: =IF($F$2=12,S20,"")
A21: MAY | B21: =$B$29 -> 2312.85 | C21: =GETPIVOTDATA("Sum of Cost",Control!$A$20,"Month",""&A21) -> 22609 | D21: =B21 -> 2312.85 | E21: =IFERROR(GETPIVOTDATA("Sum of Cost",Control!$A$3,"Month",""&A21),NA()) -> #N/A | F21: =B21+E21 -> #N/A | G21: =IF(E21>=1000,TEXT(ROUND(E21/1000,0),"0")&"k",E21) -> #N/A | I21: 10 | J21: {=INDEX(I2:I6,CHOOSE(J17,1,1,1,2,2,3,3,3,3,4,4,5))} -> Coding
A22: JUN | B22: =$B$29 -> 2312.85 | C22: =GETPIVOTDATA("Sum of Cost",Control!$A$20,"Month",""&A22) -> 30077 | D22: =B22 -> 2312.85 | E22: =IFERROR(GETPIVOTDATA("Sum of Cost",Control!$A$3,"Month",""&A22),NA()) -> #N/A | F22: =B22+E22 -> #N/A | G22: =IF(E22>=1000,TEXT(ROUND(E22/1000,0),"0")&"k",E22) -> #N/A | I22: 10 | J22: =F2/12 -> 0.75 | S22: =S16&CHAR(10)&S17&CHAR(10)&S18&CHAR(10)&S19&CHAR(10)&S20 -> Planning Design Coding Testing Release
A23: JUL | B23: =$B$29 -> 2312.85 | C23: =GETPIVOTDATA("Sum of Cost",Control!$A$20,"Month",""&A23) -> 35634 | D23: =B23 -> 2312.85 | E23: =IFERROR(GETPIVOTDATA("Sum of Cost",Control!$A$3,"Month",""&A23),NA()) -> #N/A | F23: =B23+E23 -> #N/A | G23: =IF(E23>=1000,TEXT(ROUND(E23/1000,0),"0")&"k",E23) -> #N/A | I23: 10 | J23: Progress Made: | S23: =TEXT(R16,"0%")&CHAR(10)&TEXT(R17,"0%")&CHAR(10)&TEXT(R18,"0%")&CHAR(10)&TEXT(R19,"0%")&CHAR(10)&TEXT(R20,"0%") -> 100% 100% 100% 0% 0%
A24: AUG | B24: =$B$29 -> 2312.85 | C24: =GETPIVOTDATA("Sum of Cost",Control!$A$20,"Month",""&A24) -> 46257 | D24: =B24 -> 2312.85 | E24: =IFERROR(GETPIVOTDATA("Sum of Cost",Control!$A$3,"Month",""&A24),NA()) -> #N/A | F24: =B24+E24 -> #N/A | G24: =IF(E24>=1000,TEXT(ROUND(E24/1000,0),"0")&"k",E24) -> #N/A | I24: 10
A25: SEP | B25: =$B$29 -> 2312.85 | C25: =GETPIVOTDATA("Sum of Cost",Control!$A$20,"Month",""&A25) -> 34376 | D25: =B25 -> 2312.85 | E25: =IFERROR(GETPIVOTDATA("Sum of Cost",Control!$A$3,"Month",""&A25),NA()) -> 34376 | F25: =B25+E25 -> 36688.85 | G25: =IF(E25>=1000,TEXT(ROUND(E25/1000,0),"0")&"k",E25) -> 34k | I25: 10 | J25: Prototype 1 | K25: =P2*10 -> 10 | L25: =IF(P2,J25,"") -> Prototype 1
A26: OCT | B26: =$B$29 -> 2312.85 | C26: =GETPIVOTDATA("Sum of Cost",Control!$A$20,"Month",""&A26) -> 36744 | D26: =B26 -> 2312.85 | E26: =IFERROR(GETPIVOTDATA("Sum of Cost",Control!$A$3,"Month",""&A26),NA()) -> #N/A | F26: =B26+E26 -> #N/A | G26: =IF(E26>=1000,TEXT(ROUND(E26/1000,0),"0")&"k",E26) -> #N/A | I26: 10 | J26: Prototype 2 | K26: =P3*10 -> 0 | L26: =IF(P3,J26,"")
A27: NOV | B27: =$B$29 -> 2312.85 | C27: =GETPIVOTDATA("Sum of Cost",Control!$A$20,"Month",""&A27) -> 44019 | D27: =B27 -> 2312.85 | E27: =IFERROR(GETPIVOTDATA("Sum of Cost",Control!$A$3,"Month",""&A27),NA()) -> #N/A | F27: =B27+E27 -> #N/A | G27: =IF(E27>=1000,TEXT(ROUND(E27/1000,0),"0")&"k",E27) -> #N/A | I27: 10 | J27: Prototype 3 | K27: =P4*10 -> 0 | L27: =IF(P4,J27,"")
A28: DEC | B28: =$B$29 -> 2312.85 | C28: =GETPIVOTDATA("Sum of Cost",Control!$A$20,"Month",""&A28) -> 45080 | D28: =B28 -> 2312.85 | E28: =IFERROR(GETPIVOTDATA("Sum of Cost",Control!$A$3,"Month",""&A28),NA()) -> #N/A | F28: =B28+E28 -> #N/A | G28: =IF(E28>=1000,TEXT(ROUND(E28/1000,0),"0")&"k",E28) -> #N/A | I28: 10
B29: =MAX(C17:C28)*5% -> 2312.85
A30: Monthly Expenses

Sheet Control
A3: Row Labels | B3: Max of Num Month | C3: Average of Actual | D3: Average of Target | E3: Sum of Cost | F3: Average of R1 | G3: Average of R2 | H3: Average of R3 | I3: Average of R4 | J3: Average of R5 | K3: Average of Team P | L3: Average of Team D | M3: Sum of Team С | N3: Average of Team T | O3: Average of Team R | P3: Sum of Planning | Q3: Sum of Design | R3: Sum of Coding | S3: Sum of Testing | T3: Sum of Release
A4: SEP | B4: 9 | C4: 0.2 | D4: 0.4 | E4: 34376 | F4: 0.15 | G4: 0.74 | H4: 0.72 | I4: 0.41 | J4: 0.82 | K4: 3 | L4: 3 | M4: 10 | N4: 3 | O4: 4 | P4: 2413 | Q4: 3819 | R4: 4950 | S4: 2520 | T4: 2118
A5: Grand Total | B5: 9 | C5: 0.2 | D5: 0.4 | E5: 34376 | F5: 0.15 | G5: 0.74 | H5: 0.72 | I5: 0.41 | J5: 0.82 | K5: 3 | L5: 3 | M5: 10 | N5: 3 | O5: 4 | P5: 2413 | Q5: 3819 | R5: 4950 | S5: 2520 | T5: 2118
A20: Row Labels | B20: Average of Actual | C20: Average of Target | D20: Sum of Cost | E20: Sum of Days | F20: Sum of Tasks
A21: JAN | B21: 0.9 | C21: 1 | D21: 17063 | E21: 31 | F21: 10
A22: FEB | B22: 0.7 | C22: 0.95 | D22: 19009 | E22: 28 | F22: 11
A23: MAR | B23: 0.8 | C23: 0.9 | D23: 21172 | E23: 31 | F23: 12
A24: APR | B24: 0.55 | C24: 0.85 | D24: 25512 | E24: 30 | F24: 13
A25: MAY | B25: 0.45 | C25: 0.8 | D25: 22609 | E25: 31 | F25: 14
A26: JUN | B26: 0.5 | C26: 0.7 | D26: 30077 | E26: 30 | F26: 17
A27: JUL | B27: 0.3 | C27: 0.6 | D27: 35634 | E27: 31 | F27: 20
A28: AUG | B28: 0.35 | C28: 0.5 | D28: 46257 | E28: 31 | F28: 21
A29: SEP | B29: 0.2 | C29: 0.4 | D29: 34376 | E29: 30 | F29: 22
A30: OCT | B30: 0.25 | C30: 0.3 | D30: 36744 | E30: 31 | F30: 25
A31: NOV | B31: 0.15 | C31: 0.2 | D31: 44019 | E31: 30 | F31: 26
A32: DEC | B32: 0.2 | C32: 0.1 | D32: 45080 | E32: 31 | F32: 29
A33: Grand Total | B33: 0.44583333 | C33: 0.60833333 | D33: 377552 | E33: 365 | F33: 220
A35: Row Labels
A36: 2025
A37: Grand Total

Sheet Data
A1: Year | B1: Num Month | C1: Month | D1: Actual | E1: Target | F1: R1 | G1: R2 | H1: R3 | I1: R4 | J1: R5 | K1: Planning | L1: Design | M1: Coding | N1: Testing | O1: Release | P1: Cost | Q1: Team P | R1: Team D | S1: Team С | T1: Team T | U1: Team R | V1: Days | W1: Tasks
A2: 2025 | B2: 1 | C2: JAN | D2: 0.9 | E2: 1 | F2: 0.81 | G2: 0.71 | H2: 0.19 | I2: 0.27 | J2: 0.81 | K2: 4710 | L2: 2819 | M2: 1351 | N2: 3237 | O2: 4625 | P2: 17063 | Q2: 7 | R2: 3 | S2: 5 | T2: 3 | U2: 2 | V2: 31 | W2: 10
A3: 2025 | B3: 2 | C3: FEB | D3: 0.7 | E3: 0.95 | F3: 0.54 | G3: 0.33 | H3: 0.74 | I3: 0.33 | J3: 0.32 | K3: 3343 | L3: 3507 | M3: 2665 | N3: 2445 | O3: 3408 | P3: 19009 | Q3: 8 | R3: 4 | S3: 6 | T3: 4 | U3: 3 | V3: 28 | W3: 11
A4: 2025 | B4: 3 | C4: MAR | D4: 0.8 | E4: 0.9 | F4: 0.85 | G4: 0.27 | H4: 0.85 | I4: 0.15 | J4: 0.5 | K4: 3189 | L4: 1605 | M4: 2950 | N4: 4128 | O4: 3170 | P4: 21172 | Q4: 9 | R4: 5 | S4: 5 | T4: 5 | U4: 2 | V4: 31 | W4: 12
A5: 2025 | B5: 4 | C5: APR | D5: 0.55 | E5: 0.85 | F5: 0.77 | G5: 0.17 | H5: 0.66 | I5: 0.24 | J5: 0.53 | K5: 2214 | L5: 2326 | M5: 3801 | N5: 3693 | O5: 2247 | P5: 25512 | Q5: 3 | R5: 6 | S5: 7 | T5: 4 | U5: 4 | V5: 30 | W5: 13
A6: 2025 | B6: 5 | C6: MAY | D6: 0.45 | E6: 0.8 | F6: 0.27 | G6: 0.49 | H6: 0.85 | I6: 0.15 | J6: 0.35 | K6: 2462 | L6: 2525 | M6: 3557 | N6: 3504 | O6: 2614 | P6: 22609 | Q6: 2 | R6: 7 | S6: 8 | T6: 3 | U6: 5 | V6: 31 | W6: 14
A7: 2025 | B7: 6 | C7: JUN | D7: 0.5 | E7: 0.7 | F7: 0.21 | G7: 0.15 | H7: 0.36 | I7: 0.57 | J7: 0.85 | K7: 3020 | L7: 3563 | M7: 3412 | N7: 2560 | O7: 2343 | P7: 30077 | Q7: 3 | R7: 5 | S7: 9 | T7: 5 | U7: 4 | V7: 30 | W7: 17
A8: 2025 | B8: 7 | C8: JUL | D8: 0.3 | E8: 0.6 | F8: 0.42 | G8: 0.5 | H8: 0.55 | I8: 0.67 | J8: 0.84 | K8: 3567 | L8: 4435 | M8: 3607 | N8: 1711 | O8: 1999 | P8: 35634 | Q8: 4 | R8: 3 | S8: 8 | T8: 6 | U8: 2 | V8: 31 | W8: 20
A9: 2025 | B9: 8 | C9: AUG | D9: 0.35 | E9: 0.5 | F9: 0.71 | G9: 0.15 | H9: 0.64 | I9: 0.55 | J9: 0.85 | K9: 3361 | L9: 4717 | M9: 4369 | N9: 1706 | O9: 1992 | P9: 46257 | Q9: 2 | R9: 2 | S9: 9 | T9: 4 | U9: 3 | V9: 31 | W9: 21
A10: 2025 | B10: 9 | C10: SEP | D10: 0.2 | E10: 0.4 | F10: 0.15 | G10: 0.74 | H10: 0.72 | I10: 0.41 | J10: 0.82 | K10: 2413 | L10: 3819 | M10: 4950 | N10: 2520 | O10: 2118 | P10: 34376 | Q10: 3 | R10: 3 | S10: 10 | T10: 3 | U10: 4 | V10: 30 | W10: 22
A11: 2025 | B11: 10 | C11: OCT | D11: 0.25 | E11: 0.3 | F11: 0.15 | G11: 0.76 | H11: 0.19 | I11: 0.41 | J11: 0.66 | K11: 1932 | L11: 2691 | M11: 4714 | N11: 3824 | O11: 2705 | P11: 36744 | Q11: 4 | R11: 4 | S11: 7 | T11: 5 | U11: 5 | V11: 31 | W11: 25
A12: 2025 | B12: 11 | C12: NOV | D12: 0.15 | E12: 0.2 | F12: 0.25 | G12: 0.15 | H12: 0.18 | I12: 0.66 | J12: 0.66 | K12: 2016 | L12: 2140 | M12: 3728 | N12: 4397 | O12: 3289 | P12: 44019 | Q12: 3 | R12: 3 | S12: 8 | T12: 6 | U12: 6 | V12: 30 | W12: 26
A13: 2025 | B13: 12 | C13: DEC | D13: 0.2 | E13: 0.1 | F13: 0.74 | G13: 0.85 | H13: 0.58 | I13: 0.25 | J13: 0.41 | K13: 2658 | L13: 2030 | M13: 2460 | N13: 4042 | O13: 3984 | P13: 45080 | Q13: 2 | R13: 5 | S13: 5 | T13: 7 | U13: 7 | V13: 31 | W13: 29
... A37: 2027 | B37: 12 | C37: DEC | D37: 0.23 | E37: 0.07 | F37: 0.71 | G37: 0.81 | H37: 0.61 | I37: 0.36 | J37: 0.68 | K37: 2353 | L37: 3140 | M37: 2965 | N37: 3730 | O37: 3590 | P37: 44210 | Q37: 3 | R37: 6 | S37: 6 | T37: 8 | U37: 8 | V37: 31 | W37: 65

Sheet Resources
F1: [>=1000]0,"k";[<=-1000]-0,"k";0
