Workbook
Name bigdata: 'Structuring Data'!$A$1:$BB$399
Name Slicer_Day1: #N/A
Name Slicer_Month1: #N/A

Sheet DASHBOARD

Sheet DASHBOARD Light

Sheet Budgeting

Sheet Budgeting Light

Sheet Income

Sheet Income Light

Sheet Expenses

Sheet Expenses Light

Sheet Investments

Sheet Investments Light

Sheet Debts

Sheet Debts Light
G51: https://exceltable.com/en/templates/download-personal-finances-template

Sheet Financial Goals
G51: https://exceltable.com/en/templates/download-personal-finances-template
H53: https://exceltable.com/en/templates/download-personal-finances-template

Sheet Financial Goals Light

Sheet Processing
A1: Dashboard | B1: Year | C1: ='Structuring Data'!C2 -> 2024 | D1: Month | E1: =Control!B2 -> 6 | F1: Calendar | G1: Today: | H1: {="Today: "&DAY(I1)&" "&INDEX(B4:B15,MONTH(I1))&" "&YEAR(I1)} -> Today: 18 SEPTEMBER 2026 | I1: =TODAY() -> 46283 | K1: Balance: | L1: {=SUM(Data!$BN$2:$BN$367*(--(Data!$A$2:$A$367=DATE(Processing!$C$1,Processing!$E$1,MAX($L$26:$L$56)))))} -> 714 | N1: Budget Plan | Q1: Labels | R1: Pie Chart | S1: Budgeting
A2: =C3&" & "&D3 -> Income & Expenses | E2: {=INDEX($B$4:$B$15,E1)} -> JUNE | F2: Personal Finance | H2: Ratio Income | N2: Non-Fixed Incom | O2: =P2/($P$8+$P$9) -> 0.20678704 | P2: =GETPIVOTDATA(""&N2,Control!$A$7) -> 11590 | R2: =$O$2 -> 0.20678704 | S2: =$O$3 -> 0.26768127 | T2: =$O$4 -> 0.082393663 | U2: =$O$5 -> 0.16114759 | V2: =$O$6 -> 0.21544034 | W2: =$O$7 -> 0.0665501
A3: № | B3: Month | C3: Income | D3: Expenses | E3: Income | F3: Expenses | H3: Income | I3: Expenses | N3: Fixed Incom | O3: =P3/($P$8+$P$9) -> 0.26768127 | P3: =GETPIVOTDATA(""&N3,Control!$A$7) -> 15003 | Q3: =P8 -> 31211 | R3: =$O$2 -> 0.20678704 | S3: =$O$3 -> 0.26768127 | T3: =$O$4 -> 0.082393663 | U3: =$O$5 -> 0.16114759 | V3: =$O$6 -> 0.21544034 | W3: =$O$7 -> 0.0665501
A4: 1 | B4: JANUARY | C4: =SUMIF('Structuring Data'!$D$2:$D$399,B4,'Structuring Data'!$F$2:$F$399) -> 18166 | D4: =SUMIF('Structuring Data'!$D$2:$D$399,B4,'Structuring Data'!$G$2:$G$399) -> 20397 | E4: =C4/SUM(C4:D4) -> 0.47107331 | F4: =D4/SUM(C4:D4) -> 0.52892669 | H4: {=INDEX(E4:E15,$E$1)} -> 0.55686198 | I4: {=INDEX(F4:F15,$E$1)} -> 0.44313802 | N4: Other Income | O4: =P4/($P$8+$P$9) -> 0.082393663 | P4: =GETPIVOTDATA(""&N4,Control!$A$7) -> 4618 | Q4: =N2&CHAR(10)&N3&CHAR(10)&N4&CHAR(10)&CHAR(10)&CHAR(10)&CHAR(10)&N5&CHAR(10)&N6&CHAR(10)&N7 -> Non-Fixed Incom Fixed Incom Other Income Non-Fixed Cost Fixed Costs Other Cost | R4: =$O$2 -> 0.20678704 | S4: =$O$3 -> 0.26768127 | T4: =$O$4 -> 0.082393663 | U4: =$O$5 -> 0.16114759 | V4: =$O$6 -> 0.21544034 | W4: =$O$7 -> 0.0665501
A5: 2 | B5: FEBRUARY | C5: =SUMIF('Structuring Data'!$D$2:$D$399,B5,'Structuring Data'!$F$2:$F$399) -> 19801 | D5: =SUMIF('Structuring Data'!$D$2:$D$399,B5,'Structuring Data'!$G$2:$G$399) -> 26548 | E5: =C5/SUM(C5:D5) -> 0.42721526 | F5: =D5/SUM(C5:D5) -> 0.57278474 | N5: Non-Fixed Cost | O5: =P5/($P$8+$P$9) -> 0.16114759 | P5: =GETPIVOTDATA(""&N5,Control!$A$7) -> 9032 | Q5: =TEXT(O2,"0%")&CHAR(10)&TEXT(O3,"0%")&CHAR(10)&TEXT(O4,"0%")&CHAR(10)&CHAR(10)&CHAR(10)&CHAR(10)&TEXT(O5,"0%")&CHAR(10)&TEXT(O6,"0%")&CHAR(10)&TEXT(O7,"0%") -> 21% 27% 8% 16% 22% 7%
A6: 3 | B6: MARCH | C6: =SUMIF('Structuring Data'!$D$2:$D$399,B6,'Structuring Data'!$F$2:$F$399) -> 22196 | D6: =SUMIF('Structuring Data'!$D$2:$D$399,B6,'Structuring Data'!$G$2:$G$399) -> 22099 | E6: =C6/SUM(C6:D6) -> 0.50109493 | F6: =D6/SUM(C6:D6) -> 0.49890507 | H6: Cursors | N6: Fixed Costs | O6: =P6/($P$8+$P$9) -> 0.21544034 | P6: =GETPIVOTDATA(""&N6,Control!$A$7) -> 12075 | Q6: =TEXT(P2,"$ 0 0")&CHAR(10)&TEXT(P3,"$ 0 0")&CHAR(10)&TEXT(P4,"$ 0 0")&CHAR(10)&CHAR(10)&CHAR(10)&CHAR(10)&TEXT(P5,"$ 0 0")&CHAR(10)&TEXT(P6,"$ 0 0")&CHAR(10)&TEXT($P7,"$ 0 0") -> $ 11 590 $ 15 003 $ 4 618 $ 9 032 $ 12 075 $ 3 730
A7: 4 | B7: APRIL | C7: =SUMIF('Structuring Data'!$D$2:$D$399,B7,'Structuring Data'!$F$2:$F$399) -> 25558 | D7: =SUMIF('Structuring Data'!$D$2:$D$399,B7,'Structuring Data'!$G$2:$G$399) -> 19614 | E7: =C7/SUM(C7:D7) -> 0.56579297 | F7: =D7/SUM(C7:D7) -> 0.43420703 | H7: X | I7: Y | K7: X | L7: Y | N7: Other Cost | O7: =P7/($P$8+$P$9) -> 0.0665501 | P7: =GETPIVOTDATA(""&N7,Control!$A$7) -> 3730 | Q7: Used Budget
A8: 5 | B8: MAY | C8: =SUMIF('Structuring Data'!$D$2:$D$399,B8,'Structuring Data'!$F$2:$F$399) -> 31043 | D8: =SUMIF('Structuring Data'!$D$2:$D$399,B8,'Structuring Data'!$G$2:$G$399) -> 24519 | E8: =C8/SUM(C8:D8) -> 0.55870919 | F8: =D8/SUM(C8:D8) -> 0.44129081 | G8: Income | H8: =E1 -> 6 | I8: {=INDEX(C4:C15,$E$1)} -> 31211 | K8: 0 | L8: 1 | N8: Total Incom | O8: =O2+O3+O4 -> 0.55686198 | P8: =P2+P3+P4 -> 31211 | Q8: =J58 -> 0.79577713 | R8: =1-Q8 -> 0.20422287
A9: 6 | B9: JUNE | C9: =SUMIF('Structuring Data'!$D$2:$D$399,B9,'Structuring Data'!$F$2:$F$399) -> 31211 | D9: =SUMIF('Structuring Data'!$D$2:$D$399,B9,'Structuring Data'!$G$2:$G$399) -> 24837 | E9: =C9/SUM(C9:D9) -> 0.55686198 | F9: =D9/SUM(C9:D9) -> 0.44313802 | G9: Expenses | H9: =E1 -> 6 | I9: {=INDEX(D4:D15,$E$1)} -> 24837 | K9: =SIN(H4*2*PI()) -> -0.34972198 | L9: =COS(I4*2*PI()) -> -0.93685353 | N9: Total Expenses | O9: =O5+O6+O7 -> 0.44313802 | P9: =P5+P6+P7 -> 24837
A10: 7 | B10: JULY | C10: =SUMIF('Structuring Data'!$D$2:$D$399,B10,'Structuring Data'!$F$2:$F$399) -> 30268 | D10: =SUMIF('Structuring Data'!$D$2:$D$399,B10,'Structuring Data'!$G$2:$G$399) -> 21183 | E10: =C10/SUM(C10:D10) -> 0.58828789 | F10: =D10/SUM(C10:D10) -> 0.41171211
A11: 8 | B11: AUGUST | C11: =SUMIF('Structuring Data'!$D$2:$D$399,B11,'Structuring Data'!$F$2:$F$399) -> 35419 | D11: =SUMIF('Structuring Data'!$D$2:$D$399,B11,'Structuring Data'!$G$2:$G$399) -> 22263 | E11: =C11/SUM(C11:D11) -> 0.61403904 | F11: =D11/SUM(C11:D11) -> 0.38596096
A12: 9 | B12: SEPTEMBER | C12: =SUMIF('Structuring Data'!$D$2:$D$399,B12,'Structuring Data'!$F$2:$F$399) -> 35296 | D12: =SUMIF('Structuring Data'!$D$2:$D$399,B12,'Structuring Data'!$G$2:$G$399) -> 25507 | E12: =C12/SUM(C12:D12) -> 0.58049767 | F12: =D12/SUM(C12:D12) -> 0.41950233 | Q12: Financial Goals
A13: 10 | B13: OCTOBER | C13: =SUMIF('Structuring Data'!$D$2:$D$399,B13,'Structuring Data'!$F$2:$F$399) -> 33397 | D13: =SUMIF('Structuring Data'!$D$2:$D$399,B13,'Structuring Data'!$G$2:$G$399) -> 20455 | E13: =C13/SUM(C13:D13) -> 0.62016267 | F13: =D13/SUM(C13:D13) -> 0.37983733 | R13: Goal Decomposition | T13: label
A14: 11 | B14: NOVEMBER | C14: =SUMIF('Structuring Data'!$D$2:$D$399,B14,'Structuring Data'!$F$2:$F$399) -> 33613 | D14: =SUMIF('Structuring Data'!$D$2:$D$399,B14,'Structuring Data'!$G$2:$G$399) -> 26772 | E14: =C14/SUM(C14:D14) -> 0.55664486 | F14: =D14/SUM(C14:D14) -> 0.44335514 | Q14: 217000 | R14: 0.4425 | T14: =Q14*R15 -> 64665.195
A15: 12 | B15: DECEMBER | C15: =SUMIF('Structuring Data'!$D$2:$D$399,B15,'Structuring Data'!$F$2:$F$399) -> 36231 | D15: =SUMIF('Structuring Data'!$D$2:$D$399,B15,'Structuring Data'!$G$2:$G$399) -> 24419 | E15: =C15/SUM(C15:D15) -> 0.5973784 | F15: =D15/SUM(C15:D15) -> 0.4026216 | Q15: 8 | R15: =AVERAGE(R18:X18) -> 0.29799629 | T15: =X22&CHAR(10)&V22&CHAR(10)&T22&CHAR(10)&R22 -> Goal 1 Goal 2 Goal 3 Goal 4
H16: Investments | I16: =SUM(H17:H21) -> 89000 | Q16: =AVERAGE(AA21:AD21) -> 0.74675325 | T16: =TEXT(W29,"$0 0")&CHAR(10)&TEXT(V29,"$0 0")&CHAR(10)&TEXT(X29,"$0 0")&CHAR(10)&TEXT(Y29,"$0 0") -> $65 000 $77 000 $58 000 $30 000
A17: Debts | B17: Interest Rate | C17: Amount of Debt | E17: Top | G17: Business | H17: {=SUM(Data!$AZ$2:$AZ$367*(--(Data!$A$2:$A$367=DATE(Processing!$C$1,Processing!$E$1,MAX($L$26:$L$56)))))} -> 27590 | I17: =H17/$I$16 -> 0.31 | J17: =$I17 -> 0.31 | K17: =$I17 -> 0.31 | L17: =$I17 -> 0.31 | M17: =$I17 -> 0.31 | Q17: Plan ON | R17: TRUE | AA17: Goal Management
A18: {=INDEX($A$23:$B$26,MATCH($C18,$C$23:$C$26,0),COLUMN())} -> Mortgage | B18: {=INDEX($A$23:$B$26,MATCH($C18,$C$23:$C$26,0),COLUMN())} -> 0.03 | C18: =LARGE($C$23:$C$26,D18) -> 29000 | D18: 1 | E18: =C18/SUM($C$27:$C$28) -> 0.2815534 | G18: Securities | H18: {=SUM(Data!$BA$2:$BA$367*(--(Data!$A$2:$A$367=DATE(Processing!$C$1,Processing!$E$1,MAX($L$26:$L$56)))))} -> 12460 | I18: =H18/$I$16 -> 0.14 | J18: =$I18 -> 0.14 | K18: =$I18 -> 0.14 | L18: =$I18 -> 0.14 | M18: =$I18 -> 0.14 | Q18: =IF(R17,Q16,NA()) -> 0.74675325 | R18: =(1-R20)*Y27/Y29 -> 0.15554545 | S18: =R18 -> 0.15554545 | T18: =(1-T20)*X27/X29 -> 0.27824675 | U18: =T18 -> 0.27824675 | V18: =(1-V20)*W27/W29 -> 0.29564935 | W18: =V18 -> 0.29564935 | X18: =(1-X20)*V27/V29 -> 0.62709091 | Y18: Done | Z18: Finish | AA18: =V29 -> 77000 | AB18: =W29 -> 65000 | AC18: =X29 -> 58000 | AD18: =Y29 -> 30000
A19: {=INDEX($A$23:$B$26,MATCH($C19,$C$23:$C$26,0),COLUMN())} -> Credit Card | B19: {=INDEX($A$23:$B$26,MATCH($C19,$C$23:$C$26,0),COLUMN())} -> 0.095 | C19: =LARGE($C$23:$C$26,D19) -> 17694 | D19: 2 | G19: Gold | H19: {=SUM(Data!$BB$2:$BB$367*(--(Data!$A$2:$A$367=DATE(Processing!$C$1,Processing!$E$1,MAX($L$26:$L$56)))))} -> 22250 | I19: =H19/$I$16 -> 0.25 | J19: =$I19 -> 0.25 | K19: =$I19 -> 0.25 | L19: =$I19 -> 0.25 | M19: =$I19 -> 0.25 | Q19: =IF(R17,1%,NA()) -> 0.01 | R19: =(1-R20)-R18 -> 0.23406494 | S19: =R19 -> 0.23406494 | T19: =(1-T20)-T18 -> 0.475 | U19: =T19 -> 0.475 | V19: =(1-V20)-V18 -> 0.54850649 | W19: =V19 -> 0.54850649 | X19: =(1-X20)-X18 -> 0.37290909 | Y19: Running | Z19: Start | AA19: =V27 -> 48286 | AB19: =W27 -> 22765 | AC19: =X27 -> 21425 | AD19: =Y27 -> 11977
A20: {=INDEX($A$23:$B$26,MATCH($C20,$C$23:$C$26,0),COLUMN())} -> Car Leasing | B20: {=INDEX($A$23:$B$26,MATCH($C20,$C$23:$C$26,0),COLUMN())} -> 0.05 | C20: =LARGE($C$23:$C$26,D20) -> 13750 | D20: 3 | G20: Real estate | H20: {=SUM(Data!$BC$2:$BC$367*(--(Data!$A$2:$A$367=DATE(Processing!$C$1,Processing!$E$1,MAX($L$26:$L$56)))))} -> 13350 | I20: =H20/$I$16 -> 0.15 | J20: =$I20 -> 0.15 | K20: =$I20 -> 0.15 | L20: =$I20 -> 0.15 | M20: =$I20 -> 0.15 | Q20: =1-SUM(Q18:Q19) -> 0.24324675 | R20: =1-Y29/V30 -> 0.61038961 | S20: =R20 -> 0.61038961 | T20: =1-X29/V30 -> 0.24675325 | U20: =T20 -> 0.24675325 | V20: =1-W29/V30 -> 0.15584416 | W20: =V20 -> 0.15584416 | X20: =1-V29/V30 -> 0 | Y20: Reserve | AA20: Goal 1 | AB20: Goal 2 | AC20: Goal 3 | AD20: Goal 4
A21: {=INDEX($A$23:$B$26,MATCH($C21,$C$23:$C$26,0),COLUMN())} -> Consumer Credit | B21: {=INDEX($A$23:$B$26,MATCH($C21,$C$23:$C$26,0),COLUMN())} -> 0.07 | C21: =LARGE($C$23:$C$26,D21) -> 6498 | D21: 4 | G21: Cryptocurrency | H21: {=SUM(Data!$BD$2:$BD$367*(--(Data!$A$2:$A$367=DATE(Processing!$C$1,Processing!$E$1,MAX($L$26:$L$56)))))} -> 13350 | I21: =H21/$I$16 -> 0.15 | J21: =$I21 -> 0.15 | K21: =$I21 -> 0.15 | L21: =$I21 -> 0.15 | M21: =$I21 -> 0.15 | Q21: =IF(R17,R21,NA()) -> 0.34 | R21: 0.34 | S21: =R21 -> 0.34 | T21: 0.34 | U21: =T21 -> 0.34 | V21: 0.34 | W21: =V21 -> 0.34 | X21: 0.34 | AA21: =R18+R19 -> 0.38961039 | AB21: =T18+T19 -> 0.75324675 | AC21: =V18+V19 -> 0.84415584 | AD21: =X18+X19 -> 1
A22: Total Debt Amount | I22: =SUM(I17:I21) -> 1 | J22: =SUM(J17:J21) -> 1 | K22: =SUM(K17:K21) -> 1 | L22: =SUM(L17:L21) -> 1 | M22: =SUM(M17:M21) -> 1 | R22: Goal 4 | T22: Goal 3 | V22: Goal 2 | X22: Goal 1
A23: Mortgage | B23: 0.03 | C23: {=SUM(Data!$BE$2:$BE$367*(--(Data!$A$2:$A$367=DATE(Processing!$C$1,Processing!$E$1,MAX($L$26:$L$56)))))} -> 29000 | D23: =C23/SUM($C$27:$C$28) -> 0.2815534 | S23: =Y28/Y29 -> 0.60076667
A24: Car Leasing | B24: 0.05 | C24: {=SUM(Data!$BF$2:$BF$367*(--(Data!$A$2:$A$367=DATE(Processing!$C$1,Processing!$E$1,MAX($L$26:$L$56)))))} -> 13750 | D24: =C24/SUM($C$27:$C$28) -> 0.13349515 | I24: Income Budget | J24: Expenses Budget | L24: Portfolio Capitalization | O24: {=INDEX(Data!$AY$2:$AY$367,MATCH(TRUE,Data!$AY$2:$AY$367>0,0))} -> 117000 | S24: =Y29/V29 -> 0.38961039 | AH24: Incom by Days
A25: Consumer Credit | B25: 0.07 | C25: {=SUM(Data!$BG$2:$BG$367*(--(Data!$A$2:$A$367=DATE(Processing!$C$1,Processing!$E$1,MAX($L$26:$L$56)))))} -> 6498 | D25: =C25/SUM($C$27:$C$28) -> 0.063087379 | H25: Day | K25: back | L25: Select Days | M25: Days | N25: Price | O25: Start Price | P25: Mirror | Q25: Days | R25: Closing Debts | T25: back | V25: Implementation | Z25: Check List | AA25: Distribution | AG25: Day | AH25: Fixed Incom | AI25: Non-Fixed Incom | AJ25: back | AL25: Day | AM25: Fixed Cost | AN25: Non-Fixed Cost | AO25: back
A26: Credit Card | B26: 0.095 | C26: {=SUM(Data!$BH$2:$BH$367*(--(Data!$A$2:$A$367=DATE(Processing!$C$1,Processing!$E$1,MAX($L$26:$L$56)))))} -> 17694 | D26: =C26/SUM($C$27:$C$28) -> 0.17178641 | F26: JANUARY | G26: =DAY(EOMONTH(DATE($C$1,H26,1),0)) -> 31 | H26: 1 | I26: {=IFERROR(GETPIVOTDATA(""&$N$2,Control!$A$7,""&$H$25,H26)+GETPIVOTDATA(""&$N$3,Control!$A$7,""&$H$25,H26)+GETPIVOTDATA(""&$N$4,Control!$A$7,""&$H$25,H26),NA())} -> 1117 | J26: {=IFERROR(GETPIVOTDATA(""&$N$5,Control!$A$7,""&$H$25,H26)+GETPIVOTDATA(""&$N$6,Control!$A$7,""&$H$25,H26)+GETPIVOTDATA(""&$N$7,Control!$A$7,""&$H$25,H26),NA())} -> 833 | K26: {=SUM(Data!$D$2:$F$367*(--(Data!$A$2:$A$367=DATE(Processing!$C$1,Processing!$E$1,Processing!H26))))} -> 1117 | L26: =IF(ISNA(I26),0,H26) -> 1 | M26: =H26 -> 1 | N26: {=IF(ISNA(I26),NA(),SUM(Data!$AY$2:$AY$367*(--(Data!$A$2:$A$367=DATE(Processing!$C$1,Processing!$E$1,Processing!H26)))))} -> 106000 | O26: {=INDEX(Data!$AY$2:$AY$367,MATCH(TRUE,Data!$AY$2:$AY$367>0,0))} -> 117000 | P26: {=IFERROR(IF(NOT(ISNA(I26)),NA(),SUM(Data!$AY$2:$AY$367*(--(Data!$A$2:$A$367=DATE(Processing!$C$1,Processing!$E$1,Processing!H26))))),NA())} -> #N/A | Q26: =H26 -> 1 | R26: {=IF(ISNA(I26),NA(),SUM(Data!$BE$2:$BH$367*(--(Data!$A$2:$A$367=DATE(Processing!$C$1,Processing!$E$1,Processing!H26)))))} -> 74443 | S26: =(R26>0)*$C$28 -> 36058 | T26: {=ISNUMBER(Q26)*SUM(Data!$BE$2:$BH$367*(--(Data!$A$2:$A$367=DATE(Processing!$C$1,Processing!$E$1,Processing!H26))))} -> 74443 | U26: Goals | V26: 1 | W26: 2 | X26: 3 | Y26: 4 | Z26: Total | AA26: Goal 1 | AB26: Goal 2 | AC26: Goal 3 | AD26: Goal 4 | AG26: =H26 -> 1 | AH26: {=IF(ISNA(I26),NA(),SUM(Data!$J$2:$S$367*(--(Data!$A$2:$A$367=DATE(Processing!$C$1,Processing!$E$1,Processing!H26)))))} -> 1117 | AI26: {=IF(ISNA(I26),NA(),SUM(Data!$O$2:$S$367*(--(Data!$A$2:$A$367=DATE(Processing!$C$1,Processing!$E$1,Processing!H26)))))} -> 385 | AJ26: {=SUM(Data!$J$2:$S$367*(--(Data!$A$2:$A$367=DATE(Processing!$C$1,Processing!$E$1,Processing!H26))))} -> 1117 | AL26: =H26 -> 1 | AM26: {=IF(ISNA(I26),NA(),SUM(Data!$T$2:$AX$367*(--(Data!$A$2:$A$367=DATE(Processing!$C$1,Processing!$E$1,Processing!H26)))))} -> 833 | AN26: {=IF(ISNA(I26),NA(),SUM(Data!$AP$2:$AX$367*(--(Data!$A$2:$A$367=DATE(Processing!$C$1,Processing!$E$1,Processing!H26)))))} -> 295 | AO26: {=SUM(Data!$T$2:$AX$367*(--(Data!$A$2:$A$367=DATE(Processing!$C$1,Processing!$E$1,Processing!H26))))} -> 833
A27: Total: | B27: Credit Funds | C27: =SUM(C23:C26) -> 66942 | F27: FEBRUARY | G27: =DAY(EOMONTH(DATE($C$1,H27,1),0)) -> 29 | H27: 2 | I27: {=IFERROR(GETPIVOTDATA(""&$N$2,Control!$A$7,""&$H$25,H27)+GETPIVOTDATA(""&$N$3,Control!$A$7,""&$H$25,H27)+GETPIVOTDATA(""&$N$4,Control!$A$7,""&$H$25,H27),NA())} -> 1093 | J27: {=IFERROR(GETPIVOTDATA(""&$N$5,Control!$A$7,""&$H$25,H27)+GETPIVOTDATA(""&$N$6,Control!$A$7,""&$H$25,H27)+GETPIVOTDATA(""&$N$7,Control!$A$7,""&$H$25,H27),NA())} -> 846 | K27: {=SUM(Data!$D$2:$F$367*(--(Data!$A$2:$A$367=DATE(Processing!$C$1,Processing!$E$1,Processing!H27))))} -> 1093 | L27: =IF(ISNA(I27),0,H27) -> 2 | M27: =H27 -> 2 | N27: {=IF(ISNA(I27),NA(),SUM(Data!$AY$2:$AY$367*(--(Data!$A$2:$A$367=DATE(Processing!$C$1,Processing!$E$1,Processing!H27)))))} -> 105333.5 | O27: {=INDEX(Data!$AY$2:$AY$367,MATCH(TRUE,Data!$AY$2:$AY$367>0,0))} -> 117000 | P27: {=IFERROR(IF(NOT(ISNA(I27)),NA(),SUM(Data!$AY$2:$AY$367*(--(Data!$A$2:$A$367=DATE(Processing!$C$1,Processing!$E$1,Processing!H27))))),NA())} -> #N/A | Q27: =H27 -> 2 | R27: {=IF(ISNA(I27),NA(),SUM(Data!$BE$2:$BH$367*(--(Data!$A$2:$A$367=DATE(Processing!$C$1,Processing!$E$1,Processing!H27)))))} -> 72807 | S27: =(R27>0)*$C$28 -> 36058 | T27: {=ISNUMBER(Q27)*SUM(Data!$BE$2:$BH$367*(--(Data!$A$2:$A$367=DATE(Processing!$C$1,Processing!$E$1,Processing!H27))))} -> 72807 | U27: Done | V27: {=INDEX($AA$33:$AD$44,$E$1,V26)} -> 48286 | W27: {=INDEX($AA$33:$AD$44,$E$1,W26)} -> 22765 | X27: {=INDEX($AA$33:$AD$44,$E$1,X26)} -> 21425 | Y27: {=INDEX($AA$33:$AD$44,$E$1,Y26)} -> 11977 | Z27: =SUM(V27:Y27) -> 104453 | AA27: =V27 -> 48286 | AB27: =W27 -> 22765 | AC27: =X27 -> 21425 | AD27: =Y27 -> 11977 | AG27: =H27 -> 2 | AH27: {=IF(ISNA(I27),NA(),SUM(Data!$J$2:$S$367*(--(Data!$A$2:$A$367=DATE(Processing!$C$1,Processing!$E$1,Processing!H27)))))} -> 1093 | AI27: {=IF(ISNA(I27),NA(),SUM(Data!$O$2:$S$367*(--(Data!$A$2:$A$367=DATE(Processing!$C$1,Processing!$E$1,Processing!H27)))))} -> 506 | AJ27: {=SUM(Data!$J$2:$S$367*(--(Data!$A$2:$A$367=DATE(Processing!$C$1,Processing!$E$1,Processing!H27))))} -> 1093 | AL27: =H27 -> 2 | AM27: {=IF(ISNA(I27),NA(),SUM(Data!$T$2:$AX$367*(--(Data!$A$2:$A$367=DATE(Processing!$C$1,Processing!$E$1,Processing!H27)))))} -> 846 | AN27: {=IF(ISNA(I27),NA(),SUM(Data!$AP$2:$AX$367*(--(Data!$A$2:$A$367=DATE(Processing!$C$1,Processing!$E$1,Processing!H27)))))} -> 333 | AO27: {=SUM(Data!$T$2:$AX$367*(--(Data!$A$2:$A$367=DATE(Processing!$C$1,Processing!$E$1,Processing!H27))))} -> 846
A28: Repayment | B28: Redeemed | C28: =C29-C27 -> 36058 | D28: =C28/SUM($C$27:$C$28) -> 0.35007767 | F28: MARCH | G28: =DAY(EOMONTH(DATE($C$1,H28,1),0)) -> 31 | H28: 3 | I28: {=IFERROR(GETPIVOTDATA(""&$N$2,Control!$A$7,""&$H$25,H28)+GETPIVOTDATA(""&$N$3,Control!$A$7,""&$H$25,H28)+GETPIVOTDATA(""&$N$4,Control!$A$7,""&$H$25,H28),NA())} -> 1063 | J28: {=IFERROR(GETPIVOTDATA(""&$N$5,Control!$A$7,""&$H$25,H28)+GETPIVOTDATA(""&$N$6,Control!$A$7,""&$H$25,H28)+GETPIVOTDATA(""&$N$7,Control!$A$7,""&$H$25,H28),NA())} -> 856 | K28: {=SUM(Data!$D$2:$F$367*(--(Data!$A$2:$A$367=DATE(Processing!$C$1,Processing!$E$1,Processing!H28))))} -> 1063 | L28: =IF(ISNA(I28),0,H28) -> 3 | M28: =H28 -> 3 | N28: {=IF(ISNA(I28),NA(),SUM(Data!$AY$2:$AY$367*(--(Data!$A$2:$A$367=DATE(Processing!$C$1,Processing!$E$1,Processing!H28)))))} -> 105201.7 | O28: {=INDEX(Data!$AY$2:$AY$367,MATCH(TRUE,Data!$AY$2:$AY$367>0,0))} -> 117000 | P28: {=IFERROR(IF(NOT(ISNA(I28)),NA(),SUM(Data!$AY$2:$AY$367*(--(Data!$A$2:$A$367=DATE(Processing!$C$1,Processing!$E$1,Processing!H28))))),NA())} -> #N/A | Q28: =H28 -> 3 | R28: {=IF(ISNA(I28),NA(),SUM(Data!$BE$2:$BH$367*(--(Data!$A$2:$A$367=DATE(Processing!$C$1,Processing!$E$1,Processing!H28)))))} -> 72807 | S28: =(R28>0)*$C$28 -> 36058 | T28: {=ISNUMBER(Q28)*SUM(Data!$BE$2:$BH$367*(--(Data!$A$2:$A$367=DATE(Processing!$C$1,Processing!$E$1,Processing!H28))))} -> 72807 | U28: Left | V28: =V29-V27 -> 28714 | W28: =W29-W27 -> 42235 | X28: =X29-X27 -> 36575 | Y28: =Y29-Y27 -> 18023 | Z28: =SUM(V28:Y28) -> 125547 | AG28: =H28 -> 3 | AH28: {=IF(ISNA(I28),NA(),SUM(Data!$J$2:$S$367*(--(Data!$A$2:$A$367=DATE(Processing!$C$1,Processing!$E$1,Processing!H28)))))} -> 1063 | AI28: {=IF(ISNA(I28),NA(),SUM(Data!$O$2:$S$367*(--(Data!$A$2:$A$367=DATE(Processing!$C$1,Processing!$E$1,Processing!H28)))))} -> 335 | AJ28: {=SUM(Data!$J$2:$S$367*(--(Data!$A$2:$A$367=DATE(Processing!$C$1,Processing!$E$1,Processing!H28))))} -> 1063 | AL28: =H28 -> 3 | AM28: {=IF(ISNA(I28),NA(),SUM(Data!$T$2:$AX$367*(--(Data!$A$2:$A$367=DATE(Processing!$C$1,Processing!$E$1,Processing!H28)))))} -> 856 | AN28: {=IF(ISNA(I28),NA(),SUM(Data!$AP$2:$AX$367*(--(Data!$A$2:$A$367=DATE(Processing!$C$1,Processing!$E$1,Processing!H28)))))} -> 272 | AO28: {=SUM(Data!$T$2:$AX$367*(--(Data!$A$2:$A$367=DATE(Processing!$C$1,Processing!$E$1,Processing!H28))))} -> 856
B29: Start Debt | C29: =SUM(Data!BE2:BH2) -> 103000 | F29: APRIL | G29: =DAY(EOMONTH(DATE($C$1,H29,1),0)) -> 30 | H29: 4 | I29: {=IFERROR(GETPIVOTDATA(""&$N$2,Control!$A$7,""&$H$25,H29)+GETPIVOTDATA(""&$N$3,Control!$A$7,""&$H$25,H29)+GETPIVOTDATA(""&$N$4,Control!$A$7,""&$H$25,H29),NA())} -> 1045 | J29: {=IFERROR(GETPIVOTDATA(""&$N$5,Control!$A$7,""&$H$25,H29)+GETPIVOTDATA(""&$N$6,Control!$A$7,""&$H$25,H29)+GETPIVOTDATA(""&$N$7,Control!$A$7,""&$H$25,H29),NA())} -> 859 | K29: {=SUM(Data!$D$2:$F$367*(--(Data!$A$2:$A$367=DATE(Processing!$C$1,Processing!$E$1,Processing!H29))))} -> 1045 | L29: =IF(ISNA(I29),0,H29) -> 4 | M29: =H29 -> 4 | N29: {=IF(ISNA(I29),NA(),SUM(Data!$AY$2:$AY$367*(--(Data!$A$2:$A$367=DATE(Processing!$C$1,Processing!$E$1,Processing!H29)))))} -> 105333.2 | O29: {=INDEX(Data!$AY$2:$AY$367,MATCH(TRUE,Data!$AY$2:$AY$367>0,0))} -> 117000 | P29: {=IFERROR(IF(NOT(ISNA(I29)),NA(),SUM(Data!$AY$2:$AY$367*(--(Data!$A$2:$A$367=DATE(Processing!$C$1,Processing!$E$1,Processing!H29))))),NA())} -> #N/A | Q29: =H29 -> 4 | R29: {=IF(ISNA(I29),NA(),SUM(Data!$BE$2:$BH$367*(--(Data!$A$2:$A$367=DATE(Processing!$C$1,Processing!$E$1,Processing!H29)))))} -> 72807 | S29: =(R29>0)*$C$28 -> 36058 | T29: {=ISNUMBER(Q29)*SUM(Data!$BE$2:$BH$367*(--(Data!$A$2:$A$367=DATE(Processing!$C$1,Processing!$E$1,Processing!H29))))} -> 72807 | U29: Plan | V29: 77000 | W29: 65000 | X29: 58000 | Y29: 30000 | Z29: =SUM(Z27:Z28) -> 230000 | AG29: =H29 -> 4 | AH29: {=IF(ISNA(I29),NA(),SUM(Data!$J$2:$S$367*(--(Data!$A$2:$A$367=DATE(Processing!$C$1,Processing!$E$1,Processing!H29)))))} -> 1045 | AI29: {=IF(ISNA(I29),NA(),SUM(Data!$O$2:$S$367*(--(Data!$A$2:$A$367=DATE(Processing!$C$1,Processing!$E$1,Processing!H29)))))} -> 399 | AJ29: {=SUM(Data!$J$2:$S$367*(--(Data!$A$2:$A$367=DATE(Processing!$C$1,Processing!$E$1,Processing!H29))))} -> 1045 | AL29: =H29 -> 4 | AM29: {=IF(ISNA(I29),NA(),SUM(Data!$T$2:$AX$367*(--(Data!$A$2:$A$367=DATE(Processing!$C$1,Processing!$E$1,Processing!H29)))))} -> 859 | AN29: {=IF(ISNA(I29),NA(),SUM(Data!$AP$2:$AX$367*(--(Data!$A$2:$A$367=DATE(Processing!$C$1,Processing!$E$1,Processing!H29)))))} -> 387 | AO29: {=SUM(Data!$T$2:$AX$367*(--(Data!$A$2:$A$367=DATE(Processing!$C$1,Processing!$E$1,Processing!H29))))} -> 859
A30: Total Values | B30: Used Credit Funds | D30: X | E30: Y | F30: MAY | G30: =DAY(EOMONTH(DATE($C$1,H30,1),0)) -> 31 | H30: 5 | I30: {=IFERROR(GETPIVOTDATA(""&$N$2,Control!$A$7,""&$H$25,H30)+GETPIVOTDATA(""&$N$3,Control!$A$7,""&$H$25,H30)+GETPIVOTDATA(""&$N$4,Control!$A$7,""&$H$25,H30),NA())} -> 1035 | J30: {=IFERROR(GETPIVOTDATA(""&$N$5,Control!$A$7,""&$H$25,H30)+GETPIVOTDATA(""&$N$6,Control!$A$7,""&$H$25,H30)+GETPIVOTDATA(""&$N$7,Control!$A$7,""&$H$25,H30),NA())} -> 860 | K30: {=SUM(Data!$D$2:$F$367*(--(Data!$A$2:$A$367=DATE(Processing!$C$1,Processing!$E$1,Processing!H30))))} -> 1035 | L30: =IF(ISNA(I30),0,H30) -> 5 | M30: =H30 -> 5 | N30: {=IF(ISNA(I30),NA(),SUM(Data!$AY$2:$AY$367*(--(Data!$A$2:$A$367=DATE(Processing!$C$1,Processing!$E$1,Processing!H30)))))} -> 106914.78 | O30: {=INDEX(Data!$AY$2:$AY$367,MATCH(TRUE,Data!$AY$2:$AY$367>0,0))} -> 117000 | P30: {=IFERROR(IF(NOT(ISNA(I30)),NA(),SUM(Data!$AY$2:$AY$367*(--(Data!$A$2:$A$367=DATE(Processing!$C$1,Processing!$E$1,Processing!H30))))),NA())} -> #N/A | Q30: =H30 -> 5 | R30: {=IF(ISNA(I30),NA(),SUM(Data!$BE$2:$BH$367*(--(Data!$A$2:$A$367=DATE(Processing!$C$1,Processing!$E$1,Processing!H30)))))} -> 72807 | S30: =(R30>0)*$C$28 -> 36058 | T30: {=ISNUMBER(Q30)*SUM(Data!$BE$2:$BH$367*(--(Data!$A$2:$A$367=DATE(Processing!$C$1,Processing!$E$1,Processing!H30))))} -> 72807 | U30: MAX | V30: =MAX(V29:Y29) -> 77000 | AG30: =H30 -> 5 | AH30: {=IF(ISNA(I30),NA(),SUM(Data!$J$2:$S$367*(--(Data!$A$2:$A$367=DATE(Processing!$C$1,Processing!$E$1,Processing!H30)))))} -> 1035 | AI30: {=IF(ISNA(I30),NA(),SUM(Data!$O$2:$S$367*(--(Data!$A$2:$A$367=DATE(Processing!$C$1,Processing!$E$1,Processing!H30)))))} -> 523 | AJ30: {=SUM(Data!$J$2:$S$367*(--(Data!$A$2:$A$367=DATE(Processing!$C$1,Processing!$E$1,Processing!H30))))} -> 1035 | AL30: =H30 -> 5 | AM30: {=IF(ISNA(I30),NA(),SUM(Data!$T$2:$AX$367*(--(Data!$A$2:$A$367=DATE(Processing!$C$1,Processing!$E$1,Processing!H30)))))} -> 860 | AN30: {=IF(ISNA(I30),NA(),SUM(Data!$AP$2:$AX$367*(--(Data!$A$2:$A$367=DATE(Processing!$C$1,Processing!$E$1,Processing!H30)))))} -> 231 | AO30: {=SUM(Data!$T$2:$AX$367*(--(Data!$A$2:$A$367=DATE(Processing!$C$1,Processing!$E$1,Processing!H30))))} -> 860
A31: Balance | B31: =1-C31 -> 0.64992233 | C31: =C28/SUM(C27:C28) -> 0.35007767 | D31: 0 | E31: 1 | F31: JUNE | G31: =DAY(EOMONTH(DATE($C$1,H31,1),0)) -> 30 | H31: 6 | I31: {=IFERROR(GETPIVOTDATA(""&$N$2,Control!$A$7,""&$H$25,H31)+GETPIVOTDATA(""&$N$3,Control!$A$7,""&$H$25,H31)+GETPIVOTDATA(""&$N$4,Control!$A$7,""&$H$25,H31),NA())} -> 1031 | J31: {=IFERROR(GETPIVOTDATA(""&$N$5,Control!$A$7,""&$H$25,H31)+GETPIVOTDATA(""&$N$6,Control!$A$7,""&$H$25,H31)+GETPIVOTDATA(""&$N$7,Control!$A$7,""&$H$25,H31),NA())} -> 858 | K31: {=SUM(Data!$D$2:$F$367*(--(Data!$A$2:$A$367=DATE(Processing!$C$1,Processing!$E$1,Processing!H31))))} -> 1031 | L31: =IF(ISNA(I31),0,H31) -> 6 | M31: =H31 -> 6 | N31: {=IF(ISNA(I31),NA(),SUM(Data!$AY$2:$AY$367*(--(Data!$A$2:$A$367=DATE(Processing!$C$1,Processing!$E$1,Processing!H31)))))} -> 109081.24 | O31: {=INDEX(Data!$AY$2:$AY$367,MATCH(TRUE,Data!$AY$2:$AY$367>0,0))} -> 117000 | P31: {=IFERROR(IF(NOT(ISNA(I31)),NA(),SUM(Data!$AY$2:$AY$367*(--(Data!$A$2:$A$367=DATE(Processing!$C$1,Processing!$E$1,Processing!H31))))),NA())} -> #N/A | Q31: =H31 -> 6 | R31: {=IF(ISNA(I31),NA(),SUM(Data!$BE$2:$BH$367*(--(Data!$A$2:$A$367=DATE(Processing!$C$1,Processing!$E$1,Processing!H31)))))} -> 72807 | S31: =(R31>0)*$C$28 -> 36058 | T31: {=ISNUMBER(Q31)*SUM(Data!$BE$2:$BH$367*(--(Data!$A$2:$A$367=DATE(Processing!$C$1,Processing!$E$1,Processing!H31))))} -> 72807 | V31: Activity | AG31: =H31 -> 6 | AH31: {=IF(ISNA(I31),NA(),SUM(Data!$J$2:$S$367*(--(Data!$A$2:$A$367=DATE(Processing!$C$1,Processing!$E$1,Processing!H31)))))} -> 1031 | AI31: {=IF(ISNA(I31),NA(),SUM(Data!$O$2:$S$367*(--(Data!$A$2:$A$367=DATE(Processing!$C$1,Processing!$E$1,Processing!H31)))))} -> 555 | AJ31: {=SUM(Data!$J$2:$S$367*(--(Data!$A$2:$A$367=DATE(Processing!$C$1,Processing!$E$1,Processing!H31))))} -> 1031 | AL31: =H31 -> 6 | AM31: {=IF(ISNA(I31),NA(),SUM(Data!$T$2:$AX$367*(--(Data!$A$2:$A$367=DATE(Processing!$C$1,Processing!$E$1,Processing!H31)))))} -> 858 | AN31: {=IF(ISNA(I31),NA(),SUM(Data!$AP$2:$AX$367*(--(Data!$A$2:$A$367=DATE(Processing!$C$1,Processing!$E$1,Processing!H31)))))} -> 352 | AO31: {=SUM(Data!$T$2:$AX$367*(--(Data!$A$2:$A$367=DATE(Processing!$C$1,Processing!$E$1,Processing!H31))))} -> 858
A32: Loan Portfolio Distribution | D32: =SIN(B31*2*PI()) -> -0.80873005 | E32: =COS(C31*2*PI()) -> -0.58817999 | F32: JULY | G32: =DAY(EOMONTH(DATE($C$1,H32,1),0)) -> 31 | H32: 7 | I32: {=IFERROR(GETPIVOTDATA(""&$N$2,Control!$A$7,""&$H$25,H32)+GETPIVOTDATA(""&$N$3,Control!$A$7,""&$H$25,H32)+GETPIVOTDATA(""&$N$4,Control!$A$7,""&$H$25,H32),NA())} -> 1037 | J32: {=IFERROR(GETPIVOTDATA(""&$N$5,Control!$A$7,""&$H$25,H32)+GETPIVOTDATA(""&$N$6,Control!$A$7,""&$H$25,H32)+GETPIVOTDATA(""&$N$7,Control!$A$7,""&$H$25,H32),NA())} -> 843 | K32: {=SUM(Data!$D$2:$F$367*(--(Data!$A$2:$A$367=DATE(Processing!$C$1,Processing!$E$1,Processing!H32))))} -> 1037 | L32: =IF(ISNA(I32),0,H32) -> 7 | M32: =H32 -> 7 | N32: {=IF(ISNA(I32),NA(),SUM(Data!$AY$2:$AY$367*(--(Data!$A$2:$A$367=DATE(Processing!$C$1,Processing!$E$1,Processing!H32)))))} -> 112591.84 | O32: {=INDEX(Data!$AY$2:$AY$367,MATCH(TRUE,Data!$AY$2:$AY$367>0,0))} -> 117000 | P32: {=IFERROR(IF(NOT(ISNA(I32)),NA(),SUM(Data!$AY$2:$AY$367*(--(Data!$A$2:$A$367=DATE(Processing!$C$1,Processing!$E$1,Processing!H32))))),NA())} -> #N/A | Q32: =H32 -> 7 | R32: {=IF(ISNA(I32),NA(),SUM(Data!$BE$2:$BH$367*(--(Data!$A$2:$A$367=DATE(Processing!$C$1,Processing!$E$1,Processing!H32)))))} -> 81746 | S32: =(R32>0)*$C$28 -> 36058 | T32: {=ISNUMBER(Q32)*SUM(Data!$BE$2:$BH$367*(--(Data!$A$2:$A$367=DATE(Processing!$C$1,Processing!$E$1,Processing!H32))))} -> 81746 | U32: Months | V32: Goal 1 | W32: Goal 2 | X32: Goal 3 | Y32: Goal 4 | Z32: Monthly Plan | AA32: Goal 1 | AB32: Goal 2 | AC32: Goal 3 | AD32: Goal 4 | AE32: Months | AF32: % Fact Plan | AG32: =H32 -> 7 | AH32: {=IF(ISNA(I32),NA(),SUM(Data!$J$2:$S$367*(--(Data!$A$2:$A$367=DATE(Processing!$C$1,Processing!$E$1,Processing!H32)))))} -> 1037 | AI32: {=IF(ISNA(I32),NA(),SUM(Data!$O$2:$S$367*(--(Data!$A$2:$A$367=DATE(Processing!$C$1,Processing!$E$1,Processing!H32)))))} -> 402 | AJ32: {=SUM(Data!$J$2:$S$367*(--(Data!$A$2:$A$367=DATE(Processing!$C$1,Processing!$E$1,Processing!H32))))} -> 1037 | AL32: =H32 -> 7 | AM32: {=IF(ISNA(I32),NA(),SUM(Data!$T$2:$AX$367*(--(Data!$A$2:$A$367=DATE(Processing!$C$1,Processing!$E$1,Processing!H32)))))} -> 843 | AN32: {=IF(ISNA(I32),NA(),SUM(Data!$AP$2:$AX$367*(--(Data!$A$2:$A$367=DATE(Processing!$C$1,Processing!$E$1,Processing!H32)))))} -> 338 | AO32: {=SUM(Data!$T$2:$AX$367*(--(Data!$A$2:$A$367=DATE(Processing!$C$1,Processing!$E$1,Processing!H32))))} -> 843
A33: =$D$24 -> 0.13349515 | B33: =$D$23 -> 0.2815534 | C33: =$D$25 -> 0.063087379 | D33: =$D$26 -> 0.17178641 | E33: =$D$28 -> 0.35007767 | F33: AUGUST | G33: =DAY(EOMONTH(DATE($C$1,H33,1),0)) -> 31 | H33: 8 | I33: {=IFERROR(GETPIVOTDATA(""&$N$2,Control!$A$7,""&$H$25,H33)+GETPIVOTDATA(""&$N$3,Control!$A$7,""&$H$25,H33)+GETPIVOTDATA(""&$N$4,Control!$A$7,""&$H$25,H33),NA())} -> 1056 | J33: {=IFERROR(GETPIVOTDATA(""&$N$5,Control!$A$7,""&$H$25,H33)+GETPIVOTDATA(""&$N$6,Control!$A$7,""&$H$25,H33)+GETPIVOTDATA(""&$N$7,Control!$A$7,""&$H$25,H33),NA())} -> 826 | K33: {=SUM(Data!$D$2:$F$367*(--(Data!$A$2:$A$367=DATE(Processing!$C$1,Processing!$E$1,Processing!H33))))} -> 1056 | L33: =IF(ISNA(I33),0,H33) -> 8 | M33: =H33 -> 8 | N33: {=IF(ISNA(I33),NA(),SUM(Data!$AY$2:$AY$367*(--(Data!$A$2:$A$367=DATE(Processing!$C$1,Processing!$E$1,Processing!H33)))))} -> 116459.95 | O33: {=INDEX(Data!$AY$2:$AY$367,MATCH(TRUE,Data!$AY$2:$AY$367>0,0))} -> 117000 | P33: {=IFERROR(IF(NOT(ISNA(I33)),NA(),SUM(Data!$AY$2:$AY$367*(--(Data!$A$2:$A$367=DATE(Processing!$C$1,Processing!$E$1,Processing!H33))))),NA())} -> #N/A | Q33: =H33 -> 8 | R33: {=IF(ISNA(I33),NA(),SUM(Data!$BE$2:$BH$367*(--(Data!$A$2:$A$367=DATE(Processing!$C$1,Processing!$E$1,Processing!H33)))))} -> 81746 | S33: =(R33>0)*$C$28 -> 36058 | T33: {=ISNUMBER(Q33)*SUM(Data!$BE$2:$BH$367*(--(Data!$A$2:$A$367=DATE(Processing!$C$1,Processing!$E$1,Processing!H33))))} -> 81746 | U33: JAN | V33: =AA33/$Z33 -> 0.41003448 | W33: =AB33/$Z33 -> 0.12 | X33: =AC33/$Z33 -> 0.17 | Y33: =AD33/$Z33 -> 0.060034483 | Z33: {=SUM(Data!BM$2:BM$367*(--(Data!$A$2:$A$367=DATE(Processing!$C$1,$AE33,1))))} -> 29000 | AA33: {=SUM(Data!BI$2:BI$367*(--(Data!$A$2:$A$367=DATE(Processing!$C$1,$AE33,1))))} -> 11891 | AB33: {=SUM(Data!BJ$2:BJ$367*(--(Data!$A$2:$A$367=DATE(Processing!$C$1,$AE33,1))))} -> 3480 | AC33: {=SUM(Data!BK$2:BK$367*(--(Data!$A$2:$A$367=DATE(Processing!$C$1,$AE33,1))))} -> 4930 | AD33: {=SUM(Data!BL$2:BL$367*(--(Data!$A$2:$A$367=DATE(Processing!$C$1,$AE33,1))))} -> 1741 | AE33: 1 | AF33: =IF(AE33=$E$1,SUM(V33:Y33),NA()) -> #N/A | AG33: =H33 -> 8 | AH33: {=IF(ISNA(I33),NA(),SUM(Data!$J$2:$S$367*(--(Data!$A$2:$A$367=DATE(Processing!$C$1,Processing!$E$1,Processing!H33)))))} -> 1056 | AI33: {=IF(ISNA(I33),NA(),SUM(Data!$O$2:$S$367*(--(Data!$A$2:$A$367=DATE(Processing!$C$1,Processing!$E$1,Processing!H33)))))} -> 448 | AJ33: {=SUM(Data!$J$2:$S$367*(--(Data!$A$2:$A$367=DATE(Processing!$C$1,Processing!$E$1,Processing!H33))))} -> 1056 | AL33: =H33 -> 8 | AM33: {=IF(ISNA(I33),NA(),SUM(Data!$T$2:$AX$367*(--(Data!$A$2:$A$367=DATE(Processing!$C$1,Processing!$E$1,Processing!H33)))))} -> 826 | AN33: {=IF(ISNA(I33),NA(),SUM(Data!$AP$2:$AX$367*(--(Data!$A$2:$A$367=DATE(Processing!$C$1,Processing!$E$1,Processing!H33)))))} -> 269 | AO33: {=SUM(Data!$T$2:$AX$367*(--(Data!$A$2:$A$367=DATE(Processing!$C$1,Processing!$E$1,Processing!H33))))} -> 826
A34: =$D$24 -> 0.13349515 | B34: =$D$23 -> 0.2815534 | C34: =$D$25 -> 0.063087379 | D34: =$D$26 -> 0.17178641 | E34: =$D$28 -> 0.35007767 | F34: SEPTEMBER | G34: =DAY(EOMONTH(DATE($C$1,H34,1),0)) -> 30 | H34: 9 | I34: {=IFERROR(GETPIVOTDATA(""&$N$2,Control!$A$7,""&$H$25,H34)+GETPIVOTDATA(""&$N$3,Control!$A$7,""&$H$25,H34)+GETPIVOTDATA(""&$N$4,Control!$A$7,""&$H$25,H34),NA())} -> 1082 | J34: {=IFERROR(GETPIVOTDATA(""&$N$5,Control!$A$7,""&$H$25,H34)+GETPIVOTDATA(""&$N$6,Control!$A$7,""&$H$25,H34)+GETPIVOTDATA(""&$N$7,Control!$A$7,""&$H$25,H34),NA())} -> 800 | K34: {=SUM(Data!$D$2:$F$367*(--(Data!$A$2:$A$367=DATE(Processing!$C$1,Processing!$E$1,Processing!H34))))} -> 1082 | L34: =IF(ISNA(I34),0,H34) -> 9 | M34: =H34 -> 9 | N34: {=IF(ISNA(I34),NA(),SUM(Data!$AY$2:$AY$367*(--(Data!$A$2:$A$367=DATE(Processing!$C$1,Processing!$E$1,Processing!H34)))))} -> 119624.63 | O34: {=INDEX(Data!$AY$2:$AY$367,MATCH(TRUE,Data!$AY$2:$AY$367>0,0))} -> 117000 | P34: {=IFERROR(IF(NOT(ISNA(I34)),NA(),SUM(Data!$AY$2:$AY$367*(--(Data!$A$2:$A$367=DATE(Processing!$C$1,Processing!$E$1,Processing!H34))))),NA())} -> #N/A | Q34: =H34 -> 9 | R34: {=IF(ISNA(I34),NA(),SUM(Data!$BE$2:$BH$367*(--(Data!$A$2:$A$367=DATE(Processing!$C$1,Processing!$E$1,Processing!H34)))))} -> 81746 | S34: =(R34>0)*$C$28 -> 36058 | T34: {=ISNUMBER(Q34)*SUM(Data!$BE$2:$BH$367*(--(Data!$A$2:$A$367=DATE(Processing!$C$1,Processing!$E$1,Processing!H34))))} -> 81746 | U34: FEB | V34: =AA34/$Z34 -> 0.58321053 | W34: =AB34/$Z34 -> 0.15107895 | X34: =AC34/$Z34 -> 0.14002632 | Y34: =AD34/$Z34 -> 0.050052632 | Z34: {=SUM(Data!BM$2:BM$367*(--(Data!$A$2:$A$367=DATE(Processing!$C$1,$AE34,1))))} -> 38000 | AA34: {=SUM(Data!BI$2:BI$367*(--(Data!$A$2:$A$367=DATE(Processing!$C$1,$AE34,1))))} -> 22162 | AB34: {=SUM(Data!BJ$2:BJ$367*(--(Data!$A$2:$A$367=DATE(Processing!$C$1,$AE34,1))))} -> 5741 | AC34: {=SUM(Data!BK$2:BK$367*(--(Data!$A$2:$A$367=DATE(Processing!$C$1,$AE34,1))))} -> 5321 | AD34: {=SUM(Data!BL$2:BL$367*(--(Data!$A$2:$A$367=DATE(Processing!$C$1,$AE34,1))))} -> 1902 | AE34: 2 | AF34: =IF(AE34=$E$1,SUM(V34:Y34),NA()) -> #N/A | AG34: =H34 -> 9 | AH34: {=IF(ISNA(I34),NA(),SUM(Data!$J$2:$S$367*(--(Data!$A$2:$A$367=DATE(Processing!$C$1,Processing!$E$1,Processing!H34)))))} -> 1082 | AI34: {=IF(ISNA(I34),NA(),SUM(Data!$O$2:$S$367*(--(Data!$A$2:$A$367=DATE(Processing!$C$1,Processing!$E$1,Processing!H34)))))} -> 474 | AJ34: {=SUM(Data!$J$2:$S$367*(--(Data!$A$2:$A$367=DATE(Processing!$C$1,Processing!$E$1,Processing!H34))))} -> 1082 | AL34: =H34 -> 9 | AM34: {=IF(ISNA(I34),NA(),SUM(Data!$T$2:$AX$367*(--(Data!$A$2:$A$367=DATE(Processing!$C$1,Processing!$E$1,Processing!H34)))))} -> 800 | AN34: {=IF(ISNA(I34),NA(),SUM(Data!$AP$2:$AX$367*(--(Data!$A$2:$A$367=DATE(Processing!$C$1,Processing!$E$1,Processing!H34)))))} -> 288 | AO34: {=SUM(Data!$T$2:$AX$367*(--(Data!$A$2:$A$367=DATE(Processing!$C$1,Processing!$E$1,Processing!H34))))} -> 800
A35: =$D$24 -> 0.13349515 | B35: =$D$23 -> 0.2815534 | C35: =$D$25 -> 0.063087379 | D35: =$D$26 -> 0.17178641 | E35: =$D$28 -> 0.35007767 | F35: OCTOBER | G35: =DAY(EOMONTH(DATE($C$1,H35,1),0)) -> 31 | H35: 10 | I35: {=IFERROR(GETPIVOTDATA(""&$N$2,Control!$A$7,""&$H$25,H35)+GETPIVOTDATA(""&$N$3,Control!$A$7,""&$H$25,H35)+GETPIVOTDATA(""&$N$4,Control!$A$7,""&$H$25,H35),NA())} -> 1095 | J35: {=IFERROR(GETPIVOTDATA(""&$N$5,Control!$A$7,""&$H$25,H35)+GETPIVOTDATA(""&$N$6,Control!$A$7,""&$H$25,H35)+GETPIVOTDATA(""&$N$7,Control!$A$7,""&$H$25,H35),NA())} -> 772 | K35: {=SUM(Data!$D$2:$F$367*(--(Data!$A$2:$A$367=DATE(Processing!$C$1,Processing!$E$1,Processing!H35))))} -> 1095 | L35: =IF(ISNA(I35),0,H35) -> 10 | M35: =H35 -> 10 | N35: {=IF(ISNA(I35),NA(),SUM(Data!$AY$2:$AY$367*(--(Data!$A$2:$A$367=DATE(Processing!$C$1,Processing!$E$1,Processing!H35)))))} -> 121950.66 | O35: {=INDEX(Data!$AY$2:$AY$367,MATCH(TRUE,Data!$AY$2:$AY$367>0,0))} -> 117000 | P35: {=IFERROR(IF(NOT(ISNA(I35)),NA(),SUM(Data!$AY$2:$AY$367*(--(Data!$A$2:$A$367=DATE(Processing!$C$1,Processing!$E$1,Processing!H35))))),NA())} -> #N/A | Q35: =H35 -> 10 | R35: {=IF(ISNA(I35),NA(),SUM(Data!$BE$2:$BH$367*(--(Data!$A$2:$A$367=DATE(Processing!$C$1,Processing!$E$1,Processing!H35)))))} -> 81746 | S35: =(R35>0)*$C$28 -> 36058 | T35: {=ISNUMBER(Q35)*SUM(Data!$BE$2:$BH$367*(--(Data!$A$2:$A$367=DATE(Processing!$C$1,Processing!$E$1,Processing!H35))))} -> 81746 | U35: MAR | V35: =AA35/$Z35 -> 0.62495918 | W35: =AB35/$Z35 -> 0.178 | X35: =AC35/$Z35 -> 0.12595918 | Y35: =AD35/$Z35 -> 0.043734694 | Z35: {=SUM(Data!BM$2:BM$367*(--(Data!$A$2:$A$367=DATE(Processing!$C$1,$AE35,1))))} -> 49000 | AA35: {=SUM(Data!BI$2:BI$367*(--(Data!$A$2:$A$367=DATE(Processing!$C$1,$AE35,1))))} -> 30623 | AB35: {=SUM(Data!BJ$2:BJ$367*(--(Data!$A$2:$A$367=DATE(Processing!$C$1,$AE35,1))))} -> 8722 | AC35: {=SUM(Data!BK$2:BK$367*(--(Data!$A$2:$A$367=DATE(Processing!$C$1,$AE35,1))))} -> 6172 | AD35: {=SUM(Data!BL$2:BL$367*(--(Data!$A$2:$A$367=DATE(Processing!$C$1,$AE35,1))))} -> 2143 | AE35: 3 | AF35: =IF(AE35=$E$1,SUM(V35:Y35),NA()) -> #N/A | AG35: =H35 -> 10 | AH35: {=IF(ISNA(I35),NA(),SUM(Data!$J$2:$S$367*(--(Data!$A$2:$A$367=DATE(Processing!$C$1,Processing!$E$1,Processing!H35)))))} -> 1095 | AI35: {=IF(ISNA(I35),NA(),SUM(Data!$O$2:$S$367*(--(Data!$A$2:$A$367=DATE(Processing!$C$1,Processing!$E$1,Processing!H35)))))} -> 385 | AJ35: {=SUM(Data!$J$2:$S$367*(--(Data!$A$2:$A$367=DATE(Processing!$C$1,Processing!$E$1,Processing!H35))))} -> 1095 | AL35: =H35 -> 10 | AM35: {=IF(ISNA(I35),NA(),SUM(Data!$T$2:$AX$367*(--(Data!$A$2:$A$367=DATE(Processing!$C$1,Processing!$E$1,Processing!H35)))))} -> 772 | AN35: {=IF(ISNA(I35),NA(),SUM(Data!$AP$2:$AX$367*(--(Data!$A$2:$A$367=DATE(Processing!$C$1,Processing!$E$1,Processing!H35)))))} -> 272 | AO35: {=SUM(Data!$T$2:$AX$367*(--(Data!$A$2:$A$367=DATE(Processing!$C$1,Processing!$E$1,Processing!H35))))} -> 772
F36: NOVEMBER | G36: =DAY(EOMONTH(DATE($C$1,H36,1),0)) -> 30 | H36: 11 | I36: {=IFERROR(GETPIVOTDATA(""&$N$2,Control!$A$7,""&$H$25,H36)+GETPIVOTDATA(""&$N$3,Control!$A$7,""&$H$25,H36)+GETPIVOTDATA(""&$N$4,Control!$A$7,""&$H$25,H36),NA())} -> 1101 | J36: {=IFERROR(GETPIVOTDATA(""&$N$5,Control!$A$7,""&$H$25,H36)+GETPIVOTDATA(""&$N$6,Control!$A$7,""&$H$25,H36)+GETPIVOTDATA(""&$N$7,Control!$A$7,""&$H$25,H36),NA())} -> 749 | K36: {=SUM(Data!$D$2:$F$367*(--(Data!$A$2:$A$367=DATE(Processing!$C$1,Processing!$E$1,Processing!H36))))} -> 1101 | L36: =IF(ISNA(I36),0,H36) -> 11 | M36: =H36 -> 11 | N36: {=IF(ISNA(I36),NA(),SUM(Data!$AY$2:$AY$367*(--(Data!$A$2:$A$367=DATE(Processing!$C$1,Processing!$E$1,Processing!H36)))))} -> 122466.82 | O36: {=INDEX(Data!$AY$2:$AY$367,MATCH(TRUE,Data!$AY$2:$AY$367>0,0))} -> 117000 | P36: {=IFERROR(IF(NOT(ISNA(I36)),NA(),SUM(Data!$AY$2:$AY$367*(--(Data!$A$2:$A$367=DATE(Processing!$C$1,Processing!$E$1,Processing!H36))))),NA())} -> #N/A | Q36: =H36 -> 11 | R36: {=IF(ISNA(I36),NA(),SUM(Data!$BE$2:$BH$367*(--(Data!$A$2:$A$367=DATE(Processing!$C$1,Processing!$E$1,Processing!H36)))))} -> 81746 | S36: =(R36>0)*$C$28 -> 36058 | T36: {=ISNUMBER(Q36)*SUM(Data!$BE$2:$BH$367*(--(Data!$A$2:$A$367=DATE(Processing!$C$1,Processing!$E$1,Processing!H36))))} -> 81746 | U36: APR | V36: =AA36/$Z36 -> 0.49672222 | W36: =AB36/$Z36 -> 0.19059722 | X36: =AC36/$Z36 -> 0.12004167 | Y36: =AD36/$Z36 -> 0.080055556 | Z36: {=SUM(Data!BM$2:BM$367*(--(Data!$A$2:$A$367=DATE(Processing!$C$1,$AE36,1))))} -> 72000 | AA36: {=SUM(Data!BI$2:BI$367*(--(Data!$A$2:$A$367=DATE(Processing!$C$1,$AE36,1))))} -> 35764 | AB36: {=SUM(Data!BJ$2:BJ$367*(--(Data!$A$2:$A$367=DATE(Processing!$C$1,$AE36,1))))} -> 13723 | AC36: {=SUM(Data!BK$2:BK$367*(--(Data!$A$2:$A$367=DATE(Processing!$C$1,$AE36,1))))} -> 8643 | AD36: {=SUM(Data!BL$2:BL$367*(--(Data!$A$2:$A$367=DATE(Processing!$C$1,$AE36,1))))} -> 5764 | AE36: 4 | AF36: =IF(AE36=$E$1,SUM(V36:Y36),NA()) -> #N/A | AG36: =H36 -> 11 | AH36: {=IF(ISNA(I36),NA(),SUM(Data!$J$2:$S$367*(--(Data!$A$2:$A$367=DATE(Processing!$C$1,Processing!$E$1,Processing!H36)))))} -> 1101 | AI36: {=IF(ISNA(I36),NA(),SUM(Data!$O$2:$S$367*(--(Data!$A$2:$A$367=DATE(Processing!$C$1,Processing!$E$1,Processing!H36)))))} -> 421 | AJ36: {=SUM(Data!$J$2:$S$367*(--(Data!$A$2:$A$367=DATE(Processing!$C$1,Processing!$E$1,Processing!H36))))} -> 1101 | AL36: =H36 -> 11 | AM36: {=IF(ISNA(I36),NA(),SUM(Data!$T$2:$AX$367*(--(Data!$A$2:$A$367=DATE(Processing!$C$1,Processing!$E$1,Processing!H36)))))} -> 749 | AN36: {=IF(ISNA(I36),NA(),SUM(Data!$AP$2:$AX$367*(--(Data!$A$2:$A$367=DATE(Processing!$C$1,Processing!$E$1,Processing!H36)))))} -> 283 | AO36: {=SUM(Data!$T$2:$AX$367*(--(Data!$A$2:$A$367=DATE(Processing!$C$1,Processing!$E$1,Processing!H36))))} -> 749
F37: DECEMBER | G37: =DAY(EOMONTH(DATE($C$1,H37,1),0)) -> 31 | H37: 12 | I37: {=IFERROR(GETPIVOTDATA(""&$N$2,Control!$A$7,""&$H$25,H37)+GETPIVOTDATA(""&$N$3,Control!$A$7,""&$H$25,H37)+GETPIVOTDATA(""&$N$4,Control!$A$7,""&$H$25,H37),NA())} -> 1101 | J37: {=IFERROR(GETPIVOTDATA(""&$N$5,Control!$A$7,""&$H$25,H37)+GETPIVOTDATA(""&$N$6,Control!$A$7,""&$H$25,H37)+GETPIVOTDATA(""&$N$7,Control!$A$7,""&$H$25,H37),NA())} -> 730 | K37: {=SUM(Data!$D$2:$F$367*(--(Data!$A$2:$A$367=DATE(Processing!$C$1,Processing!$E$1,Processing!H37))))} -> 1101 | L37: =IF(ISNA(I37),0,H37) -> 12 | M37: =H37 -> 12 | N37: {=IF(ISNA(I37),NA(),SUM(Data!$AY$2:$AY$367*(--(Data!$A$2:$A$367=DATE(Processing!$C$1,Processing!$E$1,Processing!H37)))))} -> 122640.18 | O37: {=INDEX(Data!$AY$2:$AY$367,MATCH(TRUE,Data!$AY$2:$AY$367>0,0))} -> 117000 | P37: {=IFERROR(IF(NOT(ISNA(I37)),NA(),SUM(Data!$AY$2:$AY$367*(--(Data!$A$2:$A$367=DATE(Processing!$C$1,Processing!$E$1,Processing!H37))))),NA())} -> #N/A | Q37: =H37 -> 12 | R37: {=IF(ISNA(I37),NA(),SUM(Data!$BE$2:$BH$367*(--(Data!$A$2:$A$367=DATE(Processing!$C$1,Processing!$E$1,Processing!H37)))))} -> 81746 | S37: =(R37>0)*$C$28 -> 36058 | T37: {=ISNUMBER(Q37)*SUM(Data!$BE$2:$BH$367*(--(Data!$A$2:$A$367=DATE(Processing!$C$1,Processing!$E$1,Processing!H37))))} -> 81746 | U37: MAY | V37: =AA37/$Z37 -> 0.39212264 | W37: =AB37/$Z37 -> 0.17569811 | X37: =AC37/$Z37 -> 0.12003774 | Y37: =AD37/$Z37 -> 0.09004717 | Z37: {=SUM(Data!BM$2:BM$367*(--(Data!$A$2:$A$367=DATE(Processing!$C$1,$AE37,1))))} -> 106000 | AA37: {=SUM(Data!BI$2:BI$367*(--(Data!$A$2:$A$367=DATE(Processing!$C$1,$AE37,1))))} -> 41565 | AB37: {=SUM(Data!BJ$2:BJ$367*(--(Data!$A$2:$A$367=DATE(Processing!$C$1,$AE37,1))))} -> 18624 | AC37: {=SUM(Data!BK$2:BK$367*(--(Data!$A$2:$A$367=DATE(Processing!$C$1,$AE37,1))))} -> 12724 | AD37: {=SUM(Data!BL$2:BL$367*(--(Data!$A$2:$A$367=DATE(Processing!$C$1,$AE37,1))))} -> 9545 | AE37: 5 | AF37: =IF(AE37=$E$1,SUM(V37:Y37),NA()) -> #N/A | AG37: =H37 -> 12 | AH37: {=IF(ISNA(I37),NA(),SUM(Data!$J$2:$S$367*(--(Data!$A$2:$A$367=DATE(Processing!$C$1,Processing!$E$1,Processing!H37)))))} -> 1101 | AI37: {=IF(ISNA(I37),NA(),SUM(Data!$O$2:$S$367*(--(Data!$A$2:$A$367=DATE(Processing!$C$1,Processing!$E$1,Processing!H37)))))} -> 401 | AJ37: {=SUM(Data!$J$2:$S$367*(--(Data!$A$2:$A$367=DATE(Processing!$C$1,Processing!$E$1,Processing!H37))))} -> 1101 | AL37: =H37 -> 12 | AM37: {=IF(ISNA(I37),NA(),SUM(Data!$T$2:$AX$367*(--(Data!$A$2:$A$367=DATE(Processing!$C$1,Processing!$E$1,Processing!H37)))))} -> 730 | AN37: {=IF(ISNA(I37),NA(),SUM(Data!$AP$2:$AX$367*(--(Data!$A$2:$A$367=DATE(Processing!$C$1,Processing!$E$1,Processing!H37)))))} -> 223 | AO37: {=SUM(Data!$T$2:$AX$367*(--(Data!$A$2:$A$367=DATE(Processing!$C$1,Processing!$E$1,Processing!H37))))} -> 730
A38: Income | B38: Fixed vs Non-Fixed | H38: 13 | I38: {=IFERROR(GETPIVOTDATA(""&$N$2,Control!$A$7,""&$H$25,H38)+GETPIVOTDATA(""&$N$3,Control!$A$7,""&$H$25,H38)+GETPIVOTDATA(""&$N$4,Control!$A$7,""&$H$25,H38),NA())} -> 1097 | J38: {=IFERROR(GETPIVOTDATA(""&$N$5,Control!$A$7,""&$H$25,H38)+GETPIVOTDATA(""&$N$6,Control!$A$7,""&$H$25,H38)+GETPIVOTDATA(""&$N$7,Control!$A$7,""&$H$25,H38),NA())} -> 722 | K38: {=SUM(Data!$D$2:$F$367*(--(Data!$A$2:$A$367=DATE(Processing!$C$1,Processing!$E$1,Processing!H38))))} -> 1097 | L38: =IF(ISNA(I38),0,H38) -> 13 | M38: =H38 -> 13 | N38: {=IF(ISNA(I38),NA(),SUM(Data!$AY$2:$AY$367*(--(Data!$A$2:$A$367=DATE(Processing!$C$1,Processing!$E$1,Processing!H38)))))} -> 121944.95 | O38: {=INDEX(Data!$AY$2:$AY$367,MATCH(TRUE,Data!$AY$2:$AY$367>0,0))} -> 117000 | P38: {=IFERROR(IF(NOT(ISNA(I38)),NA(),SUM(Data!$AY$2:$AY$367*(--(Data!$A$2:$A$367=DATE(Processing!$C$1,Processing!$E$1,Processing!H38))))),NA())} -> #N/A | Q38: =H38 -> 13 | R38: {=IF(ISNA(I38),NA(),SUM(Data!$BE$2:$BH$367*(--(Data!$A$2:$A$367=DATE(Processing!$C$1,Processing!$E$1,Processing!H38)))))} -> 81746 | S38: =(R38>0)*$C$28 -> 36058 | T38: {=ISNUMBER(Q38)*SUM(Data!$BE$2:$BH$367*(--(Data!$A$2:$A$367=DATE(Processing!$C$1,Processing!$E$1,Processing!H38))))} -> 81746 | U38: JUN | V38: =AA38/$Z38 -> 0.38322222 | W38: =AB38/$Z38 -> 0.1806746 | X38: =AC38/$Z38 -> 0.17003968 | Y38: =AD38/$Z38 -> 0.095055556 | Z38: {=SUM(Data!BM$2:BM$367*(--(Data!$A$2:$A$367=DATE(Processing!$C$1,$AE38,1))))} -> 126000 | AA38: {=SUM(Data!BI$2:BI$367*(--(Data!$A$2:$A$367=DATE(Processing!$C$1,$AE38,1))))} -> 48286 | AB38: {=SUM(Data!BJ$2:BJ$367*(--(Data!$A$2:$A$367=DATE(Processing!$C$1,$AE38,1))))} -> 22765 | AC38: {=SUM(Data!BK$2:BK$367*(--(Data!$A$2:$A$367=DATE(Processing!$C$1,$AE38,1))))} -> 21425 | AD38: {=SUM(Data!BL$2:BL$367*(--(Data!$A$2:$A$367=DATE(Processing!$C$1,$AE38,1))))} -> 11977 | AE38: 6 | AF38: =IF(AE38=$E$1,SUM(V38:Y38),NA()) -> 0.82899206 | AG38: =H38 -> 13 | AH38: {=IF(ISNA(I38),NA(),SUM(Data!$J$2:$S$367*(--(Data!$A$2:$A$367=DATE(Processing!$C$1,Processing!$E$1,Processing!H38)))))} -> 1097 | AI38: {=IF(ISNA(I38),NA(),SUM(Data!$O$2:$S$367*(--(Data!$A$2:$A$367=DATE(Processing!$C$1,Processing!$E$1,Processing!H38)))))} -> 624 | AJ38: {=SUM(Data!$J$2:$S$367*(--(Data!$A$2:$A$367=DATE(Processing!$C$1,Processing!$E$1,Processing!H38))))} -> 1097 | AL38: =H38 -> 13 | AM38: {=IF(ISNA(I38),NA(),SUM(Data!$T$2:$AX$367*(--(Data!$A$2:$A$367=DATE(Processing!$C$1,Processing!$E$1,Processing!H38)))))} -> 722 | AN38: {=IF(ISNA(I38),NA(),SUM(Data!$AP$2:$AX$367*(--(Data!$A$2:$A$367=DATE(Processing!$C$1,Processing!$E$1,Processing!H38)))))} -> 221 | AO38: {=SUM(Data!$T$2:$AX$367*(--(Data!$A$2:$A$367=DATE(Processing!$C$1,Processing!$E$1,Processing!H38))))} -> 722
B39: Business | C39: Securities | D39: Gold | E39: Real estate | F39: Cryptocurrency | G39: Total | H39: 14 | I39: {=IFERROR(GETPIVOTDATA(""&$N$2,Control!$A$7,""&$H$25,H39)+GETPIVOTDATA(""&$N$3,Control!$A$7,""&$H$25,H39)+GETPIVOTDATA(""&$N$4,Control!$A$7,""&$H$25,H39),NA())} -> 1079 | J39: {=IFERROR(GETPIVOTDATA(""&$N$5,Control!$A$7,""&$H$25,H39)+GETPIVOTDATA(""&$N$6,Control!$A$7,""&$H$25,H39)+GETPIVOTDATA(""&$N$7,Control!$A$7,""&$H$25,H39),NA())} -> 719 | K39: {=SUM(Data!$D$2:$F$367*(--(Data!$A$2:$A$367=DATE(Processing!$C$1,Processing!$E$1,Processing!H39))))} -> 1079 | L39: =IF(ISNA(I39),0,H39) -> 14 | M39: =H39 -> 14 | N39: {=IF(ISNA(I39),NA(),SUM(Data!$AY$2:$AY$367*(--(Data!$A$2:$A$367=DATE(Processing!$C$1,Processing!$E$1,Processing!H39)))))} -> 120740.64 | O39: {=INDEX(Data!$AY$2:$AY$367,MATCH(TRUE,Data!$AY$2:$AY$367>0,0))} -> 117000 | P39: {=IFERROR(IF(NOT(ISNA(I39)),NA(),SUM(Data!$AY$2:$AY$367*(--(Data!$A$2:$A$367=DATE(Processing!$C$1,Processing!$E$1,Processing!H39))))),NA())} -> #N/A | Q39: =H39 -> 14 | R39: {=IF(ISNA(I39),NA(),SUM(Data!$BE$2:$BH$367*(--(Data!$A$2:$A$367=DATE(Processing!$C$1,Processing!$E$1,Processing!H39)))))} -> 81746 | S39: =(R39>0)*$C$28 -> 36058 | T39: {=ISNUMBER(Q39)*SUM(Data!$BE$2:$BH$367*(--(Data!$A$2:$A$367=DATE(Processing!$C$1,Processing!$E$1,Processing!H39))))} -> 81746 | U39: JUL | V39: =AA39/$Z39 -> 0.37020301 | W39: =AB39/$Z39 -> 0.22989474 | X39: =AC39/$Z39 -> 0.18004511 | Y39: =AD39/$Z39 -> 0.10425564 | Z39: {=SUM(Data!BM$2:BM$367*(--(Data!$A$2:$A$367=DATE(Processing!$C$1,$AE39,1))))} -> 133000 | AA39: {=SUM(Data!BI$2:BI$367*(--(Data!$A$2:$A$367=DATE(Processing!$C$1,$AE39,1))))} -> 49237 | AB39: {=SUM(Data!BJ$2:BJ$367*(--(Data!$A$2:$A$367=DATE(Processing!$C$1,$AE39,1))))} -> 30576 | AC39: {=SUM(Data!BK$2:BK$367*(--(Data!$A$2:$A$367=DATE(Processing!$C$1,$AE39,1))))} -> 23946 | AD39: {=SUM(Data!BL$2:BL$367*(--(Data!$A$2:$A$367=DATE(Processing!$C$1,$AE39,1))))} -> 13866 | AE39: 7 | AF39: =IF(AE39=$E$1,SUM(V39:Y39),NA()) -> #N/A | AG39: =H39 -> 14 | AH39: {=IF(ISNA(I39),NA(),SUM(Data!$J$2:$S$367*(--(Data!$A$2:$A$367=DATE(Processing!$C$1,Processing!$E$1,Processing!H39)))))} -> 1079 | AI39: {=IF(ISNA(I39),NA(),SUM(Data!$O$2:$S$367*(--(Data!$A$2:$A$367=DATE(Processing!$C$1,Processing!$E$1,Processing!H39)))))} -> 620 | AJ39: {=SUM(Data!$J$2:$S$367*(--(Data!$A$2:$A$367=DATE(Processing!$C$1,Processing!$E$1,Processing!H39))))} -> 1079 | AL39: =H39 -> 14 | AM39: {=IF(ISNA(I39),NA(),SUM(Data!$T$2:$AX$367*(--(Data!$A$2:$A$367=DATE(Processing!$C$1,Processing!$E$1,Processing!H39)))))} -> 719 | AN39: {=IF(ISNA(I39),NA(),SUM(Data!$AP$2:$AX$367*(--(Data!$A$2:$A$367=DATE(Processing!$C$1,Processing!$E$1,Processing!H39)))))} -> 220 | AO39: {=SUM(Data!$T$2:$AX$367*(--(Data!$A$2:$A$367=DATE(Processing!$C$1,Processing!$E$1,Processing!H39))))} -> 719
A40: Fixed Incom | B40: =GETPIVOTDATA(""&$A$40&" "&B39,Control!$A$7) -> 8115 | C40: =GETPIVOTDATA(""&$A$40&" "&C39,Control!$A$7) -> 4310 | D40: =GETPIVOTDATA(""&$A$40&" "&D39,Control!$A$7) -> 2141 | E40: =GETPIVOTDATA(""&$A$40&" "&E39,Control!$A$7) -> 2205 | F40: =GETPIVOTDATA(""&$A$40&" "&F39,Control!$A$7) -> 1151 | G40: =SUM(B40:F40) -> 17922 | H40: 15 | I40: {=IFERROR(GETPIVOTDATA(""&$N$2,Control!$A$7,""&$H$25,H40)+GETPIVOTDATA(""&$N$3,Control!$A$7,""&$H$25,H40)+GETPIVOTDATA(""&$N$4,Control!$A$7,""&$H$25,H40),NA())} -> 1048 | J40: {=IFERROR(GETPIVOTDATA(""&$N$5,Control!$A$7,""&$H$25,H40)+GETPIVOTDATA(""&$N$6,Control!$A$7,""&$H$25,H40)+GETPIVOTDATA(""&$N$7,Control!$A$7,""&$H$25,H40),NA())} -> 723 | K40: {=SUM(Data!$D$2:$F$367*(--(Data!$A$2:$A$367=DATE(Processing!$C$1,Processing!$E$1,Processing!H40))))} -> 1048 | L40: =IF(ISNA(I40),0,H40) -> 15 | M40: =H40 -> 15 | N40: {=IF(ISNA(I40),NA(),SUM(Data!$AY$2:$AY$367*(--(Data!$A$2:$A$367=DATE(Processing!$C$1,Processing!$E$1,Processing!H40)))))} -> 119050.54 | O40: {=INDEX(Data!$AY$2:$AY$367,MATCH(TRUE,Data!$AY$2:$AY$367>0,0))} -> 117000 | P40: {=IFERROR(IF(NOT(ISNA(I40)),NA(),SUM(Data!$AY$2:$AY$367*(--(Data!$A$2:$A$367=DATE(Processing!$C$1,Processing!$E$1,Processing!H40))))),NA())} -> #N/A | Q40: =H40 -> 15 | R40: {=IF(ISNA(I40),NA(),SUM(Data!$BE$2:$BH$367*(--(Data!$A$2:$A$367=DATE(Processing!$C$1,Processing!$E$1,Processing!H40)))))} -> 78246 | S40: =(R40>0)*$C$28 -> 36058 | T40: {=ISNUMBER(Q40)*SUM(Data!$BE$2:$BH$367*(--(Data!$A$2:$A$367=DATE(Processing!$C$1,Processing!$E$1,Processing!H40))))} -> 78246 | U40: AUG | V40: =AA40/$Z40 -> 0.34816216 | W40: =AB40/$Z40 -> 0.27329054 | X40: =AC40/$Z40 -> 0.1900473 | Y40: =AD40/$Z40 -> 0.12377703 | Z40: {=SUM(Data!BM$2:BM$367*(--(Data!$A$2:$A$367=DATE(Processing!$C$1,$AE40,1))))} -> 148000 | AA40: {=SUM(Data!BI$2:BI$367*(--(Data!$A$2:$A$367=DATE(Processing!$C$1,$AE40,1))))} -> 51528 | AB40: {=SUM(Data!BJ$2:BJ$367*(--(Data!$A$2:$A$367=DATE(Processing!$C$1,$AE40,1))))} -> 40447 | AC40: {=SUM(Data!BK$2:BK$367*(--(Data!$A$2:$A$367=DATE(Processing!$C$1,$AE40,1))))} -> 28127 | AD40: {=SUM(Data!BL$2:BL$367*(--(Data!$A$2:$A$367=DATE(Processing!$C$1,$AE40,1))))} -> 18319 | AE40: 8 | AF40: =IF(AE40=$E$1,SUM(V40:Y40),NA()) -> #N/A | AG40: =H40 -> 15 | AH40: {=IF(ISNA(I40),NA(),SUM(Data!$J$2:$S$367*(--(Data!$A$2:$A$367=DATE(Processing!$C$1,Processing!$E$1,Processing!H40)))))} -> 1048 | AI40: {=IF(ISNA(I40),NA(),SUM(Data!$O$2:$S$367*(--(Data!$A$2:$A$367=DATE(Processing!$C$1,Processing!$E$1,Processing!H40)))))} -> 420 | AJ40: {=SUM(Data!$J$2:$S$367*(--(Data!$A$2:$A$367=DATE(Processing!$C$1,Processing!$E$1,Processing!H40))))} -> 1048 | AL40: =H40 -> 15 | AM40: {=IF(ISNA(I40),NA(),SUM(Data!$T$2:$AX$367*(--(Data!$A$2:$A$367=DATE(Processing!$C$1,Processing!$E$1,Processing!H40)))))} -> 723 | AN40: {=IF(ISNA(I40),NA(),SUM(Data!$AP$2:$AX$367*(--(Data!$A$2:$A$367=DATE(Processing!$C$1,Processing!$E$1,Processing!H40)))))} -> 261 | AO40: {=SUM(Data!$T$2:$AX$367*(--(Data!$A$2:$A$367=DATE(Processing!$C$1,Processing!$E$1,Processing!H40))))} -> 723
...

Sheet Structuring Data
A1: RowID | B1: Date | C1: Year | D1: Month | E1: Day | F1: Income | G1: Expenses | H1: Non-Fixed Incom | I1: Fixed Incom | J1: Other Income | K1: Non-Fixed Cost | L1: Fixed Costs | M1: Other Cost | N1: Fixed Incom Business | O1: Fixed Incom Securities | P1: Fixed Incom Real estate | Q1: Fixed Incom Gold | R1: Fixed Incom Cryptocurrency | S1: Non-Fixed Incom Business | T1: Non-Fixed Incom Securities | U1: Non-Fixed Incom Real estate | V1: Non-Fixed Incom Gold | W1: Non-Fixed Incom Cryptocurrency | X1: Loans | Y1: Training courses | Z1: Travel public transport | AA1: Mobile connection | AB1: Food | AC1: Utility Payments | AD1: Internet & TV | AE1: Household chemicals | AF1: Furniture & utensils | AG1: BedLinen & tablecloth | AH1: Cat food | AI1: Clothing & footwear | AJ1: Gym | AK1: Hygiene products | AL1: Medications | AM1: Hairdresser | AN1: Cosmetics & perfum | AO1: Fuel | AP1: Spare parts | AQ1: Parking | AR1: Washing | AS1: Insurance | AT1: Holidays | AU1: Excursions | AV1: Restaurants | AW1: Gotheli | AX1: Bags, packages, boxes | AY1: Snacks on the way | AZ1: Alcohol | BA1: Hobby | BB1: Unexpected expenses
A2: 367 | C2: 2024 | D2: JANUARY | E2: 0.01 | F2: {=INDEX(Data!B$2:B$368,$A2)} -> 0 | G2: {=INDEX(Data!C$2:C$368,$A2)} -> 0 | H2: {=INDEX(Data!D$2:D$368,$A2)} -> 0 | I2: {=INDEX(Data!E$2:E$368,$A2)} -> 0 | J2: {=INDEX(Data!F$2:F$368,$A2)} -> 0 | K2: {=INDEX(Data!G$2:G$368,$A2)} -> 0 | L2: {=INDEX(Data!H$2:H$368,$A2)} -> 0 | M2: {=INDEX(Data!I$2:I$368,$A2)} -> 0 | ... BB2: {=INDEX(Data!AX$2:AX$368,$A2)} -> 0
A3: 1 | B3: 45292 | C3: 2024 | D3: JANUARY | E3: 1 | F3: {=INDEX(Data!B$2:B$368,$A3)} -> 496 | G3: {=INDEX(Data!C$2:C$368,$A3)} -> 575 | H3: {=INDEX(Data!D$2:D$368,$A3)} -> 243 | I3: {=INDEX(Data!E$2:E$368,$A3)} -> 189 | J3: {=INDEX(Data!F$2:F$368,$A3)} -> 64 | K3: {=INDEX(Data!G$2:G$368,$A3)} -> 172 | L3: {=INDEX(Data!H$2:H$368,$A3)} -> 271 | M3: {=INDEX(Data!I$2:I$368,$A3)} -> 132 | ... BB3: {=INDEX(Data!AX$2:AX$368,$A3)} -> 114
A4: 2 | B4: 45293 | C4: 2024 | D4: JANUARY | E4: 2 | F4: {=INDEX(Data!B$2:B$368,$A4)} -> 516 | G4: {=INDEX(Data!C$2:C$368,$A4)} -> 585 | H4: {=INDEX(Data!D$2:D$368,$A4)} -> 268 | I4: {=INDEX(Data!E$2:E$368,$A4)} -> 218 | J4: {=INDEX(Data!F$2:F$368,$A4)} -> 30 | K4: {=INDEX(Data!G$2:G$368,$A4)} -> 286 | L4: {=INDEX(Data!H$2:H$368,$A4)} -> 259 | M4: {=INDEX(Data!I$2:I$368,$A4)} -> 40 | ... BB4: {=INDEX(Data!AX$2:AX$368,$A4)} -> 2
A5: 3 | B5: 45294 | C5: 2024 | D5: JANUARY | E5: 3 | F5: {=INDEX(Data!B$2:B$368,$A5)} -> 539 | G5: {=INDEX(Data!C$2:C$368,$A5)} -> 610 | H5: {=INDEX(Data!D$2:D$368,$A5)} -> 285 | I5: {=INDEX(Data!E$2:E$368,$A5)} -> 131 | J5: {=INDEX(Data!F$2:F$368,$A5)} -> 123 | K5: {=INDEX(Data!G$2:G$368,$A5)} -> 244 | L5: {=INDEX(Data!H$2:H$368,$A5)} -> 318 | M5: {=INDEX(Data!I$2:I$368,$A5)} -> 48 | ... BB5: {=INDEX(Data!AX$2:AX$368,$A5)} -> 0
A6: 4 | B6: 45295 | C6: 2024 | D6: JANUARY | E6: 4 | F6: {=INDEX(Data!B$2:B$368,$A6)} -> 557 | G6: {=INDEX(Data!C$2:C$368,$A6)} -> 641 | H6: {=INDEX(Data!D$2:D$368,$A6)} -> 150 | I6: {=INDEX(Data!E$2:E$368,$A6)} -> 307 | J6: {=INDEX(Data!F$2:F$368,$A6)} -> 100 | K6: {=INDEX(Data!G$2:G$368,$A6)} -> 262 | L6: {=INDEX(Data!H$2:H$368,$A6)} -> 219 | M6: {=INDEX(Data!I$2:I$368,$A6)} -> 160 | ... BB6: {=INDEX(Data!AX$2:AX$368,$A6)} -> 12
A7: 5 | B7: 45296 | C7: 2024 | D7: JANUARY | E7: 5 | F7: {=INDEX(Data!B$2:B$368,$A7)} -> 575 | G7: {=INDEX(Data!C$2:C$368,$A7)} -> 667 | H7: {=INDEX(Data!D$2:D$368,$A7)} -> 132 | I7: {=INDEX(Data!E$2:E$368,$A7)} -> 415 | J7: {=INDEX(Data!F$2:F$368,$A7)} -> 28 | K7: {=INDEX(Data!G$2:G$368,$A7)} -> 153 | L7: {=INDEX(Data!H$2:H$368,$A7)} -> 374 | M7: {=INDEX(Data!I$2:I$368,$A7)} -> 140 | ... BB7: {=INDEX(Data!AX$2:AX$368,$A7)} -> 27
A8: 6 | B8: 45297 | C8: 2024 | D8: JANUARY | E8: 6 | F8: {=INDEX(Data!B$2:B$368,$A8)} -> 586 | G8: {=INDEX(Data!C$2:C$368,$A8)} -> 685 | H8: {=INDEX(Data!D$2:D$368,$A8)} -> 175 | I8: {=INDEX(Data!E$2:E$368,$A8)} -> 335 | J8: {=INDEX(Data!F$2:F$368,$A8)} -> 76 | K8: {=INDEX(Data!G$2:G$368,$A8)} -> 212 | L8: {=INDEX(Data!H$2:H$368,$A8)} -> 336 | M8: {=INDEX(Data!I$2:I$368,$A8)} -> 137 | ... BB8: {=INDEX(Data!AX$2:AX$368,$A8)} -> 0
A9: 7 | B9: 45298 | C9: 2024 | D9: JANUARY | E9: 7 | F9: {=INDEX(Data!B$2:B$368,$A9)} -> 597 | G9: {=INDEX(Data!C$2:C$368,$A9)} -> 690 | H9: {=INDEX(Data!D$2:D$368,$A9)} -> 310 | I9: {=INDEX(Data!E$2:E$368,$A9)} -> 162 | J9: {=INDEX(Data!F$2:F$368,$A9)} -> 125 | K9: {=INDEX(Data!G$2:G$368,$A9)} -> 282 | L9: {=INDEX(Data!H$2:H$368,$A9)} -> 353 | M9: {=INDEX(Data!I$2:I$368,$A9)} -> 55 | ... BB9: {=INDEX(Data!AX$2:AX$368,$A9)} -> 120
A10: 8 | B10: 45299 | C10: 2024 | D10: JANUARY | E10: 8 | F10: {=INDEX(Data!B$2:B$368,$A10)} -> 604 | G10: {=INDEX(Data!C$2:C$368,$A10)} -> 684 | H10: {=INDEX(Data!D$2:D$368,$A10)} -> 217 | I10: {=INDEX(Data!E$2:E$368,$A10)} -> 273 | J10: {=INDEX(Data!F$2:F$368,$A10)} -> 114 | K10: {=INDEX(Data!G$2:G$368,$A10)} -> 307 | L10: {=INDEX(Data!H$2:H$368,$A10)} -> 316 | M10: {=INDEX(Data!I$2:I$368,$A10)} -> 61 | ... BB10: {=INDEX(Data!AX$2:AX$368,$A10)} -> 0
A11: 9 | B11: 45300 | C11: 2024 | D11: JANUARY | E11: 9 | F11: {=INDEX(Data!B$2:B$368,$A11)} -> 606 | G11: {=INDEX(Data!C$2:C$368,$A11)} -> 664 | H11: {=INDEX(Data!D$2:D$368,$A11)} -> 284 | I11: {=INDEX(Data!E$2:E$368,$A11)} -> 262 | J11: {=INDEX(Data!F$2:F$368,$A11)} -> 60 | K11: {=INDEX(Data!G$2:G$368,$A11)} -> 232 | L11: {=INDEX(Data!H$2:H$368,$A11)} -> 346 | M11: {=INDEX(Data!I$2:I$368,$A11)} -> 86 | ... BB11: {=INDEX(Data!AX$2:AX$368,$A11)} -> 30
A12: 10 | B12: 45301 | C12: 2024 | D12: JANUARY | E12: 10 | F12: {=INDEX(Data!B$2:B$368,$A12)} -> 602 | G12: {=INDEX(Data!C$2:C$368,$A12)} -> 625 | H12: {=INDEX(Data!D$2:D$368,$A12)} -> 258 | I12: {=INDEX(Data!E$2:E$368,$A12)} -> 314 | J12: {=INDEX(Data!F$2:F$368,$A12)} -> 30 | K12: {=INDEX(Data!G$2:G$368,$A12)} -> 131 | L12: {=INDEX(Data!H$2:H$368,$A12)} -> 451 | M12: {=INDEX(Data!I$2:I$368,$A12)} -> 43 | ... BB12: {=INDEX(Data!AX$2:AX$368,$A12)} -> 34
A13: 11 | B13: 45302 | C13: 2024 | D13: JANUARY | E13: 11 | F13: {=INDEX(Data!B$2:B$368,$A13)} -> 584 | G13: {=INDEX(Data!C$2:C$368,$A13)} -> 588 | H13: {=INDEX(Data!D$2:D$368,$A13)} -> 186 | I13: {=INDEX(Data!E$2:E$368,$A13)} -> 334 | J13: {=INDEX(Data!F$2:F$368,$A13)} -> 64 | K13: {=INDEX(Data!G$2:G$368,$A13)} -> 158 | L13: {=INDEX(Data!H$2:H$368,$A13)} -> 313 | M13: {=INDEX(Data!I$2:I$368,$A13)} -> 117 | ... BB13: {=INDEX(Data!AX$2:AX$368,$A13)} -> 0
A14: 12 | B14: 45303 | C14: 2024 | D14: JANUARY | E14: 12 | F14: {=INDEX(Data!B$2:B$368,$A14)} -> 560 | G14: {=INDEX(Data!C$2:C$368,$A14)} -> 575 | H14: {=INDEX(Data!D$2:D$368,$A14)} -> 123 | I14: {=INDEX(Data!E$2:E$368,$A14)} -> 348 | J14: {=INDEX(Data!F$2:F$368,$A14)} -> 89 | K14: {=INDEX(Data!G$2:G$368,$A14)} -> 149 | L14: {=INDEX(Data!H$2:H$368,$A14)} -> 369 | M14: {=INDEX(Data!I$2:I$368,$A14)} -> 57 | ... BB14: {=INDEX(Data!AX$2:AX$368,$A14)} -> 0
... A33: 31 | B33: 45322 | C33: 2024 | D33: JANUARY | E33: 31 | F33: {=INDEX(Data!B$2:B$368,$A33)} -> 578 | G33: {=INDEX(Data!C$2:C$368,$A33)} -> 654 | H33: {=INDEX(Data!D$2:D$368,$A33)} -> 306 | I33: {=INDEX(Data!E$2:E$368,$A33)} -> 128 | J33: {=INDEX(Data!F$2:F$368,$A33)} -> 144 | K33: {=INDEX(Data!G$2:G$368,$A33)} -> 248 | L33: {=INDEX(Data!H$2:H$368,$A33)} -> 302 | M33: {=INDEX(Data!I$2:I$368,$A33)} -> 104 | ... BB33: {=INDEX(Data!AX$2:AX$368,$A33)} -> 19
A34: 367 | C34: 2024 | D34: FEBRUARY | E34: 0.01 | F34: {=INDEX(Data!B$2:B$368,$A34)} -> 0 | G34: {=INDEX(Data!C$2:C$368,$A34)} -> 0 | H34: {=INDEX(Data!D$2:D$368,$A34)} -> 0 | I34: {=INDEX(Data!E$2:E$368,$A34)} -> 0 | J34: {=INDEX(Data!F$2:F$368,$A34)} -> 0 | K34: {=INDEX(Data!G$2:G$368,$A34)} -> 0 | L34: {=INDEX(Data!H$2:H$368,$A34)} -> 0 | M34: {=INDEX(Data!I$2:I$368,$A34)} -> 0 | ... BB34: {=INDEX(Data!AX$2:AX$368,$A34)} -> 0
A35: 367 | C35: 2024 | D35: FEBRUARY | E35: 0.02 | F35: {=INDEX(Data!B$2:B$368,$A35)} -> 0 | G35: {=INDEX(Data!C$2:C$368,$A35)} -> 0 | H35: {=INDEX(Data!D$2:D$368,$A35)} -> 0 | I35: {=INDEX(Data!E$2:E$368,$A35)} -> 0 | J35: {=INDEX(Data!F$2:F$368,$A35)} -> 0 | K35: {=INDEX(Data!G$2:G$368,$A35)} -> 0 | L35: {=INDEX(Data!H$2:H$368,$A35)} -> 0 | M35: {=INDEX(Data!I$2:I$368,$A35)} -> 0 | ... BB35: {=INDEX(Data!AX$2:AX$368,$A35)} -> 0
