Workbook
Name axesXA: IF(ProcessingA!$H$2,ProcessingA!$I$37:$I$48,ProcessingA!$I$2:$I$32)
Name axesXM1: IF(ProcessingM1!$H$2,ProcessingM1!$I$37:$I$48,ProcessingM1!$I$2:$I$32)
Name axesXM2: IF(ProcessingM2!$H$2,ProcessingM2!$I$37:$I$48,ProcessingM2!$I$2:$I$32)
Name axesXM3: IF(ProcessingM3!$H$2,ProcessingM3!$I$37:$I$48,ProcessingM3!$I$2:$I$32)
Name axesXM4: IF(ProcessingM4!$H$2,ProcessingM4!$I$37:$I$48,ProcessingM4!$I$2:$I$32)
Name currentA: IF(ProcessingA!$H$2,ProcessingA!$K$37:$K$48,ProcessingA!$K$2:$K$32)
Name currentM1: IF(ProcessingM1!$H$2,ProcessingM1!$K$37:$K$48,ProcessingM1!$K$2:$K$32)
Name currentM2: IF(ProcessingM2!$H$2,ProcessingM2!$K$37:$K$48,ProcessingM2!$K$2:$K$32)
Name currentM3: IF(ProcessingM3!$H$2,ProcessingM3!$K$37:$K$48,ProcessingM3!$K$2:$K$32)
Name currentM4: IF(ProcessingM4!$H$2,ProcessingM4!$K$37:$K$48,ProcessingM4!$K$2:$K$32)
Name DatabaseA: DataA!$A$2:$BO$1614
Name DatabaseM1: DataM1!$A$2:$BN$405
Name DatabaseM2: DataM2!$A$2:$BN$405
Name DatabaseM3: DataM3!$A$2:$BN$405
Name DatabaseM4: DataM4!$A$2:$BN$405
Name LoginA: CHOOSE(Passwords!$G$6,'M1'!$C$5,'M2'!$C$5,'M3'!$C$5,'M4'!$C$5,A!$C$5,LOGOUT!$C$5)
Name LoginLOGOUT: CHOOSE(Passwords!$G$7,'M1'!$C$5,'M2'!$C$5,'M3'!$C$5,'M4'!$C$5,A!$C$5,LOGOUT!$C$5)
Name LoginM1: CHOOSE(Passwords!$G$2,'M1'!$C$5,'M2'!$C$5,'M3'!$C$5,'M4'!$C$5,A!$C$5,LOGOUT!$C$5)
Name LoginM2: CHOOSE(Passwords!$G$3,'M1'!$C$5,'M2'!$C$5,'M3'!$C$5,'M4'!$C$5,A!$C$5,LOGOUT!$C$5)
Name LoginM3: CHOOSE(Passwords!$G$4,'M1'!$C$5,'M2'!$C$5,'M3'!$C$5,'M4'!$C$5,A!$C$5,LOGOUT!$C$5)
Name LoginM4: CHOOSE(Passwords!$G$5,'M1'!$C$5,'M2'!$C$5,'M3'!$C$5,'M4'!$C$5,A!$C$5,LOGOUT!$C$5)
Name salesA: IF(ProcessingA!$H$2,ProcessingA!$J$37:$J$48,ProcessingA!$J$2:$J$32)
Name salesM1: IF(ProcessingM1!$H$2,ProcessingM1!$J$37:$J$48,ProcessingM1!$J$2:$J$32)
Name salesM2: IF(ProcessingM2!$H$2,ProcessingM2!$J$37:$J$48,ProcessingM2!$J$2:$J$32)
Name salesM3: IF(ProcessingM3!$H$2,ProcessingM3!$J$37:$J$48,ProcessingM3!$J$2:$J$32)
Name salesM4: IF(ProcessingM4!$H$2,ProcessingM4!$J$37:$J$48,ProcessingM4!$J$2:$J$32)
Name seasonA: IF(ProcessingA!$H$2,ProcessingA!$M$37:$M$48,ProcessingA!$M$2:$M$32)
Name seasonM1: IF(ProcessingM1!$H$2,ProcessingM1!$M$37:$M$48,ProcessingM1!$M$2:$M$32)
Name seasonM2: IF(ProcessingM2!$H$2,ProcessingM2!$M$37:$M$48,ProcessingM2!$M$2:$M$32)
Name seasonM3: IF(ProcessingM3!$H$2,ProcessingM3!$M$37:$M$48,ProcessingM3!$M$2:$M$32)
Name seasonM4: IF(ProcessingM4!$H$2,ProcessingM4!$M$37:$M$48,ProcessingM4!$M$2:$M$32)
Name Slicer_Day: #N/A
Name Slicer_Day1: #N/A
Name Slicer_Day11: #N/A
Name Slicer_Day2: #N/A
Name Slicer_DayA: #N/A
Name Slicer_Manager: #N/A
Name Slicer_Month: #N/A
Name Slicer_Month1: #N/A
Name Slicer_Month11: #N/A
Name Slicer_Month2: #N/A
Name Slicer_MonthA: #N/A

Sheet LOGOUT
C6: Email
C7: alex19XX@gmail.com
C8: Password
C9: a12345

Sheet A
C6: Email
C7: markmanager2-19XX@gmail.com
C8: Password
C9: Mmanag-2

Sheet M1
C6: Email
C7: markmanager2-19XX@gmail.com
C8: Password
C9: e12345

Sheet M2
C6: Email
C7: alex19XX@gmail.com
C8: Password
C9: a12345

Sheet M3
C6: Email
C7: admin
C8: Password
C9: Mmanag-2

Sheet M4
C6: Email
C7: admin
C8: Password
C9: admin

Sheet DataA
O1: ADP | U1: CRM | AA1: Credit Card | AK1: Bank Account | AU1: Cash | BE1: Bitcoin
A2: Date | B2: Month | C2: Day | D2: Sales | E2: Credit Card | F2: Bank Account | G2: Cash | H2: Bitcoin | I2: Seasonal Days | J2: CAC | K2: ROI | L2: CPA | M2: EPC | N2: APR | O2: StrategyA | P2: TestingA | Q2: DevelopmentA | R2: ResearchA | S2: DesignA | T2: SMMA | U2: StrategyC | V2: TestingC | W2: DevelopmentC | X2: ResearchC | Y2: DesignC | Z2: SMMC | AA2: NEW YORK-CC | AB2: NASHVILLE-CC | AC2: CHICAGO-CC | AD2: DALLAS-CC | AE2: DENVER-CC | AF2: LOS ANGELES-CC | AG2: SAN FRANCISCO-CC | AH2: SEATTLE-CC | AI2: MIAMI-CC | AJ2: SAINT AUGUSTINE-CC | AK2: NEW YORK-BA | AL2: NASHVILLE-BA | AM2: CHICAGO-BA | AN2: DALLAS-BA | AO2: DENVER-BA | AP2: LOS ANGELES-BA | AQ2: SAN FRANCISCO-BA | AR2: SEATTLE-BA | AS2: MIAMI-BA | AT2: SAINT AUGUSTINE-BA | AU2: NEW YORK-C | AV2: NASHVILLE-C | AW2: CHICAGO-C | AX2: DALLAS-C | AY2: DENVER-C | AZ2: LOS ANGELES-C | BA2: SAN FRANCISCO-C | BB2: SEATTLE-C | BC2: MIAMI-C | BD2: SAINT AUGUSTINE-C | BE2: NEW YORK-B | BF2: NASHVILLE-B | BG2: CHICAGO-B | BH2: DALLAS-B | BI2: DENVER-B | BJ2: LOS ANGELES-B | BK2: SAN FRANCISCO-B | BL2: SEATTLE-B | BM2: MIAMI-B | BN2: SAINT AUGUSTINE-B | BO2: Manager
A3: 44927 | B3: JANUARY | C3: 1 | D3: =SUM(E3:H3) -> 427.9 | E3: =SUM(BE3:BN3) -> 144.1 | F3: =SUM(AA3:AJ3) -> 122.1 | G3: =SUM(AU3:BD3) -> 56.1 | H3: =SUM(AL3:AT3) -> 105.6 | I3: 1 | J3: 0.429 | K3: 0.759 | L3: 0.88 | M3: 0.88 | N3: 1.045 | O3: 1.045 | P3: 0.825 | Q3: 0.682 | R3: 0.946 | S3: 1.056 | T3: 1.045 | U3: 0.99 | V3: 0.539 | W3: 1.001 | X3: 0.319 | Y3: 0.275 | Z3: 1.023 | AA3: 4.4 | AB3: 3.3 | AC3: 0 | AD3: 11 | AE3: 7.7 | AF3: 19.8 | AG3: 30.8 | AH3: 0 | AI3: 38.5 | AJ3: 6.6 | AK3: 0 | AL3: 0 | AM3: 15.4 | AN3: 7.7 | AO3: 0 | AP3: 22 | AQ3: 1.1 | AR3: 38.5 | AS3: 19.8 | AT3: 1.1 | AU3: 0 | AV3: 14.3 | AW3: 0 | AX3: 11 | AY3: 4.4 | AZ3: 0 | BA3: 1.1 | BB3: 0 | BC3: 13.2 | BD3: 12.1 | BE3: 0 | BF3: 20.9 | BG3: 3.3 | BH3: 13.2 | BI3: 11 | BJ3: 37.4 | BK3: 0 | BL3: 33 | BM3: 15.4 | BN3: 9.9 | BO3: Alex
A4: 44928 | B4: JANUARY | C4: 2 | D4: =SUM(E4:H4) -> 624.8 | E4: =SUM(BE4:BN4) -> 174.9 | F4: =SUM(AA4:AJ4) -> 198 | G4: =SUM(AU4:BD4) -> 104.5 | H4: =SUM(AL4:AT4) -> 147.4 | I4: 0 | J4: 1.012 | K4: 0.66 | L4: 0.847 | M4: 0.77 | N4: 0.55 | O4: 0.77 | P4: 0.792 | Q4: 1.001 | R4: 0.99 | S4: 0.616 | T4: 0.759 | U4: 0.957 | V4: 0.473 | W4: 0.495 | X4: 0.88 | Y4: 0.979 | Z4: 1.023 | AA4: 23.1 | AB4: 18.7 | AC4: 0 | AD4: 35.2 | AE4: 11 | AF4: 59.4 | AG4: 0 | AH4: 2.2 | AI4: 9.9 | AJ4: 38.5 | AK4: 9.9 | AL4: 37.4 | AM4: 33 | AN4: 7.7 | AO4: 17.6 | AP4: 0 | AQ4: 0 | AR4: 11 | AS4: 17.6 | AT4: 23.1 | AU4: 0 | AV4: 37.4 | AW4: 39.6 | AX4: 0 | AY4: 0 | AZ4: 18.7 | BA4: 5.5 | BB4: 0 | BC4: 3.3 | BD4: 0 | BE4: 1.1 | BF4: 12.1 | BG4: 4.4 | BH4: 22 | BI4: 16.5 | BJ4: 4.4 | BK4: 40.7 | BL4: 23.1 | BM4: 23.1 | BN4: 27.5 | BO4: Alex
A5: 44929 | B5: JANUARY | C5: 3 | D5: =SUM(E5:H5) -> 512.6 | E5: =SUM(BE5:BN5) -> 104.5 | F5: =SUM(AA5:AJ5) -> 129.8 | G5: =SUM(AU5:BD5) -> 166.1 | H5: =SUM(AL5:AT5) -> 112.2 | I5: 0 | J5: 1.034 | K5: 0.792 | L5: 0.737 | M5: 0.253 | N5: 0.902 | O5: 0.979 | P5: 0.979 | Q5: 0.737 | R5: 0.616 | S5: 0.825 | T5: 0.671 | U5: 1.089 | V5: 0.99 | W5: 0.44 | X5: 0.473 | Y5: 0.825 | Z5: 1.034 | AA5: 14.3 | AB5: 27.5 | AC5: 16.5 | AD5: 0 | AE5: 39.6 | AF5: 0 | AG5: 19.8 | AH5: 5.5 | AI5: 6.6 | AJ5: 0 | AK5: 33 | AL5: 1.1 | AM5: 0 | AN5: 0 | AO5: 0 | AP5: 16.5 | AQ5: 7.7 | AR5: 28.6 | AS5: 35.2 | AT5: 23.1 | AU5: 0 | AV5: 3.3 | AW5: 0 | AX5: 6.6 | AY5: 50.6 | AZ5: 19.8 | BA5: 17.6 | BB5: 0 | BC5: 23.1 | BD5: 45.1 | BE5: 22 | BF5: 3.3 | BG5: 13.2 | BH5: 9.9 | BI5: 6.6 | BJ5: 2.2 | BK5: 9.9 | BL5: 0 | BM5: 3.3 | BN5: 34.1 | BO5: Alex
A6: 44930 | B6: JANUARY | C6: 4 | D6: =SUM(E6:H6) -> 495 | E6: =SUM(BE6:BN6) -> 88 | F6: =SUM(AA6:AJ6) -> 152.9 | G6: =SUM(AU6:BD6) -> 198 | H6: =SUM(AL6:AT6) -> 56.1 | I6: 0 | J6: 0.319 | K6: 0.605 | L6: 0.561 | M6: 1.034 | N6: 1.023 | O6: 0.726 | P6: 0.66 | Q6: 0.77 | R6: 0.88 | S6: 0.814 | T6: 0.836 | U6: 0.748 | V6: 0.99 | W6: 0.638 | X6: 0.968 | Y6: 1.056 | Z6: 1.034 | AA6: 0 | AB6: 16.5 | AC6: 0 | AD6: 0 | AE6: 3.3 | AF6: 6.6 | AG6: 39.6 | AH6: 33 | AI6: 7.7 | AJ6: 46.2 | AK6: 3.3 | AL6: 0 | AM6: 11 | AN6: 0 | AO6: 0 | AP6: 0 | AQ6: 22 | AR6: 12.1 | AS6: 2.2 | AT6: 8.8 | AU6: 8.8 | AV6: 25.3 | AW6: 40.7 | AX6: 1.1 | AY6: 12.1 | AZ6: 5.5 | BA6: 44 | BB6: 11 | BC6: 45.1 | BD6: 4.4 | BE6: 11 | BF6: 4.4 | BG6: 31.9 | BH6: 0 | BI6: 4.4 | BJ6: 22 | BK6: 4.4 | BL6: 0 | BM6: 9.9 | BN6: 0 | BO6: Alex
A7: 44931 | B7: JANUARY | C7: 5 | D7: =SUM(E7:H7) -> 405.9 | E7: =SUM(BE7:BN7) -> 122.1 | F7: =SUM(AA7:AJ7) -> 136.4 | G7: =SUM(AU7:BD7) -> 107.8 | H7: =SUM(AL7:AT7) -> 39.6 | I7: 0 | J7: 0.253 | K7: 0.594 | L7: 0.825 | M7: 1.067 | N7: 1.023 | O7: 0.814 | P7: 0.11 | Q7: 0.748 | R7: 0.792 | S7: 0.715 | T7: 0.66 | U7: 0.341 | V7: 1.1 | W7: 1.045 | X7: 0.286 | Y7: 1.023 | Z7: 0.407 | AA7: 0 | AB7: 26.4 | AC7: 15.4 | AD7: 23.1 | AE7: 0 | AF7: 4.4 | AG7: 44 | AH7: 0 | AI7: 6.6 | AJ7: 16.5 | AK7: 0 | AL7: 0 | AM7: 0 | AN7: 17.6 | AO7: 0 | AP7: 0 | AQ7: 3.3 | AR7: 14.3 | AS7: 0 | AT7: 4.4 | AU7: 4.4 | AV7: 0 | AW7: 23.1 | AX7: 19.8 | AY7: 0 | AZ7: 15.4 | BA7: 0 | BB7: 16.5 | BC7: 0 | BD7: 28.6 | BE7: 27.5 | BF7: 1.1 | BG7: 14.3 | BH7: 14.3 | BI7: 0 | BJ7: 26.4 | BK7: 24.2 | BL7: 0 | BM7: 13.2 | BN7: 1.1 | BO7: Alex
A8: 44932 | B8: JANUARY | C8: 6 | D8: =SUM(E8:H8) -> 543.4 | E8: =SUM(BE8:BN8) -> 88 | F8: =SUM(AA8:AJ8) -> 125.4 | G8: =SUM(AU8:BD8) -> 188.1 | H8: =SUM(AL8:AT8) -> 141.9 | I8: 0 | J8: 0.649 | K8: 0.99 | L8: 0.825 | M8: 0.88 | N8: 0.957 | O8: 0.737 | P8: 0.726 | Q8: 0.792 | R8: 0.946 | S8: 0.792 | T8: 0.858 | U8: 0.165 | V8: 1.1 | W8: 0.33 | X8: 0.616 | Y8: 1.067 | Z8: 0.616 | AA8: 45.1 | AB8: 17.6 | AC8: 17.6 | AD8: 11 | AE8: 19.8 | AF8: 0 | AG8: 2.2 | AH8: 0 | AI8: 2.2 | AJ8: 9.9 | AK8: 47.3 | AL8: 31.9 | AM8: 0 | AN8: 0 | AO8: 0 | AP8: 30.8 | AQ8: 24.2 | AR8: 12.1 | AS8: 17.6 | AT8: 25.3 | AU8: 17.6 | AV8: 7.7 | AW8: 44 | AX8: 24.2 | AY8: 1.1 | AZ8: 4.4 | BA8: 6.6 | BB8: 48.4 | BC8: 34.1 | BD8: 0 | BE8: 11 | BF8: 8.8 | BG8: 0 | BH8: 0 | BI8: 15.4 | BJ8: 23.1 | BK8: 0 | BL8: 11 | BM8: 6.6 | BN8: 12.1 | BO8: Alex
A9: 44933 | B9: JANUARY | C9: 7 | D9: =SUM(E9:H9) -> 596.2 | E9: =SUM(BE9:BN9) -> 201.3 | F9: =SUM(AA9:AJ9) -> 114.4 | G9: =SUM(AU9:BD9) -> 179.3 | H9: =SUM(AL9:AT9) -> 101.2 | I9: 0 | J9: 0.682 | K9: 0.594 | L9: 0.22 | M9: 0.902 | N9: 1.012 | O9: 1.1 | P9: 0.605 | Q9: 0.935 | R9: 0.55 | S9: 0.66 | T9: 1.155 | U9: 1.056 | V9: 0.572 | W9: 0.803 | X9: 1.023 | Y9: 0.924 | Z9: 0.891 | AA9: 27.5 | AB9: 0 | AC9: 50.6 | AD9: 9.9 | AE9: 13.2 | AF9: 8.8 | AG9: 0 | AH9: 0 | AI9: 0 | AJ9: 4.4 | AK9: 59.4 | AL9: 1.1 | AM9: 5.5 | AN9: 3.3 | AO9: 26.4 | AP9: 39.6 | AQ9: 0 | AR9: 0 | AS9: 4.4 | AT9: 20.9 | AU9: 0 | AV9: 24.2 | AW9: 31.9 | AX9: 0 | AY9: 35.2 | AZ9: 0 | BA9: 26.4 | BB9: 1.1 | BC9: 36.3 | BD9: 24.2 | BE9: 23.1 | BF9: 4.4 | BG9: 2.2 | BH9: 0 | BI9: 28.6 | BJ9: 23.1 | BK9: 29.7 | BL9: 35.2 | BM9: 22 | BN9: 33 | BO9: Alex
A10: 44934 | B10: JANUARY | C10: 8 | D10: =SUM(E10:H10) -> 570.9 | E10: =SUM(BE10:BN10) -> 118.8 | F10: =SUM(AA10:AJ10) -> 125.4 | G10: =SUM(AU10:BD10) -> 204.6 | H10: =SUM(AL10:AT10) -> 122.1 | I10: 0 | J10: 0.836 | K10: 0.726 | L10: 0.935 | M10: 0.913 | N10: 0.748 | O10: 0.66 | P10: 0.825 | Q10: 0.66 | R10: 0.825 | S10: 0.528 | T10: 0.748 | U10: 0.418 | V10: 0.627 | W10: 0.451 | X10: 1.1 | Y10: 1.078 | Z10: 0.165 | AA10: 11 | AB10: 7.7 | AC10: 0 | AD10: 5.5 | AE10: 9.9 | AF10: 56.1 | AG10: 5.5 | AH10: 0 | AI10: 29.7 | AJ10: 0 | AK10: 13.2 | AL10: 0 | AM10: 0 | AN10: 0 | AO10: 14.3 | AP10: 0 | AQ10: 17.6 | AR10: 47.3 | AS10: 42.9 | AT10: 0 | AU10: 11 | AV10: 41.8 | AW10: 0 | AX10: 7.7 | AY10: 22 | AZ10: 26.4 | BA10: 42.9 | BB10: 37.4 | BC10: 15.4 | BD10: 0 | BE10: 0 | BF10: 3.3 | BG10: 31.9 | BH10: 14.3 | BI10: 13.2 | BJ10: 29.7 | BK10: 15.4 | BL10: 11 | BM10: 0 | BN10: 0 | BO10: Alex
A11: 44935 | B11: JANUARY | C11: 9 | D11: =SUM(E11:H11) -> 535.7 | E11: =SUM(BE11:BN11) -> 118.8 | F11: =SUM(AA11:AJ11) -> 139.7 | G11: =SUM(AU11:BD11) -> 144.1 | H11: =SUM(AL11:AT11) -> 133.1 | I11: 0 | J11: 0.297 | K11: 0.704 | L11: 0.869 | M11: 0.946 | N11: 1.023 | O11: 0.99 | P11: 0.781 | Q11: 0.638 | R11: 0.759 | S11: 0.781 | T11: 0.759 | U11: 0.616 | V11: 1.067 | W11: 1.001 | X11: 0.682 | Y11: 0.396 | Z11: 1.067 | AA11: 0 | AB11: 14.3 | AC11: 7.7 | AD11: 3.3 | AE11: 3.3 | AF11: 0 | AG11: 23.1 | AH11: 23.1 | AI11: 39.6 | AJ11: 25.3 | AK11: 29.7 | AL11: 0 | AM11: 18.7 | AN11: 34.1 | AO11: 0 | AP11: 6.6 | AQ11: 31.9 | AR11: 0 | AS11: 18.7 | AT11: 23.1 | AU11: 59.4 | AV11: 8.8 | AW11: 9.9 | AX11: 4.4 | AY11: 17.6 | AZ11: 9.9 | BA11: 0 | BB11: 13.2 | BC11: 18.7 | BD11: 2.2 | BE11: 9.9 | BF11: 16.5 | BG11: 5.5 | BH11: 17.6 | BI11: 57.2 | BJ11: 3.3 | BK11: 0 | BL11: 1.1 | BM11: 7.7 | BN11: 0 | BO11: Alex
A12: 44936 | B12: JANUARY | C12: 10 | D12: =SUM(E12:H12) -> 381.7 | E12: =SUM(BE12:BN12) -> 110 | F12: =SUM(AA12:AJ12) -> 113.3 | G12: =SUM(AU12:BD12) -> 71.5 | H12: =SUM(AL12:AT12) -> 86.9 | I12: 0 | J12: 0.528 | K12: 0.99 | L12: 0.792 | M12: 0.88 | N12: 1.089 | O12: 1.001 | P12: 1.089 | Q12: 0.803 | R12: 0.957 | S12: 0.693 | T12: 0.979 | U12: 0.891 | V12: 0.924 | W12: 0.99 | X12: 0.946 | Y12: 1.012 | Z12: 1.001 | AA12: 0 | AB12: 0 | AC12: 38.5 | AD12: 0 | AE12: 2.2 | AF12: 26.4 | AG12: 17.6 | AH12: 0 | AI12: 15.4 | AJ12: 13.2 | AK12: 22 | AL12: 29.7 | AM12: 14.3 | AN12: 3.3 | AO12: 8.8 | AP12: 1.1 | AQ12: 0 | AR12: 20.9 | AS12: 8.8 | AT12: 0 | AU12: 13.2 | AV12: 7.7 | AW12: 7.7 | AX12: 0 | AY12: 0 | AZ12: 0 | BA12: 0 | BB12: 34.1 | BC12: 8.8 | BD12: 0 | BE12: 4.4 | BF12: 26.4 | BG12: 0 | BH12: 30.8 | BI12: 11 | BJ12: 23.1 | BK12: 0 | BL12: 0 | BM12: 7.7 | BN12: 6.6 | BO12: Alex
A13: 44937 | B13: JANUARY | C13: 11 | D13: =SUM(E13:H13) -> 570.9 | E13: =SUM(BE13:BN13) -> 232.1 | F13: =SUM(AA13:AJ13) -> 121 | G13: =SUM(AU13:BD13) -> 141.9 | H13: =SUM(AL13:AT13) -> 75.9 | I13: 0 | J13: 0.55 | K13: 0.847 | L13: 0.825 | M13: 0.902 | N13: 0.99 | O13: 0.77 | P13: 0.858 | Q13: 0.605 | R13: 0.781 | S13: 0.825 | T13: 1.012 | U13: 0.451 | V13: 0.462 | W13: 0.968 | X13: 0.286 | Y13: 0.407 | Z13: 0.66 | AA13: 12.1 | AB13: 22 | AC13: 0 | AD13: 0 | AE13: 13.2 | AF13: 34.1 | AG13: 4.4 | AH13: 0 | AI13: 35.2 | AJ13: 0 | AK13: 4.4 | AL13: 0 | AM13: 27.5 | AN13: 0 | AO13: 5.5 | AP13: 6.6 | AQ13: 2.2 | AR13: 34.1 | AS13: 0 | AT13: 0 | AU13: 33 | AV13: 29.7 | AW13: 3.3 | AX13: 3.3 | AY13: 11 | AZ13: 0 | BA13: 20.9 | BB13: 0 | BC13: 30.8 | BD13: 9.9 | BE13: 25.3 | BF13: 8.8 | BG13: 34.1 | BH13: 55 | BI13: 0 | BJ13: 5.5 | BK13: 22 | BL13: 0 | BM13: 45.1 | BN13: 36.3 | BO13: Alex
A14: 44938 | B14: JANUARY | C14: 12 | D14: =SUM(E14:H14) -> 674.3 | E14: =SUM(BE14:BN14) -> 180.4 | F14: =SUM(AA14:AJ14) -> 158.4 | G14: =SUM(AU14:BD14) -> 215.6 | H14: =SUM(AL14:AT14) -> 119.9 | I14: 0 | J14: 0.528 | K14: 0.726 | L14: 1.001 | M14: 0.693 | N14: 0.22 | O14: 0.957 | P14: 0.88 | Q14: 1.067 | R14: 0.847 | S14: 0.539 | T14: 0.638 | U14: 0.825 | V14: 0.792 | W14: 0.99 | X14: 1.045 | Y14: 0.792 | Z14: 0.33 | AA14: 4.4 | AB14: 8.8 | AC14: 0 | AD14: 17.6 | AE14: 22 | AF14: 19.8 | AG14: 30.8 | AH14: 6.6 | AI14: 15.4 | AJ14: 33 | AK14: 37.4 | AL14: 14.3 | AM14: 6.6 | AN14: 18.7 | AO14: 0 | AP14: 6.6 | AQ14: 27.5 | AR14: 12.1 | AS14: 33 | AT14: 1.1 | AU14: 12.1 | AV14: 20.9 | AW14: 59.4 | AX14: 0 | AY14: 38.5 | AZ14: 8.8 | BA14: 6.6 | BB14: 4.4 | BC14: 28.6 | BD14: 36.3 | BE14: 12.1 | BF14: 0 | BG14: 18.7 | BH14: 7.7 | BI14: 22 | BJ14: 60.5 | BK14: 3.3 | BL14: 19.8 | BM14: 13.2 | BN14: 23.1 | BO14: Alex
... A33: 44957 | B33: JANUARY | C33: 31 | D33: =SUM(E33:H33) -> 430.1 | E33: =SUM(BE33:BN33) -> 101.2 | F33: =SUM(AA33:AJ33) -> 129.8 | G33: =SUM(AU33:BD33) -> 110 | H33: =SUM(AL33:AT33) -> 89.1 | I33: 0 | J33: 0.99 | K33: 1.023 | L33: 1.034 | M33: 0.726 | N33: 0.88 | O33: 0.66 | P33: 0.792 | Q33: 0.726 | R33: 1.023 | S33: 0.979 | T33: 0.638 | U33: 0.814 | V33: 0.605 | W33: 1.078 | X33: 1.045 | Y33: 1.089 | Z33: 0.627 | AA33: 0 | AB33: 33 | AC33: 5.5 | AD33: 15.4 | AE33: 16.5 | AF33: 5.5 | AG33: 38.5 | AH33: 0 | AI33: 1.1 | AJ33: 14.3 | AK33: 3.3 | AL33: 28.6 | AM33: 5.5 | AN33: 0 | AO33: 12.1 | AP33: 4.4 | AQ33: 12.1 | AR33: 17.6 | AS33: 8.8 | AT33: 0 | AU33: 4.4 | AV33: 18.7 | AW33: 2.2 | AX33: 1.1 | AY33: 45.1 | AZ33: 0 | BA33: 0 | BB33: 7.7 | BC33: 25.3 | BD33: 5.5 | BE33: 3.3 | BF33: 6.6 | BG33: 23.1 | BH33: 25.3 | BI33: 9.9 | BJ33: 22 | BK33: 6.6 | BL33: 0 | BM33: 4.4 | BN33: 0 | BO33: Alex
B34: FEBRUARY | C34: 1e-08 | D34: =SUM(E34:H34) -> 0 | E34: 0 | F34: 0 | G34: 0 | H34: 0 | I34: 0 | J34: 0 | K34: 0 | L34: 0 | M34: 0 | N34: 0 | O34: 0 | P34: 0 | Q34: 0 | R34: 0 | S34: 0 | T34: 0 | U34: 0 | V34: 0 | W34: 0 | X34: 0 | Y34: 0 | Z34: 0 | AA34: 0 | AB34: 0 | AC34: 0 | AD34: 0 | AE34: 0 | AF34: 0 | AG34: 0 | AH34: 0 | AI34: 0 | AJ34: 0 | AK34: 0 | AL34: 0 | AM34: 0 | AN34: 0 | AO34: 0 | AP34: 0 | AQ34: 0 | AR34: 0 | AS34: 0 | AT34: 0 | AU34: 0 | AV34: 0 | AW34: 0 | AX34: 0 | AY34: 0 | AZ34: 0 | BA34: 0 | BB34: 0 | BC34: 0 | BD34: 0 | BE34: 0 | BF34: 0 | BG34: 0 | BH34: 0 | BI34: 0 | BJ34: 0 | BK34: 0 | BL34: 0 | BM34: 0 | BN34: 0
B35: FEBRUARY | C35: 2e-08 | D35: =SUM(E35:H35) -> 0 | E35: 0 | F35: 0 | G35: 0 | H35: 0 | I35: 0 | J35: 0 | K35: 0 | L35: 0 | M35: 0 | N35: 0 | O35: 0 | P35: 0 | Q35: 0 | R35: 0 | S35: 0 | T35: 0 | U35: 0 | V35: 0 | W35: 0 | X35: 0 | Y35: 0 | Z35: 0 | AA35: 0 | AB35: 0 | AC35: 0 | AD35: 0 | AE35: 0 | AF35: 0 | AG35: 0 | AH35: 0 | AI35: 0 | AJ35: 0 | AK35: 0 | AL35: 0 | AM35: 0 | AN35: 0 | AO35: 0 | AP35: 0 | AQ35: 0 | AR35: 0 | AS35: 0 | AT35: 0 | AU35: 0 | AV35: 0 | AW35: 0 | AX35: 0 | AY35: 0 | AZ35: 0 | BA35: 0 | BB35: 0 | BC35: 0 | BD35: 0 | BE35: 0 | BF35: 0 | BG35: 0 | BH35: 0 | BI35: 0 | BJ35: 0 | BK35: 0 | BL35: 0 | BM35: 0 | BN35: 0
B36: FEBRUARY | C36: 3e-08 | D36: =SUM(E36:H36) -> 0 | E36: 0 | F36: 0 | G36: 0 | H36: 0 | I36: 0 | J36: 0 | K36: 0 | L36: 0 | M36: 0 | N36: 0 | O36: 0 | P36: 0 | Q36: 0 | R36: 0 | S36: 0 | T36: 0 | U36: 0 | V36: 0 | W36: 0 | X36: 0 | Y36: 0 | Z36: 0 | AA36: 0 | AB36: 0 | AC36: 0 | AD36: 0 | AE36: 0 | AF36: 0 | AG36: 0 | AH36: 0 | AI36: 0 | AJ36: 0 | AK36: 0 | AL36: 0 | AM36: 0 | AN36: 0 | AO36: 0 | AP36: 0 | AQ36: 0 | AR36: 0 | AS36: 0 | AT36: 0 | AU36: 0 | AV36: 0 | AW36: 0 | AX36: 0 | AY36: 0 | AZ36: 0 | BA36: 0 | BB36: 0 | BC36: 0 | BD36: 0 | BE36: 0 | BF36: 0 | BG36: 0 | BH36: 0 | BI36: 0 | BJ36: 0 | BK36: 0 | BL36: 0 | BM36: 0 | BN36: 0
A37: 44958 | B37: FEBRUARY | C37: 1 | D37: =SUM(E37:H37) -> 588.5 | E37: =SUM(BE37:BN37) -> 72.6 | F37: =SUM(AA37:AJ37) -> 121 | G37: =SUM(AU37:BD37) -> 146.3 | H37: =SUM(AL37:AT37) -> 248.6 | I37: 0 | J37: 0.198 | K37: 0.957 | L37: 0.88 | M37: 0.693 | N37: 1.078 | O37: 0.66 | P37: 0.792 | Q37: 0.748 | R37: 0.462 | S37: 0.517 | T37: 0.869 | U37: 0.979 | V37: 1.034 | W37: 0.88 | X37: 1.034 | Y37: 0.715 | Z37: 1.001 | AA37: 49.5 | AB37: 33 | AC37: 13.2 | AD37: 0 | AE37: 12.1 | AF37: 0 | AG37: 0 | AH37: 0 | AI37: 12.1 | AJ37: 1.1 | AK37: 47.3 | AL37: 48.4 | AM37: 47.3 | AN37: 36.3 | AO37: 0 | AP37: 53.9 | AQ37: 23.1 | AR37: 15.4 | AS37: 1.1 | AT37: 23.1 | AU37: 6.6 | AV37: 13.2 | AW37: 33 | AX37: 27.5 | AY37: 0 | AZ37: 8.8 | BA37: 1.1 | BB37: 2.2 | BC37: 14.3 | BD37: 39.6 | BE37: 5.5 | BF37: 0 | BG37: 3.3 | BH37: 0 | BI37: 3.3 | BJ37: 24.2 | BK37: 16.5 | BL37: 1.1 | BM37: 18.7 | BN37: 0 | BO37: Alex
A38: 44959 | B38: FEBRUARY | C38: 2 | D38: =SUM(E38:H38) -> 563.2 | E38: =SUM(BE38:BN38) -> 158.4 | F38: =SUM(AA38:AJ38) -> 144.1 | G38: =SUM(AU38:BD38) -> 101.2 | H38: =SUM(AL38:AT38) -> 159.5 | I38: 1 | J38: 0.517 | K38: 0.583 | L38: 0.99 | M38: 0.858 | N38: 0.748 | O38: 1.001 | P38: 0.726 | Q38: 0.935 | R38: 0.671 | S38: 0.704 | T38: 0.682 | U38: 0.473 | V38: 0.495 | W38: 0.814 | X38: 0.946 | Y38: 0.319 | Z38: 1.056 | AA38: 2.2 | AB38: 0 | AC38: 0 | AD38: 22 | AE38: 19.8 | AF38: 37.4 | AG38: 19.8 | AH38: 19.8 | AI38: 9.9 | AJ38: 13.2 | AK38: 37.4 | AL38: 13.2 | AM38: 17.6 | AN38: 24.2 | AO38: 3.3 | AP38: 36.3 | AQ38: 8.8 | AR38: 0 | AS38: 23.1 | AT38: 33 | AU38: 0 | AV38: 0 | AW38: 13.2 | AX38: 42.9 | AY38: 4.4 | AZ38: 0 | BA38: 12.1 | BB38: 0 | BC38: 5.5 | BD38: 23.1 | BE38: 3.3 | BF38: 46.2 | BG38: 24.2 | BH38: 0 | BI38: 1.1 | BJ38: 0 | BK38: 0 | BL38: 42.9 | BM38: 35.2 | BN38: 5.5 | BO38: Alex
A39: 44960 | B39: FEBRUARY | C39: 3 | D39: =SUM(E39:H39) -> 497.2 | E39: =SUM(BE39:BN39) -> 167.2 | F39: =SUM(AA39:AJ39) -> 173.8 | G39: =SUM(AU39:BD39) -> 68.2 | H39: =SUM(AL39:AT39) -> 88 | I39: 0 | J39: 0.605 | K39: 0.748 | L39: 0.781 | M39: 0.946 | N39: 0.737 | O39: 1.012 | P39: 0.66 | Q39: 0.451 | R39: 1.089 | S39: 1.023 | T39: 0.77 | U39: 1.1 | V39: 1.067 | W39: 1.001 | X39: 0.473 | Y39: 0.484 | Z39: 1.089 | AA39: 1.1 | AB39: 12.1 | AC39: 26.4 | AD39: 23.1 | AE39: 26.4 | AF39: 22 | AG39: 0 | AH39: 40.7 | AI39: 8.8 | AJ39: 13.2 | AK39: 2.2 | AL39: 8.8 | AM39: 0 | AN39: 3.3 | AO39: 17.6 | AP39: 0 | AQ39: 0 | AR39: 50.6 | AS39: 7.7 | AT39: 0 | AU39: 0 | AV39: 3.3 | AW39: 0 | AX39: 7.7 | AY39: 0 | AZ39: 0 | BA39: 30.8 | BB39: 0 | BC39: 26.4 | BD39: 0 | BE39: 8.8 | BF39: 0 | BG39: 37.4 | BH39: 17.6 | BI39: 0 | BJ39: 1.1 | BK39: 37.4 | BL39: 0 | BM39: 49.5 | BN39: 15.4 | BO39: Alex
A40: 44961 | B40: FEBRUARY | C40: 4 | D40: =SUM(E40:H40) -> 524.7 | E40: =SUM(BE40:BN40) -> 141.9 | F40: =SUM(AA40:AJ40) -> 117.7 | G40: =SUM(AU40:BD40) -> 152.9 | H40: =SUM(AL40:AT40) -> 112.2 | I40: 0 | J40: 0.473 | K40: 0.517 | L40: 0.957 | M40: 0.836 | N40: 1.023 | O40: 0.715 | P40: 0.803 | Q40: 0.704 | R40: 0.869 | S40: 0.902 | T40: 0.682 | U40: 0.374 | V40: 1.001 | W40: 0.869 | X40: 0.396 | Y40: 1.067 | Z40: 0.858 | AA40: 7.7 | AB40: 35.2 | AC40: 6.6 | AD40: 24.2 | AE40: 12.1 | AF40: 18.7 | AG40: 13.2 | AH40: 0 | AI40: 0 | AJ40: 0 | AK40: 4.4 | AL40: 9.9 | AM40: 52.8 | AN40: 27.5 | AO40: 9.9 | AP40: 12.1 | AQ40: 0 | AR40: 0 | AS40: 0 | AT40: 0 | AU40: 19.8 | AV40: 19.8 | AW40: 39.6 | AX40: 9.9 | AY40: 0 | AZ40: 5.5 | BA40: 7.7 | BB40: 11 | BC40: 33 | BD40: 6.6 | BE40: 1.1 | BF40: 4.4 | BG40: 19.8 | BH40: 39.6 | BI40: 0 | BJ40: 25.3 | BK40: 1.1 | BL40: 44 | BM40: 6.6 | BN40: 0 | BO40: Alex
A41: 44962 | B41: FEBRUARY | C41: 5 | D41: =SUM(E41:H41) -> 591.8 | E41: =SUM(BE41:BN41) -> 166.1 | F41: =SUM(AA41:AJ41) -> 103.4 | G41: =SUM(AU41:BD41) -> 205.7 | H41: =SUM(AL41:AT41) -> 116.6 | I41: 0 | J41: 0.759 | K41: 0.55 | L41: 0.385 | M41: 0.847 | N41: 0.44 | O41: 0.946 | P41: 0.286 | Q41: 1.034 | R41: 0.616 | S41: 0.792 | T41: 0.968 | U41: 0.495 | V41: 1.089 | W41: 0.858 | X41: 0.825 | Y41: 0.407 | Z41: 1.023 | AA41: 9.9 | AB41: 11 | AC41: 4.4 | AD41: 0 | AE41: 16.5 | AF41: 4.4 | AG41: 13.2 | AH41: 16.5 | AI41: 26.4 | AJ41: 1.1 | AK41: 7.7 | AL41: 9.9 | AM41: 0 | AN41: 0 | AO41: 2.2 | AP41: 18.7 | AQ41: 27.5 | AR41: 0 | AS41: 41.8 | AT41: 16.5 | AU41: 20.9 | AV41: 41.8 | AW41: 31.9 | AX41: 3.3 | AY41: 35.2 | AZ41: 0 | BA41: 0 | BB41: 15.4 | BC41: 6.6 | BD41: 50.6 | BE41: 24.2 | BF41: 15.4 | BG41: 3.3 | BH41: 13.2 | BI41: 22 | BJ41: 9.9 | BK41: 2.2 | BL41: 0 | BM41: 68.2 | BN41: 7.7 | BO41: Alex
A42: 44963 | B42: FEBRUARY | C42: 6 | D42: =SUM(E42:H42) -> 640.2 | E42: =SUM(BE42:BN42) -> 133.1 | F42: =SUM(AA42:AJ42) -> 227.7 | G42: =SUM(AU42:BD42) -> 161.7 | H42: =SUM(AL42:AT42) -> 117.7 | I42: 0 | J42: 0.231 | K42: 0.275 | L42: 0.792 | M42: 0.88 | N42: 1.056 | O42: 1.045 | P42: 0.363 | Q42: 0.638 | R42: 1.023 | S42: 0.671 | T42: 0.649 | U42: 0.649 | V42: 0.308 | W42: 0.462 | X42: 0.99 | Y42: 0.737 | Z42: 0.429 | AA42: 5.5 | AB42: 46.2 | AC42: 0 | AD42: 44 | AE42: 0 | AF42: 17.6 | AG42: 46.2 | AH42: 8.8 | AI42: 27.5 | AJ42: 31.9 | AK42: 16.5 | AL42: 0 | AM42: 4.4 | AN42: 44 | AO42: 22 | AP42: 16.5 | AQ42: 0 | AR42: 0 | AS42: 30.8 | AT42: 0 | AU42: 47.3 | AV42: 22 | AW42: 19.8 | AX42: 5.5 | AY42: 7.7 | AZ42: 0 | BA42: 2.2 | BB42: 50.6 | BC42: 3.3 | BD42: 3.3 | BE42: 0 | BF42: 17.6 | BG42: 2.2 | BH42: 44 | BI42: 4.4 | BJ42: 35.2 | BK42: 0 | BL42: 0 | BM42: 29.7 | BN42: 0 | BO42: Alex
A43: 44964 | B43: FEBRUARY | C43: 7 | D43: =SUM(E43:H43) -> 402.6 | E43: =SUM(BE43:BN43) -> 117.7 | F43: =SUM(AA43:AJ43) -> 61.6 | G43: =SUM(AU43:BD43) -> 122.1 | H43: =SUM(AL43:AT43) -> 101.2 | I43: 0 | J43: 0.781 | K43: 0.99 | L43: 1.089 | M43: 1.001 | N43: 1.067 | O43: 0.814 | P43: 0.77 | Q43: 1.089 | R43: 1.045 | S43: 0.781 | T43: 0.781 | U43: 0.715 | V43: 0.451 | W43: 0.99 | X43: 0.308 | Y43: 1.078 | Z43: 0.308 | AA43: 17.6 | AB43: 2.2 | AC43: 9.9 | AD43: 0 | AE43: 0 | AF43: 15.4 | AG43: 4.4 | AH43: 8.8 | AI43: 0 | AJ43: 3.3 | AK43: 5.5 | AL43: 8.8 | AM43: 0 | AN43: 0 | AO43: 9.9 | AP43: 5.5 | AQ43: 0 | AR43: 1.1 | AS43: 59.4 | AT43: 16.5 | AU43: 0 | AV43: 0 | AW43: 41.8 | AX43: 13.2 | AY43: 42.9 | AZ43: 6.6 | BA43: 0 | BB43: 0 | BC43: 2.2 | BD43: 15.4 | BE43: 11 | BF43: 24.2 | BG43: 38.5 | BH43: 11 | BI43: 0 | BJ43: 29.7 | BK43: 3.3 | BL43: 0 | BM43: 0 | BN43: 0 | BO43: Alex
A44: 44965 | B44: FEBRUARY | C44: 8 | D44: =SUM(E44:H44) -> 532.4 | E44: =SUM(BE44:BN44) -> 138.6 | F44: =SUM(AA44:AJ44) -> 181.5 | G44: =SUM(AU44:BD44) -> 190.3 | H44: =SUM(AL44:AT44) -> 22 | I44: 0 | J44: 0.528 | K44: 0.825 | L44: 0.814 | M44: 0.924 | N44: 0.275 | O44: 0.473 | P44: 0.957 | Q44: 0.671 | R44: 0.132 | S44: 0.693 | T44: 0.913 | U44: 0.88 | V44: 0.616 | W44: 0.99 | X44: 1.012 | Y44: 0.935 | Z44: 0.935 | AA44: 0 | AB44: 38.5 | AC44: 0 | AD44: 1.1 | AE44: 23.1 | AF44: 34.1 | AG44: 0 | AH44: 6.6 | AI44: 38.5 | AJ44: 39.6 | AK44: 1.1 | AL44: 0 | AM44: 0 | AN44: 0 | AO44: 5.5 | AP44: 0 | AQ44: 0 | AR44: 0 | AS44: 8.8 | AT44: 7.7 | AU44: 22 | AV44: 20.9 | AW44: 37.4 | AX44: 41.8 | AY44: 22 | AZ44: 0 | BA44: 5.5 | BB44: 40.7 | BC44: 0 | BD44: 0 | BE44: 11 | BF44: 3.3 | BG44: 0 | BH44: 46.2 | BI44: 4.4 | BJ44: 14.3 | BK44: 0 | BL44: 3.3 | BM44: 18.7 | BN44: 37.4 | BO44: Alex
A45: 44966 | B45: FEBRUARY | C45: 9 | D45: =SUM(E45:H45) -> 519.2 | E45: =SUM(BE45:BN45) -> 73.7 | F45: =SUM(AA45:AJ45) -> 172.7 | G45: =SUM(AU45:BD45) -> 147.4 | H45: =SUM(AL45:AT45) -> 125.4 | I45: 0 | J45: 0.275 | K45: 0.605 | L45: 0.814 | M45: 0.924 | N45: 0.99 | O45: 0.792 | P45: 0.671 | Q45: 0.847 | R45: 0.22 | S45: 0.11 | T45: 0.66 | U45: 0.649 | V45: 0.605 | W45: 1.034 | X45: 0.968 | Y45: 0.319 | Z45: 0.44 | AA45: 11 | AB45: 30.8 | AC45: 0 | AD45: 14.3 | AE45: 25.3 | AF45: 23.1 | AG45: 6.6 | AH45: 53.9 | AI45: 0 | AJ45: 7.7 | AK45: 14.3 | AL45: 36.3 | AM45: 17.6 | AN45: 17.6 | AO45: 18.7 | AP45: 17.6 | AQ45: 0 | AR45: 0 | AS45: 0 | AT45: 17.6 | AU45: 20.9 | AV45: 16.5 | AW45: 47.3 | AX45: 22 | AY45: 7.7 | AZ45: 0 | BA45: 0 | BB45: 33 | BC45: 0 | BD45: 0 | BE45: 0 | BF45: 30.8 | BG45: 0 | BH45: 0 | BI45: 18.7 | BJ45: 1.1 | BK45: 0 | BL45: 18.7 | BM45: 0 | BN45: 4.4 | BO45: Alex
A46: 44967 | B46: FEBRUARY | C46: 10 | D46: =SUM(E46:H46) -> 647.9 | E46: =SUM(BE46:BN46) -> 234.3 | F46: =SUM(AA46:AJ46) -> 152.9 | G46: =SUM(AU46:BD46) -> 134.2 | H46: =SUM(AL46:AT46) -> 126.5 | I46: 0 | J46: 0.418 | K46: 0.891 | L46: 1.089 | M46: 0.99 | N46: 1.045 | O46: 0.902 | P46: 0.858 | Q46: 0.737 | R46: 0.979 | S46: 0.726 | T46: 0.847 | U46: 0.979 | V46: 1.078 | W46: 0.946 | X46: 1.089 | Y46: 1.012 | Z46: 0.638 | AA46: 0 | AB46: 5.5 | AC46: 24.2 | AD46: 23.1 | AE46: 15.4 | AF46: 28.6 | AG46: 18.7 | AH46: 24.2 | AI46: 9.9 | AJ46: 3.3 | AK46: 4.4 | AL46: 23.1 | AM46: 23.1 | AN46: 0 | AO46: 0 | AP46: 20.9 | AQ46: 17.6 | AR46: 0 | AS46: 22 | AT46: 19.8 | AU46: 16.5 | AV46: 20.9 | AW46: 17.6 | AX46: 6.6 | AY46: 0 | AZ46: 0 | BA46: 0 | BB46: 31.9 | BC46: 40.7 | BD46: 0 | BE46: 24.2 | BF46: 0 | BG46: 30.8 | BH46: 30.8 | BI46: 16.5 | BJ46: 51.7 | BK46: 0 | BL46: 20.9 | BM46: 20.9 | BN46: 38.5 | BO46: Alex
A47: 44968 | B47: FEBRUARY | C47: 11 | D47: =SUM(E47:H47) -> 588.5 | E47: =SUM(BE47:BN47) -> 144.1 | F47: =SUM(AA47:AJ47) -> 213.4 | G47: =SUM(AU47:BD47) -> 70.4 | H47: =SUM(AL47:AT47) -> 160.6 | I47: 0 | J47: 0.77 | K47: 0.825 | L47: 0.913 | M47: 1.045 | N47: 1.012 | O47: 0.803 | P47: 0.847 | Q47: 0.825 | R47: 0.814 | S47: 0.891 | T47: 1.078 | U47: 0.473 | V47: 1.1 | W47: 0.825 | X47: 0.594 | Y47: 1.067 | Z47: 0.979 | AA47: 15.4 | AB47: 2.2 | AC47: 29.7 | AD47: 28.6 | AE47: 0 | AF47: 19.8 | AG47: 11 | AH47: 39.6 | AI47: 4.4 | AJ47: 62.7 | AK47: 26.4 | AL47: 17.6 | AM47: 16.5 | AN47: 45.1 | AO47: 0 | AP47: 42.9 | AQ47: 23.1 | AR47: 12.1 | AS47: 3.3 | AT47: 0 | AU47: 34.1 | AV47: 0 | AW47: 0 | AX47: 6.6 | AY47: 6.6 | AZ47: 5.5 | BA47: 2.2 | BB47: 0 | BC47: 14.3 | BD47: 1.1 | BE47: 0 | BF47: 12.1 | BG47: 12.1 | BH47: 5.5 | BI47: 6.6 | BJ47: 0 | BK47: 1.1 | BL47: 35.2 | BM47: 36.3 | BN47: 35.2 | BO47: Alex
A48: 44969 | B48: FEBRUARY | C48: 12 | D48: =SUM(E48:H48) -> 618.2 | E48: =SUM(BE48:BN48) -> 156.2 | F48: =SUM(AA48:AJ48) -> 113.3 | G48: =SUM(AU48:BD48) -> 173.8 | H48: =SUM(AL48:AT48) -> 174.9 | I48: 0 | J48: 0.528 | K48: 0.561 | L48: 0.803 | M48: 0.803 | N48: 0.99 | O48: 0.363 | P48: 0.759 | Q48: 0.649 | R48: 0.682 | S48: 0.759 | T48: 0.781 | U48: 1.067 | V48: 0.352 | W48: 0.913 | X48: 0.869 | Y48: 0.275 | Z48: 0.946 | AA48: 17.6 | AB48: 0 | AC48: 4.4 | AD48: 0 | AE48: 0 | AF48: 11 | AG48: 39.6 | AH48: 0 | AI48: 0 | AJ48: 40.7 | AK48: 6.6 | AL48: 7.7 | AM48: 37.4 | AN48: 0 | AO48: 0 | AP48: 41.8 | AQ48: 46.2 | AR48: 0 | AS48: 8.8 | AT48: 33 | AU48: 6.6 | AV48: 0 | AW48: 61.6 | AX48: 8.8 | AY48: 4.4 | AZ48: 0 | BA48: 25.3 | BB48: 0 | BC48: 60.5 | BD48: 6.6 | BE48: 4.4 | BF48: 25.3 | BG48: 17.6 | BH48: 6.6 | BI48: 25.3 | BJ48: 28.6 | BK48: 14.3 | BL48: 6.6 | BM48: 0 | BN48: 27.5 | BO48: Alex
... A64: 44985 | B64: FEBRUARY | C64: 28 | D64: =SUM(E64:H64) -> 431.2 | E64: =SUM(BE64:BN64) -> 138.6 | F64: =SUM(AA64:AJ64) -> 90.2 | G64: =SUM(AU64:BD64) -> 135.3 | H64: =SUM(AL64:AT64) -> 67.1 | I64: 0 | J64: 0.638 | K64: 0.638 | L64: 0.825 | M64: 0.968 | N64: 0.935 | O64: 0.748 | P64: 0.792 | Q64: 0.88 | R64: 1.089 | S64: 0.726 | T64: 0.792 | U64: 1.012 | V64: 1.1 | W64: 0.495 | X64: 0.836 | Y64: 0.638 | Z64: 0.451 | AA64: 35.2 | AB64: 3.3 | AC64: 0 | AD64: 3.3 | AE64: 44 | AF64: 0 | AG64: 0 | AH64: 0 | AI64: 4.4 | AJ64: 0 | AK64: 24.2 | AL64: 0 | AM64: 0 | AN64: 0 | AO64: 8.8 | AP64: 30.8 | AQ64: 0 | AR64: 5.5 | AS64: 8.8 | AT64: 13.2 | AU64: 8.8 | AV64: 14.3 | AW64: 12.1 | AX64: 12.1 | AY64: 13.2 | AZ64: 6.6 | BA64: 23.1 | BB64: 0 | BC64: 30.8 | BD64: 14.3 | BE64: 23.1 | BF64: 4.4 | BG64: 28.6 | BH64: 17.6 | BI64: 15.4 | BJ64: 6.6 | BK64: 7.7 | BL64: 0 | BM64: 20.9 | BN64: 14.3 | BO64: Alex
B65: MARCH | C65: 0.01 | D65: =SUM(E65:H65) -> 0 | E65: 0 | F65: 0 | G65: 0 | H65: 0 | I65: 0 | J65: 0 | K65: 0 | L65: 0 | M65: 0 | N65: 0 | O65: 0 | P65: 0 | Q65: 0 | R65: 0 | S65: 0 | T65: 0 | U65: 0 | V65: 0 | W65: 0 | X65: 0 | Y65: 0 | Z65: 0 | AA65: 0 | AB65: 0 | AC65: 0 | AD65: 0 | AE65: 0 | AF65: 0 | AG65: 0 | AH65: 0 | AI65: 0 | AJ65: 0 | AK65: 0 | AL65: 0 | AM65: 0 | AN65: 0 | AO65: 0 | AP65: 0 | AQ65: 0 | AR65: 0 | AS65: 0 | AT65: 0 | AU65: 0 | AV65: 0 | AW65: 0 | AX65: 0 | AY65: 0 | AZ65: 0 | BA65: 0 | BB65: 0 | BC65: 0 | BD65: 0 | BE65: 0 | BF65: 0 | BG65: 0 | BH65: 0 | BI65: 0 | BJ65: 0 | BK65: 0 | BL65: 0 | BM65: 0 | BN65: 0
B66: MARCH | C66: 0.02 | D66: =SUM(E66:H66) -> 0 | E66: 0 | F66: 0 | G66: 0 | H66: 0 | I66: 0 | J66: 0 | K66: 0 | L66: 0 | M66: 0 | N66: 0 | O66: 0 | P66: 0 | Q66: 0 | R66: 0 | S66: 0 | T66: 0 | U66: 0 | V66: 0 | W66: 0 | X66: 0 | Y66: 0 | Z66: 0 | AA66: 0 | AB66: 0 | AC66: 0 | AD66: 0 | AE66: 0 | AF66: 0 | AG66: 0 | AH66: 0 | AI66: 0 | AJ66: 0 | AK66: 0 | AL66: 0 | AM66: 0 | AN66: 0 | AO66: 0 | AP66: 0 | AQ66: 0 | AR66: 0 | AS66: 0 | AT66: 0 | AU66: 0 | AV66: 0 | AW66: 0 | AX66: 0 | AY66: 0 | AZ66: 0 | BA66: 0 | BB66: 0 | BC66: 0 | BD66: 0 | BE66: 0 | BF66: 0 | BG66: 0 | BH66: 0 | BI66: 0 | BJ66: 0 | BK66: 0 | BL66: 0 | BM66: 0 | BN66: 0
B67: MARCH | C67: 0.03 | D67: =SUM(E67:H67) -> 0 | E67: 0 | F67: 0 | G67: 0 | H67: 0 | I67: 0 | J67: 0 | K67: 0 | L67: 0 | M67: 0 | N67: 0 | O67: 0 | P67: 0 | Q67: 0 | R67: 0 | S67: 0 | T67: 0 | U67: 0 | V67: 0 | W67: 0 | X67: 0 | Y67: 0 | Z67: 0 | AA67: 0 | AB67: 0 | AC67: 0 | AD67: 0 | AE67: 0 | AF67: 0 | AG67: 0 | AH67: 0 | AI67: 0 | AJ67: 0 | AK67: 0 | AL67: 0 | AM67: 0 | AN67: 0 | AO67: 0 | AP67: 0 | AQ67: 0 | AR67: 0 | AS67: 0 | AT67: 0 | AU67: 0 | AV67: 0 | AW67: 0 | AX67: 0 | AY67: 0 | AZ67: 0 | BA67: 0 | BB67: 0 | BC67: 0 | BD67: 0 | BE67: 0 | BF67: 0 | BG67: 0 | BH67: 0 | BI67: 0 | BJ67: 0 | BK67: 0 | BL67: 0 | BM67: 0 | BN67: 0
A68: 44986 | B68: MARCH | C68: 1 | D68: =SUM(E68:H68) -> 405.9 | E68: =SUM(BE68:BN68) -> 58.3 | F68: =SUM(AA68:AJ68) -> 135.3 | G68: =SUM(AU68:BD68) -> 101.2 | H68: =SUM(AL68:AT68) -> 111.1 | I68: 0 | J68: 0.495 | K68: 0.88 | L68: 0.198 | M68: 0.99 | N68: 1.012 | O68: 0.627 | P68: 0.957 | Q68: 0.803 | R68: 0.88 | S68: 0.748 | T68: 0.715 | U68: 0.165 | V68: 1.001 | W68: 1.067 | X68: 0.781 | Y68: 0.297 | Z68: 0.924 | AA68: 4.4 | AB68: 8.8 | AC68: 3.3 | AD68: 5.5 | AE68: 0 | AF68: 0 | AG68: 18.7 | AH68: 27.5 | AI68: 42.9 | AJ68: 24.2 | AK68: 0 | AL68: 6.6 | AM68: 2.2 | AN68: 4.4 | AO68: 12.1 | AP68: 2.2 | AQ68: 0 | AR68: 23.1 | AS68: 0 | AT68: 60.5 | AU68: 6.6 | AV68: 6.6 | AW68: 0 | AX68: 6.6 | AY68: 0 | AZ68: 14.3 | BA68: 0 | BB68: 34.1 | BC68: 33 | BD68: 0 | BE68: 20.9 | BF68: 6.6 | BG68: 15.4 | BH68: 0 | BI68: 1.1 | BJ68: 0 | BK68: 9.9 | BL68: 0 | BM68: 4.4 | BN68: 0 | BO68: Alex
A69: 44987 | B69: MARCH | C69: 2 | D69: =SUM(E69:H69) -> 535.7 | E69: =SUM(BE69:BN69) -> 189.2 | F69: =SUM(AA69:AJ69) -> 113.3 | G69: =SUM(AU69:BD69) -> 93.5 | H69: =SUM(AL69:AT69) -> 139.7 | I69: 0 | J69: 0.363 | K69: 0.319 | L69: 1.001 | M69: 0.539 | N69: 1.067 | O69: 0.66 | P69: 0.715 | Q69: 0.704 | R69: 0.198 | S69: 0.66 | T69: 0.781 | U69: 1.089 | V69: 1.012 | W69: 0.781 | X69: 1.078 | Y69: 0.88 | Z69: 0.88 | AA69: 0 | AB69: 0 | AC69: 0 | AD69: 17.6 | AE69: 0 | AF69: 30.8 | AG69: 1.1 | AH69: 7.7 | AI69: 29.7 | AJ69: 26.4 | AK69: 4.4 | AL69: 0 | AM69: 0 | AN69: 0 | AO69: 0 | AP69: 4.4 | AQ69: 30.8 | AR69: 24.2 | AS69: 17.6 | AT69: 62.7 | AU69: 18.7 | AV69: 9.9 | AW69: 24.2 | AX69: 0 | AY69: 5.5 | AZ69: 12.1 | BA69: 8.8 | BB69: 6.6 | BC69: 3.3 | BD69: 4.4 | BE69: 8.8 | BF69: 39.6 | BG69: 11 | BH69: 15.4 | BI69: 1.1 | BJ69: 48.4 | BK69: 16.5 | BL69: 25.3 | BM69: 23.1 | BN69: 0 | BO69: Alex
A70: 44988 | B70: MARCH | C70: 3 | D70: =SUM(E70:H70) -> 484 | E70: =SUM(BE70:BN70) -> 162.8 | F70: =SUM(AA70:AJ70) -> 108.9 | G70: =SUM(AU70:BD70) -> 90.2 | H70: =SUM(AL70:AT70) -> 122.1 | I70: 0 | J70: 0.33 | K70: 0.627 | L70: 0.781 | M70: 0.979 | N70: 0.33 | O70: 0.693 | P70: 0.11 | Q70: 0.77 | R70: 1.089 | S70: 0.715 | T70: 0.693 | U70: 0.902 | V70: 1.034 | W70: 1.067 | X70: 0.484 | Y70: 0.429 | Z70: 1.012 | AA70: 33 | AB70: 12.1 | AC70: 0 | AD70: 2.2 | AE70: 15.4 | AF70: 0 | AG70: 0 | AH70: 19.8 | AI70: 15.4 | AJ70: 11 | AK70: 11 | AL70: 11 | AM70: 6.6 | AN70: 17.6 | AO70: 29.7 | AP70: 0 | AQ70: 0 | AR70: 17.6 | AS70: 19.8 | AT70: 19.8 | AU70: 2.2 | AV70: 2.2 | AW70: 26.4 | AX70: 0 | AY70: 2.2 | AZ70: 0 | BA70: 23.1 | BB70: 33 | BC70: 1.1 | BD70: 0 | BE70: 29.7 | BF70: 28.6 | BG70: 15.4 | BH70: 0 | BI70: 0 | BJ70: 0 | BK70: 31.9 | BL70: 20.9 | BM70: 36.3 | BN70: 0 | BO70: Alex
A71: 44989 | B71: MARCH | C71: 4 | D71: =SUM(E71:H71) -> 531.3 | E71: =SUM(BE71:BN71) -> 86.9 | F71: =SUM(AA71:AJ71) -> 102.3 | G71: =SUM(AU71:BD71) -> 170.5 | H71: =SUM(AL71:AT71) -> 171.6 | I71: 0 | J71: 0.319 | K71: 0.781 | L71: 0.88 | M71: 0.891 | N71: 1.078 | O71: 0.759 | P71: 0.847 | Q71: 0.88 | R71: 0.726 | S71: 0.814 | T71: 0.682 | U71: 1.001 | V71: 0.286 | W71: 1.1 | X71: 1.034 | Y71: 0.561 | Z71: 0.11 | AA71: 0 | AB71: 9.9 | AC71: 0 | AD71: 15.4 | AE71: 0 | AF71: 7.7 | AG71: 29.7 | AH71: 0 | AI71: 8.8 | AJ71: 30.8 | AK71: 26.4 | AL71: 14.3 | AM71: 0 | AN71: 0 | AO71: 30.8 | AP71: 47.3 | AQ71: 55 | AR71: 18.7 | AS71: 5.5 | AT71: 0 | AU71: 1.1 | AV71: 0 | AW71: 40.7 | AX71: 0 | AY71: 38.5 | AZ71: 11 | BA71: 1.1 | BB71: 40.7 | BC71: 6.6 | BD71: 30.8 | BE71: 0 | BF71: 5.5 | BG71: 26.4 | BH71: 2.2 | BI71: 34.1 | BJ71: 0 | BK71: 0 | BL71: 17.6 | BM71: 0 | BN71: 1.1 | BO71: Alex
A72: 44990 | B72: MARCH | C72: 5 | D72: =SUM(E72:H72) -> 543.4 | E72: =SUM(BE72:BN72) -> 119.9 | F72: =SUM(AA72:AJ72) -> 61.6 | G72: =SUM(AU72:BD72) -> 200.2 | H72: =SUM(AL72:AT72) -> 161.7 | I72: 0 | J72: 1.012 | K72: 0.583 | L72: 0.847 | M72: 0.902 | N72: 1.045 | O72: 0.693 | P72: 0.957 | Q72: 0.968 | R72: 0.957 | S72: 0.682 | T72: 1.1 | U72: 0.924 | V72: 0.902 | W72: 0.605 | X72: 1.034 | Y72: 0.572 | Z72: 0.814 | AA72: 6.6 | AB72: 6.6 | AC72: 0 | AD72: 14.3 | AE72: 0 | AF72: 0 | AG72: 29.7 | AH72: 0 | AI72: 1.1 | AJ72: 3.3 | AK72: 22 | AL72: 14.3 | AM72: 45.1 | AN72: 35.2 | AO72: 0 | AP72: 5.5 | AQ72: 0 | AR72: 23.1 | AS72: 24.2 | AT72: 14.3 | AU72: 0 | AV72: 16.5 | AW72: 26.4 | AX72: 39.6 | AY72: 33 | AZ72: 47.3 | BA72: 0 | BB72: 0 | BC72: 26.4 | BD72: 11 | BE72: 0 | BF72: 2.2 | BG72: 0 | BH72: 0 | BI72: 0 | BJ72: 44 | BK72: 5.5 | BL72: 23.1 | BM72: 1.1 | BN72: 44 | BO72: Alex
A73: 44991 | B73: MARCH | C73: 6 | D73: =SUM(E73:H73) -> 399.3 | E73: =SUM(BE73:BN73) -> 81.4 | F73: =SUM(AA73:AJ73) -> 103.4 | G73: =SUM(AU73:BD73) -> 84.7 | H73: =SUM(AL73:AT73) -> 129.8 | I73: 0 | J73: 1.001 | K73: 0.869 | L73: 0.572 | M73: 0.957 | N73: 1.089 | O73: 0.649 | P73: 0.825 | Q73: 0.605 | R73: 0.704 | S73: 0.781 | T73: 0.979 | U73: 0.924 | V73: 1.078 | W73: 0.935 | X73: 0.803 | Y73: 0.88 | Z73: 0.451 | AA73: 22 | AB73: 0 | AC73: 0 | AD73: 4.4 | AE73: 16.5 | AF73: 2.2 | AG73: 12.1 | AH73: 20.9 | AI73: 23.1 | AJ73: 2.2 | AK73: 11 | AL73: 0 | AM73: 8.8 | AN73: 6.6 | AO73: 53.9 | AP73: 9.9 | AQ73: 27.5 | AR73: 15.4 | AS73: 7.7 | AT73: 0 | AU73: 0 | AV73: 7.7 | AW73: 0 | AX73: 16.5 | AY73: 0 | AZ73: 36.3 | BA73: 3.3 | BB73: 6.6 | BC73: 14.3 | BD73: 0 | BE73: 1.1 | BF73: 3.3 | BG73: 0 | BH73: 5.5 | BI73: 15.4 | BJ73: 0 | BK73: 0 | BL73: 24.2 | BM73: 17.6 | BN73: 14.3 | BO73: Alex
...

Sheet DataM1
O1: ADP | U1: CRM | AA1: Credit Card | AK1: Bank Account | AU1: Cash | BE1: Bitcoin
A2: Date | B2: Month | C2: Day | D2: Sales | E2: Credit Card | F2: Bank Account | G2: Cash | H2: Bitcoin | I2: Seasonal Days | J2: CAC | K2: ROI | L2: CPA | M2: EPC | N2: APR | O2: StrategyA | P2: TestingA | Q2: DevelopmentA | R2: ResearchA | S2: DesignA | T2: SMMA | U2: StrategyC | V2: TestingC | W2: DevelopmentC | X2: ResearchC | Y2: DesignC | Z2: SMMC | AA2: NEW YORK-CC | AB2: NASHVILLE-CC | AC2: CHICAGO-CC | AD2: DALLAS-CC | AE2: DENVER-CC | AF2: LOS ANGELES-CC | AG2: SAN FRANCISCO-CC | AH2: SEATTLE-CC | AI2: MIAMI-CC | AJ2: SAINT AUGUSTINE-CC | AK2: NEW YORK-BA | AL2: NASHVILLE-BA | AM2: CHICAGO-BA | AN2: DALLAS-BA | AO2: DENVER-BA | AP2: LOS ANGELES-BA | AQ2: SAN FRANCISCO-BA | AR2: SEATTLE-BA | AS2: MIAMI-BA | AT2: SAINT AUGUSTINE-BA | AU2: NEW YORK-C | AV2: NASHVILLE-C | AW2: CHICAGO-C | AX2: DALLAS-C | AY2: DENVER-C | AZ2: LOS ANGELES-C | BA2: SAN FRANCISCO-C | BB2: SEATTLE-C | BC2: MIAMI-C | BD2: SAINT AUGUSTINE-C | BE2: NEW YORK-B | BF2: NASHVILLE-B | BG2: CHICAGO-B | BH2: DALLAS-B | BI2: DENVER-B | BJ2: LOS ANGELES-B | BK2: SAN FRANCISCO-B | BL2: SEATTLE-B | BM2: MIAMI-B | BN2: SAINT AUGUSTINE-B
A3: 44927 | B3: JANUARY | C3: 1 | D3: =SUM(E3:H3) -> 427.9 | E3: =SUM(BE3:BN3) -> 144.1 | F3: =SUM(AA3:AJ3) -> 122.1 | G3: =SUM(AU3:BD3) -> 56.1 | H3: =SUM(AL3:AT3) -> 105.6 | I3: 1 | J3: 0.429 | K3: 0.759 | L3: 0.88 | M3: 0.88 | N3: 1.045 | O3: 1.045 | P3: 0.825 | Q3: 0.682 | R3: 0.946 | S3: 1.056 | T3: 1.045 | U3: 0.99 | V3: 0.539 | W3: 1.001 | X3: 0.319 | Y3: 0.275 | Z3: 1.023 | AA3: 4.4 | AB3: 3.3 | AC3: 0 | AD3: 11 | AE3: 7.7 | AF3: 19.8 | AG3: 30.8 | AH3: 0 | AI3: 38.5 | AJ3: 6.6 | AK3: 0 | AL3: 0 | AM3: 15.4 | AN3: 7.7 | AO3: 0 | AP3: 22 | AQ3: 1.1 | AR3: 38.5 | AS3: 19.8 | AT3: 1.1 | AU3: 0 | AV3: 14.3 | AW3: 0 | AX3: 11 | AY3: 4.4 | AZ3: 0 | BA3: 1.1 | BB3: 0 | BC3: 13.2 | BD3: 12.1 | BE3: 0 | BF3: 20.9 | BG3: 3.3 | BH3: 13.2 | BI3: 11 | BJ3: 37.4 | BK3: 0 | BL3: 33 | BM3: 15.4 | BN3: 9.9
A4: 44928 | B4: JANUARY | C4: 2 | D4: =SUM(E4:H4) -> 624.8 | E4: =SUM(BE4:BN4) -> 174.9 | F4: =SUM(AA4:AJ4) -> 198 | G4: =SUM(AU4:BD4) -> 104.5 | H4: =SUM(AL4:AT4) -> 147.4 | I4: 0 | J4: 1.012 | K4: 0.66 | L4: 0.847 | M4: 0.77 | N4: 0.55 | O4: 0.77 | P4: 0.792 | Q4: 1.001 | R4: 0.99 | S4: 0.616 | T4: 0.759 | U4: 0.957 | V4: 0.473 | W4: 0.495 | X4: 0.88 | Y4: 0.979 | Z4: 1.023 | AA4: 23.1 | AB4: 18.7 | AC4: 0 | AD4: 35.2 | AE4: 11 | AF4: 59.4 | AG4: 0 | AH4: 2.2 | AI4: 9.9 | AJ4: 38.5 | AK4: 9.9 | AL4: 37.4 | AM4: 33 | AN4: 7.7 | AO4: 17.6 | AP4: 0 | AQ4: 0 | AR4: 11 | AS4: 17.6 | AT4: 23.1 | AU4: 0 | AV4: 37.4 | AW4: 39.6 | AX4: 0 | AY4: 0 | AZ4: 18.7 | BA4: 5.5 | BB4: 0 | BC4: 3.3 | BD4: 0 | BE4: 1.1 | BF4: 12.1 | BG4: 4.4 | BH4: 22 | BI4: 16.5 | BJ4: 4.4 | BK4: 40.7 | BL4: 23.1 | BM4: 23.1 | BN4: 27.5
A5: 44929 | B5: JANUARY | C5: 3 | D5: =SUM(E5:H5) -> 512.6 | E5: =SUM(BE5:BN5) -> 104.5 | F5: =SUM(AA5:AJ5) -> 129.8 | G5: =SUM(AU5:BD5) -> 166.1 | H5: =SUM(AL5:AT5) -> 112.2 | I5: 0 | J5: 1.034 | K5: 0.792 | L5: 0.737 | M5: 0.253 | N5: 0.902 | O5: 0.979 | P5: 0.979 | Q5: 0.737 | R5: 0.616 | S5: 0.825 | T5: 0.671 | U5: 1.089 | V5: 0.99 | W5: 0.44 | X5: 0.473 | Y5: 0.825 | Z5: 1.034 | AA5: 14.3 | AB5: 27.5 | AC5: 16.5 | AD5: 0 | AE5: 39.6 | AF5: 0 | AG5: 19.8 | AH5: 5.5 | AI5: 6.6 | AJ5: 0 | AK5: 33 | AL5: 1.1 | AM5: 0 | AN5: 0 | AO5: 0 | AP5: 16.5 | AQ5: 7.7 | AR5: 28.6 | AS5: 35.2 | AT5: 23.1 | AU5: 0 | AV5: 3.3 | AW5: 0 | AX5: 6.6 | AY5: 50.6 | AZ5: 19.8 | BA5: 17.6 | BB5: 0 | BC5: 23.1 | BD5: 45.1 | BE5: 22 | BF5: 3.3 | BG5: 13.2 | BH5: 9.9 | BI5: 6.6 | BJ5: 2.2 | BK5: 9.9 | BL5: 0 | BM5: 3.3 | BN5: 34.1
A6: 44930 | B6: JANUARY | C6: 4 | D6: =SUM(E6:H6) -> 495 | E6: =SUM(BE6:BN6) -> 88 | F6: =SUM(AA6:AJ6) -> 152.9 | G6: =SUM(AU6:BD6) -> 198 | H6: =SUM(AL6:AT6) -> 56.1 | I6: 0 | J6: 0.319 | K6: 0.605 | L6: 0.561 | M6: 1.034 | N6: 1.023 | O6: 0.726 | P6: 0.66 | Q6: 0.77 | R6: 0.88 | S6: 0.814 | T6: 0.836 | U6: 0.748 | V6: 0.99 | W6: 0.638 | X6: 0.968 | Y6: 1.056 | Z6: 1.034 | AA6: 0 | AB6: 16.5 | AC6: 0 | AD6: 0 | AE6: 3.3 | AF6: 6.6 | AG6: 39.6 | AH6: 33 | AI6: 7.7 | AJ6: 46.2 | AK6: 3.3 | AL6: 0 | AM6: 11 | AN6: 0 | AO6: 0 | AP6: 0 | AQ6: 22 | AR6: 12.1 | AS6: 2.2 | AT6: 8.8 | AU6: 8.8 | AV6: 25.3 | AW6: 40.7 | AX6: 1.1 | AY6: 12.1 | AZ6: 5.5 | BA6: 44 | BB6: 11 | BC6: 45.1 | BD6: 4.4 | BE6: 11 | BF6: 4.4 | BG6: 31.9 | BH6: 0 | BI6: 4.4 | BJ6: 22 | BK6: 4.4 | BL6: 0 | BM6: 9.9 | BN6: 0
A7: 44931 | B7: JANUARY | C7: 5 | D7: =SUM(E7:H7) -> 405.9 | E7: =SUM(BE7:BN7) -> 122.1 | F7: =SUM(AA7:AJ7) -> 136.4 | G7: =SUM(AU7:BD7) -> 107.8 | H7: =SUM(AL7:AT7) -> 39.6 | I7: 0 | J7: 0.253 | K7: 0.594 | L7: 0.825 | M7: 1.067 | N7: 1.023 | O7: 0.814 | P7: 0.11 | Q7: 0.748 | R7: 0.792 | S7: 0.715 | T7: 0.66 | U7: 0.341 | V7: 1.1 | W7: 1.045 | X7: 0.286 | Y7: 1.023 | Z7: 0.407 | AA7: 0 | AB7: 26.4 | AC7: 15.4 | AD7: 23.1 | AE7: 0 | AF7: 4.4 | AG7: 44 | AH7: 0 | AI7: 6.6 | AJ7: 16.5 | AK7: 0 | AL7: 0 | AM7: 0 | AN7: 17.6 | AO7: 0 | AP7: 0 | AQ7: 3.3 | AR7: 14.3 | AS7: 0 | AT7: 4.4 | AU7: 4.4 | AV7: 0 | AW7: 23.1 | AX7: 19.8 | AY7: 0 | AZ7: 15.4 | BA7: 0 | BB7: 16.5 | BC7: 0 | BD7: 28.6 | BE7: 27.5 | BF7: 1.1 | BG7: 14.3 | BH7: 14.3 | BI7: 0 | BJ7: 26.4 | BK7: 24.2 | BL7: 0 | BM7: 13.2 | BN7: 1.1
A8: 44932 | B8: JANUARY | C8: 6 | D8: =SUM(E8:H8) -> 543.4 | E8: =SUM(BE8:BN8) -> 88 | F8: =SUM(AA8:AJ8) -> 125.4 | G8: =SUM(AU8:BD8) -> 188.1 | H8: =SUM(AL8:AT8) -> 141.9 | I8: 0 | J8: 0.649 | K8: 0.99 | L8: 0.825 | M8: 0.88 | N8: 0.957 | O8: 0.737 | P8: 0.726 | Q8: 0.792 | R8: 0.946 | S8: 0.792 | T8: 0.858 | U8: 0.165 | V8: 1.1 | W8: 0.33 | X8: 0.616 | Y8: 1.067 | Z8: 0.616 | AA8: 45.1 | AB8: 17.6 | AC8: 17.6 | AD8: 11 | AE8: 19.8 | AF8: 0 | AG8: 2.2 | AH8: 0 | AI8: 2.2 | AJ8: 9.9 | AK8: 47.3 | AL8: 31.9 | AM8: 0 | AN8: 0 | AO8: 0 | AP8: 30.8 | AQ8: 24.2 | AR8: 12.1 | AS8: 17.6 | AT8: 25.3 | AU8: 17.6 | AV8: 7.7 | AW8: 44 | AX8: 24.2 | AY8: 1.1 | AZ8: 4.4 | BA8: 6.6 | BB8: 48.4 | BC8: 34.1 | BD8: 0 | BE8: 11 | BF8: 8.8 | BG8: 0 | BH8: 0 | BI8: 15.4 | BJ8: 23.1 | BK8: 0 | BL8: 11 | BM8: 6.6 | BN8: 12.1
A9: 44933 | B9: JANUARY | C9: 7 | D9: =SUM(E9:H9) -> 596.2 | E9: =SUM(BE9:BN9) -> 201.3 | F9: =SUM(AA9:AJ9) -> 114.4 | G9: =SUM(AU9:BD9) -> 179.3 | H9: =SUM(AL9:AT9) -> 101.2 | I9: 0 | J9: 0.682 | K9: 0.594 | L9: 0.22 | M9: 0.902 | N9: 1.012 | O9: 1.1 | P9: 0.605 | Q9: 0.935 | R9: 0.55 | S9: 0.66 | T9: 1.155 | U9: 1.056 | V9: 0.572 | W9: 0.803 | X9: 1.023 | Y9: 0.924 | Z9: 0.891 | AA9: 27.5 | AB9: 0 | AC9: 50.6 | AD9: 9.9 | AE9: 13.2 | AF9: 8.8 | AG9: 0 | AH9: 0 | AI9: 0 | AJ9: 4.4 | AK9: 59.4 | AL9: 1.1 | AM9: 5.5 | AN9: 3.3 | AO9: 26.4 | AP9: 39.6 | AQ9: 0 | AR9: 0 | AS9: 4.4 | AT9: 20.9 | AU9: 0 | AV9: 24.2 | AW9: 31.9 | AX9: 0 | AY9: 35.2 | AZ9: 0 | BA9: 26.4 | BB9: 1.1 | BC9: 36.3 | BD9: 24.2 | BE9: 23.1 | BF9: 4.4 | BG9: 2.2 | BH9: 0 | BI9: 28.6 | BJ9: 23.1 | BK9: 29.7 | BL9: 35.2 | BM9: 22 | BN9: 33
A10: 44934 | B10: JANUARY | C10: 8 | D10: =SUM(E10:H10) -> 570.9 | E10: =SUM(BE10:BN10) -> 118.8 | F10: =SUM(AA10:AJ10) -> 125.4 | G10: =SUM(AU10:BD10) -> 204.6 | H10: =SUM(AL10:AT10) -> 122.1 | I10: 0 | J10: 0.836 | K10: 0.726 | L10: 0.935 | M10: 0.913 | N10: 0.748 | O10: 0.66 | P10: 0.825 | Q10: 0.66 | R10: 0.825 | S10: 0.528 | T10: 0.748 | U10: 0.418 | V10: 0.627 | W10: 0.451 | X10: 1.1 | Y10: 1.078 | Z10: 0.165 | AA10: 11 | AB10: 7.7 | AC10: 0 | AD10: 5.5 | AE10: 9.9 | AF10: 56.1 | AG10: 5.5 | AH10: 0 | AI10: 29.7 | AJ10: 0 | AK10: 13.2 | AL10: 0 | AM10: 0 | AN10: 0 | AO10: 14.3 | AP10: 0 | AQ10: 17.6 | AR10: 47.3 | AS10: 42.9 | AT10: 0 | AU10: 11 | AV10: 41.8 | AW10: 0 | AX10: 7.7 | AY10: 22 | AZ10: 26.4 | BA10: 42.9 | BB10: 37.4 | BC10: 15.4 | BD10: 0 | BE10: 0 | BF10: 3.3 | BG10: 31.9 | BH10: 14.3 | BI10: 13.2 | BJ10: 29.7 | BK10: 15.4 | BL10: 11 | BM10: 0 | BN10: 0
A11: 44935 | B11: JANUARY | C11: 9 | D11: =SUM(E11:H11) -> 535.7 | E11: =SUM(BE11:BN11) -> 118.8 | F11: =SUM(AA11:AJ11) -> 139.7 | G11: =SUM(AU11:BD11) -> 144.1 | H11: =SUM(AL11:AT11) -> 133.1 | I11: 0 | J11: 0.297 | K11: 0.704 | L11: 0.869 | M11: 0.946 | N11: 1.023 | O11: 0.99 | P11: 0.781 | Q11: 0.638 | R11: 0.759 | S11: 0.781 | T11: 0.759 | U11: 0.616 | V11: 1.067 | W11: 1.001 | X11: 0.682 | Y11: 0.396 | Z11: 1.067 | AA11: 0 | AB11: 14.3 | AC11: 7.7 | AD11: 3.3 | AE11: 3.3 | AF11: 0 | AG11: 23.1 | AH11: 23.1 | AI11: 39.6 | AJ11: 25.3 | AK11: 29.7 | AL11: 0 | AM11: 18.7 | AN11: 34.1 | AO11: 0 | AP11: 6.6 | AQ11: 31.9 | AR11: 0 | AS11: 18.7 | AT11: 23.1 | AU11: 59.4 | AV11: 8.8 | AW11: 9.9 | AX11: 4.4 | AY11: 17.6 | AZ11: 9.9 | BA11: 0 | BB11: 13.2 | BC11: 18.7 | BD11: 2.2 | BE11: 9.9 | BF11: 16.5 | BG11: 5.5 | BH11: 17.6 | BI11: 57.2 | BJ11: 3.3 | BK11: 0 | BL11: 1.1 | BM11: 7.7 | BN11: 0
A12: 44936 | B12: JANUARY | C12: 10 | D12: =SUM(E12:H12) -> 381.7 | E12: =SUM(BE12:BN12) -> 110 | F12: =SUM(AA12:AJ12) -> 113.3 | G12: =SUM(AU12:BD12) -> 71.5 | H12: =SUM(AL12:AT12) -> 86.9 | I12: 0 | J12: 0.528 | K12: 0.99 | L12: 0.792 | M12: 0.88 | N12: 1.089 | O12: 1.001 | P12: 1.089 | Q12: 0.803 | R12: 0.957 | S12: 0.693 | T12: 0.979 | U12: 0.891 | V12: 0.924 | W12: 0.99 | X12: 0.946 | Y12: 1.012 | Z12: 1.001 | AA12: 0 | AB12: 0 | AC12: 38.5 | AD12: 0 | AE12: 2.2 | AF12: 26.4 | AG12: 17.6 | AH12: 0 | AI12: 15.4 | AJ12: 13.2 | AK12: 22 | AL12: 29.7 | AM12: 14.3 | AN12: 3.3 | AO12: 8.8 | AP12: 1.1 | AQ12: 0 | AR12: 20.9 | AS12: 8.8 | AT12: 0 | AU12: 13.2 | AV12: 7.7 | AW12: 7.7 | AX12: 0 | AY12: 0 | AZ12: 0 | BA12: 0 | BB12: 34.1 | BC12: 8.8 | BD12: 0 | BE12: 4.4 | BF12: 26.4 | BG12: 0 | BH12: 30.8 | BI12: 11 | BJ12: 23.1 | BK12: 0 | BL12: 0 | BM12: 7.7 | BN12: 6.6
A13: 44937 | B13: JANUARY | C13: 11 | D13: =SUM(E13:H13) -> 570.9 | E13: =SUM(BE13:BN13) -> 232.1 | F13: =SUM(AA13:AJ13) -> 121 | G13: =SUM(AU13:BD13) -> 141.9 | H13: =SUM(AL13:AT13) -> 75.9 | I13: 0 | J13: 0.55 | K13: 0.847 | L13: 0.825 | M13: 0.902 | N13: 0.99 | O13: 0.77 | P13: 0.858 | Q13: 0.605 | R13: 0.781 | S13: 0.825 | T13: 1.012 | U13: 0.451 | V13: 0.462 | W13: 0.968 | X13: 0.286 | Y13: 0.407 | Z13: 0.66 | AA13: 12.1 | AB13: 22 | AC13: 0 | AD13: 0 | AE13: 13.2 | AF13: 34.1 | AG13: 4.4 | AH13: 0 | AI13: 35.2 | AJ13: 0 | AK13: 4.4 | AL13: 0 | AM13: 27.5 | AN13: 0 | AO13: 5.5 | AP13: 6.6 | AQ13: 2.2 | AR13: 34.1 | AS13: 0 | AT13: 0 | AU13: 33 | AV13: 29.7 | AW13: 3.3 | AX13: 3.3 | AY13: 11 | AZ13: 0 | BA13: 20.9 | BB13: 0 | BC13: 30.8 | BD13: 9.9 | BE13: 25.3 | BF13: 8.8 | BG13: 34.1 | BH13: 55 | BI13: 0 | BJ13: 5.5 | BK13: 22 | BL13: 0 | BM13: 45.1 | BN13: 36.3
A14: 44938 | B14: JANUARY | C14: 12 | D14: =SUM(E14:H14) -> 674.3 | E14: =SUM(BE14:BN14) -> 180.4 | F14: =SUM(AA14:AJ14) -> 158.4 | G14: =SUM(AU14:BD14) -> 215.6 | H14: =SUM(AL14:AT14) -> 119.9 | I14: 0 | J14: 0.528 | K14: 0.726 | L14: 1.001 | M14: 0.693 | N14: 0.22 | O14: 0.957 | P14: 0.88 | Q14: 1.067 | R14: 0.847 | S14: 0.539 | T14: 0.638 | U14: 0.825 | V14: 0.792 | W14: 0.99 | X14: 1.045 | Y14: 0.792 | Z14: 0.33 | AA14: 4.4 | AB14: 8.8 | AC14: 0 | AD14: 17.6 | AE14: 22 | AF14: 19.8 | AG14: 30.8 | AH14: 6.6 | AI14: 15.4 | AJ14: 33 | AK14: 37.4 | AL14: 14.3 | AM14: 6.6 | AN14: 18.7 | AO14: 0 | AP14: 6.6 | AQ14: 27.5 | AR14: 12.1 | AS14: 33 | AT14: 1.1 | AU14: 12.1 | AV14: 20.9 | AW14: 59.4 | AX14: 0 | AY14: 38.5 | AZ14: 8.8 | BA14: 6.6 | BB14: 4.4 | BC14: 28.6 | BD14: 36.3 | BE14: 12.1 | BF14: 0 | BG14: 18.7 | BH14: 7.7 | BI14: 22 | BJ14: 60.5 | BK14: 3.3 | BL14: 19.8 | BM14: 13.2 | BN14: 23.1
... A33: 44957 | B33: JANUARY | C33: 31 | D33: =SUM(E33:H33) -> 430.1 | E33: =SUM(BE33:BN33) -> 101.2 | F33: =SUM(AA33:AJ33) -> 129.8 | G33: =SUM(AU33:BD33) -> 110 | H33: =SUM(AL33:AT33) -> 89.1 | I33: 0 | J33: 0.99 | K33: 1.023 | L33: 1.034 | M33: 0.726 | N33: 0.88 | O33: 0.66 | P33: 0.792 | Q33: 0.726 | R33: 1.023 | S33: 0.979 | T33: 0.638 | U33: 0.814 | V33: 0.605 | W33: 1.078 | X33: 1.045 | Y33: 1.089 | Z33: 0.627 | AA33: 0 | AB33: 33 | AC33: 5.5 | AD33: 15.4 | AE33: 16.5 | AF33: 5.5 | AG33: 38.5 | AH33: 0 | AI33: 1.1 | AJ33: 14.3 | AK33: 3.3 | AL33: 28.6 | AM33: 5.5 | AN33: 0 | AO33: 12.1 | AP33: 4.4 | AQ33: 12.1 | AR33: 17.6 | AS33: 8.8 | AT33: 0 | AU33: 4.4 | AV33: 18.7 | AW33: 2.2 | AX33: 1.1 | AY33: 45.1 | AZ33: 0 | BA33: 0 | BB33: 7.7 | BC33: 25.3 | BD33: 5.5 | BE33: 3.3 | BF33: 6.6 | BG33: 23.1 | BH33: 25.3 | BI33: 9.9 | BJ33: 22 | BK33: 6.6 | BL33: 0 | BM33: 4.4 | BN33: 0
B34: FEBRUARY | C34: 1e-08 | D34: =SUM(E34:H34) -> 0 | E34: 0 | F34: 0 | G34: 0 | H34: 0 | I34: 0 | J34: 0 | K34: 0 | L34: 0 | M34: 0 | N34: 0 | O34: 0 | P34: 0 | Q34: 0 | R34: 0 | S34: 0 | T34: 0 | U34: 0 | V34: 0 | W34: 0 | X34: 0 | Y34: 0 | Z34: 0 | AA34: 0 | AB34: 0 | AC34: 0 | AD34: 0 | AE34: 0 | AF34: 0 | AG34: 0 | AH34: 0 | AI34: 0 | AJ34: 0 | AK34: 0 | AL34: 0 | AM34: 0 | AN34: 0 | AO34: 0 | AP34: 0 | AQ34: 0 | AR34: 0 | AS34: 0 | AT34: 0 | AU34: 0 | AV34: 0 | AW34: 0 | AX34: 0 | AY34: 0 | AZ34: 0 | BA34: 0 | BB34: 0 | BC34: 0 | BD34: 0 | BE34: 0 | BF34: 0 | BG34: 0 | BH34: 0 | BI34: 0 | BJ34: 0 | BK34: 0 | BL34: 0 | BM34: 0 | BN34: 0
B35: FEBRUARY | C35: 2e-08 | D35: =SUM(E35:H35) -> 0 | E35: 0 | F35: 0 | G35: 0 | H35: 0 | I35: 0 | J35: 0 | K35: 0 | L35: 0 | M35: 0 | N35: 0 | O35: 0 | P35: 0 | Q35: 0 | R35: 0 | S35: 0 | T35: 0 | U35: 0 | V35: 0 | W35: 0 | X35: 0 | Y35: 0 | Z35: 0 | AA35: 0 | AB35: 0 | AC35: 0 | AD35: 0 | AE35: 0 | AF35: 0 | AG35: 0 | AH35: 0 | AI35: 0 | AJ35: 0 | AK35: 0 | AL35: 0 | AM35: 0 | AN35: 0 | AO35: 0 | AP35: 0 | AQ35: 0 | AR35: 0 | AS35: 0 | AT35: 0 | AU35: 0 | AV35: 0 | AW35: 0 | AX35: 0 | AY35: 0 | AZ35: 0 | BA35: 0 | BB35: 0 | BC35: 0 | BD35: 0 | BE35: 0 | BF35: 0 | BG35: 0 | BH35: 0 | BI35: 0 | BJ35: 0 | BK35: 0 | BL35: 0 | BM35: 0 | BN35: 0
B36: FEBRUARY | C36: 3e-08 | D36: =SUM(E36:H36) -> 0 | E36: 0 | F36: 0 | G36: 0 | H36: 0 | I36: 0 | J36: 0 | K36: 0 | L36: 0 | M36: 0 | N36: 0 | O36: 0 | P36: 0 | Q36: 0 | R36: 0 | S36: 0 | T36: 0 | U36: 0 | V36: 0 | W36: 0 | X36: 0 | Y36: 0 | Z36: 0 | AA36: 0 | AB36: 0 | AC36: 0 | AD36: 0 | AE36: 0 | AF36: 0 | AG36: 0 | AH36: 0 | AI36: 0 | AJ36: 0 | AK36: 0 | AL36: 0 | AM36: 0 | AN36: 0 | AO36: 0 | AP36: 0 | AQ36: 0 | AR36: 0 | AS36: 0 | AT36: 0 | AU36: 0 | AV36: 0 | AW36: 0 | AX36: 0 | AY36: 0 | AZ36: 0 | BA36: 0 | BB36: 0 | BC36: 0 | BD36: 0 | BE36: 0 | BF36: 0 | BG36: 0 | BH36: 0 | BI36: 0 | BJ36: 0 | BK36: 0 | BL36: 0 | BM36: 0 | BN36: 0
A37: 44958 | B37: FEBRUARY | C37: 1 | D37: =SUM(E37:H37) -> 588.5 | E37: =SUM(BE37:BN37) -> 72.6 | F37: =SUM(AA37:AJ37) -> 121 | G37: =SUM(AU37:BD37) -> 146.3 | H37: =SUM(AL37:AT37) -> 248.6 | I37: 0 | J37: 0.198 | K37: 0.957 | L37: 0.88 | M37: 0.693 | N37: 1.078 | O37: 0.66 | P37: 0.792 | Q37: 0.748 | R37: 0.462 | S37: 0.517 | T37: 0.869 | U37: 0.979 | V37: 1.034 | W37: 0.88 | X37: 1.034 | Y37: 0.715 | Z37: 1.001 | AA37: 49.5 | AB37: 33 | AC37: 13.2 | AD37: 0 | AE37: 12.1 | AF37: 0 | AG37: 0 | AH37: 0 | AI37: 12.1 | AJ37: 1.1 | AK37: 47.3 | AL37: 48.4 | AM37: 47.3 | AN37: 36.3 | AO37: 0 | AP37: 53.9 | AQ37: 23.1 | AR37: 15.4 | AS37: 1.1 | AT37: 23.1 | AU37: 6.6 | AV37: 13.2 | AW37: 33 | AX37: 27.5 | AY37: 0 | AZ37: 8.8 | BA37: 1.1 | BB37: 2.2 | BC37: 14.3 | BD37: 39.6 | BE37: 5.5 | BF37: 0 | BG37: 3.3 | BH37: 0 | BI37: 3.3 | BJ37: 24.2 | BK37: 16.5 | BL37: 1.1 | BM37: 18.7 | BN37: 0
A38: 44959 | B38: FEBRUARY | C38: 2 | D38: =SUM(E38:H38) -> 563.2 | E38: =SUM(BE38:BN38) -> 158.4 | F38: =SUM(AA38:AJ38) -> 144.1 | G38: =SUM(AU38:BD38) -> 101.2 | H38: =SUM(AL38:AT38) -> 159.5 | I38: 1 | J38: 0.517 | K38: 0.583 | L38: 0.99 | M38: 0.858 | N38: 0.748 | O38: 1.001 | P38: 0.726 | Q38: 0.935 | R38: 0.671 | S38: 0.704 | T38: 0.682 | U38: 0.473 | V38: 0.495 | W38: 0.814 | X38: 0.946 | Y38: 0.319 | Z38: 1.056 | AA38: 2.2 | AB38: 0 | AC38: 0 | AD38: 22 | AE38: 19.8 | AF38: 37.4 | AG38: 19.8 | AH38: 19.8 | AI38: 9.9 | AJ38: 13.2 | AK38: 37.4 | AL38: 13.2 | AM38: 17.6 | AN38: 24.2 | AO38: 3.3 | AP38: 36.3 | AQ38: 8.8 | AR38: 0 | AS38: 23.1 | AT38: 33 | AU38: 0 | AV38: 0 | AW38: 13.2 | AX38: 42.9 | AY38: 4.4 | AZ38: 0 | BA38: 12.1 | BB38: 0 | BC38: 5.5 | BD38: 23.1 | BE38: 3.3 | BF38: 46.2 | BG38: 24.2 | BH38: 0 | BI38: 1.1 | BJ38: 0 | BK38: 0 | BL38: 42.9 | BM38: 35.2 | BN38: 5.5
A39: 44960 | B39: FEBRUARY | C39: 3 | D39: =SUM(E39:H39) -> 497.2 | E39: =SUM(BE39:BN39) -> 167.2 | F39: =SUM(AA39:AJ39) -> 173.8 | G39: =SUM(AU39:BD39) -> 68.2 | H39: =SUM(AL39:AT39) -> 88 | I39: 0 | J39: 0.605 | K39: 0.748 | L39: 0.781 | M39: 0.946 | N39: 0.737 | O39: 1.012 | P39: 0.66 | Q39: 0.451 | R39: 1.089 | S39: 1.023 | T39: 0.77 | U39: 1.1 | V39: 1.067 | W39: 1.001 | X39: 0.473 | Y39: 0.484 | Z39: 1.089 | AA39: 1.1 | AB39: 12.1 | AC39: 26.4 | AD39: 23.1 | AE39: 26.4 | AF39: 22 | AG39: 0 | AH39: 40.7 | AI39: 8.8 | AJ39: 13.2 | AK39: 2.2 | AL39: 8.8 | AM39: 0 | AN39: 3.3 | AO39: 17.6 | AP39: 0 | AQ39: 0 | AR39: 50.6 | AS39: 7.7 | AT39: 0 | AU39: 0 | AV39: 3.3 | AW39: 0 | AX39: 7.7 | AY39: 0 | AZ39: 0 | BA39: 30.8 | BB39: 0 | BC39: 26.4 | BD39: 0 | BE39: 8.8 | BF39: 0 | BG39: 37.4 | BH39: 17.6 | BI39: 0 | BJ39: 1.1 | BK39: 37.4 | BL39: 0 | BM39: 49.5 | BN39: 15.4
A40: 44961 | B40: FEBRUARY | C40: 4 | D40: =SUM(E40:H40) -> 524.7 | E40: =SUM(BE40:BN40) -> 141.9 | F40: =SUM(AA40:AJ40) -> 117.7 | G40: =SUM(AU40:BD40) -> 152.9 | H40: =SUM(AL40:AT40) -> 112.2 | I40: 0 | J40: 0.473 | K40: 0.517 | L40: 0.957 | M40: 0.836 | N40: 1.023 | O40: 0.715 | P40: 0.803 | Q40: 0.704 | R40: 0.869 | S40: 0.902 | T40: 0.682 | U40: 0.374 | V40: 1.001 | W40: 0.869 | X40: 0.396 | Y40: 1.067 | Z40: 0.858 | AA40: 7.7 | AB40: 35.2 | AC40: 6.6 | AD40: 24.2 | AE40: 12.1 | AF40: 18.7 | AG40: 13.2 | AH40: 0 | AI40: 0 | AJ40: 0 | AK40: 4.4 | AL40: 9.9 | AM40: 52.8 | AN40: 27.5 | AO40: 9.9 | AP40: 12.1 | AQ40: 0 | AR40: 0 | AS40: 0 | AT40: 0 | AU40: 19.8 | AV40: 19.8 | AW40: 39.6 | AX40: 9.9 | AY40: 0 | AZ40: 5.5 | BA40: 7.7 | BB40: 11 | BC40: 33 | BD40: 6.6 | BE40: 1.1 | BF40: 4.4 | BG40: 19.8 | BH40: 39.6 | BI40: 0 | BJ40: 25.3 | BK40: 1.1 | BL40: 44 | BM40: 6.6 | BN40: 0
A41: 44962 | B41: FEBRUARY | C41: 5 | D41: =SUM(E41:H41) -> 591.8 | E41: =SUM(BE41:BN41) -> 166.1 | F41: =SUM(AA41:AJ41) -> 103.4 | G41: =SUM(AU41:BD41) -> 205.7 | H41: =SUM(AL41:AT41) -> 116.6 | I41: 0 | J41: 0.759 | K41: 0.55 | L41: 0.385 | M41: 0.847 | N41: 0.44 | O41: 0.946 | P41: 0.286 | Q41: 1.034 | R41: 0.616 | S41: 0.792 | T41: 0.968 | U41: 0.495 | V41: 1.089 | W41: 0.858 | X41: 0.825 | Y41: 0.407 | Z41: 1.023 | AA41: 9.9 | AB41: 11 | AC41: 4.4 | AD41: 0 | AE41: 16.5 | AF41: 4.4 | AG41: 13.2 | AH41: 16.5 | AI41: 26.4 | AJ41: 1.1 | AK41: 7.7 | AL41: 9.9 | AM41: 0 | AN41: 0 | AO41: 2.2 | AP41: 18.7 | AQ41: 27.5 | AR41: 0 | AS41: 41.8 | AT41: 16.5 | AU41: 20.9 | AV41: 41.8 | AW41: 31.9 | AX41: 3.3 | AY41: 35.2 | AZ41: 0 | BA41: 0 | BB41: 15.4 | BC41: 6.6 | BD41: 50.6 | BE41: 24.2 | BF41: 15.4 | BG41: 3.3 | BH41: 13.2 | BI41: 22 | BJ41: 9.9 | BK41: 2.2 | BL41: 0 | BM41: 68.2 | BN41: 7.7
A42: 44963 | B42: FEBRUARY | C42: 6 | D42: =SUM(E42:H42) -> 640.2 | E42: =SUM(BE42:BN42) -> 133.1 | F42: =SUM(AA42:AJ42) -> 227.7 | G42: =SUM(AU42:BD42) -> 161.7 | H42: =SUM(AL42:AT42) -> 117.7 | I42: 0 | J42: 0.231 | K42: 0.275 | L42: 0.792 | M42: 0.88 | N42: 1.056 | O42: 1.045 | P42: 0.363 | Q42: 0.638 | R42: 1.023 | S42: 0.671 | T42: 0.649 | U42: 0.649 | V42: 0.308 | W42: 0.462 | X42: 0.99 | Y42: 0.737 | Z42: 0.429 | AA42: 5.5 | AB42: 46.2 | AC42: 0 | AD42: 44 | AE42: 0 | AF42: 17.6 | AG42: 46.2 | AH42: 8.8 | AI42: 27.5 | AJ42: 31.9 | AK42: 16.5 | AL42: 0 | AM42: 4.4 | AN42: 44 | AO42: 22 | AP42: 16.5 | AQ42: 0 | AR42: 0 | AS42: 30.8 | AT42: 0 | AU42: 47.3 | AV42: 22 | AW42: 19.8 | AX42: 5.5 | AY42: 7.7 | AZ42: 0 | BA42: 2.2 | BB42: 50.6 | BC42: 3.3 | BD42: 3.3 | BE42: 0 | BF42: 17.6 | BG42: 2.2 | BH42: 44 | BI42: 4.4 | BJ42: 35.2 | BK42: 0 | BL42: 0 | BM42: 29.7 | BN42: 0
A43: 44964 | B43: FEBRUARY | C43: 7 | D43: =SUM(E43:H43) -> 402.6 | E43: =SUM(BE43:BN43) -> 117.7 | F43: =SUM(AA43:AJ43) -> 61.6 | G43: =SUM(AU43:BD43) -> 122.1 | H43: =SUM(AL43:AT43) -> 101.2 | I43: 0 | J43: 0.781 | K43: 0.99 | L43: 1.089 | M43: 1.001 | N43: 1.067 | O43: 0.814 | P43: 0.77 | Q43: 1.089 | R43: 1.045 | S43: 0.781 | T43: 0.781 | U43: 0.715 | V43: 0.451 | W43: 0.99 | X43: 0.308 | Y43: 1.078 | Z43: 0.308 | AA43: 17.6 | AB43: 2.2 | AC43: 9.9 | AD43: 0 | AE43: 0 | AF43: 15.4 | AG43: 4.4 | AH43: 8.8 | AI43: 0 | AJ43: 3.3 | AK43: 5.5 | AL43: 8.8 | AM43: 0 | AN43: 0 | AO43: 9.9 | AP43: 5.5 | AQ43: 0 | AR43: 1.1 | AS43: 59.4 | AT43: 16.5 | AU43: 0 | AV43: 0 | AW43: 41.8 | AX43: 13.2 | AY43: 42.9 | AZ43: 6.6 | BA43: 0 | BB43: 0 | BC43: 2.2 | BD43: 15.4 | BE43: 11 | BF43: 24.2 | BG43: 38.5 | BH43: 11 | BI43: 0 | BJ43: 29.7 | BK43: 3.3 | BL43: 0 | BM43: 0 | BN43: 0
A44: 44965 | B44: FEBRUARY | C44: 8 | D44: =SUM(E44:H44) -> 532.4 | E44: =SUM(BE44:BN44) -> 138.6 | F44: =SUM(AA44:AJ44) -> 181.5 | G44: =SUM(AU44:BD44) -> 190.3 | H44: =SUM(AL44:AT44) -> 22 | I44: 0 | J44: 0.528 | K44: 0.825 | L44: 0.814 | M44: 0.924 | N44: 0.275 | O44: 0.473 | P44: 0.957 | Q44: 0.671 | R44: 0.132 | S44: 0.693 | T44: 0.913 | U44: 0.88 | V44: 0.616 | W44: 0.99 | X44: 1.012 | Y44: 0.935 | Z44: 0.935 | AA44: 0 | AB44: 38.5 | AC44: 0 | AD44: 1.1 | AE44: 23.1 | AF44: 34.1 | AG44: 0 | AH44: 6.6 | AI44: 38.5 | AJ44: 39.6 | AK44: 1.1 | AL44: 0 | AM44: 0 | AN44: 0 | AO44: 5.5 | AP44: 0 | AQ44: 0 | AR44: 0 | AS44: 8.8 | AT44: 7.7 | AU44: 22 | AV44: 20.9 | AW44: 37.4 | AX44: 41.8 | AY44: 22 | AZ44: 0 | BA44: 5.5 | BB44: 40.7 | BC44: 0 | BD44: 0 | BE44: 11 | BF44: 3.3 | BG44: 0 | BH44: 46.2 | BI44: 4.4 | BJ44: 14.3 | BK44: 0 | BL44: 3.3 | BM44: 18.7 | BN44: 37.4
A45: 44966 | B45: FEBRUARY | C45: 9 | D45: =SUM(E45:H45) -> 519.2 | E45: =SUM(BE45:BN45) -> 73.7 | F45: =SUM(AA45:AJ45) -> 172.7 | G45: =SUM(AU45:BD45) -> 147.4 | H45: =SUM(AL45:AT45) -> 125.4 | I45: 0 | J45: 0.275 | K45: 0.605 | L45: 0.814 | M45: 0.924 | N45: 0.99 | O45: 0.792 | P45: 0.671 | Q45: 0.847 | R45: 0.22 | S45: 0.11 | T45: 0.66 | U45: 0.649 | V45: 0.605 | W45: 1.034 | X45: 0.968 | Y45: 0.319 | Z45: 0.44 | AA45: 11 | AB45: 30.8 | AC45: 0 | AD45: 14.3 | AE45: 25.3 | AF45: 23.1 | AG45: 6.6 | AH45: 53.9 | AI45: 0 | AJ45: 7.7 | AK45: 14.3 | AL45: 36.3 | AM45: 17.6 | AN45: 17.6 | AO45: 18.7 | AP45: 17.6 | AQ45: 0 | AR45: 0 | AS45: 0 | AT45: 17.6 | AU45: 20.9 | AV45: 16.5 | AW45: 47.3 | AX45: 22 | AY45: 7.7 | AZ45: 0 | BA45: 0 | BB45: 33 | BC45: 0 | BD45: 0 | BE45: 0 | BF45: 30.8 | BG45: 0 | BH45: 0 | BI45: 18.7 | BJ45: 1.1 | BK45: 0 | BL45: 18.7 | BM45: 0 | BN45: 4.4
A46: 44967 | B46: FEBRUARY | C46: 10 | D46: =SUM(E46:H46) -> 647.9 | E46: =SUM(BE46:BN46) -> 234.3 | F46: =SUM(AA46:AJ46) -> 152.9 | G46: =SUM(AU46:BD46) -> 134.2 | H46: =SUM(AL46:AT46) -> 126.5 | I46: 0 | J46: 0.418 | K46: 0.891 | L46: 1.089 | M46: 0.99 | N46: 1.045 | O46: 0.902 | P46: 0.858 | Q46: 0.737 | R46: 0.979 | S46: 0.726 | T46: 0.847 | U46: 0.979 | V46: 1.078 | W46: 0.946 | X46: 1.089 | Y46: 1.012 | Z46: 0.638 | AA46: 0 | AB46: 5.5 | AC46: 24.2 | AD46: 23.1 | AE46: 15.4 | AF46: 28.6 | AG46: 18.7 | AH46: 24.2 | AI46: 9.9 | AJ46: 3.3 | AK46: 4.4 | AL46: 23.1 | AM46: 23.1 | AN46: 0 | AO46: 0 | AP46: 20.9 | AQ46: 17.6 | AR46: 0 | AS46: 22 | AT46: 19.8 | AU46: 16.5 | AV46: 20.9 | AW46: 17.6 | AX46: 6.6 | AY46: 0 | AZ46: 0 | BA46: 0 | BB46: 31.9 | BC46: 40.7 | BD46: 0 | BE46: 24.2 | BF46: 0 | BG46: 30.8 | BH46: 30.8 | BI46: 16.5 | BJ46: 51.7 | BK46: 0 | BL46: 20.9 | BM46: 20.9 | BN46: 38.5
