Workbook
Name Slicer_Indicators: #N/A
Name Slicer_Month: #N/A
Name Slicer_Tariffs: #N/A
Name Slicer_Traffic: #N/A
Name Slicer_Year: #N/A

Sheet DASHBOARD

Sheet DASHBOARD Light
B47: https://exceltable.com/

Sheet DASHBOARD Bright
B47: https://exceltable.com/

Sheet Sales
B47: https://exceltable.com/

Sheet Sales Light
B47: https://exceltable.com/

Sheet Sales Bright
B47: https://exceltable.com/

Sheet Tariffs
B47: https://exceltable.com/

Sheet Tariffs Light
B47: https://exceltable.com/

Sheet Tariffs Bright
B47: https://exceltable.com/

Sheet Coverage
B47: https://exceltable.com/

Sheet Coverage Light
B47: https://exceltable.com/

Sheet Coverage Bright
B47: https://exceltable.com/

Sheet Traffic
B47: https://exceltable.com/

Sheet Traffic Light
B47: https://exceltable.com/

Sheet Traffic Bright
B47: https://exceltable.com/

Sheet Processing
B1: =ISNUMBER(MATCH(B2,Control!$A$51:$A$53,0)) -> TRUE | C1: =ISNUMBER(MATCH(C2,Control!$A$51:$A$53,0)) -> FALSE | D1: =ISNUMBER(MATCH(D2,Control!$A$51:$A$53,0)) -> FALSE | H1: TRUE | I1: toggle | J1: Traffic Sources | L1: =SUM(K2:K4) -> 0.70888889 | O1: Year | P1: indent | Q1: Subscribers | R1: Cursor | S1: https://exceltable.com/
A2: Month | B2: Revenue | C2: Expenses | D2: Profit | E2: Cursor R | F2: Cursor E | G2: Cursor P | H2: Sales Target | I2: =IF($H$1,10,0) -> 10 | J2: Referral | K2: =GETPIVOTDATA(""&J2,Control!$A$3) -> 0.16416667 | L2: Label | O2: 2025 | P2: =$P$6 -> 843.56 | Q2: =GETPIVOTDATA(""&Q$1,Control!$A$42,"Year",O2) -> 3873 | R2: =IF(ISNUMBER(MATCH(O2,Control!$A$36:$A$39,0)),Q2,NA()) -> #N/A
A3: JAN | B3: =IF(B$1,GETPIVOTDATA(""&B$2,Control!$A$20,"Month",""&$A3),NA()) -> 112023 | C3: =IF(C$1,GETPIVOTDATA(""&C$2,Control!$A$20,"Month",""&$A3),NA()) -> #N/A | D3: =IF(D$1,GETPIVOTDATA(""&D$2,Control!$A$20,"Month",""&$A3),NA()) -> #N/A | E3: =IF(ISNUMBER(GETPIVOTDATA(""&B$2,Control!$A$3,"Month",""&$A3)),B3,NA()) -> 112023 | F3: =IF(ISNUMBER(GETPIVOTDATA(""&C$2,Control!$A$3,"Month",""&$A3)),C3,NA()) -> #N/A | G3: =IF(ISNUMBER(GETPIVOTDATA(""&D$2,Control!$A$3,"Month",""&$A3)),D3,NA()) -> #N/A | H3: =IF($H$1,GETPIVOTDATA("Sum of Sales Target",Control!$A$20,"Month",""&A3),NA()) -> 100000 | I3: =IF($H$1,0,10) -> 0 | J3: Social | K3: =GETPIVOTDATA(""&J3,Control!$A$3) -> 0.3675 | L3: =J2&CHAR(10)&J3&CHAR(10)&J4&CHAR(10)&J5 -> Referral Social Organic Other | O3: 2026 | P3: =$P$6 -> 843.56 | Q3: =GETPIVOTDATA(""&Q$1,Control!$A$42,"Year",O3) -> 9235 | R3: =IF(ISNUMBER(MATCH(O3,Control!$A$36:$A$39,0)),Q3,NA()) -> #N/A
A4: FEB | B4: =IF(B$1,GETPIVOTDATA(""&B$2,Control!$A$20,"Month",""&$A4),NA()) -> 89374 | C4: =IF(C$1,GETPIVOTDATA(""&C$2,Control!$A$20,"Month",""&$A4),NA()) -> #N/A | D4: =IF(D$1,GETPIVOTDATA(""&D$2,Control!$A$20,"Month",""&$A4),NA()) -> #N/A | E4: =IF(ISNUMBER(GETPIVOTDATA(""&B$2,Control!$A$3,"Month",""&$A4)),B4,NA()) -> 89374 | F4: =IF(ISNUMBER(GETPIVOTDATA(""&C$2,Control!$A$3,"Month",""&$A4)),C4,NA()) -> #N/A | G4: =IF(ISNUMBER(GETPIVOTDATA(""&D$2,Control!$A$3,"Month",""&$A4)),D4,NA()) -> #N/A | H4: =IF($H$1,GETPIVOTDATA("Sum of Sales Target",Control!$A$20,"Month",""&A4),NA()) -> 100000 | J4: Organic | K4: =GETPIVOTDATA(""&J4,Control!$A$3) -> 0.17722222 | L4: =TEXT(K2,"0%")&CHAR(10)&TEXT(K3,"0%")&CHAR(10)&TEXT(K4,"0%")&CHAR(10)&TEXT(K5,"0%") -> 16% 37% 18% 29% | O4: 2027 | P4: =$P$6 -> 843.56 | Q4: =GETPIVOTDATA(""&Q$1,Control!$A$42,"Year",O4) -> 15418 | R4: =IF(ISNUMBER(MATCH(O4,Control!$A$36:$A$39,0)),Q4,NA()) -> #N/A
A5: MAR | B5: =IF(B$1,GETPIVOTDATA(""&B$2,Control!$A$20,"Month",""&$A5),NA()) -> 73824 | C5: =IF(C$1,GETPIVOTDATA(""&C$2,Control!$A$20,"Month",""&$A5),NA()) -> #N/A | D5: =IF(D$1,GETPIVOTDATA(""&D$2,Control!$A$20,"Month",""&$A5),NA()) -> #N/A | E5: =IF(ISNUMBER(GETPIVOTDATA(""&B$2,Control!$A$3,"Month",""&$A5)),B5,NA()) -> 73824 | F5: =IF(ISNUMBER(GETPIVOTDATA(""&C$2,Control!$A$3,"Month",""&$A5)),C5,NA()) -> #N/A | G5: =IF(ISNUMBER(GETPIVOTDATA(""&D$2,Control!$A$3,"Month",""&$A5)),D5,NA()) -> #N/A | H5: =IF($H$1,GETPIVOTDATA("Sum of Sales Target",Control!$A$20,"Month",""&A5),NA()) -> 100000 | I5: Indicators | J5: Other | K5: =GETPIVOTDATA(""&J5,Control!$A$3) -> 0.29111111 | O5: 2028 | P5: =$P$6 -> 843.56 | Q5: =GETPIVOTDATA(""&Q$1,Control!$A$42,"Year",O5) -> 21089 | R5: =IF(ISNUMBER(MATCH(O5,Control!$A$36:$A$39,0)),Q5,NA()) -> 21089
A6: APR | B6: =IF(B$1,GETPIVOTDATA(""&B$2,Control!$A$20,"Month",""&$A6),NA()) -> 70497 | C6: =IF(C$1,GETPIVOTDATA(""&C$2,Control!$A$20,"Month",""&$A6),NA()) -> #N/A | D6: =IF(D$1,GETPIVOTDATA(""&D$2,Control!$A$20,"Month",""&$A6),NA()) -> #N/A | E6: =IF(ISNUMBER(GETPIVOTDATA(""&B$2,Control!$A$3,"Month",""&$A6)),B6,NA()) -> 70497 | F6: =IF(ISNUMBER(GETPIVOTDATA(""&C$2,Control!$A$3,"Month",""&$A6)),C6,NA()) -> #N/A | G6: =IF(ISNUMBER(GETPIVOTDATA(""&D$2,Control!$A$3,"Month",""&$A6)),D6,NA()) -> #N/A | H6: =IF($H$1,GETPIVOTDATA("Sum of Sales Target",Control!$A$20,"Month",""&A6),NA()) -> 100000 | I6: Revenue | P6: =MAX(Q2:Q5)*4% -> 843.56 | R6: =GETPIVOTDATA("Sum of Subscribers",Control!$A$3) -> 21089
A7: MAY | B7: =IF(B$1,GETPIVOTDATA(""&B$2,Control!$A$20,"Month",""&$A7),NA()) -> 80257 | C7: =IF(C$1,GETPIVOTDATA(""&C$2,Control!$A$20,"Month",""&$A7),NA()) -> #N/A | D7: =IF(D$1,GETPIVOTDATA(""&D$2,Control!$A$20,"Month",""&$A7),NA()) -> #N/A | E7: =IF(ISNUMBER(GETPIVOTDATA(""&B$2,Control!$A$3,"Month",""&$A7)),B7,NA()) -> 80257 | F7: =IF(ISNUMBER(GETPIVOTDATA(""&C$2,Control!$A$3,"Month",""&$A7)),C7,NA()) -> #N/A | G7: =IF(ISNUMBER(GETPIVOTDATA(""&D$2,Control!$A$3,"Month",""&$A7)),D7,NA()) -> #N/A | H7: =IF($H$1,GETPIVOTDATA("Sum of Sales Target",Control!$A$20,"Month",""&A7),NA()) -> 100000 | I7: Expenses | K7: District | L7: Coverage | M7: Coverage Target | N7: =IF($H$1,H17,"") -> Target | P7: Leads | Q7: Deals
A8: JUN | B8: =IF(B$1,GETPIVOTDATA(""&B$2,Control!$A$20,"Month",""&$A8),NA()) -> 100146 | C8: =IF(C$1,GETPIVOTDATA(""&C$2,Control!$A$20,"Month",""&$A8),NA()) -> #N/A | D8: =IF(D$1,GETPIVOTDATA(""&D$2,Control!$A$20,"Month",""&$A8),NA()) -> #N/A | E8: =IF(ISNUMBER(GETPIVOTDATA(""&B$2,Control!$A$3,"Month",""&$A8)),B8,NA()) -> 100146 | F8: =IF(ISNUMBER(GETPIVOTDATA(""&C$2,Control!$A$3,"Month",""&$A8)),C8,NA()) -> #N/A | G8: =IF(ISNUMBER(GETPIVOTDATA(""&D$2,Control!$A$3,"Month",""&$A8)),D8,NA()) -> #N/A | H8: =IF($H$1,GETPIVOTDATA("Sum of Sales Target",Control!$A$20,"Month",""&A8),NA()) -> 100000 | I8: Profit | J8: North | K8: N | L8: =GETPIVOTDATA(""&K8,Control!$A$3) -> 0.96666667 | M8: =IF($H$1,GETPIVOTDATA("Max of Coverage Target",Control!$A$3),NA()) -> 1 | N8: =IF($H$1,M15,"") -> 1 | P8: =GETPIVOTDATA("Sum of Leads",Control!$A$3) -> 44358 | Q8: =GETPIVOTDATA("Sum of Deals",Control!$A$3) -> 28942
A9: JUL | B9: =IF(B$1,GETPIVOTDATA(""&B$2,Control!$A$20,"Month",""&$A9),NA()) -> 123979 | C9: =IF(C$1,GETPIVOTDATA(""&C$2,Control!$A$20,"Month",""&$A9),NA()) -> #N/A | D9: =IF(D$1,GETPIVOTDATA(""&D$2,Control!$A$20,"Month",""&$A9),NA()) -> #N/A | E9: =IF(ISNUMBER(GETPIVOTDATA(""&B$2,Control!$A$3,"Month",""&$A9)),B9,NA()) -> 123979 | F9: =IF(ISNUMBER(GETPIVOTDATA(""&C$2,Control!$A$3,"Month",""&$A9)),C9,NA()) -> #N/A | G9: =IF(ISNUMBER(GETPIVOTDATA(""&D$2,Control!$A$3,"Month",""&$A9)),D9,NA()) -> #N/A | H9: =IF($H$1,GETPIVOTDATA("Sum of Sales Target",Control!$A$20,"Month",""&A9),NA()) -> 100000 | J9: Northeast | K9: NE | L9: =GETPIVOTDATA(""&K9,Control!$A$3) -> 0.95833333 | M9: =IF($H$1,GETPIVOTDATA("Max of Coverage Target",Control!$A$3),NA()) -> 1 | P9: Conversion
A10: AUG | B10: =IF(B$1,GETPIVOTDATA(""&B$2,Control!$A$20,"Month",""&$A10),NA()) -> 143879 | C10: =IF(C$1,GETPIVOTDATA(""&C$2,Control!$A$20,"Month",""&$A10),NA()) -> #N/A | D10: =IF(D$1,GETPIVOTDATA(""&D$2,Control!$A$20,"Month",""&$A10),NA()) -> #N/A | E10: =IF(ISNUMBER(GETPIVOTDATA(""&B$2,Control!$A$3,"Month",""&$A10)),B10,NA()) -> 143879 | F10: =IF(ISNUMBER(GETPIVOTDATA(""&C$2,Control!$A$3,"Month",""&$A10)),C10,NA()) -> #N/A | G10: =IF(ISNUMBER(GETPIVOTDATA(""&D$2,Control!$A$3,"Month",""&$A10)),D10,NA()) -> #N/A | H10: =IF($H$1,GETPIVOTDATA("Sum of Sales Target",Control!$A$20,"Month",""&A10),NA()) -> 100000 | J10: East | K10: E | L10: =GETPIVOTDATA(""&K10,Control!$A$3) -> 0.95 | M10: =IF($H$1,GETPIVOTDATA("Max of Coverage Target",Control!$A$3),NA()) -> 1 | P10: =Q8/P8 -> 0.65246404 | Q10: =1-P10 -> 0.34753596
A11: SEP | B11: =IF(B$1,GETPIVOTDATA(""&B$2,Control!$A$20,"Month",""&$A11),NA()) -> 153629 | C11: =IF(C$1,GETPIVOTDATA(""&C$2,Control!$A$20,"Month",""&$A11),NA()) -> #N/A | D11: =IF(D$1,GETPIVOTDATA(""&D$2,Control!$A$20,"Month",""&$A11),NA()) -> #N/A | E11: =IF(ISNUMBER(GETPIVOTDATA(""&B$2,Control!$A$3,"Month",""&$A11)),B11,NA()) -> 153629 | F11: =IF(ISNUMBER(GETPIVOTDATA(""&C$2,Control!$A$3,"Month",""&$A11)),C11,NA()) -> #N/A | G11: =IF(ISNUMBER(GETPIVOTDATA(""&D$2,Control!$A$3,"Month",""&$A11)),D11,NA()) -> #N/A | H11: =IF($H$1,GETPIVOTDATA("Sum of Sales Target",Control!$A$20,"Month",""&A11),NA()) -> 100000 | J11: Southeast | K11: SE | L11: =GETPIVOTDATA(""&K11,Control!$A$3) -> 0.94166667 | M11: =IF($H$1,GETPIVOTDATA("Max of Coverage Target",Control!$A$3),NA()) -> 1
A12: OCT | B12: =IF(B$1,GETPIVOTDATA(""&B$2,Control!$A$20,"Month",""&$A12),NA()) -> 150252 | C12: =IF(C$1,GETPIVOTDATA(""&C$2,Control!$A$20,"Month",""&$A12),NA()) -> #N/A | D12: =IF(D$1,GETPIVOTDATA(""&D$2,Control!$A$20,"Month",""&$A12),NA()) -> #N/A | E12: =IF(ISNUMBER(GETPIVOTDATA(""&B$2,Control!$A$3,"Month",""&$A12)),B12,NA()) -> 150252 | F12: =IF(ISNUMBER(GETPIVOTDATA(""&C$2,Control!$A$3,"Month",""&$A12)),C12,NA()) -> #N/A | G12: =IF(ISNUMBER(GETPIVOTDATA(""&D$2,Control!$A$3,"Month",""&$A12)),D12,NA()) -> #N/A | H12: =IF($H$1,GETPIVOTDATA("Sum of Sales Target",Control!$A$20,"Month",""&A12),NA()) -> 100000 | J12: South | K12: S | L12: =GETPIVOTDATA(""&K12,Control!$A$3) -> 0.93333333 | M12: =IF($H$1,GETPIVOTDATA("Max of Coverage Target",Control!$A$3),NA()) -> 1 | P12: Target | Q12: =E15/H15 -> 1.1206375
A13: NOV | B13: =IF(B$1,GETPIVOTDATA(""&B$2,Control!$A$20,"Month",""&$A13),NA()) -> 134779 | C13: =IF(C$1,GETPIVOTDATA(""&C$2,Control!$A$20,"Month",""&$A13),NA()) -> #N/A | D13: =IF(D$1,GETPIVOTDATA(""&D$2,Control!$A$20,"Month",""&$A13),NA()) -> #N/A | E13: =IF(ISNUMBER(GETPIVOTDATA(""&B$2,Control!$A$3,"Month",""&$A13)),B13,NA()) -> 134779 | F13: =IF(ISNUMBER(GETPIVOTDATA(""&C$2,Control!$A$3,"Month",""&$A13)),C13,NA()) -> #N/A | G13: =IF(ISNUMBER(GETPIVOTDATA(""&D$2,Control!$A$3,"Month",""&$A13)),D13,NA()) -> #N/A | H13: =IF($H$1,GETPIVOTDATA("Sum of Sales Target",Control!$A$20,"Month",""&A13),NA()) -> 100000 | J13: Southwest | K13: SW | L13: =GETPIVOTDATA(""&K13,Control!$A$3) -> 0.91666667 | M13: =IF($H$1,GETPIVOTDATA("Max of Coverage Target",Control!$A$3),NA()) -> 1 | P13: =IF($Q$12>100%,0,$Q$12) -> 0
A14: DEC | B14: =IF(B$1,GETPIVOTDATA(""&B$2,Control!$A$20,"Month",""&$A14),NA()) -> 112126 | C14: =IF(C$1,GETPIVOTDATA(""&C$2,Control!$A$20,"Month",""&$A14),NA()) -> #N/A | D14: =IF(D$1,GETPIVOTDATA(""&D$2,Control!$A$20,"Month",""&$A14),NA()) -> #N/A | E14: =IF(ISNUMBER(GETPIVOTDATA(""&B$2,Control!$A$3,"Month",""&$A14)),B14,NA()) -> 112126 | F14: =IF(ISNUMBER(GETPIVOTDATA(""&C$2,Control!$A$3,"Month",""&$A14)),C14,NA()) -> #N/A | G14: =IF(ISNUMBER(GETPIVOTDATA(""&D$2,Control!$A$3,"Month",""&$A14)),D14,NA()) -> #N/A | H14: =IF($H$1,GETPIVOTDATA("Sum of Sales Target",Control!$A$20,"Month",""&A14),NA()) -> 100000 | J14: West | K14: W | L14: =GETPIVOTDATA(""&K14,Control!$A$3) -> 0.9 | M14: =IF($H$1,GETPIVOTDATA("Max of Coverage Target",Control!$A$3),NA()) -> 1 | P14: =IF($Q$12>100%,0,1-P13) -> 0
E15: =GETPIVOTDATA(""&B2,Control!$A$3) -> 1344765 | F15: =GETPIVOTDATA(""&C2,Control!$A$3) -> 1277190 | G15: =GETPIVOTDATA(""&D2,Control!$A$3) -> 67575 | H15: =GETPIVOTDATA(""&H2,Control!$A$3) -> 1200000 | J15: Northwest | K15: NW | L15: =GETPIVOTDATA(""&K15,Control!$A$3) -> 0.88333333 | M15: =IF($H$1,GETPIVOTDATA("Max of Coverage Target",Control!$A$3),NA()) -> 1 | P15: =IF($Q$12>100%,Q12-1,0) -> 0.1206375
C16: =ISNUMBER(MATCH(C17,Control!$A$58:$A$59,0)) -> TRUE | D16: =ISNUMBER(MATCH(D17,Control!$A$58:$A$59,0)) -> TRUE | L16: =AVERAGE(L8:L15) -> 0.93125 | P16: =IF($Q$12>100%,1-P15,0) -> 0.8793625
A17: Month | B17: indent | C17: Standart | D17: Premium | E17: indent C | F17: Cursor S | G17: Cursor P | H17: Target | I17: Tariffs | K17: Month | L17: Referral | M17: Social | N17: Organic | O17: Other | P17: Cursor | Q17: Traffic
A18: JAN | B18: =$B$30 -> 71.92 | C18: =IF(C$16,GETPIVOTDATA(""&C$17,Control!$A$20,"Month",""&$A18),NA()) -> 1090 | D18: =IF(D$16,GETPIVOTDATA(""&D$17,Control!$A$20,"Month",""&$A18),NA()) -> 474 | E18: =B18 -> 71.92 | F18: =IF(ISNUMBER(GETPIVOTDATA("Sum of Revenue",Control!$A$3,"Month",""&$A18)),C18,NA()) -> 1090 | G18: =IF(ISNUMBER(GETPIVOTDATA("Sum of Revenue",Control!$A$3,"Month",""&$A18)),D18,NA()) -> 474 | H18: =IF($H$1,GETPIVOTDATA(""&H$30,Control!$A$20,"Month",""&A3),NA()) -> 1800 | I18: Standart | K18: JAN | L18: =IF(L$30,GETPIVOTDATA(""&L$17,Control!$A$20,"Month",""&$K18),NA()) -> 0.13 | M18: =IF(M$30,GETPIVOTDATA(""&M$17,Control!$A$20,"Month",""&$K18),NA()) -> 0.31 | N18: =IF(N$30,GETPIVOTDATA(""&N$17,Control!$A$20,"Month",""&$K18),NA()) -> 0.14666667 | O18: =IF(O$30,GETPIVOTDATA(""&O$17,Control!$A$20,"Month",""&$K18),NA()) -> 0.41333333 | P18: {=IF(ISNA(F18),F18,MAX(IFERROR($L$18:$O$29,0)+10%))} -> 0.63333333 | Q18: Referral
A19: FEB | B19: =$B$30 -> 71.92 | C19: =IF(C$16,GETPIVOTDATA(""&C$17,Control!$A$20,"Month",""&$A19),NA()) -> 956 | D19: =IF(D$16,GETPIVOTDATA(""&D$17,Control!$A$20,"Month",""&$A19),NA()) -> 561 | E19: =B19 -> 71.92 | F19: =IF(ISNUMBER(GETPIVOTDATA("Sum of Revenue",Control!$A$3,"Month",""&$A19)),C19,NA()) -> 956 | G19: =IF(ISNUMBER(GETPIVOTDATA("Sum of Revenue",Control!$A$3,"Month",""&$A19)),D19,NA()) -> 561 | H19: =IF($H$1,GETPIVOTDATA(""&H$30,Control!$A$20,"Month",""&A4),NA()) -> 1800 | I19: Premium | K19: FEB | L19: =IF(L$30,GETPIVOTDATA(""&L$17,Control!$A$20,"Month",""&$K19),NA()) -> 0.21 | M19: =IF(M$30,GETPIVOTDATA(""&M$17,Control!$A$20,"Month",""&$K19),NA()) -> 0.44 | N19: =IF(N$30,GETPIVOTDATA(""&N$17,Control!$A$20,"Month",""&$K19),NA()) -> 0.21666667 | O19: =IF(O$30,GETPIVOTDATA(""&O$17,Control!$A$20,"Month",""&$K19),NA()) -> 0.13333333 | P19: {=IF(ISNA(F19),F19,MAX(IFERROR($L$18:$O$29,0)+10%))} -> 0.63333333 | Q19: Social
A20: MAR | B20: =$B$30 -> 71.92 | C20: =IF(C$16,GETPIVOTDATA(""&C$17,Control!$A$20,"Month",""&$A20),NA()) -> 969 | D20: =IF(D$16,GETPIVOTDATA(""&D$17,Control!$A$20,"Month",""&$A20),NA()) -> 614 | E20: =B20 -> 71.92 | F20: =IF(ISNUMBER(GETPIVOTDATA("Sum of Revenue",Control!$A$3,"Month",""&$A20)),C20,NA()) -> 969 | G20: =IF(ISNUMBER(GETPIVOTDATA("Sum of Revenue",Control!$A$3,"Month",""&$A20)),D20,NA()) -> 614 | H20: =IF($H$1,GETPIVOTDATA(""&H$30,Control!$A$20,"Month",""&A5),NA()) -> 1800 | K20: MAR | L20: =IF(L$30,GETPIVOTDATA(""&L$17,Control!$A$20,"Month",""&$K20),NA()) -> 0.18 | M20: =IF(M$30,GETPIVOTDATA(""&M$17,Control!$A$20,"Month",""&$K20),NA()) -> 0.27 | N20: =IF(N$30,GETPIVOTDATA(""&N$17,Control!$A$20,"Month",""&$K20),NA()) -> 0.15 | O20: =IF(O$30,GETPIVOTDATA(""&O$17,Control!$A$20,"Month",""&$K20),NA()) -> 0.4 | P20: {=IF(ISNA(F20),F20,MAX(IFERROR($L$18:$O$29,0)+10%))} -> 0.63333333 | Q20: Organic
A21: APR | B21: =$B$30 -> 71.92 | C21: =IF(C$16,GETPIVOTDATA(""&C$17,Control!$A$20,"Month",""&$A21),NA()) -> 1430 | D21: =IF(D$16,GETPIVOTDATA(""&D$17,Control!$A$20,"Month",""&$A21),NA()) -> 254 | E21: =B21 -> 71.92 | F21: =IF(ISNUMBER(GETPIVOTDATA("Sum of Revenue",Control!$A$3,"Month",""&$A21)),C21,NA()) -> 1430 | G21: =IF(ISNUMBER(GETPIVOTDATA("Sum of Revenue",Control!$A$3,"Month",""&$A21)),D21,NA()) -> 254 | H21: =IF($H$1,GETPIVOTDATA(""&H$30,Control!$A$20,"Month",""&A6),NA()) -> 1800 | I21: =IF(H1,"Total Target","") -> Total Target | K21: APR | L21: =IF(L$30,GETPIVOTDATA(""&L$17,Control!$A$20,"Month",""&$K21),NA()) -> 0.07 | M21: =IF(M$30,GETPIVOTDATA(""&M$17,Control!$A$20,"Month",""&$K21),NA()) -> 0.47 | N21: =IF(N$30,GETPIVOTDATA(""&N$17,Control!$A$20,"Month",""&$K21),NA()) -> 0.18 | O21: =IF(O$30,GETPIVOTDATA(""&O$17,Control!$A$20,"Month",""&$K21),NA()) -> 0.28 | P21: {=IF(ISNA(F21),F21,MAX(IFERROR($L$18:$O$29,0)+10%))} -> 0.63333333 | Q21: Other
A22: MAY | B22: =$B$30 -> 71.92 | C22: =IF(C$16,GETPIVOTDATA(""&C$17,Control!$A$20,"Month",""&$A22),NA()) -> 834 | D22: =IF(D$16,GETPIVOTDATA(""&D$17,Control!$A$20,"Month",""&$A22),NA()) -> 913 | E22: =B22 -> 71.92 | F22: =IF(ISNUMBER(GETPIVOTDATA("Sum of Revenue",Control!$A$3,"Month",""&$A22)),C22,NA()) -> 834 | G22: =IF(ISNUMBER(GETPIVOTDATA("Sum of Revenue",Control!$A$3,"Month",""&$A22)),D22,NA()) -> 913 | H22: =IF($H$1,GETPIVOTDATA(""&H$30,Control!$A$20,"Month",""&A7),NA()) -> 1800 | I22: =IF(H1,H18,"") -> 1800 | K22: MAY | L22: =IF(L$30,GETPIVOTDATA(""&L$17,Control!$A$20,"Month",""&$K22),NA()) -> 0.12 | M22: =IF(M$30,GETPIVOTDATA(""&M$17,Control!$A$20,"Month",""&$K22),NA()) -> 0.44 | N22: =IF(N$30,GETPIVOTDATA(""&N$17,Control!$A$20,"Month",""&$K22),NA()) -> 0.18666667 | O22: =IF(O$30,GETPIVOTDATA(""&O$17,Control!$A$20,"Month",""&$K22),NA()) -> 0.25333333 | P22: {=IF(ISNA(F22),F22,MAX(IFERROR($L$18:$O$29,0)+10%))} -> 0.63333333
A23: JUN | B23: =$B$30 -> 71.92 | C23: =IF(C$16,GETPIVOTDATA(""&C$17,Control!$A$20,"Month",""&$A23),NA()) -> 961 | D23: =IF(D$16,GETPIVOTDATA(""&D$17,Control!$A$20,"Month",""&$A23),NA()) -> 803 | E23: =B23 -> 71.92 | F23: =IF(ISNUMBER(GETPIVOTDATA("Sum of Revenue",Control!$A$3,"Month",""&$A23)),C23,NA()) -> 961 | G23: =IF(ISNUMBER(GETPIVOTDATA("Sum of Revenue",Control!$A$3,"Month",""&$A23)),D23,NA()) -> 803 | H23: =IF($H$1,GETPIVOTDATA(""&H$30,Control!$A$20,"Month",""&A8),NA()) -> 1800 | K23: JUN | L23: =IF(L$30,GETPIVOTDATA(""&L$17,Control!$A$20,"Month",""&$K23),NA()) -> 0.25 | M23: =IF(M$30,GETPIVOTDATA(""&M$17,Control!$A$20,"Month",""&$K23),NA()) -> 0.38 | N23: =IF(N$30,GETPIVOTDATA(""&N$17,Control!$A$20,"Month",""&$K23),NA()) -> 0.21 | O23: =IF(O$30,GETPIVOTDATA(""&O$17,Control!$A$20,"Month",""&$K23),NA()) -> 0.16 | P23: {=IF(ISNA(F23),F23,MAX(IFERROR($L$18:$O$29,0)+10%))} -> 0.63333333
A24: JUL | B24: =$B$30 -> 71.92 | C24: =IF(C$16,GETPIVOTDATA(""&C$17,Control!$A$20,"Month",""&$A24),NA()) -> 1644 | D24: =IF(D$16,GETPIVOTDATA(""&D$17,Control!$A$20,"Month",""&$A24),NA()) -> 149 | E24: =B24 -> 71.92 | F24: =IF(ISNUMBER(GETPIVOTDATA("Sum of Revenue",Control!$A$3,"Month",""&$A24)),C24,NA()) -> 1644 | G24: =IF(ISNUMBER(GETPIVOTDATA("Sum of Revenue",Control!$A$3,"Month",""&$A24)),D24,NA()) -> 149 | H24: =IF($H$1,GETPIVOTDATA(""&H$30,Control!$A$20,"Month",""&A9),NA()) -> 1800 | K24: JUL | L24: =IF(L$30,GETPIVOTDATA(""&L$17,Control!$A$20,"Month",""&$K24),NA()) -> 0.18 | M24: =IF(M$30,GETPIVOTDATA(""&M$17,Control!$A$20,"Month",""&$K24),NA()) -> 0.48 | N24: =IF(N$30,GETPIVOTDATA(""&N$17,Control!$A$20,"Month",""&$K24),NA()) -> 0.22 | O24: =IF(O$30,GETPIVOTDATA(""&O$17,Control!$A$20,"Month",""&$K24),NA()) -> 0.12 | P24: {=IF(ISNA(F24),F24,MAX(IFERROR($L$18:$O$29,0)+10%))} -> 0.63333333
A25: AUG | B25: =$B$30 -> 71.92 | C25: =IF(C$16,GETPIVOTDATA(""&C$17,Control!$A$20,"Month",""&$A25),NA()) -> 1637 | D25: =IF(D$16,GETPIVOTDATA(""&D$17,Control!$A$20,"Month",""&$A25),NA()) -> 149 | E25: =B25 -> 71.92 | F25: =IF(ISNUMBER(GETPIVOTDATA("Sum of Revenue",Control!$A$3,"Month",""&$A25)),C25,NA()) -> 1637 | G25: =IF(ISNUMBER(GETPIVOTDATA("Sum of Revenue",Control!$A$3,"Month",""&$A25)),D25,NA()) -> 149 | H25: =IF($H$1,GETPIVOTDATA(""&H$30,Control!$A$20,"Month",""&A10),NA()) -> 1800 | K25: AUG | L25: =IF(L$30,GETPIVOTDATA(""&L$17,Control!$A$20,"Month",""&$K25),NA()) -> 0.18 | M25: =IF(M$30,GETPIVOTDATA(""&M$17,Control!$A$20,"Month",""&$K25),NA()) -> 0.43 | N25: =IF(N$30,GETPIVOTDATA(""&N$17,Control!$A$20,"Month",""&$K25),NA()) -> 0.20333333 | O25: =IF(O$30,GETPIVOTDATA(""&O$17,Control!$A$20,"Month",""&$K25),NA()) -> 0.18666667 | P25: {=IF(ISNA(F25),F25,MAX(IFERROR($L$18:$O$29,0)+10%))} -> 0.63333333
A26: SEP | B26: =$B$30 -> 71.92 | C26: =IF(C$16,GETPIVOTDATA(""&C$17,Control!$A$20,"Month",""&$A26),NA()) -> 1482 | D26: =IF(D$16,GETPIVOTDATA(""&D$17,Control!$A$20,"Month",""&$A26),NA()) -> 338 | E26: =B26 -> 71.92 | F26: =IF(ISNUMBER(GETPIVOTDATA("Sum of Revenue",Control!$A$3,"Month",""&$A26)),C26,NA()) -> 1482 | G26: =IF(ISNUMBER(GETPIVOTDATA("Sum of Revenue",Control!$A$3,"Month",""&$A26)),D26,NA()) -> 338 | H26: =IF($H$1,GETPIVOTDATA(""&H$30,Control!$A$20,"Month",""&A11),NA()) -> 1800 | K26: SEP | L26: =IF(L$30,GETPIVOTDATA(""&L$17,Control!$A$20,"Month",""&$K26),NA()) -> 0.23 | M26: =IF(M$30,GETPIVOTDATA(""&M$17,Control!$A$20,"Month",""&$K26),NA()) -> 0.43 | N26: =IF(N$30,GETPIVOTDATA(""&N$17,Control!$A$20,"Month",""&$K26),NA()) -> 0.22 | O26: =IF(O$30,GETPIVOTDATA(""&O$17,Control!$A$20,"Month",""&$K26),NA()) -> 0.12 | P26: {=IF(ISNA(F26),F26,MAX(IFERROR($L$18:$O$29,0)+10%))} -> 0.63333333
A27: OCT | B27: =$B$30 -> 71.92 | C27: =IF(C$16,GETPIVOTDATA(""&C$17,Control!$A$20,"Month",""&$A27),NA()) -> 1701 | D27: =IF(D$16,GETPIVOTDATA(""&D$17,Control!$A$20,"Month",""&$A27),NA()) -> 189 | E27: =B27 -> 71.92 | F27: =IF(ISNUMBER(GETPIVOTDATA("Sum of Revenue",Control!$A$3,"Month",""&$A27)),C27,NA()) -> 1701 | G27: =IF(ISNUMBER(GETPIVOTDATA("Sum of Revenue",Control!$A$3,"Month",""&$A27)),D27,NA()) -> 189 | H27: =IF($H$1,GETPIVOTDATA(""&H$30,Control!$A$20,"Month",""&A12),NA()) -> 1800 | K27: OCT | L27: =IF(L$30,GETPIVOTDATA(""&L$17,Control!$A$20,"Month",""&$K27),NA()) -> 0.18 | M27: =IF(M$30,GETPIVOTDATA(""&M$17,Control!$A$20,"Month",""&$K27),NA()) -> 0.2 | N27: =IF(N$30,GETPIVOTDATA(""&N$17,Control!$A$20,"Month",""&$K27),NA()) -> 0.12666667 | O27: =IF(O$30,GETPIVOTDATA(""&O$17,Control!$A$20,"Month",""&$K27),NA()) -> 0.49333333 | P27: {=IF(ISNA(F27),F27,MAX(IFERROR($L$18:$O$29,0)+10%))} -> 0.63333333
A28: NOV | B28: =$B$30 -> 71.92 | C28: =IF(C$16,GETPIVOTDATA(""&C$17,Control!$A$20,"Month",""&$A28),NA()) -> 1156 | D28: =IF(D$16,GETPIVOTDATA(""&D$17,Control!$A$20,"Month",""&$A28),NA()) -> 785 | E28: =B28 -> 71.92 | F28: =IF(ISNUMBER(GETPIVOTDATA("Sum of Revenue",Control!$A$3,"Month",""&$A28)),C28,NA()) -> 1156 | G28: =IF(ISNUMBER(GETPIVOTDATA("Sum of Revenue",Control!$A$3,"Month",""&$A28)),D28,NA()) -> 785 | H28: =IF($H$1,GETPIVOTDATA(""&H$30,Control!$A$20,"Month",""&A13),NA()) -> 1800 | K28: NOV | L28: =IF(L$30,GETPIVOTDATA(""&L$17,Control!$A$20,"Month",""&$K28),NA()) -> 0.12 | M28: =IF(M$30,GETPIVOTDATA(""&M$17,Control!$A$20,"Month",""&$K28),NA()) -> 0.33 | N28: =IF(N$30,GETPIVOTDATA(""&N$17,Control!$A$20,"Month",""&$K28),NA()) -> 0.15 | O28: =IF(O$30,GETPIVOTDATA(""&O$17,Control!$A$20,"Month",""&$K28),NA()) -> 0.4 | P28: {=IF(ISNA(F28),F28,MAX(IFERROR($L$18:$O$29,0)+10%))} -> 0.63333333
A29: DEC | B29: =$B$30 -> 71.92 | C29: =IF(C$16,GETPIVOTDATA(""&C$17,Control!$A$20,"Month",""&$A29),NA()) -> 1798 | D29: =IF(D$16,GETPIVOTDATA(""&D$17,Control!$A$20,"Month",""&$A29),NA()) -> 202 | E29: =B29 -> 71.92 | F29: =IF(ISNUMBER(GETPIVOTDATA("Sum of Revenue",Control!$A$3,"Month",""&$A29)),C29,NA()) -> 1798 | G29: =IF(ISNUMBER(GETPIVOTDATA("Sum of Revenue",Control!$A$3,"Month",""&$A29)),D29,NA()) -> 202 | H29: =IF($H$1,GETPIVOTDATA(""&H$30,Control!$A$20,"Month",""&A14),NA()) -> 1800 | K29: DEC | L29: =IF(L$30,GETPIVOTDATA(""&L$17,Control!$A$20,"Month",""&$K29),NA()) -> 0.12 | M29: =IF(M$30,GETPIVOTDATA(""&M$17,Control!$A$20,"Month",""&$K29),NA()) -> 0.23 | N29: =IF(N$30,GETPIVOTDATA(""&N$17,Control!$A$20,"Month",""&$K29),NA()) -> 0.11666667 | O29: =IF(O$30,GETPIVOTDATA(""&O$17,Control!$A$20,"Month",""&$K29),NA()) -> 0.53333333 | P29: {=IF(ISNA(F29),F29,MAX(IFERROR($L$18:$O$29,0)+10%))} -> 0.63333333
B30: {=MAX(IFERROR(C18:D29,0))*4%} -> 71.92 | F30: =GETPIVOTDATA("Sum of Standart",Control!$A$3) -> 15658 | G30: =GETPIVOTDATA("Sum of Premium",Control!$A$3) -> 5431 | H30: Subscribers Target | L30: =ISNUMBER(MATCH(L17,Control!$A$63:$A$66,0)) -> TRUE | M30: =ISNUMBER(MATCH(M17,Control!$A$63:$A$66,0)) -> TRUE | N30: =ISNUMBER(MATCH(N17,Control!$A$63:$A$66,0)) -> TRUE | O30: =ISNUMBER(MATCH(O17,Control!$A$63:$A$66,0)) -> TRUE

Sheet Control
A3: Row Labels | B3: Sum of Revenue | C3: Sum of Expenses | D3: Sum of Profit | E3: Sum of Subscribers | F3: Sum of Leads | G3: Sum of Deals | H3: Average of Referral | I3: Average of Social | J3: Average of Organic | K3: Average of Other | L3: Average of N | M3: Average of NE | N3: Average of E | O3: Average of SE | P3: Average of S | Q3: Average of SW | R3: Average of W | S3: Average of NW | T3: Sum of Sales Target | U3: Sum of Subscribers Target | V3: Sum of Standart | W3: Sum of Premium | X3: Max of Coverage Target
A4: JAN | B4: 112023 | C4: 100740 | D4: 11283 | E4: 1564 | F4: 3018 | G4: 2658 | H4: 0.13 | I4: 0.31 | J4: 0.14666667 | K4: 0.41333333 | L4: 0.9 | M4: 0.9 | N4: 0.9 | O4: 0.9 | P4: 0.9 | Q4: 0.8 | R4: 0.8 | S4: 0.8 | T4: 100000 | U4: 1800 | V4: 1090 | W4: 474 | X4: 1
A5: FEB | B5: 89374 | C5: 94530 | D5: -5156 | E5: 1517 | F5: 3261 | G5: 2336 | H5: 0.21 | I5: 0.44 | J5: 0.21666667 | K5: 0.13333333 | L5: 0.9 | M5: 0.9 | N5: 0.9 | O5: 0.9 | P5: 0.9 | Q5: 0.9 | R5: 0.8 | S5: 0.8 | T5: 100000 | U5: 1800 | V5: 956 | W5: 561 | X5: 1
A6: MAR | B6: 73824 | C6: 102810 | D6: -28986 | E6: 1583 | F6: 3039 | G6: 2437 | H6: 0.18 | I6: 0.27 | J6: 0.15 | K6: 0.4 | L6: 0.9 | M6: 0.9 | N6: 0.9 | O6: 0.9 | P6: 0.9 | Q6: 0.9 | R6: 0.9 | S6: 0.8 | T6: 100000 | U6: 1800 | V6: 969 | W6: 614 | X6: 1
A7: APR | B7: 70497 | C7: 113850 | D7: -43353 | E7: 1684 | F7: 2997 | G7: 2576 | H7: 0.07 | I7: 0.47 | J7: 0.18 | K7: 0.28 | L7: 0.9 | M7: 0.9 | N7: 0.9 | O7: 0.9 | P7: 0.9 | Q7: 0.9 | R7: 0.9 | S7: 0.9 | T7: 100000 | U7: 1800 | V7: 1430 | W7: 254 | X7: 1
A8: MAY | B8: 80257 | C8: 106260 | D8: -26003 | E8: 1747 | F8: 4332 | G8: 2882 | H8: 0.12 | I8: 0.44 | J8: 0.18666667 | K8: 0.25333333 | L8: 1 | M8: 0.9 | N8: 0.9 | O8: 0.9 | P8: 0.9 | Q8: 0.9 | R8: 0.9 | S8: 0.9 | T8: 100000 | U8: 1800 | V8: 834 | W8: 913 | X8: 1
A9: JUN | B9: 100146 | C9: 89700 | D9: 10446 | E9: 1764 | F9: 3139 | G9: 2504 | H9: 0.25 | I9: 0.38 | J9: 0.21 | K9: 0.16 | L9: 1 | M9: 1 | N9: 0.9 | O9: 0.9 | P9: 0.9 | Q9: 0.9 | R9: 0.9 | S9: 0.9 | T9: 100000 | U9: 1800 | V9: 961 | W9: 803 | X9: 1
A10: JUL | B10: 123979 | C10: 88320 | D10: 35659 | E10: 1793 | F10: 2797 | G10: 1972 | H10: 0.18 | I10: 0.48 | J10: 0.22 | K10: 0.12 | L10: 1 | M10: 1 | N10: 1 | O10: 0.9 | P10: 0.9 | Q10: 0.9 | R10: 0.9 | S10: 0.9 | T10: 100000 | U10: 1800 | V10: 1644 | W10: 149 | X10: 1
A11: AUG | B11: 143879 | C11: 99360 | D11: 44519 | E11: 1786 | F11: 4036 | G11: 2089 | H11: 0.18 | I11: 0.43 | J11: 0.20333333 | K11: 0.18666667 | L11: 1 | M11: 1 | N11: 1 | O11: 1 | P11: 0.9 | Q11: 0.9 | R11: 0.9 | S11: 0.9 | T11: 100000 | U11: 1800 | V11: 1637 | W11: 149 | X11: 1
A12: SEP | B12: 153629 | C12: 120060 | D12: 33569 | E12: 1820 | F12: 4604 | G12: 2129 | H12: 0.23 | I12: 0.43 | J12: 0.22 | K12: 0.12 | L12: 1 | M12: 1 | N12: 1 | O12: 1 | P12: 1 | Q12: 0.9 | R12: 0.9 | S12: 0.9 | T12: 100000 | U12: 1800 | V12: 1482 | W12: 338 | X12: 1
A13: OCT | B13: 150252 | C13: 128340 | D13: 21912 | E13: 1890 | F13: 3780 | G13: 2740 | H13: 0.18 | I13: 0.2 | J13: 0.12666667 | K13: 0.49333333 | L13: 1 | M13: 1 | N13: 1 | O13: 1 | P13: 1 | Q13: 1 | R13: 0.9 | S13: 0.9 | T13: 100000 | U13: 1800 | V13: 1701 | W13: 189 | X13: 1
A14: NOV | B14: 134779 | C14: 122820 | D14: 11959 | E14: 1941 | F14: 5415 | G14: 1979 | H14: 0.12 | I14: 0.33 | J14: 0.15 | K14: 0.4 | L14: 1 | M14: 1 | N14: 1 | O14: 1 | P14: 1 | Q14: 1 | R14: 1 | S14: 0.9 | T14: 100000 | U14: 1800 | V14: 1156 | W14: 785 | X14: 1
A15: DEC | B15: 112126 | C15: 110400 | D15: 1726 | E15: 2000 | F15: 3940 | G15: 2640 | H15: 0.12 | I15: 0.23 | J15: 0.11666667 | K15: 0.53333333 | L15: 1 | M15: 1 | N15: 1 | O15: 1 | P15: 1 | Q15: 1 | R15: 1 | S15: 1 | T15: 100000 | U15: 1800 | V15: 1798 | W15: 202 | X15: 1
A16: Grand Total | B16: 1344765 | C16: 1277190 | D16: 67575 | E16: 21089 | F16: 44358 | G16: 28942 | H16: 0.16416667 | I16: 0.3675 | J16: 0.17722222 | K16: 0.29111111 | L16: 0.96666667 | M16: 0.95833333 | N16: 0.95 | O16: 0.94166667 | P16: 0.93333333 | Q16: 0.91666667 | R16: 0.9 | S16: 0.88333333 | T16: 1200000 | U16: 21600 | V16: 15658 | W16: 5431 | X16: 1
A20: Row Labels | B20: Sum of Revenue | C20: Sum of Expenses | D20: Sum of Profit | E20: Sum of Sales Target | F20: Sum of Standart | G20: Sum of Premium | H20: Sum of Subscribers | I20: Sum of Subscribers Target | J20: Sum of Referral | K20: Sum of Social | L20: Sum of Organic | M20: Sum of Other
A21: JAN | B21: 112023 | C21: 100740 | D21: 11283 | E21: 100000 | F21: 1090 | G21: 474 | H21: 1564 | I21: 1800 | J21: 0.13 | K21: 0.31 | L21: 0.14666667 | M21: 0.41333333
A22: FEB | B22: 89374 | C22: 94530 | D22: -5156 | E22: 100000 | F22: 956 | G22: 561 | H22: 1517 | I22: 1800 | J22: 0.21 | K22: 0.44 | L22: 0.21666667 | M22: 0.13333333
A23: MAR | B23: 73824 | C23: 102810 | D23: -28986 | E23: 100000 | F23: 969 | G23: 614 | H23: 1583 | I23: 1800 | J23: 0.18 | K23: 0.27 | L23: 0.15 | M23: 0.4
A24: APR | B24: 70497 | C24: 113850 | D24: -43353 | E24: 100000 | F24: 1430 | G24: 254 | H24: 1684 | I24: 1800 | J24: 0.07 | K24: 0.47 | L24: 0.18 | M24: 0.28
A25: MAY | B25: 80257 | C25: 106260 | D25: -26003 | E25: 100000 | F25: 834 | G25: 913 | H25: 1747 | I25: 1800 | J25: 0.12 | K25: 0.44 | L25: 0.18666667 | M25: 0.25333333
A26: JUN | B26: 100146 | C26: 89700 | D26: 10446 | E26: 100000 | F26: 961 | G26: 803 | H26: 1764 | I26: 1800 | J26: 0.25 | K26: 0.38 | L26: 0.21 | M26: 0.16
A27: JUL | B27: 123979 | C27: 88320 | D27: 35659 | E27: 100000 | F27: 1644 | G27: 149 | H27: 1793 | I27: 1800 | J27: 0.18 | K27: 0.48 | L27: 0.22 | M27: 0.12
A28: AUG | B28: 143879 | C28: 99360 | D28: 44519 | E28: 100000 | F28: 1637 | G28: 149 | H28: 1786 | I28: 1800 | J28: 0.18 | K28: 0.43 | L28: 0.20333333 | M28: 0.18666667
A29: SEP | B29: 153629 | C29: 120060 | D29: 33569 | E29: 100000 | F29: 1482 | G29: 338 | H29: 1820 | I29: 1800 | J29: 0.23 | K29: 0.43 | L29: 0.22 | M29: 0.12
A30: OCT | B30: 150252 | C30: 128340 | D30: 21912 | E30: 100000 | F30: 1701 | G30: 189 | H30: 1890 | I30: 1800 | J30: 0.18 | K30: 0.2 | L30: 0.12666667 | M30: 0.49333333
A31: NOV | B31: 134779 | C31: 122820 | D31: 11959 | E31: 100000 | F31: 1156 | G31: 785 | H31: 1941 | I31: 1800 | J31: 0.12 | K31: 0.33 | L31: 0.15 | M31: 0.4
A32: DEC | B32: 112126 | C32: 110400 | D32: 1726 | E32: 100000 | F32: 1798 | G32: 202 | H32: 2000 | I32: 1800 | J32: 0.12 | K32: 0.23 | L32: 0.11666667 | M32: 0.53333333
A33: Grand Total | B33: 1344765 | C33: 1277190 | D33: 67575 | E33: 1200000 | F33: 15658 | G33: 5431 | H33: 21089 | I33: 21600 | J33: 1.97 | K33: 4.41 | L33: 2.1266667 | M33: 3.4933333
A35: Row Labels | B35: Sum of Subscribers
A36: 2028 | B36: 21089
A37: Grand Total | B37: 21089
A42: Row Labels | B42: Sum of Subscribers
A43: 2025 | B43: 3873
A44: 2026 | B44: 9235
A45: 2027 | B45: 15418
A46: 2028 | B46: 21089
A47: Grand Total | B47: 49615
A50: Row Labels
A51: Revenue
A52: Grand Total
...

Sheet Data
A1: Year | B1: Month | C1: Revenue | D1: Expenses | E1: Sales Target | F1: Standart | G1: Premium | H1: Subscribers | I1: Subscribers Target | J1: Leads | K1: Deals | L1: Referral | M1: Social | N1: Organic | O1: Other | P1: N | Q1: NE | R1: E | S1: SE | T1: S | U1: SW | V1: W | W1: NW | X1: Coverage Target | Z1: https://exceltable.com/
A2: 2025 | B2: JAN | C2: 37835 | D2: 26660 | E2: 45000 | F2: 59 | G2: 41 | H2: 100 | I2: 300 | J2: 158 | K2: 138 | L2: 0.17 | M2: 0.48 | N2: 0.21666667 | O2: 0.13333333 | P2: 0.2 | Q2: 0.2 | R2: 0.2 | S2: 0.2 | T2: 0.2 | U2: 0.2 | V2: 0.2 | W2: 0.1 | X2: 0.5
A3: 2025 | B3: FEB | C3: 48805 | D3: 32060 | E3: 45000 | F3: 68 | G3: 67 | H3: 135 | I3: 300 | J3: 193 | K3: 193 | L3: 0.1 | M3: 0.31 | N3: 0.13666667 | O3: 0.45333333 | P3: 0.4 | Q3: 0.2 | R3: 0.2 | S3: 0.2 | T3: 0.2 | U3: 0.2 | V3: 0.2 | W3: 0.2 | X3: 0.5
A4: 2025 | B4: MAR | C4: 52169 | D4: 35760 | E4: 45000 | F4: 165 | G4: 42 | H4: 207 | I4: 300 | J4: 602 | K4: 335 | L4: 0.08 | M4: 0.37 | N4: 0.15 | O4: 0.4 | P4: 0.4 | Q4: 0.4 | R4: 0.2 | S4: 0.2 | T4: 0.2 | U4: 0.2 | V4: 0.2 | W4: 0.2 | X4: 0.5
A5: 2025 | B5: APR | C5: 47883 | D5: 36560 | E5: 45000 | F5: 151 | G5: 131 | H5: 282 | I5: 300 | J5: 569 | K5: 386 | L5: 0.24 | M5: 0.33 | N5: 0.19 | O5: 0.24 | P5: 0.4 | Q5: 0.4 | R5: 0.4 | S5: 0.2 | T5: 0.2 | U5: 0.2 | V5: 0.2 | W5: 0.2 | X5: 0.5
A6: 2025 | B6: MAY | C6: 39309 | D6: 34220 | E6: 45000 | F6: 117 | G6: 53 | H6: 170 | I6: 300 | J6: 336 | K6: 210 | L6: 0.08 | M6: 0.4 | N6: 0.16 | O6: 0.36 | P6: 0.4 | Q6: 0.4 | R6: 0.4 | S6: 0.4 | T6: 0.2 | U6: 0.2 | V6: 0.2 | W6: 0.2 | X6: 0.5
A7: 2025 | B7: JUN | C7: 31455 | D7: 29500 | E7: 45000 | F7: 230 | G7: 63 | H7: 293 | I7: 300 | J7: 471 | K7: 345 | L7: 0.14 | M7: 0.39 | N7: 0.17666667 | O7: 0.29333333 | P7: 0.4 | Q7: 0.4 | R7: 0.4 | S7: 0.4 | T7: 0.4 | U7: 0.2 | V7: 0.2 | W7: 0.2 | X7: 0.5
A8: 2025 | B8: JUL | C8: 31175 | D8: 23820 | E8: 45000 | F8: 270 | G8: 136 | H8: 406 | I8: 300 | J8: 840 | K8: 604 | L8: 0.19 | M8: 0.28 | N8: 0.15666667 | O8: 0.37333333 | P8: 0.4 | Q8: 0.4 | R8: 0.4 | S8: 0.4 | T8: 0.4 | U8: 0.4 | V8: 0.2 | W8: 0.2 | X8: 0.5
A9: 2025 | B9: AUG | C9: 43810 | D9: 19100 | E9: 45000 | F9: 318 | G9: 96 | H9: 414 | I9: 300 | J9: 1010 | K9: 554 | L9: 0.14 | M9: 0.39 | N9: 0.17666667 | O9: 0.29333333 | P9: 0.4 | Q9: 0.4 | R9: 0.4 | S9: 0.4 | T9: 0.4 | U9: 0.4 | V9: 0.4 | W9: 0.2 | X9: 0.5
A10: 2025 | B10: SEP | C10: 50097 | D10: 16760 | E10: 45000 | F10: 352 | G10: 53 | H10: 405 | I10: 300 | J10: 599 | K10: 542 | L10: 0.19 | M10: 0.24 | N10: 0.14333333 | O10: 0.42666667 | P10: 0.4 | Q10: 0.4 | R10: 0.4 | S10: 0.4 | T10: 0.4 | U10: 0.4 | V10: 0.4 | W10: 0.4 | X10: 0.5
A11: 2025 | B11: OCT | C11: 50762 | D11: 17560 | E11: 45000 | F11: 323 | G11: 163 | H11: 486 | I11: 300 | J11: 763 | K11: 568 | L11: 0.17 | M11: 0.22 | N11: 0.13 | O11: 0.48 | P11: 0.55 | Q11: 0.4 | R11: 0.4 | S11: 0.4 | T11: 0.4 | U11: 0.4 | V11: 0.4 | W11: 0.4 | X11: 0.5
A12: 2025 | B12: NOV | C12: 45773 | D12: 21260 | E12: 45000 | F12: 284 | G12: 165 | H12: 449 | I12: 300 | J12: 1279 | K12: 682 | L12: 0.17 | M12: 0.26 | N12: 0.14333333 | O12: 0.42666667 | P12: 0.55 | Q12: 0.55 | R12: 0.4 | S12: 0.4 | T12: 0.4 | U12: 0.4 | V12: 0.4 | W12: 0.4 | X12: 0.5
A13: 2025 | B13: DEC | C13: 46402 | D13: 26660 | E13: 45000 | F13: 235 | G13: 291 | H13: 526 | I13: 300 | J13: 878 | K13: 552 | L13: 0.21 | M13: 0.45 | N13: 0.22 | O13: 0.12 | P13: 0.55 | Q13: 0.55 | R13: 0.55 | S13: 0.4 | T13: 0.4 | U13: 0.4 | V13: 0.4 | W13: 0.4 | X13: 0.5
... A49: 2028 | B49: DEC | C49: 112126 | D49: 110400 | E49: 100000 | F49: 1798 | G49: 202 | H49: 2000 | I49: 1800 | J49: 3940 | K49: 2640 | L49: 0.12 | M49: 0.23 | N49: 0.11666667 | O49: 0.53333333 | P49: 1 | Q49: 1 | R49: 1 | S49: 1 | T49: 1 | U49: 1 | V49: 1 | W49: 1 | X49: 1

Sheet Resources
D1: https://exceltable.com/
B3: E993EB
B4: 394CA9
B6: #5987F6
B7: #7A59CD
B9: #F0F8FD
B10: #A2D8F0
B12: #61A7F5
