Workbook
Name Slicer_Density: #N/A

Sheet DASHBOARD

Sheet Processing
A1: counter | B1: mode | C1: recycling1 | D1: recycling2 | E1: recycling3 | F1: recycling4 | G1: recycling5 | H1: ⬛ | I1: █ | J1: =IF(K3,I1,"") -> █ | K1: In/Out | L1: recyclingA | M1: recyclingB | Q1: Marker
A2: 25902 | B2: =GETPIVOTDATA("Mode",Control!$A$10) -> 4 | C2: =IF(MOD($A$2,30)=0,30,MOD($A$2,30)) -> 12 | D2: =MOD($A$2,30) -> 12 | E2: =MOD($A$2,148) -> 2 | F2: =MOD($A$2-30,148) -> 120 | G2: =MOD($A$2,60) -> 42 | H2: Alt+254 | I2: Alt+219 | J2: =IF(K3,"",I1) | K2: =K3+1 -> 2 | L2: =IF(MOD($A$2,44)=0,44,MOD($A$2,44)) -> 30 | M2: =MOD($A$2,88) -> 30 | Q2: =C2 -> 12
B3: Animation 1 | C3: =MOD($A$2,30) -> 12 | D3: AGILE PROJECT MANAGEMENT SPRINTS | F3: =MOD($A$2-117,120)+1 -> 106 | G3: =MOD($A$2,180)+1 -> 163 | J3: =IF(K3,H1,"") -> ⬛ | K3: TRUE | L3: mode1 | M3: mode2 | N3: mode3 | O3: mode4 | P3: Sprint Load Dynamics | R3: dia0 | S3: dia1 | T3: Resource Accumulation
B4: {=IF(OR(A4,$K$2=2),CHOOSE($K$2,INDEX($C$11:$F$40,A4,$B$2),INDEX($L$4:$O$47,K4,$B$2)),"")} -> ⬛ | C4: =MOD($A$2,44) -> 30 | D4: Acceleration | J4: =IF(K3,"","I") | K4: 1 | L4: =IF(K4=$L$2,$H$1,"") | M4: =IF(AND(K4<=$M$2,(K4+44)>$M$2),$H$1,"") -> ⬛ | N4: =IF(MOD($D$2,5)=MOD(K4-ROW($A$1),5),$H$1,"") | O4: =IF(ISEVEN($A$2),$H$1,"") -> ⬛ | P4: {=INDEX(Data!$I$3:$I$182,INT(MOD($G$3,180)/($A$40))*$A$40+A11)} -> 0.175 | Q4: {=INDEX($P$4:$P$33,Q2)} -> 0.805 | R4: 1 | S4: 300 | T4: =IF($F$3=120,300,0) -> 0 | U4: 300 | AJ4: 40
B5: {=IF(OR(A5,$K$2=2),CHOOSE($K$2,INDEX($C$11:$F$40,A5,$B$2),INDEX($L$4:$O$47,K5,$B$2)),"")} | J5: =IF(K3,"",H1) | K5: 2 | L5: =IF(K5=$L$2,$H$1,"") | M5: =IF(AND(K5<=$M$2,(K5+44)>$M$2),$H$1,"") -> ⬛ | N5: =IF(MOD($D$2,5)=MOD(K5-ROW($A$1),5),$H$1,"") | O5: =IF(ISODD($A$2),$H$1,"") | P5: {=INDEX(Data!$I$3:$I$182,INT(MOD($G$3,180)/($A$40))*$A$40+A12)} -> 0.219 | R5: 1 | S5: 40 | T5: =IF($F$3=120,40,0) -> 0 | U5: 40 | AJ5: 45
B6: {=IF(OR(A6,$K$2=2),CHOOSE($K$2,INDEX($C$11:$F$40,A6,$B$2),INDEX($L$4:$O$47,K6,$B$2)),"")} -> ⬛ | K6: 3 | L6: =IF(K6=$L$2,$H$1,"") | M6: =IF(AND(K6<=$M$2,(K6+44)>$M$2),$H$1,"") -> ⬛ | N6: =IF(MOD($D$2,5)=MOD(K6-ROW($A$1),5),$H$1,"") -> ⬛ | O6: =IF(ISEVEN($A$2),$H$1,"") -> ⬛ | P6: {=INDEX(Data!$I$3:$I$182,INT(MOD($G$3,180)/($A$40))*$A$40+A13)} -> 0.285 | R6: 1 | S6: 45 | T6: =SUM(OFFSET($AI$18,$F$3,0,2,1))-T5 -> 0 | U6: 45 | AJ6: 50
B7: {=IF(OR(A7,$K$2=2),CHOOSE($K$2,INDEX($C$11:$F$40,A7,$B$2),INDEX($L$4:$O$47,K7,$B$2)),"")} | K7: 4 | L7: =IF(K7=$L$2,$H$1,"") | M7: =IF(AND(K7<=$M$2,(K7+44)>$M$2),$H$1,"") -> ⬛ | N7: =IF(MOD($D$2,5)=MOD(K7-ROW($A$1),5),$H$1,"") | O7: =IF(ISODD($A$2),$H$1,"") | P7: {=INDEX(Data!$I$3:$I$182,INT(MOD($G$3,180)/($A$40))*$A$40+A14)} -> 0.375 | Q7: =INT(MOD($G$3,180)/($A$40))*$A$40+A11 -> 151 | R7: 1 | S7: 50 | T7: {=INDEX($AW$4:$AW$123,$F$3)} -> 0 | U7: 50 | AJ7: 55
B8: {=IF(OR(A8,$K$2=2),CHOOSE($K$2,INDEX($C$11:$F$40,A8,$B$2),INDEX($L$4:$O$47,K8,$B$2)),"")} -> ⬛ | H8: Agile Sprints | K8: 5 | L8: =IF(K8=$L$2,$H$1,"") | M8: =IF(AND(K8<=$M$2,(K8+44)>$M$2),$H$1,"") -> ⬛ | N8: =IF(MOD($D$2,5)=MOD(K8-ROW($A$1),5),$H$1,"") | O8: =IF(ISEVEN($A$2),$H$1,"") -> ⬛ | P8: {=INDEX(Data!$I$3:$I$182,INT(MOD($G$3,180)/($A$40))*$A$40+A15)} -> 0.489 | R8: 1 | S8: 55 | T8: =SUM(OFFSET($AH$17,$F$3,0,3,1))-T7 -> 0 | U8: 55 | AJ8: 60
B9: {=IF(OR(A9,$K$2=2),CHOOSE($K$2,INDEX($C$11:$F$40,A9,$B$2),INDEX($L$4:$O$47,K9,$B$2)),"")} | H9: CHOOSE | J9: =CHOOSE($K$2,IF(C3>28,15,14),IF((C4-7)>28,15,14)) -> 14 | K9: 6 | L9: =IF(K9=$L$2,$H$1,"") | M9: =IF(AND(K9<=$M$2,(K9+44)>$M$2),$H$1,"") -> ⬛ | N9: =IF(MOD($D$2,5)=MOD(K9-ROW($A$1),5),$H$1,"") | O9: =IF(ISODD($A$2),$H$1,"") | P9: {=INDEX(Data!$I$3:$I$182,INT(MOD($G$3,180)/($A$40))*$A$40+A16)} -> 0.615 | R9: 1 | S9: 60 | T9: {=INDEX($AV$4:$AV$123,$F$3)} -> 0 | U9: 60 | AJ9: 65
B10: {=IF(OR(A10,$K$2=2),CHOOSE($K$2,INDEX($C$11:$F$40,A10,$B$2),INDEX($L$4:$O$47,K10,$B$2)),"")} -> ⬛ | C10: mode1 | D10: mode2 | E10: mode3 | F10: mode4 | G10: dia | H10: =CHOOSE($K$2,(D40=H1)+1,(B47=H1)+1) -> 1 | K10: 7 | L10: =IF(K10=$L$2,$H$1,"") | M10: =IF(AND(K10<=$M$2,(K10+44)>$M$2),$H$1,"") -> ⬛ | N10: =IF(MOD($D$2,5)=MOD(K10-ROW($A$1),5),$H$1,"") | O10: =IF(ISEVEN($A$2),$H$1,"") -> ⬛ | P10: {=INDEX(Data!$I$3:$I$182,INT(MOD($G$3,180)/($A$40))*$A$40+A17)} -> 0.7 | R10: 1 | S10: 65 | T10: =SUM(OFFSET($AG$16,$F$3,0,4,1))-T9 -> 0 | U10: 65 | AJ10: 70
A11: 1 | B11: {=IF(OR(A11,$K$2=2),CHOOSE($K$2,INDEX($C$11:$F$40,A11,$B$2),INDEX($L$4:$O$47,K11,$B$2)),"")} | C11: =IF(A11=$C$2,$H$1,"") | D11: =IF(AND(A11<=$G$2,(A11+30)>$G$2),$H$1,"") | E11: =IF(MOD($D$2,5)=MOD(A11-ROW($A$1),5),$H$1,"") | F11: =IF(ISEVEN($A$2),$H$1,"") -> ⬛ | G11: 1 | H11: {=INDEX($I$11:$J$16,A11,$H$10)} -> 7 | I11: =30-SUM(I12:I15) -> 7 | J11: 0 | K11: 8 | L11: =IF(K11=$L$2,$H$1,"") | M11: =IF(AND(K11<=$M$2,(K11+44)>$M$2),$H$1,"") -> ⬛ | N11: =IF(MOD($D$2,5)=MOD(K11-ROW($A$1),5),$H$1,"") -> ⬛ | O11: =IF(ISODD($A$2),$H$1,"") | P11: {=INDEX(Data!$I$3:$I$182,INT(MOD($G$3,180)/($A$40))*$A$40+A18)} -> 0.757 | R11: 1 | S11: 70 | T11: {=INDEX($AU$4:$AU$123,$F$3)} -> 0 | U11: 70 | AJ11: 75
A12: 2 | B12: {=IF(OR(A12,$K$2=2),CHOOSE($K$2,INDEX($C$11:$F$40,A12,$B$2),INDEX($L$4:$O$47,K12,$B$2)),"")} -> ⬛ | C12: =IF(A12=$C$2,$H$1,"") | D12: =IF(AND(A12<=$G$2,(A12+30)>$G$2),$H$1,"") | E12: =IF(MOD($D$2,5)=MOD(A12-ROW($A$1),5),$H$1,"") | F12: =IF(ISODD($A$2),$H$1,"") | G12: 1 | H12: {=INDEX($I$11:$J$16,A12,$H$10)} -> 1 | I12: =CHOOSE($K$2,(C3>=15)*1,IF(C4<8,0,AND(C4>=15+7,C4<38)*1)) -> 1 | J12: =CHOOSE($K$2,1,0) -> 0 | K12: 9 | L12: =IF(K12=$L$2,$H$1,"") | M12: =IF(AND(K12<=$M$2,(K12+44)>$M$2),$H$1,"") -> ⬛ | N12: =IF(MOD($D$2,5)=MOD(K12-ROW($A$1),5),$H$1,"") | O12: =IF(ISEVEN($A$2),$H$1,"") -> ⬛ | P12: {=INDEX(Data!$I$3:$I$182,INT(MOD($G$3,180)/($A$40))*$A$40+A19)} -> 0.791 | R12: 1 | S12: 75 | T12: =SUM(OFFSET($AF$15,$F$3,0,5,1))-T11 -> 300 | U12: 75 | AJ12: 80
A13: 3 | B13: {=IF(OR(A13,$K$2=2),CHOOSE($K$2,INDEX($C$11:$F$40,A13,$B$2),INDEX($L$4:$O$47,K13,$B$2)),"")} | C13: =IF(A13=$C$2,$H$1,"") | D13: =IF(AND(A13<=$G$2,(A13+30)>$G$2),$H$1,"") | E13: =IF(MOD($D$2,5)=MOD(A13-ROW($A$1),5),$H$1,"") -> ⬛ | F13: =IF(ISEVEN($A$2),$H$1,"") -> ⬛ | G13: 1 | H13: {=INDEX($I$11:$J$16,A13,$H$10)} -> 0 | I13: =CHOOSE($K$2,AND(C3<=14,C3>0)*1,IF(C4<8,0,(C4<=14+7)*1)) -> 0 | J13: 0 | K13: 10 | L13: =IF(K13=$L$2,$H$1,"") | M13: =IF(AND(K13<=$M$2,(K13+44)>$M$2),$H$1,"") -> ⬛ | N13: =IF(MOD($D$2,5)=MOD(K13-ROW($A$1),5),$H$1,"") | O13: =IF(ISODD($A$2),$H$1,"") | P13: {=INDEX(Data!$I$3:$I$182,INT(MOD($G$3,180)/($A$40))*$A$40+A20)} -> 0.808 | R13: 1 | S13: 80 | T13: {=INDEX($AT$4:$AT$123,$F$3)} -> 40 | U13: 80 | AJ13: 85
A14: 4 | B14: {=IF(OR(A14,$K$2=2),CHOOSE($K$2,INDEX($C$11:$F$40,A14,$B$2),INDEX($L$4:$O$47,K14,$B$2)),"")} -> ⬛ | C14: =IF(A14=$C$2,$H$1,"") | D14: =IF(AND(A14<=$G$2,(A14+30)>$G$2),$H$1,"") | E14: =IF(MOD($D$2,5)=MOD(A14-ROW($A$1),5),$H$1,"") | F14: =IF(ISODD($A$2),$H$1,"") | G14: 1 | H14: {=INDEX($I$11:$J$16,A14,$H$10)} -> 8 | I14: =CHOOSE($K$2,IF(I12,C3-15,0),CHOOSE((C4>8)*1+1+(C4>37),0,IF(I12,C4-14-8,0),16)) -> 8 | J14: =CHOOSE($K$2,IF(C3>=J9,29-C3,15),CHOOSE((C4>8)*1+1+(C4>37),16,IF((C4-7)>=15,30-(C4-7),16),),16) -> 7 | K14: 11 | L14: =IF(K14=$L$2,$H$1,"") | M14: =IF(AND(K14<=$M$2,(K14+44)>$M$2),$H$1,"") -> ⬛ | N14: =IF(MOD($D$2,5)=MOD(K14-ROW($A$1),5),$H$1,"") | O14: =IF(ISEVEN($A$2),$H$1,"") -> ⬛ | P14: {=INDEX(Data!$I$3:$I$182,INT(MOD($G$3,180)/($A$40))*$A$40+A21)} -> 0.812 | R14: 1 | S14: 85 | T14: =SUM(OFFSET($AE$14,$F$3,0,6,1))-T13 -> 210 | U14: 85 | AJ14: 90
A15: 5 | B15: {=IF(OR(A15,$K$2=2),CHOOSE($K$2,INDEX($C$11:$F$40,A15,$B$2),INDEX($L$4:$O$47,K15,$B$2)),"")} | C15: =IF(A15=$C$2,$H$1,"") | D15: =IF(AND(A15<=$G$2,(A15+30)>$G$2),$H$1,"") | E15: =IF(MOD($D$2,5)=MOD(A15-ROW($A$1),5),$H$1,"") | F15: =IF(ISEVEN($A$2),$H$1,"") -> ⬛ | G15: 1 | H15: {=INDEX($I$11:$J$16,A15,$H$10)} -> 14 | I15: =CHOOSE($K$2,IF(OR(I13,C3=0),C3-1+(C3=0),14),IF(C4<8,0,IF(I13,C4-8,14))) -> 14 | J15: =CHOOSE($K$2,IF(C3<=13,J9-C3,0),IF(C4<8,14,IF((C4-7)<=13,J9-(C4-7),0))) -> 0 | K15: 12 | L15: =IF(K15=$L$2,$H$1,"") | M15: =IF(AND(K15<=$M$2,(K15+44)>$M$2),$H$1,"") -> ⬛ | N15: =IF(MOD($D$2,5)=MOD(K15-ROW($A$1),5),$H$1,"") | O15: =IF(ISODD($A$2),$H$1,"") | P15: {=INDEX(Data!$I$3:$I$182,INT(MOD($G$3,180)/($A$40))*$A$40+A22)} -> 0.805 | R15: 1 | S15: 90 | T15: {=INDEX($AS$4:$AS$123,$F$3)} -> 65 | U15: 90 | AJ15: 95
A16: 6 | B16: {=IF(OR(A16,$K$2=2),CHOOSE($K$2,INDEX($C$11:$F$40,A16,$B$2),INDEX($L$4:$O$47,K16,$B$2)),"")} -> ⬛ | C16: =IF(A16=$C$2,$H$1,"") | D16: =IF(AND(A16<=$G$2,(A16+30)>$G$2),$H$1,"") | E16: =IF(MOD($D$2,5)=MOD(A16-ROW($A$1),5),$H$1,"") | F16: =IF(ISODD($A$2),$H$1,"") | G16: 1 | H16: {=INDEX($I$11:$J$16,A16,$H$10)} -> 0 | I16: 0 | J16: =30-SUM(J11:J15) -> 23 | K16: 13 | L16: =IF(K16=$L$2,$H$1,"") | M16: =IF(AND(K16<=$M$2,(K16+44)>$M$2),$H$1,"") -> ⬛ | N16: =IF(MOD($D$2,5)=MOD(K16-ROW($A$1),5),$H$1,"") -> ⬛ | O16: =IF(ISEVEN($A$2),$H$1,"") -> ⬛ | P16: {=INDEX(Data!$I$3:$I$182,INT(MOD($G$3,180)/($A$40))*$A$40+A23)} -> 0.78 | S16: 95 | T16: =SUM(OFFSET($AD$13,$F$3,0,7,1))-T15 -> 0 | U16: 95 | AJ16: 110
A17: 7 | B17: {=IF(OR(A17,$K$2=2),CHOOSE($K$2,INDEX($C$11:$F$40,A17,$B$2),INDEX($L$4:$O$47,K17,$B$2)),"")} | C17: =IF(A17=$C$2,$H$1,"") | D17: =IF(AND(A17<=$G$2,(A17+30)>$G$2),$H$1,"") | E17: =IF(MOD($D$2,5)=MOD(A17-ROW($A$1),5),$H$1,"") | F17: =IF(ISEVEN($A$2),$H$1,"") -> ⬛ | G17: 1 | H17: Enter/Exit | K17: 14 | L17: =IF(K17=$L$2,$H$1,"") | M17: =IF(AND(K17<=$M$2,(K17+44)>$M$2),$H$1,"") -> ⬛ | N17: =IF(MOD($D$2,5)=MOD(K17-ROW($A$1),5),$H$1,"") | O17: =IF(ISODD($A$2),$H$1,"") | P17: {=INDEX(Data!$I$3:$I$182,INT(MOD($G$3,180)/($A$40))*$A$40+A24)} -> 0.752 | Q17: Backlog | S17: 110 | T17: {=INDEX($AR$4:$AR$123,$F$3)} -> 70 | U17: 110 | AJ17: 200
A18: 8 | B18: {=IF(OR(A18,$K$2=2),CHOOSE($K$2,INDEX($C$11:$F$40,A18,$B$2),INDEX($L$4:$O$47,K18,$B$2)),"")} -> ⬛ | C18: =IF(A18=$C$2,$H$1,"") | D18: =IF(AND(A18<=$G$2,(A18+30)>$G$2),$H$1,"") | E18: =IF(MOD($D$2,5)=MOD(A18-ROW($A$1),5),$H$1,"") -> ⬛ | F18: =IF(ISODD($A$2),$H$1,"") | G18: 1 | H18: back Top | I18: back Top | J18: back Top | K18: 15 | L18: =IF(K18=$L$2,$H$1,"") | M18: =IF(AND(K18<=$M$2,(K18+44)>$M$2),$H$1,"") -> ⬛ | N18: =IF(MOD($D$2,5)=MOD(K18-ROW($A$1),5),$H$1,"") | O18: =IF(ISEVEN($A$2),$H$1,"") -> ⬛ | P18: {=INDEX(Data!$I$3:$I$182,INT(MOD($G$3,180)/($A$40))*$A$40+A25)} -> 0.726 | Q18: Features | R18: Bugs | S18: 200 | T18: =SUM(OFFSET($AC$12,$F$3,0,8,1))-T17 -> 0 | U18: 200 | AJ18: 250
A19: 9 | B19: {=IF(OR(A19,$K$2=2),CHOOSE($K$2,INDEX($C$11:$F$40,A19,$B$2),INDEX($L$4:$O$47,K19,$B$2)),"")} | C19: =IF(A19=$C$2,$H$1,"") | D19: =IF(AND(A19<=$G$2,(A19+30)>$G$2),$H$1,"") | E19: =IF(MOD($D$2,5)=MOD(A19-ROW($A$1),5),$H$1,"") | F19: =IF(ISEVEN($A$2),$H$1,"") -> ⬛ | G19: 1 | H19: {=INDEX($I$19:$J$92,ROW(A1),$H$10)} -> 1 | I19: =IF(OR($C$4<34),1,0)*$K$3 -> 1 | J19: =IF(OR($C$4>=33,$C$4=0),0,1)*$K$3 -> 1 | K19: 16 | L19: =IF(K19=$L$2,$H$1,"") | M19: =IF(AND(K19<=$M$2,(K19+44)>$M$2),$H$1,"") -> ⬛ | N19: =IF(MOD($D$2,5)=MOD(K19-ROW($A$1),5),$H$1,"") | O19: =IF(ISODD($A$2),$H$1,"") | P19: {=INDEX(Data!$I$3:$I$182,INT(MOD($G$3,180)/($A$40))*$A$40+A26)} -> 0.704 | Q19: {=INDEX(Data!$J$3:$J$182,$G$3)} -> 0.343 | R19: {=INDEX(Data!$K$3:$K$182,$G$3)} -> 0.657 | S19: 250 | T19: {=INDEX($AQ$4:$AQ$123,$F$3)} -> 75 | U19: 250 | AJ19: 250 | AK19: 40
A20: 10 | B20: {=IF(OR(A20,$K$2=2),CHOOSE($K$2,INDEX($C$11:$F$40,A20,$B$2),INDEX($L$4:$O$47,K20,$B$2)),"")} -> ⬛ | C20: =IF(A20=$C$2,$H$1,"") | D20: =IF(AND(A20<=$G$2,(A20+30)>$G$2),$H$1,"") | E20: =IF(MOD($D$2,5)=MOD(A20-ROW($A$1),5),$H$1,"") | F20: =IF(ISODD($A$2),$H$1,"") | G20: 1 | H20: {=INDEX($I$19:$J$92,ROW(A2),$H$10)} -> 1 | I20: =IF(OR($C$4<34),1,0)*$K$3 -> 1 | J20: =IF(OR($C$4>=33,$C$4=0),0,1)*$K$3 -> 1 | K20: 17 | L20: =IF(K20=$L$2,$H$1,"") | M20: =IF(AND(K20<=$M$2,(K20+44)>$M$2),$H$1,"") -> ⬛ | N20: =IF(MOD($D$2,5)=MOD(K20-ROW($A$1),5),$H$1,"") | O20: =IF(ISEVEN($A$2),$H$1,"") -> ⬛ | P20: {=INDEX(Data!$I$3:$I$182,INT(MOD($G$3,180)/($A$40))*$A$40+A27)} -> 0.686 | S20: =SUM(S4:S19) -> 1670 | T20: =SUM(OFFSET($AB$11,$F$3,0,9,1))-T19 -> 0 | V20: 300 | AJ20: 250 | AK20: 45
A21: 11 | B21: {=IF(OR(A21,$K$2=2),CHOOSE($K$2,INDEX($C$11:$F$40,A21,$B$2),INDEX($L$4:$O$47,K21,$B$2)),"")} | C21: =IF(A21=$C$2,$H$1,"") | D21: =IF(AND(A21<=$G$2,(A21+30)>$G$2),$H$1,"") | E21: =IF(MOD($D$2,5)=MOD(A21-ROW($A$1),5),$H$1,"") | F21: =IF(ISEVEN($A$2),$H$1,"") -> ⬛ | G21: 1 | H21: {=INDEX($I$19:$J$92,ROW(A3),$H$10)} -> 1 | I21: =IF(OR($C$4<34),1,0)*$K$3 -> 1 | J21: =IF(OR($C$4>=33,$C$4=0),0,1)*$K$3 -> 1 | K21: 18 | L21: =IF(K21=$L$2,$H$1,"") | M21: =IF(AND(K21<=$M$2,(K21+44)>$M$2),$H$1,"") -> ⬛ | N21: =IF(MOD($D$2,5)=MOD(K21-ROW($A$1),5),$H$1,"") -> ⬛ | O21: =IF(ISODD($A$2),$H$1,"") | P21: {=INDEX(Data!$I$3:$I$182,INT(MOD($G$3,180)/($A$40))*$A$40+A28)} -> 0.668 | T21: {=INDEX($AP$4:$AP$123,$F$3)} -> 80 | V21: 40 | AJ21: 250 | AK21: 50
A22: 12 | B22: {=IF(OR(A22,$K$2=2),CHOOSE($K$2,INDEX($C$11:$F$40,A22,$B$2),INDEX($L$4:$O$47,K22,$B$2)),"")} -> ⬛ | C22: =IF(A22=$C$2,$H$1,"") -> ⬛ | D22: =IF(AND(A22<=$G$2,(A22+30)>$G$2),$H$1,"") | E22: =IF(MOD($D$2,5)=MOD(A22-ROW($A$1),5),$H$1,"") | F22: =IF(ISODD($A$2),$H$1,"") | G22: 1 | H22: {=INDEX($I$19:$J$92,ROW(A4),$H$10)} -> 1 | I22: =IF(OR($C$4<34),1,0)*$K$3 -> 1 | J22: =IF(OR($C$4>=33,$C$4=0),0,1)*$K$3 -> 1 | K22: 19 | L22: =IF(K22=$L$2,$H$1,"") | M22: =IF(AND(K22<=$M$2,(K22+44)>$M$2),$H$1,"") -> ⬛ | N22: =IF(MOD($D$2,5)=MOD(K22-ROW($A$1),5),$H$1,"") | O22: =IF(ISEVEN($A$2),$H$1,"") -> ⬛ | P22: {=INDEX(Data!$I$3:$I$182,INT(MOD($G$3,180)/($A$40))*$A$40+A29)} -> 0.654 | T22: =SUM(OFFSET($AA$10,$F$3,0,10,1))-T21 -> 0 | V22: 45 | AJ22: 250 | AK22: 55
A23: 13 | B23: {=IF(OR(A23,$K$2=2),CHOOSE($K$2,INDEX($C$11:$F$40,A23,$B$2),INDEX($L$4:$O$47,K23,$B$2)),"")} | C23: =IF(A23=$C$2,$H$1,"") | D23: =IF(AND(A23<=$G$2,(A23+30)>$G$2),$H$1,"") -> ⬛ | E23: =IF(MOD($D$2,5)=MOD(A23-ROW($A$1),5),$H$1,"") -> ⬛ | F23: =IF(ISEVEN($A$2),$H$1,"") -> ⬛ | G23: 1 | H23: {=INDEX($I$19:$J$92,ROW(A5),$H$10)} -> 1 | I23: =IF(OR($C$4<34),1,0)*$K$3 -> 1 | J23: =IF(OR($C$4>=33,$C$4=0),0,1)*$K$3 -> 1 | K23: 20 | L23: =IF(K23=$L$2,$H$1,"") | M23: =IF(AND(K23<=$M$2,(K23+44)>$M$2),$H$1,"") -> ⬛ | N23: =IF(MOD($D$2,5)=MOD(K23-ROW($A$1),5),$H$1,"") | O23: =IF(ISODD($A$2),$H$1,"") | P23: {=INDEX(Data!$I$3:$I$182,INT(MOD($G$3,180)/($A$40))*$A$40+A30)} -> 0.645 | T23: {=INDEX($AO$4:$AO$123,$F$3)} -> 85 | V23: 50 | AJ23: 250 | AK23: 60
A24: 14 | B24: {=IF(OR(A24,$K$2=2),CHOOSE($K$2,INDEX($C$11:$F$40,A24,$B$2),INDEX($L$4:$O$47,K24,$B$2)),"")} -> ⬛ | C24: =IF(A24=$C$2,$H$1,"") | D24: =IF(AND(A24<=$G$2,(A24+30)>$G$2),$H$1,"") -> ⬛ | E24: =IF(MOD($D$2,5)=MOD(A24-ROW($A$1),5),$H$1,"") | F24: =IF(ISODD($A$2),$H$1,"") | G24: 1 | H24: {=INDEX($I$19:$J$92,ROW(A6),$H$10)} -> 1 | I24: =IF(OR($C$4<34),1,0)*$K$3 -> 1 | J24: =IF(OR($C$4>=33,$C$4=0),0,1)*$K$3 -> 1 | K24: 21 | L24: =IF(K24=$L$2,$H$1,"") | M24: =IF(AND(K24<=$M$2,(K24+44)>$M$2),$H$1,"") -> ⬛ | N24: =IF(MOD($D$2,5)=MOD(K24-ROW($A$1),5),$H$1,"") | O24: =IF(ISEVEN($A$2),$H$1,"") -> ⬛ | P24: {=INDEX(Data!$I$3:$I$182,INT(MOD($G$3,180)/($A$40))*$A$40+A31)} -> 0.633 | T24: =SUM(OFFSET($Z$9,$F$3,0,11,1))-T23 -> 0 | V24: 55 | AJ24: 250 | AK24: 65
A25: 15 | B25: {=IF(OR(A25,$K$2=2),CHOOSE($K$2,INDEX($C$11:$F$40,A25,$B$2),INDEX($L$4:$O$47,K25,$B$2)),"")} | C25: =IF(A25=$C$2,$H$1,"") | D25: =IF(AND(A25<=$G$2,(A25+30)>$G$2),$H$1,"") -> ⬛ | E25: =IF(MOD($D$2,5)=MOD(A25-ROW($A$1),5),$H$1,"") | F25: =IF(ISEVEN($A$2),$H$1,"") -> ⬛ | G25: 1 | H25: {=INDEX($I$19:$J$92,ROW(A7),$H$10)} -> 1 | I25: =IF(OR($C$4<34),1,0)*$K$3 -> 1 | J25: =IF(OR($C$4>=33,$C$4=0),0,1)*$K$3 -> 1 | K25: 22 | L25: =IF(K25=$L$2,$H$1,"") | M25: =IF(AND(K25<=$M$2,(K25+44)>$M$2),$H$1,"") -> ⬛ | N25: =IF(MOD($D$2,5)=MOD(K25-ROW($A$1),5),$H$1,"") | O25: =IF(ISODD($A$2),$H$1,"") | P25: {=INDEX(Data!$I$3:$I$182,INT(MOD($G$3,180)/($A$40))*$A$40+A32)} -> 0.598 | T25: {=INDEX($AN$4:$AN$123,$F$3)} -> 90 | V25: 60 | AJ25: 250 | AK25: 70
A26: 16 | B26: {=IF(OR(A26,$K$2=2),CHOOSE($K$2,INDEX($C$11:$F$40,A26,$B$2),INDEX($L$4:$O$47,K26,$B$2)),"")} -> ⬛ | C26: =IF(A26=$C$2,$H$1,"") | D26: =IF(AND(A26<=$G$2,(A26+30)>$G$2),$H$1,"") -> ⬛ | E26: =IF(MOD($D$2,5)=MOD(A26-ROW($A$1),5),$H$1,"") | F26: =IF(ISODD($A$2),$H$1,"") | G26: 1 | H26: {=INDEX($I$19:$J$92,ROW(A8),$H$10)} -> 0 | I26: =IF($C$4>=34,1,0)*$K$3 -> 0 | J26: =IF($C$4>=33,1,0)*$K$3 -> 0 | K26: 23 | L26: =IF(K26=$L$2,$H$1,"") | M26: =IF(AND(K26<=$M$2,(K26+44)>$M$2),$H$1,"") -> ⬛ | N26: =IF(MOD($D$2,5)=MOD(K26-ROW($A$1),5),$H$1,"") -> ⬛ | O26: =IF(ISEVEN($A$2),$H$1,"") -> ⬛ | P26: {=INDEX(Data!$I$3:$I$182,INT(MOD($G$3,180)/($A$40))*$A$40+A33)} -> 0.547 | T26: =SUM(OFFSET($Y$8,$F$3,0,12,1))-T25 -> 0 | V26: 65 | AJ26: 250 | AK26: 75
A27: 17 | B27: {=IF(OR(A27,$K$2=2),CHOOSE($K$2,INDEX($C$11:$F$40,A27,$B$2),INDEX($L$4:$O$47,K27,$B$2)),"")} | C27: =IF(A27=$C$2,$H$1,"") | D27: =IF(AND(A27<=$G$2,(A27+30)>$G$2),$H$1,"") -> ⬛ | E27: =IF(MOD($D$2,5)=MOD(A27-ROW($A$1),5),$H$1,"") | F27: =IF(ISEVEN($A$2),$H$1,"") -> ⬛ | G27: 1 | H27: {=INDEX($I$19:$J$92,ROW(A9),$H$10)} -> 0 | I27: =IF($C$4>=34,1,0)*$K$3 -> 0 | J27: =IF($C$4>=33,1,0)*$K$3 -> 0 | K27: 24 | L27: =IF(K27=$L$2,$H$1,"") | M27: =IF(AND(K27<=$M$2,(K27+44)>$M$2),$H$1,"") -> ⬛ | N27: =IF(MOD($D$2,5)=MOD(K27-ROW($A$1),5),$H$1,"") | O27: =IF(ISODD($A$2),$H$1,"") | P27: {=INDEX(Data!$I$3:$I$182,INT(MOD($G$3,180)/($A$40))*$A$40+A34)} -> 0.48 | T27: {=INDEX($AM$4:$AM$123,$F$3)} -> 95 | V27: 70 | AJ27: 250 | AK27: 80
A28: 18 | B28: {=IF(OR(A28,$K$2=2),CHOOSE($K$2,INDEX($C$11:$F$40,A28,$B$2),INDEX($L$4:$O$47,K28,$B$2)),"")} -> ⬛ | C28: =IF(A28=$C$2,$H$1,"") | D28: =IF(AND(A28<=$G$2,(A28+30)>$G$2),$H$1,"") -> ⬛ | E28: =IF(MOD($D$2,5)=MOD(A28-ROW($A$1),5),$H$1,"") -> ⬛ | F28: =IF(ISODD($A$2),$H$1,"") | G28: 1 | H28: {=INDEX($I$19:$J$92,ROW(A10),$H$10)} -> 0 | I28: =IF($C$4>=34,1,0)*$K$3 -> 0 | J28: =IF($C$4>=33,1,0)*$K$3 -> 0 | K28: 25 | L28: =IF(K28=$L$2,$H$1,"") | M28: =IF(AND(K28<=$M$2,(K28+44)>$M$2),$H$1,"") -> ⬛ | N28: =IF(MOD($D$2,5)=MOD(K28-ROW($A$1),5),$H$1,"") | O28: =IF(ISEVEN($A$2),$H$1,"") -> ⬛ | P28: {=INDEX(Data!$I$3:$I$182,INT(MOD($G$3,180)/($A$40))*$A$40+A35)} -> 0.412 | T28: =SUM(OFFSET($X$7,$F$3,0,13,1))-T27 -> 0 | V28: 75 | AJ28: 250 | AK28: 85
A29: 19 | B29: {=IF(OR(A29,$K$2=2),CHOOSE($K$2,INDEX($C$11:$F$40,A29,$B$2),INDEX($L$4:$O$47,K29,$B$2)),"")} | C29: =IF(A29=$C$2,$H$1,"") | D29: =IF(AND(A29<=$G$2,(A29+30)>$G$2),$H$1,"") -> ⬛ | E29: =IF(MOD($D$2,5)=MOD(A29-ROW($A$1),5),$H$1,"") | F29: =IF(ISEVEN($A$2),$H$1,"") -> ⬛ | G29: 1 | H29: {=INDEX($I$19:$J$92,ROW(A11),$H$10)} -> 0 | I29: =IF($C$4>=34,1,0)*$K$3 -> 0 | J29: =IF($C$4>=33,1,0)*$K$3 -> 0 | K29: 26 | L29: =IF(K29=$L$2,$H$1,"") | M29: =IF(AND(K29<=$M$2,(K29+44)>$M$2),$H$1,"") -> ⬛ | N29: =IF(MOD($D$2,5)=MOD(K29-ROW($A$1),5),$H$1,"") | O29: =IF(ISODD($A$2),$H$1,"") | P29: {=INDEX(Data!$I$3:$I$182,INT(MOD($G$3,180)/($A$40))*$A$40+A36)} -> 0.35 | Q29: =CHOOSE(MATCH($S$29,{0;4;10;18;26},0),27%,41%,55%,60%,100%) -> 0.27 | R29: Ideas | S29: {=INDEX(Data!$L$3:$L$182,$G$3)} -> 0 | T29: {=INDEX($AL$4:$AL$123,$F$3)} -> 110 | V29: 80 | AJ29: 250 | AK29: 90
A30: 20 | B30: {=IF(OR(A30,$K$2=2),CHOOSE($K$2,INDEX($C$11:$F$40,A30,$B$2),INDEX($L$4:$O$47,K30,$B$2)),"")} -> ⬛ | C30: =IF(A30=$C$2,$H$1,"") | D30: =IF(AND(A30<=$G$2,(A30+30)>$G$2),$H$1,"") -> ⬛ | E30: =IF(MOD($D$2,5)=MOD(A30-ROW($A$1),5),$H$1,"") | F30: =IF(ISODD($A$2),$H$1,"") | G30: 1 | H30: {=INDEX($I$19:$J$92,ROW(A12),$H$10)} -> 0 | I30: =IF($C$4>=34,1,0)*$K$3 -> 0 | J30: =IF($C$4>=33,1,0)*$K$3 -> 0 | K30: 27 | L30: =IF(K30=$L$2,$H$1,"") | M30: =IF(AND(K30<=$M$2,(K30+44)>$M$2),$H$1,"") -> ⬛ | N30: =IF(MOD($D$2,5)=MOD(K30-ROW($A$1),5),$H$1,"") | O30: =IF(ISEVEN($A$2),$H$1,"") -> ⬛ | P30: {=INDEX(Data!$I$3:$I$182,INT(MOD($G$3,180)/($A$40))*$A$40+A37)} -> 0.294 | Q30: =CHOOSE(MATCH($S$29,{0;4;10;18;26},0),24%,25%,27%,40%,0%) -> 0.24 | R30: AI Analysis | S30: =IF(S29<>0,10,0) -> 0 | T30: =SUM(OFFSET($W$6,$F$3,0,14,1))-T29 -> 0 | V30: 85 | AJ30: 250 | AK30: 95
A31: 21 | B31: {=IF(OR(A31,$K$2=2),CHOOSE($K$2,INDEX($C$11:$F$40,A31,$B$2),INDEX($L$4:$O$47,K31,$B$2)),"")} | C31: =IF(A31=$C$2,$H$1,"") | D31: =IF(AND(A31<=$G$2,(A31+30)>$G$2),$H$1,"") -> ⬛ | E31: =IF(MOD($D$2,5)=MOD(A31-ROW($A$1),5),$H$1,"") | F31: =IF(ISEVEN($A$2),$H$1,"") -> ⬛ | G31: 1 | H31: {=INDEX($I$19:$J$92,ROW(A13),$H$10)} -> 0 | I31: =IF($C$4>=34,1,0)*$K$3 -> 0 | J31: =IF($C$4>=33,1,0)*$K$3 -> 0 | K31: 28 | L31: =IF(K31=$L$2,$H$1,"") | M31: =IF(AND(K31<=$M$2,(K31+44)>$M$2),$H$1,"") -> ⬛ | N31: =IF(MOD($D$2,5)=MOD(K31-ROW($A$1),5),$H$1,"") -> ⬛ | O31: =IF(ISODD($A$2),$H$1,"") | P31: {=INDEX(Data!$I$3:$I$182,INT(MOD($G$3,180)/($A$40))*$A$40+A38)} -> 0.249 | Q31: =CHOOSE(MATCH($S$29,{0;4;10;18;26},0),20%,19%,18%,0%,0%) -> 0.2 | R31: All Ready | T31: {=INDEX($AK$4:$AK$123,$F$3)} -> 200 | V31: 90 | AJ31: 250 | AK31: 110
A32: 22 | B32: {=IF(OR(A32,$K$2=2),CHOOSE($K$2,INDEX($C$11:$F$40,A32,$B$2),INDEX($L$4:$O$47,K32,$B$2)),"")} -> ⬛ | C32: =IF(A32=$C$2,$H$1,"") | D32: =IF(AND(A32<=$G$2,(A32+30)>$G$2),$H$1,"") -> ⬛ | E32: =IF(MOD($D$2,5)=MOD(A32-ROW($A$1),5),$H$1,"") | F32: =IF(ISODD($A$2),$H$1,"") | G32: 1 | H32: {=INDEX($I$19:$J$92,ROW(A14),$H$10)} -> 0 | I32: =IF($C$4>=34,1,0)*$K$3 -> 0 | J32: =IF($C$4>=33,1,0)*$K$3 -> 0 | K32: 29 | L32: =IF(K32=$L$2,$H$1,"") | M32: =IF(AND(K32<=$M$2,(K32+44)>$M$2),$H$1,"") -> ⬛ | N32: =IF(MOD($D$2,5)=MOD(K32-ROW($A$1),5),$H$1,"") | O32: =IF(ISEVEN($A$2),$H$1,"") -> ⬛ | P32: {=INDEX(Data!$I$3:$I$182,INT(MOD($G$3,180)/($A$40))*$A$40+A39)} -> 0.219 | Q32: =CHOOSE(MATCH($S$29,{0;4;10;18;26},0),17%,15%,0%,0%,0%) -> 0.17 | R32: Process | T32: =SUM(OFFSET($V$5,$F$3,0,15,1))-T31 -> 0 | V32: 95 | AJ32: 250 | AK32: 200
A33: 23 | B33: {=IF(OR(A33,$K$2=2),CHOOSE($K$2,INDEX($C$11:$F$40,A33,$B$2),INDEX($L$4:$O$47,K33,$B$2)),"")} | C33: =IF(A33=$C$2,$H$1,"") | D33: =IF(AND(A33<=$G$2,(A33+30)>$G$2),$H$1,"") -> ⬛ | E33: =IF(MOD($D$2,5)=MOD(A33-ROW($A$1),5),$H$1,"") -> ⬛ | F33: =IF(ISEVEN($A$2),$H$1,"") -> ⬛ | G33: 1 | H33: {=INDEX($I$19:$J$92,ROW(A15),$H$10)} -> folow | I33: folow | J33: folow | K33: 30 | L33: =IF(K33=$L$2,$H$1,"") -> ⬛ | M33: =IF(AND(K33<=$M$2,(K33+44)>$M$2),$H$1,"") -> ⬛ | N33: =IF(MOD($D$2,5)=MOD(K33-ROW($A$1),5),$H$1,"") | O33: =IF(ISODD($A$2),$H$1,"") | P33: {=INDEX(Data!$I$3:$I$182,INT(MOD($G$3,180)/($A$40))*$A$40+A40)} -> 0.2 | Q33: =CHOOSE(MATCH($S$29,{0;4;10;18;26},0),12%,0%,0%,0%,0%) -> 0.12 | R33: Done | T33: {=INDEX($AJ$4:$AJ$123,$F$3)} -> 250 | V33: 110 | AJ33: 250 | AK33: 200 | AL33: 40
A34: 24 | B34: {=IF(OR(A34,$K$2=2),CHOOSE($K$2,INDEX($C$11:$F$40,A34,$B$2),INDEX($L$4:$O$47,K34,$B$2)),"")} -> ⬛ | C34: =IF(A34=$C$2,$H$1,"") | D34: =IF(AND(A34<=$G$2,(A34+30)>$G$2),$H$1,"") -> ⬛ | E34: =IF(MOD($D$2,5)=MOD(A34-ROW($A$1),5),$H$1,"") | F34: =IF(ISODD($A$2),$H$1,"") | G34: 1 | H34: {=INDEX($I$19:$J$92,ROW(A16),$H$10)} -> 1 | I34: =AND($C$4>A11,$C$4<34)*1*$K$3 -> 1 | J34: =(NOT(AND($C$4>=A11))*1-($C$4=0))*$K$3 -> 0 | K34: 31 | L34: =IF(K34=$L$2,$H$1,"") | M34: =IF(AND(K34<=$M$2,(K34+44)>$M$2),$H$1,"") | N34: =IF(MOD($D$2,5)=MOD(K34-ROW($A$1),5),$H$1,"") | O34: =IF(ISEVEN($A$2),$H$1,"") -> ⬛ | T34: =SUM(OFFSET($U$4,$F$3,0,15,1))-T33 -> 0 | U34: 250 | V34: 200 | AJ34: 250 | AK34: 200 | AL34: 45
A35: 25 | B35: {=IF(OR(A35,$K$2=2),CHOOSE($K$2,INDEX($C$11:$F$40,A35,$B$2),INDEX($L$4:$O$47,K35,$B$2)),"")} | C35: =IF(A35=$C$2,$H$1,"") | D35: =IF(AND(A35<=$G$2,(A35+30)>$G$2),$H$1,"") -> ⬛ | E35: =IF(MOD($D$2,5)=MOD(A35-ROW($A$1),5),$H$1,"") | F35: =IF(ISEVEN($A$2),$H$1,"") -> ⬛ | G35: 1 | H35: {=INDEX($I$19:$J$92,ROW(A17),$H$10)} -> 1 | I35: =AND($C$4>A12,$C$4<34)*1*$K$3 -> 1 | J35: =(NOT(AND($C$4>=A12))*1-($C$4=0))*$K$3 -> 0 | K35: 32 | L35: =IF(K35=$L$2,$H$1,"") | M35: =IF(AND(K35<=$M$2,(K35+44)>$M$2),$H$1,"") | N35: =IF(MOD($D$2,5)=MOD(K35-ROW($A$1),5),$H$1,"") | O35: =IF(ISODD($A$2),$H$1,"") | T35: =SUM(T4:T34) -> 1670 | W35: 300 | AJ35: 250 | AK35: 200 | AL35: 50
A36: 26 | B36: {=IF(OR(A36,$K$2=2),CHOOSE($K$2,INDEX($C$11:$F$40,A36,$B$2),INDEX($L$4:$O$47,K36,$B$2)),"")} -> ⬛ | C36: =IF(A36=$C$2,$H$1,"") | D36: =IF(AND(A36<=$G$2,(A36+30)>$G$2),$H$1,"") -> ⬛ | E36: =IF(MOD($D$2,5)=MOD(A36-ROW($A$1),5),$H$1,"") | F36: =IF(ISODD($A$2),$H$1,"") | G36: 1 | H36: {=INDEX($I$19:$J$92,ROW(A18),$H$10)} -> 1 | I36: =AND($C$4>A13,$C$4<34)*1*$K$3 -> 1 | J36: =(NOT(AND($C$4>=A13))*1-($C$4=0))*$K$3 -> 0 | K36: 33 | L36: =IF(K36=$L$2,$H$1,"") | M36: =IF(AND(K36<=$M$2,(K36+44)>$M$2),$H$1,"") | N36: =IF(MOD($D$2,5)=MOD(K36-ROW($A$1),5),$H$1,"") -> ⬛ | O36: =IF(ISEVEN($A$2),$H$1,"") -> ⬛ | T36: {=SUMPRODUCT((MOD(ROW(T4:T34),2)=1)*(T4:T34))/(T35-S4)} -> 0.84671533 | W36: 40 | AJ36: 250 | AK36: 200 | AL36: 55
A37: 27 | B37: {=IF(OR(A37,$K$2=2),CHOOSE($K$2,INDEX($C$11:$F$40,A37,$B$2),INDEX($L$4:$O$47,K37,$B$2)),"")} | C37: =IF(A37=$C$2,$H$1,"") | D37: =IF(AND(A37<=$G$2,(A37+30)>$G$2),$H$1,"") -> ⬛ | E37: =IF(MOD($D$2,5)=MOD(A37-ROW($A$1),5),$H$1,"") | F37: =IF(ISEVEN($A$2),$H$1,"") -> ⬛ | G37: 1 | H37: {=INDEX($I$19:$J$92,ROW(A19),$H$10)} -> 1 | I37: =AND($C$4>A14,$C$4<34)*1*$K$3 -> 1 | J37: =(NOT(AND($C$4>=A14))*1-($C$4=0))*$K$3 -> 0 | K37: 34 | L37: =IF(K37=$L$2,$H$1,"") | M37: =IF(AND(K37<=$M$2,(K37+44)>$M$2),$H$1,"") | N37: =IF(MOD($D$2,5)=MOD(K37-ROW($A$1),5),$H$1,"") | O37: =IF(ISODD($A$2),$H$1,"") | P37: Team Capacity Usage | S37: indent | W37: 45 | AJ37: 250 | AK37: 200 | AL37: 60
A38: 28 | B38: {=IF(OR(A38,$K$2=2),CHOOSE($K$2,INDEX($C$11:$F$40,A38,$B$2),INDEX($L$4:$O$47,K38,$B$2)),"")} -> ⬛ | C38: =IF(A38=$C$2,$H$1,"") | D38: =IF(AND(A38<=$G$2,(A38+30)>$G$2),$H$1,"") -> ⬛ | E38: =IF(MOD($D$2,5)=MOD(A38-ROW($A$1),5),$H$1,"") -> ⬛ | F38: =IF(ISODD($A$2),$H$1,"") | G38: 1 | H38: {=INDEX($I$19:$J$92,ROW(A20),$H$10)} -> 1 | I38: =AND($C$4>A15,$C$4<34)*1*$K$3 -> 1 | J38: =(NOT(AND($C$4>=A15))*1-($C$4=0))*$K$3 -> 0 | K38: 35 | L38: =IF(K38=$L$2,$H$1,"") | M38: =IF(AND(K38<=$M$2,(K38+44)>$M$2),$H$1,"") | N38: =IF(MOD($D$2,5)=MOD(K38-ROW($A$1),5),$H$1,"") | O38: =IF(ISEVEN($A$2),$H$1,"") -> ⬛ | P38: Workload | Q38: {=INDEX(Data!$G$3:$G$182,$G$3)} -> 0.651 | R38: =1-Q38 -> 0.349 | S38: 0.2 | W38: 50 | AJ38: 250 | AK38: 200 | AL38: 65
A39: 29 | B39: {=IF(OR(A39,$K$2=2),CHOOSE($K$2,INDEX($C$11:$F$40,A39,$B$2),INDEX($L$4:$O$47,K39,$B$2)),"")} | C39: =IF(A39=$C$2,$H$1,"") | D39: =IF(AND(A39<=$G$2,(A39+30)>$G$2),$H$1,"") -> ⬛ | E39: =IF(MOD($D$2,5)=MOD(A39-ROW($A$1),5),$H$1,"") | F39: =IF(ISEVEN($A$2),$H$1,"") -> ⬛ | G39: 1 | H39: {=INDEX($I$19:$J$92,ROW(A21),$H$10)} -> 1 | I39: =AND($C$4>A16,$C$4<34)*1*$K$3 -> 1 | J39: =(NOT(AND($C$4>=A16))*1-($C$4=0))*$K$3 -> 0 | K39: 36 | L39: =IF(K39=$L$2,$H$1,"") | M39: =IF(AND(K39<=$M$2,(K39+44)>$M$2),$H$1,"") | N39: =IF(MOD($D$2,5)=MOD(K39-ROW($A$1),5),$H$1,"") | O39: =IF(ISODD($A$2),$H$1,"") | P39: Engagement | Q39: {=INDEX(Data!$H$3:$H$182,$G$3)} -> 0.667 | R39: =1-Q39 -> 0.333 | S39: 0.2 | W39: 55 | AJ39: 250 | AK39: 200 | AL39: 70
A40: 30 | B40: {=IF(OR(A40,$K$2=2),CHOOSE($K$2,INDEX($C$11:$F$40,A40,$B$2),INDEX($L$4:$O$47,K40,$B$2)),"")} -> ⬛ | C40: =IF(A40=$C$2,$H$1,"") | D40: =IF(AND(A40<=$G$2,(A40+30)>$G$2),$H$1,"") -> ⬛ | E40: =IF(MOD($D$2,5)=MOD(A40-ROW($A$1),5),$H$1,"") | F40: =IF(ISODD($A$2),$H$1,"") | G40: 1 | H40: {=INDEX($I$19:$J$92,ROW(A22),$H$10)} -> 1 | I40: =AND($C$4>A17,$C$4<34)*1*$K$3 -> 1 | J40: =(NOT(AND($C$4>=A17))*1-($C$4=0))*$K$3 -> 0 | K40: 37 | L40: =IF(K40=$L$2,$H$1,"") | M40: =IF(AND(K40<=$M$2,(K40+44)>$M$2),$H$1,"") | N40: =IF(MOD($D$2,5)=MOD(K40-ROW($A$1),5),$H$1,"") | O40: =IF(ISEVEN($A$2),$H$1,"") -> ⬛ | W40: 60 | AJ40: 250 | AK40: 200 | AL40: 75
...

Sheet Control
A1: Density | B1: Mode
A2: Capacity 1 | B2: 1
A3: Capacity 2 | B3: 2
A4: Capacity 3 | B4: 3
A5: Capacity 4 | B5: 4
A10: Row Labels | B10: Max of Mode
A11: Capacity 4 | B11: 4
A12: Grand Total | B12: 4

Sheet Data
A1: Global Сycle | B1: Energy Power | E1: Warehouse Storage | I1: Sprint Load Dynamics | J1: Mine Source | M1: Manufacturing Chain | R1: Costs Level
B2: Plan | C2: Actual | D2: previous | E2: Task Balance | F2: Risk of Overload | G2: Workload | H2: Engagement | J2: Features | K2: Bugs | L2: Availability | M2: Initiation | N2: Design | O2: Prototyping | P2: Engineering | Q2: Testing
A3: 1 | B3: 0.317 | C3: 0.412 | D3: 0.218 | E3: 0.89 | F3: 0.25 | G3: 0.218 | H3: 0.17 | I3: 0.2 | J3: 0.84 | K3: 0.16 | L3: 0 | M3: 662 | N3: 599 | O3: 521 | P3: 408 | Q3: 379 | R3: 98
A4: 2 | B4: 0.322 | C4: 0.425 | D4: 0.237 | E4: 0.87 | F4: 0.28 | G4: 0.237 | H4: 0.23 | I4: 0.219 | J4: 0.78 | K4: 0.22 | L4: 0 | M4: 170 | N4: 218 | O4: 237 | P4: 230 | Q4: 85 | R4: 95
A5: 3 | B5: 0.34 | C5: 0.441 | D5: 0.268 | E5: 0.86 | F5: 0.3 | G5: 0.268 | H5: 0.3 | I5: 0.249 | J5: 0.71 | K5: 0.29 | L5: 0 | M5: 230 | N5: 237 | O5: 268 | P5: 300 | Q5: 115 | R5: 90
A6: 4 | B6: 0.369 | C6: 0.46 | D6: 0.303 | E6: 0.83 | F6: 0.38 | G6: 0.303 | H6: 0.368 | I6: 0.294 | J6: 0.642 | K6: 0.358 | L6: 0 | M6: 300 | N6: 268 | O6: 303 | P6: 368 | Q6: 150 | R6: 85
A7: 5 | B7: 0.409 | C7: 0.482 | D7: 0.349 | E7: 0.83 | F7: 0.43 | G7: 0.349 | H7: 0.436 | I7: 0.35 | J7: 0.574 | K7: 0.426 | L7: 0 | M7: 368 | N7: 303 | O7: 349 | P7: 436 | Q7: 184 | R7: 80
A8: 6 | B8: 0.458 | C8: 0.504 | D8: 0.4 | E8: 0.83 | F8: 0.43 | G8: 0.4 | H8: 0.488 | I8: 0.412 | J8: 0.522 | K8: 0.478 | L8: 0 | M8: 436 | N8: 349 | O8: 400 | P8: 488 | Q8: 218 | R8: 75
A9: 7 | B9: 0.502 | C9: 0.523 | D9: 0.449 | E9: 0.82 | F9: 0.44 | G9: 0.449 | H9: 0.531 | I9: 0.48 | J9: 0.479 | K9: 0.521 | L9: 0 | M9: 488 | N9: 400 | O9: 449 | P9: 531 | Q9: 244 | R9: 70
A10: 8 | B10: 0.54 | C10: 0.54 | D10: 0.488 | E10: 0.82 | F10: 0.45 | G10: 0.488 | H10: 0.564 | I10: 0.547 | J10: 0.446 | K10: 0.554 | L10: 4 | M10: 531 | N10: 449 | O10: 488 | P10: 564 | Q10: 266 | R10: 65
A11: 9 | B11: 0.572 | C11: 0.555 | D11: 0.521 | E11: 0.8 | F11: 0.46 | G11: 0.521 | H11: 0.591 | I11: 0.598 | J11: 0.419 | K11: 0.581 | L11: 4 | M11: 564 | N11: 488 | O11: 521 | P11: 591 | Q11: 282 | R11: 60
A12: 10 | B12: 0.597 | C12: 0.568 | D12: 0.552 | E12: 0.79 | F12: 0.49 | G12: 0.552 | H12: 0.612 | I12: 0.633 | J12: 0.398 | K12: 0.602 | L12: 10 | M12: 591 | N12: 521 | O12: 552 | P12: 612 | Q12: 296 | R12: 55
A13: 11 | B13: 0.617 | C13: 0.58 | D13: 0.578 | E13: 0.79 | F13: 0.5 | G13: 0.578 | H13: 0.63 | I13: 0.645 | J13: 0.38 | K13: 0.62 | L13: 10 | M13: 612 | N13: 552 | O13: 578 | P13: 630 | Q13: 306 | R13: 50
A14: 12 | B14: 0.632 | C14: 0.59 | D14: 0.603 | E14: 0.76 | F14: 0.51 | G14: 0.603 | H14: 0.644 | I14: 0.654 | J14: 0.366 | K14: 0.634 | L14: 18 | M14: 630 | N14: 578 | O14: 603 | P14: 644 | Q14: 315 | R14: 45
... A182: 180 | B182: 0.231 | C182: 0.607 | D182: 0.17 | E182: 0.25 | F182: 0.89 | G182: 0.17 | H182: 0.218 | I182: 0.2 | J182: 0.792 | K182: 0.208 | L182: 0 | M182: 237 | N182: 230 | O182: 170 | P182: 218 | Q182: 119 | R182: 55

Sheet Resources
B1: Colors | C1: Position | D1: Angle | E1: Transparency | G1: Shadow | O1: $#,##0;-$#,##0;0 | R1: [>=1000]0,"k";[<=-1000]-0,"k";0
